2023-07-24 16:14:28.915 - ETL_TEST_INA_AD5_TO_XSIFF [ERROR   ] Read file and parse error
2023-07-24 16:14:28.916 - ETL_TEST_INA_AD5_TO_XSIFF [ERROR   ] name 'process_HF' is not defined
2023-07-24 16:14:28.922 - CustomFuction [ERROR   ] name 'process_HF' is not defined
Traceback (most recent call last):
  File "D:\Ina\ETL_XdmLib_2.A.13\ETL_XdmLib_2.A.13\EDAETL\ETL_TABLE\ETL_TEST_INA_WAT_TO_XSIFF\../..\XdmLib\CustomFuction.py", line 596, in file2db_init
    res = do_file(file_root_source_path,
  File "D:/Ina/ETL_XdmLib_2.A.13/ETL_XdmLib_2.A.13/EDAETL/ETL_TABLE/ETL_TEST_INA_WAT_TO_XSIFF/ETL_TEST_INA_AD5_TO_XSIFF.py", line 294, in do_file
    raise ex
  File "D:/Ina/ETL_XdmLib_2.A.13/ETL_XdmLib_2.A.13/EDAETL/ETL_TABLE/ETL_TEST_INA_WAT_TO_XSIFF/ETL_TEST_INA_AD5_TO_XSIFF.py", line 209, in do_file
    file_creation_datetime_str = process_HF(process_list)
NameError: name 'process_HF' is not defined
Stack (most recent call last):
  File "D:\soft\PyCharm Community Edition 2022.1.3\plugins\python-ce\helpers\pydev\pydevd.py", line 2181, in <module>
    main()
  File "D:\soft\PyCharm Community Edition 2022.1.3\plugins\python-ce\helpers\pydev\pydevd.py", line 2172, in main
    globals = debugger.run(setup['file'], None, None, is_module)
  File "D:\soft\PyCharm Community Edition 2022.1.3\plugins\python-ce\helpers\pydev\pydevd.py", line 1484, in run
    return self._exec(is_module, entry_point_fn, module_name, file, globals, locals)
  File "D:\soft\PyCharm Community Edition 2022.1.3\plugins\python-ce\helpers\pydev\pydevd.py", line 1491, in _exec
    pydev_imports.execfile(file, globals, locals)  # execute the script
  File "D:\soft\PyCharm Community Edition 2022.1.3\plugins\python-ce\helpers\pydev\_pydev_imps\_pydev_execfile.py", line 18, in execfile
    exec(compile(contents+"\n", file, 'exec'), glob, loc)
  File "D:/Ina/ETL_XdmLib_2.A.13/ETL_XdmLib_2.A.13/EDAETL/ETL_TABLE/ETL_TEST_INA_WAT_TO_XSIFF/ETL_TEST_INA_AD5_TO_XSIFF.py", line 450, in <module>
    XdmLib.CustomFuction.file2db_init(
  File "D:\Ina\ETL_XdmLib_2.A.13\ETL_XdmLib_2.A.13\EDAETL\ETL_TABLE\ETL_TEST_INA_WAT_TO_XSIFF\../..\XdmLib\CustomFuction.py", line 631, in file2db_init
    log.error(ex, exc_info=True, stack_info=True)
2023-07-24 16:14:28.943 - CustomFuction [ERROR   ] Move File Error
2023-07-24 16:14:28.944 - CustomFuction [ERROR   ] [WinError 32] 另一个程序正在使用此文件，进程无法访问。: '.\\\\Data\\\\Source\\2022111517445900_0625682.002_PUIXE010MXE3.ad5'
Traceback (most recent call last):
  File "D:\Ina\ETL_XdmLib_2.A.13\ETL_XdmLib_2.A.13\EDAETL\ETL_TABLE\ETL_TEST_INA_WAT_TO_XSIFF\../..\XdmLib\CustomFuction.py", line 596, in file2db_init
    res = do_file(file_root_source_path,
  File "D:/Ina/ETL_XdmLib_2.A.13/ETL_XdmLib_2.A.13/EDAETL/ETL_TABLE/ETL_TEST_INA_WAT_TO_XSIFF/ETL_TEST_INA_AD5_TO_XSIFF.py", line 294, in do_file
    raise ex
  File "D:/Ina/ETL_XdmLib_2.A.13/ETL_XdmLib_2.A.13/EDAETL/ETL_TABLE/ETL_TEST_INA_WAT_TO_XSIFF/ETL_TEST_INA_AD5_TO_XSIFF.py", line 209, in do_file
    file_creation_datetime_str = process_HF(process_list)
NameError: name 'process_HF' is not defined

During handling of the above exception, another exception occurred:

Traceback (most recent call last):
  File "D:\soft\anaconda3\lib\shutil.py", line 823, in move
    os.rename(src, real_dst)
PermissionError: [WinError 32] 另一个程序正在使用此文件，进程无法访问。: '.\\\\Data\\\\Source\\2022111517445900_0625682.002_PUIXE010MXE3.ad5' -> 'Data\\ERROR\\2022111517445900_0625682.002_PUIXE010MXE3.ad5'

During handling of the above exception, another exception occurred:

Traceback (most recent call last):
  File "D:\Ina\ETL_XdmLib_2.A.13\ETL_XdmLib_2.A.13\EDAETL\ETL_TABLE\ETL_TEST_INA_WAT_TO_XSIFF\../..\XdmLib\CustomFuction.py", line 1035, in move_file
    msg = shutil.move(os.path.join(source_path, fileName),
  File "D:\soft\anaconda3\lib\shutil.py", line 844, in move
    os.unlink(src)
PermissionError: [WinError 32] 另一个程序正在使用此文件，进程无法访问。: '.\\\\Data\\\\Source\\2022111517445900_0625682.002_PUIXE010MXE3.ad5'
Stack (most recent call last):
  File "D:\soft\PyCharm Community Edition 2022.1.3\plugins\python-ce\helpers\pydev\pydevd.py", line 2181, in <module>
    main()
  File "D:\soft\PyCharm Community Edition 2022.1.3\plugins\python-ce\helpers\pydev\pydevd.py", line 2172, in main
    globals = debugger.run(setup['file'], None, None, is_module)
  File "D:\soft\PyCharm Community Edition 2022.1.3\plugins\python-ce\helpers\pydev\pydevd.py", line 1484, in run
    return self._exec(is_module, entry_point_fn, module_name, file, globals, locals)
  File "D:\soft\PyCharm Community Edition 2022.1.3\plugins\python-ce\helpers\pydev\pydevd.py", line 1491, in _exec
    pydev_imports.execfile(file, globals, locals)  # execute the script
  File "D:\soft\PyCharm Community Edition 2022.1.3\plugins\python-ce\helpers\pydev\_pydev_imps\_pydev_execfile.py", line 18, in execfile
    exec(compile(contents+"\n", file, 'exec'), glob, loc)
  File "D:/Ina/ETL_XdmLib_2.A.13/ETL_XdmLib_2.A.13/EDAETL/ETL_TABLE/ETL_TEST_INA_WAT_TO_XSIFF/ETL_TEST_INA_AD5_TO_XSIFF.py", line 450, in <module>
    XdmLib.CustomFuction.file2db_init(
  File "D:\Ina\ETL_XdmLib_2.A.13\ETL_XdmLib_2.A.13\EDAETL\ETL_TABLE\ETL_TEST_INA_WAT_TO_XSIFF\../..\XdmLib\CustomFuction.py", line 646, in file2db_init
    move_file_self(move_file_info)
  File "D:\Ina\ETL_XdmLib_2.A.13\ETL_XdmLib_2.A.13\EDAETL\ETL_TABLE\ETL_TEST_INA_WAT_TO_XSIFF\../..\XdmLib\CustomFuction.py", line 1044, in move_file
    log.error(ex, exc_info=True, stack_info=True)
2023-07-24 17:19:37.367 - ETL_TEST_INA_AD5_TO_XSIFF [ERROR   ] Read file and parse error
2023-07-24 17:19:37.369 - ETL_TEST_INA_AD5_TO_XSIFF [ERROR   ] I/O operation on closed file.
2023-07-24 17:19:37.377 - CustomFuction [ERROR   ] I/O operation on closed file.
Traceback (most recent call last):
  File "D:\Ina\ETL_XdmLib_2.A.13\ETL_XdmLib_2.A.13\EDAETL\ETL_TABLE\ETL_TEST_INA_WAT_TO_XSIFF\../..\XdmLib\CustomFuction.py", line 596, in file2db_init
    res = do_file(file_root_source_path,
  File "D:\Ina\ETL_XdmLib_2.A.13\ETL_XdmLib_2.A.13\EDAETL\ETL_TABLE\ETL_TEST_INA_WAT_TO_XSIFF\ETL_TEST_INA_AD5_TO_XSIFF.py", line 347, in do_file
    raise ex
  File "D:\Ina\ETL_XdmLib_2.A.13\ETL_XdmLib_2.A.13\EDAETL\ETL_TABLE\ETL_TEST_INA_WAT_TO_XSIFF\ETL_TEST_INA_AD5_TO_XSIFF.py", line 226, in do_file
    for line in f:
ValueError: I/O operation on closed file.
Stack (most recent call last):
  File "D:\Ina\ETL_XdmLib_2.A.13\ETL_XdmLib_2.A.13\EDAETL\ETL_TABLE\ETL_TEST_INA_WAT_TO_XSIFF\ETL_TEST_INA_AD5_TO_XSIFF.py", line 505, in <module>
    XdmLib.CustomFuction.file2db_init(
  File "D:\Ina\ETL_XdmLib_2.A.13\ETL_XdmLib_2.A.13\EDAETL\ETL_TABLE\ETL_TEST_INA_WAT_TO_XSIFF\../..\XdmLib\CustomFuction.py", line 631, in file2db_init
    log.error(ex, exc_info=True, stack_info=True)
2023-07-24 17:21:25.789 - ETL_TEST_INA_AD5_TO_XSIFF [ERROR   ] Read file and parse error
2023-07-24 17:21:25.790 - ETL_TEST_INA_AD5_TO_XSIFF [ERROR   ] I/O operation on closed file.
2023-07-24 17:21:25.800 - CustomFuction [ERROR   ] I/O operation on closed file.
Traceback (most recent call last):
  File "D:\Ina\ETL_XdmLib_2.A.13\ETL_XdmLib_2.A.13\EDAETL\ETL_TABLE\ETL_TEST_INA_WAT_TO_XSIFF\../..\XdmLib\CustomFuction.py", line 596, in file2db_init
    res = do_file(file_root_source_path,
  File "D:\Ina\ETL_XdmLib_2.A.13\ETL_XdmLib_2.A.13\EDAETL\ETL_TABLE\ETL_TEST_INA_WAT_TO_XSIFF\ETL_TEST_INA_AD5_TO_XSIFF.py", line 347, in do_file
    raise ex
  File "D:\Ina\ETL_XdmLib_2.A.13\ETL_XdmLib_2.A.13\EDAETL\ETL_TABLE\ETL_TEST_INA_WAT_TO_XSIFF\ETL_TEST_INA_AD5_TO_XSIFF.py", line 226, in do_file
    for line in f:
ValueError: I/O operation on closed file.
Stack (most recent call last):
  File "D:\Ina\ETL_XdmLib_2.A.13\ETL_XdmLib_2.A.13\EDAETL\ETL_TABLE\ETL_TEST_INA_WAT_TO_XSIFF\ETL_TEST_INA_AD5_TO_XSIFF.py", line 505, in <module>
    XdmLib.CustomFuction.file2db_init(
  File "D:\Ina\ETL_XdmLib_2.A.13\ETL_XdmLib_2.A.13\EDAETL\ETL_TABLE\ETL_TEST_INA_WAT_TO_XSIFF\../..\XdmLib\CustomFuction.py", line 631, in file2db_init
    log.error(ex, exc_info=True, stack_info=True)
2023-07-24 17:28:29.537 - ETL_TEST_INA_AD5_TO_XSIFF [ERROR   ] Data has null value : x:6,y:9,value:None
2023-07-24 17:28:32.575 - __init__   [ERROR   ] File:2022111517445900_0625682.002_PUIXE010MXE3.ad5 Move To Error Folder
                                                Error: None
2023-07-24 17:35:58.117 - ETL_TEST_INA_AD5_TO_XSIFF [ERROR   ] Data has null value : x:6,y:9,value:None
2023-07-24 17:36:01.182 - __init__   [ERROR   ] File:2022111517445900_0625682.002_PUIXE010MXE3.ad5 Move To Error Folder
                                                Error: None
