2023-12-22 10:34:01.768 - ETL_LC_CP_TO_XSIFF [ERROR   ] 'Series' object has no attribute 'applymap'
Traceback (most recent call last):
  File "D:/Ina/ETL_XdmLib_2.A.13/ETL_XdmLib_2.A.13/EDAETL/ETL_TABLE/ETL_LC_CP_TO_XSIFF/ETL_LC_CP_TO_XSIFF.py", line 185, in do_file
    temp_df['SpecLow'] = temp_df['SpecLow'].applymap(lambda x: x.rstrip('0').rstrip('.') if '.' in x else x)
  File "D:\Python37\lib\site-packages\pandas\core\generic.py", line 5141, in __getattr__
    return object.__getattribute__(self, name)
AttributeError: 'Series' object has no attribute 'applymap'
Stack (most recent call last):
  File "D:/Ina/ETL_XdmLib_2.A.13/ETL_XdmLib_2.A.13/EDAETL/ETL_TABLE/ETL_LC_CP_TO_XSIFF/ETL_LC_CP_TO_XSIFF.py", line 402, in <module>
    do_file, before_do_file, after_do_file, skip_file, None, log, config, config_sql)
  File "../..\XdmLib\CustomFuction.py", line 597, in file2db_init
    file, pre_params, db_src, db_tgt)
  File "D:/Ina/ETL_XdmLib_2.A.13/ETL_XdmLib_2.A.13/EDAETL/ETL_TABLE/ETL_LC_CP_TO_XSIFF/ETL_LC_CP_TO_XSIFF.py", line 302, in do_file
    log.error(ex, exc_info=True, stack_info=True)
2023-12-22 10:34:01.993 - __init__   [ERROR   ] File:#24.csv Move To Error Folder
                                                Error: None
2023-12-22 10:38:29.535 - ETL_LC_CP_TO_XSIFF [ERROR   ] 'str' object has no attribute 'dtype'
Traceback (most recent call last):
  File "D:/Ina/ETL_XdmLib_2.A.13/ETL_XdmLib_2.A.13/EDAETL/ETL_TABLE/ETL_LC_CP_TO_XSIFF/ETL_LC_CP_TO_XSIFF.py", line 185, in do_file
    temp_df['SpecLow'] = temp_df['SpecLow'].apply(lambda x: x.str.rstrip('0').str.rstrip('.') if x.dtype == 'object' else x)
  File "D:\Python37\lib\site-packages\pandas\core\series.py", line 4213, in apply
    mapped = lib.map_infer(values, f, convert=convert_dtype)
  File "pandas\_libs\lib.pyx", line 2403, in pandas._libs.lib.map_infer
  File "D:/Ina/ETL_XdmLib_2.A.13/ETL_XdmLib_2.A.13/EDAETL/ETL_TABLE/ETL_LC_CP_TO_XSIFF/ETL_LC_CP_TO_XSIFF.py", line 185, in <lambda>
    temp_df['SpecLow'] = temp_df['SpecLow'].apply(lambda x: x.str.rstrip('0').str.rstrip('.') if x.dtype == 'object' else x)
AttributeError: 'str' object has no attribute 'dtype'
Stack (most recent call last):
  File "D:/Ina/ETL_XdmLib_2.A.13/ETL_XdmLib_2.A.13/EDAETL/ETL_TABLE/ETL_LC_CP_TO_XSIFF/ETL_LC_CP_TO_XSIFF.py", line 402, in <module>
    do_file, before_do_file, after_do_file, skip_file, None, log, config, config_sql)
  File "../..\XdmLib\CustomFuction.py", line 597, in file2db_init
    file, pre_params, db_src, db_tgt)
  File "D:/Ina/ETL_XdmLib_2.A.13/ETL_XdmLib_2.A.13/EDAETL/ETL_TABLE/ETL_LC_CP_TO_XSIFF/ETL_LC_CP_TO_XSIFF.py", line 302, in do_file
    log.error(ex, exc_info=True, stack_info=True)
2023-12-22 10:38:29.745 - __init__   [ERROR   ] File:#24.csv Move To Error Folder
                                                Error: None
2023-12-22 10:49:30.771 - ETL_LC_CP_TO_XSIFF [ERROR   ] module 'datetime' has no attribute 'strptime'
Traceback (most recent call last):
  File "D:/Ina/ETL_XdmLib_2.A.13/ETL_XdmLib_2.A.13/EDAETL/ETL_TABLE/ETL_LC_CP_TO_XSIFF/ETL_LC_CP_TO_XSIFF.py", line 278, in do_file
    datetime.strptime(header[variable_name], date_format)
AttributeError: module 'datetime' has no attribute 'strptime'
Stack (most recent call last):
  File "D:/Ina/ETL_XdmLib_2.A.13/ETL_XdmLib_2.A.13/EDAETL/ETL_TABLE/ETL_LC_CP_TO_XSIFF/ETL_LC_CP_TO_XSIFF.py", line 397, in <module>
    do_file, before_do_file, after_do_file, skip_file, None, log, config, config_sql)
  File "../..\XdmLib\CustomFuction.py", line 597, in file2db_init
    file, pre_params, db_src, db_tgt)
  File "D:/Ina/ETL_XdmLib_2.A.13/ETL_XdmLib_2.A.13/EDAETL/ETL_TABLE/ETL_LC_CP_TO_XSIFF/ETL_LC_CP_TO_XSIFF.py", line 297, in do_file
    log.error(ex, exc_info=True, stack_info=True)
2023-12-22 10:49:30.979 - __init__   [ERROR   ] File:#24.csv Move To Error Folder
                                                Error: None
2023-12-22 10:55:13.170 - ETL_LC_CP_TO_XSIFF [ERROR   ] 'str' object has no attribute 'dtype'
Traceback (most recent call last):
  File "D:/Ina/ETL_XdmLib_2.A.13/ETL_XdmLib_2.A.13/EDAETL/ETL_TABLE/ETL_LC_CP_TO_XSIFF/ETL_LC_CP_TO_XSIFF.py", line 181, in do_file
    temp_df['SpecLow'] = temp_df['SpecLow'].apply(lambda x: x.str.rstrip('0').str.rstrip('.') if x.dtype == 'object' else x)
  File "D:\Python37\lib\site-packages\pandas\core\series.py", line 4213, in apply
    mapped = lib.map_infer(values, f, convert=convert_dtype)
  File "pandas\_libs\lib.pyx", line 2403, in pandas._libs.lib.map_infer
  File "D:/Ina/ETL_XdmLib_2.A.13/ETL_XdmLib_2.A.13/EDAETL/ETL_TABLE/ETL_LC_CP_TO_XSIFF/ETL_LC_CP_TO_XSIFF.py", line 181, in <lambda>
    temp_df['SpecLow'] = temp_df['SpecLow'].apply(lambda x: x.str.rstrip('0').str.rstrip('.') if x.dtype == 'object' else x)
AttributeError: 'str' object has no attribute 'dtype'
Stack (most recent call last):
  File "D:/Ina/ETL_XdmLib_2.A.13/ETL_XdmLib_2.A.13/EDAETL/ETL_TABLE/ETL_LC_CP_TO_XSIFF/ETL_LC_CP_TO_XSIFF.py", line 397, in <module>
    do_file, before_do_file, after_do_file, skip_file, None, log, config, config_sql)
  File "../..\XdmLib\CustomFuction.py", line 597, in file2db_init
    file, pre_params, db_src, db_tgt)
  File "D:/Ina/ETL_XdmLib_2.A.13/ETL_XdmLib_2.A.13/EDAETL/ETL_TABLE/ETL_LC_CP_TO_XSIFF/ETL_LC_CP_TO_XSIFF.py", line 297, in do_file
    log.error(ex, exc_info=True, stack_info=True)
2023-12-22 10:55:13.399 - __init__   [ERROR   ] File:#24.csv Move To Error Folder
                                                Error: None
2023-12-22 10:55:52.751 - ETL_LC_CP_TO_XSIFF [ERROR   ] 'str' object has no attribute 'dtype'
Traceback (most recent call last):
  File "D:/Ina/ETL_XdmLib_2.A.13/ETL_XdmLib_2.A.13/EDAETL/ETL_TABLE/ETL_LC_CP_TO_XSIFF/ETL_LC_CP_TO_XSIFF.py", line 181, in do_file
    temp_df['SpecLow'] = temp_df['SpecLow'].apply(lambda x: x.str.rstrip('0').str.rstrip('.') if x.dtype == 'str' else x)
  File "D:\Python37\lib\site-packages\pandas\core\series.py", line 4213, in apply
    mapped = lib.map_infer(values, f, convert=convert_dtype)
  File "pandas\_libs\lib.pyx", line 2403, in pandas._libs.lib.map_infer
  File "D:/Ina/ETL_XdmLib_2.A.13/ETL_XdmLib_2.A.13/EDAETL/ETL_TABLE/ETL_LC_CP_TO_XSIFF/ETL_LC_CP_TO_XSIFF.py", line 181, in <lambda>
    temp_df['SpecLow'] = temp_df['SpecLow'].apply(lambda x: x.str.rstrip('0').str.rstrip('.') if x.dtype == 'str' else x)
AttributeError: 'str' object has no attribute 'dtype'
Stack (most recent call last):
  File "D:/Ina/ETL_XdmLib_2.A.13/ETL_XdmLib_2.A.13/EDAETL/ETL_TABLE/ETL_LC_CP_TO_XSIFF/ETL_LC_CP_TO_XSIFF.py", line 397, in <module>
    do_file, before_do_file, after_do_file, skip_file, None, log, config, config_sql)
  File "../..\XdmLib\CustomFuction.py", line 597, in file2db_init
    file, pre_params, db_src, db_tgt)
  File "D:/Ina/ETL_XdmLib_2.A.13/ETL_XdmLib_2.A.13/EDAETL/ETL_TABLE/ETL_LC_CP_TO_XSIFF/ETL_LC_CP_TO_XSIFF.py", line 297, in do_file
    log.error(ex, exc_info=True, stack_info=True)
2023-12-22 10:55:52.943 - __init__   [ERROR   ] File:#24.csv Move To Error Folder
                                                Error: None
