2024-01-30 17:03:31.909 - ETL_LC_CP_TO_XSIFF [ERROR   ] 'utf-8' codec can't decode byte 0xb2 in position 159: invalid start byte
Traceback (most recent call last):
  File "D:/Ina/ETL_XdmLib_2.A.13/ETL_XdmLib_2.A.13/EDAETL/ETL_TABLE/ETL_LC_CP_TO_XSIFF/ETL_LC_CP_TO_XSIFF.py", line 154, in do_file
    result = process_csv(file_path)
  File "D:/Ina/ETL_XdmLib_2.A.13/ETL_XdmLib_2.A.13/EDAETL/ETL_TABLE/ETL_LC_CP_TO_XSIFF/ETL_LC_CP_TO_XSIFF.py", line 112, in process_csv
    for row in csv_reader:
  File "D:\Python37\lib\codecs.py", line 322, in decode
    (result, consumed) = self._buffer_decode(data, self.errors, final)
UnicodeDecodeError: 'utf-8' codec can't decode byte 0xb2 in position 159: invalid start byte
Stack (most recent call last):
  File "D:/Ina/ETL_XdmLib_2.A.13/ETL_XdmLib_2.A.13/EDAETL/ETL_TABLE/ETL_LC_CP_TO_XSIFF/ETL_LC_CP_TO_XSIFF.py", line 409, in <module>
    do_file, before_do_file, after_do_file, skip_file, None, log, config, config_sql)
  File "../..\XdmLib\CustomFuction.py", line 597, in file2db_init
    file, pre_params, db_src, db_tgt)
  File "D:/Ina/ETL_XdmLib_2.A.13/ETL_XdmLib_2.A.13/EDAETL/ETL_TABLE/ETL_LC_CP_TO_XSIFF/ETL_LC_CP_TO_XSIFF.py", line 157, in do_file
    log.error(ex, exc_info=True, stack_info=True)
2024-01-30 17:03:32.085 - __init__   [ERROR   ] File:23GD0101_240120152703.csv Move To Error Folder
                                                Error: None
2024-01-30 17:03:32.095 - ETL_LC_CP_TO_XSIFF [ERROR   ] 'utf-8' codec can't decode byte 0xb2 in position 159: invalid start byte
Traceback (most recent call last):
  File "D:/Ina/ETL_XdmLib_2.A.13/ETL_XdmLib_2.A.13/EDAETL/ETL_TABLE/ETL_LC_CP_TO_XSIFF/ETL_LC_CP_TO_XSIFF.py", line 154, in do_file
    result = process_csv(file_path)
  File "D:/Ina/ETL_XdmLib_2.A.13/ETL_XdmLib_2.A.13/EDAETL/ETL_TABLE/ETL_LC_CP_TO_XSIFF/ETL_LC_CP_TO_XSIFF.py", line 112, in process_csv
    for row in csv_reader:
  File "D:\Python37\lib\codecs.py", line 322, in decode
    (result, consumed) = self._buffer_decode(data, self.errors, final)
UnicodeDecodeError: 'utf-8' codec can't decode byte 0xb2 in position 159: invalid start byte
Stack (most recent call last):
  File "D:/Ina/ETL_XdmLib_2.A.13/ETL_XdmLib_2.A.13/EDAETL/ETL_TABLE/ETL_LC_CP_TO_XSIFF/ETL_LC_CP_TO_XSIFF.py", line 409, in <module>
    do_file, before_do_file, after_do_file, skip_file, None, log, config, config_sql)
  File "../..\XdmLib\CustomFuction.py", line 597, in file2db_init
    file, pre_params, db_src, db_tgt)
  File "D:/Ina/ETL_XdmLib_2.A.13/ETL_XdmLib_2.A.13/EDAETL/ETL_TABLE/ETL_LC_CP_TO_XSIFF/ETL_LC_CP_TO_XSIFF.py", line 157, in do_file
    log.error(ex, exc_info=True, stack_info=True)
2024-01-30 17:03:32.288 - __init__   [ERROR   ] File:23GD0110_240120140549.csv Move To Error Folder
                                                Error: None
2024-01-30 17:03:32.310 - ETL_LC_CP_TO_XSIFF [ERROR   ] 'utf-8' codec can't decode byte 0xb2 in position 151: invalid start byte
Traceback (most recent call last):
  File "D:/Ina/ETL_XdmLib_2.A.13/ETL_XdmLib_2.A.13/EDAETL/ETL_TABLE/ETL_LC_CP_TO_XSIFF/ETL_LC_CP_TO_XSIFF.py", line 154, in do_file
    result = process_csv(file_path)
  File "D:/Ina/ETL_XdmLib_2.A.13/ETL_XdmLib_2.A.13/EDAETL/ETL_TABLE/ETL_LC_CP_TO_XSIFF/ETL_LC_CP_TO_XSIFF.py", line 112, in process_csv
    for row in csv_reader:
  File "D:\Python37\lib\codecs.py", line 322, in decode
    (result, consumed) = self._buffer_decode(data, self.errors, final)
UnicodeDecodeError: 'utf-8' codec can't decode byte 0xb2 in position 151: invalid start byte
Stack (most recent call last):
  File "D:/Ina/ETL_XdmLib_2.A.13/ETL_XdmLib_2.A.13/EDAETL/ETL_TABLE/ETL_LC_CP_TO_XSIFF/ETL_LC_CP_TO_XSIFF.py", line 409, in <module>
    do_file, before_do_file, after_do_file, skip_file, None, log, config, config_sql)
  File "../..\XdmLib\CustomFuction.py", line 597, in file2db_init
    file, pre_params, db_src, db_tgt)
  File "D:/Ina/ETL_XdmLib_2.A.13/ETL_XdmLib_2.A.13/EDAETL/ETL_TABLE/ETL_LC_CP_TO_XSIFF/ETL_LC_CP_TO_XSIFF.py", line 157, in do_file
    log.error(ex, exc_info=True, stack_info=True)
2024-01-30 17:03:32.507 - __init__   [ERROR   ] File:23GD0119_240120171105.csv Move To Error Folder
                                                Error: None
