2024-03-05 14:18:27.001 - ETL_LC_CP_TO_XSIFF [ERROR   ] name 'no_parameter' is not defined
Traceback (most recent call last):
  File "D:/Ina/ETL_XdmLib_2.A.13/ETL_XdmLib_2.A.13/EDAETL/ETL_TABLE/ETL_LC_CP_TO_XSIFF/ETL_LC_CP_TO_XSIFF.py", line 219, in do_file
    no_parameter[i-4] = parameter_value
NameError: name 'no_parameter' is not defined
Stack (most recent call last):
  File "D:\soft\PyCharm Community Edition 2022.1.3\plugins\python-ce\helpers\pydev\pydevd.py", line 2181, in <module>
    main()
  File "D:\soft\PyCharm Community Edition 2022.1.3\plugins\python-ce\helpers\pydev\pydevd.py", line 2172, in main
    globals = debugger.run(setup['file'], None, None, is_module)
  File "D:\soft\PyCharm Community Edition 2022.1.3\plugins\python-ce\helpers\pydev\pydevd.py", line 1484, in run
    return self._exec(is_module, entry_point_fn, module_name, file, globals, locals)
  File "D:\soft\PyCharm Community Edition 2022.1.3\plugins\python-ce\helpers\pydev\pydevd.py", line 1491, in _exec
    pydev_imports.execfile(file, globals, locals)  # execute the script
  File "D:\soft\PyCharm Community Edition 2022.1.3\plugins\python-ce\helpers\pydev\_pydev_imps\_pydev_execfile.py", line 18, in execfile
    exec(compile(contents+"\n", file, 'exec'), glob, loc)
  File "D:/Ina/ETL_XdmLib_2.A.13/ETL_XdmLib_2.A.13/EDAETL/ETL_TABLE/ETL_LC_CP_TO_XSIFF/ETL_LC_CP_TO_XSIFF.py", line 449, in <module>
    do_file, before_do_file, after_do_file, skip_file, None, log, config, config_sql)
  File "../..\XdmLib\CustomFuction.py", line 597, in file2db_init
    file, pre_params, db_src, db_tgt)
  File "D:/Ina/ETL_XdmLib_2.A.13/ETL_XdmLib_2.A.13/EDAETL/ETL_TABLE/ETL_LC_CP_TO_XSIFF/ETL_LC_CP_TO_XSIFF.py", line 349, in do_file
    log.error(ex, exc_info=True, stack_info=True)
2024-03-05 14:18:27.283 - __init__   [ERROR   ] File:23GD0103_240118161158.csv Move To Error Folder
                                                Error: None
2024-03-05 14:18:27.298 - CustomFuction [ERROR   ] Move File Error
2024-03-05 14:18:27.299 - CustomFuction [ERROR   ] './Data/Source\\23GD0103_240118161158.csv' and 'Data\\Source\\23GD0103_240118161158.csv' are the same file
Traceback (most recent call last):
  File "D:\Python37\lib\shutil.py", line 557, in move
    os.rename(src, real_dst)
PermissionError: [WinError 32] 另一个程序正在使用此文件，进程无法访问。: './Data/Source\\23GD0103_240118161158.csv' -> 'Data\\Source\\23GD0103_240118161158.csv'

During handling of the above exception, another exception occurred:

Traceback (most recent call last):
  File "../..\XdmLib\CustomFuction.py", line 1036, in move_file
    os.path.join(target_path, fileName))
  File "D:\Python37\lib\shutil.py", line 571, in move
    copy_function(src, real_dst)
  File "D:\Python37\lib\shutil.py", line 257, in copy2
    copyfile(src, dst, follow_symlinks=follow_symlinks)
  File "D:\Python37\lib\shutil.py", line 104, in copyfile
    raise SameFileError("{!r} and {!r} are the same file".format(src, dst))
shutil.SameFileError: './Data/Source\\23GD0103_240118161158.csv' and 'Data\\Source\\23GD0103_240118161158.csv' are the same file
Stack (most recent call last):
  File "D:\soft\PyCharm Community Edition 2022.1.3\plugins\python-ce\helpers\pydev\pydevd.py", line 2181, in <module>
    main()
  File "D:\soft\PyCharm Community Edition 2022.1.3\plugins\python-ce\helpers\pydev\pydevd.py", line 2172, in main
    globals = debugger.run(setup['file'], None, None, is_module)
  File "D:\soft\PyCharm Community Edition 2022.1.3\plugins\python-ce\helpers\pydev\pydevd.py", line 1484, in run
    return self._exec(is_module, entry_point_fn, module_name, file, globals, locals)
  File "D:\soft\PyCharm Community Edition 2022.1.3\plugins\python-ce\helpers\pydev\pydevd.py", line 1491, in _exec
    pydev_imports.execfile(file, globals, locals)  # execute the script
  File "D:\soft\PyCharm Community Edition 2022.1.3\plugins\python-ce\helpers\pydev\_pydev_imps\_pydev_execfile.py", line 18, in execfile
    exec(compile(contents+"\n", file, 'exec'), glob, loc)
  File "D:/Ina/ETL_XdmLib_2.A.13/ETL_XdmLib_2.A.13/EDAETL/ETL_TABLE/ETL_LC_CP_TO_XSIFF/ETL_LC_CP_TO_XSIFF.py", line 449, in <module>
    do_file, before_do_file, after_do_file, skip_file, None, log, config, config_sql)
  File "../..\XdmLib\CustomFuction.py", line 629, in file2db_init
    move_file_self(move_file_info)
  File "../..\XdmLib\CustomFuction.py", line 1044, in move_file
    log.error(ex, exc_info=True, stack_info=True)
2024-03-05 14:18:27.329 - ETL_LC_CP_TO_XSIFF [ERROR   ] name 'no_parameter' is not defined
Traceback (most recent call last):
  File "D:/Ina/ETL_XdmLib_2.A.13/ETL_XdmLib_2.A.13/EDAETL/ETL_TABLE/ETL_LC_CP_TO_XSIFF/ETL_LC_CP_TO_XSIFF.py", line 219, in do_file
    no_parameter[i-4] = parameter_value
NameError: name 'no_parameter' is not defined
Stack (most recent call last):
  File "D:\soft\PyCharm Community Edition 2022.1.3\plugins\python-ce\helpers\pydev\pydevd.py", line 2181, in <module>
    main()
  File "D:\soft\PyCharm Community Edition 2022.1.3\plugins\python-ce\helpers\pydev\pydevd.py", line 2172, in main
    globals = debugger.run(setup['file'], None, None, is_module)
  File "D:\soft\PyCharm Community Edition 2022.1.3\plugins\python-ce\helpers\pydev\pydevd.py", line 1484, in run
    return self._exec(is_module, entry_point_fn, module_name, file, globals, locals)
  File "D:\soft\PyCharm Community Edition 2022.1.3\plugins\python-ce\helpers\pydev\pydevd.py", line 1491, in _exec
    pydev_imports.execfile(file, globals, locals)  # execute the script
  File "D:\soft\PyCharm Community Edition 2022.1.3\plugins\python-ce\helpers\pydev\_pydev_imps\_pydev_execfile.py", line 18, in execfile
    exec(compile(contents+"\n", file, 'exec'), glob, loc)
  File "D:/Ina/ETL_XdmLib_2.A.13/ETL_XdmLib_2.A.13/EDAETL/ETL_TABLE/ETL_LC_CP_TO_XSIFF/ETL_LC_CP_TO_XSIFF.py", line 449, in <module>
    do_file, before_do_file, after_do_file, skip_file, None, log, config, config_sql)
  File "../..\XdmLib\CustomFuction.py", line 597, in file2db_init
    file, pre_params, db_src, db_tgt)
  File "D:/Ina/ETL_XdmLib_2.A.13/ETL_XdmLib_2.A.13/EDAETL/ETL_TABLE/ETL_LC_CP_TO_XSIFF/ETL_LC_CP_TO_XSIFF.py", line 349, in do_file
    log.error(ex, exc_info=True, stack_info=True)
2024-03-05 14:18:27.648 - __init__   [ERROR   ] File:23GD0141_240218152432.csv Move To Error Folder
                                                Error: None
2024-03-05 14:18:48.591 - ETL_LC_CP_TO_XSIFF [ERROR   ] name 'i' is not defined
Traceback (most recent call last):
  File "D:/Ina/ETL_XdmLib_2.A.13/ETL_XdmLib_2.A.13/EDAETL/ETL_TABLE/ETL_LC_CP_TO_XSIFF/ETL_LC_CP_TO_XSIFF.py", line 219, in do_file
    no_parameter[i-4] = parameter_value
NameError: name 'i' is not defined
Stack (most recent call last):
  File "D:\soft\PyCharm Community Edition 2022.1.3\plugins\python-ce\helpers\pydev\pydevd.py", line 2181, in <module>
    main()
  File "D:\soft\PyCharm Community Edition 2022.1.3\plugins\python-ce\helpers\pydev\pydevd.py", line 2172, in main
    globals = debugger.run(setup['file'], None, None, is_module)
  File "D:\soft\PyCharm Community Edition 2022.1.3\plugins\python-ce\helpers\pydev\pydevd.py", line 1484, in run
    return self._exec(is_module, entry_point_fn, module_name, file, globals, locals)
  File "D:\soft\PyCharm Community Edition 2022.1.3\plugins\python-ce\helpers\pydev\pydevd.py", line 1491, in _exec
    pydev_imports.execfile(file, globals, locals)  # execute the script
  File "D:\soft\PyCharm Community Edition 2022.1.3\plugins\python-ce\helpers\pydev\_pydev_imps\_pydev_execfile.py", line 18, in execfile
    exec(compile(contents+"\n", file, 'exec'), glob, loc)
  File "D:/Ina/ETL_XdmLib_2.A.13/ETL_XdmLib_2.A.13/EDAETL/ETL_TABLE/ETL_LC_CP_TO_XSIFF/ETL_LC_CP_TO_XSIFF.py", line 449, in <module>
    do_file, before_do_file, after_do_file, skip_file, None, log, config, config_sql)
  File "../..\XdmLib\CustomFuction.py", line 597, in file2db_init
    file, pre_params, db_src, db_tgt)
  File "D:/Ina/ETL_XdmLib_2.A.13/ETL_XdmLib_2.A.13/EDAETL/ETL_TABLE/ETL_LC_CP_TO_XSIFF/ETL_LC_CP_TO_XSIFF.py", line 349, in do_file
    log.error(ex, exc_info=True, stack_info=True)
2024-03-05 14:18:48.916 - __init__   [ERROR   ] File:23GD0103_240118161158.csv Move To Error Folder
                                                Error: None
2024-03-05 14:18:48.954 - CustomFuction [ERROR   ] Move File Error
2024-03-05 14:18:48.958 - CustomFuction [ERROR   ] './Data/Source\\23GD0103_240118161158.csv' and 'Data\\Source\\23GD0103_240118161158.csv' are the same file
Traceback (most recent call last):
  File "D:\Python37\lib\shutil.py", line 557, in move
    os.rename(src, real_dst)
PermissionError: [WinError 32] 另一个程序正在使用此文件，进程无法访问。: './Data/Source\\23GD0103_240118161158.csv' -> 'Data\\Source\\23GD0103_240118161158.csv'

During handling of the above exception, another exception occurred:

Traceback (most recent call last):
  File "../..\XdmLib\CustomFuction.py", line 1036, in move_file
    os.path.join(target_path, fileName))
  File "D:\Python37\lib\shutil.py", line 571, in move
    copy_function(src, real_dst)
  File "D:\Python37\lib\shutil.py", line 257, in copy2
    copyfile(src, dst, follow_symlinks=follow_symlinks)
  File "D:\Python37\lib\shutil.py", line 104, in copyfile
    raise SameFileError("{!r} and {!r} are the same file".format(src, dst))
shutil.SameFileError: './Data/Source\\23GD0103_240118161158.csv' and 'Data\\Source\\23GD0103_240118161158.csv' are the same file
Stack (most recent call last):
  File "D:\soft\PyCharm Community Edition 2022.1.3\plugins\python-ce\helpers\pydev\pydevd.py", line 2181, in <module>
    main()
  File "D:\soft\PyCharm Community Edition 2022.1.3\plugins\python-ce\helpers\pydev\pydevd.py", line 2172, in main
    globals = debugger.run(setup['file'], None, None, is_module)
  File "D:\soft\PyCharm Community Edition 2022.1.3\plugins\python-ce\helpers\pydev\pydevd.py", line 1484, in run
    return self._exec(is_module, entry_point_fn, module_name, file, globals, locals)
  File "D:\soft\PyCharm Community Edition 2022.1.3\plugins\python-ce\helpers\pydev\pydevd.py", line 1491, in _exec
    pydev_imports.execfile(file, globals, locals)  # execute the script
  File "D:\soft\PyCharm Community Edition 2022.1.3\plugins\python-ce\helpers\pydev\_pydev_imps\_pydev_execfile.py", line 18, in execfile
    exec(compile(contents+"\n", file, 'exec'), glob, loc)
  File "D:/Ina/ETL_XdmLib_2.A.13/ETL_XdmLib_2.A.13/EDAETL/ETL_TABLE/ETL_LC_CP_TO_XSIFF/ETL_LC_CP_TO_XSIFF.py", line 449, in <module>
    do_file, before_do_file, after_do_file, skip_file, None, log, config, config_sql)
  File "../..\XdmLib\CustomFuction.py", line 629, in file2db_init
    move_file_self(move_file_info)
  File "../..\XdmLib\CustomFuction.py", line 1044, in move_file
    log.error(ex, exc_info=True, stack_info=True)
2024-03-05 14:18:49.052 - ETL_LC_CP_TO_XSIFF [ERROR   ] name 'i' is not defined
Traceback (most recent call last):
  File "D:/Ina/ETL_XdmLib_2.A.13/ETL_XdmLib_2.A.13/EDAETL/ETL_TABLE/ETL_LC_CP_TO_XSIFF/ETL_LC_CP_TO_XSIFF.py", line 219, in do_file
    no_parameter[i-4] = parameter_value
NameError: name 'i' is not defined
Stack (most recent call last):
  File "D:\soft\PyCharm Community Edition 2022.1.3\plugins\python-ce\helpers\pydev\pydevd.py", line 2181, in <module>
    main()
  File "D:\soft\PyCharm Community Edition 2022.1.3\plugins\python-ce\helpers\pydev\pydevd.py", line 2172, in main
    globals = debugger.run(setup['file'], None, None, is_module)
  File "D:\soft\PyCharm Community Edition 2022.1.3\plugins\python-ce\helpers\pydev\pydevd.py", line 1484, in run
    return self._exec(is_module, entry_point_fn, module_name, file, globals, locals)
  File "D:\soft\PyCharm Community Edition 2022.1.3\plugins\python-ce\helpers\pydev\pydevd.py", line 1491, in _exec
    pydev_imports.execfile(file, globals, locals)  # execute the script
  File "D:\soft\PyCharm Community Edition 2022.1.3\plugins\python-ce\helpers\pydev\_pydev_imps\_pydev_execfile.py", line 18, in execfile
    exec(compile(contents+"\n", file, 'exec'), glob, loc)
  File "D:/Ina/ETL_XdmLib_2.A.13/ETL_XdmLib_2.A.13/EDAETL/ETL_TABLE/ETL_LC_CP_TO_XSIFF/ETL_LC_CP_TO_XSIFF.py", line 449, in <module>
    do_file, before_do_file, after_do_file, skip_file, None, log, config, config_sql)
  File "../..\XdmLib\CustomFuction.py", line 597, in file2db_init
    file, pre_params, db_src, db_tgt)
  File "D:/Ina/ETL_XdmLib_2.A.13/ETL_XdmLib_2.A.13/EDAETL/ETL_TABLE/ETL_LC_CP_TO_XSIFF/ETL_LC_CP_TO_XSIFF.py", line 349, in do_file
    log.error(ex, exc_info=True, stack_info=True)
2024-03-05 14:18:49.312 - __init__   [ERROR   ] File:23GD0141_240218152432.csv Move To Error Folder
                                                Error: None
2024-03-05 14:19:31.534 - ETL_LC_CP_TO_XSIFF [ERROR   ] name 'block' is not defined
Traceback (most recent call last):
  File "D:/Ina/ETL_XdmLib_2.A.13/ETL_XdmLib_2.A.13/EDAETL/ETL_TABLE/ETL_LC_CP_TO_XSIFF/ETL_LC_CP_TO_XSIFF.py", line 215, in do_file
    key_value = f"{block.BiasList[idx][0]}={value}"
NameError: name 'block' is not defined
Stack (most recent call last):
  File "D:\soft\PyCharm Community Edition 2022.1.3\plugins\python-ce\helpers\pydev\pydevd.py", line 2181, in <module>
    main()
  File "D:\soft\PyCharm Community Edition 2022.1.3\plugins\python-ce\helpers\pydev\pydevd.py", line 2172, in main
    globals = debugger.run(setup['file'], None, None, is_module)
  File "D:\soft\PyCharm Community Edition 2022.1.3\plugins\python-ce\helpers\pydev\pydevd.py", line 1484, in run
    return self._exec(is_module, entry_point_fn, module_name, file, globals, locals)
  File "D:\soft\PyCharm Community Edition 2022.1.3\plugins\python-ce\helpers\pydev\pydevd.py", line 1491, in _exec
    pydev_imports.execfile(file, globals, locals)  # execute the script
  File "D:\soft\PyCharm Community Edition 2022.1.3\plugins\python-ce\helpers\pydev\_pydev_imps\_pydev_execfile.py", line 18, in execfile
    exec(compile(contents+"\n", file, 'exec'), glob, loc)
  File "D:/Ina/ETL_XdmLib_2.A.13/ETL_XdmLib_2.A.13/EDAETL/ETL_TABLE/ETL_LC_CP_TO_XSIFF/ETL_LC_CP_TO_XSIFF.py", line 449, in <module>
    do_file, before_do_file, after_do_file, skip_file, None, log, config, config_sql)
  File "../..\XdmLib\CustomFuction.py", line 597, in file2db_init
    file, pre_params, db_src, db_tgt)
  File "D:/Ina/ETL_XdmLib_2.A.13/ETL_XdmLib_2.A.13/EDAETL/ETL_TABLE/ETL_LC_CP_TO_XSIFF/ETL_LC_CP_TO_XSIFF.py", line 349, in do_file
    log.error(ex, exc_info=True, stack_info=True)
2024-03-05 14:19:31.761 - __init__   [ERROR   ] File:23GD0103_240118161158.csv Move To Error Folder
                                                Error: None
2024-03-05 14:19:31.774 - CustomFuction [ERROR   ] Move File Error
2024-03-05 14:19:31.774 - CustomFuction [ERROR   ] './Data/Source\\23GD0103_240118161158.csv' and 'Data\\Source\\23GD0103_240118161158.csv' are the same file
Traceback (most recent call last):
  File "D:\Python37\lib\shutil.py", line 557, in move
    os.rename(src, real_dst)
PermissionError: [WinError 32] 另一个程序正在使用此文件，进程无法访问。: './Data/Source\\23GD0103_240118161158.csv' -> 'Data\\Source\\23GD0103_240118161158.csv'

During handling of the above exception, another exception occurred:

Traceback (most recent call last):
  File "../..\XdmLib\CustomFuction.py", line 1036, in move_file
    os.path.join(target_path, fileName))
  File "D:\Python37\lib\shutil.py", line 571, in move
    copy_function(src, real_dst)
  File "D:\Python37\lib\shutil.py", line 257, in copy2
    copyfile(src, dst, follow_symlinks=follow_symlinks)
  File "D:\Python37\lib\shutil.py", line 104, in copyfile
    raise SameFileError("{!r} and {!r} are the same file".format(src, dst))
shutil.SameFileError: './Data/Source\\23GD0103_240118161158.csv' and 'Data\\Source\\23GD0103_240118161158.csv' are the same file
Stack (most recent call last):
  File "D:\soft\PyCharm Community Edition 2022.1.3\plugins\python-ce\helpers\pydev\pydevd.py", line 2181, in <module>
    main()
  File "D:\soft\PyCharm Community Edition 2022.1.3\plugins\python-ce\helpers\pydev\pydevd.py", line 2172, in main
    globals = debugger.run(setup['file'], None, None, is_module)
  File "D:\soft\PyCharm Community Edition 2022.1.3\plugins\python-ce\helpers\pydev\pydevd.py", line 1484, in run
    return self._exec(is_module, entry_point_fn, module_name, file, globals, locals)
  File "D:\soft\PyCharm Community Edition 2022.1.3\plugins\python-ce\helpers\pydev\pydevd.py", line 1491, in _exec
    pydev_imports.execfile(file, globals, locals)  # execute the script
  File "D:\soft\PyCharm Community Edition 2022.1.3\plugins\python-ce\helpers\pydev\_pydev_imps\_pydev_execfile.py", line 18, in execfile
    exec(compile(contents+"\n", file, 'exec'), glob, loc)
  File "D:/Ina/ETL_XdmLib_2.A.13/ETL_XdmLib_2.A.13/EDAETL/ETL_TABLE/ETL_LC_CP_TO_XSIFF/ETL_LC_CP_TO_XSIFF.py", line 449, in <module>
    do_file, before_do_file, after_do_file, skip_file, None, log, config, config_sql)
  File "../..\XdmLib\CustomFuction.py", line 629, in file2db_init
    move_file_self(move_file_info)
  File "../..\XdmLib\CustomFuction.py", line 1044, in move_file
    log.error(ex, exc_info=True, stack_info=True)
2024-03-05 14:19:31.805 - ETL_LC_CP_TO_XSIFF [ERROR   ] name 'block' is not defined
Traceback (most recent call last):
  File "D:/Ina/ETL_XdmLib_2.A.13/ETL_XdmLib_2.A.13/EDAETL/ETL_TABLE/ETL_LC_CP_TO_XSIFF/ETL_LC_CP_TO_XSIFF.py", line 215, in do_file
    key_value = f"{block.BiasList[idx][0]}={value}"
NameError: name 'block' is not defined
Stack (most recent call last):
  File "D:\soft\PyCharm Community Edition 2022.1.3\plugins\python-ce\helpers\pydev\pydevd.py", line 2181, in <module>
    main()
  File "D:\soft\PyCharm Community Edition 2022.1.3\plugins\python-ce\helpers\pydev\pydevd.py", line 2172, in main
    globals = debugger.run(setup['file'], None, None, is_module)
  File "D:\soft\PyCharm Community Edition 2022.1.3\plugins\python-ce\helpers\pydev\pydevd.py", line 1484, in run
    return self._exec(is_module, entry_point_fn, module_name, file, globals, locals)
  File "D:\soft\PyCharm Community Edition 2022.1.3\plugins\python-ce\helpers\pydev\pydevd.py", line 1491, in _exec
    pydev_imports.execfile(file, globals, locals)  # execute the script
  File "D:\soft\PyCharm Community Edition 2022.1.3\plugins\python-ce\helpers\pydev\_pydev_imps\_pydev_execfile.py", line 18, in execfile
    exec(compile(contents+"\n", file, 'exec'), glob, loc)
  File "D:/Ina/ETL_XdmLib_2.A.13/ETL_XdmLib_2.A.13/EDAETL/ETL_TABLE/ETL_LC_CP_TO_XSIFF/ETL_LC_CP_TO_XSIFF.py", line 449, in <module>
    do_file, before_do_file, after_do_file, skip_file, None, log, config, config_sql)
  File "../..\XdmLib\CustomFuction.py", line 597, in file2db_init
    file, pre_params, db_src, db_tgt)
  File "D:/Ina/ETL_XdmLib_2.A.13/ETL_XdmLib_2.A.13/EDAETL/ETL_TABLE/ETL_LC_CP_TO_XSIFF/ETL_LC_CP_TO_XSIFF.py", line 349, in do_file
    log.error(ex, exc_info=True, stack_info=True)
2024-03-05 14:19:32.066 - __init__   [ERROR   ] File:23GD0141_240218152432.csv Move To Error Folder
                                                Error: None
2024-03-05 14:38:27.515 - CustomFuction [ERROR   ] Move File Error
2024-03-05 14:38:27.518 - CustomFuction [ERROR   ] './Data/Source\\23GD0103_240118161158.csv' and 'Data\\Source\\23GD0103_240118161158.csv' are the same file
Traceback (most recent call last):
  File "D:\Python37\lib\shutil.py", line 557, in move
    os.rename(src, real_dst)
PermissionError: [WinError 32] 另一个程序正在使用此文件，进程无法访问。: './Data/Source\\23GD0103_240118161158.csv' -> 'Data\\Source\\23GD0103_240118161158.csv'

During handling of the above exception, another exception occurred:

Traceback (most recent call last):
  File "../..\XdmLib\CustomFuction.py", line 1036, in move_file
    os.path.join(target_path, fileName))
  File "D:\Python37\lib\shutil.py", line 571, in move
    copy_function(src, real_dst)
  File "D:\Python37\lib\shutil.py", line 257, in copy2
    copyfile(src, dst, follow_symlinks=follow_symlinks)
  File "D:\Python37\lib\shutil.py", line 104, in copyfile
    raise SameFileError("{!r} and {!r} are the same file".format(src, dst))
shutil.SameFileError: './Data/Source\\23GD0103_240118161158.csv' and 'Data\\Source\\23GD0103_240118161158.csv' are the same file
Stack (most recent call last):
  File "D:/Ina/ETL_XdmLib_2.A.13/ETL_XdmLib_2.A.13/EDAETL/ETL_TABLE/ETL_LC_CP_TO_XSIFF/ETL_LC_CP_TO_XSIFF.py", line 453, in <module>
    do_file, before_do_file, after_do_file, skip_file, None, log, config, config_sql)
  File "../..\XdmLib\CustomFuction.py", line 629, in file2db_init
    move_file_self(move_file_info)
  File "../..\XdmLib\CustomFuction.py", line 1044, in move_file
    log.error(ex, exc_info=True, stack_info=True)
2024-03-05 15:24:43.277 - ETL_LC_CP_TO_XSIFF [ERROR   ] operands could not be broadcast together with shapes (3,) (34,) 
Traceback (most recent call last):
  File "D:/Ina/ETL_XdmLib_2.A.13/ETL_XdmLib_2.A.13/EDAETL/ETL_TABLE/ETL_LC_CP_TO_XSIFF/ETL_LC_CP_TO_XSIFF.py", line 281, in do_file
    data_df.columns = first_three_columns + rest_of_columns
  File "D:\Python37\lib\site-packages\pandas\core\ops\common.py", line 65, in new_method
    return method(self, other)
  File "D:\Python37\lib\site-packages\pandas\core\ops\__init__.py", line 343, in wrapper
    result = arithmetic_op(lvalues, rvalues, op)
  File "D:\Python37\lib\site-packages\pandas\core\ops\array_ops.py", line 190, in arithmetic_op
    res_values = na_arithmetic_op(lvalues, rvalues, op)
  File "D:\Python37\lib\site-packages\pandas\core\ops\array_ops.py", line 143, in na_arithmetic_op
    result = expressions.evaluate(op, left, right)
  File "D:\Python37\lib\site-packages\pandas\core\computation\expressions.py", line 233, in evaluate
    return _evaluate(op, op_str, a, b)  # type: ignore
  File "D:\Python37\lib\site-packages\pandas\core\computation\expressions.py", line 68, in _evaluate_standard
    return op(a, b)
  File "D:\Python37\lib\site-packages\pandas\core\ops\roperator.py", line 9, in radd
    return right + left
ValueError: operands could not be broadcast together with shapes (3,) (34,) 
Stack (most recent call last):
  File "D:/Ina/ETL_XdmLib_2.A.13/ETL_XdmLib_2.A.13/EDAETL/ETL_TABLE/ETL_LC_CP_TO_XSIFF/ETL_LC_CP_TO_XSIFF.py", line 454, in <module>
    do_file, before_do_file, after_do_file, skip_file, None, log, config, config_sql)
  File "../..\XdmLib\CustomFuction.py", line 597, in file2db_init
    file, pre_params, db_src, db_tgt)
  File "D:/Ina/ETL_XdmLib_2.A.13/ETL_XdmLib_2.A.13/EDAETL/ETL_TABLE/ETL_LC_CP_TO_XSIFF/ETL_LC_CP_TO_XSIFF.py", line 354, in do_file
    log.error(ex, exc_info=True, stack_info=True)
2024-03-05 15:24:43.538 - __init__   [ERROR   ] File:23GD0103_240118161158.csv Move To Error Folder
                                                Error: None
2024-03-05 15:24:43.964 - ETL_LC_CP_TO_XSIFF [ERROR   ] operands could not be broadcast together with shapes (3,) (34,) 
Traceback (most recent call last):
  File "D:/Ina/ETL_XdmLib_2.A.13/ETL_XdmLib_2.A.13/EDAETL/ETL_TABLE/ETL_LC_CP_TO_XSIFF/ETL_LC_CP_TO_XSIFF.py", line 281, in do_file
    data_df.columns = first_three_columns + rest_of_columns
  File "D:\Python37\lib\site-packages\pandas\core\ops\common.py", line 65, in new_method
    return method(self, other)
  File "D:\Python37\lib\site-packages\pandas\core\ops\__init__.py", line 343, in wrapper
    result = arithmetic_op(lvalues, rvalues, op)
  File "D:\Python37\lib\site-packages\pandas\core\ops\array_ops.py", line 190, in arithmetic_op
    res_values = na_arithmetic_op(lvalues, rvalues, op)
  File "D:\Python37\lib\site-packages\pandas\core\ops\array_ops.py", line 143, in na_arithmetic_op
    result = expressions.evaluate(op, left, right)
  File "D:\Python37\lib\site-packages\pandas\core\computation\expressions.py", line 233, in evaluate
    return _evaluate(op, op_str, a, b)  # type: ignore
  File "D:\Python37\lib\site-packages\pandas\core\computation\expressions.py", line 68, in _evaluate_standard
    return op(a, b)
  File "D:\Python37\lib\site-packages\pandas\core\ops\roperator.py", line 9, in radd
    return right + left
ValueError: operands could not be broadcast together with shapes (3,) (34,) 
Stack (most recent call last):
  File "D:/Ina/ETL_XdmLib_2.A.13/ETL_XdmLib_2.A.13/EDAETL/ETL_TABLE/ETL_LC_CP_TO_XSIFF/ETL_LC_CP_TO_XSIFF.py", line 454, in <module>
    do_file, before_do_file, after_do_file, skip_file, None, log, config, config_sql)
  File "../..\XdmLib\CustomFuction.py", line 597, in file2db_init
    file, pre_params, db_src, db_tgt)
  File "D:/Ina/ETL_XdmLib_2.A.13/ETL_XdmLib_2.A.13/EDAETL/ETL_TABLE/ETL_LC_CP_TO_XSIFF/ETL_LC_CP_TO_XSIFF.py", line 354, in do_file
    log.error(ex, exc_info=True, stack_info=True)
2024-03-05 15:24:44.238 - __init__   [ERROR   ] File:23GD0141_240218152432.csv Move To Error Folder
                                                Error: None
2024-03-05 15:25:58.613 - ETL_LC_CP_TO_XSIFF [ERROR   ] operands could not be broadcast together with shapes (3,) (34,) 
Traceback (most recent call last):
  File "D:/Ina/ETL_XdmLib_2.A.13/ETL_XdmLib_2.A.13/EDAETL/ETL_TABLE/ETL_LC_CP_TO_XSIFF/ETL_LC_CP_TO_XSIFF.py", line 281, in do_file
    data_df.columns = first_three_columns + rest_of_columns
  File "D:\Python37\lib\site-packages\pandas\core\ops\common.py", line 65, in new_method
    return method(self, other)
  File "D:\Python37\lib\site-packages\pandas\core\ops\__init__.py", line 343, in wrapper
    result = arithmetic_op(lvalues, rvalues, op)
  File "D:\Python37\lib\site-packages\pandas\core\ops\array_ops.py", line 190, in arithmetic_op
    res_values = na_arithmetic_op(lvalues, rvalues, op)
  File "D:\Python37\lib\site-packages\pandas\core\ops\array_ops.py", line 143, in na_arithmetic_op
    result = expressions.evaluate(op, left, right)
  File "D:\Python37\lib\site-packages\pandas\core\computation\expressions.py", line 233, in evaluate
    return _evaluate(op, op_str, a, b)  # type: ignore
  File "D:\Python37\lib\site-packages\pandas\core\computation\expressions.py", line 68, in _evaluate_standard
    return op(a, b)
  File "D:\Python37\lib\site-packages\pandas\core\ops\roperator.py", line 9, in radd
    return right + left
ValueError: operands could not be broadcast together with shapes (3,) (34,) 
Stack (most recent call last):
  File "D:/Ina/ETL_XdmLib_2.A.13/ETL_XdmLib_2.A.13/EDAETL/ETL_TABLE/ETL_LC_CP_TO_XSIFF/ETL_LC_CP_TO_XSIFF.py", line 454, in <module>
    do_file, before_do_file, after_do_file, skip_file, None, log, config, config_sql)
  File "../..\XdmLib\CustomFuction.py", line 597, in file2db_init
    file, pre_params, db_src, db_tgt)
  File "D:/Ina/ETL_XdmLib_2.A.13/ETL_XdmLib_2.A.13/EDAETL/ETL_TABLE/ETL_LC_CP_TO_XSIFF/ETL_LC_CP_TO_XSIFF.py", line 354, in do_file
    log.error(ex, exc_info=True, stack_info=True)
2024-03-05 15:25:58.753 - __init__   [ERROR   ] File:23GD0103_240118161158.csv Move To Error Folder
                                                Error: None
2024-03-05 15:25:59.177 - ETL_LC_CP_TO_XSIFF [ERROR   ] operands could not be broadcast together with shapes (3,) (34,) 
Traceback (most recent call last):
  File "D:/Ina/ETL_XdmLib_2.A.13/ETL_XdmLib_2.A.13/EDAETL/ETL_TABLE/ETL_LC_CP_TO_XSIFF/ETL_LC_CP_TO_XSIFF.py", line 281, in do_file
    data_df.columns = first_three_columns + rest_of_columns
  File "D:\Python37\lib\site-packages\pandas\core\ops\common.py", line 65, in new_method
    return method(self, other)
  File "D:\Python37\lib\site-packages\pandas\core\ops\__init__.py", line 343, in wrapper
    result = arithmetic_op(lvalues, rvalues, op)
  File "D:\Python37\lib\site-packages\pandas\core\ops\array_ops.py", line 190, in arithmetic_op
    res_values = na_arithmetic_op(lvalues, rvalues, op)
  File "D:\Python37\lib\site-packages\pandas\core\ops\array_ops.py", line 143, in na_arithmetic_op
    result = expressions.evaluate(op, left, right)
  File "D:\Python37\lib\site-packages\pandas\core\computation\expressions.py", line 233, in evaluate
    return _evaluate(op, op_str, a, b)  # type: ignore
  File "D:\Python37\lib\site-packages\pandas\core\computation\expressions.py", line 68, in _evaluate_standard
    return op(a, b)
  File "D:\Python37\lib\site-packages\pandas\core\ops\roperator.py", line 9, in radd
    return right + left
ValueError: operands could not be broadcast together with shapes (3,) (34,) 
Stack (most recent call last):
  File "D:/Ina/ETL_XdmLib_2.A.13/ETL_XdmLib_2.A.13/EDAETL/ETL_TABLE/ETL_LC_CP_TO_XSIFF/ETL_LC_CP_TO_XSIFF.py", line 454, in <module>
    do_file, before_do_file, after_do_file, skip_file, None, log, config, config_sql)
  File "../..\XdmLib\CustomFuction.py", line 597, in file2db_init
    file, pre_params, db_src, db_tgt)
  File "D:/Ina/ETL_XdmLib_2.A.13/ETL_XdmLib_2.A.13/EDAETL/ETL_TABLE/ETL_LC_CP_TO_XSIFF/ETL_LC_CP_TO_XSIFF.py", line 354, in do_file
    log.error(ex, exc_info=True, stack_info=True)
2024-03-05 15:25:59.314 - __init__   [ERROR   ] File:23GD0141_240218152432.csv Move To Error Folder
                                                Error: None
2024-03-05 16:07:18.487 - ETL_LC_CP_TO_XSIFF [ERROR   ] Length mismatch: Expected axis has 37 elements, new values have 3 elements
Traceback (most recent call last):
  File "D:/Ina/ETL_XdmLib_2.A.13/ETL_XdmLib_2.A.13/EDAETL/ETL_TABLE/ETL_LC_CP_TO_XSIFF/ETL_LC_CP_TO_XSIFF.py", line 268, in do_file
    data_df.columns = ['HBIN', 'DieX', 'DieY'] + no_parameter_df['ParameterName'].tolist()
  File "D:\Python37\lib\site-packages\pandas\core\generic.py", line 5154, in __setattr__
    return object.__setattr__(self, name, value)
  File "pandas\_libs\properties.pyx", line 66, in pandas._libs.properties.AxisProperty.__set__
  File "D:\Python37\lib\site-packages\pandas\core\generic.py", line 564, in _set_axis
    self._mgr.set_axis(axis, labels)
  File "D:\Python37\lib\site-packages\pandas\core\internals\managers.py", line 227, in set_axis
    f"Length mismatch: Expected axis has {old_len} elements, new "
ValueError: Length mismatch: Expected axis has 37 elements, new values have 3 elements
Stack (most recent call last):
  File "D:/Ina/ETL_XdmLib_2.A.13/ETL_XdmLib_2.A.13/EDAETL/ETL_TABLE/ETL_LC_CP_TO_XSIFF/ETL_LC_CP_TO_XSIFF.py", line 439, in <module>
    do_file, before_do_file, after_do_file, skip_file, None, log, config, config_sql)
  File "../..\XdmLib\CustomFuction.py", line 597, in file2db_init
    file, pre_params, db_src, db_tgt)
  File "D:/Ina/ETL_XdmLib_2.A.13/ETL_XdmLib_2.A.13/EDAETL/ETL_TABLE/ETL_LC_CP_TO_XSIFF/ETL_LC_CP_TO_XSIFF.py", line 339, in do_file
    log.error(ex, exc_info=True, stack_info=True)
2024-03-05 16:07:18.684 - __init__   [ERROR   ] File:23GD0103_240118161158.csv Move To Error Folder
                                                Error: None
2024-03-05 16:07:19.067 - ETL_LC_CP_TO_XSIFF [ERROR   ] Length mismatch: Expected axis has 37 elements, new values have 3 elements
Traceback (most recent call last):
  File "D:/Ina/ETL_XdmLib_2.A.13/ETL_XdmLib_2.A.13/EDAETL/ETL_TABLE/ETL_LC_CP_TO_XSIFF/ETL_LC_CP_TO_XSIFF.py", line 268, in do_file
    data_df.columns = ['HBIN', 'DieX', 'DieY'] + no_parameter_df['ParameterName'].tolist()
  File "D:\Python37\lib\site-packages\pandas\core\generic.py", line 5154, in __setattr__
    return object.__setattr__(self, name, value)
  File "pandas\_libs\properties.pyx", line 66, in pandas._libs.properties.AxisProperty.__set__
  File "D:\Python37\lib\site-packages\pandas\core\generic.py", line 564, in _set_axis
    self._mgr.set_axis(axis, labels)
  File "D:\Python37\lib\site-packages\pandas\core\internals\managers.py", line 227, in set_axis
    f"Length mismatch: Expected axis has {old_len} elements, new "
ValueError: Length mismatch: Expected axis has 37 elements, new values have 3 elements
Stack (most recent call last):
  File "D:/Ina/ETL_XdmLib_2.A.13/ETL_XdmLib_2.A.13/EDAETL/ETL_TABLE/ETL_LC_CP_TO_XSIFF/ETL_LC_CP_TO_XSIFF.py", line 439, in <module>
    do_file, before_do_file, after_do_file, skip_file, None, log, config, config_sql)
  File "../..\XdmLib\CustomFuction.py", line 597, in file2db_init
    file, pre_params, db_src, db_tgt)
  File "D:/Ina/ETL_XdmLib_2.A.13/ETL_XdmLib_2.A.13/EDAETL/ETL_TABLE/ETL_LC_CP_TO_XSIFF/ETL_LC_CP_TO_XSIFF.py", line 339, in do_file
    log.error(ex, exc_info=True, stack_info=True)
2024-03-05 16:07:19.338 - __init__   [ERROR   ] File:23GD0141_240218152432.csv Move To Error Folder
                                                Error: None
