2023-12-26 16:45:42.201 - base       [ERROR   ] Exception during reset or similar
Traceback (most recent call last):
  File "../..\XdmLib\CustomFuction.py", line 597, in file2db_init
    file, pre_params, db_src, db_tgt)
  File "D:/Ina/ETL_XdmLib_2.A.13/ETL_XdmLib_2.A.13/EDAETL/ETL_TABLE/ETL_LC_CP_TO_XSIFF/ETL_LC_CP_TO_XSIFF.py", line 185, in do_file
    # 拼接 DataFrame
  File "D:/Ina/ETL_XdmLib_2.A.13/ETL_XdmLib_2.A.13/EDAETL/ETL_TABLE/ETL_LC_CP_TO_XSIFF/ETL_LC_CP_TO_XSIFF.py", line 185, in do_file
    # 拼接 DataFrame
  File "_pydevd_bundle\pydevd_cython_win32_37_64.pyx", line 1179, in _pydevd_bundle.pydevd_cython_win32_37_64.SafeCallWrapper.__call__
  File "_pydevd_bundle\pydevd_cython_win32_37_64.pyx", line 620, in _pydevd_bundle.pydevd_cython_win32_37_64.PyDBFrame.trace_dispatch
  File "_pydevd_bundle\pydevd_cython_win32_37_64.pyx", line 1095, in _pydevd_bundle.pydevd_cython_win32_37_64.PyDBFrame.trace_dispatch
  File "_pydevd_bundle\pydevd_cython_win32_37_64.pyx", line 1057, in _pydevd_bundle.pydevd_cython_win32_37_64.PyDBFrame.trace_dispatch
  File "_pydevd_bundle\pydevd_cython_win32_37_64.pyx", line 317, in _pydevd_bundle.pydevd_cython_win32_37_64.PyDBFrame.do_wait_suspend
  File "D:\soft\PyCharm Community Edition 2022.1.3\plugins\python-ce\helpers\pydev\pydevd.py", line 1155, in do_wait_suspend
    self._do_wait_suspend(thread, frame, event, arg, suspend_type, from_this_thread)
  File "D:\soft\PyCharm Community Edition 2022.1.3\plugins\python-ce\helpers\pydev\pydevd.py", line 1170, in _do_wait_suspend
    time.sleep(0.01)
KeyboardInterrupt

During handling of the above exception, another exception occurred:

Traceback (most recent call last):
  File "D:\Python37\lib\site-packages\sqlalchemy\pool\base.py", line 697, in _finalize_fairy
    fairy._reset(pool)
  File "D:\Python37\lib\site-packages\sqlalchemy\pool\base.py", line 893, in _reset
    pool._dialect.do_rollback(self)
  File "D:\Python37\lib\site-packages\sqlalchemy\engine\default.py", line 559, in do_rollback
    dbapi_connection.rollback()
cx_Oracle.DatabaseError: DPI-1080: connection was closed by ORA-3135
2023-12-26 16:45:42.273 - base       [ERROR   ] Exception closing connection <cx_Oracle.Connection to vidatest@(DESCRIPTION=(ADDRESS=(PROTOCOL=TCP)(HOST=192.168.1.73)(PORT=1521))(CONNECT_DATA=(SID=demodb)))>
Traceback (most recent call last):
  File "../..\XdmLib\CustomFuction.py", line 597, in file2db_init
    file, pre_params, db_src, db_tgt)
  File "D:/Ina/ETL_XdmLib_2.A.13/ETL_XdmLib_2.A.13/EDAETL/ETL_TABLE/ETL_LC_CP_TO_XSIFF/ETL_LC_CP_TO_XSIFF.py", line 185, in do_file
    # 拼接 DataFrame
  File "D:/Ina/ETL_XdmLib_2.A.13/ETL_XdmLib_2.A.13/EDAETL/ETL_TABLE/ETL_LC_CP_TO_XSIFF/ETL_LC_CP_TO_XSIFF.py", line 185, in do_file
    # 拼接 DataFrame
  File "_pydevd_bundle\pydevd_cython_win32_37_64.pyx", line 1179, in _pydevd_bundle.pydevd_cython_win32_37_64.SafeCallWrapper.__call__
  File "_pydevd_bundle\pydevd_cython_win32_37_64.pyx", line 620, in _pydevd_bundle.pydevd_cython_win32_37_64.PyDBFrame.trace_dispatch
  File "_pydevd_bundle\pydevd_cython_win32_37_64.pyx", line 1095, in _pydevd_bundle.pydevd_cython_win32_37_64.PyDBFrame.trace_dispatch
  File "_pydevd_bundle\pydevd_cython_win32_37_64.pyx", line 1057, in _pydevd_bundle.pydevd_cython_win32_37_64.PyDBFrame.trace_dispatch
  File "_pydevd_bundle\pydevd_cython_win32_37_64.pyx", line 317, in _pydevd_bundle.pydevd_cython_win32_37_64.PyDBFrame.do_wait_suspend
  File "D:\soft\PyCharm Community Edition 2022.1.3\plugins\python-ce\helpers\pydev\pydevd.py", line 1155, in do_wait_suspend
    self._do_wait_suspend(thread, frame, event, arg, suspend_type, from_this_thread)
  File "D:\soft\PyCharm Community Edition 2022.1.3\plugins\python-ce\helpers\pydev\pydevd.py", line 1170, in _do_wait_suspend
    time.sleep(0.01)
KeyboardInterrupt

During handling of the above exception, another exception occurred:

Traceback (most recent call last):
  File "D:\Python37\lib\site-packages\sqlalchemy\pool\base.py", line 270, in _close_connection
    self._dialect.do_close(connection)
  File "D:\Python37\lib\site-packages\sqlalchemy\engine\default.py", line 565, in do_close
    dbapi_connection.close()
cx_Oracle.DatabaseError: DPI-1080: connection was closed by ORA-3135
2023-12-26 16:45:42.308 - base       [ERROR   ] Exception during reset or similar
Traceback (most recent call last):
  File "../..\XdmLib\CustomFuction.py", line 597, in file2db_init
    file, pre_params, db_src, db_tgt)
  File "D:/Ina/ETL_XdmLib_2.A.13/ETL_XdmLib_2.A.13/EDAETL/ETL_TABLE/ETL_LC_CP_TO_XSIFF/ETL_LC_CP_TO_XSIFF.py", line 185, in do_file
    # 拼接 DataFrame
  File "D:/Ina/ETL_XdmLib_2.A.13/ETL_XdmLib_2.A.13/EDAETL/ETL_TABLE/ETL_LC_CP_TO_XSIFF/ETL_LC_CP_TO_XSIFF.py", line 185, in do_file
    # 拼接 DataFrame
  File "_pydevd_bundle\pydevd_cython_win32_37_64.pyx", line 1179, in _pydevd_bundle.pydevd_cython_win32_37_64.SafeCallWrapper.__call__
  File "_pydevd_bundle\pydevd_cython_win32_37_64.pyx", line 620, in _pydevd_bundle.pydevd_cython_win32_37_64.PyDBFrame.trace_dispatch
  File "_pydevd_bundle\pydevd_cython_win32_37_64.pyx", line 1095, in _pydevd_bundle.pydevd_cython_win32_37_64.PyDBFrame.trace_dispatch
  File "_pydevd_bundle\pydevd_cython_win32_37_64.pyx", line 1057, in _pydevd_bundle.pydevd_cython_win32_37_64.PyDBFrame.trace_dispatch
  File "_pydevd_bundle\pydevd_cython_win32_37_64.pyx", line 317, in _pydevd_bundle.pydevd_cython_win32_37_64.PyDBFrame.do_wait_suspend
  File "D:\soft\PyCharm Community Edition 2022.1.3\plugins\python-ce\helpers\pydev\pydevd.py", line 1155, in do_wait_suspend
    self._do_wait_suspend(thread, frame, event, arg, suspend_type, from_this_thread)
  File "D:\soft\PyCharm Community Edition 2022.1.3\plugins\python-ce\helpers\pydev\pydevd.py", line 1170, in _do_wait_suspend
    time.sleep(0.01)
KeyboardInterrupt

During handling of the above exception, another exception occurred:

Traceback (most recent call last):
  File "D:\Python37\lib\site-packages\sqlalchemy\pool\base.py", line 697, in _finalize_fairy
    fairy._reset(pool)
  File "D:\Python37\lib\site-packages\sqlalchemy\pool\base.py", line 893, in _reset
    pool._dialect.do_rollback(self)
  File "D:\Python37\lib\site-packages\sqlalchemy\engine\default.py", line 559, in do_rollback
    dbapi_connection.rollback()
cx_Oracle.DatabaseError: DPI-1080: connection was closed by ORA-3135
2023-12-26 16:45:42.313 - base       [ERROR   ] Exception closing connection <cx_Oracle.Connection to vidatest@(DESCRIPTION=(ADDRESS=(PROTOCOL=TCP)(HOST=192.168.1.73)(PORT=1521))(CONNECT_DATA=(SID=demodb)))>
Traceback (most recent call last):
  File "../..\XdmLib\CustomFuction.py", line 597, in file2db_init
    file, pre_params, db_src, db_tgt)
  File "D:/Ina/ETL_XdmLib_2.A.13/ETL_XdmLib_2.A.13/EDAETL/ETL_TABLE/ETL_LC_CP_TO_XSIFF/ETL_LC_CP_TO_XSIFF.py", line 185, in do_file
    # 拼接 DataFrame
  File "D:/Ina/ETL_XdmLib_2.A.13/ETL_XdmLib_2.A.13/EDAETL/ETL_TABLE/ETL_LC_CP_TO_XSIFF/ETL_LC_CP_TO_XSIFF.py", line 185, in do_file
    # 拼接 DataFrame
  File "_pydevd_bundle\pydevd_cython_win32_37_64.pyx", line 1179, in _pydevd_bundle.pydevd_cython_win32_37_64.SafeCallWrapper.__call__
  File "_pydevd_bundle\pydevd_cython_win32_37_64.pyx", line 620, in _pydevd_bundle.pydevd_cython_win32_37_64.PyDBFrame.trace_dispatch
  File "_pydevd_bundle\pydevd_cython_win32_37_64.pyx", line 1095, in _pydevd_bundle.pydevd_cython_win32_37_64.PyDBFrame.trace_dispatch
  File "_pydevd_bundle\pydevd_cython_win32_37_64.pyx", line 1057, in _pydevd_bundle.pydevd_cython_win32_37_64.PyDBFrame.trace_dispatch
  File "_pydevd_bundle\pydevd_cython_win32_37_64.pyx", line 317, in _pydevd_bundle.pydevd_cython_win32_37_64.PyDBFrame.do_wait_suspend
  File "D:\soft\PyCharm Community Edition 2022.1.3\plugins\python-ce\helpers\pydev\pydevd.py", line 1155, in do_wait_suspend
    self._do_wait_suspend(thread, frame, event, arg, suspend_type, from_this_thread)
  File "D:\soft\PyCharm Community Edition 2022.1.3\plugins\python-ce\helpers\pydev\pydevd.py", line 1170, in _do_wait_suspend
    time.sleep(0.01)
KeyboardInterrupt

During handling of the above exception, another exception occurred:

Traceback (most recent call last):
  File "D:\Python37\lib\site-packages\sqlalchemy\pool\base.py", line 270, in _close_connection
    self._dialect.do_close(connection)
  File "D:\Python37\lib\site-packages\sqlalchemy\engine\default.py", line 565, in do_close
    dbapi_connection.close()
cx_Oracle.DatabaseError: DPI-1080: connection was closed by ORA-3135
