2023-12-26 14:25:56.161 - __init__   [INFO    ] # ===== [ XdmLib Ver. ] ===== #
2023-12-26 14:25:56.163 - __init__   [INFO    ] XdmLib Ver. 2.A.13
2023-12-26 14:25:56.164 - __init__   [INFO    ] # ===== [ XdmLib Ver. ] ===== #
2023-12-26 14:25:56.166 - __init__   [INFO    ] Console Quick Edit Disabled
2023-12-26 14:25:56.231 - __init__   [INFO    ] Server/Host Name: DESKTOP-J6AUF2I
2023-12-26 14:25:56.234 - __init__   [INFO    ] Archive setting non-setting, Archive files will be kept.
2023-12-26 14:25:56.236 - __init__   [INFO    ] Error setting non-setting, Error files will be kept.
2023-12-26 14:26:01.493 - __init__   [INFO    ] Server: DESKTOP-J6AUF2I, Status: 0, data_time_flg: None.
2023-12-26 14:26:01.494 - __init__   [WARNING ] The loader duplicate execute(Set attribute: 'ALLOW_DUPLICATE_EXECUTE = False' disable it).
2023-12-26 14:26:05.065 - __init__   [INFO    ] Watching control file: D:\Ina\ETL_XdmLib_2.A.13\ETL_XdmLib_2.A.13\EDAETL\ETL_TABLE\ETL_LC_CP_TO_XSIFF\ETL_LC_CP_TO_XSIFF.py.*
2023-12-26 14:26:05.086 - __init__   [INFO    ] SetProcessStatus 0, Start time: 2023-12-26 14:25:56.104911
2023-12-26 14:26:10.925 - __init__   [INFO    ] Set process status code: 0.
2023-12-26 14:26:11.023 - Database   [INFO    ] Non set logging! Using default logging.
2023-12-26 14:26:11.493 - Database   [INFO    ] Non set logging! Using default logging.
2023-12-26 14:26:11.981 - Database   [INFO    ] Non set logging! Using default logging.
2023-12-26 14:26:12.969 - ETL_LC_CP_TO_XSIFF [INFO    ] Currently working on files: #24.csv 
2023-12-26 14:26:13.071 - ETL_LC_CP_TO_XSIFF [INFO    ] Read source file:0:00:00.101453
2023-12-26 16:45:42.201 - base       [ERROR   ] Exception during reset or similar
Traceback (most recent call last):
  File "../..\XdmLib\CustomFuction.py", line 597, in file2db_init
    file, pre_params, db_src, db_tgt)
  File "D:/Ina/ETL_XdmLib_2.A.13/ETL_XdmLib_2.A.13/EDAETL/ETL_TABLE/ETL_LC_CP_TO_XSIFF/ETL_LC_CP_TO_XSIFF.py", line 185, in do_file
    # 拼接 DataFrame
  File "D:/Ina/ETL_XdmLib_2.A.13/ETL_XdmLib_2.A.13/EDAETL/ETL_TABLE/ETL_LC_CP_TO_XSIFF/ETL_LC_CP_TO_XSIFF.py", line 185, in do_file
    # 拼接 DataFrame
  File "_pydevd_bundle\pydevd_cython_win32_37_64.pyx", line 1179, in _pydevd_bundle.pydevd_cython_win32_37_64.SafeCallWrapper.__call__
  File "_pydevd_bundle\pydevd_cython_win32_37_64.pyx", line 620, in _pydevd_bundle.pydevd_cython_win32_37_64.PyDBFrame.trace_dispatch
  File "_pydevd_bundle\pydevd_cython_win32_37_64.pyx", line 1095, in _pydevd_bundle.pydevd_cython_win32_37_64.PyDBFrame.trace_dispatch
  File "_pydevd_bundle\pydevd_cython_win32_37_64.pyx", line 1057, in _pydevd_bundle.pydevd_cython_win32_37_64.PyDBFrame.trace_dispatch
  File "_pydevd_bundle\pydevd_cython_win32_37_64.pyx", line 317, in _pydevd_bundle.pydevd_cython_win32_37_64.PyDBFrame.do_wait_suspend
  File "D:\soft\PyCharm Community Edition 2022.1.3\plugins\python-ce\helpers\pydev\pydevd.py", line 1155, in do_wait_suspend
    self._do_wait_suspend(thread, frame, event, arg, suspend_type, from_this_thread)
  File "D:\soft\PyCharm Community Edition 2022.1.3\plugins\python-ce\helpers\pydev\pydevd.py", line 1170, in _do_wait_suspend
    time.sleep(0.01)
KeyboardInterrupt

During handling of the above exception, another exception occurred:

Traceback (most recent call last):
  File "D:\Python37\lib\site-packages\sqlalchemy\pool\base.py", line 697, in _finalize_fairy
    fairy._reset(pool)
  File "D:\Python37\lib\site-packages\sqlalchemy\pool\base.py", line 893, in _reset
    pool._dialect.do_rollback(self)
  File "D:\Python37\lib\site-packages\sqlalchemy\engine\default.py", line 559, in do_rollback
    dbapi_connection.rollback()
cx_Oracle.DatabaseError: DPI-1080: connection was closed by ORA-3135
2023-12-26 16:45:42.273 - base       [ERROR   ] Exception closing connection <cx_Oracle.Connection to vidatest@(DESCRIPTION=(ADDRESS=(PROTOCOL=TCP)(HOST=192.168.1.73)(PORT=1521))(CONNECT_DATA=(SID=demodb)))>
Traceback (most recent call last):
  File "../..\XdmLib\CustomFuction.py", line 597, in file2db_init
    file, pre_params, db_src, db_tgt)
  File "D:/Ina/ETL_XdmLib_2.A.13/ETL_XdmLib_2.A.13/EDAETL/ETL_TABLE/ETL_LC_CP_TO_XSIFF/ETL_LC_CP_TO_XSIFF.py", line 185, in do_file
    # 拼接 DataFrame
  File "D:/Ina/ETL_XdmLib_2.A.13/ETL_XdmLib_2.A.13/EDAETL/ETL_TABLE/ETL_LC_CP_TO_XSIFF/ETL_LC_CP_TO_XSIFF.py", line 185, in do_file
    # 拼接 DataFrame
  File "_pydevd_bundle\pydevd_cython_win32_37_64.pyx", line 1179, in _pydevd_bundle.pydevd_cython_win32_37_64.SafeCallWrapper.__call__
  File "_pydevd_bundle\pydevd_cython_win32_37_64.pyx", line 620, in _pydevd_bundle.pydevd_cython_win32_37_64.PyDBFrame.trace_dispatch
  File "_pydevd_bundle\pydevd_cython_win32_37_64.pyx", line 1095, in _pydevd_bundle.pydevd_cython_win32_37_64.PyDBFrame.trace_dispatch
  File "_pydevd_bundle\pydevd_cython_win32_37_64.pyx", line 1057, in _pydevd_bundle.pydevd_cython_win32_37_64.PyDBFrame.trace_dispatch
  File "_pydevd_bundle\pydevd_cython_win32_37_64.pyx", line 317, in _pydevd_bundle.pydevd_cython_win32_37_64.PyDBFrame.do_wait_suspend
  File "D:\soft\PyCharm Community Edition 2022.1.3\plugins\python-ce\helpers\pydev\pydevd.py", line 1155, in do_wait_suspend
    self._do_wait_suspend(thread, frame, event, arg, suspend_type, from_this_thread)
  File "D:\soft\PyCharm Community Edition 2022.1.3\plugins\python-ce\helpers\pydev\pydevd.py", line 1170, in _do_wait_suspend
    time.sleep(0.01)
KeyboardInterrupt

During handling of the above exception, another exception occurred:

Traceback (most recent call last):
  File "D:\Python37\lib\site-packages\sqlalchemy\pool\base.py", line 270, in _close_connection
    self._dialect.do_close(connection)
  File "D:\Python37\lib\site-packages\sqlalchemy\engine\default.py", line 565, in do_close
    dbapi_connection.close()
cx_Oracle.DatabaseError: DPI-1080: connection was closed by ORA-3135
2023-12-26 16:45:42.308 - base       [ERROR   ] Exception during reset or similar
Traceback (most recent call last):
  File "../..\XdmLib\CustomFuction.py", line 597, in file2db_init
    file, pre_params, db_src, db_tgt)
  File "D:/Ina/ETL_XdmLib_2.A.13/ETL_XdmLib_2.A.13/EDAETL/ETL_TABLE/ETL_LC_CP_TO_XSIFF/ETL_LC_CP_TO_XSIFF.py", line 185, in do_file
    # 拼接 DataFrame
  File "D:/Ina/ETL_XdmLib_2.A.13/ETL_XdmLib_2.A.13/EDAETL/ETL_TABLE/ETL_LC_CP_TO_XSIFF/ETL_LC_CP_TO_XSIFF.py", line 185, in do_file
    # 拼接 DataFrame
  File "_pydevd_bundle\pydevd_cython_win32_37_64.pyx", line 1179, in _pydevd_bundle.pydevd_cython_win32_37_64.SafeCallWrapper.__call__
  File "_pydevd_bundle\pydevd_cython_win32_37_64.pyx", line 620, in _pydevd_bundle.pydevd_cython_win32_37_64.PyDBFrame.trace_dispatch
  File "_pydevd_bundle\pydevd_cython_win32_37_64.pyx", line 1095, in _pydevd_bundle.pydevd_cython_win32_37_64.PyDBFrame.trace_dispatch
  File "_pydevd_bundle\pydevd_cython_win32_37_64.pyx", line 1057, in _pydevd_bundle.pydevd_cython_win32_37_64.PyDBFrame.trace_dispatch
  File "_pydevd_bundle\pydevd_cython_win32_37_64.pyx", line 317, in _pydevd_bundle.pydevd_cython_win32_37_64.PyDBFrame.do_wait_suspend
  File "D:\soft\PyCharm Community Edition 2022.1.3\plugins\python-ce\helpers\pydev\pydevd.py", line 1155, in do_wait_suspend
    self._do_wait_suspend(thread, frame, event, arg, suspend_type, from_this_thread)
  File "D:\soft\PyCharm Community Edition 2022.1.3\plugins\python-ce\helpers\pydev\pydevd.py", line 1170, in _do_wait_suspend
    time.sleep(0.01)
KeyboardInterrupt

During handling of the above exception, another exception occurred:

Traceback (most recent call last):
  File "D:\Python37\lib\site-packages\sqlalchemy\pool\base.py", line 697, in _finalize_fairy
    fairy._reset(pool)
  File "D:\Python37\lib\site-packages\sqlalchemy\pool\base.py", line 893, in _reset
    pool._dialect.do_rollback(self)
  File "D:\Python37\lib\site-packages\sqlalchemy\engine\default.py", line 559, in do_rollback
    dbapi_connection.rollback()
cx_Oracle.DatabaseError: DPI-1080: connection was closed by ORA-3135
2023-12-26 16:45:42.313 - base       [ERROR   ] Exception closing connection <cx_Oracle.Connection to vidatest@(DESCRIPTION=(ADDRESS=(PROTOCOL=TCP)(HOST=192.168.1.73)(PORT=1521))(CONNECT_DATA=(SID=demodb)))>
Traceback (most recent call last):
  File "../..\XdmLib\CustomFuction.py", line 597, in file2db_init
    file, pre_params, db_src, db_tgt)
  File "D:/Ina/ETL_XdmLib_2.A.13/ETL_XdmLib_2.A.13/EDAETL/ETL_TABLE/ETL_LC_CP_TO_XSIFF/ETL_LC_CP_TO_XSIFF.py", line 185, in do_file
    # 拼接 DataFrame
  File "D:/Ina/ETL_XdmLib_2.A.13/ETL_XdmLib_2.A.13/EDAETL/ETL_TABLE/ETL_LC_CP_TO_XSIFF/ETL_LC_CP_TO_XSIFF.py", line 185, in do_file
    # 拼接 DataFrame
  File "_pydevd_bundle\pydevd_cython_win32_37_64.pyx", line 1179, in _pydevd_bundle.pydevd_cython_win32_37_64.SafeCallWrapper.__call__
  File "_pydevd_bundle\pydevd_cython_win32_37_64.pyx", line 620, in _pydevd_bundle.pydevd_cython_win32_37_64.PyDBFrame.trace_dispatch
  File "_pydevd_bundle\pydevd_cython_win32_37_64.pyx", line 1095, in _pydevd_bundle.pydevd_cython_win32_37_64.PyDBFrame.trace_dispatch
  File "_pydevd_bundle\pydevd_cython_win32_37_64.pyx", line 1057, in _pydevd_bundle.pydevd_cython_win32_37_64.PyDBFrame.trace_dispatch
  File "_pydevd_bundle\pydevd_cython_win32_37_64.pyx", line 317, in _pydevd_bundle.pydevd_cython_win32_37_64.PyDBFrame.do_wait_suspend
  File "D:\soft\PyCharm Community Edition 2022.1.3\plugins\python-ce\helpers\pydev\pydevd.py", line 1155, in do_wait_suspend
    self._do_wait_suspend(thread, frame, event, arg, suspend_type, from_this_thread)
  File "D:\soft\PyCharm Community Edition 2022.1.3\plugins\python-ce\helpers\pydev\pydevd.py", line 1170, in _do_wait_suspend
    time.sleep(0.01)
KeyboardInterrupt

During handling of the above exception, another exception occurred:

Traceback (most recent call last):
  File "D:\Python37\lib\site-packages\sqlalchemy\pool\base.py", line 270, in _close_connection
    self._dialect.do_close(connection)
  File "D:\Python37\lib\site-packages\sqlalchemy\engine\default.py", line 565, in do_close
    dbapi_connection.close()
cx_Oracle.DatabaseError: DPI-1080: connection was closed by ORA-3135
