2024-01-05 11:35:22.432 - ETL_LC_CP_TO_XSIFF_20240102 [ERROR   ] list index out of range
Traceback (most recent call last):
  File "D:/Ina/ETL_XdmLib_2.A.13/ETL_XdmLib_2.A.13/EDAETL/ETL_TABLE/ETL_LC_CP_TO_XSIFF/ETL_LC_CP_TO_XSIFF_20240102.py", line 197, in do_file
    selectedParameterName = parameterName[0][2:]
IndexError: list index out of range
Stack (most recent call last):
  File "D:/Ina/ETL_XdmLib_2.A.13/ETL_XdmLib_2.A.13/EDAETL/ETL_TABLE/ETL_LC_CP_TO_XSIFF/ETL_LC_CP_TO_XSIFF_20240102.py", line 434, in <module>
    do_file, before_do_file, after_do_file, skip_file, None, log, config, config_sql)
  File "../..\XdmLib\CustomFuction.py", line 597, in file2db_init
    file, pre_params, db_src, db_tgt)
  File "D:/Ina/ETL_XdmLib_2.A.13/ETL_XdmLib_2.A.13/EDAETL/ETL_TABLE/ETL_LC_CP_TO_XSIFF/ETL_LC_CP_TO_XSIFF_20240102.py", line 334, in do_file
    log.error(ex, exc_info=True, stack_info=True)
2024-01-05 11:35:22.583 - __init__   [ERROR   ] File:#24.csv Move To Error Folder
                                                Error: None
2024-01-05 11:35:22.601 - ETL_LC_CP_TO_XSIFF_20240102 [ERROR   ] list index out of range
Traceback (most recent call last):
  File "D:/Ina/ETL_XdmLib_2.A.13/ETL_XdmLib_2.A.13/EDAETL/ETL_TABLE/ETL_LC_CP_TO_XSIFF/ETL_LC_CP_TO_XSIFF_20240102.py", line 197, in do_file
    selectedParameterName = parameterName[0][2:]
IndexError: list index out of range
Stack (most recent call last):
  File "D:/Ina/ETL_XdmLib_2.A.13/ETL_XdmLib_2.A.13/EDAETL/ETL_TABLE/ETL_LC_CP_TO_XSIFF/ETL_LC_CP_TO_XSIFF_20240102.py", line 434, in <module>
    do_file, before_do_file, after_do_file, skip_file, None, log, config, config_sql)
  File "../..\XdmLib\CustomFuction.py", line 597, in file2db_init
    file, pre_params, db_src, db_tgt)
  File "D:/Ina/ETL_XdmLib_2.A.13/ETL_XdmLib_2.A.13/EDAETL/ETL_TABLE/ETL_LC_CP_TO_XSIFF/ETL_LC_CP_TO_XSIFF_20240102.py", line 334, in do_file
    log.error(ex, exc_info=True, stack_info=True)
2024-01-05 11:35:22.809 - __init__   [ERROR   ] File:23GD0040_231211141600(1).csv Move To Error Folder
                                                Error: None
2024-01-05 13:14:39.298 - ETL_LC_CP_TO_XSIFF_20240102 [ERROR   ] list index out of range
Traceback (most recent call last):
  File "D:/Ina/ETL_XdmLib_2.A.13/ETL_XdmLib_2.A.13/EDAETL/ETL_TABLE/ETL_LC_CP_TO_XSIFF/ETL_LC_CP_TO_XSIFF_20240102.py", line 198, in do_file
    selectedParameterName = parameterName[0][2:]
IndexError: list index out of range
Stack (most recent call last):
  File "D:\soft\PyCharm Community Edition 2022.1.3\plugins\python-ce\helpers\pydev\pydevd.py", line 2181, in <module>
    main()
  File "D:\soft\PyCharm Community Edition 2022.1.3\plugins\python-ce\helpers\pydev\pydevd.py", line 2172, in main
    globals = debugger.run(setup['file'], None, None, is_module)
  File "D:\soft\PyCharm Community Edition 2022.1.3\plugins\python-ce\helpers\pydev\pydevd.py", line 1484, in run
    return self._exec(is_module, entry_point_fn, module_name, file, globals, locals)
  File "D:\soft\PyCharm Community Edition 2022.1.3\plugins\python-ce\helpers\pydev\pydevd.py", line 1491, in _exec
    pydev_imports.execfile(file, globals, locals)  # execute the script
  File "D:\soft\PyCharm Community Edition 2022.1.3\plugins\python-ce\helpers\pydev\_pydev_imps\_pydev_execfile.py", line 18, in execfile
    exec(compile(contents+"\n", file, 'exec'), glob, loc)
  File "D:/Ina/ETL_XdmLib_2.A.13/ETL_XdmLib_2.A.13/EDAETL/ETL_TABLE/ETL_LC_CP_TO_XSIFF/ETL_LC_CP_TO_XSIFF_20240102.py", line 435, in <module>
    do_file, before_do_file, after_do_file, skip_file, None, log, config, config_sql)
  File "../..\XdmLib\CustomFuction.py", line 597, in file2db_init
    file, pre_params, db_src, db_tgt)
  File "D:/Ina/ETL_XdmLib_2.A.13/ETL_XdmLib_2.A.13/EDAETL/ETL_TABLE/ETL_LC_CP_TO_XSIFF/ETL_LC_CP_TO_XSIFF_20240102.py", line 335, in do_file
    log.error(ex, exc_info=True, stack_info=True)
2024-01-05 13:14:39.506 - __init__   [ERROR   ] File:#24.csv Move To Error Folder
                                                Error: None
2024-01-05 13:14:39.524 - ETL_LC_CP_TO_XSIFF_20240102 [ERROR   ] list index out of range
Traceback (most recent call last):
  File "D:/Ina/ETL_XdmLib_2.A.13/ETL_XdmLib_2.A.13/EDAETL/ETL_TABLE/ETL_LC_CP_TO_XSIFF/ETL_LC_CP_TO_XSIFF_20240102.py", line 198, in do_file
    selectedParameterName = parameterName[0][2:]
IndexError: list index out of range
Stack (most recent call last):
  File "D:\soft\PyCharm Community Edition 2022.1.3\plugins\python-ce\helpers\pydev\pydevd.py", line 2181, in <module>
    main()
  File "D:\soft\PyCharm Community Edition 2022.1.3\plugins\python-ce\helpers\pydev\pydevd.py", line 2172, in main
    globals = debugger.run(setup['file'], None, None, is_module)
  File "D:\soft\PyCharm Community Edition 2022.1.3\plugins\python-ce\helpers\pydev\pydevd.py", line 1484, in run
    return self._exec(is_module, entry_point_fn, module_name, file, globals, locals)
  File "D:\soft\PyCharm Community Edition 2022.1.3\plugins\python-ce\helpers\pydev\pydevd.py", line 1491, in _exec
    pydev_imports.execfile(file, globals, locals)  # execute the script
  File "D:\soft\PyCharm Community Edition 2022.1.3\plugins\python-ce\helpers\pydev\_pydev_imps\_pydev_execfile.py", line 18, in execfile
    exec(compile(contents+"\n", file, 'exec'), glob, loc)
  File "D:/Ina/ETL_XdmLib_2.A.13/ETL_XdmLib_2.A.13/EDAETL/ETL_TABLE/ETL_LC_CP_TO_XSIFF/ETL_LC_CP_TO_XSIFF_20240102.py", line 435, in <module>
    do_file, before_do_file, after_do_file, skip_file, None, log, config, config_sql)
  File "../..\XdmLib\CustomFuction.py", line 597, in file2db_init
    file, pre_params, db_src, db_tgt)
  File "D:/Ina/ETL_XdmLib_2.A.13/ETL_XdmLib_2.A.13/EDAETL/ETL_TABLE/ETL_LC_CP_TO_XSIFF/ETL_LC_CP_TO_XSIFF_20240102.py", line 335, in do_file
    log.error(ex, exc_info=True, stack_info=True)
2024-01-05 13:14:39.690 - __init__   [ERROR   ] File:23GD0040_231211141600(1).csv Move To Error Folder
                                                Error: None
2024-01-05 13:25:37.149 - ETL_LC_CP_TO_XSIFF_20240102 [ERROR   ] name 'parameter_name' is not defined
Traceback (most recent call last):
  File "D:/Ina/ETL_XdmLib_2.A.13/ETL_XdmLib_2.A.13/EDAETL/ETL_TABLE/ETL_LC_CP_TO_XSIFF/ETL_LC_CP_TO_XSIFF_20240102.py", line 185, in do_file
    selectedParameterName = parameter_name[0][2:]
NameError: name 'parameter_name' is not defined
Stack (most recent call last):
  File "D:/Ina/ETL_XdmLib_2.A.13/ETL_XdmLib_2.A.13/EDAETL/ETL_TABLE/ETL_LC_CP_TO_XSIFF/ETL_LC_CP_TO_XSIFF_20240102.py", line 422, in <module>
    do_file, before_do_file, after_do_file, skip_file, None, log, config, config_sql)
  File "../..\XdmLib\CustomFuction.py", line 597, in file2db_init
    file, pre_params, db_src, db_tgt)
  File "D:/Ina/ETL_XdmLib_2.A.13/ETL_XdmLib_2.A.13/EDAETL/ETL_TABLE/ETL_LC_CP_TO_XSIFF/ETL_LC_CP_TO_XSIFF_20240102.py", line 322, in do_file
    log.error(ex, exc_info=True, stack_info=True)
2024-01-05 13:25:37.330 - __init__   [ERROR   ] File:#24.csv Move To Error Folder
                                                Error: None
2024-01-05 13:25:37.348 - ETL_LC_CP_TO_XSIFF_20240102 [ERROR   ] name 'parameter_name' is not defined
Traceback (most recent call last):
  File "D:/Ina/ETL_XdmLib_2.A.13/ETL_XdmLib_2.A.13/EDAETL/ETL_TABLE/ETL_LC_CP_TO_XSIFF/ETL_LC_CP_TO_XSIFF_20240102.py", line 185, in do_file
    selectedParameterName = parameter_name[0][2:]
NameError: name 'parameter_name' is not defined
Stack (most recent call last):
  File "D:/Ina/ETL_XdmLib_2.A.13/ETL_XdmLib_2.A.13/EDAETL/ETL_TABLE/ETL_LC_CP_TO_XSIFF/ETL_LC_CP_TO_XSIFF_20240102.py", line 422, in <module>
    do_file, before_do_file, after_do_file, skip_file, None, log, config, config_sql)
  File "../..\XdmLib\CustomFuction.py", line 597, in file2db_init
    file, pre_params, db_src, db_tgt)
  File "D:/Ina/ETL_XdmLib_2.A.13/ETL_XdmLib_2.A.13/EDAETL/ETL_TABLE/ETL_LC_CP_TO_XSIFF/ETL_LC_CP_TO_XSIFF_20240102.py", line 322, in do_file
    log.error(ex, exc_info=True, stack_info=True)
2024-01-05 13:25:37.527 - __init__   [ERROR   ] File:23GD0040_231211141600(1).csv Move To Error Folder
                                                Error: None
2024-01-05 13:28:30.339 - ETL_LC_CP_TO_XSIFF_20240102 [ERROR   ] 'str' object does not support item assignment
Traceback (most recent call last):
  File "D:/Ina/ETL_XdmLib_2.A.13/ETL_XdmLib_2.A.13/EDAETL/ETL_TABLE/ETL_LC_CP_TO_XSIFF/ETL_LC_CP_TO_XSIFF_20240102.py", line 187, in do_file
    selectedParameterName[:3] = ['HBIN','DieX', 'DieY']
TypeError: 'str' object does not support item assignment
Stack (most recent call last):
  File "D:/Ina/ETL_XdmLib_2.A.13/ETL_XdmLib_2.A.13/EDAETL/ETL_TABLE/ETL_LC_CP_TO_XSIFF/ETL_LC_CP_TO_XSIFF_20240102.py", line 422, in <module>
    do_file, before_do_file, after_do_file, skip_file, None, log, config, config_sql)
  File "../..\XdmLib\CustomFuction.py", line 597, in file2db_init
    file, pre_params, db_src, db_tgt)
  File "D:/Ina/ETL_XdmLib_2.A.13/ETL_XdmLib_2.A.13/EDAETL/ETL_TABLE/ETL_LC_CP_TO_XSIFF/ETL_LC_CP_TO_XSIFF_20240102.py", line 322, in do_file
    log.error(ex, exc_info=True, stack_info=True)
2024-01-05 13:28:30.500 - __init__   [ERROR   ] File:#24.csv Move To Error Folder
                                                Error: None
2024-01-05 13:28:30.520 - ETL_LC_CP_TO_XSIFF_20240102 [ERROR   ] 'str' object does not support item assignment
Traceback (most recent call last):
  File "D:/Ina/ETL_XdmLib_2.A.13/ETL_XdmLib_2.A.13/EDAETL/ETL_TABLE/ETL_LC_CP_TO_XSIFF/ETL_LC_CP_TO_XSIFF_20240102.py", line 187, in do_file
    selectedParameterName[:3] = ['HBIN','DieX', 'DieY']
TypeError: 'str' object does not support item assignment
Stack (most recent call last):
  File "D:/Ina/ETL_XdmLib_2.A.13/ETL_XdmLib_2.A.13/EDAETL/ETL_TABLE/ETL_LC_CP_TO_XSIFF/ETL_LC_CP_TO_XSIFF_20240102.py", line 422, in <module>
    do_file, before_do_file, after_do_file, skip_file, None, log, config, config_sql)
  File "../..\XdmLib\CustomFuction.py", line 597, in file2db_init
    file, pre_params, db_src, db_tgt)
  File "D:/Ina/ETL_XdmLib_2.A.13/ETL_XdmLib_2.A.13/EDAETL/ETL_TABLE/ETL_LC_CP_TO_XSIFF/ETL_LC_CP_TO_XSIFF_20240102.py", line 322, in do_file
    log.error(ex, exc_info=True, stack_info=True)
2024-01-05 13:28:30.697 - __init__   [ERROR   ] File:23GD0040_231211141600(1).csv Move To Error Folder
                                                Error: None
2024-01-05 17:08:49.956 - ETL_LC_CP_TO_XSIFF_20240102 [ERROR   ] 'str' object does not support item assignment
Traceback (most recent call last):
  File "D:/Ina/ETL_XdmLib_2.A.13/ETL_XdmLib_2.A.13/EDAETL/ETL_TABLE/ETL_LC_CP_TO_XSIFF/ETL_LC_CP_TO_XSIFF_20240102.py", line 190, in do_file
    selectedParameterName[:3] = ['HBIN','DieX', 'DieY']
TypeError: 'str' object does not support item assignment
Stack (most recent call last):
  File "D:/Ina/ETL_XdmLib_2.A.13/ETL_XdmLib_2.A.13/EDAETL/ETL_TABLE/ETL_LC_CP_TO_XSIFF/ETL_LC_CP_TO_XSIFF_20240102.py", line 425, in <module>
    do_file, before_do_file, after_do_file, skip_file, None, log, config, config_sql)
  File "../..\XdmLib\CustomFuction.py", line 597, in file2db_init
    file, pre_params, db_src, db_tgt)
  File "D:/Ina/ETL_XdmLib_2.A.13/ETL_XdmLib_2.A.13/EDAETL/ETL_TABLE/ETL_LC_CP_TO_XSIFF/ETL_LC_CP_TO_XSIFF_20240102.py", line 325, in do_file
    log.error(ex, exc_info=True, stack_info=True)
2024-01-05 17:08:50.136 - __init__   [ERROR   ] File:#24.csv Move To Error Folder
                                                Error: None
2024-01-05 17:08:50.189 - ETL_LC_CP_TO_XSIFF_20240102 [ERROR   ] 'str' object does not support item assignment
Traceback (most recent call last):
  File "D:/Ina/ETL_XdmLib_2.A.13/ETL_XdmLib_2.A.13/EDAETL/ETL_TABLE/ETL_LC_CP_TO_XSIFF/ETL_LC_CP_TO_XSIFF_20240102.py", line 190, in do_file
    selectedParameterName[:3] = ['HBIN','DieX', 'DieY']
TypeError: 'str' object does not support item assignment
Stack (most recent call last):
  File "D:/Ina/ETL_XdmLib_2.A.13/ETL_XdmLib_2.A.13/EDAETL/ETL_TABLE/ETL_LC_CP_TO_XSIFF/ETL_LC_CP_TO_XSIFF_20240102.py", line 425, in <module>
    do_file, before_do_file, after_do_file, skip_file, None, log, config, config_sql)
  File "../..\XdmLib\CustomFuction.py", line 597, in file2db_init
    file, pre_params, db_src, db_tgt)
  File "D:/Ina/ETL_XdmLib_2.A.13/ETL_XdmLib_2.A.13/EDAETL/ETL_TABLE/ETL_LC_CP_TO_XSIFF/ETL_LC_CP_TO_XSIFF_20240102.py", line 325, in do_file
    log.error(ex, exc_info=True, stack_info=True)
2024-01-05 17:08:50.427 - __init__   [ERROR   ] File:23GD0040_231211141600(1).csv Move To Error Folder
                                                Error: None
2024-01-05 17:17:29.669 - ETL_LC_CP_TO_XSIFF_20240102 [ERROR   ] name 'unit_list' is not defined
Traceback (most recent call last):
  File "D:/Ina/ETL_XdmLib_2.A.13/ETL_XdmLib_2.A.13/EDAETL/ETL_TABLE/ETL_LC_CP_TO_XSIFF/ETL_LC_CP_TO_XSIFF_20240102.py", line 201, in do_file
    temp_df = pd.DataFrame({'Unit': unit_list[0][5:],'SpecLow': result.limit_list[3][5:],'SpecHigh': result.limit_list[4][5:]})
NameError: name 'unit_list' is not defined
Stack (most recent call last):
  File "D:/Ina/ETL_XdmLib_2.A.13/ETL_XdmLib_2.A.13/EDAETL/ETL_TABLE/ETL_LC_CP_TO_XSIFF/ETL_LC_CP_TO_XSIFF_20240102.py", line 425, in <module>
    do_file, before_do_file, after_do_file, skip_file, None, log, config, config_sql)
  File "../..\XdmLib\CustomFuction.py", line 597, in file2db_init
    file, pre_params, db_src, db_tgt)
  File "D:/Ina/ETL_XdmLib_2.A.13/ETL_XdmLib_2.A.13/EDAETL/ETL_TABLE/ETL_LC_CP_TO_XSIFF/ETL_LC_CP_TO_XSIFF_20240102.py", line 325, in do_file
    log.error(ex, exc_info=True, stack_info=True)
2024-01-05 17:17:29.839 - __init__   [ERROR   ] File:#24.csv Move To Error Folder
                                                Error: None
2024-01-05 17:17:29.859 - ETL_LC_CP_TO_XSIFF_20240102 [ERROR   ] name 'unit_list' is not defined
Traceback (most recent call last):
  File "D:/Ina/ETL_XdmLib_2.A.13/ETL_XdmLib_2.A.13/EDAETL/ETL_TABLE/ETL_LC_CP_TO_XSIFF/ETL_LC_CP_TO_XSIFF_20240102.py", line 201, in do_file
    temp_df = pd.DataFrame({'Unit': unit_list[0][5:],'SpecLow': result.limit_list[3][5:],'SpecHigh': result.limit_list[4][5:]})
NameError: name 'unit_list' is not defined
Stack (most recent call last):
  File "D:/Ina/ETL_XdmLib_2.A.13/ETL_XdmLib_2.A.13/EDAETL/ETL_TABLE/ETL_LC_CP_TO_XSIFF/ETL_LC_CP_TO_XSIFF_20240102.py", line 425, in <module>
    do_file, before_do_file, after_do_file, skip_file, None, log, config, config_sql)
  File "../..\XdmLib\CustomFuction.py", line 597, in file2db_init
    file, pre_params, db_src, db_tgt)
  File "D:/Ina/ETL_XdmLib_2.A.13/ETL_XdmLib_2.A.13/EDAETL/ETL_TABLE/ETL_LC_CP_TO_XSIFF/ETL_LC_CP_TO_XSIFF_20240102.py", line 325, in do_file
    log.error(ex, exc_info=True, stack_info=True)
2024-01-05 17:17:30.013 - __init__   [ERROR   ] File:23GD0040_231211141600(1).csv Move To Error Folder
                                                Error: None
