2023-08-25 11:02:38.009 - CustomFuction [ERROR   ] local variable 'BadDie' referenced before assignment
Traceback (most recent call last):
  File "D:\Ina\ETL_XdmLib_2.A.13\ETL_XdmLib_2.A.13\EDAETL\ETL_TABLE\ETL_TEST_INA_WAT_TO_XSIFF\../..\XdmLib\CustomFuction.py", line 596, in file2db_init
    res = do_file(file_root_source_path,
  File "D:\Ina\ETL_XdmLib_2.A.13\ETL_XdmLib_2.A.13\EDAETL\ETL_TABLE\ETL_TEST_INA_WAT_TO_XSIFF\ETL_TXT_TO_XSIFF.py", line 279, in do_file
    raise ex
  File "D:\Ina\ETL_XdmLib_2.A.13\ETL_XdmLib_2.A.13\EDAETL\ETL_TABLE\ETL_TEST_INA_WAT_TO_XSIFF\ETL_TXT_TO_XSIFF.py", line 217, in do_file
    TotalDie = GoodDie+BadDie
UnboundLocalError: local variable 'BadDie' referenced before assignment
Stack (most recent call last):
  File "D:\Ina\ETL_XdmLib_2.A.13\ETL_XdmLib_2.A.13\EDAETL\ETL_TABLE\ETL_TEST_INA_WAT_TO_XSIFF\ETL_TXT_TO_XSIFF.py", line 397, in <module>
    XdmLib.CustomFuction.file2db_init(do_file, before_do_file, after_do_file,
  File "D:\Ina\ETL_XdmLib_2.A.13\ETL_XdmLib_2.A.13\EDAETL\ETL_TABLE\ETL_TEST_INA_WAT_TO_XSIFF\../..\XdmLib\CustomFuction.py", line 631, in file2db_init
    log.error(ex, exc_info=True, stack_info=True)
2023-08-25 11:07:38.991 - CustomFuction [ERROR   ] local variable 'BadDie' referenced before assignment
Traceback (most recent call last):
  File "D:\Ina\ETL_XdmLib_2.A.13\ETL_XdmLib_2.A.13\EDAETL\ETL_TABLE\ETL_TEST_INA_WAT_TO_XSIFF\../..\XdmLib\CustomFuction.py", line 596, in file2db_init
    res = do_file(file_root_source_path,
  File "D:\Ina\ETL_XdmLib_2.A.13\ETL_XdmLib_2.A.13\EDAETL\ETL_TABLE\ETL_TEST_INA_WAT_TO_XSIFF\ETL_TXT_TO_XSIFF.py", line 279, in do_file
    raise ex
  File "D:\Ina\ETL_XdmLib_2.A.13\ETL_XdmLib_2.A.13\EDAETL\ETL_TABLE\ETL_TEST_INA_WAT_TO_XSIFF\ETL_TXT_TO_XSIFF.py", line 217, in do_file
    GrossDie = GoodDie+BadDie
UnboundLocalError: local variable 'BadDie' referenced before assignment
Stack (most recent call last):
  File "D:\Ina\ETL_XdmLib_2.A.13\ETL_XdmLib_2.A.13\EDAETL\ETL_TABLE\ETL_TEST_INA_WAT_TO_XSIFF\ETL_TXT_TO_XSIFF.py", line 397, in <module>
    XdmLib.CustomFuction.file2db_init(do_file, before_do_file, after_do_file,
  File "D:\Ina\ETL_XdmLib_2.A.13\ETL_XdmLib_2.A.13\EDAETL\ETL_TABLE\ETL_TEST_INA_WAT_TO_XSIFF\../..\XdmLib\CustomFuction.py", line 631, in file2db_init
    log.error(ex, exc_info=True, stack_info=True)
2023-08-25 11:43:43.841 - CustomFuction [ERROR   ] Length mismatch: Expected axis has 0 elements, new values have 6 elements
Traceback (most recent call last):
  File "D:\Ina\ETL_XdmLib_2.A.13\ETL_XdmLib_2.A.13\EDAETL\ETL_TABLE\ETL_TEST_INA_WAT_TO_XSIFF\../..\XdmLib\CustomFuction.py", line 596, in file2db_init
    res = do_file(file_root_source_path,
  File "D:\Ina\ETL_XdmLib_2.A.13\ETL_XdmLib_2.A.13\EDAETL\ETL_TABLE\ETL_TEST_INA_WAT_TO_XSIFF\ETL_TXT_TO_XSIFF.py", line 255, in do_file
    raise ex
  File "D:\Ina\ETL_XdmLib_2.A.13\ETL_XdmLib_2.A.13\EDAETL\ETL_TABLE\ETL_TEST_INA_WAT_TO_XSIFF\ETL_TXT_TO_XSIFF.py", line 225, in do_file
    data_df.columns = ["DieX", "DieY", "HBIN", "SBIN", "TouchdownNo", "DutNo"]
  File "D:\soft\anaconda3\lib\site-packages\pandas\core\generic.py", line 5588, in __setattr__
    return object.__setattr__(self, name, value)
  File "pandas\_libs\properties.pyx", line 70, in pandas._libs.properties.AxisProperty.__set__
  File "D:\soft\anaconda3\lib\site-packages\pandas\core\generic.py", line 769, in _set_axis
    self._mgr.set_axis(axis, labels)
  File "D:\soft\anaconda3\lib\site-packages\pandas\core\internals\managers.py", line 214, in set_axis
    self._validate_set_axis(axis, new_labels)
  File "D:\soft\anaconda3\lib\site-packages\pandas\core\internals\base.py", line 69, in _validate_set_axis
    raise ValueError(
ValueError: Length mismatch: Expected axis has 0 elements, new values have 6 elements
Stack (most recent call last):
  File "D:\Ina\ETL_XdmLib_2.A.13\ETL_XdmLib_2.A.13\EDAETL\ETL_TABLE\ETL_TEST_INA_WAT_TO_XSIFF\ETL_TXT_TO_XSIFF.py", line 373, in <module>
    XdmLib.CustomFuction.file2db_init(do_file, before_do_file, after_do_file,
  File "D:\Ina\ETL_XdmLib_2.A.13\ETL_XdmLib_2.A.13\EDAETL\ETL_TABLE\ETL_TEST_INA_WAT_TO_XSIFF\../..\XdmLib\CustomFuction.py", line 631, in file2db_init
    log.error(ex, exc_info=True, stack_info=True)
2023-08-25 11:46:55.818 - CustomFuction [ERROR   ] Length mismatch: Expected axis has 0 elements, new values have 6 elements
Traceback (most recent call last):
  File "D:\Ina\ETL_XdmLib_2.A.13\ETL_XdmLib_2.A.13\EDAETL\ETL_TABLE\ETL_TEST_INA_WAT_TO_XSIFF\../..\XdmLib\CustomFuction.py", line 596, in file2db_init
    res = do_file(file_root_source_path,
  File "D:/Ina/ETL_XdmLib_2.A.13/ETL_XdmLib_2.A.13/EDAETL/ETL_TABLE/ETL_TEST_INA_WAT_TO_XSIFF/ETL_TXT_TO_XSIFF.py", line 255, in do_file
    raise ex
  File "D:/Ina/ETL_XdmLib_2.A.13/ETL_XdmLib_2.A.13/EDAETL/ETL_TABLE/ETL_TEST_INA_WAT_TO_XSIFF/ETL_TXT_TO_XSIFF.py", line 231, in do_file
    'WaferNo': WaferNo,
  File "D:\soft\anaconda3\lib\site-packages\pandas\core\generic.py", line 5588, in __setattr__
    return object.__setattr__(self, name, value)
  File "pandas\_libs\properties.pyx", line 70, in pandas._libs.properties.AxisProperty.__set__
  File "D:\soft\anaconda3\lib\site-packages\pandas\core\generic.py", line 769, in _set_axis
    self._mgr.set_axis(axis, labels)
  File "D:\soft\anaconda3\lib\site-packages\pandas\core\internals\managers.py", line 214, in set_axis
    self._validate_set_axis(axis, new_labels)
  File "D:\soft\anaconda3\lib\site-packages\pandas\core\internals\base.py", line 69, in _validate_set_axis
    raise ValueError(
ValueError: Length mismatch: Expected axis has 0 elements, new values have 6 elements
Stack (most recent call last):
  File "D:\soft\PyCharm Community Edition 2022.1.3\plugins\python-ce\helpers\pydev\pydevd.py", line 2181, in <module>
    main()
  File "D:\soft\PyCharm Community Edition 2022.1.3\plugins\python-ce\helpers\pydev\pydevd.py", line 2172, in main
    globals = debugger.run(setup['file'], None, None, is_module)
  File "D:\soft\PyCharm Community Edition 2022.1.3\plugins\python-ce\helpers\pydev\pydevd.py", line 1484, in run
    return self._exec(is_module, entry_point_fn, module_name, file, globals, locals)
  File "D:\soft\PyCharm Community Edition 2022.1.3\plugins\python-ce\helpers\pydev\pydevd.py", line 1491, in _exec
    pydev_imports.execfile(file, globals, locals)  # execute the script
  File "D:\soft\PyCharm Community Edition 2022.1.3\plugins\python-ce\helpers\pydev\_pydev_imps\_pydev_execfile.py", line 18, in execfile
    exec(compile(contents+"\n", file, 'exec'), glob, loc)
  File "D:/Ina/ETL_XdmLib_2.A.13/ETL_XdmLib_2.A.13/EDAETL/ETL_TABLE/ETL_TEST_INA_WAT_TO_XSIFF/ETL_TXT_TO_XSIFF.py", line 373, in <module>
    XdmLib.CustomFuction.file2db_init(do_file, before_do_file, after_do_file,
  File "D:\Ina\ETL_XdmLib_2.A.13\ETL_XdmLib_2.A.13\EDAETL\ETL_TABLE\ETL_TEST_INA_WAT_TO_XSIFF\../..\XdmLib\CustomFuction.py", line 631, in file2db_init
    log.error(ex, exc_info=True, stack_info=True)
2023-08-25 11:57:12.224 - CustomFuction [ERROR   ] name 'tempValue' is not defined
Traceback (most recent call last):
  File "D:\Ina\ETL_XdmLib_2.A.13\ETL_XdmLib_2.A.13\EDAETL\ETL_TABLE\ETL_TEST_INA_WAT_TO_XSIFF\../..\XdmLib\CustomFuction.py", line 596, in file2db_init
    res = do_file(file_root_source_path,
  File "D:\Ina\ETL_XdmLib_2.A.13\ETL_XdmLib_2.A.13\EDAETL\ETL_TABLE\ETL_TEST_INA_WAT_TO_XSIFF\ETL_TXT_TO_XSIFF.py", line 256, in do_file
    raise ex
  File "D:\Ina\ETL_XdmLib_2.A.13\ETL_XdmLib_2.A.13\EDAETL\ETL_TABLE\ETL_TEST_INA_WAT_TO_XSIFF\ETL_TXT_TO_XSIFF.py", line 203, in do_file
    xyDict = {'DieX': colIndex, 'DieY': index, 'HBIN': tempDict[tempValue][1],
NameError: name 'tempValue' is not defined
Stack (most recent call last):
  File "D:\Ina\ETL_XdmLib_2.A.13\ETL_XdmLib_2.A.13\EDAETL\ETL_TABLE\ETL_TEST_INA_WAT_TO_XSIFF\ETL_TXT_TO_XSIFF.py", line 374, in <module>
    XdmLib.CustomFuction.file2db_init(do_file, before_do_file, after_do_file,
  File "D:\Ina\ETL_XdmLib_2.A.13\ETL_XdmLib_2.A.13\EDAETL\ETL_TABLE\ETL_TEST_INA_WAT_TO_XSIFF\../..\XdmLib\CustomFuction.py", line 631, in file2db_init
    log.error(ex, exc_info=True, stack_info=True)
2023-08-25 12:03:24.840 - CustomFuction [ERROR   ] '___'
Traceback (most recent call last):
  File "D:\Ina\ETL_XdmLib_2.A.13\ETL_XdmLib_2.A.13\EDAETL\ETL_TABLE\ETL_TEST_INA_WAT_TO_XSIFF\../..\XdmLib\CustomFuction.py", line 596, in file2db_init
    res = do_file(file_root_source_path,
  File "D:\Ina\ETL_XdmLib_2.A.13\ETL_XdmLib_2.A.13\EDAETL\ETL_TABLE\ETL_TEST_INA_WAT_TO_XSIFF\ETL_TXT_TO_XSIFF.py", line 262, in do_file
    raise ex
  File "D:\Ina\ETL_XdmLib_2.A.13\ETL_XdmLib_2.A.13\EDAETL\ETL_TABLE\ETL_TEST_INA_WAT_TO_XSIFF\ETL_TXT_TO_XSIFF.py", line 200, in do_file
    'HBIN': tempDict[tempValue][1],
KeyError: '___'
Stack (most recent call last):
  File "D:\Ina\ETL_XdmLib_2.A.13\ETL_XdmLib_2.A.13\EDAETL\ETL_TABLE\ETL_TEST_INA_WAT_TO_XSIFF\ETL_TXT_TO_XSIFF.py", line 380, in <module>
    XdmLib.CustomFuction.file2db_init(do_file, before_do_file, after_do_file,
  File "D:\Ina\ETL_XdmLib_2.A.13\ETL_XdmLib_2.A.13\EDAETL\ETL_TABLE\ETL_TEST_INA_WAT_TO_XSIFF\../..\XdmLib\CustomFuction.py", line 631, in file2db_init
    log.error(ex, exc_info=True, stack_info=True)
2023-08-25 13:39:19.571 - CustomFuction [ERROR   ] unhashable type: 'list'
Traceback (most recent call last):
  File "D:\Ina\ETL_XdmLib_2.A.13\ETL_XdmLib_2.A.13\EDAETL\ETL_TABLE\ETL_TEST_INA_WAT_TO_XSIFF\../..\XdmLib\CustomFuction.py", line 596, in file2db_init
    res = do_file(file_root_source_path,
  File "D:\Ina\ETL_XdmLib_2.A.13\ETL_XdmLib_2.A.13\EDAETL\ETL_TABLE\ETL_TEST_INA_WAT_TO_XSIFF\ETL_TXT_TO_XSIFF.py", line 315, in do_file
    raise ex
  File "D:\Ina\ETL_XdmLib_2.A.13\ETL_XdmLib_2.A.13\EDAETL\ETL_TABLE\ETL_TEST_INA_WAT_TO_XSIFF\ETL_TXT_TO_XSIFF.py", line 291, in do_file
    data_df = data_df.where(data_df.notnull(), None).drop_duplicates()
  File "D:\soft\anaconda3\lib\site-packages\pandas\util\_decorators.py", line 311, in wrapper
    return func(*args, **kwargs)
  File "D:\soft\anaconda3\lib\site-packages\pandas\core\frame.py", line 6116, in drop_duplicates
    duplicated = self.duplicated(subset, keep=keep)
  File "D:\soft\anaconda3\lib\site-packages\pandas\core\frame.py", line 6253, in duplicated
    labels, shape = map(list, zip(*map(f, vals)))
  File "D:\soft\anaconda3\lib\site-packages\pandas\core\frame.py", line 6226, in f
    labels, shape = algorithms.factorize(vals, size_hint=len(self))
  File "D:\soft\anaconda3\lib\site-packages\pandas\core\algorithms.py", line 763, in factorize
    codes, uniques = factorize_array(
  File "D:\soft\anaconda3\lib\site-packages\pandas\core\algorithms.py", line 560, in factorize_array
    uniques, codes = table.factorize(
  File "pandas\_libs\hashtable_class_helper.pxi", line 5394, in pandas._libs.hashtable.PyObjectHashTable.factorize
  File "pandas\_libs\hashtable_class_helper.pxi", line 5310, in pandas._libs.hashtable.PyObjectHashTable._unique
TypeError: unhashable type: 'list'
Stack (most recent call last):
  File "D:\Ina\ETL_XdmLib_2.A.13\ETL_XdmLib_2.A.13\EDAETL\ETL_TABLE\ETL_TEST_INA_WAT_TO_XSIFF\ETL_TXT_TO_XSIFF.py", line 375, in <module>
    XdmLib.CustomFuction.file2db_init(do_file, before_do_file, after_do_file,
  File "D:\Ina\ETL_XdmLib_2.A.13\ETL_XdmLib_2.A.13\EDAETL\ETL_TABLE\ETL_TEST_INA_WAT_TO_XSIFF\../..\XdmLib\CustomFuction.py", line 631, in file2db_init
    log.error(ex, exc_info=True, stack_info=True)
2023-08-25 13:40:12.063 - CustomFuction [ERROR   ] '0'
Traceback (most recent call last):
  File "D:\Ina\ETL_XdmLib_2.A.13\ETL_XdmLib_2.A.13\EDAETL\ETL_TABLE\ETL_TEST_INA_WAT_TO_XSIFF\../..\XdmLib\CustomFuction.py", line 596, in file2db_init
    res = do_file(file_root_source_path,
  File "D:\Ina\ETL_XdmLib_2.A.13\ETL_XdmLib_2.A.13\EDAETL\ETL_TABLE\ETL_TEST_INA_WAT_TO_XSIFF\ETL_TXT_TO_XSIFF.py", line 257, in do_file
    raise ex
  File "D:\Ina\ETL_XdmLib_2.A.13\ETL_XdmLib_2.A.13\EDAETL\ETL_TABLE\ETL_TEST_INA_WAT_TO_XSIFF\ETL_TXT_TO_XSIFF.py", line 204, in do_file
    xyDict = {'DieX': colIndex, 'DieY': index, 'HBIN': tempDict[tempValue],
KeyError: '0'
Stack (most recent call last):
  File "D:\Ina\ETL_XdmLib_2.A.13\ETL_XdmLib_2.A.13\EDAETL\ETL_TABLE\ETL_TEST_INA_WAT_TO_XSIFF\ETL_TXT_TO_XSIFF.py", line 375, in <module>
    XdmLib.CustomFuction.file2db_init(do_file, before_do_file, after_do_file,
  File "D:\Ina\ETL_XdmLib_2.A.13\ETL_XdmLib_2.A.13\EDAETL\ETL_TABLE\ETL_TEST_INA_WAT_TO_XSIFF\../..\XdmLib\CustomFuction.py", line 631, in file2db_init
    log.error(ex, exc_info=True, stack_info=True)
2023-08-25 13:48:22.297 - CustomFuction [ERROR   ] unhashable type: 'list'
Traceback (most recent call last):
  File "D:\Ina\ETL_XdmLib_2.A.13\ETL_XdmLib_2.A.13\EDAETL\ETL_TABLE\ETL_TEST_INA_WAT_TO_XSIFF\../..\XdmLib\CustomFuction.py", line 596, in file2db_init
    res = do_file(file_root_source_path,
  File "D:\Ina\ETL_XdmLib_2.A.13\ETL_XdmLib_2.A.13\EDAETL\ETL_TABLE\ETL_TEST_INA_WAT_TO_XSIFF\ETL_TXT_TO_XSIFF.py", line 315, in do_file
    raise ex
  File "D:\Ina\ETL_XdmLib_2.A.13\ETL_XdmLib_2.A.13\EDAETL\ETL_TABLE\ETL_TEST_INA_WAT_TO_XSIFF\ETL_TXT_TO_XSIFF.py", line 291, in do_file
    data_df = data_df.where(data_df.notnull(), None).drop_duplicates()
  File "D:\soft\anaconda3\lib\site-packages\pandas\util\_decorators.py", line 311, in wrapper
    return func(*args, **kwargs)
  File "D:\soft\anaconda3\lib\site-packages\pandas\core\frame.py", line 6116, in drop_duplicates
    duplicated = self.duplicated(subset, keep=keep)
  File "D:\soft\anaconda3\lib\site-packages\pandas\core\frame.py", line 6253, in duplicated
    labels, shape = map(list, zip(*map(f, vals)))
  File "D:\soft\anaconda3\lib\site-packages\pandas\core\frame.py", line 6226, in f
    labels, shape = algorithms.factorize(vals, size_hint=len(self))
  File "D:\soft\anaconda3\lib\site-packages\pandas\core\algorithms.py", line 763, in factorize
    codes, uniques = factorize_array(
  File "D:\soft\anaconda3\lib\site-packages\pandas\core\algorithms.py", line 560, in factorize_array
    uniques, codes = table.factorize(
  File "pandas\_libs\hashtable_class_helper.pxi", line 5394, in pandas._libs.hashtable.PyObjectHashTable.factorize
  File "pandas\_libs\hashtable_class_helper.pxi", line 5310, in pandas._libs.hashtable.PyObjectHashTable._unique
TypeError: unhashable type: 'list'
Stack (most recent call last):
  File "D:\Ina\ETL_XdmLib_2.A.13\ETL_XdmLib_2.A.13\EDAETL\ETL_TABLE\ETL_TEST_INA_WAT_TO_XSIFF\ETL_TXT_TO_XSIFF.py", line 375, in <module>
    XdmLib.CustomFuction.file2db_init(do_file, before_do_file, after_do_file,
  File "D:\Ina\ETL_XdmLib_2.A.13\ETL_XdmLib_2.A.13\EDAETL\ETL_TABLE\ETL_TEST_INA_WAT_TO_XSIFF\../..\XdmLib\CustomFuction.py", line 631, in file2db_init
    log.error(ex, exc_info=True, stack_info=True)
2023-08-25 13:55:11.664 - CustomFuction [ERROR   ] unhashable type: 'list'
Traceback (most recent call last):
  File "D:\Ina\ETL_XdmLib_2.A.13\ETL_XdmLib_2.A.13\EDAETL\ETL_TABLE\ETL_TEST_INA_WAT_TO_XSIFF\../..\XdmLib\CustomFuction.py", line 596, in file2db_init
    res = do_file(file_root_source_path,
  File "D:\Ina\ETL_XdmLib_2.A.13\ETL_XdmLib_2.A.13\EDAETL\ETL_TABLE\ETL_TEST_INA_WAT_TO_XSIFF\ETL_TXT_TO_XSIFF.py", line 316, in do_file
    raise ex
  File "D:\Ina\ETL_XdmLib_2.A.13\ETL_XdmLib_2.A.13\EDAETL\ETL_TABLE\ETL_TEST_INA_WAT_TO_XSIFF\ETL_TXT_TO_XSIFF.py", line 292, in do_file
    data_df = data_df.where(data_df.notnull(), None).drop_duplicates()
  File "D:\soft\anaconda3\lib\site-packages\pandas\util\_decorators.py", line 311, in wrapper
    return func(*args, **kwargs)
  File "D:\soft\anaconda3\lib\site-packages\pandas\core\frame.py", line 6116, in drop_duplicates
    duplicated = self.duplicated(subset, keep=keep)
  File "D:\soft\anaconda3\lib\site-packages\pandas\core\frame.py", line 6253, in duplicated
    labels, shape = map(list, zip(*map(f, vals)))
  File "D:\soft\anaconda3\lib\site-packages\pandas\core\frame.py", line 6226, in f
    labels, shape = algorithms.factorize(vals, size_hint=len(self))
  File "D:\soft\anaconda3\lib\site-packages\pandas\core\algorithms.py", line 763, in factorize
    codes, uniques = factorize_array(
  File "D:\soft\anaconda3\lib\site-packages\pandas\core\algorithms.py", line 560, in factorize_array
    uniques, codes = table.factorize(
  File "pandas\_libs\hashtable_class_helper.pxi", line 5394, in pandas._libs.hashtable.PyObjectHashTable.factorize
  File "pandas\_libs\hashtable_class_helper.pxi", line 5310, in pandas._libs.hashtable.PyObjectHashTable._unique
TypeError: unhashable type: 'list'
Stack (most recent call last):
  File "D:\Ina\ETL_XdmLib_2.A.13\ETL_XdmLib_2.A.13\EDAETL\ETL_TABLE\ETL_TEST_INA_WAT_TO_XSIFF\ETL_TXT_TO_XSIFF.py", line 376, in <module>
    XdmLib.CustomFuction.file2db_init(do_file, before_do_file, after_do_file,
  File "D:\Ina\ETL_XdmLib_2.A.13\ETL_XdmLib_2.A.13\EDAETL\ETL_TABLE\ETL_TEST_INA_WAT_TO_XSIFF\../..\XdmLib\CustomFuction.py", line 631, in file2db_init
    log.error(ex, exc_info=True, stack_info=True)
2023-08-25 13:56:09.027 - CustomFuction [ERROR   ] unhashable type: 'list'
Traceback (most recent call last):
  File "D:\Ina\ETL_XdmLib_2.A.13\ETL_XdmLib_2.A.13\EDAETL\ETL_TABLE\ETL_TEST_INA_WAT_TO_XSIFF\../..\XdmLib\CustomFuction.py", line 596, in file2db_init
    res = do_file(file_root_source_path,
  File "D:\Ina\ETL_XdmLib_2.A.13\ETL_XdmLib_2.A.13\EDAETL\ETL_TABLE\ETL_TEST_INA_WAT_TO_XSIFF\ETL_TXT_TO_XSIFF.py", line 316, in do_file
    raise ex
  File "D:\Ina\ETL_XdmLib_2.A.13\ETL_XdmLib_2.A.13\EDAETL\ETL_TABLE\ETL_TEST_INA_WAT_TO_XSIFF\ETL_TXT_TO_XSIFF.py", line 292, in do_file
    data_df = data_df.where(data_df.notnull(), None).drop_duplicates()
  File "D:\soft\anaconda3\lib\site-packages\pandas\util\_decorators.py", line 311, in wrapper
    return func(*args, **kwargs)
  File "D:\soft\anaconda3\lib\site-packages\pandas\core\frame.py", line 6116, in drop_duplicates
    duplicated = self.duplicated(subset, keep=keep)
  File "D:\soft\anaconda3\lib\site-packages\pandas\core\frame.py", line 6253, in duplicated
    labels, shape = map(list, zip(*map(f, vals)))
  File "D:\soft\anaconda3\lib\site-packages\pandas\core\frame.py", line 6226, in f
    labels, shape = algorithms.factorize(vals, size_hint=len(self))
  File "D:\soft\anaconda3\lib\site-packages\pandas\core\algorithms.py", line 763, in factorize
    codes, uniques = factorize_array(
  File "D:\soft\anaconda3\lib\site-packages\pandas\core\algorithms.py", line 560, in factorize_array
    uniques, codes = table.factorize(
  File "pandas\_libs\hashtable_class_helper.pxi", line 5394, in pandas._libs.hashtable.PyObjectHashTable.factorize
  File "pandas\_libs\hashtable_class_helper.pxi", line 5310, in pandas._libs.hashtable.PyObjectHashTable._unique
TypeError: unhashable type: 'list'
Stack (most recent call last):
  File "D:\Ina\ETL_XdmLib_2.A.13\ETL_XdmLib_2.A.13\EDAETL\ETL_TABLE\ETL_TEST_INA_WAT_TO_XSIFF\ETL_TXT_TO_XSIFF.py", line 376, in <module>
    XdmLib.CustomFuction.file2db_init(do_file, before_do_file, after_do_file,
  File "D:\Ina\ETL_XdmLib_2.A.13\ETL_XdmLib_2.A.13\EDAETL\ETL_TABLE\ETL_TEST_INA_WAT_TO_XSIFF\../..\XdmLib\CustomFuction.py", line 631, in file2db_init
    log.error(ex, exc_info=True, stack_info=True)
2023-08-25 14:32:42.820 - CustomFuction [ERROR   ] local variable 'data_df' referenced before assignment
Traceback (most recent call last):
  File "D:\Ina\ETL_XdmLib_2.A.13\ETL_XdmLib_2.A.13\EDAETL\ETL_TABLE\ETL_TEST_INA_WAT_TO_XSIFF\../..\XdmLib\CustomFuction.py", line 596, in file2db_init
    res = do_file(file_root_source_path,
  File "D:\Ina\ETL_XdmLib_2.A.13\ETL_XdmLib_2.A.13\EDAETL\ETL_TABLE\ETL_TEST_INA_WAT_TO_XSIFF\ETL_TXT_TO_XSIFF.py", line 245, in do_file
    raise ex
  File "D:\Ina\ETL_XdmLib_2.A.13\ETL_XdmLib_2.A.13\EDAETL\ETL_TABLE\ETL_TEST_INA_WAT_TO_XSIFF\ETL_TXT_TO_XSIFF.py", line 218, in do_file
    print(data_df)
UnboundLocalError: local variable 'data_df' referenced before assignment
Stack (most recent call last):
  File "D:\Ina\ETL_XdmLib_2.A.13\ETL_XdmLib_2.A.13\EDAETL\ETL_TABLE\ETL_TEST_INA_WAT_TO_XSIFF\ETL_TXT_TO_XSIFF.py", line 363, in <module>
    XdmLib.CustomFuction.file2db_init(do_file, before_do_file, after_do_file,
  File "D:\Ina\ETL_XdmLib_2.A.13\ETL_XdmLib_2.A.13\EDAETL\ETL_TABLE\ETL_TEST_INA_WAT_TO_XSIFF\../..\XdmLib\CustomFuction.py", line 631, in file2db_init
    log.error(ex, exc_info=True, stack_info=True)
2023-08-25 15:46:23.363 - CustomFuction [ERROR   ] 'VERSION'
Traceback (most recent call last):
  File "D:\Ina\ETL_XdmLib_2.A.13\ETL_XdmLib_2.A.13\EDAETL\ETL_TABLE\ETL_TEST_INA_WAT_TO_XSIFF\../..\XdmLib\CustomFuction.py", line 596, in file2db_init
    res = do_file(file_root_source_path,
  File "D:\Ina\ETL_XdmLib_2.A.13\ETL_XdmLib_2.A.13\EDAETL\ETL_TABLE\ETL_TEST_INA_WAT_TO_XSIFF\ETL_TXT_TO_XSIFF.py", line 311, in do_file
    raise ex
  File "D:\Ina\ETL_XdmLib_2.A.13\ETL_XdmLib_2.A.13\EDAETL\ETL_TABLE\ETL_TEST_INA_WAT_TO_XSIFF\ETL_TXT_TO_XSIFF.py", line 309, in do_file
    xsiff_file_name = export_cp_xsiff(xsiff_dict, config.XSIFF_FOLDER)
  File "D:\Ina\ETL_XdmLib_2.A.13\ETL_XdmLib_2.A.13\EDAETL\ETL_TABLE\ETL_TEST_INA_WAT_TO_XSIFF\ETL_TXT_TO_XSIFF.py", line 45, in export_cp_xsiff
    version_str = f"FileVersion={xsiff_dict['VERSION']}\n"
KeyError: 'VERSION'
Stack (most recent call last):
  File "D:\Ina\ETL_XdmLib_2.A.13\ETL_XdmLib_2.A.13\EDAETL\ETL_TABLE\ETL_TEST_INA_WAT_TO_XSIFF\ETL_TXT_TO_XSIFF.py", line 371, in <module>
    XdmLib.CustomFuction.file2db_init(do_file, before_do_file, after_do_file,
  File "D:\Ina\ETL_XdmLib_2.A.13\ETL_XdmLib_2.A.13\EDAETL\ETL_TABLE\ETL_TEST_INA_WAT_TO_XSIFF\../..\XdmLib\CustomFuction.py", line 631, in file2db_init
    log.error(ex, exc_info=True, stack_info=True)
2023-08-25 15:50:49.803 - CustomFuction [ERROR   ] 'VERSION'
Traceback (most recent call last):
  File "D:\Ina\ETL_XdmLib_2.A.13\ETL_XdmLib_2.A.13\EDAETL\ETL_TABLE\ETL_TEST_INA_WAT_TO_XSIFF\../..\XdmLib\CustomFuction.py", line 596, in file2db_init
    res = do_file(file_root_source_path,
  File "D:\Ina\ETL_XdmLib_2.A.13\ETL_XdmLib_2.A.13\EDAETL\ETL_TABLE\ETL_TEST_INA_WAT_TO_XSIFF\ETL_TXT_TO_XSIFF.py", line 311, in do_file
    raise ex
  File "D:\Ina\ETL_XdmLib_2.A.13\ETL_XdmLib_2.A.13\EDAETL\ETL_TABLE\ETL_TEST_INA_WAT_TO_XSIFF\ETL_TXT_TO_XSIFF.py", line 309, in do_file
    xsiff_file_name = export_cp_xsiff(xsiff_dict, config.XSIFF_FOLDER)
  File "D:\Ina\ETL_XdmLib_2.A.13\ETL_XdmLib_2.A.13\EDAETL\ETL_TABLE\ETL_TEST_INA_WAT_TO_XSIFF\ETL_TXT_TO_XSIFF.py", line 45, in export_cp_xsiff
    version_str = f"FileVersion={xsiff_dict['VERSION']}\n"
KeyError: 'VERSION'
Stack (most recent call last):
  File "D:\Ina\ETL_XdmLib_2.A.13\ETL_XdmLib_2.A.13\EDAETL\ETL_TABLE\ETL_TEST_INA_WAT_TO_XSIFF\ETL_TXT_TO_XSIFF.py", line 371, in <module>
    XdmLib.CustomFuction.file2db_init(do_file, before_do_file, after_do_file,
  File "D:\Ina\ETL_XdmLib_2.A.13\ETL_XdmLib_2.A.13\EDAETL\ETL_TABLE\ETL_TEST_INA_WAT_TO_XSIFF\../..\XdmLib\CustomFuction.py", line 631, in file2db_init
    log.error(ex, exc_info=True, stack_info=True)
