2023-08-24 14:04:06.561 - CustomFuction [ERROR   ] name 'bin_def_df' is not defined
Traceback (most recent call last):
  File "D:\Ina\ETL_XdmLib_2.A.13\ETL_XdmLib_2.A.13\EDAETL\ETL_TABLE\ETL_TEST_INA_WAT_TO_XSIFF\../..\XdmLib\CustomFuction.py", line 596, in file2db_init
    res = do_file(file_root_source_path,
  File "D:\Ina\ETL_XdmLib_2.A.13\ETL_XdmLib_2.A.13\EDAETL\ETL_TABLE\ETL_TEST_INA_WAT_TO_XSIFF\ETL_TXT_TO_XSIFF.py", line 183, in do_file
    raise ex
  File "D:\Ina\ETL_XdmLib_2.A.13\ETL_XdmLib_2.A.13\EDAETL\ETL_TABLE\ETL_TEST_INA_WAT_TO_XSIFF\ETL_TXT_TO_XSIFF.py", line 154, in do_file
    bin_def_df.columns = ["RecordType", "BinName", "BinType", "BinDesc"]
NameError: name 'bin_def_df' is not defined
Stack (most recent call last):
  File "D:\Ina\ETL_XdmLib_2.A.13\ETL_XdmLib_2.A.13\EDAETL\ETL_TABLE\ETL_TEST_INA_WAT_TO_XSIFF\ETL_TXT_TO_XSIFF.py", line 299, in <module>
    XdmLib.CustomFuction.file2db_init(do_file, before_do_file, after_do_file,
  File "D:\Ina\ETL_XdmLib_2.A.13\ETL_XdmLib_2.A.13\EDAETL\ETL_TABLE\ETL_TEST_INA_WAT_TO_XSIFF\../..\XdmLib\CustomFuction.py", line 631, in file2db_init
    log.error(ex, exc_info=True, stack_info=True)
2023-08-24 14:40:41.938 - CustomFuction [ERROR   ] local variable 'xyDict' referenced before assignment
Traceback (most recent call last):
  File "D:\Ina\ETL_XdmLib_2.A.13\ETL_XdmLib_2.A.13\EDAETL\ETL_TABLE\ETL_TEST_INA_WAT_TO_XSIFF\../..\XdmLib\CustomFuction.py", line 596, in file2db_init
    res = do_file(file_root_source_path,
  File "D:\Ina\ETL_XdmLib_2.A.13\ETL_XdmLib_2.A.13\EDAETL\ETL_TABLE\ETL_TEST_INA_WAT_TO_XSIFF\ETL_TXT_TO_XSIFF.py", line 219, in do_file
    raise ex
  File "D:\Ina\ETL_XdmLib_2.A.13\ETL_XdmLib_2.A.13\EDAETL\ETL_TABLE\ETL_TEST_INA_WAT_TO_XSIFF\ETL_TXT_TO_XSIFF.py", line 139, in do_file
    dataDict = {'HBIN':xyDict}
UnboundLocalError: local variable 'xyDict' referenced before assignment
Stack (most recent call last):
  File "D:\Ina\ETL_XdmLib_2.A.13\ETL_XdmLib_2.A.13\EDAETL\ETL_TABLE\ETL_TEST_INA_WAT_TO_XSIFF\ETL_TXT_TO_XSIFF.py", line 335, in <module>
    XdmLib.CustomFuction.file2db_init(do_file, before_do_file, after_do_file,
  File "D:\Ina\ETL_XdmLib_2.A.13\ETL_XdmLib_2.A.13\EDAETL\ETL_TABLE\ETL_TEST_INA_WAT_TO_XSIFF\../..\XdmLib\CustomFuction.py", line 631, in file2db_init
    log.error(ex, exc_info=True, stack_info=True)
2023-08-24 14:41:23.795 - CustomFuction [ERROR   ] 'str' object does not support item assignment
Traceback (most recent call last):
  File "D:\Ina\ETL_XdmLib_2.A.13\ETL_XdmLib_2.A.13\EDAETL\ETL_TABLE\ETL_TEST_INA_WAT_TO_XSIFF\../..\XdmLib\CustomFuction.py", line 596, in file2db_init
    res = do_file(file_root_source_path,
  File "D:\Ina\ETL_XdmLib_2.A.13\ETL_XdmLib_2.A.13\EDAETL\ETL_TABLE\ETL_TEST_INA_WAT_TO_XSIFF\ETL_TXT_TO_XSIFF.py", line 219, in do_file
    raise ex
  File "D:\Ina\ETL_XdmLib_2.A.13\ETL_XdmLib_2.A.13\EDAETL\ETL_TABLE\ETL_TEST_INA_WAT_TO_XSIFF\ETL_TXT_TO_XSIFF.py", line 191, in do_file
    dataDict['HBIN'][BinName]= xyDict
TypeError: 'str' object does not support item assignment
Stack (most recent call last):
  File "D:\Ina\ETL_XdmLib_2.A.13\ETL_XdmLib_2.A.13\EDAETL\ETL_TABLE\ETL_TEST_INA_WAT_TO_XSIFF\ETL_TXT_TO_XSIFF.py", line 335, in <module>
    XdmLib.CustomFuction.file2db_init(do_file, before_do_file, after_do_file,
  File "D:\Ina\ETL_XdmLib_2.A.13\ETL_XdmLib_2.A.13\EDAETL\ETL_TABLE\ETL_TEST_INA_WAT_TO_XSIFF\../..\XdmLib\CustomFuction.py", line 631, in file2db_init
    log.error(ex, exc_info=True, stack_info=True)
2023-08-24 14:49:20.980 - CustomFuction [ERROR   ] name 'xyDict' is not defined
Traceback (most recent call last):
  File "D:\Ina\ETL_XdmLib_2.A.13\ETL_XdmLib_2.A.13\EDAETL\ETL_TABLE\ETL_TEST_INA_WAT_TO_XSIFF\../..\XdmLib\CustomFuction.py", line 596, in file2db_init
    res = do_file(file_root_source_path,
  File "D:\Ina\ETL_XdmLib_2.A.13\ETL_XdmLib_2.A.13\EDAETL\ETL_TABLE\ETL_TEST_INA_WAT_TO_XSIFF\ETL_TXT_TO_XSIFF.py", line 219, in do_file
    raise ex
  File "D:\Ina\ETL_XdmLib_2.A.13\ETL_XdmLib_2.A.13\EDAETL\ETL_TABLE\ETL_TEST_INA_WAT_TO_XSIFF\ETL_TXT_TO_XSIFF.py", line 188, in do_file
    xyDict[str(item) + "_" + str(colIndex)] = {'x_temp': item, 'y_temp': colIndex}
NameError: name 'xyDict' is not defined
Stack (most recent call last):
  File "D:\Ina\ETL_XdmLib_2.A.13\ETL_XdmLib_2.A.13\EDAETL\ETL_TABLE\ETL_TEST_INA_WAT_TO_XSIFF\ETL_TXT_TO_XSIFF.py", line 335, in <module>
    XdmLib.CustomFuction.file2db_init(do_file, before_do_file, after_do_file,
  File "D:\Ina\ETL_XdmLib_2.A.13\ETL_XdmLib_2.A.13\EDAETL\ETL_TABLE\ETL_TEST_INA_WAT_TO_XSIFF\../..\XdmLib\CustomFuction.py", line 631, in file2db_init
    log.error(ex, exc_info=True, stack_info=True)
2023-08-24 15:12:49.048 - CustomFuction [ERROR   ] '30_3'
Traceback (most recent call last):
  File "D:\Ina\ETL_XdmLib_2.A.13\ETL_XdmLib_2.A.13\EDAETL\ETL_TABLE\ETL_TEST_INA_WAT_TO_XSIFF\../..\XdmLib\CustomFuction.py", line 596, in file2db_init
    res = do_file(file_root_source_path,
  File "D:\Ina\ETL_XdmLib_2.A.13\ETL_XdmLib_2.A.13\EDAETL\ETL_TABLE\ETL_TEST_INA_WAT_TO_XSIFF\ETL_TXT_TO_XSIFF.py", line 220, in do_file
    raise ex
  File "D:\Ina\ETL_XdmLib_2.A.13\ETL_XdmLib_2.A.13\EDAETL\ETL_TABLE\ETL_TEST_INA_WAT_TO_XSIFF\ETL_TXT_TO_XSIFF.py", line 191, in do_file
    print(xyDict['30_3'])
KeyError: '30_3'
Stack (most recent call last):
  File "D:\Ina\ETL_XdmLib_2.A.13\ETL_XdmLib_2.A.13\EDAETL\ETL_TABLE\ETL_TEST_INA_WAT_TO_XSIFF\ETL_TXT_TO_XSIFF.py", line 336, in <module>
    XdmLib.CustomFuction.file2db_init(do_file, before_do_file, after_do_file,
  File "D:\Ina\ETL_XdmLib_2.A.13\ETL_XdmLib_2.A.13\EDAETL\ETL_TABLE\ETL_TEST_INA_WAT_TO_XSIFF\../..\XdmLib\CustomFuction.py", line 631, in file2db_init
    log.error(ex, exc_info=True, stack_info=True)
2023-08-24 15:13:17.409 - CustomFuction [ERROR   ] '15_3'
Traceback (most recent call last):
  File "D:\Ina\ETL_XdmLib_2.A.13\ETL_XdmLib_2.A.13\EDAETL\ETL_TABLE\ETL_TEST_INA_WAT_TO_XSIFF\../..\XdmLib\CustomFuction.py", line 596, in file2db_init
    res = do_file(file_root_source_path,
  File "D:\Ina\ETL_XdmLib_2.A.13\ETL_XdmLib_2.A.13\EDAETL\ETL_TABLE\ETL_TEST_INA_WAT_TO_XSIFF\ETL_TXT_TO_XSIFF.py", line 220, in do_file
    raise ex
  File "D:\Ina\ETL_XdmLib_2.A.13\ETL_XdmLib_2.A.13\EDAETL\ETL_TABLE\ETL_TEST_INA_WAT_TO_XSIFF\ETL_TXT_TO_XSIFF.py", line 191, in do_file
    print(xyDict['15_3'])
KeyError: '15_3'
Stack (most recent call last):
  File "D:\Ina\ETL_XdmLib_2.A.13\ETL_XdmLib_2.A.13\EDAETL\ETL_TABLE\ETL_TEST_INA_WAT_TO_XSIFF\ETL_TXT_TO_XSIFF.py", line 336, in <module>
    XdmLib.CustomFuction.file2db_init(do_file, before_do_file, after_do_file,
  File "D:\Ina\ETL_XdmLib_2.A.13\ETL_XdmLib_2.A.13\EDAETL\ETL_TABLE\ETL_TEST_INA_WAT_TO_XSIFF\../..\XdmLib\CustomFuction.py", line 631, in file2db_init
    log.error(ex, exc_info=True, stack_info=True)
2023-08-24 15:13:39.692 - CustomFuction [ERROR   ] '15_3'
Traceback (most recent call last):
  File "D:\Ina\ETL_XdmLib_2.A.13\ETL_XdmLib_2.A.13\EDAETL\ETL_TABLE\ETL_TEST_INA_WAT_TO_XSIFF\../..\XdmLib\CustomFuction.py", line 596, in file2db_init
    res = do_file(file_root_source_path,
  File "D:\Ina\ETL_XdmLib_2.A.13\ETL_XdmLib_2.A.13\EDAETL\ETL_TABLE\ETL_TEST_INA_WAT_TO_XSIFF\ETL_TXT_TO_XSIFF.py", line 221, in do_file
    raise ex
  File "D:\Ina\ETL_XdmLib_2.A.13\ETL_XdmLib_2.A.13\EDAETL\ETL_TABLE\ETL_TEST_INA_WAT_TO_XSIFF\ETL_TXT_TO_XSIFF.py", line 192, in do_file
    print(xyDict['15_3'])
KeyError: '15_3'
Stack (most recent call last):
  File "D:\Ina\ETL_XdmLib_2.A.13\ETL_XdmLib_2.A.13\EDAETL\ETL_TABLE\ETL_TEST_INA_WAT_TO_XSIFF\ETL_TXT_TO_XSIFF.py", line 337, in <module>
    XdmLib.CustomFuction.file2db_init(do_file, before_do_file, after_do_file,
  File "D:\Ina\ETL_XdmLib_2.A.13\ETL_XdmLib_2.A.13\EDAETL\ETL_TABLE\ETL_TEST_INA_WAT_TO_XSIFF\../..\XdmLib\CustomFuction.py", line 631, in file2db_init
    log.error(ex, exc_info=True, stack_info=True)
2023-08-24 16:06:47.175 - CustomFuction [ERROR   ] '135_264'
Traceback (most recent call last):
  File "D:\Ina\ETL_XdmLib_2.A.13\ETL_XdmLib_2.A.13\EDAETL\ETL_TABLE\ETL_TEST_INA_WAT_TO_XSIFF\../..\XdmLib\CustomFuction.py", line 596, in file2db_init
    res = do_file(file_root_source_path,
  File "D:\Ina\ETL_XdmLib_2.A.13\ETL_XdmLib_2.A.13\EDAETL\ETL_TABLE\ETL_TEST_INA_WAT_TO_XSIFF\ETL_TXT_TO_XSIFF.py", line 231, in do_file
    raise ex
  File "D:\Ina\ETL_XdmLib_2.A.13\ETL_XdmLib_2.A.13\EDAETL\ETL_TABLE\ETL_TEST_INA_WAT_TO_XSIFF\ETL_TXT_TO_XSIFF.py", line 194, in do_file
    print(xyDict['135_264'])
KeyError: '135_264'
Stack (most recent call last):
  File "D:\Ina\ETL_XdmLib_2.A.13\ETL_XdmLib_2.A.13\EDAETL\ETL_TABLE\ETL_TEST_INA_WAT_TO_XSIFF\ETL_TXT_TO_XSIFF.py", line 347, in <module>
    XdmLib.CustomFuction.file2db_init(do_file, before_do_file, after_do_file,
  File "D:\Ina\ETL_XdmLib_2.A.13\ETL_XdmLib_2.A.13\EDAETL\ETL_TABLE\ETL_TEST_INA_WAT_TO_XSIFF\../..\XdmLib\CustomFuction.py", line 631, in file2db_init
    log.error(ex, exc_info=True, stack_info=True)
2023-08-24 16:08:19.751 - CustomFuction [ERROR   ] '135_264'
Traceback (most recent call last):
  File "D:\Ina\ETL_XdmLib_2.A.13\ETL_XdmLib_2.A.13\EDAETL\ETL_TABLE\ETL_TEST_INA_WAT_TO_XSIFF\../..\XdmLib\CustomFuction.py", line 596, in file2db_init
    res = do_file(file_root_source_path,
  File "D:\Ina\ETL_XdmLib_2.A.13\ETL_XdmLib_2.A.13\EDAETL\ETL_TABLE\ETL_TEST_INA_WAT_TO_XSIFF\ETL_TXT_TO_XSIFF.py", line 231, in do_file
    raise ex
  File "D:\Ina\ETL_XdmLib_2.A.13\ETL_XdmLib_2.A.13\EDAETL\ETL_TABLE\ETL_TEST_INA_WAT_TO_XSIFF\ETL_TXT_TO_XSIFF.py", line 194, in do_file
    print(xyDict['135_264'])
KeyError: '135_264'
Stack (most recent call last):
  File "D:\Ina\ETL_XdmLib_2.A.13\ETL_XdmLib_2.A.13\EDAETL\ETL_TABLE\ETL_TEST_INA_WAT_TO_XSIFF\ETL_TXT_TO_XSIFF.py", line 347, in <module>
    XdmLib.CustomFuction.file2db_init(do_file, before_do_file, after_do_file,
  File "D:\Ina\ETL_XdmLib_2.A.13\ETL_XdmLib_2.A.13\EDAETL\ETL_TABLE\ETL_TEST_INA_WAT_TO_XSIFF\../..\XdmLib\CustomFuction.py", line 631, in file2db_init
    log.error(ex, exc_info=True, stack_info=True)
2023-08-24 16:22:24.759 - CustomFuction [ERROR   ] 'value'
Traceback (most recent call last):
  File "D:\Ina\ETL_XdmLib_2.A.13\ETL_XdmLib_2.A.13\EDAETL\ETL_TABLE\ETL_TEST_INA_WAT_TO_XSIFF\../..\XdmLib\CustomFuction.py", line 596, in file2db_init
    res = do_file(file_root_source_path,
  File "D:\Ina\ETL_XdmLib_2.A.13\ETL_XdmLib_2.A.13\EDAETL\ETL_TABLE\ETL_TEST_INA_WAT_TO_XSIFF\ETL_TXT_TO_XSIFF.py", line 232, in do_file
    raise ex
  File "D:\Ina\ETL_XdmLib_2.A.13\ETL_XdmLib_2.A.13\EDAETL\ETL_TABLE\ETL_TEST_INA_WAT_TO_XSIFF\ETL_TXT_TO_XSIFF.py", line 195, in do_file
    print(xyDict['value'])
KeyError: 'value'
Stack (most recent call last):
  File "D:\Ina\ETL_XdmLib_2.A.13\ETL_XdmLib_2.A.13\EDAETL\ETL_TABLE\ETL_TEST_INA_WAT_TO_XSIFF\ETL_TXT_TO_XSIFF.py", line 348, in <module>
    XdmLib.CustomFuction.file2db_init(do_file, before_do_file, after_do_file,
  File "D:\Ina\ETL_XdmLib_2.A.13\ETL_XdmLib_2.A.13\EDAETL\ETL_TABLE\ETL_TEST_INA_WAT_TO_XSIFF\../..\XdmLib\CustomFuction.py", line 631, in file2db_init
    log.error(ex, exc_info=True, stack_info=True)
2023-08-24 16:44:23.161 - CustomFuction [ERROR   ] '___'
Traceback (most recent call last):
  File "D:\Ina\ETL_XdmLib_2.A.13\ETL_XdmLib_2.A.13\EDAETL\ETL_TABLE\ETL_TEST_INA_WAT_TO_XSIFF\../..\XdmLib\CustomFuction.py", line 596, in file2db_init
    res = do_file(file_root_source_path,
  File "D:\Ina\ETL_XdmLib_2.A.13\ETL_XdmLib_2.A.13\EDAETL\ETL_TABLE\ETL_TEST_INA_WAT_TO_XSIFF\ETL_TXT_TO_XSIFF.py", line 233, in do_file
    raise ex
  File "D:\Ina\ETL_XdmLib_2.A.13\ETL_XdmLib_2.A.13\EDAETL\ETL_TABLE\ETL_TEST_INA_WAT_TO_XSIFF\ETL_TXT_TO_XSIFF.py", line 195, in do_file
    print(tempDict[tempValue])
KeyError: '___'
Stack (most recent call last):
  File "D:\Ina\ETL_XdmLib_2.A.13\ETL_XdmLib_2.A.13\EDAETL\ETL_TABLE\ETL_TEST_INA_WAT_TO_XSIFF\ETL_TXT_TO_XSIFF.py", line 349, in <module>
    XdmLib.CustomFuction.file2db_init(do_file, before_do_file, after_do_file,
  File "D:\Ina\ETL_XdmLib_2.A.13\ETL_XdmLib_2.A.13\EDAETL\ETL_TABLE\ETL_TEST_INA_WAT_TO_XSIFF\../..\XdmLib\CustomFuction.py", line 631, in file2db_init
    log.error(ex, exc_info=True, stack_info=True)
2023-08-24 16:46:36.107 - CustomFuction [ERROR   ] '___'
Traceback (most recent call last):
  File "D:\Ina\ETL_XdmLib_2.A.13\ETL_XdmLib_2.A.13\EDAETL\ETL_TABLE\ETL_TEST_INA_WAT_TO_XSIFF\../..\XdmLib\CustomFuction.py", line 596, in file2db_init
    res = do_file(file_root_source_path,
  File "D:\Ina\ETL_XdmLib_2.A.13\ETL_XdmLib_2.A.13\EDAETL\ETL_TABLE\ETL_TEST_INA_WAT_TO_XSIFF\ETL_TXT_TO_XSIFF.py", line 236, in do_file
    raise ex
  File "D:\Ina\ETL_XdmLib_2.A.13\ETL_XdmLib_2.A.13\EDAETL\ETL_TABLE\ETL_TEST_INA_WAT_TO_XSIFF\ETL_TXT_TO_XSIFF.py", line 198, in do_file
    print(tempDict[tempValue])
KeyError: '___'
Stack (most recent call last):
  File "D:\Ina\ETL_XdmLib_2.A.13\ETL_XdmLib_2.A.13\EDAETL\ETL_TABLE\ETL_TEST_INA_WAT_TO_XSIFF\ETL_TXT_TO_XSIFF.py", line 352, in <module>
    XdmLib.CustomFuction.file2db_init(do_file, before_do_file, after_do_file,
  File "D:\Ina\ETL_XdmLib_2.A.13\ETL_XdmLib_2.A.13\EDAETL\ETL_TABLE\ETL_TEST_INA_WAT_TO_XSIFF\../..\XdmLib\CustomFuction.py", line 631, in file2db_init
    log.error(ex, exc_info=True, stack_info=True)
2023-08-24 16:56:45.964 - CustomFuction [ERROR   ] 'list' object has no attribute 'values'
Traceback (most recent call last):
  File "D:\Ina\ETL_XdmLib_2.A.13\ETL_XdmLib_2.A.13\EDAETL\ETL_TABLE\ETL_TEST_INA_WAT_TO_XSIFF\../..\XdmLib\CustomFuction.py", line 596, in file2db_init
    res = do_file(file_root_source_path,
  File "D:\Ina\ETL_XdmLib_2.A.13\ETL_XdmLib_2.A.13\EDAETL\ETL_TABLE\ETL_TEST_INA_WAT_TO_XSIFF\ETL_TXT_TO_XSIFF.py", line 240, in do_file
    raise ex
  File "D:\Ina\ETL_XdmLib_2.A.13\ETL_XdmLib_2.A.13\EDAETL\ETL_TABLE\ETL_TEST_INA_WAT_TO_XSIFF\ETL_TXT_TO_XSIFF.py", line 200, in do_file
    xyDict = list(xyDict.values())
AttributeError: 'list' object has no attribute 'values'
Stack (most recent call last):
  File "D:\Ina\ETL_XdmLib_2.A.13\ETL_XdmLib_2.A.13\EDAETL\ETL_TABLE\ETL_TEST_INA_WAT_TO_XSIFF\ETL_TXT_TO_XSIFF.py", line 356, in <module>
    XdmLib.CustomFuction.file2db_init(do_file, before_do_file, after_do_file,
  File "D:\Ina\ETL_XdmLib_2.A.13\ETL_XdmLib_2.A.13\EDAETL\ETL_TABLE\ETL_TEST_INA_WAT_TO_XSIFF\../..\XdmLib\CustomFuction.py", line 631, in file2db_init
    log.error(ex, exc_info=True, stack_info=True)
2023-08-24 17:00:54.729 - CustomFuction [ERROR   ] 'dict' object has no attribute 'tolist'
Traceback (most recent call last):
  File "D:\Ina\ETL_XdmLib_2.A.13\ETL_XdmLib_2.A.13\EDAETL\ETL_TABLE\ETL_TEST_INA_WAT_TO_XSIFF\../..\XdmLib\CustomFuction.py", line 596, in file2db_init
    res = do_file(file_root_source_path,
  File "D:\Ina\ETL_XdmLib_2.A.13\ETL_XdmLib_2.A.13\EDAETL\ETL_TABLE\ETL_TEST_INA_WAT_TO_XSIFF\ETL_TXT_TO_XSIFF.py", line 241, in do_file
    raise ex
  File "D:\Ina\ETL_XdmLib_2.A.13\ETL_XdmLib_2.A.13\EDAETL\ETL_TABLE\ETL_TEST_INA_WAT_TO_XSIFF\ETL_TXT_TO_XSIFF.py", line 200, in do_file
    xyDict = xyDict.tolist()
AttributeError: 'dict' object has no attribute 'tolist'
Stack (most recent call last):
  File "D:\Ina\ETL_XdmLib_2.A.13\ETL_XdmLib_2.A.13\EDAETL\ETL_TABLE\ETL_TEST_INA_WAT_TO_XSIFF\ETL_TXT_TO_XSIFF.py", line 357, in <module>
    XdmLib.CustomFuction.file2db_init(do_file, before_do_file, after_do_file,
  File "D:\Ina\ETL_XdmLib_2.A.13\ETL_XdmLib_2.A.13\EDAETL\ETL_TABLE\ETL_TEST_INA_WAT_TO_XSIFF\../..\XdmLib\CustomFuction.py", line 631, in file2db_init
    log.error(ex, exc_info=True, stack_info=True)
2023-08-24 17:07:34.707 - CustomFuction [ERROR   ] 'CpType'
Traceback (most recent call last):
  File "D:\Ina\ETL_XdmLib_2.A.13\ETL_XdmLib_2.A.13\EDAETL\ETL_TABLE\ETL_TEST_INA_WAT_TO_XSIFF\../..\XdmLib\CustomFuction.py", line 596, in file2db_init
    res = do_file(file_root_source_path,
  File "D:\Ina\ETL_XdmLib_2.A.13\ETL_XdmLib_2.A.13\EDAETL\ETL_TABLE\ETL_TEST_INA_WAT_TO_XSIFF\ETL_TXT_TO_XSIFF.py", line 297, in do_file
    raise ex
  File "D:\Ina\ETL_XdmLib_2.A.13\ETL_XdmLib_2.A.13\EDAETL\ETL_TABLE\ETL_TEST_INA_WAT_TO_XSIFF\ETL_TXT_TO_XSIFF.py", line 295, in do_file
    xsiff_file_name = export_cp_xsiff(xsiff_dict, config.XSIFF_FOLDER)
  File "D:\Ina\ETL_XdmLib_2.A.13\ETL_XdmLib_2.A.13\EDAETL\ETL_TABLE\ETL_TEST_INA_WAT_TO_XSIFF\ETL_TXT_TO_XSIFF.py", line 46, in export_cp_xsiff
    file_name = f"CP_{header['Product']}_{header['Lot']}_{header['CpType']}_{time.strftime('%Y%m%d%H%M%S', time.strptime(header['MeasTime'], '%Y-%m-%d %H:%M:%S'))}.xsiff"
KeyError: 'CpType'
Stack (most recent call last):
  File "D:\Ina\ETL_XdmLib_2.A.13\ETL_XdmLib_2.A.13\EDAETL\ETL_TABLE\ETL_TEST_INA_WAT_TO_XSIFF\ETL_TXT_TO_XSIFF.py", line 357, in <module>
    XdmLib.CustomFuction.file2db_init(do_file, before_do_file, after_do_file,
  File "D:\Ina\ETL_XdmLib_2.A.13\ETL_XdmLib_2.A.13\EDAETL\ETL_TABLE\ETL_TEST_INA_WAT_TO_XSIFF\../..\XdmLib\CustomFuction.py", line 631, in file2db_init
    log.error(ex, exc_info=True, stack_info=True)
2023-08-24 17:12:15.784 - CustomFuction [ERROR   ] time data '2023/8/2 17:41:49' does not match format '%Y-%m-%d %H:%M:%S'
Traceback (most recent call last):
  File "D:\Ina\ETL_XdmLib_2.A.13\ETL_XdmLib_2.A.13\EDAETL\ETL_TABLE\ETL_TEST_INA_WAT_TO_XSIFF\../..\XdmLib\CustomFuction.py", line 596, in file2db_init
    res = do_file(file_root_source_path,
  File "D:\Ina\ETL_XdmLib_2.A.13\ETL_XdmLib_2.A.13\EDAETL\ETL_TABLE\ETL_TEST_INA_WAT_TO_XSIFF\ETL_TXT_TO_XSIFF.py", line 297, in do_file
    raise ex
  File "D:\Ina\ETL_XdmLib_2.A.13\ETL_XdmLib_2.A.13\EDAETL\ETL_TABLE\ETL_TEST_INA_WAT_TO_XSIFF\ETL_TXT_TO_XSIFF.py", line 295, in do_file
    xsiff_file_name = export_cp_xsiff(xsiff_dict, config.XSIFF_FOLDER)
  File "D:\Ina\ETL_XdmLib_2.A.13\ETL_XdmLib_2.A.13\EDAETL\ETL_TABLE\ETL_TEST_INA_WAT_TO_XSIFF\ETL_TXT_TO_XSIFF.py", line 46, in export_cp_xsiff
    file_name = f"CP_{header['Product']}_{header['Lot']}_{header['CpType']}_{time.strftime('%Y%m%d%H%M%S', time.strptime(header['MeasTime'], '%Y-%m-%d %H:%M:%S'))}.xsiff"
  File "D:\soft\anaconda3\lib\_strptime.py", line 562, in _strptime_time
    tt = _strptime(data_string, format)[0]
  File "D:\soft\anaconda3\lib\_strptime.py", line 349, in _strptime
    raise ValueError("time data %r does not match format %r" %
ValueError: time data '2023/8/2 17:41:49' does not match format '%Y-%m-%d %H:%M:%S'
Stack (most recent call last):
  File "D:\Ina\ETL_XdmLib_2.A.13\ETL_XdmLib_2.A.13\EDAETL\ETL_TABLE\ETL_TEST_INA_WAT_TO_XSIFF\ETL_TXT_TO_XSIFF.py", line 357, in <module>
    XdmLib.CustomFuction.file2db_init(do_file, before_do_file, after_do_file,
  File "D:\Ina\ETL_XdmLib_2.A.13\ETL_XdmLib_2.A.13\EDAETL\ETL_TABLE\ETL_TEST_INA_WAT_TO_XSIFF\../..\XdmLib\CustomFuction.py", line 631, in file2db_init
    log.error(ex, exc_info=True, stack_info=True)
2023-08-24 17:28:45.827 - CustomFuction [ERROR   ] 'StringMethods' object has no attribute 'cuount'
Traceback (most recent call last):
  File "D:\Ina\ETL_XdmLib_2.A.13\ETL_XdmLib_2.A.13\EDAETL\ETL_TABLE\ETL_TEST_INA_WAT_TO_XSIFF\../..\XdmLib\CustomFuction.py", line 596, in file2db_init
    res = do_file(file_root_source_path,
  File "D:/Ina/ETL_XdmLib_2.A.13/ETL_XdmLib_2.A.13/EDAETL/ETL_TABLE/ETL_TEST_INA_WAT_TO_XSIFF/ETL_TXT_TO_XSIFF.py", line 246, in do_file
    raise ex
  File "D:/Ina/ETL_XdmLib_2.A.13/ETL_XdmLib_2.A.13/EDAETL/ETL_TABLE/ETL_TEST_INA_WAT_TO_XSIFF/ETL_TXT_TO_XSIFF.py", line 127, in do_file
    GoodDie = (DataDF[0].str.cuount('000')).sum()
AttributeError: 'StringMethods' object has no attribute 'cuount'
Stack (most recent call last):
  File "D:\soft\PyCharm Community Edition 2022.1.3\plugins\python-ce\helpers\pydev\pydevd.py", line 2181, in <module>
    main()
  File "D:\soft\PyCharm Community Edition 2022.1.3\plugins\python-ce\helpers\pydev\pydevd.py", line 2172, in main
    globals = debugger.run(setup['file'], None, None, is_module)
  File "D:\soft\PyCharm Community Edition 2022.1.3\plugins\python-ce\helpers\pydev\pydevd.py", line 1484, in run
    return self._exec(is_module, entry_point_fn, module_name, file, globals, locals)
  File "D:\soft\PyCharm Community Edition 2022.1.3\plugins\python-ce\helpers\pydev\pydevd.py", line 1491, in _exec
    pydev_imports.execfile(file, globals, locals)  # execute the script
  File "D:\soft\PyCharm Community Edition 2022.1.3\plugins\python-ce\helpers\pydev\_pydev_imps\_pydev_execfile.py", line 18, in execfile
    exec(compile(contents+"\n", file, 'exec'), glob, loc)
  File "D:/Ina/ETL_XdmLib_2.A.13/ETL_XdmLib_2.A.13/EDAETL/ETL_TABLE/ETL_TEST_INA_WAT_TO_XSIFF/ETL_TXT_TO_XSIFF.py", line 362, in <module>
    XdmLib.CustomFuction.file2db_init(do_file, before_do_file, after_do_file,
  File "D:\Ina\ETL_XdmLib_2.A.13\ETL_XdmLib_2.A.13\EDAETL\ETL_TABLE\ETL_TEST_INA_WAT_TO_XSIFF\../..\XdmLib\CustomFuction.py", line 631, in file2db_init
    log.error(ex, exc_info=True, stack_info=True)
2023-08-24 17:29:47.209 - CustomFuction [ERROR   ] 'StringMethods' object has no attribute 'cuount'
Traceback (most recent call last):
  File "D:\Ina\ETL_XdmLib_2.A.13\ETL_XdmLib_2.A.13\EDAETL\ETL_TABLE\ETL_TEST_INA_WAT_TO_XSIFF\../..\XdmLib\CustomFuction.py", line 596, in file2db_init
    res = do_file(file_root_source_path,
  File "D:\Ina\ETL_XdmLib_2.A.13\ETL_XdmLib_2.A.13\EDAETL\ETL_TABLE\ETL_TEST_INA_WAT_TO_XSIFF\ETL_TXT_TO_XSIFF.py", line 246, in do_file
    raise ex
  File "D:\Ina\ETL_XdmLib_2.A.13\ETL_XdmLib_2.A.13\EDAETL\ETL_TABLE\ETL_TEST_INA_WAT_TO_XSIFF\ETL_TXT_TO_XSIFF.py", line 127, in do_file
    GoodDie = (DataDF[0].str.cuount('000')).sum()
AttributeError: 'StringMethods' object has no attribute 'cuount'
Stack (most recent call last):
  File "D:\Ina\ETL_XdmLib_2.A.13\ETL_XdmLib_2.A.13\EDAETL\ETL_TABLE\ETL_TEST_INA_WAT_TO_XSIFF\ETL_TXT_TO_XSIFF.py", line 362, in <module>
    XdmLib.CustomFuction.file2db_init(do_file, before_do_file, after_do_file,
  File "D:\Ina\ETL_XdmLib_2.A.13\ETL_XdmLib_2.A.13\EDAETL\ETL_TABLE\ETL_TEST_INA_WAT_TO_XSIFF\../..\XdmLib\CustomFuction.py", line 631, in file2db_init
    log.error(ex, exc_info=True, stack_info=True)
2023-08-24 17:33:15.329 - CustomFuction [ERROR   ] 'StringMethods' object has no attribute 'cuount'
Traceback (most recent call last):
  File "D:\Ina\ETL_XdmLib_2.A.13\ETL_XdmLib_2.A.13\EDAETL\ETL_TABLE\ETL_TEST_INA_WAT_TO_XSIFF\../..\XdmLib\CustomFuction.py", line 596, in file2db_init
    res = do_file(file_root_source_path,
  File "D:\Ina\ETL_XdmLib_2.A.13\ETL_XdmLib_2.A.13\EDAETL\ETL_TABLE\ETL_TEST_INA_WAT_TO_XSIFF\ETL_TXT_TO_XSIFF.py", line 246, in do_file
    raise ex
  File "D:\Ina\ETL_XdmLib_2.A.13\ETL_XdmLib_2.A.13\EDAETL\ETL_TABLE\ETL_TEST_INA_WAT_TO_XSIFF\ETL_TXT_TO_XSIFF.py", line 127, in do_file
    GoodDie = (DataDFCount.str.cuount('000')).sum()
AttributeError: 'StringMethods' object has no attribute 'cuount'
Stack (most recent call last):
  File "D:\Ina\ETL_XdmLib_2.A.13\ETL_XdmLib_2.A.13\EDAETL\ETL_TABLE\ETL_TEST_INA_WAT_TO_XSIFF\ETL_TXT_TO_XSIFF.py", line 362, in <module>
    XdmLib.CustomFuction.file2db_init(do_file, before_do_file, after_do_file,
  File "D:\Ina\ETL_XdmLib_2.A.13\ETL_XdmLib_2.A.13\EDAETL\ETL_TABLE\ETL_TEST_INA_WAT_TO_XSIFF\../..\XdmLib\CustomFuction.py", line 631, in file2db_init
    log.error(ex, exc_info=True, stack_info=True)
2023-08-24 17:46:25.976 - CustomFuction [ERROR   ] local variable 'TotalDie' referenced before assignment
Traceback (most recent call last):
  File "D:\Ina\ETL_XdmLib_2.A.13\ETL_XdmLib_2.A.13\EDAETL\ETL_TABLE\ETL_TEST_INA_WAT_TO_XSIFF\../..\XdmLib\CustomFuction.py", line 596, in file2db_init
    res = do_file(file_root_source_path,
  File "D:\Ina\ETL_XdmLib_2.A.13\ETL_XdmLib_2.A.13\EDAETL\ETL_TABLE\ETL_TEST_INA_WAT_TO_XSIFF\ETL_TXT_TO_XSIFF.py", line 250, in do_file
    raise ex
  File "D:\Ina\ETL_XdmLib_2.A.13\ETL_XdmLib_2.A.13\EDAETL\ETL_TABLE\ETL_TEST_INA_WAT_TO_XSIFF\ETL_TXT_TO_XSIFF.py", line 207, in do_file
    TotalDie += 1
UnboundLocalError: local variable 'TotalDie' referenced before assignment
Stack (most recent call last):
  File "D:\Ina\ETL_XdmLib_2.A.13\ETL_XdmLib_2.A.13\EDAETL\ETL_TABLE\ETL_TEST_INA_WAT_TO_XSIFF\ETL_TXT_TO_XSIFF.py", line 366, in <module>
    XdmLib.CustomFuction.file2db_init(do_file, before_do_file, after_do_file,
  File "D:\Ina\ETL_XdmLib_2.A.13\ETL_XdmLib_2.A.13\EDAETL\ETL_TABLE\ETL_TEST_INA_WAT_TO_XSIFF\../..\XdmLib\CustomFuction.py", line 631, in file2db_init
    log.error(ex, exc_info=True, stack_info=True)
2023-08-24 17:47:30.713 - CustomFuction [ERROR   ] 'NoneType' object is not subscriptable
Traceback (most recent call last):
  File "D:\Ina\ETL_XdmLib_2.A.13\ETL_XdmLib_2.A.13\EDAETL\ETL_TABLE\ETL_TEST_INA_WAT_TO_XSIFF\../..\XdmLib\CustomFuction.py", line 598, in file2db_init
    analysis_res.append(res['data'])
TypeError: 'NoneType' object is not subscriptable
Stack (most recent call last):
  File "D:\Ina\ETL_XdmLib_2.A.13\ETL_XdmLib_2.A.13\EDAETL\ETL_TABLE\ETL_TEST_INA_WAT_TO_XSIFF\ETL_TXT_TO_XSIFF.py", line 367, in <module>
    XdmLib.CustomFuction.file2db_init(do_file, before_do_file, after_do_file,
  File "D:\Ina\ETL_XdmLib_2.A.13\ETL_XdmLib_2.A.13\EDAETL\ETL_TABLE\ETL_TEST_INA_WAT_TO_XSIFF\../..\XdmLib\CustomFuction.py", line 631, in file2db_init
    log.error(ex, exc_info=True, stack_info=True)
2023-08-24 17:51:07.211 - CustomFuction [ERROR   ] 'NoneType' object is not subscriptable
Traceback (most recent call last):
  File "D:\Ina\ETL_XdmLib_2.A.13\ETL_XdmLib_2.A.13\EDAETL\ETL_TABLE\ETL_TEST_INA_WAT_TO_XSIFF\../..\XdmLib\CustomFuction.py", line 598, in file2db_init
    analysis_res.append(res['data'])
TypeError: 'NoneType' object is not subscriptable
Stack (most recent call last):
  File "D:\Ina\ETL_XdmLib_2.A.13\ETL_XdmLib_2.A.13\EDAETL\ETL_TABLE\ETL_TEST_INA_WAT_TO_XSIFF\ETL_TXT_TO_XSIFF.py", line 367, in <module>
    XdmLib.CustomFuction.file2db_init(do_file, before_do_file, after_do_file,
  File "D:\Ina\ETL_XdmLib_2.A.13\ETL_XdmLib_2.A.13\EDAETL\ETL_TABLE\ETL_TEST_INA_WAT_TO_XSIFF\../..\XdmLib\CustomFuction.py", line 631, in file2db_init
    log.error(ex, exc_info=True, stack_info=True)
2023-08-24 18:10:39.318 - CustomFuction [ERROR   ] 'NoneType' object is not subscriptable
Traceback (most recent call last):
  File "D:\Ina\ETL_XdmLib_2.A.13\ETL_XdmLib_2.A.13\EDAETL\ETL_TABLE\ETL_TEST_INA_WAT_TO_XSIFF\../..\XdmLib\CustomFuction.py", line 598, in file2db_init
    analysis_res.append(res['data'])
TypeError: 'NoneType' object is not subscriptable
Stack (most recent call last):
  File "D:\Ina\ETL_XdmLib_2.A.13\ETL_XdmLib_2.A.13\EDAETL\ETL_TABLE\ETL_TEST_INA_WAT_TO_XSIFF\ETL_TXT_TO_XSIFF.py", line 367, in <module>
    XdmLib.CustomFuction.file2db_init(do_file, before_do_file, after_do_file,
  File "D:\Ina\ETL_XdmLib_2.A.13\ETL_XdmLib_2.A.13\EDAETL\ETL_TABLE\ETL_TEST_INA_WAT_TO_XSIFF\../..\XdmLib\CustomFuction.py", line 631, in file2db_init
    log.error(ex, exc_info=True, stack_info=True)
2023-08-24 18:45:03.575 - CustomFuction [ERROR   ] local variable 'bin_def_df' referenced before assignment
Traceback (most recent call last):
  File "D:\Ina\ETL_XdmLib_2.A.13\ETL_XdmLib_2.A.13\EDAETL\ETL_TABLE\ETL_TEST_INA_WAT_TO_XSIFF\../..\XdmLib\CustomFuction.py", line 596, in file2db_init
    res = do_file(file_root_source_path,
  File "D:\Ina\ETL_XdmLib_2.A.13\ETL_XdmLib_2.A.13\EDAETL\ETL_TABLE\ETL_TEST_INA_WAT_TO_XSIFF\ETL_TXT_TO_XSIFF.py", line 243, in do_file
    raise ex
  File "D:\Ina\ETL_XdmLib_2.A.13\ETL_XdmLib_2.A.13\EDAETL\ETL_TABLE\ETL_TEST_INA_WAT_TO_XSIFF\ETL_TXT_TO_XSIFF.py", line 174, in do_file
    print(bin_def_df)
UnboundLocalError: local variable 'bin_def_df' referenced before assignment
Stack (most recent call last):
  File "D:\Ina\ETL_XdmLib_2.A.13\ETL_XdmLib_2.A.13\EDAETL\ETL_TABLE\ETL_TEST_INA_WAT_TO_XSIFF\ETL_TXT_TO_XSIFF.py", line 360, in <module>
    XdmLib.CustomFuction.file2db_init(do_file, before_do_file, after_do_file,
  File "D:\Ina\ETL_XdmLib_2.A.13\ETL_XdmLib_2.A.13\EDAETL\ETL_TABLE\ETL_TEST_INA_WAT_TO_XSIFF\../..\XdmLib\CustomFuction.py", line 631, in file2db_init
    log.error(ex, exc_info=True, stack_info=True)
2023-08-24 19:07:50.204 - CustomFuction [ERROR   ] Shape of passed values is (6, 1), indices imply (6, 6)
Traceback (most recent call last):
  File "D:\Ina\ETL_XdmLib_2.A.13\ETL_XdmLib_2.A.13\EDAETL\ETL_TABLE\ETL_TEST_INA_WAT_TO_XSIFF\../..\XdmLib\CustomFuction.py", line 596, in file2db_init
    res = do_file(file_root_source_path,
  File "D:\Ina\ETL_XdmLib_2.A.13\ETL_XdmLib_2.A.13\EDAETL\ETL_TABLE\ETL_TEST_INA_WAT_TO_XSIFF\ETL_TXT_TO_XSIFF.py", line 260, in do_file
    raise ex
  File "D:\Ina\ETL_XdmLib_2.A.13\ETL_XdmLib_2.A.13\EDAETL\ETL_TABLE\ETL_TEST_INA_WAT_TO_XSIFF\ETL_TXT_TO_XSIFF.py", line 213, in do_file
    data_df = pd.DataFrame(data=xyDict,columns=["DieX","DieY","HBIN","SBIN","TouchdownNo","DutNo"], dtype=object)
  File "D:\soft\anaconda3\lib\site-packages\pandas\core\frame.py", line 737, in __init__
    mgr = ndarray_to_mgr(
  File "D:\soft\anaconda3\lib\site-packages\pandas\core\internals\construction.py", line 351, in ndarray_to_mgr
    _check_values_indices_shape_match(values, index, columns)
  File "D:\soft\anaconda3\lib\site-packages\pandas\core\internals\construction.py", line 422, in _check_values_indices_shape_match
    raise ValueError(f"Shape of passed values is {passed}, indices imply {implied}")
ValueError: Shape of passed values is (6, 1), indices imply (6, 6)
Stack (most recent call last):
  File "D:\Ina\ETL_XdmLib_2.A.13\ETL_XdmLib_2.A.13\EDAETL\ETL_TABLE\ETL_TEST_INA_WAT_TO_XSIFF\ETL_TXT_TO_XSIFF.py", line 378, in <module>
    XdmLib.CustomFuction.file2db_init(do_file, before_do_file, after_do_file,
  File "D:\Ina\ETL_XdmLib_2.A.13\ETL_XdmLib_2.A.13\EDAETL\ETL_TABLE\ETL_TEST_INA_WAT_TO_XSIFF\../..\XdmLib\CustomFuction.py", line 631, in file2db_init
    log.error(ex, exc_info=True, stack_info=True)
2023-08-24 19:12:26.328 - CustomFuction [ERROR   ] Shape of passed values is (6, 1), indices imply (6, 6)
Traceback (most recent call last):
  File "D:\Ina\ETL_XdmLib_2.A.13\ETL_XdmLib_2.A.13\EDAETL\ETL_TABLE\ETL_TEST_INA_WAT_TO_XSIFF\../..\XdmLib\CustomFuction.py", line 596, in file2db_init
    res = do_file(file_root_source_path,
  File "D:\Ina\ETL_XdmLib_2.A.13\ETL_XdmLib_2.A.13\EDAETL\ETL_TABLE\ETL_TEST_INA_WAT_TO_XSIFF\ETL_TXT_TO_XSIFF.py", line 260, in do_file
    raise ex
  File "D:\Ina\ETL_XdmLib_2.A.13\ETL_XdmLib_2.A.13\EDAETL\ETL_TABLE\ETL_TEST_INA_WAT_TO_XSIFF\ETL_TXT_TO_XSIFF.py", line 213, in do_file
    data_df = pd.DataFrame(data=xyDict,columns=[["DieX","DieY","HBIN","SBIN","TouchdownNo","DutNo"]], dtype=object)
  File "D:\soft\anaconda3\lib\site-packages\pandas\core\frame.py", line 737, in __init__
    mgr = ndarray_to_mgr(
  File "D:\soft\anaconda3\lib\site-packages\pandas\core\internals\construction.py", line 351, in ndarray_to_mgr
    _check_values_indices_shape_match(values, index, columns)
  File "D:\soft\anaconda3\lib\site-packages\pandas\core\internals\construction.py", line 422, in _check_values_indices_shape_match
    raise ValueError(f"Shape of passed values is {passed}, indices imply {implied}")
ValueError: Shape of passed values is (6, 1), indices imply (6, 6)
Stack (most recent call last):
  File "D:\Ina\ETL_XdmLib_2.A.13\ETL_XdmLib_2.A.13\EDAETL\ETL_TABLE\ETL_TEST_INA_WAT_TO_XSIFF\ETL_TXT_TO_XSIFF.py", line 378, in <module>
    XdmLib.CustomFuction.file2db_init(do_file, before_do_file, after_do_file,
  File "D:\Ina\ETL_XdmLib_2.A.13\ETL_XdmLib_2.A.13\EDAETL\ETL_TABLE\ETL_TEST_INA_WAT_TO_XSIFF\../..\XdmLib\CustomFuction.py", line 631, in file2db_init
    log.error(ex, exc_info=True, stack_info=True)
2023-08-24 19:13:47.280 - CustomFuction [ERROR   ] Length mismatch: Expected axis has 1 elements, new values have 6 elements
Traceback (most recent call last):
  File "D:\Ina\ETL_XdmLib_2.A.13\ETL_XdmLib_2.A.13\EDAETL\ETL_TABLE\ETL_TEST_INA_WAT_TO_XSIFF\../..\XdmLib\CustomFuction.py", line 596, in file2db_init
    res = do_file(file_root_source_path,
  File "D:\Ina\ETL_XdmLib_2.A.13\ETL_XdmLib_2.A.13\EDAETL\ETL_TABLE\ETL_TEST_INA_WAT_TO_XSIFF\ETL_TXT_TO_XSIFF.py", line 261, in do_file
    raise ex
  File "D:\Ina\ETL_XdmLib_2.A.13\ETL_XdmLib_2.A.13\EDAETL\ETL_TABLE\ETL_TEST_INA_WAT_TO_XSIFF\ETL_TXT_TO_XSIFF.py", line 214, in do_file
    data_df.columns = ["DieX", "DieY", "HBIN", "SBIN", "TouchdownNo", "DutNo"]
  File "D:\soft\anaconda3\lib\site-packages\pandas\core\generic.py", line 5588, in __setattr__
    return object.__setattr__(self, name, value)
  File "pandas\_libs\properties.pyx", line 70, in pandas._libs.properties.AxisProperty.__set__
  File "D:\soft\anaconda3\lib\site-packages\pandas\core\generic.py", line 769, in _set_axis
    self._mgr.set_axis(axis, labels)
  File "D:\soft\anaconda3\lib\site-packages\pandas\core\internals\managers.py", line 214, in set_axis
    self._validate_set_axis(axis, new_labels)
  File "D:\soft\anaconda3\lib\site-packages\pandas\core\internals\base.py", line 69, in _validate_set_axis
    raise ValueError(
ValueError: Length mismatch: Expected axis has 1 elements, new values have 6 elements
Stack (most recent call last):
  File "D:\Ina\ETL_XdmLib_2.A.13\ETL_XdmLib_2.A.13\EDAETL\ETL_TABLE\ETL_TEST_INA_WAT_TO_XSIFF\ETL_TXT_TO_XSIFF.py", line 379, in <module>
    XdmLib.CustomFuction.file2db_init(do_file, before_do_file, after_do_file,
  File "D:\Ina\ETL_XdmLib_2.A.13\ETL_XdmLib_2.A.13\EDAETL\ETL_TABLE\ETL_TEST_INA_WAT_TO_XSIFF\../..\XdmLib\CustomFuction.py", line 631, in file2db_init
    log.error(ex, exc_info=True, stack_info=True)
2023-08-24 19:15:28.687 - CustomFuction [ERROR   ] local variable 'data_df' referenced before assignment
Traceback (most recent call last):
  File "D:\Ina\ETL_XdmLib_2.A.13\ETL_XdmLib_2.A.13\EDAETL\ETL_TABLE\ETL_TEST_INA_WAT_TO_XSIFF\../..\XdmLib\CustomFuction.py", line 596, in file2db_init
    res = do_file(file_root_source_path,
  File "D:\Ina\ETL_XdmLib_2.A.13\ETL_XdmLib_2.A.13\EDAETL\ETL_TABLE\ETL_TEST_INA_WAT_TO_XSIFF\ETL_TXT_TO_XSIFF.py", line 319, in do_file
    raise ex
  File "D:\Ina\ETL_XdmLib_2.A.13\ETL_XdmLib_2.A.13\EDAETL\ETL_TABLE\ETL_TEST_INA_WAT_TO_XSIFF\ETL_TXT_TO_XSIFF.py", line 295, in do_file
    data_df = data_df.where(data_df.notnull(), None).drop_duplicates()
UnboundLocalError: local variable 'data_df' referenced before assignment
Stack (most recent call last):
  File "D:\Ina\ETL_XdmLib_2.A.13\ETL_XdmLib_2.A.13\EDAETL\ETL_TABLE\ETL_TEST_INA_WAT_TO_XSIFF\ETL_TXT_TO_XSIFF.py", line 379, in <module>
    XdmLib.CustomFuction.file2db_init(do_file, before_do_file, after_do_file,
  File "D:\Ina\ETL_XdmLib_2.A.13\ETL_XdmLib_2.A.13\EDAETL\ETL_TABLE\ETL_TEST_INA_WAT_TO_XSIFF\../..\XdmLib\CustomFuction.py", line 631, in file2db_init
    log.error(ex, exc_info=True, stack_info=True)
2023-08-24 19:18:31.786 - CustomFuction [ERROR   ] local variable 'xyList' referenced before assignment
Traceback (most recent call last):
  File "D:\Ina\ETL_XdmLib_2.A.13\ETL_XdmLib_2.A.13\EDAETL\ETL_TABLE\ETL_TEST_INA_WAT_TO_XSIFF\../..\XdmLib\CustomFuction.py", line 596, in file2db_init
    res = do_file(file_root_source_path,
  File "D:\Ina\ETL_XdmLib_2.A.13\ETL_XdmLib_2.A.13\EDAETL\ETL_TABLE\ETL_TEST_INA_WAT_TO_XSIFF\ETL_TXT_TO_XSIFF.py", line 263, in do_file
    raise ex
  File "D:\Ina\ETL_XdmLib_2.A.13\ETL_XdmLib_2.A.13\EDAETL\ETL_TABLE\ETL_TEST_INA_WAT_TO_XSIFF\ETL_TXT_TO_XSIFF.py", line 213, in do_file
    xyList = xyList.append(xyDict.values())
UnboundLocalError: local variable 'xyList' referenced before assignment
Stack (most recent call last):
  File "D:\Ina\ETL_XdmLib_2.A.13\ETL_XdmLib_2.A.13\EDAETL\ETL_TABLE\ETL_TEST_INA_WAT_TO_XSIFF\ETL_TXT_TO_XSIFF.py", line 381, in <module>
    XdmLib.CustomFuction.file2db_init(do_file, before_do_file, after_do_file,
  File "D:\Ina\ETL_XdmLib_2.A.13\ETL_XdmLib_2.A.13\EDAETL\ETL_TABLE\ETL_TEST_INA_WAT_TO_XSIFF\../..\XdmLib\CustomFuction.py", line 631, in file2db_init
    log.error(ex, exc_info=True, stack_info=True)
2023-08-24 19:19:22.480 - CustomFuction [ERROR   ] 'NoneType' object has no attribute 'append'
Traceback (most recent call last):
  File "D:\Ina\ETL_XdmLib_2.A.13\ETL_XdmLib_2.A.13\EDAETL\ETL_TABLE\ETL_TEST_INA_WAT_TO_XSIFF\../..\XdmLib\CustomFuction.py", line 596, in file2db_init
    res = do_file(file_root_source_path,
  File "D:\Ina\ETL_XdmLib_2.A.13\ETL_XdmLib_2.A.13\EDAETL\ETL_TABLE\ETL_TEST_INA_WAT_TO_XSIFF\ETL_TXT_TO_XSIFF.py", line 264, in do_file
    raise ex
  File "D:\Ina\ETL_XdmLib_2.A.13\ETL_XdmLib_2.A.13\EDAETL\ETL_TABLE\ETL_TEST_INA_WAT_TO_XSIFF\ETL_TXT_TO_XSIFF.py", line 214, in do_file
    xyList = xyList.append(xyDict.values())
AttributeError: 'NoneType' object has no attribute 'append'
Stack (most recent call last):
  File "D:\Ina\ETL_XdmLib_2.A.13\ETL_XdmLib_2.A.13\EDAETL\ETL_TABLE\ETL_TEST_INA_WAT_TO_XSIFF\ETL_TXT_TO_XSIFF.py", line 382, in <module>
    XdmLib.CustomFuction.file2db_init(do_file, before_do_file, after_do_file,
  File "D:\Ina\ETL_XdmLib_2.A.13\ETL_XdmLib_2.A.13\EDAETL\ETL_TABLE\ETL_TEST_INA_WAT_TO_XSIFF\../..\XdmLib\CustomFuction.py", line 631, in file2db_init
    log.error(ex, exc_info=True, stack_info=True)
2023-08-24 19:20:04.252 - CustomFuction [ERROR   ] local variable 'data_df' referenced before assignment
Traceback (most recent call last):
  File "D:\Ina\ETL_XdmLib_2.A.13\ETL_XdmLib_2.A.13\EDAETL\ETL_TABLE\ETL_TEST_INA_WAT_TO_XSIFF\../..\XdmLib\CustomFuction.py", line 596, in file2db_init
    res = do_file(file_root_source_path,
  File "D:\Ina\ETL_XdmLib_2.A.13\ETL_XdmLib_2.A.13\EDAETL\ETL_TABLE\ETL_TEST_INA_WAT_TO_XSIFF\ETL_TXT_TO_XSIFF.py", line 322, in do_file
    raise ex
  File "D:\Ina\ETL_XdmLib_2.A.13\ETL_XdmLib_2.A.13\EDAETL\ETL_TABLE\ETL_TEST_INA_WAT_TO_XSIFF\ETL_TXT_TO_XSIFF.py", line 298, in do_file
    data_df = data_df.where(data_df.notnull(), None).drop_duplicates()
UnboundLocalError: local variable 'data_df' referenced before assignment
Stack (most recent call last):
  File "D:\Ina\ETL_XdmLib_2.A.13\ETL_XdmLib_2.A.13\EDAETL\ETL_TABLE\ETL_TEST_INA_WAT_TO_XSIFF\ETL_TXT_TO_XSIFF.py", line 382, in <module>
    XdmLib.CustomFuction.file2db_init(do_file, before_do_file, after_do_file,
  File "D:\Ina\ETL_XdmLib_2.A.13\ETL_XdmLib_2.A.13\EDAETL\ETL_TABLE\ETL_TEST_INA_WAT_TO_XSIFF\../..\XdmLib\CustomFuction.py", line 631, in file2db_init
    log.error(ex, exc_info=True, stack_info=True)
2023-08-24 19:30:50.624 - CustomFuction [ERROR   ] local variable 'data_df' referenced before assignment
Traceback (most recent call last):
  File "D:\Ina\ETL_XdmLib_2.A.13\ETL_XdmLib_2.A.13\EDAETL\ETL_TABLE\ETL_TEST_INA_WAT_TO_XSIFF\../..\XdmLib\CustomFuction.py", line 596, in file2db_init
    res = do_file(file_root_source_path,
  File "D:\Ina\ETL_XdmLib_2.A.13\ETL_XdmLib_2.A.13\EDAETL\ETL_TABLE\ETL_TEST_INA_WAT_TO_XSIFF\ETL_TXT_TO_XSIFF.py", line 323, in do_file
    raise ex
  File "D:\Ina\ETL_XdmLib_2.A.13\ETL_XdmLib_2.A.13\EDAETL\ETL_TABLE\ETL_TEST_INA_WAT_TO_XSIFF\ETL_TXT_TO_XSIFF.py", line 299, in do_file
    data_df = data_df.where(data_df.notnull(), None).drop_duplicates()
UnboundLocalError: local variable 'data_df' referenced before assignment
Stack (most recent call last):
  File "D:\Ina\ETL_XdmLib_2.A.13\ETL_XdmLib_2.A.13\EDAETL\ETL_TABLE\ETL_TEST_INA_WAT_TO_XSIFF\ETL_TXT_TO_XSIFF.py", line 383, in <module>
    XdmLib.CustomFuction.file2db_init(do_file, before_do_file, after_do_file,
  File "D:\Ina\ETL_XdmLib_2.A.13\ETL_XdmLib_2.A.13\EDAETL\ETL_TABLE\ETL_TEST_INA_WAT_TO_XSIFF\../..\XdmLib\CustomFuction.py", line 631, in file2db_init
    log.error(ex, exc_info=True, stack_info=True)
2023-08-24 19:34:05.323 - CustomFuction [ERROR   ] list.append() takes exactly one argument (2 given)
Traceback (most recent call last):
  File "D:\Ina\ETL_XdmLib_2.A.13\ETL_XdmLib_2.A.13\EDAETL\ETL_TABLE\ETL_TEST_INA_WAT_TO_XSIFF\../..\XdmLib\CustomFuction.py", line 596, in file2db_init
    res = do_file(file_root_source_path,
  File "D:\Ina\ETL_XdmLib_2.A.13\ETL_XdmLib_2.A.13\EDAETL\ETL_TABLE\ETL_TEST_INA_WAT_TO_XSIFF\ETL_TXT_TO_XSIFF.py", line 265, in do_file
    raise ex
  File "D:\Ina\ETL_XdmLib_2.A.13\ETL_XdmLib_2.A.13\EDAETL\ETL_TABLE\ETL_TEST_INA_WAT_TO_XSIFF\ETL_TXT_TO_XSIFF.py", line 215, in do_file
    xyList= xyList.append(xyDict['DieX'],xyDict['DieY'])
TypeError: list.append() takes exactly one argument (2 given)
Stack (most recent call last):
  File "D:\Ina\ETL_XdmLib_2.A.13\ETL_XdmLib_2.A.13\EDAETL\ETL_TABLE\ETL_TEST_INA_WAT_TO_XSIFF\ETL_TXT_TO_XSIFF.py", line 383, in <module>
    XdmLib.CustomFuction.file2db_init(do_file, before_do_file, after_do_file,
  File "D:\Ina\ETL_XdmLib_2.A.13\ETL_XdmLib_2.A.13\EDAETL\ETL_TABLE\ETL_TEST_INA_WAT_TO_XSIFF\../..\XdmLib\CustomFuction.py", line 631, in file2db_init
    log.error(ex, exc_info=True, stack_info=True)
2023-08-24 19:35:15.913 - CustomFuction [ERROR   ] 'NoneType' object has no attribute 'append'
Traceback (most recent call last):
  File "D:\Ina\ETL_XdmLib_2.A.13\ETL_XdmLib_2.A.13\EDAETL\ETL_TABLE\ETL_TEST_INA_WAT_TO_XSIFF\../..\XdmLib\CustomFuction.py", line 596, in file2db_init
    res = do_file(file_root_source_path,
  File "D:\Ina\ETL_XdmLib_2.A.13\ETL_XdmLib_2.A.13\EDAETL\ETL_TABLE\ETL_TEST_INA_WAT_TO_XSIFF\ETL_TXT_TO_XSIFF.py", line 265, in do_file
    raise ex
  File "D:\Ina\ETL_XdmLib_2.A.13\ETL_XdmLib_2.A.13\EDAETL\ETL_TABLE\ETL_TEST_INA_WAT_TO_XSIFF\ETL_TXT_TO_XSIFF.py", line 215, in do_file
    xyList= xyList.append([xyDict['DieX'],xyDict['DieY']])
AttributeError: 'NoneType' object has no attribute 'append'
Stack (most recent call last):
  File "D:\Ina\ETL_XdmLib_2.A.13\ETL_XdmLib_2.A.13\EDAETL\ETL_TABLE\ETL_TEST_INA_WAT_TO_XSIFF\ETL_TXT_TO_XSIFF.py", line 383, in <module>
    XdmLib.CustomFuction.file2db_init(do_file, before_do_file, after_do_file,
  File "D:\Ina\ETL_XdmLib_2.A.13\ETL_XdmLib_2.A.13\EDAETL\ETL_TABLE\ETL_TEST_INA_WAT_TO_XSIFF\../..\XdmLib\CustomFuction.py", line 631, in file2db_init
    log.error(ex, exc_info=True, stack_info=True)
2023-08-24 19:41:15.277 - CustomFuction [ERROR   ] local variable 'data_df' referenced before assignment
Traceback (most recent call last):
  File "D:\Ina\ETL_XdmLib_2.A.13\ETL_XdmLib_2.A.13\EDAETL\ETL_TABLE\ETL_TEST_INA_WAT_TO_XSIFF\../..\XdmLib\CustomFuction.py", line 596, in file2db_init
    res = do_file(file_root_source_path,
  File "D:\Ina\ETL_XdmLib_2.A.13\ETL_XdmLib_2.A.13\EDAETL\ETL_TABLE\ETL_TEST_INA_WAT_TO_XSIFF\ETL_TXT_TO_XSIFF.py", line 324, in do_file
    raise ex
  File "D:\Ina\ETL_XdmLib_2.A.13\ETL_XdmLib_2.A.13\EDAETL\ETL_TABLE\ETL_TEST_INA_WAT_TO_XSIFF\ETL_TXT_TO_XSIFF.py", line 300, in do_file
    data_df = data_df.where(data_df.notnull(), None).drop_duplicates()
UnboundLocalError: local variable 'data_df' referenced before assignment
Stack (most recent call last):
  File "D:\Ina\ETL_XdmLib_2.A.13\ETL_XdmLib_2.A.13\EDAETL\ETL_TABLE\ETL_TEST_INA_WAT_TO_XSIFF\ETL_TXT_TO_XSIFF.py", line 384, in <module>
    XdmLib.CustomFuction.file2db_init(do_file, before_do_file, after_do_file,
  File "D:\Ina\ETL_XdmLib_2.A.13\ETL_XdmLib_2.A.13\EDAETL\ETL_TABLE\ETL_TEST_INA_WAT_TO_XSIFF\../..\XdmLib\CustomFuction.py", line 631, in file2db_init
    log.error(ex, exc_info=True, stack_info=True)
2023-08-24 19:45:10.728 - CustomFuction [ERROR   ] If using all scalar values, you must pass an index
Traceback (most recent call last):
  File "D:\Ina\ETL_XdmLib_2.A.13\ETL_XdmLib_2.A.13\EDAETL\ETL_TABLE\ETL_TEST_INA_WAT_TO_XSIFF\../..\XdmLib\CustomFuction.py", line 596, in file2db_init
    res = do_file(file_root_source_path,
  File "D:\Ina\ETL_XdmLib_2.A.13\ETL_XdmLib_2.A.13\EDAETL\ETL_TABLE\ETL_TEST_INA_WAT_TO_XSIFF\ETL_TXT_TO_XSIFF.py", line 266, in do_file
    raise ex
  File "D:\Ina\ETL_XdmLib_2.A.13\ETL_XdmLib_2.A.13\EDAETL\ETL_TABLE\ETL_TEST_INA_WAT_TO_XSIFF\ETL_TXT_TO_XSIFF.py", line 218, in do_file
    data_df = pd.DataFrame(data=xyDict, dtype=object)
  File "D:\soft\anaconda3\lib\site-packages\pandas\core\frame.py", line 636, in __init__
    mgr = dict_to_mgr(data, index, columns, dtype=dtype, copy=copy, typ=manager)
  File "D:\soft\anaconda3\lib\site-packages\pandas\core\internals\construction.py", line 502, in dict_to_mgr
    return arrays_to_mgr(arrays, columns, index, dtype=dtype, typ=typ, consolidate=copy)
  File "D:\soft\anaconda3\lib\site-packages\pandas\core\internals\construction.py", line 120, in arrays_to_mgr
    index = _extract_index(arrays)
  File "D:\soft\anaconda3\lib\site-packages\pandas\core\internals\construction.py", line 664, in _extract_index
    raise ValueError("If using all scalar values, you must pass an index")
ValueError: If using all scalar values, you must pass an index
Stack (most recent call last):
  File "D:\Ina\ETL_XdmLib_2.A.13\ETL_XdmLib_2.A.13\EDAETL\ETL_TABLE\ETL_TEST_INA_WAT_TO_XSIFF\ETL_TXT_TO_XSIFF.py", line 384, in <module>
    XdmLib.CustomFuction.file2db_init(do_file, before_do_file, after_do_file,
  File "D:\Ina\ETL_XdmLib_2.A.13\ETL_XdmLib_2.A.13\EDAETL\ETL_TABLE\ETL_TEST_INA_WAT_TO_XSIFF\../..\XdmLib\CustomFuction.py", line 631, in file2db_init
    log.error(ex, exc_info=True, stack_info=True)
2023-08-24 19:47:13.943 - CustomFuction [ERROR   ] Length mismatch: Expected axis has 1 elements, new values have 6 elements
Traceback (most recent call last):
  File "D:\Ina\ETL_XdmLib_2.A.13\ETL_XdmLib_2.A.13\EDAETL\ETL_TABLE\ETL_TEST_INA_WAT_TO_XSIFF\../..\XdmLib\CustomFuction.py", line 596, in file2db_init
    res = do_file(file_root_source_path,
  File "D:\Ina\ETL_XdmLib_2.A.13\ETL_XdmLib_2.A.13\EDAETL\ETL_TABLE\ETL_TEST_INA_WAT_TO_XSIFF\ETL_TXT_TO_XSIFF.py", line 266, in do_file
    raise ex
  File "D:\Ina\ETL_XdmLib_2.A.13\ETL_XdmLib_2.A.13\EDAETL\ETL_TABLE\ETL_TEST_INA_WAT_TO_XSIFF\ETL_TXT_TO_XSIFF.py", line 219, in do_file
    data_df.columns = ["DieX", "DieY", "HBIN", "SBIN", "TouchdownNo", "DutNo"]
  File "D:\soft\anaconda3\lib\site-packages\pandas\core\generic.py", line 5588, in __setattr__
    return object.__setattr__(self, name, value)
  File "pandas\_libs\properties.pyx", line 70, in pandas._libs.properties.AxisProperty.__set__
  File "D:\soft\anaconda3\lib\site-packages\pandas\core\generic.py", line 769, in _set_axis
    self._mgr.set_axis(axis, labels)
  File "D:\soft\anaconda3\lib\site-packages\pandas\core\internals\managers.py", line 214, in set_axis
    self._validate_set_axis(axis, new_labels)
  File "D:\soft\anaconda3\lib\site-packages\pandas\core\internals\base.py", line 69, in _validate_set_axis
    raise ValueError(
ValueError: Length mismatch: Expected axis has 1 elements, new values have 6 elements
Stack (most recent call last):
  File "D:\Ina\ETL_XdmLib_2.A.13\ETL_XdmLib_2.A.13\EDAETL\ETL_TABLE\ETL_TEST_INA_WAT_TO_XSIFF\ETL_TXT_TO_XSIFF.py", line 384, in <module>
    XdmLib.CustomFuction.file2db_init(do_file, before_do_file, after_do_file,
  File "D:\Ina\ETL_XdmLib_2.A.13\ETL_XdmLib_2.A.13\EDAETL\ETL_TABLE\ETL_TEST_INA_WAT_TO_XSIFF\../..\XdmLib\CustomFuction.py", line 631, in file2db_init
    log.error(ex, exc_info=True, stack_info=True)
2023-08-24 19:48:08.433 - CustomFuction [ERROR   ] Length mismatch: Expected axis has 2 elements, new values have 6 elements
Traceback (most recent call last):
  File "D:\Ina\ETL_XdmLib_2.A.13\ETL_XdmLib_2.A.13\EDAETL\ETL_TABLE\ETL_TEST_INA_WAT_TO_XSIFF\../..\XdmLib\CustomFuction.py", line 596, in file2db_init
    res = do_file(file_root_source_path,
  File "D:\Ina\ETL_XdmLib_2.A.13\ETL_XdmLib_2.A.13\EDAETL\ETL_TABLE\ETL_TEST_INA_WAT_TO_XSIFF\ETL_TXT_TO_XSIFF.py", line 266, in do_file
    raise ex
  File "D:\Ina\ETL_XdmLib_2.A.13\ETL_XdmLib_2.A.13\EDAETL\ETL_TABLE\ETL_TEST_INA_WAT_TO_XSIFF\ETL_TXT_TO_XSIFF.py", line 219, in do_file
    data_df.columns = ["DieX", "DieY", "HBIN", "SBIN", "TouchdownNo", "DutNo"]
  File "D:\soft\anaconda3\lib\site-packages\pandas\core\generic.py", line 5588, in __setattr__
    return object.__setattr__(self, name, value)
  File "pandas\_libs\properties.pyx", line 70, in pandas._libs.properties.AxisProperty.__set__
  File "D:\soft\anaconda3\lib\site-packages\pandas\core\generic.py", line 769, in _set_axis
    self._mgr.set_axis(axis, labels)
  File "D:\soft\anaconda3\lib\site-packages\pandas\core\internals\managers.py", line 214, in set_axis
    self._validate_set_axis(axis, new_labels)
  File "D:\soft\anaconda3\lib\site-packages\pandas\core\internals\base.py", line 69, in _validate_set_axis
    raise ValueError(
ValueError: Length mismatch: Expected axis has 2 elements, new values have 6 elements
Stack (most recent call last):
  File "D:\Ina\ETL_XdmLib_2.A.13\ETL_XdmLib_2.A.13\EDAETL\ETL_TABLE\ETL_TEST_INA_WAT_TO_XSIFF\ETL_TXT_TO_XSIFF.py", line 384, in <module>
    XdmLib.CustomFuction.file2db_init(do_file, before_do_file, after_do_file,
  File "D:\Ina\ETL_XdmLib_2.A.13\ETL_XdmLib_2.A.13\EDAETL\ETL_TABLE\ETL_TEST_INA_WAT_TO_XSIFF\../..\XdmLib\CustomFuction.py", line 631, in file2db_init
    log.error(ex, exc_info=True, stack_info=True)
2023-08-24 19:51:28.024 - CustomFuction [ERROR   ] Length mismatch: Expected axis has 6 elements, new values have 2 elements
Traceback (most recent call last):
  File "D:\Ina\ETL_XdmLib_2.A.13\ETL_XdmLib_2.A.13\EDAETL\ETL_TABLE\ETL_TEST_INA_WAT_TO_XSIFF\../..\XdmLib\CustomFuction.py", line 596, in file2db_init
    res = do_file(file_root_source_path,
  File "D:\Ina\ETL_XdmLib_2.A.13\ETL_XdmLib_2.A.13\EDAETL\ETL_TABLE\ETL_TEST_INA_WAT_TO_XSIFF\ETL_TXT_TO_XSIFF.py", line 268, in do_file
    raise ex
  File "D:\Ina\ETL_XdmLib_2.A.13\ETL_XdmLib_2.A.13\EDAETL\ETL_TABLE\ETL_TEST_INA_WAT_TO_XSIFF\ETL_TXT_TO_XSIFF.py", line 219, in do_file
    data_df.columns = ["DieX", "DieY"
  File "D:\soft\anaconda3\lib\site-packages\pandas\core\generic.py", line 5588, in __setattr__
    return object.__setattr__(self, name, value)
  File "pandas\_libs\properties.pyx", line 70, in pandas._libs.properties.AxisProperty.__set__
  File "D:\soft\anaconda3\lib\site-packages\pandas\core\generic.py", line 769, in _set_axis
    self._mgr.set_axis(axis, labels)
  File "D:\soft\anaconda3\lib\site-packages\pandas\core\internals\managers.py", line 214, in set_axis
    self._validate_set_axis(axis, new_labels)
  File "D:\soft\anaconda3\lib\site-packages\pandas\core\internals\base.py", line 69, in _validate_set_axis
    raise ValueError(
ValueError: Length mismatch: Expected axis has 6 elements, new values have 2 elements
Stack (most recent call last):
  File "D:\Ina\ETL_XdmLib_2.A.13\ETL_XdmLib_2.A.13\EDAETL\ETL_TABLE\ETL_TEST_INA_WAT_TO_XSIFF\ETL_TXT_TO_XSIFF.py", line 386, in <module>
    XdmLib.CustomFuction.file2db_init(do_file, before_do_file, after_do_file,
  File "D:\Ina\ETL_XdmLib_2.A.13\ETL_XdmLib_2.A.13\EDAETL\ETL_TABLE\ETL_TEST_INA_WAT_TO_XSIFF\../..\XdmLib\CustomFuction.py", line 631, in file2db_init
    log.error(ex, exc_info=True, stack_info=True)
