2023-08-23 09:18:56.316 - CustomFuction [ERROR   ] [Errno 2] No such file or directory: 'FMGDM7009A1_A509537.01.txt'
Traceback (most recent call last):
  File "D:\Ina\ETL_XdmLib_2.A.13\ETL_XdmLib_2.A.13\EDAETL\ETL_TABLE\ETL_TEST_INA_WAT_TO_XSIFF\../..\XdmLib\CustomFuction.py", line 596, in file2db_init
    res = do_file(file_root_source_path,
  File "D:\Ina\ETL_XdmLib_2.A.13\ETL_XdmLib_2.A.13\EDAETL\ETL_TABLE\ETL_TEST_INA_WAT_TO_XSIFF\ETL_TXT_TO_XSIFF.py", line 89, in do_file
    with open(file_name, 'r') as file:
FileNotFoundError: [Errno 2] No such file or directory: 'FMGDM7009A1_A509537.01.txt'
Stack (most recent call last):
  File "D:\Ina\ETL_XdmLib_2.A.13\ETL_XdmLib_2.A.13\EDAETL\ETL_TABLE\ETL_TEST_INA_WAT_TO_XSIFF\ETL_TXT_TO_XSIFF.py", line 231, in <module>
    XdmLib.CustomFuction.file2db_init(do_file, before_do_file, after_do_file,
  File "D:\Ina\ETL_XdmLib_2.A.13\ETL_XdmLib_2.A.13\EDAETL\ETL_TABLE\ETL_TEST_INA_WAT_TO_XSIFF\../..\XdmLib\CustomFuction.py", line 631, in file2db_init
    log.error(ex, exc_info=True, stack_info=True)
2023-08-23 09:48:57.532 - CustomFuction [ERROR   ] local variable 'te_t' referenced before assignment
Traceback (most recent call last):
  File "D:\Ina\ETL_XdmLib_2.A.13\ETL_XdmLib_2.A.13\EDAETL\ETL_TABLE\ETL_TEST_INA_WAT_TO_XSIFF\../..\XdmLib\CustomFuction.py", line 596, in file2db_init
    res = do_file(file_root_source_path,
  File "D:\Ina\ETL_XdmLib_2.A.13\ETL_XdmLib_2.A.13\EDAETL\ETL_TABLE\ETL_TEST_INA_WAT_TO_XSIFF\ETL_TXT_TO_XSIFF.py", line 121, in do_file
    'MeasTime': te_t.strftime('%Y-%m-%d %H:%M:%S', time.strptime(string_list[0], '%m/%d/%Y %H:%M:%S')),
UnboundLocalError: local variable 'te_t' referenced before assignment
Stack (most recent call last):
  File "D:\Ina\ETL_XdmLib_2.A.13\ETL_XdmLib_2.A.13\EDAETL\ETL_TABLE\ETL_TEST_INA_WAT_TO_XSIFF\ETL_TXT_TO_XSIFF.py", line 245, in <module>
    XdmLib.CustomFuction.file2db_init(do_file, before_do_file, after_do_file,
  File "D:\Ina\ETL_XdmLib_2.A.13\ETL_XdmLib_2.A.13\EDAETL\ETL_TABLE\ETL_TEST_INA_WAT_TO_XSIFF\../..\XdmLib\CustomFuction.py", line 631, in file2db_init
    log.error(ex, exc_info=True, stack_info=True)
2023-08-23 09:55:34.087 - CustomFuction [ERROR   ] local variable 'te_t' referenced before assignment
Traceback (most recent call last):
  File "D:\Ina\ETL_XdmLib_2.A.13\ETL_XdmLib_2.A.13\EDAETL\ETL_TABLE\ETL_TEST_INA_WAT_TO_XSIFF\../..\XdmLib\CustomFuction.py", line 596, in file2db_init
    res = do_file(file_root_source_path,
  File "D:\Ina\ETL_XdmLib_2.A.13\ETL_XdmLib_2.A.13\EDAETL\ETL_TABLE\ETL_TEST_INA_WAT_TO_XSIFF\ETL_TXT_TO_XSIFF.py", line 122, in do_file
    'MeasTime': te_t.strftime('%Y-%m-%d %H:%M:%S', time.strptime(string_list[0], '%m/%d/%Y %H:%M:%S')),
UnboundLocalError: local variable 'te_t' referenced before assignment
Stack (most recent call last):
  File "D:\Ina\ETL_XdmLib_2.A.13\ETL_XdmLib_2.A.13\EDAETL\ETL_TABLE\ETL_TEST_INA_WAT_TO_XSIFF\ETL_TXT_TO_XSIFF.py", line 246, in <module>
    XdmLib.CustomFuction.file2db_init(do_file, before_do_file, after_do_file,
  File "D:\Ina\ETL_XdmLib_2.A.13\ETL_XdmLib_2.A.13\EDAETL\ETL_TABLE\ETL_TEST_INA_WAT_TO_XSIFF\../..\XdmLib\CustomFuction.py", line 631, in file2db_init
    log.error(ex, exc_info=True, stack_info=True)
2023-08-23 09:58:32.743 - CustomFuction [ERROR   ] 'str' object has no attribute 'strftime'
Traceback (most recent call last):
  File "D:\Ina\ETL_XdmLib_2.A.13\ETL_XdmLib_2.A.13\EDAETL\ETL_TABLE\ETL_TEST_INA_WAT_TO_XSIFF\../..\XdmLib\CustomFuction.py", line 596, in file2db_init
    res = do_file(file_root_source_path,
  File "D:\Ina\ETL_XdmLib_2.A.13\ETL_XdmLib_2.A.13\EDAETL\ETL_TABLE\ETL_TEST_INA_WAT_TO_XSIFF\ETL_TXT_TO_XSIFF.py", line 123, in do_file
    'MeasTime': te_t.strftime('%Y-%m-%d %H:%M:%S', time.strptime(string_list[0], '%m/%d/%Y %H:%M:%S')),
AttributeError: 'str' object has no attribute 'strftime'
Stack (most recent call last):
  File "D:\Ina\ETL_XdmLib_2.A.13\ETL_XdmLib_2.A.13\EDAETL\ETL_TABLE\ETL_TEST_INA_WAT_TO_XSIFF\ETL_TXT_TO_XSIFF.py", line 247, in <module>
    XdmLib.CustomFuction.file2db_init(do_file, before_do_file, after_do_file,
  File "D:\Ina\ETL_XdmLib_2.A.13\ETL_XdmLib_2.A.13\EDAETL\ETL_TABLE\ETL_TEST_INA_WAT_TO_XSIFF\../..\XdmLib\CustomFuction.py", line 631, in file2db_init
    log.error(ex, exc_info=True, stack_info=True)
2023-08-23 10:04:20.744 - CustomFuction [ERROR   ] 'NoneType' object has no attribute 'strftime'
Traceback (most recent call last):
  File "D:\Ina\ETL_XdmLib_2.A.13\ETL_XdmLib_2.A.13\EDAETL\ETL_TABLE\ETL_TEST_INA_WAT_TO_XSIFF\../..\XdmLib\CustomFuction.py", line 596, in file2db_init
    res = do_file(file_root_source_path,
  File "D:\Ina\ETL_XdmLib_2.A.13\ETL_XdmLib_2.A.13\EDAETL\ETL_TABLE\ETL_TEST_INA_WAT_TO_XSIFF\ETL_TXT_TO_XSIFF.py", line 123, in do_file
    'MeasTime': te_t.strftime('%Y-%m-%d %H:%M:%S', time.strptime(string_list[0], '%m/%d/%Y %H:%M:%S')),
AttributeError: 'NoneType' object has no attribute 'strftime'
Stack (most recent call last):
  File "D:\Ina\ETL_XdmLib_2.A.13\ETL_XdmLib_2.A.13\EDAETL\ETL_TABLE\ETL_TEST_INA_WAT_TO_XSIFF\ETL_TXT_TO_XSIFF.py", line 247, in <module>
    XdmLib.CustomFuction.file2db_init(do_file, before_do_file, after_do_file,
  File "D:\Ina\ETL_XdmLib_2.A.13\ETL_XdmLib_2.A.13\EDAETL\ETL_TABLE\ETL_TEST_INA_WAT_TO_XSIFF\../..\XdmLib\CustomFuction.py", line 631, in file2db_init
    log.error(ex, exc_info=True, stack_info=True)
2023-08-23 10:15:30.478 - CustomFuction [ERROR   ] name 'string_list' is not defined
Traceback (most recent call last):
  File "D:\Ina\ETL_XdmLib_2.A.13\ETL_XdmLib_2.A.13\EDAETL\ETL_TABLE\ETL_TEST_INA_WAT_TO_XSIFF\../..\XdmLib\CustomFuction.py", line 596, in file2db_init
    res = do_file(file_root_source_path,
  File "D:\Ina\ETL_XdmLib_2.A.13\ETL_XdmLib_2.A.13\EDAETL\ETL_TABLE\ETL_TEST_INA_WAT_TO_XSIFF\ETL_TXT_TO_XSIFF.py", line 121, in do_file
    'StartTime' : ts_t.strftime('%Y-%m-%d %H:%M:%S', time.strptime(string_list[0], '%m/%d/%Y %H:%M:%S')),
NameError: name 'string_list' is not defined
Stack (most recent call last):
  File "D:\Ina\ETL_XdmLib_2.A.13\ETL_XdmLib_2.A.13\EDAETL\ETL_TABLE\ETL_TEST_INA_WAT_TO_XSIFF\ETL_TXT_TO_XSIFF.py", line 244, in <module>
    XdmLib.CustomFuction.file2db_init(do_file, before_do_file, after_do_file,
  File "D:\Ina\ETL_XdmLib_2.A.13\ETL_XdmLib_2.A.13\EDAETL\ETL_TABLE\ETL_TEST_INA_WAT_TO_XSIFF\../..\XdmLib\CustomFuction.py", line 631, in file2db_init
    log.error(ex, exc_info=True, stack_info=True)
2023-08-23 10:57:55.832 - CustomFuction [ERROR   ] No axis named 000 for object type DataFrame
Traceback (most recent call last):
  File "D:\soft\anaconda3\lib\site-packages\pandas\core\generic.py", line 550, in _get_axis_number
    return cls._AXIS_TO_AXIS_NUMBER[axis]
KeyError: '000'

During handling of the above exception, another exception occurred:

Traceback (most recent call last):
  File "D:\Ina\ETL_XdmLib_2.A.13\ETL_XdmLib_2.A.13\EDAETL\ETL_TABLE\ETL_TEST_INA_WAT_TO_XSIFF\../..\XdmLib\CustomFuction.py", line 596, in file2db_init
    res = do_file(file_root_source_path,
  File "D:\Ina\ETL_XdmLib_2.A.13\ETL_XdmLib_2.A.13\EDAETL\ETL_TABLE\ETL_TEST_INA_WAT_TO_XSIFF\ETL_TXT_TO_XSIFF.py", line 107, in do_file
    count = DataDF.count("000")
  File "D:\soft\anaconda3\lib\site-packages\pandas\core\frame.py", line 9852, in count
    axis = self._get_axis_number(axis)
  File "D:\soft\anaconda3\lib\site-packages\pandas\core\generic.py", line 552, in _get_axis_number
    raise ValueError(f"No axis named {axis} for object type {cls.__name__}")
ValueError: No axis named 000 for object type DataFrame
Stack (most recent call last):
  File "D:\Ina\ETL_XdmLib_2.A.13\ETL_XdmLib_2.A.13\EDAETL\ETL_TABLE\ETL_TEST_INA_WAT_TO_XSIFF\ETL_TXT_TO_XSIFF.py", line 252, in <module>
    XdmLib.CustomFuction.file2db_init(do_file, before_do_file, after_do_file,
  File "D:\Ina\ETL_XdmLib_2.A.13\ETL_XdmLib_2.A.13\EDAETL\ETL_TABLE\ETL_TEST_INA_WAT_TO_XSIFF\../..\XdmLib\CustomFuction.py", line 631, in file2db_init
    log.error(ex, exc_info=True, stack_info=True)
2023-08-23 11:00:06.494 - CustomFuction [ERROR   ] name 'df' is not defined
Traceback (most recent call last):
  File "D:\Ina\ETL_XdmLib_2.A.13\ETL_XdmLib_2.A.13\EDAETL\ETL_TABLE\ETL_TEST_INA_WAT_TO_XSIFF\../..\XdmLib\CustomFuction.py", line 596, in file2db_init
    res = do_file(file_root_source_path,
  File "D:\Ina\ETL_XdmLib_2.A.13\ETL_XdmLib_2.A.13\EDAETL\ETL_TABLE\ETL_TEST_INA_WAT_TO_XSIFF\ETL_TXT_TO_XSIFF.py", line 107, in do_file
    count = (df[0].str.count('000')).sum()
NameError: name 'df' is not defined
Stack (most recent call last):
  File "D:\Ina\ETL_XdmLib_2.A.13\ETL_XdmLib_2.A.13\EDAETL\ETL_TABLE\ETL_TEST_INA_WAT_TO_XSIFF\ETL_TXT_TO_XSIFF.py", line 252, in <module>
    XdmLib.CustomFuction.file2db_init(do_file, before_do_file, after_do_file,
  File "D:\Ina\ETL_XdmLib_2.A.13\ETL_XdmLib_2.A.13\EDAETL\ETL_TABLE\ETL_TEST_INA_WAT_TO_XSIFF\../..\XdmLib\CustomFuction.py", line 631, in file2db_init
    log.error(ex, exc_info=True, stack_info=True)
2023-08-23 17:27:06.425 - CustomFuction [ERROR   ] 'DataFrame' object has no attribute 'unique'
Traceback (most recent call last):
  File "D:\Ina\ETL_XdmLib_2.A.13\ETL_XdmLib_2.A.13\EDAETL\ETL_TABLE\ETL_TEST_INA_WAT_TO_XSIFF\../..\XdmLib\CustomFuction.py", line 596, in file2db_init
    res = do_file(file_root_source_path,
  File "D:\Ina\ETL_XdmLib_2.A.13\ETL_XdmLib_2.A.13\EDAETL\ETL_TABLE\ETL_TEST_INA_WAT_TO_XSIFF\ETL_TXT_TO_XSIFF.py", line 174, in do_file
    raise ex
  File "D:\Ina\ETL_XdmLib_2.A.13\ETL_XdmLib_2.A.13\EDAETL\ETL_TABLE\ETL_TEST_INA_WAT_TO_XSIFF\ETL_TXT_TO_XSIFF.py", line 130, in do_file
    BinDefClassList = DataDF.unique().tolist()
  File "D:\soft\anaconda3\lib\site-packages\pandas\core\generic.py", line 5575, in __getattr__
    return object.__getattribute__(self, name)
AttributeError: 'DataFrame' object has no attribute 'unique'
Stack (most recent call last):
  File "D:\Ina\ETL_XdmLib_2.A.13\ETL_XdmLib_2.A.13\EDAETL\ETL_TABLE\ETL_TEST_INA_WAT_TO_XSIFF\ETL_TXT_TO_XSIFF.py", line 290, in <module>
    XdmLib.CustomFuction.file2db_init(do_file, before_do_file, after_do_file,
  File "D:\Ina\ETL_XdmLib_2.A.13\ETL_XdmLib_2.A.13\EDAETL\ETL_TABLE\ETL_TEST_INA_WAT_TO_XSIFF\../..\XdmLib\CustomFuction.py", line 631, in file2db_init
    log.error(ex, exc_info=True, stack_info=True)
2023-08-23 17:28:31.510 - CustomFuction [ERROR   ] name 'BinDefList' is not defined
Traceback (most recent call last):
  File "D:\Ina\ETL_XdmLib_2.A.13\ETL_XdmLib_2.A.13\EDAETL\ETL_TABLE\ETL_TEST_INA_WAT_TO_XSIFF\../..\XdmLib\CustomFuction.py", line 596, in file2db_init
    res = do_file(file_root_source_path,
  File "D:\Ina\ETL_XdmLib_2.A.13\ETL_XdmLib_2.A.13\EDAETL\ETL_TABLE\ETL_TEST_INA_WAT_TO_XSIFF\ETL_TXT_TO_XSIFF.py", line 174, in do_file
    raise ex
  File "D:\Ina\ETL_XdmLib_2.A.13\ETL_XdmLib_2.A.13\EDAETL\ETL_TABLE\ETL_TEST_INA_WAT_TO_XSIFF\ETL_TXT_TO_XSIFF.py", line 145, in do_file
    BinDefList.append([RecordType,BinName,BinType,BinDesc])
NameError: name 'BinDefList' is not defined
Stack (most recent call last):
  File "D:\Ina\ETL_XdmLib_2.A.13\ETL_XdmLib_2.A.13\EDAETL\ETL_TABLE\ETL_TEST_INA_WAT_TO_XSIFF\ETL_TXT_TO_XSIFF.py", line 290, in <module>
    XdmLib.CustomFuction.file2db_init(do_file, before_do_file, after_do_file,
  File "D:\Ina\ETL_XdmLib_2.A.13\ETL_XdmLib_2.A.13\EDAETL\ETL_TABLE\ETL_TEST_INA_WAT_TO_XSIFF\../..\XdmLib\CustomFuction.py", line 631, in file2db_init
    log.error(ex, exc_info=True, stack_info=True)
2023-08-23 17:29:13.456 - CustomFuction [ERROR   ] local variable 'RecordType' referenced before assignment
Traceback (most recent call last):
  File "D:\Ina\ETL_XdmLib_2.A.13\ETL_XdmLib_2.A.13\EDAETL\ETL_TABLE\ETL_TEST_INA_WAT_TO_XSIFF\../..\XdmLib\CustomFuction.py", line 596, in file2db_init
    res = do_file(file_root_source_path,
  File "D:\Ina\ETL_XdmLib_2.A.13\ETL_XdmLib_2.A.13\EDAETL\ETL_TABLE\ETL_TEST_INA_WAT_TO_XSIFF\ETL_TXT_TO_XSIFF.py", line 175, in do_file
    raise ex
  File "D:\Ina\ETL_XdmLib_2.A.13\ETL_XdmLib_2.A.13\EDAETL\ETL_TABLE\ETL_TEST_INA_WAT_TO_XSIFF\ETL_TXT_TO_XSIFF.py", line 146, in do_file
    BinDefList.append([RecordType,BinName,BinType,BinDesc])
UnboundLocalError: local variable 'RecordType' referenced before assignment
Stack (most recent call last):
  File "D:\Ina\ETL_XdmLib_2.A.13\ETL_XdmLib_2.A.13\EDAETL\ETL_TABLE\ETL_TEST_INA_WAT_TO_XSIFF\ETL_TXT_TO_XSIFF.py", line 291, in <module>
    XdmLib.CustomFuction.file2db_init(do_file, before_do_file, after_do_file,
  File "D:\Ina\ETL_XdmLib_2.A.13\ETL_XdmLib_2.A.13\EDAETL\ETL_TABLE\ETL_TEST_INA_WAT_TO_XSIFF\../..\XdmLib\CustomFuction.py", line 631, in file2db_init
    log.error(ex, exc_info=True, stack_info=True)
2023-08-23 17:41:34.663 - CustomFuction [ERROR   ] 'Series' object has no attribute 'strip'
Traceback (most recent call last):
  File "D:\Ina\ETL_XdmLib_2.A.13\ETL_XdmLib_2.A.13\EDAETL\ETL_TABLE\ETL_TEST_INA_WAT_TO_XSIFF\../..\XdmLib\CustomFuction.py", line 596, in file2db_init
    res = do_file(file_root_source_path,
  File "D:/Ina/ETL_XdmLib_2.A.13/ETL_XdmLib_2.A.13/EDAETL/ETL_TABLE/ETL_TEST_INA_WAT_TO_XSIFF/ETL_TXT_TO_XSIFF.py", line 175, in do_file
    raise ex
  File "D:/Ina/ETL_XdmLib_2.A.13/ETL_XdmLib_2.A.13/EDAETL/ETL_TABLE/ETL_TEST_INA_WAT_TO_XSIFF/ETL_TXT_TO_XSIFF.py", line 136, in do_file
    for column_name, column_value in row.strip(' ').iteritems():
  File "D:\soft\anaconda3\lib\site-packages\pandas\core\generic.py", line 5575, in __getattr__
    return object.__getattribute__(self, name)
AttributeError: 'Series' object has no attribute 'strip'
Stack (most recent call last):
  File "D:\soft\PyCharm Community Edition 2022.1.3\plugins\python-ce\helpers\pydev\pydevd.py", line 2181, in <module>
    main()
  File "D:\soft\PyCharm Community Edition 2022.1.3\plugins\python-ce\helpers\pydev\pydevd.py", line 2172, in main
    globals = debugger.run(setup['file'], None, None, is_module)
  File "D:\soft\PyCharm Community Edition 2022.1.3\plugins\python-ce\helpers\pydev\pydevd.py", line 1484, in run
    return self._exec(is_module, entry_point_fn, module_name, file, globals, locals)
  File "D:\soft\PyCharm Community Edition 2022.1.3\plugins\python-ce\helpers\pydev\pydevd.py", line 1491, in _exec
    pydev_imports.execfile(file, globals, locals)  # execute the script
  File "D:\soft\PyCharm Community Edition 2022.1.3\plugins\python-ce\helpers\pydev\_pydev_imps\_pydev_execfile.py", line 18, in execfile
    exec(compile(contents+"\n", file, 'exec'), glob, loc)
  File "D:/Ina/ETL_XdmLib_2.A.13/ETL_XdmLib_2.A.13/EDAETL/ETL_TABLE/ETL_TEST_INA_WAT_TO_XSIFF/ETL_TXT_TO_XSIFF.py", line 291, in <module>
    XdmLib.CustomFuction.file2db_init(do_file, before_do_file, after_do_file,
  File "D:\Ina\ETL_XdmLib_2.A.13\ETL_XdmLib_2.A.13\EDAETL\ETL_TABLE\ETL_TEST_INA_WAT_TO_XSIFF\../..\XdmLib\CustomFuction.py", line 631, in file2db_init
    log.error(ex, exc_info=True, stack_info=True)
2023-08-23 17:47:40.432 - CustomFuction [ERROR   ] 'Series' object has no attribute 'strip'
Traceback (most recent call last):
  File "D:\Ina\ETL_XdmLib_2.A.13\ETL_XdmLib_2.A.13\EDAETL\ETL_TABLE\ETL_TEST_INA_WAT_TO_XSIFF\../..\XdmLib\CustomFuction.py", line 596, in file2db_init
    res = do_file(file_root_source_path,
  File "D:/Ina/ETL_XdmLib_2.A.13/ETL_XdmLib_2.A.13/EDAETL/ETL_TABLE/ETL_TEST_INA_WAT_TO_XSIFF/ETL_TXT_TO_XSIFF.py", line 176, in do_file
    raise ex
  File "D:/Ina/ETL_XdmLib_2.A.13/ETL_XdmLib_2.A.13/EDAETL/ETL_TABLE/ETL_TEST_INA_WAT_TO_XSIFF/ETL_TXT_TO_XSIFF.py", line 135, in do_file
    for column_name, column_value in row.strip(' ').iteritems():
  File "D:\soft\anaconda3\lib\site-packages\pandas\core\generic.py", line 5575, in __getattr__
    return object.__getattribute__(self, name)
AttributeError: 'Series' object has no attribute 'strip'
Stack (most recent call last):
  File "D:\soft\PyCharm Community Edition 2022.1.3\plugins\python-ce\helpers\pydev\pydevd.py", line 2181, in <module>
    main()
  File "D:\soft\PyCharm Community Edition 2022.1.3\plugins\python-ce\helpers\pydev\pydevd.py", line 2172, in main
    globals = debugger.run(setup['file'], None, None, is_module)
  File "D:\soft\PyCharm Community Edition 2022.1.3\plugins\python-ce\helpers\pydev\pydevd.py", line 1484, in run
    return self._exec(is_module, entry_point_fn, module_name, file, globals, locals)
  File "D:\soft\PyCharm Community Edition 2022.1.3\plugins\python-ce\helpers\pydev\pydevd.py", line 1491, in _exec
    pydev_imports.execfile(file, globals, locals)  # execute the script
  File "D:\soft\PyCharm Community Edition 2022.1.3\plugins\python-ce\helpers\pydev\_pydev_imps\_pydev_execfile.py", line 18, in execfile
    exec(compile(contents+"\n", file, 'exec'), glob, loc)
  File "D:/Ina/ETL_XdmLib_2.A.13/ETL_XdmLib_2.A.13/EDAETL/ETL_TABLE/ETL_TEST_INA_WAT_TO_XSIFF/ETL_TXT_TO_XSIFF.py", line 292, in <module>
    XdmLib.CustomFuction.file2db_init(do_file, before_do_file, after_do_file,
  File "D:\Ina\ETL_XdmLib_2.A.13\ETL_XdmLib_2.A.13\EDAETL\ETL_TABLE\ETL_TEST_INA_WAT_TO_XSIFF\../..\XdmLib\CustomFuction.py", line 631, in file2db_init
    log.error(ex, exc_info=True, stack_info=True)
2023-08-23 17:51:08.079 - CustomFuction [ERROR   ] 'Series' object has no attribute 'split'
Traceback (most recent call last):
  File "D:\Ina\ETL_XdmLib_2.A.13\ETL_XdmLib_2.A.13\EDAETL\ETL_TABLE\ETL_TEST_INA_WAT_TO_XSIFF\../..\XdmLib\CustomFuction.py", line 596, in file2db_init
    res = do_file(file_root_source_path,
  File "D:\Ina\ETL_XdmLib_2.A.13\ETL_XdmLib_2.A.13\EDAETL\ETL_TABLE\ETL_TEST_INA_WAT_TO_XSIFF\ETL_TXT_TO_XSIFF.py", line 176, in do_file
    raise ex
  File "D:\Ina\ETL_XdmLib_2.A.13\ETL_XdmLib_2.A.13\EDAETL\ETL_TABLE\ETL_TEST_INA_WAT_TO_XSIFF\ETL_TXT_TO_XSIFF.py", line 125, in do_file
    DataDF[0] = DataDF[0].str.replace('RowData:', '').split(' ')
  File "D:\soft\anaconda3\lib\site-packages\pandas\core\generic.py", line 5575, in __getattr__
    return object.__getattribute__(self, name)
AttributeError: 'Series' object has no attribute 'split'
Stack (most recent call last):
  File "D:\Ina\ETL_XdmLib_2.A.13\ETL_XdmLib_2.A.13\EDAETL\ETL_TABLE\ETL_TEST_INA_WAT_TO_XSIFF\ETL_TXT_TO_XSIFF.py", line 292, in <module>
    XdmLib.CustomFuction.file2db_init(do_file, before_do_file, after_do_file,
  File "D:\Ina\ETL_XdmLib_2.A.13\ETL_XdmLib_2.A.13\EDAETL\ETL_TABLE\ETL_TEST_INA_WAT_TO_XSIFF\../..\XdmLib\CustomFuction.py", line 631, in file2db_init
    log.error(ex, exc_info=True, stack_info=True)
2023-08-23 17:58:30.383 - CustomFuction [ERROR   ] 'DataFrame' object has no attribute 'array'
Traceback (most recent call last):
  File "D:\Ina\ETL_XdmLib_2.A.13\ETL_XdmLib_2.A.13\EDAETL\ETL_TABLE\ETL_TEST_INA_WAT_TO_XSIFF\../..\XdmLib\CustomFuction.py", line 596, in file2db_init
    res = do_file(file_root_source_path,
  File "D:\Ina\ETL_XdmLib_2.A.13\ETL_XdmLib_2.A.13\EDAETL\ETL_TABLE\ETL_TEST_INA_WAT_TO_XSIFF\ETL_TXT_TO_XSIFF.py", line 176, in do_file
    raise ex
  File "D:\Ina\ETL_XdmLib_2.A.13\ETL_XdmLib_2.A.13\EDAETL\ETL_TABLE\ETL_TEST_INA_WAT_TO_XSIFF\ETL_TXT_TO_XSIFF.py", line 137, in do_file
    BinDefClassList = DataDF.array().tolist()
  File "D:\soft\anaconda3\lib\site-packages\pandas\core\generic.py", line 5575, in __getattr__
    return object.__getattribute__(self, name)
AttributeError: 'DataFrame' object has no attribute 'array'
Stack (most recent call last):
  File "D:\Ina\ETL_XdmLib_2.A.13\ETL_XdmLib_2.A.13\EDAETL\ETL_TABLE\ETL_TEST_INA_WAT_TO_XSIFF\ETL_TXT_TO_XSIFF.py", line 292, in <module>
    XdmLib.CustomFuction.file2db_init(do_file, before_do_file, after_do_file,
  File "D:\Ina\ETL_XdmLib_2.A.13\ETL_XdmLib_2.A.13\EDAETL\ETL_TABLE\ETL_TEST_INA_WAT_TO_XSIFF\../..\XdmLib\CustomFuction.py", line 631, in file2db_init
    log.error(ex, exc_info=True, stack_info=True)
2023-08-23 20:43:01.389 - base       [ERROR   ] Exception during reset or similar
Traceback (most recent call last):
  File "D:\Ina\ETL_XdmLib_2.A.13\ETL_XdmLib_2.A.13\EDAETL\ETL_TABLE\ETL_TEST_INA_WAT_TO_XSIFF\../..\XdmLib\CustomFuction.py", line 596, in file2db_init
    res = do_file(file_root_source_path,
  File "D:/Ina/ETL_XdmLib_2.A.13/ETL_XdmLib_2.A.13/EDAETL/ETL_TABLE/ETL_TEST_INA_WAT_TO_XSIFF/ETL_TXT_TO_XSIFF.py", line 147, in do_file
    print('STOP')
  File "D:/Ina/ETL_XdmLib_2.A.13/ETL_XdmLib_2.A.13/EDAETL/ETL_TABLE/ETL_TEST_INA_WAT_TO_XSIFF/ETL_TXT_TO_XSIFF.py", line 147, in do_file
    print('STOP')
  File "_pydevd_bundle\pydevd_cython_win32_39_64.pyx", line 1179, in _pydevd_bundle.pydevd_cython_win32_39_64.SafeCallWrapper.__call__
  File "_pydevd_bundle\pydevd_cython_win32_39_64.pyx", line 620, in _pydevd_bundle.pydevd_cython_win32_39_64.PyDBFrame.trace_dispatch
  File "_pydevd_bundle\pydevd_cython_win32_39_64.pyx", line 1095, in _pydevd_bundle.pydevd_cython_win32_39_64.PyDBFrame.trace_dispatch
  File "_pydevd_bundle\pydevd_cython_win32_39_64.pyx", line 1057, in _pydevd_bundle.pydevd_cython_win32_39_64.PyDBFrame.trace_dispatch
  File "_pydevd_bundle\pydevd_cython_win32_39_64.pyx", line 317, in _pydevd_bundle.pydevd_cython_win32_39_64.PyDBFrame.do_wait_suspend
  File "D:\soft\PyCharm Community Edition 2022.1.3\plugins\python-ce\helpers\pydev\pydevd.py", line 1155, in do_wait_suspend
    self._do_wait_suspend(thread, frame, event, arg, suspend_type, from_this_thread)
  File "D:\soft\PyCharm Community Edition 2022.1.3\plugins\python-ce\helpers\pydev\pydevd.py", line 1170, in _do_wait_suspend
    time.sleep(0.01)
KeyboardInterrupt

During handling of the above exception, another exception occurred:

Traceback (most recent call last):
  File "D:\soft\anaconda3\lib\site-packages\sqlalchemy\pool\base.py", line 739, in _finalize_fairy
    fairy._reset(pool)
  File "D:\soft\anaconda3\lib\site-packages\sqlalchemy\pool\base.py", line 988, in _reset
    pool._dialect.do_rollback(self)
  File "D:\soft\anaconda3\lib\site-packages\sqlalchemy\engine\default.py", line 682, in do_rollback
    dbapi_connection.rollback()
cx_Oracle.DatabaseError: DPI-1080: connection was closed by ORA-3135
2023-08-23 20:43:01.555 - base       [ERROR   ] Exception during reset or similar
Traceback (most recent call last):
  File "D:\Ina\ETL_XdmLib_2.A.13\ETL_XdmLib_2.A.13\EDAETL\ETL_TABLE\ETL_TEST_INA_WAT_TO_XSIFF\../..\XdmLib\CustomFuction.py", line 596, in file2db_init
    res = do_file(file_root_source_path,
  File "D:/Ina/ETL_XdmLib_2.A.13/ETL_XdmLib_2.A.13/EDAETL/ETL_TABLE/ETL_TEST_INA_WAT_TO_XSIFF/ETL_TXT_TO_XSIFF.py", line 147, in do_file
    print('STOP')
  File "D:/Ina/ETL_XdmLib_2.A.13/ETL_XdmLib_2.A.13/EDAETL/ETL_TABLE/ETL_TEST_INA_WAT_TO_XSIFF/ETL_TXT_TO_XSIFF.py", line 147, in do_file
    print('STOP')
  File "_pydevd_bundle\pydevd_cython_win32_39_64.pyx", line 1179, in _pydevd_bundle.pydevd_cython_win32_39_64.SafeCallWrapper.__call__
  File "_pydevd_bundle\pydevd_cython_win32_39_64.pyx", line 620, in _pydevd_bundle.pydevd_cython_win32_39_64.PyDBFrame.trace_dispatch
  File "_pydevd_bundle\pydevd_cython_win32_39_64.pyx", line 1095, in _pydevd_bundle.pydevd_cython_win32_39_64.PyDBFrame.trace_dispatch
  File "_pydevd_bundle\pydevd_cython_win32_39_64.pyx", line 1057, in _pydevd_bundle.pydevd_cython_win32_39_64.PyDBFrame.trace_dispatch
  File "_pydevd_bundle\pydevd_cython_win32_39_64.pyx", line 317, in _pydevd_bundle.pydevd_cython_win32_39_64.PyDBFrame.do_wait_suspend
  File "D:\soft\PyCharm Community Edition 2022.1.3\plugins\python-ce\helpers\pydev\pydevd.py", line 1155, in do_wait_suspend
    self._do_wait_suspend(thread, frame, event, arg, suspend_type, from_this_thread)
  File "D:\soft\PyCharm Community Edition 2022.1.3\plugins\python-ce\helpers\pydev\pydevd.py", line 1170, in _do_wait_suspend
    time.sleep(0.01)
KeyboardInterrupt

During handling of the above exception, another exception occurred:

Traceback (most recent call last):
  File "D:\soft\anaconda3\lib\site-packages\sqlalchemy\pool\base.py", line 739, in _finalize_fairy
    fairy._reset(pool)
  File "D:\soft\anaconda3\lib\site-packages\sqlalchemy\pool\base.py", line 988, in _reset
    pool._dialect.do_rollback(self)
  File "D:\soft\anaconda3\lib\site-packages\sqlalchemy\engine\default.py", line 682, in do_rollback
    dbapi_connection.rollback()
cx_Oracle.DatabaseError: DPI-1080: connection was closed by ORA-3135
2023-08-23 21:03:13.301 - __init__   [ERROR   ] Access XDM Loader control table fail.
