2023-09-14 11:15:28.175 - CustomFuction [ERROR   ] list index out of range
Traceback (most recent call last):
  File "D:\Ina\ETL_XdmLib_2.A.13\ETL_XdmLib_2.A.13\EDAETL\ETL_TABLE\ETL_TXT_TO_XSIFF\../..\XdmLib\CustomFuction.py", line 596, in file2db_init
    res = do_file(file_root_source_path,
  File "D:\Ina\ETL_XdmLib_2.A.13\ETL_XdmLib_2.A.13\EDAETL\ETL_TABLE\ETL_TXT_TO_XSIFF\ETL_TXT_TO_XSIFF.py", line 206, in do_file
    raise ex
  File "D:\Ina\ETL_XdmLib_2.A.13\ETL_XdmLib_2.A.13\EDAETL\ETL_TABLE\ETL_TXT_TO_XSIFF\ETL_TXT_TO_XSIFF.py", line 149, in do_file
    temp = line.split(':')[1]
IndexError: list index out of range
Stack (most recent call last):
  File "D:\Ina\ETL_XdmLib_2.A.13\ETL_XdmLib_2.A.13\EDAETL\ETL_TABLE\ETL_TXT_TO_XSIFF\ETL_TXT_TO_XSIFF.py", line 315, in <module>
    XdmLib.CustomFuction.file2db_init(
  File "D:\Ina\ETL_XdmLib_2.A.13\ETL_XdmLib_2.A.13\EDAETL\ETL_TABLE\ETL_TXT_TO_XSIFF\../..\XdmLib\CustomFuction.py", line 631, in file2db_init
    log.error(ex, exc_info=True, stack_info=True)
2023-09-14 11:17:33.087 - CustomFuction [ERROR   ] list index out of range
Traceback (most recent call last):
  File "D:\Ina\ETL_XdmLib_2.A.13\ETL_XdmLib_2.A.13\EDAETL\ETL_TABLE\ETL_TXT_TO_XSIFF\../..\XdmLib\CustomFuction.py", line 596, in file2db_init
    res = do_file(file_root_source_path,
  File "D:\Ina\ETL_XdmLib_2.A.13\ETL_XdmLib_2.A.13\EDAETL\ETL_TABLE\ETL_TXT_TO_XSIFF\ETL_TXT_TO_XSIFF.py", line 206, in do_file
    raise ex
  File "D:\Ina\ETL_XdmLib_2.A.13\ETL_XdmLib_2.A.13\EDAETL\ETL_TABLE\ETL_TXT_TO_XSIFF\ETL_TXT_TO_XSIFF.py", line 149, in do_file
    temp = line.split(':')[1]
IndexError: list index out of range
Stack (most recent call last):
  File "D:\Ina\ETL_XdmLib_2.A.13\ETL_XdmLib_2.A.13\EDAETL\ETL_TABLE\ETL_TXT_TO_XSIFF\ETL_TXT_TO_XSIFF.py", line 315, in <module>
    XdmLib.CustomFuction.file2db_init(
  File "D:\Ina\ETL_XdmLib_2.A.13\ETL_XdmLib_2.A.13\EDAETL\ETL_TABLE\ETL_TXT_TO_XSIFF\../..\XdmLib\CustomFuction.py", line 631, in file2db_init
    log.error(ex, exc_info=True, stack_info=True)
2023-09-14 11:19:17.931 - CustomFuction [ERROR   ] list index out of range
Traceback (most recent call last):
  File "D:\Ina\ETL_XdmLib_2.A.13\ETL_XdmLib_2.A.13\EDAETL\ETL_TABLE\ETL_TXT_TO_XSIFF\../..\XdmLib\CustomFuction.py", line 596, in file2db_init
    res = do_file(file_root_source_path,
  File "D:\Ina\ETL_XdmLib_2.A.13\ETL_XdmLib_2.A.13\EDAETL\ETL_TABLE\ETL_TXT_TO_XSIFF\ETL_TXT_TO_XSIFF.py", line 172, in do_file
    raise ex
  File "D:\Ina\ETL_XdmLib_2.A.13\ETL_XdmLib_2.A.13\EDAETL\ETL_TABLE\ETL_TXT_TO_XSIFF\ETL_TXT_TO_XSIFF.py", line 141, in do_file
    temp = line.split(':')[1]
IndexError: list index out of range
Stack (most recent call last):
  File "D:\Ina\ETL_XdmLib_2.A.13\ETL_XdmLib_2.A.13\EDAETL\ETL_TABLE\ETL_TXT_TO_XSIFF\ETL_TXT_TO_XSIFF.py", line 317, in <module>
    XdmLib.CustomFuction.file2db_init(
  File "D:\Ina\ETL_XdmLib_2.A.13\ETL_XdmLib_2.A.13\EDAETL\ETL_TABLE\ETL_TXT_TO_XSIFF\../..\XdmLib\CustomFuction.py", line 631, in file2db_init
    log.error(ex, exc_info=True, stack_info=True)
2023-09-14 11:21:12.078 - CustomFuction [ERROR   ] 'EqpName'
Traceback (most recent call last):
  File "D:\Ina\ETL_XdmLib_2.A.13\ETL_XdmLib_2.A.13\EDAETL\ETL_TABLE\ETL_TXT_TO_XSIFF\../..\XdmLib\CustomFuction.py", line 596, in file2db_init
    res = do_file(file_root_source_path,
  File "D:\Ina\ETL_XdmLib_2.A.13\ETL_XdmLib_2.A.13\EDAETL\ETL_TABLE\ETL_TXT_TO_XSIFF\ETL_TXT_TO_XSIFF.py", line 207, in do_file
    raise ex
  File "D:\Ina\ETL_XdmLib_2.A.13\ETL_XdmLib_2.A.13\EDAETL\ETL_TABLE\ETL_TXT_TO_XSIFF\ETL_TXT_TO_XSIFF.py", line 196, in do_file
    'EqpName':header_dict['EqpName'],
KeyError: 'EqpName'
Stack (most recent call last):
  File "D:\Ina\ETL_XdmLib_2.A.13\ETL_XdmLib_2.A.13\EDAETL\ETL_TABLE\ETL_TXT_TO_XSIFF\ETL_TXT_TO_XSIFF.py", line 316, in <module>
    XdmLib.CustomFuction.file2db_init(
  File "D:\Ina\ETL_XdmLib_2.A.13\ETL_XdmLib_2.A.13\EDAETL\ETL_TABLE\ETL_TXT_TO_XSIFF\../..\XdmLib\CustomFuction.py", line 631, in file2db_init
    log.error(ex, exc_info=True, stack_info=True)
2023-09-14 15:45:02.886 - CustomFuction [ERROR   ] Error tokenizing data. C error: Expected 2 fields in line 3, saw 3
Traceback (most recent call last):
  File "D:\Ina\ETL_XdmLib_2.A.13\ETL_XdmLib_2.A.13\EDAETL\ETL_TABLE\ETL_TXT_TO_XSIFF\../..\XdmLib\CustomFuction.py", line 596, in file2db_init
    res = do_file(file_root_source_path,
  File "D:\Ina\ETL_XdmLib_2.A.13\ETL_XdmLib_2.A.13\EDAETL\ETL_TABLE\ETL_TXT_TO_XSIFF\ETL_TXT_TO_XSIFF.py", line 178, in do_file
    raise ex
  File "D:\Ina\ETL_XdmLib_2.A.13\ETL_XdmLib_2.A.13\EDAETL\ETL_TABLE\ETL_TXT_TO_XSIFF\ETL_TXT_TO_XSIFF.py", line 135, in do_file
    data = pd.read_csv(file, delimiter='\s+', header=None)
  File "D:\soft\anaconda3\lib\site-packages\pandas\util\_decorators.py", line 311, in wrapper
    return func(*args, **kwargs)
  File "D:\soft\anaconda3\lib\site-packages\pandas\io\parsers\readers.py", line 680, in read_csv
    return _read(filepath_or_buffer, kwds)
  File "D:\soft\anaconda3\lib\site-packages\pandas\io\parsers\readers.py", line 581, in _read
    return parser.read(nrows)
  File "D:\soft\anaconda3\lib\site-packages\pandas\io\parsers\readers.py", line 1254, in read
    index, columns, col_dict = self._engine.read(nrows)
  File "D:\soft\anaconda3\lib\site-packages\pandas\io\parsers\c_parser_wrapper.py", line 225, in read
    chunks = self._reader.read_low_memory(nrows)
  File "pandas\_libs\parsers.pyx", line 805, in pandas._libs.parsers.TextReader.read_low_memory
  File "pandas\_libs\parsers.pyx", line 861, in pandas._libs.parsers.TextReader._read_rows
  File "pandas\_libs\parsers.pyx", line 847, in pandas._libs.parsers.TextReader._tokenize_rows
  File "pandas\_libs\parsers.pyx", line 1960, in pandas._libs.parsers.raise_parser_error
pandas.errors.ParserError: Error tokenizing data. C error: Expected 2 fields in line 3, saw 3
Stack (most recent call last):
  File "D:\Ina\ETL_XdmLib_2.A.13\ETL_XdmLib_2.A.13\EDAETL\ETL_TABLE\ETL_TXT_TO_XSIFF\ETL_TXT_TO_XSIFF.py", line 323, in <module>
    XdmLib.CustomFuction.file2db_init(
  File "D:\Ina\ETL_XdmLib_2.A.13\ETL_XdmLib_2.A.13\EDAETL\ETL_TABLE\ETL_TXT_TO_XSIFF\../..\XdmLib\CustomFuction.py", line 631, in file2db_init
    log.error(ex, exc_info=True, stack_info=True)
2023-09-14 15:47:13.251 - CustomFuction [ERROR   ] 'EqpName'
Traceback (most recent call last):
  File "D:\Ina\ETL_XdmLib_2.A.13\ETL_XdmLib_2.A.13\EDAETL\ETL_TABLE\ETL_TXT_TO_XSIFF\../..\XdmLib\CustomFuction.py", line 596, in file2db_init
    res = do_file(file_root_source_path,
  File "D:\Ina\ETL_XdmLib_2.A.13\ETL_XdmLib_2.A.13\EDAETL\ETL_TABLE\ETL_TXT_TO_XSIFF\ETL_TXT_TO_XSIFF.py", line 214, in do_file
    raise ex
  File "D:\Ina\ETL_XdmLib_2.A.13\ETL_XdmLib_2.A.13\EDAETL\ETL_TABLE\ETL_TXT_TO_XSIFF\ETL_TXT_TO_XSIFF.py", line 203, in do_file
    'EqpName':header_dict['EqpName'],
KeyError: 'EqpName'
Stack (most recent call last):
  File "D:\Ina\ETL_XdmLib_2.A.13\ETL_XdmLib_2.A.13\EDAETL\ETL_TABLE\ETL_TXT_TO_XSIFF\ETL_TXT_TO_XSIFF.py", line 323, in <module>
    XdmLib.CustomFuction.file2db_init(
  File "D:\Ina\ETL_XdmLib_2.A.13\ETL_XdmLib_2.A.13\EDAETL\ETL_TABLE\ETL_TXT_TO_XSIFF\../..\XdmLib\CustomFuction.py", line 631, in file2db_init
    log.error(ex, exc_info=True, stack_info=True)
2023-09-14 15:50:22.180 - CustomFuction [ERROR   ] name 'lines' is not defined
Traceback (most recent call last):
  File "D:\Ina\ETL_XdmLib_2.A.13\ETL_XdmLib_2.A.13\EDAETL\ETL_TABLE\ETL_TXT_TO_XSIFF\../..\XdmLib\CustomFuction.py", line 596, in file2db_init
    res = do_file(file_root_source_path,
  File "D:\Ina\ETL_XdmLib_2.A.13\ETL_XdmLib_2.A.13\EDAETL\ETL_TABLE\ETL_TXT_TO_XSIFF\ETL_TXT_TO_XSIFF.py", line 190, in do_file
    raise ex
  File "D:\Ina\ETL_XdmLib_2.A.13\ETL_XdmLib_2.A.13\EDAETL\ETL_TABLE\ETL_TXT_TO_XSIFF\ETL_TXT_TO_XSIFF.py", line 140, in do_file
    for line in lines:
NameError: name 'lines' is not defined
Stack (most recent call last):
  File "D:\Ina\ETL_XdmLib_2.A.13\ETL_XdmLib_2.A.13\EDAETL\ETL_TABLE\ETL_TXT_TO_XSIFF\ETL_TXT_TO_XSIFF.py", line 335, in <module>
    XdmLib.CustomFuction.file2db_init(
  File "D:\Ina\ETL_XdmLib_2.A.13\ETL_XdmLib_2.A.13\EDAETL\ETL_TABLE\ETL_TXT_TO_XSIFF\../..\XdmLib\CustomFuction.py", line 631, in file2db_init
    log.error(ex, exc_info=True, stack_info=True)
2023-09-14 15:50:48.220 - CustomFuction [ERROR   ] argument of type 'method' is not iterable
Traceback (most recent call last):
  File "D:\Ina\ETL_XdmLib_2.A.13\ETL_XdmLib_2.A.13\EDAETL\ETL_TABLE\ETL_TXT_TO_XSIFF\../..\XdmLib\CustomFuction.py", line 596, in file2db_init
    res = do_file(file_root_source_path,
  File "D:\Ina\ETL_XdmLib_2.A.13\ETL_XdmLib_2.A.13\EDAETL\ETL_TABLE\ETL_TXT_TO_XSIFF\ETL_TXT_TO_XSIFF.py", line 190, in do_file
    raise ex
  File "D:\Ina\ETL_XdmLib_2.A.13\ETL_XdmLib_2.A.13\EDAETL\ETL_TABLE\ETL_TXT_TO_XSIFF\ETL_TXT_TO_XSIFF.py", line 152, in do_file
    DataDF = pd.read_csv(pd.Series(data_lines), sep='\s+', header=None)
  File "D:\soft\anaconda3\lib\site-packages\pandas\util\_decorators.py", line 311, in wrapper
    return func(*args, **kwargs)
  File "D:\soft\anaconda3\lib\site-packages\pandas\io\parsers\readers.py", line 680, in read_csv
    return _read(filepath_or_buffer, kwds)
  File "D:\soft\anaconda3\lib\site-packages\pandas\io\parsers\readers.py", line 575, in _read
    parser = TextFileReader(filepath_or_buffer, **kwds)
  File "D:\soft\anaconda3\lib\site-packages\pandas\io\parsers\readers.py", line 933, in __init__
    self._engine = self._make_engine(f, self.engine)
  File "D:\soft\anaconda3\lib\site-packages\pandas\io\parsers\readers.py", line 1217, in _make_engine
    self.handles = get_handle(  # type: ignore[call-overload]
  File "D:\soft\anaconda3\lib\site-packages\pandas\io\common.py", line 661, in get_handle
    if _is_binary_mode(path_or_buf, mode) and "b" not in mode:
  File "D:\soft\anaconda3\lib\site-packages\pandas\io\common.py", line 1128, in _is_binary_mode
    return isinstance(handle, _get_binary_io_classes()) or "b" in getattr(
TypeError: argument of type 'method' is not iterable
Stack (most recent call last):
  File "D:\Ina\ETL_XdmLib_2.A.13\ETL_XdmLib_2.A.13\EDAETL\ETL_TABLE\ETL_TXT_TO_XSIFF\ETL_TXT_TO_XSIFF.py", line 335, in <module>
    XdmLib.CustomFuction.file2db_init(
  File "D:\Ina\ETL_XdmLib_2.A.13\ETL_XdmLib_2.A.13\EDAETL\ETL_TABLE\ETL_TXT_TO_XSIFF\../..\XdmLib\CustomFuction.py", line 631, in file2db_init
    log.error(ex, exc_info=True, stack_info=True)
2023-09-14 15:52:19.348 - CustomFuction [ERROR   ] 'EqpName'
Traceback (most recent call last):
  File "D:\Ina\ETL_XdmLib_2.A.13\ETL_XdmLib_2.A.13\EDAETL\ETL_TABLE\ETL_TXT_TO_XSIFF\../..\XdmLib\CustomFuction.py", line 596, in file2db_init
    res = do_file(file_root_source_path,
  File "D:\Ina\ETL_XdmLib_2.A.13\ETL_XdmLib_2.A.13\EDAETL\ETL_TABLE\ETL_TXT_TO_XSIFF\ETL_TXT_TO_XSIFF.py", line 226, in do_file
    raise ex
  File "D:\Ina\ETL_XdmLib_2.A.13\ETL_XdmLib_2.A.13\EDAETL\ETL_TABLE\ETL_TXT_TO_XSIFF\ETL_TXT_TO_XSIFF.py", line 215, in do_file
    'EqpName':header_dict['EqpName'],
KeyError: 'EqpName'
Stack (most recent call last):
  File "D:\Ina\ETL_XdmLib_2.A.13\ETL_XdmLib_2.A.13\EDAETL\ETL_TABLE\ETL_TXT_TO_XSIFF\ETL_TXT_TO_XSIFF.py", line 335, in <module>
    XdmLib.CustomFuction.file2db_init(
  File "D:\Ina\ETL_XdmLib_2.A.13\ETL_XdmLib_2.A.13\EDAETL\ETL_TABLE\ETL_TXT_TO_XSIFF\../..\XdmLib\CustomFuction.py", line 631, in file2db_init
    log.error(ex, exc_info=True, stack_info=True)
2023-09-14 15:53:39.015 - CustomFuction [ERROR   ] 'EqpName'
Traceback (most recent call last):
  File "D:\Ina\ETL_XdmLib_2.A.13\ETL_XdmLib_2.A.13\EDAETL\ETL_TABLE\ETL_TXT_TO_XSIFF\../..\XdmLib\CustomFuction.py", line 596, in file2db_init
    res = do_file(file_root_source_path,
  File "D:\Ina\ETL_XdmLib_2.A.13\ETL_XdmLib_2.A.13\EDAETL\ETL_TABLE\ETL_TXT_TO_XSIFF\ETL_TXT_TO_XSIFF.py", line 226, in do_file
    raise ex
  File "D:\Ina\ETL_XdmLib_2.A.13\ETL_XdmLib_2.A.13\EDAETL\ETL_TABLE\ETL_TXT_TO_XSIFF\ETL_TXT_TO_XSIFF.py", line 215, in do_file
    'EqpName':header_dict['EqpName'],
KeyError: 'EqpName'
Stack (most recent call last):
  File "D:\Ina\ETL_XdmLib_2.A.13\ETL_XdmLib_2.A.13\EDAETL\ETL_TABLE\ETL_TXT_TO_XSIFF\ETL_TXT_TO_XSIFF.py", line 335, in <module>
    XdmLib.CustomFuction.file2db_init(
  File "D:\Ina\ETL_XdmLib_2.A.13\ETL_XdmLib_2.A.13\EDAETL\ETL_TABLE\ETL_TXT_TO_XSIFF\../..\XdmLib\CustomFuction.py", line 631, in file2db_init
    log.error(ex, exc_info=True, stack_info=True)
2023-09-14 16:04:58.293 - CustomFuction [ERROR   ] Error tokenizing data. C error: Expected 1 fields in line 14, saw 8
Traceback (most recent call last):
  File "D:\Ina\ETL_XdmLib_2.A.13\ETL_XdmLib_2.A.13\EDAETL\ETL_TABLE\ETL_TXT_TO_XSIFF\../..\XdmLib\CustomFuction.py", line 596, in file2db_init
    res = do_file(file_root_source_path,
  File "D:\Ina\ETL_XdmLib_2.A.13\ETL_XdmLib_2.A.13\EDAETL\ETL_TABLE\ETL_TXT_TO_XSIFF\ETL_TXT_TO_XSIFF.py", line 185, in do_file
    raise ex
  File "D:\Ina\ETL_XdmLib_2.A.13\ETL_XdmLib_2.A.13\EDAETL\ETL_TABLE\ETL_TXT_TO_XSIFF\ETL_TXT_TO_XSIFF.py", line 135, in do_file
    data = pd.read_csv(file, delimiter=',', header=None)
  File "D:\soft\anaconda3\lib\site-packages\pandas\util\_decorators.py", line 311, in wrapper
    return func(*args, **kwargs)
  File "D:\soft\anaconda3\lib\site-packages\pandas\io\parsers\readers.py", line 680, in read_csv
    return _read(filepath_or_buffer, kwds)
  File "D:\soft\anaconda3\lib\site-packages\pandas\io\parsers\readers.py", line 581, in _read
    return parser.read(nrows)
  File "D:\soft\anaconda3\lib\site-packages\pandas\io\parsers\readers.py", line 1254, in read
    index, columns, col_dict = self._engine.read(nrows)
  File "D:\soft\anaconda3\lib\site-packages\pandas\io\parsers\c_parser_wrapper.py", line 225, in read
    chunks = self._reader.read_low_memory(nrows)
  File "pandas\_libs\parsers.pyx", line 805, in pandas._libs.parsers.TextReader.read_low_memory
  File "pandas\_libs\parsers.pyx", line 861, in pandas._libs.parsers.TextReader._read_rows
  File "pandas\_libs\parsers.pyx", line 847, in pandas._libs.parsers.TextReader._tokenize_rows
  File "pandas\_libs\parsers.pyx", line 1960, in pandas._libs.parsers.raise_parser_error
pandas.errors.ParserError: Error tokenizing data. C error: Expected 1 fields in line 14, saw 8
Stack (most recent call last):
  File "D:\Ina\ETL_XdmLib_2.A.13\ETL_XdmLib_2.A.13\EDAETL\ETL_TABLE\ETL_TXT_TO_XSIFF\ETL_TXT_TO_XSIFF.py", line 330, in <module>
    XdmLib.CustomFuction.file2db_init(
  File "D:\Ina\ETL_XdmLib_2.A.13\ETL_XdmLib_2.A.13\EDAETL\ETL_TABLE\ETL_TXT_TO_XSIFF\../..\XdmLib\CustomFuction.py", line 631, in file2db_init
    log.error(ex, exc_info=True, stack_info=True)
2023-09-14 16:08:04.723 - CustomFuction [ERROR   ] Error tokenizing data. C error: Expected 2 fields in line 3, saw 3
Traceback (most recent call last):
  File "D:\Ina\ETL_XdmLib_2.A.13\ETL_XdmLib_2.A.13\EDAETL\ETL_TABLE\ETL_TXT_TO_XSIFF\../..\XdmLib\CustomFuction.py", line 596, in file2db_init
    res = do_file(file_root_source_path,
  File "D:\Ina\ETL_XdmLib_2.A.13\ETL_XdmLib_2.A.13\EDAETL\ETL_TABLE\ETL_TXT_TO_XSIFF\ETL_TXT_TO_XSIFF.py", line 185, in do_file
    raise ex
  File "D:\Ina\ETL_XdmLib_2.A.13\ETL_XdmLib_2.A.13\EDAETL\ETL_TABLE\ETL_TXT_TO_XSIFF\ETL_TXT_TO_XSIFF.py", line 135, in do_file
    data = pd.read_csv(file, delimiter='\s+', header=None)
  File "D:\soft\anaconda3\lib\site-packages\pandas\util\_decorators.py", line 311, in wrapper
    return func(*args, **kwargs)
  File "D:\soft\anaconda3\lib\site-packages\pandas\io\parsers\readers.py", line 680, in read_csv
    return _read(filepath_or_buffer, kwds)
  File "D:\soft\anaconda3\lib\site-packages\pandas\io\parsers\readers.py", line 581, in _read
    return parser.read(nrows)
  File "D:\soft\anaconda3\lib\site-packages\pandas\io\parsers\readers.py", line 1254, in read
    index, columns, col_dict = self._engine.read(nrows)
  File "D:\soft\anaconda3\lib\site-packages\pandas\io\parsers\c_parser_wrapper.py", line 225, in read
    chunks = self._reader.read_low_memory(nrows)
  File "pandas\_libs\parsers.pyx", line 805, in pandas._libs.parsers.TextReader.read_low_memory
  File "pandas\_libs\parsers.pyx", line 861, in pandas._libs.parsers.TextReader._read_rows
  File "pandas\_libs\parsers.pyx", line 847, in pandas._libs.parsers.TextReader._tokenize_rows
  File "pandas\_libs\parsers.pyx", line 1960, in pandas._libs.parsers.raise_parser_error
pandas.errors.ParserError: Error tokenizing data. C error: Expected 2 fields in line 3, saw 3
Stack (most recent call last):
  File "D:\Ina\ETL_XdmLib_2.A.13\ETL_XdmLib_2.A.13\EDAETL\ETL_TABLE\ETL_TXT_TO_XSIFF\ETL_TXT_TO_XSIFF.py", line 330, in <module>
    XdmLib.CustomFuction.file2db_init(
  File "D:\Ina\ETL_XdmLib_2.A.13\ETL_XdmLib_2.A.13\EDAETL\ETL_TABLE\ETL_TXT_TO_XSIFF\../..\XdmLib\CustomFuction.py", line 631, in file2db_init
    log.error(ex, exc_info=True, stack_info=True)
2023-09-14 16:10:24.706 - CustomFuction [ERROR   ] Error tokenizing data. C error: Expected 8 fields in line 19, saw 12
Traceback (most recent call last):
  File "D:\Ina\ETL_XdmLib_2.A.13\ETL_XdmLib_2.A.13\EDAETL\ETL_TABLE\ETL_TXT_TO_XSIFF\../..\XdmLib\CustomFuction.py", line 596, in file2db_init
    res = do_file(file_root_source_path,
  File "D:\Ina\ETL_XdmLib_2.A.13\ETL_XdmLib_2.A.13\EDAETL\ETL_TABLE\ETL_TXT_TO_XSIFF\ETL_TXT_TO_XSIFF.py", line 181, in do_file
    raise ex
  File "D:\Ina\ETL_XdmLib_2.A.13\ETL_XdmLib_2.A.13\EDAETL\ETL_TABLE\ETL_TXT_TO_XSIFF\ETL_TXT_TO_XSIFF.py", line 135, in do_file
    data = pd.read_csv(file, delimiter='\s+', skiprows=11)
  File "D:\soft\anaconda3\lib\site-packages\pandas\util\_decorators.py", line 311, in wrapper
    return func(*args, **kwargs)
  File "D:\soft\anaconda3\lib\site-packages\pandas\io\parsers\readers.py", line 680, in read_csv
    return _read(filepath_or_buffer, kwds)
  File "D:\soft\anaconda3\lib\site-packages\pandas\io\parsers\readers.py", line 581, in _read
    return parser.read(nrows)
  File "D:\soft\anaconda3\lib\site-packages\pandas\io\parsers\readers.py", line 1254, in read
    index, columns, col_dict = self._engine.read(nrows)
  File "D:\soft\anaconda3\lib\site-packages\pandas\io\parsers\c_parser_wrapper.py", line 225, in read
    chunks = self._reader.read_low_memory(nrows)
  File "pandas\_libs\parsers.pyx", line 805, in pandas._libs.parsers.TextReader.read_low_memory
  File "pandas\_libs\parsers.pyx", line 861, in pandas._libs.parsers.TextReader._read_rows
  File "pandas\_libs\parsers.pyx", line 847, in pandas._libs.parsers.TextReader._tokenize_rows
  File "pandas\_libs\parsers.pyx", line 1960, in pandas._libs.parsers.raise_parser_error
pandas.errors.ParserError: Error tokenizing data. C error: Expected 8 fields in line 19, saw 12
Stack (most recent call last):
  File "D:\Ina\ETL_XdmLib_2.A.13\ETL_XdmLib_2.A.13\EDAETL\ETL_TABLE\ETL_TXT_TO_XSIFF\ETL_TXT_TO_XSIFF.py", line 326, in <module>
    XdmLib.CustomFuction.file2db_init(
  File "D:\Ina\ETL_XdmLib_2.A.13\ETL_XdmLib_2.A.13\EDAETL\ETL_TABLE\ETL_TXT_TO_XSIFF\../..\XdmLib\CustomFuction.py", line 631, in file2db_init
    log.error(ex, exc_info=True, stack_info=True)
2023-09-14 16:30:05.102 - CustomFuction [ERROR   ] Error tokenizing data. C error: Expected 2 fields in line 8, saw 3
Traceback (most recent call last):
  File "D:\Ina\ETL_XdmLib_2.A.13\ETL_XdmLib_2.A.13\EDAETL\ETL_TABLE\ETL_TXT_TO_XSIFF\../..\XdmLib\CustomFuction.py", line 596, in file2db_init
    res = do_file(file_root_source_path,
  File "D:\Ina\ETL_XdmLib_2.A.13\ETL_XdmLib_2.A.13\EDAETL\ETL_TABLE\ETL_TXT_TO_XSIFF\ETL_TXT_TO_XSIFF.py", line 187, in do_file
    raise ex
  File "D:\Ina\ETL_XdmLib_2.A.13\ETL_XdmLib_2.A.13\EDAETL\ETL_TABLE\ETL_TXT_TO_XSIFF\ETL_TXT_TO_XSIFF.py", line 154, in do_file
    data = pd.read_csv(file_path, delimiter='\s+',
  File "D:\soft\anaconda3\lib\site-packages\pandas\util\_decorators.py", line 311, in wrapper
    return func(*args, **kwargs)
  File "D:\soft\anaconda3\lib\site-packages\pandas\io\parsers\readers.py", line 680, in read_csv
    return _read(filepath_or_buffer, kwds)
  File "D:\soft\anaconda3\lib\site-packages\pandas\io\parsers\readers.py", line 581, in _read
    return parser.read(nrows)
  File "D:\soft\anaconda3\lib\site-packages\pandas\io\parsers\readers.py", line 1254, in read
    index, columns, col_dict = self._engine.read(nrows)
  File "D:\soft\anaconda3\lib\site-packages\pandas\io\parsers\c_parser_wrapper.py", line 225, in read
    chunks = self._reader.read_low_memory(nrows)
  File "pandas\_libs\parsers.pyx", line 805, in pandas._libs.parsers.TextReader.read_low_memory
  File "pandas\_libs\parsers.pyx", line 861, in pandas._libs.parsers.TextReader._read_rows
  File "pandas\_libs\parsers.pyx", line 847, in pandas._libs.parsers.TextReader._tokenize_rows
  File "pandas\_libs\parsers.pyx", line 1960, in pandas._libs.parsers.raise_parser_error
pandas.errors.ParserError: Error tokenizing data. C error: Expected 2 fields in line 8, saw 3
Stack (most recent call last):
  File "D:\Ina\ETL_XdmLib_2.A.13\ETL_XdmLib_2.A.13\EDAETL\ETL_TABLE\ETL_TXT_TO_XSIFF\ETL_TXT_TO_XSIFF.py", line 332, in <module>
    XdmLib.CustomFuction.file2db_init(
  File "D:\Ina\ETL_XdmLib_2.A.13\ETL_XdmLib_2.A.13\EDAETL\ETL_TABLE\ETL_TXT_TO_XSIFF\../..\XdmLib\CustomFuction.py", line 631, in file2db_init
    log.error(ex, exc_info=True, stack_info=True)
2023-09-14 16:31:06.889 - CustomFuction [ERROR   ] Error tokenizing data. C error: Expected 2 fields in line 8, saw 3
Traceback (most recent call last):
  File "D:\Ina\ETL_XdmLib_2.A.13\ETL_XdmLib_2.A.13\EDAETL\ETL_TABLE\ETL_TXT_TO_XSIFF\../..\XdmLib\CustomFuction.py", line 596, in file2db_init
    res = do_file(file_root_source_path,
  File "D:\Ina\ETL_XdmLib_2.A.13\ETL_XdmLib_2.A.13\EDAETL\ETL_TABLE\ETL_TXT_TO_XSIFF\ETL_TXT_TO_XSIFF.py", line 186, in do_file
    raise ex
  File "D:\Ina\ETL_XdmLib_2.A.13\ETL_XdmLib_2.A.13\EDAETL\ETL_TABLE\ETL_TXT_TO_XSIFF\ETL_TXT_TO_XSIFF.py", line 134, in do_file
    data = pd.read_csv(file, delimiter='\s+',
  File "D:\soft\anaconda3\lib\site-packages\pandas\util\_decorators.py", line 311, in wrapper
    return func(*args, **kwargs)
  File "D:\soft\anaconda3\lib\site-packages\pandas\io\parsers\readers.py", line 680, in read_csv
    return _read(filepath_or_buffer, kwds)
  File "D:\soft\anaconda3\lib\site-packages\pandas\io\parsers\readers.py", line 581, in _read
    return parser.read(nrows)
  File "D:\soft\anaconda3\lib\site-packages\pandas\io\parsers\readers.py", line 1254, in read
    index, columns, col_dict = self._engine.read(nrows)
  File "D:\soft\anaconda3\lib\site-packages\pandas\io\parsers\c_parser_wrapper.py", line 225, in read
    chunks = self._reader.read_low_memory(nrows)
  File "pandas\_libs\parsers.pyx", line 805, in pandas._libs.parsers.TextReader.read_low_memory
  File "pandas\_libs\parsers.pyx", line 861, in pandas._libs.parsers.TextReader._read_rows
  File "pandas\_libs\parsers.pyx", line 847, in pandas._libs.parsers.TextReader._tokenize_rows
  File "pandas\_libs\parsers.pyx", line 1960, in pandas._libs.parsers.raise_parser_error
pandas.errors.ParserError: Error tokenizing data. C error: Expected 2 fields in line 8, saw 3
Stack (most recent call last):
  File "D:\Ina\ETL_XdmLib_2.A.13\ETL_XdmLib_2.A.13\EDAETL\ETL_TABLE\ETL_TXT_TO_XSIFF\ETL_TXT_TO_XSIFF.py", line 331, in <module>
    XdmLib.CustomFuction.file2db_init(
  File "D:\Ina\ETL_XdmLib_2.A.13\ETL_XdmLib_2.A.13\EDAETL\ETL_TABLE\ETL_TXT_TO_XSIFF\../..\XdmLib\CustomFuction.py", line 631, in file2db_init
    log.error(ex, exc_info=True, stack_info=True)
2023-09-14 16:34:52.068 - CustomFuction [ERROR   ] Error tokenizing data. C error: Expected 12 fields in line 20, saw 15
Traceback (most recent call last):
  File "D:\Ina\ETL_XdmLib_2.A.13\ETL_XdmLib_2.A.13\EDAETL\ETL_TABLE\ETL_TXT_TO_XSIFF\../..\XdmLib\CustomFuction.py", line 596, in file2db_init
    res = do_file(file_root_source_path,
  File "D:\Ina\ETL_XdmLib_2.A.13\ETL_XdmLib_2.A.13\EDAETL\ETL_TABLE\ETL_TXT_TO_XSIFF\ETL_TXT_TO_XSIFF.py", line 186, in do_file
    raise ex
  File "D:\Ina\ETL_XdmLib_2.A.13\ETL_XdmLib_2.A.13\EDAETL\ETL_TABLE\ETL_TXT_TO_XSIFF\ETL_TXT_TO_XSIFF.py", line 134, in do_file
    data = pd.read_csv(file, delimiter='\s+',
  File "D:\soft\anaconda3\lib\site-packages\pandas\util\_decorators.py", line 311, in wrapper
    return func(*args, **kwargs)
  File "D:\soft\anaconda3\lib\site-packages\pandas\io\parsers\readers.py", line 680, in read_csv
    return _read(filepath_or_buffer, kwds)
  File "D:\soft\anaconda3\lib\site-packages\pandas\io\parsers\readers.py", line 581, in _read
    return parser.read(nrows)
  File "D:\soft\anaconda3\lib\site-packages\pandas\io\parsers\readers.py", line 1254, in read
    index, columns, col_dict = self._engine.read(nrows)
  File "D:\soft\anaconda3\lib\site-packages\pandas\io\parsers\c_parser_wrapper.py", line 225, in read
    chunks = self._reader.read_low_memory(nrows)
  File "pandas\_libs\parsers.pyx", line 805, in pandas._libs.parsers.TextReader.read_low_memory
  File "pandas\_libs\parsers.pyx", line 861, in pandas._libs.parsers.TextReader._read_rows
  File "pandas\_libs\parsers.pyx", line 847, in pandas._libs.parsers.TextReader._tokenize_rows
  File "pandas\_libs\parsers.pyx", line 1960, in pandas._libs.parsers.raise_parser_error
pandas.errors.ParserError: Error tokenizing data. C error: Expected 12 fields in line 20, saw 15
Stack (most recent call last):
  File "D:\Ina\ETL_XdmLib_2.A.13\ETL_XdmLib_2.A.13\EDAETL\ETL_TABLE\ETL_TXT_TO_XSIFF\ETL_TXT_TO_XSIFF.py", line 331, in <module>
    XdmLib.CustomFuction.file2db_init(
  File "D:\Ina\ETL_XdmLib_2.A.13\ETL_XdmLib_2.A.13\EDAETL\ETL_TABLE\ETL_TXT_TO_XSIFF\../..\XdmLib\CustomFuction.py", line 631, in file2db_init
    log.error(ex, exc_info=True, stack_info=True)
2023-09-14 16:40:14.143 - CustomFuction [ERROR   ] Specified \n as separator or delimiter. This forces the python engine which does not accept a line terminator. Hence it is not allowed to use the line terminator as separator.
Traceback (most recent call last):
  File "D:\Ina\ETL_XdmLib_2.A.13\ETL_XdmLib_2.A.13\EDAETL\ETL_TABLE\ETL_TXT_TO_XSIFF\../..\XdmLib\CustomFuction.py", line 596, in file2db_init
    res = do_file(file_root_source_path,
  File "D:\Ina\ETL_XdmLib_2.A.13\ETL_XdmLib_2.A.13\EDAETL\ETL_TABLE\ETL_TXT_TO_XSIFF\ETL_TXT_TO_XSIFF.py", line 197, in do_file
    raise ex
  File "D:\Ina\ETL_XdmLib_2.A.13\ETL_XdmLib_2.A.13\EDAETL\ETL_TABLE\ETL_TXT_TO_XSIFF\ETL_TXT_TO_XSIFF.py", line 134, in do_file
    data = pd.read_csv(file, delimiter='\n', header=None)
  File "D:\soft\anaconda3\lib\site-packages\pandas\util\_decorators.py", line 311, in wrapper
    return func(*args, **kwargs)
  File "D:\soft\anaconda3\lib\site-packages\pandas\io\parsers\readers.py", line 665, in read_csv
    kwds_defaults = _refine_defaults_read(
  File "D:\soft\anaconda3\lib\site-packages\pandas\io\parsers\readers.py", line 1537, in _refine_defaults_read
    raise ValueError(
ValueError: Specified \n as separator or delimiter. This forces the python engine which does not accept a line terminator. Hence it is not allowed to use the line terminator as separator.
Stack (most recent call last):
  File "D:\Ina\ETL_XdmLib_2.A.13\ETL_XdmLib_2.A.13\EDAETL\ETL_TABLE\ETL_TXT_TO_XSIFF\ETL_TXT_TO_XSIFF.py", line 342, in <module>
    XdmLib.CustomFuction.file2db_init(
  File "D:\Ina\ETL_XdmLib_2.A.13\ETL_XdmLib_2.A.13\EDAETL\ETL_TABLE\ETL_TXT_TO_XSIFF\../..\XdmLib\CustomFuction.py", line 631, in file2db_init
    log.error(ex, exc_info=True, stack_info=True)
2023-09-14 16:42:36.532 - CustomFuction [ERROR   ] Error tokenizing data. C error: Expected 2 fields in line 3, saw 3
Traceback (most recent call last):
  File "D:\Ina\ETL_XdmLib_2.A.13\ETL_XdmLib_2.A.13\EDAETL\ETL_TABLE\ETL_TXT_TO_XSIFF\../..\XdmLib\CustomFuction.py", line 596, in file2db_init
    res = do_file(file_root_source_path,
  File "D:\Ina\ETL_XdmLib_2.A.13\ETL_XdmLib_2.A.13\EDAETL\ETL_TABLE\ETL_TXT_TO_XSIFF\ETL_TXT_TO_XSIFF.py", line 197, in do_file
    raise ex
  File "D:\Ina\ETL_XdmLib_2.A.13\ETL_XdmLib_2.A.13\EDAETL\ETL_TABLE\ETL_TXT_TO_XSIFF\ETL_TXT_TO_XSIFF.py", line 134, in do_file
    data = pd.read_csv(file, delimiter='\s+', header=None)
  File "D:\soft\anaconda3\lib\site-packages\pandas\util\_decorators.py", line 311, in wrapper
    return func(*args, **kwargs)
  File "D:\soft\anaconda3\lib\site-packages\pandas\io\parsers\readers.py", line 680, in read_csv
    return _read(filepath_or_buffer, kwds)
  File "D:\soft\anaconda3\lib\site-packages\pandas\io\parsers\readers.py", line 581, in _read
    return parser.read(nrows)
  File "D:\soft\anaconda3\lib\site-packages\pandas\io\parsers\readers.py", line 1254, in read
    index, columns, col_dict = self._engine.read(nrows)
  File "D:\soft\anaconda3\lib\site-packages\pandas\io\parsers\c_parser_wrapper.py", line 225, in read
    chunks = self._reader.read_low_memory(nrows)
  File "pandas\_libs\parsers.pyx", line 805, in pandas._libs.parsers.TextReader.read_low_memory
  File "pandas\_libs\parsers.pyx", line 861, in pandas._libs.parsers.TextReader._read_rows
  File "pandas\_libs\parsers.pyx", line 847, in pandas._libs.parsers.TextReader._tokenize_rows
  File "pandas\_libs\parsers.pyx", line 1960, in pandas._libs.parsers.raise_parser_error
pandas.errors.ParserError: Error tokenizing data. C error: Expected 2 fields in line 3, saw 3
Stack (most recent call last):
  File "D:\Ina\ETL_XdmLib_2.A.13\ETL_XdmLib_2.A.13\EDAETL\ETL_TABLE\ETL_TXT_TO_XSIFF\ETL_TXT_TO_XSIFF.py", line 342, in <module>
    XdmLib.CustomFuction.file2db_init(
  File "D:\Ina\ETL_XdmLib_2.A.13\ETL_XdmLib_2.A.13\EDAETL\ETL_TABLE\ETL_TXT_TO_XSIFF\../..\XdmLib\CustomFuction.py", line 631, in file2db_init
    log.error(ex, exc_info=True, stack_info=True)
2023-09-14 16:44:02.870 - CustomFuction [ERROR   ] name 'header_dict' is not defined
Traceback (most recent call last):
  File "D:\Ina\ETL_XdmLib_2.A.13\ETL_XdmLib_2.A.13\EDAETL\ETL_TABLE\ETL_TXT_TO_XSIFF\../..\XdmLib\CustomFuction.py", line 596, in file2db_init
    res = do_file(file_root_source_path,
  File "D:\Ina\ETL_XdmLib_2.A.13\ETL_XdmLib_2.A.13\EDAETL\ETL_TABLE\ETL_TXT_TO_XSIFF\ETL_TXT_TO_XSIFF.py", line 197, in do_file
    raise ex
  File "D:\Ina\ETL_XdmLib_2.A.13\ETL_XdmLib_2.A.13\EDAETL\ETL_TABLE\ETL_TXT_TO_XSIFF\ETL_TXT_TO_XSIFF.py", line 148, in do_file
    header_dict['Lot'] = file_name.split('_')[1]
NameError: name 'header_dict' is not defined
Stack (most recent call last):
  File "D:\Ina\ETL_XdmLib_2.A.13\ETL_XdmLib_2.A.13\EDAETL\ETL_TABLE\ETL_TXT_TO_XSIFF\ETL_TXT_TO_XSIFF.py", line 342, in <module>
    XdmLib.CustomFuction.file2db_init(
  File "D:\Ina\ETL_XdmLib_2.A.13\ETL_XdmLib_2.A.13\EDAETL\ETL_TABLE\ETL_TXT_TO_XSIFF\../..\XdmLib\CustomFuction.py", line 631, in file2db_init
    log.error(ex, exc_info=True, stack_info=True)
2023-09-14 16:44:50.056 - CustomFuction [ERROR   ] name 'lines' is not defined
Traceback (most recent call last):
  File "D:\Ina\ETL_XdmLib_2.A.13\ETL_XdmLib_2.A.13\EDAETL\ETL_TABLE\ETL_TXT_TO_XSIFF\../..\XdmLib\CustomFuction.py", line 596, in file2db_init
    res = do_file(file_root_source_path,
  File "D:\Ina\ETL_XdmLib_2.A.13\ETL_XdmLib_2.A.13\EDAETL\ETL_TABLE\ETL_TXT_TO_XSIFF\ETL_TXT_TO_XSIFF.py", line 197, in do_file
    raise ex
  File "D:\Ina\ETL_XdmLib_2.A.13\ETL_XdmLib_2.A.13\EDAETL\ETL_TABLE\ETL_TXT_TO_XSIFF\ETL_TXT_TO_XSIFF.py", line 153, in do_file
    for line in lines:
NameError: name 'lines' is not defined
Stack (most recent call last):
  File "D:\Ina\ETL_XdmLib_2.A.13\ETL_XdmLib_2.A.13\EDAETL\ETL_TABLE\ETL_TXT_TO_XSIFF\ETL_TXT_TO_XSIFF.py", line 342, in <module>
    XdmLib.CustomFuction.file2db_init(
  File "D:\Ina\ETL_XdmLib_2.A.13\ETL_XdmLib_2.A.13\EDAETL\ETL_TABLE\ETL_TXT_TO_XSIFF\../..\XdmLib\CustomFuction.py", line 631, in file2db_init
    log.error(ex, exc_info=True, stack_info=True)
2023-09-14 16:45:32.980 - CustomFuction [ERROR   ] 'EqpName'
Traceback (most recent call last):
  File "D:\Ina\ETL_XdmLib_2.A.13\ETL_XdmLib_2.A.13\EDAETL\ETL_TABLE\ETL_TXT_TO_XSIFF\../..\XdmLib\CustomFuction.py", line 596, in file2db_init
    res = do_file(file_root_source_path,
  File "D:\Ina\ETL_XdmLib_2.A.13\ETL_XdmLib_2.A.13\EDAETL\ETL_TABLE\ETL_TXT_TO_XSIFF\ETL_TXT_TO_XSIFF.py", line 233, in do_file
    raise ex
  File "D:\Ina\ETL_XdmLib_2.A.13\ETL_XdmLib_2.A.13\EDAETL\ETL_TABLE\ETL_TXT_TO_XSIFF\ETL_TXT_TO_XSIFF.py", line 222, in do_file
    'EqpName':header_dict['EqpName'],
KeyError: 'EqpName'
Stack (most recent call last):
  File "D:\Ina\ETL_XdmLib_2.A.13\ETL_XdmLib_2.A.13\EDAETL\ETL_TABLE\ETL_TXT_TO_XSIFF\ETL_TXT_TO_XSIFF.py", line 342, in <module>
    XdmLib.CustomFuction.file2db_init(
  File "D:\Ina\ETL_XdmLib_2.A.13\ETL_XdmLib_2.A.13\EDAETL\ETL_TABLE\ETL_TXT_TO_XSIFF\../..\XdmLib\CustomFuction.py", line 631, in file2db_init
    log.error(ex, exc_info=True, stack_info=True)
2023-09-14 16:47:44.574 - CustomFuction [ERROR   ] 'EqpName'
Traceback (most recent call last):
  File "D:\Ina\ETL_XdmLib_2.A.13\ETL_XdmLib_2.A.13\EDAETL\ETL_TABLE\ETL_TXT_TO_XSIFF\../..\XdmLib\CustomFuction.py", line 596, in file2db_init
    res = do_file(file_root_source_path,
  File "D:\Ina\ETL_XdmLib_2.A.13\ETL_XdmLib_2.A.13\EDAETL\ETL_TABLE\ETL_TXT_TO_XSIFF\ETL_TXT_TO_XSIFF.py", line 233, in do_file
    raise ex
  File "D:\Ina\ETL_XdmLib_2.A.13\ETL_XdmLib_2.A.13\EDAETL\ETL_TABLE\ETL_TXT_TO_XSIFF\ETL_TXT_TO_XSIFF.py", line 222, in do_file
    'EqpName':header_dict['EqpName'],
KeyError: 'EqpName'
Stack (most recent call last):
  File "D:\Ina\ETL_XdmLib_2.A.13\ETL_XdmLib_2.A.13\EDAETL\ETL_TABLE\ETL_TXT_TO_XSIFF\ETL_TXT_TO_XSIFF.py", line 342, in <module>
    XdmLib.CustomFuction.file2db_init(
  File "D:\Ina\ETL_XdmLib_2.A.13\ETL_XdmLib_2.A.13\EDAETL\ETL_TABLE\ETL_TXT_TO_XSIFF\../..\XdmLib\CustomFuction.py", line 631, in file2db_init
    log.error(ex, exc_info=True, stack_info=True)
2023-09-14 16:49:12.898 - CustomFuction [ERROR   ] 'EqpName'
Traceback (most recent call last):
  File "D:\Ina\ETL_XdmLib_2.A.13\ETL_XdmLib_2.A.13\EDAETL\ETL_TABLE\ETL_TXT_TO_XSIFF\../..\XdmLib\CustomFuction.py", line 596, in file2db_init
    res = do_file(file_root_source_path,
  File "D:\Ina\ETL_XdmLib_2.A.13\ETL_XdmLib_2.A.13\EDAETL\ETL_TABLE\ETL_TXT_TO_XSIFF\ETL_TXT_TO_XSIFF.py", line 235, in do_file
    raise ex
  File "D:\Ina\ETL_XdmLib_2.A.13\ETL_XdmLib_2.A.13\EDAETL\ETL_TABLE\ETL_TXT_TO_XSIFF\ETL_TXT_TO_XSIFF.py", line 224, in do_file
    'EqpName':header_dict['EqpName'],
KeyError: 'EqpName'
Stack (most recent call last):
  File "D:\Ina\ETL_XdmLib_2.A.13\ETL_XdmLib_2.A.13\EDAETL\ETL_TABLE\ETL_TXT_TO_XSIFF\ETL_TXT_TO_XSIFF.py", line 344, in <module>
    XdmLib.CustomFuction.file2db_init(
  File "D:\Ina\ETL_XdmLib_2.A.13\ETL_XdmLib_2.A.13\EDAETL\ETL_TABLE\ETL_TXT_TO_XSIFF\../..\XdmLib\CustomFuction.py", line 631, in file2db_init
    log.error(ex, exc_info=True, stack_info=True)
2023-09-14 16:50:22.990 - CustomFuction [ERROR   ] Error tokenizing data. C error: Expected 12 fields in line 20, saw 15
Traceback (most recent call last):
  File "D:\Ina\ETL_XdmLib_2.A.13\ETL_XdmLib_2.A.13\EDAETL\ETL_TABLE\ETL_TXT_TO_XSIFF\../..\XdmLib\CustomFuction.py", line 596, in file2db_init
    res = do_file(file_root_source_path,
  File "D:\Ina\ETL_XdmLib_2.A.13\ETL_XdmLib_2.A.13\EDAETL\ETL_TABLE\ETL_TXT_TO_XSIFF\ETL_TXT_TO_XSIFF.py", line 199, in do_file
    raise ex
  File "D:\Ina\ETL_XdmLib_2.A.13\ETL_XdmLib_2.A.13\EDAETL\ETL_TABLE\ETL_TXT_TO_XSIFF\ETL_TXT_TO_XSIFF.py", line 140, in do_file
    data = pd.read_csv(file, delimiter='\s+', header=None, skiprows=range(17))
  File "D:\soft\anaconda3\lib\site-packages\pandas\util\_decorators.py", line 311, in wrapper
    return func(*args, **kwargs)
  File "D:\soft\anaconda3\lib\site-packages\pandas\io\parsers\readers.py", line 680, in read_csv
    return _read(filepath_or_buffer, kwds)
  File "D:\soft\anaconda3\lib\site-packages\pandas\io\parsers\readers.py", line 581, in _read
    return parser.read(nrows)
  File "D:\soft\anaconda3\lib\site-packages\pandas\io\parsers\readers.py", line 1254, in read
    index, columns, col_dict = self._engine.read(nrows)
  File "D:\soft\anaconda3\lib\site-packages\pandas\io\parsers\c_parser_wrapper.py", line 225, in read
    chunks = self._reader.read_low_memory(nrows)
  File "pandas\_libs\parsers.pyx", line 805, in pandas._libs.parsers.TextReader.read_low_memory
  File "pandas\_libs\parsers.pyx", line 861, in pandas._libs.parsers.TextReader._read_rows
  File "pandas\_libs\parsers.pyx", line 847, in pandas._libs.parsers.TextReader._tokenize_rows
  File "pandas\_libs\parsers.pyx", line 1960, in pandas._libs.parsers.raise_parser_error
pandas.errors.ParserError: Error tokenizing data. C error: Expected 12 fields in line 20, saw 15
Stack (most recent call last):
  File "D:\Ina\ETL_XdmLib_2.A.13\ETL_XdmLib_2.A.13\EDAETL\ETL_TABLE\ETL_TXT_TO_XSIFF\ETL_TXT_TO_XSIFF.py", line 344, in <module>
    XdmLib.CustomFuction.file2db_init(
  File "D:\Ina\ETL_XdmLib_2.A.13\ETL_XdmLib_2.A.13\EDAETL\ETL_TABLE\ETL_TXT_TO_XSIFF\../..\XdmLib\CustomFuction.py", line 631, in file2db_init
    log.error(ex, exc_info=True, stack_info=True)
2023-09-14 17:37:20.840 - CustomFuction [ERROR   ] name 'DataDF' is not defined
Traceback (most recent call last):
  File "D:\Ina\ETL_XdmLib_2.A.13\ETL_XdmLib_2.A.13\EDAETL\ETL_TABLE\ETL_TXT_TO_XSIFF\../..\XdmLib\CustomFuction.py", line 596, in file2db_init
    res = do_file(file_root_source_path,
  File "D:/Ina/ETL_XdmLib_2.A.13/ETL_XdmLib_2.A.13/EDAETL/ETL_TABLE/ETL_TXT_TO_XSIFF/ETL_TXT_TO_XSIFF.py", line 185, in do_file
    raise ex
  File "D:/Ina/ETL_XdmLib_2.A.13/ETL_XdmLib_2.A.13/EDAETL/ETL_TABLE/ETL_TXT_TO_XSIFF/ETL_TXT_TO_XSIFF.py", line 176, in do_file
    for index, row in DataDF.iterrows():
NameError: name 'DataDF' is not defined
Stack (most recent call last):
  File "D:\soft\PyCharm Community Edition 2022.1.3\plugins\python-ce\helpers\pydev\pydevd.py", line 2181, in <module>
    main()
  File "D:\soft\PyCharm Community Edition 2022.1.3\plugins\python-ce\helpers\pydev\pydevd.py", line 2172, in main
    globals = debugger.run(setup['file'], None, None, is_module)
  File "D:\soft\PyCharm Community Edition 2022.1.3\plugins\python-ce\helpers\pydev\pydevd.py", line 1484, in run
    return self._exec(is_module, entry_point_fn, module_name, file, globals, locals)
  File "D:\soft\PyCharm Community Edition 2022.1.3\plugins\python-ce\helpers\pydev\pydevd.py", line 1491, in _exec
    pydev_imports.execfile(file, globals, locals)  # execute the script
  File "D:\soft\PyCharm Community Edition 2022.1.3\plugins\python-ce\helpers\pydev\_pydev_imps\_pydev_execfile.py", line 18, in execfile
    exec(compile(contents+"\n", file, 'exec'), glob, loc)
  File "D:/Ina/ETL_XdmLib_2.A.13/ETL_XdmLib_2.A.13/EDAETL/ETL_TABLE/ETL_TXT_TO_XSIFF/ETL_TXT_TO_XSIFF.py", line 334, in <module>
    XdmLib.CustomFuction.file2db_init(
  File "D:\Ina\ETL_XdmLib_2.A.13\ETL_XdmLib_2.A.13\EDAETL\ETL_TABLE\ETL_TXT_TO_XSIFF\../..\XdmLib\CustomFuction.py", line 631, in file2db_init
    log.error(ex, exc_info=True, stack_info=True)
2023-09-14 17:39:53.543 - CustomFuction [ERROR   ] name 'spec_limits_list' is not defined
Traceback (most recent call last):
  File "D:\Ina\ETL_XdmLib_2.A.13\ETL_XdmLib_2.A.13\EDAETL\ETL_TABLE\ETL_TXT_TO_XSIFF\../..\XdmLib\CustomFuction.py", line 596, in file2db_init
    res = do_file(file_root_source_path,
  File "D:\Ina\ETL_XdmLib_2.A.13\ETL_XdmLib_2.A.13\EDAETL\ETL_TABLE\ETL_TXT_TO_XSIFF\ETL_TXT_TO_XSIFF.py", line 225, in do_file
    raise ex
  File "D:\Ina\ETL_XdmLib_2.A.13\ETL_XdmLib_2.A.13\EDAETL\ETL_TABLE\ETL_TXT_TO_XSIFF\ETL_TXT_TO_XSIFF.py", line 220, in do_file
    spec_limits_list.append(
NameError: name 'spec_limits_list' is not defined
Stack (most recent call last):
  File "D:\Ina\ETL_XdmLib_2.A.13\ETL_XdmLib_2.A.13\EDAETL\ETL_TABLE\ETL_TXT_TO_XSIFF\ETL_TXT_TO_XSIFF.py", line 334, in <module>
    XdmLib.CustomFuction.file2db_init(
  File "D:\Ina\ETL_XdmLib_2.A.13\ETL_XdmLib_2.A.13\EDAETL\ETL_TABLE\ETL_TXT_TO_XSIFF\../..\XdmLib\CustomFuction.py", line 631, in file2db_init
    log.error(ex, exc_info=True, stack_info=True)
