2024-01-02 14:58:04.436 - CustomFuction [ERROR   ] Move File Error
2024-01-02 14:58:04.438 - CustomFuction [ERROR   ] 'D:\\Ina\\ETL_XdmLib_2.A.13\\ETL_XdmLib_2.A.13\\EDAETL\\ETL_TABLE\\ETL_FT_SD_TO_XSIFF\\Data\\Source\\StarPower\\FT\\Module\\UNISIC\\Dynamic\\GW\\XWECIQ743-CW_新阳光GD600MLS100L6S-CW-D125486-左.xlsx' and 'D:\\Ina\\ETL_XdmLib_2.A.13\\ETL_XdmLib_2.A.13\\EDAETL\\ETL_TABLE\\ETL_FT_SD_TO_XSIFF\\Data\\Source\\StarPower\\FT\\Module\\UNISIC\\Dynamic\\GW\\XWECIQ743-CW_新阳光GD600MLS100L6S-CW-D125486-左.xlsx' are the same file
Traceback (most recent call last):
  File "D:\Python37\lib\shutil.py", line 557, in move
    os.rename(src, real_dst)
PermissionError: [WinError 32] 另一个程序正在使用此文件，进程无法访问。: 'D:\\Ina\\ETL_XdmLib_2.A.13\\ETL_XdmLib_2.A.13\\EDAETL\\ETL_TABLE\\ETL_FT_SD_TO_XSIFF\\Data\\Source\\StarPower\\FT\\Module\\UNISIC\\Dynamic\\GW\\XWECIQ743-CW_新阳光GD600MLS100L6S-CW-D125486-左.xlsx' -> 'D:\\Ina\\ETL_XdmLib_2.A.13\\ETL_XdmLib_2.A.13\\EDAETL\\ETL_TABLE\\ETL_FT_SD_TO_XSIFF\\Data\\Source\\StarPower\\FT\\Module\\UNISIC\\Dynamic\\GW\\XWECIQ743-CW_新阳光GD600MLS100L6S-CW-D125486-左.xlsx'

During handling of the above exception, another exception occurred:

Traceback (most recent call last):
  File "../..\XdmLib\CustomFuction.py", line 1036, in move_file
    os.path.join(target_path, fileName))
  File "D:\Python37\lib\shutil.py", line 571, in move
    copy_function(src, real_dst)
  File "D:\Python37\lib\shutil.py", line 257, in copy2
    copyfile(src, dst, follow_symlinks=follow_symlinks)
  File "D:\Python37\lib\shutil.py", line 104, in copyfile
    raise SameFileError("{!r} and {!r} are the same file".format(src, dst))
shutil.SameFileError: 'D:\\Ina\\ETL_XdmLib_2.A.13\\ETL_XdmLib_2.A.13\\EDAETL\\ETL_TABLE\\ETL_FT_SD_TO_XSIFF\\Data\\Source\\StarPower\\FT\\Module\\UNISIC\\Dynamic\\GW\\XWECIQ743-CW_新阳光GD600MLS100L6S-CW-D125486-左.xlsx' and 'D:\\Ina\\ETL_XdmLib_2.A.13\\ETL_XdmLib_2.A.13\\EDAETL\\ETL_TABLE\\ETL_FT_SD_TO_XSIFF\\Data\\Source\\StarPower\\FT\\Module\\UNISIC\\Dynamic\\GW\\XWECIQ743-CW_新阳光GD600MLS100L6S-CW-D125486-左.xlsx' are the same file
Stack (most recent call last):
  File "D:/Ina/ETL_XdmLib_2.A.13/ETL_XdmLib_2.A.13/EDAETL/ETL_TABLE/ETL_FT_SD_TO_XSIFF/ETL_FT_SD_TO_XSIFF_20231228.py", line 553, in <module>
    skip_file, None, log, config, config_sql)
  File "../..\XdmLib\CustomFuction.py", line 629, in file2db_init
    move_file_self(move_file_info)
  File "../..\XdmLib\CustomFuction.py", line 1044, in move_file
    log.error(ex, exc_info=True, stack_info=True)
2024-01-02 14:58:04.542 - ETL_FT_SD_TO_XSIFF_20231228 [ERROR   ] [Errno 13] Permission denied: 'D:\\Ina\\ETL_XdmLib_2.A.13\\ETL_XdmLib_2.A.13\\EDAETL\\ETL_TABLE\\ETL_FT_SD_TO_XSIFF\\Data\\Source\\StarPower\\FT\\Module\\UNISIC\\Dynamic\\GW\\~$XWECIQ743-CW_新阳光GD600MLS100L6S-CW-D125486-左.xlsx'
Traceback (most recent call last):
  File "D:/Ina/ETL_XdmLib_2.A.13/ETL_XdmLib_2.A.13/EDAETL/ETL_TABLE/ETL_FT_SD_TO_XSIFF/ETL_FT_SD_TO_XSIFF_20231228.py", line 120, in do_file
    excel_data = pd.read_excel(file_path, header=None)
  File "D:\Python37\lib\site-packages\pandas\util\_decorators.py", line 296, in wrapper
    return func(*args, **kwargs)
  File "D:\Python37\lib\site-packages\pandas\io\excel\_base.py", line 304, in read_excel
    io = ExcelFile(io, engine=engine)
  File "D:\Python37\lib\site-packages\pandas\io\excel\_base.py", line 867, in __init__
    self._reader = self._engines[engine](self._io)
  File "D:\Python37\lib\site-packages\pandas\io\excel\_xlrd.py", line 22, in __init__
    super().__init__(filepath_or_buffer)
  File "D:\Python37\lib\site-packages\pandas\io\excel\_base.py", line 353, in __init__
    self.book = self.load_workbook(filepath_or_buffer)
  File "D:\Python37\lib\site-packages\pandas\io\excel\_xlrd.py", line 37, in load_workbook
    return open_workbook(filepath_or_buffer)
  File "D:\Python37\lib\site-packages\xlrd\__init__.py", line 111, in open_workbook
    with open(filename, "rb") as f:
PermissionError: [Errno 13] Permission denied: 'D:\\Ina\\ETL_XdmLib_2.A.13\\ETL_XdmLib_2.A.13\\EDAETL\\ETL_TABLE\\ETL_FT_SD_TO_XSIFF\\Data\\Source\\StarPower\\FT\\Module\\UNISIC\\Dynamic\\GW\\~$XWECIQ743-CW_新阳光GD600MLS100L6S-CW-D125486-左.xlsx'
Stack (most recent call last):
  File "D:/Ina/ETL_XdmLib_2.A.13/ETL_XdmLib_2.A.13/EDAETL/ETL_TABLE/ETL_FT_SD_TO_XSIFF/ETL_FT_SD_TO_XSIFF_20231228.py", line 553, in <module>
    skip_file, None, log, config, config_sql)
  File "../..\XdmLib\CustomFuction.py", line 597, in file2db_init
    file, pre_params, db_src, db_tgt)
  File "D:/Ina/ETL_XdmLib_2.A.13/ETL_XdmLib_2.A.13/EDAETL/ETL_TABLE/ETL_FT_SD_TO_XSIFF/ETL_FT_SD_TO_XSIFF_20231228.py", line 367, in do_file
    log.error(ex, exc_info=True, stack_info=True)
2024-01-02 14:58:04.708 - __init__   [ERROR   ] File:~$XWECIQ743-CW_新阳光GD600MLS100L6S-CW-D125486-左.xlsx Move To Error Folder
                                                Error: None
2024-01-02 14:58:04.718 - CustomFuction [ERROR   ] Move File Error
2024-01-02 14:58:04.718 - CustomFuction [ERROR   ] 'D:\\Ina\\ETL_XdmLib_2.A.13\\ETL_XdmLib_2.A.13\\EDAETL\\ETL_TABLE\\ETL_FT_SD_TO_XSIFF\\Data\\Source\\StarPower\\FT\\Module\\UNISIC\\Dynamic\\GW\\~$XWECIQ743-CW_新阳光GD600MLS100L6S-CW-D125486-左.xlsx' and 'D:\\Ina\\ETL_XdmLib_2.A.13\\ETL_XdmLib_2.A.13\\EDAETL\\ETL_TABLE\\ETL_FT_SD_TO_XSIFF\\Data\\Source\\StarPower\\FT\\Module\\UNISIC\\Dynamic\\GW\\~$XWECIQ743-CW_新阳光GD600MLS100L6S-CW-D125486-左.xlsx' are the same file
Traceback (most recent call last):
  File "D:\Python37\lib\shutil.py", line 557, in move
    os.rename(src, real_dst)
PermissionError: [WinError 32] 另一个程序正在使用此文件，进程无法访问。: 'D:\\Ina\\ETL_XdmLib_2.A.13\\ETL_XdmLib_2.A.13\\EDAETL\\ETL_TABLE\\ETL_FT_SD_TO_XSIFF\\Data\\Source\\StarPower\\FT\\Module\\UNISIC\\Dynamic\\GW\\~$XWECIQ743-CW_新阳光GD600MLS100L6S-CW-D125486-左.xlsx' -> 'D:\\Ina\\ETL_XdmLib_2.A.13\\ETL_XdmLib_2.A.13\\EDAETL\\ETL_TABLE\\ETL_FT_SD_TO_XSIFF\\Data\\Source\\StarPower\\FT\\Module\\UNISIC\\Dynamic\\GW\\~$XWECIQ743-CW_新阳光GD600MLS100L6S-CW-D125486-左.xlsx'

During handling of the above exception, another exception occurred:

Traceback (most recent call last):
  File "../..\XdmLib\CustomFuction.py", line 1036, in move_file
    os.path.join(target_path, fileName))
  File "D:\Python37\lib\shutil.py", line 571, in move
    copy_function(src, real_dst)
  File "D:\Python37\lib\shutil.py", line 257, in copy2
    copyfile(src, dst, follow_symlinks=follow_symlinks)
  File "D:\Python37\lib\shutil.py", line 104, in copyfile
    raise SameFileError("{!r} and {!r} are the same file".format(src, dst))
shutil.SameFileError: 'D:\\Ina\\ETL_XdmLib_2.A.13\\ETL_XdmLib_2.A.13\\EDAETL\\ETL_TABLE\\ETL_FT_SD_TO_XSIFF\\Data\\Source\\StarPower\\FT\\Module\\UNISIC\\Dynamic\\GW\\~$XWECIQ743-CW_新阳光GD600MLS100L6S-CW-D125486-左.xlsx' and 'D:\\Ina\\ETL_XdmLib_2.A.13\\ETL_XdmLib_2.A.13\\EDAETL\\ETL_TABLE\\ETL_FT_SD_TO_XSIFF\\Data\\Source\\StarPower\\FT\\Module\\UNISIC\\Dynamic\\GW\\~$XWECIQ743-CW_新阳光GD600MLS100L6S-CW-D125486-左.xlsx' are the same file
Stack (most recent call last):
  File "D:/Ina/ETL_XdmLib_2.A.13/ETL_XdmLib_2.A.13/EDAETL/ETL_TABLE/ETL_FT_SD_TO_XSIFF/ETL_FT_SD_TO_XSIFF_20231228.py", line 553, in <module>
    skip_file, None, log, config, config_sql)
  File "../..\XdmLib\CustomFuction.py", line 629, in file2db_init
    move_file_self(move_file_info)
  File "../..\XdmLib\CustomFuction.py", line 1044, in move_file
    log.error(ex, exc_info=True, stack_info=True)
2024-01-02 14:58:46.439 - CustomFuction [ERROR   ] Move File Error
2024-01-02 14:58:46.445 - CustomFuction [ERROR   ] 'D:\\Ina\\ETL_XdmLib_2.A.13\\ETL_XdmLib_2.A.13\\EDAETL\\ETL_TABLE\\ETL_FT_SD_TO_XSIFF\\Data\\Source\\StarPower\\FT\\Module\\UNISIC\\Dynamic\\GW\\XWECIQ743-CW_新阳光GD600MLS100L6S-CW-D125486-左.xlsx' and 'D:\\Ina\\ETL_XdmLib_2.A.13\\ETL_XdmLib_2.A.13\\EDAETL\\ETL_TABLE\\ETL_FT_SD_TO_XSIFF\\Data\\Source\\StarPower\\FT\\Module\\UNISIC\\Dynamic\\GW\\XWECIQ743-CW_新阳光GD600MLS100L6S-CW-D125486-左.xlsx' are the same file
Traceback (most recent call last):
  File "D:\Python37\lib\shutil.py", line 557, in move
    os.rename(src, real_dst)
PermissionError: [WinError 32] 另一个程序正在使用此文件，进程无法访问。: 'D:\\Ina\\ETL_XdmLib_2.A.13\\ETL_XdmLib_2.A.13\\EDAETL\\ETL_TABLE\\ETL_FT_SD_TO_XSIFF\\Data\\Source\\StarPower\\FT\\Module\\UNISIC\\Dynamic\\GW\\XWECIQ743-CW_新阳光GD600MLS100L6S-CW-D125486-左.xlsx' -> 'D:\\Ina\\ETL_XdmLib_2.A.13\\ETL_XdmLib_2.A.13\\EDAETL\\ETL_TABLE\\ETL_FT_SD_TO_XSIFF\\Data\\Source\\StarPower\\FT\\Module\\UNISIC\\Dynamic\\GW\\XWECIQ743-CW_新阳光GD600MLS100L6S-CW-D125486-左.xlsx'

During handling of the above exception, another exception occurred:

Traceback (most recent call last):
  File "../..\XdmLib\CustomFuction.py", line 1036, in move_file
    os.path.join(target_path, fileName))
  File "D:\Python37\lib\shutil.py", line 571, in move
    copy_function(src, real_dst)
  File "D:\Python37\lib\shutil.py", line 257, in copy2
    copyfile(src, dst, follow_symlinks=follow_symlinks)
  File "D:\Python37\lib\shutil.py", line 104, in copyfile
    raise SameFileError("{!r} and {!r} are the same file".format(src, dst))
shutil.SameFileError: 'D:\\Ina\\ETL_XdmLib_2.A.13\\ETL_XdmLib_2.A.13\\EDAETL\\ETL_TABLE\\ETL_FT_SD_TO_XSIFF\\Data\\Source\\StarPower\\FT\\Module\\UNISIC\\Dynamic\\GW\\XWECIQ743-CW_新阳光GD600MLS100L6S-CW-D125486-左.xlsx' and 'D:\\Ina\\ETL_XdmLib_2.A.13\\ETL_XdmLib_2.A.13\\EDAETL\\ETL_TABLE\\ETL_FT_SD_TO_XSIFF\\Data\\Source\\StarPower\\FT\\Module\\UNISIC\\Dynamic\\GW\\XWECIQ743-CW_新阳光GD600MLS100L6S-CW-D125486-左.xlsx' are the same file
Stack (most recent call last):
  File "D:/Ina/ETL_XdmLib_2.A.13/ETL_XdmLib_2.A.13/EDAETL/ETL_TABLE/ETL_FT_SD_TO_XSIFF/ETL_FT_SD_TO_XSIFF_20231228.py", line 553, in <module>
    skip_file, None, log, config, config_sql)
  File "../..\XdmLib\CustomFuction.py", line 629, in file2db_init
    move_file_self(move_file_info)
  File "../..\XdmLib\CustomFuction.py", line 1044, in move_file
    log.error(ex, exc_info=True, stack_info=True)
2024-01-02 14:58:46.517 - ETL_FT_SD_TO_XSIFF_20231228 [ERROR   ] [Errno 13] Permission denied: 'D:\\Ina\\ETL_XdmLib_2.A.13\\ETL_XdmLib_2.A.13\\EDAETL\\ETL_TABLE\\ETL_FT_SD_TO_XSIFF\\Data\\Source\\StarPower\\FT\\Module\\UNISIC\\Dynamic\\GW\\~$XWECIQ743-CW_新阳光GD600MLS100L6S-CW-D125486-左.xlsx'
Traceback (most recent call last):
  File "D:/Ina/ETL_XdmLib_2.A.13/ETL_XdmLib_2.A.13/EDAETL/ETL_TABLE/ETL_FT_SD_TO_XSIFF/ETL_FT_SD_TO_XSIFF_20231228.py", line 120, in do_file
    excel_data = pd.read_excel(file_path, header=None)
  File "D:\Python37\lib\site-packages\pandas\util\_decorators.py", line 296, in wrapper
    return func(*args, **kwargs)
  File "D:\Python37\lib\site-packages\pandas\io\excel\_base.py", line 304, in read_excel
    io = ExcelFile(io, engine=engine)
  File "D:\Python37\lib\site-packages\pandas\io\excel\_base.py", line 867, in __init__
    self._reader = self._engines[engine](self._io)
  File "D:\Python37\lib\site-packages\pandas\io\excel\_xlrd.py", line 22, in __init__
    super().__init__(filepath_or_buffer)
  File "D:\Python37\lib\site-packages\pandas\io\excel\_base.py", line 353, in __init__
    self.book = self.load_workbook(filepath_or_buffer)
  File "D:\Python37\lib\site-packages\pandas\io\excel\_xlrd.py", line 37, in load_workbook
    return open_workbook(filepath_or_buffer)
  File "D:\Python37\lib\site-packages\xlrd\__init__.py", line 111, in open_workbook
    with open(filename, "rb") as f:
PermissionError: [Errno 13] Permission denied: 'D:\\Ina\\ETL_XdmLib_2.A.13\\ETL_XdmLib_2.A.13\\EDAETL\\ETL_TABLE\\ETL_FT_SD_TO_XSIFF\\Data\\Source\\StarPower\\FT\\Module\\UNISIC\\Dynamic\\GW\\~$XWECIQ743-CW_新阳光GD600MLS100L6S-CW-D125486-左.xlsx'
Stack (most recent call last):
  File "D:/Ina/ETL_XdmLib_2.A.13/ETL_XdmLib_2.A.13/EDAETL/ETL_TABLE/ETL_FT_SD_TO_XSIFF/ETL_FT_SD_TO_XSIFF_20231228.py", line 553, in <module>
    skip_file, None, log, config, config_sql)
  File "../..\XdmLib\CustomFuction.py", line 597, in file2db_init
    file, pre_params, db_src, db_tgt)
  File "D:/Ina/ETL_XdmLib_2.A.13/ETL_XdmLib_2.A.13/EDAETL/ETL_TABLE/ETL_FT_SD_TO_XSIFF/ETL_FT_SD_TO_XSIFF_20231228.py", line 367, in do_file
    log.error(ex, exc_info=True, stack_info=True)
2024-01-02 14:58:46.672 - __init__   [ERROR   ] File:~$XWECIQ743-CW_新阳光GD600MLS100L6S-CW-D125486-左.xlsx Move To Error Folder
                                                Error: None
2024-01-02 14:58:46.681 - CustomFuction [ERROR   ] Move File Error
2024-01-02 14:58:46.682 - CustomFuction [ERROR   ] 'D:\\Ina\\ETL_XdmLib_2.A.13\\ETL_XdmLib_2.A.13\\EDAETL\\ETL_TABLE\\ETL_FT_SD_TO_XSIFF\\Data\\Source\\StarPower\\FT\\Module\\UNISIC\\Dynamic\\GW\\~$XWECIQ743-CW_新阳光GD600MLS100L6S-CW-D125486-左.xlsx' and 'D:\\Ina\\ETL_XdmLib_2.A.13\\ETL_XdmLib_2.A.13\\EDAETL\\ETL_TABLE\\ETL_FT_SD_TO_XSIFF\\Data\\Source\\StarPower\\FT\\Module\\UNISIC\\Dynamic\\GW\\~$XWECIQ743-CW_新阳光GD600MLS100L6S-CW-D125486-左.xlsx' are the same file
Traceback (most recent call last):
  File "D:\Python37\lib\shutil.py", line 557, in move
    os.rename(src, real_dst)
PermissionError: [WinError 32] 另一个程序正在使用此文件，进程无法访问。: 'D:\\Ina\\ETL_XdmLib_2.A.13\\ETL_XdmLib_2.A.13\\EDAETL\\ETL_TABLE\\ETL_FT_SD_TO_XSIFF\\Data\\Source\\StarPower\\FT\\Module\\UNISIC\\Dynamic\\GW\\~$XWECIQ743-CW_新阳光GD600MLS100L6S-CW-D125486-左.xlsx' -> 'D:\\Ina\\ETL_XdmLib_2.A.13\\ETL_XdmLib_2.A.13\\EDAETL\\ETL_TABLE\\ETL_FT_SD_TO_XSIFF\\Data\\Source\\StarPower\\FT\\Module\\UNISIC\\Dynamic\\GW\\~$XWECIQ743-CW_新阳光GD600MLS100L6S-CW-D125486-左.xlsx'

During handling of the above exception, another exception occurred:

Traceback (most recent call last):
  File "../..\XdmLib\CustomFuction.py", line 1036, in move_file
    os.path.join(target_path, fileName))
  File "D:\Python37\lib\shutil.py", line 571, in move
    copy_function(src, real_dst)
  File "D:\Python37\lib\shutil.py", line 257, in copy2
    copyfile(src, dst, follow_symlinks=follow_symlinks)
  File "D:\Python37\lib\shutil.py", line 104, in copyfile
    raise SameFileError("{!r} and {!r} are the same file".format(src, dst))
shutil.SameFileError: 'D:\\Ina\\ETL_XdmLib_2.A.13\\ETL_XdmLib_2.A.13\\EDAETL\\ETL_TABLE\\ETL_FT_SD_TO_XSIFF\\Data\\Source\\StarPower\\FT\\Module\\UNISIC\\Dynamic\\GW\\~$XWECIQ743-CW_新阳光GD600MLS100L6S-CW-D125486-左.xlsx' and 'D:\\Ina\\ETL_XdmLib_2.A.13\\ETL_XdmLib_2.A.13\\EDAETL\\ETL_TABLE\\ETL_FT_SD_TO_XSIFF\\Data\\Source\\StarPower\\FT\\Module\\UNISIC\\Dynamic\\GW\\~$XWECIQ743-CW_新阳光GD600MLS100L6S-CW-D125486-左.xlsx' are the same file
Stack (most recent call last):
  File "D:/Ina/ETL_XdmLib_2.A.13/ETL_XdmLib_2.A.13/EDAETL/ETL_TABLE/ETL_FT_SD_TO_XSIFF/ETL_FT_SD_TO_XSIFF_20231228.py", line 553, in <module>
    skip_file, None, log, config, config_sql)
  File "../..\XdmLib\CustomFuction.py", line 629, in file2db_init
    move_file_self(move_file_info)
  File "../..\XdmLib\CustomFuction.py", line 1044, in move_file
    log.error(ex, exc_info=True, stack_info=True)
