2023-10-26 13:55:58.641 - ETL_FT_SD_TO_XSIFF [ERROR   ] Not the correct documentation:  [Serial no.] This column is numeric only.
2023-10-26 13:56:01.617 - __init__   [ERROR   ] File:QG35-CW_GD400TAS100L6S.xlsx Move To Error Folder
                                                Error: None
2023-10-26 13:56:01.926 - ETL_FT_SD_TO_XSIFF [ERROR   ] 参数值检查发生异常: cannot insert ParameterDesc, already exists
2023-10-26 13:56:04.879 - __init__   [ERROR   ] File:TLECGQG81-CW_阳光GD200FYS100L6S.xlsx Move To Error Folder
                                                Error: None
2023-10-26 13:56:05.592 - ETL_FT_SD_TO_XSIFF [ERROR   ] 参数值检查发生异常: cannot insert ParameterDesc, already exists
2023-10-26 13:56:08.580 - __init__   [ERROR   ] File:XWECYQH20-CW_GD600MLS100L6S.xlsx Move To Error Folder
                                                Error: None
2023-10-26 13:56:09.270 - ETL_FT_SD_TO_XSIFF [ERROR   ] 参数值检查发生异常: cannot insert ParameterDesc, already exists
2023-10-26 13:56:12.234 - __init__   [ERROR   ] File:XWECYQH62-GW_GD600MLS100L6S-GW.xlsx Move To Error Folder
                                                Error: None
2023-10-26 14:02:42.654 - ETL_FT_SD_TO_XSIFF [ERROR   ] Not the correct documentation:  [Serial no.] This column is numeric only.
2023-10-26 14:02:45.650 - __init__   [ERROR   ] File:QG35-CW_GD400TAS100L6S.xlsx Move To Error Folder
                                                Error: None
2023-10-26 14:02:45.953 - ETL_FT_SD_TO_XSIFF [ERROR   ] Parameter in row_data_df and spec_df are not equal
2023-10-26 14:02:48.942 - __init__   [ERROR   ] File:TLECGQG81-CW_阳光GD200FYS100L6S.xlsx Move To Error Folder
                                                Error: None
2023-10-26 14:02:49.770 - ETL_FT_SD_TO_XSIFF [ERROR   ] Parameter in row_data_df and spec_df are not equal
2023-10-26 14:02:52.783 - __init__   [ERROR   ] File:XWECYQH20-CW_GD600MLS100L6S.xlsx Move To Error Folder
                                                Error: None
2023-10-26 14:02:53.510 - ETL_FT_SD_TO_XSIFF [ERROR   ] 参数值不符合要求，包含非数值型或非空值的值: ∞
2023-10-26 14:02:56.509 - __init__   [ERROR   ] File:XWECYQH62-GW_GD600MLS100L6S-GW.xlsx Move To Error Folder
                                                Error: None
2023-10-26 14:04:53.550 - ETL_FT_SD_TO_XSIFF [ERROR   ] Not the correct documentation:  [Serial no.] This column is numeric only.
2023-10-26 14:04:56.546 - __init__   [ERROR   ] File:QG35-CW_GD400TAS100L6S.xlsx Move To Error Folder
                                                Error: None
2023-10-26 14:04:56.871 - ETL_FT_SD_TO_XSIFF [ERROR   ] Parameter in row_data_df and spec_df are not equal
2023-10-26 14:04:59.820 - __init__   [ERROR   ] File:TLECGQG81-CW_阳光GD200FYS100L6S.xlsx Move To Error Folder
                                                Error: None
2023-10-26 14:05:00.633 - ETL_FT_SD_TO_XSIFF [ERROR   ] Parameter in row_data_df and spec_df are not equal
2023-10-26 14:05:03.612 - __init__   [ERROR   ] File:XWECYQH20-CW_GD600MLS100L6S.xlsx Move To Error Folder
                                                Error: None
2023-10-26 14:05:04.295 - ETL_FT_SD_TO_XSIFF [ERROR   ] The parameter value does not meet the requirements and contains a value that is not numeric or non-null: ∞
2023-10-26 14:05:07.285 - __init__   [ERROR   ] File:XWECYQH62-GW_GD600MLS100L6S-GW.xlsx Move To Error Folder
                                                Error: None
2023-10-26 14:06:31.762 - ETL_FT_SD_TO_XSIFF [ERROR   ] Not the correct documentation:  [Serial no.] This column is numeric only.
2023-10-26 14:06:34.734 - __init__   [ERROR   ] File:QG35-CW_GD400TAS100L6S.xlsx Move To Error Folder
                                                Error: None
2023-10-26 14:06:36.400 - ETL_FT_SD_TO_XSIFF [ERROR   ] The parameter value does not meet the requirements and contains a value that is not numeric or non-null: ∞
2023-10-26 14:06:39.296 - __init__   [ERROR   ] File:XWECYQH62-GW_GD600MLS100L6S-GW.xlsx Move To Error Folder
                                                Error: None
2023-10-26 14:09:21.668 - ETL_FT_SD_TO_XSIFF [ERROR   ] Not the correct documentation:  [Serial no.] This column is numeric only.
2023-10-26 14:09:24.635 - __init__   [ERROR   ] File:QG35-CW_GD400TAS100L6S.xlsx Move To Error Folder
                                                Error: None
2023-10-26 14:09:26.276 - ETL_FT_SD_TO_XSIFF [ERROR   ] The parameter value does not meet the requirements and contains a value that is not numeric or non-null: ∞
2023-10-26 14:09:29.275 - __init__   [ERROR   ] File:XWECYQH62-GW_GD600MLS100L6S-GW.xlsx Move To Error Folder
                                                Error: None
2023-10-26 14:11:42.827 - ETL_FT_SD_TO_XSIFF [ERROR   ] Not the correct documentation:  [Serial no.] This column is numeric only.
2023-10-26 14:11:45.826 - __init__   [ERROR   ] File:QG35-CW_GD400TAS100L6S.xlsx Move To Error Folder
                                                Error: None
2023-10-26 14:11:47.499 - ETL_FT_SD_TO_XSIFF [ERROR   ] The parameter value does not meet the requirements and contains a value that is not numeric or non-null: ∞
2023-10-26 14:11:50.490 - __init__   [ERROR   ] File:XWECYQH62-GW_GD600MLS100L6S-GW.xlsx Move To Error Folder
                                                Error: None
2023-10-26 14:16:46.932 - ETL_FT_SD_TO_XSIFF [ERROR   ] 'Test Date.'
Traceback (most recent call last):
  File "D:\soft\anaconda3\lib\site-packages\pandas\core\indexes\base.py", line 3621, in get_loc
    return self._engine.get_loc(casted_key)
  File "pandas\_libs\index.pyx", line 136, in pandas._libs.index.IndexEngine.get_loc
  File "pandas\_libs\index.pyx", line 144, in pandas._libs.index.IndexEngine.get_loc
  File "pandas\_libs\index_class_helper.pxi", line 41, in pandas._libs.index.Int64Engine._check_type
KeyError: 'Test Date.'

The above exception was the direct cause of the following exception:

Traceback (most recent call last):
  File "D:\Ina\ETL_XdmLib_2.A.13\ETL_XdmLib_2.A.13\EDAETL\ETL_TABLE\ETL_FT_SD_TO_XSIFF\ETL_FT_SD_TO_XSIFF.py", line 242, in do_file
    filtered_df.loc[:, 'Test Date.'] = filtered_df['Test Date.'].str.replace('上午', 'AM')
  File "D:\soft\anaconda3\lib\site-packages\pandas\core\series.py", line 958, in __getitem__
    return self._get_value(key)
  File "D:\soft\anaconda3\lib\site-packages\pandas\core\series.py", line 1069, in _get_value
    loc = self.index.get_loc(label)
  File "D:\soft\anaconda3\lib\site-packages\pandas\core\indexes\base.py", line 3623, in get_loc
    raise KeyError(key) from err
KeyError: 'Test Date.'
Stack (most recent call last):
  File "D:\Ina\ETL_XdmLib_2.A.13\ETL_XdmLib_2.A.13\EDAETL\ETL_TABLE\ETL_FT_SD_TO_XSIFF\ETL_FT_SD_TO_XSIFF.py", line 588, in <module>
    XdmLib.CustomFuction.file2db_init(do_file, before_do_file, after_do_file,
  File "D:\Ina\ETL_XdmLib_2.A.13\ETL_XdmLib_2.A.13\EDAETL\ETL_TABLE\ETL_FT_SD_TO_XSIFF\../..\XdmLib\CustomFuction.py", line 596, in file2db_init
    res = do_file(file_root_source_path,
  File "D:\Ina\ETL_XdmLib_2.A.13\ETL_XdmLib_2.A.13\EDAETL\ETL_TABLE\ETL_FT_SD_TO_XSIFF\ETL_FT_SD_TO_XSIFF.py", line 408, in do_file
    log.error(ex, exc_info=True, stack_info=True)
2023-10-26 14:16:49.917 - __init__   [ERROR   ] File:TLECGQG81-CW_阳光GD200FYS100L6S.xlsx Move To Error Folder
                                                Error: None
2023-10-26 14:16:50.584 - ETL_FT_SD_TO_XSIFF [ERROR   ] 'Test Date.'
Traceback (most recent call last):
  File "D:\soft\anaconda3\lib\site-packages\pandas\core\indexes\base.py", line 3621, in get_loc
    return self._engine.get_loc(casted_key)
  File "pandas\_libs\index.pyx", line 136, in pandas._libs.index.IndexEngine.get_loc
  File "pandas\_libs\index.pyx", line 144, in pandas._libs.index.IndexEngine.get_loc
  File "pandas\_libs\index_class_helper.pxi", line 41, in pandas._libs.index.Int64Engine._check_type
KeyError: 'Test Date.'

The above exception was the direct cause of the following exception:

Traceback (most recent call last):
  File "D:\Ina\ETL_XdmLib_2.A.13\ETL_XdmLib_2.A.13\EDAETL\ETL_TABLE\ETL_FT_SD_TO_XSIFF\ETL_FT_SD_TO_XSIFF.py", line 242, in do_file
    filtered_df.loc[:, 'Test Date.'] = filtered_df['Test Date.'].str.replace('上午', 'AM')
  File "D:\soft\anaconda3\lib\site-packages\pandas\core\series.py", line 958, in __getitem__
    return self._get_value(key)
  File "D:\soft\anaconda3\lib\site-packages\pandas\core\series.py", line 1069, in _get_value
    loc = self.index.get_loc(label)
  File "D:\soft\anaconda3\lib\site-packages\pandas\core\indexes\base.py", line 3623, in get_loc
    raise KeyError(key) from err
KeyError: 'Test Date.'
Stack (most recent call last):
  File "D:\Ina\ETL_XdmLib_2.A.13\ETL_XdmLib_2.A.13\EDAETL\ETL_TABLE\ETL_FT_SD_TO_XSIFF\ETL_FT_SD_TO_XSIFF.py", line 588, in <module>
    XdmLib.CustomFuction.file2db_init(do_file, before_do_file, after_do_file,
  File "D:\Ina\ETL_XdmLib_2.A.13\ETL_XdmLib_2.A.13\EDAETL\ETL_TABLE\ETL_FT_SD_TO_XSIFF\../..\XdmLib\CustomFuction.py", line 596, in file2db_init
    res = do_file(file_root_source_path,
  File "D:\Ina\ETL_XdmLib_2.A.13\ETL_XdmLib_2.A.13\EDAETL\ETL_TABLE\ETL_FT_SD_TO_XSIFF\ETL_FT_SD_TO_XSIFF.py", line 408, in do_file
    log.error(ex, exc_info=True, stack_info=True)
2023-10-26 14:16:53.575 - __init__   [ERROR   ] File:XWECYQH20-CW_GD600MLS100L6S.xlsx Move To Error Folder
                                                Error: None
2023-10-26 14:27:01.072 - ETL_FT_SD_TO_XSIFF [ERROR   ] Not the correct documentation:  [Serial no.] This column is numeric only.
2023-10-26 14:27:04.050 - __init__   [ERROR   ] File:QG35-CW_GD400TAS100L6S.xlsx Move To Error Folder
                                                Error: None
2023-10-26 14:27:04.372 - ETL_FT_SD_TO_XSIFF [ERROR   ] time data '07/20/2023 1:54:16 PM' does not match format '%Y%m%d%H%M%S' (match)
Traceback (most recent call last):
  File "D:\soft\anaconda3\lib\site-packages\pandas\core\tools\datetimes.py", line 510, in _to_datetime_with_format
    values, tz = conversion.datetime_to_datetime64(arg)
  File "pandas\_libs\tslibs\conversion.pyx", line 360, in pandas._libs.tslibs.conversion.datetime_to_datetime64
TypeError: Unrecognized value type: <class 'str'>

During handling of the above exception, another exception occurred:

Traceback (most recent call last):
  File "D:\Ina\ETL_XdmLib_2.A.13\ETL_XdmLib_2.A.13\EDAETL\ETL_TABLE\ETL_FT_SD_TO_XSIFF\ETL_FT_SD_TO_XSIFF.py", line 251, in do_file
    filtered_df['Test Date.'] = pd.to_datetime(filtered_df['Test Date.'], format='%Y%m%d%H%M%S')
  File "D:\soft\anaconda3\lib\site-packages\pandas\core\tools\datetimes.py", line 1051, in to_datetime
    values = convert_listlike(arg._values, format)
  File "D:\soft\anaconda3\lib\site-packages\pandas\core\tools\datetimes.py", line 394, in _convert_listlike_datetimes
    res = _to_datetime_with_format(
  File "D:\soft\anaconda3\lib\site-packages\pandas\core\tools\datetimes.py", line 514, in _to_datetime_with_format
    raise err
  File "D:\soft\anaconda3\lib\site-packages\pandas\core\tools\datetimes.py", line 501, in _to_datetime_with_format
    res = _array_strptime_with_fallback(
  File "D:\soft\anaconda3\lib\site-packages\pandas\core\tools\datetimes.py", line 437, in _array_strptime_with_fallback
    result, timezones = array_strptime(arg, fmt, exact=exact, errors=errors)
  File "pandas\_libs\tslibs\strptime.pyx", line 150, in pandas._libs.tslibs.strptime.array_strptime
ValueError: time data '07/20/2023 1:54:16 PM' does not match format '%Y%m%d%H%M%S' (match)
Stack (most recent call last):
  File "D:\Ina\ETL_XdmLib_2.A.13\ETL_XdmLib_2.A.13\EDAETL\ETL_TABLE\ETL_FT_SD_TO_XSIFF\ETL_FT_SD_TO_XSIFF.py", line 597, in <module>
    XdmLib.CustomFuction.file2db_init(do_file, before_do_file, after_do_file,
  File "D:\Ina\ETL_XdmLib_2.A.13\ETL_XdmLib_2.A.13\EDAETL\ETL_TABLE\ETL_FT_SD_TO_XSIFF\../..\XdmLib\CustomFuction.py", line 596, in file2db_init
    res = do_file(file_root_source_path,
  File "D:\Ina\ETL_XdmLib_2.A.13\ETL_XdmLib_2.A.13\EDAETL\ETL_TABLE\ETL_FT_SD_TO_XSIFF\ETL_FT_SD_TO_XSIFF.py", line 417, in do_file
    log.error(ex, exc_info=True, stack_info=True)
2023-10-26 14:27:07.360 - __init__   [ERROR   ] File:TLECGQG81-CW_阳光GD200FYS100L6S.xlsx Move To Error Folder
                                                Error: None
2023-10-26 14:27:08.091 - ETL_FT_SD_TO_XSIFF [ERROR   ] time data '07/07/2023 5:50:41 AM' does not match format '%Y%m%d%H%M%S' (match)
Traceback (most recent call last):
  File "D:\soft\anaconda3\lib\site-packages\pandas\core\tools\datetimes.py", line 510, in _to_datetime_with_format
    values, tz = conversion.datetime_to_datetime64(arg)
  File "pandas\_libs\tslibs\conversion.pyx", line 360, in pandas._libs.tslibs.conversion.datetime_to_datetime64
TypeError: Unrecognized value type: <class 'str'>

During handling of the above exception, another exception occurred:

Traceback (most recent call last):
  File "D:\Ina\ETL_XdmLib_2.A.13\ETL_XdmLib_2.A.13\EDAETL\ETL_TABLE\ETL_FT_SD_TO_XSIFF\ETL_FT_SD_TO_XSIFF.py", line 251, in do_file
    filtered_df['Test Date.'] = pd.to_datetime(filtered_df['Test Date.'], format='%Y%m%d%H%M%S')
  File "D:\soft\anaconda3\lib\site-packages\pandas\core\tools\datetimes.py", line 1051, in to_datetime
    values = convert_listlike(arg._values, format)
  File "D:\soft\anaconda3\lib\site-packages\pandas\core\tools\datetimes.py", line 394, in _convert_listlike_datetimes
    res = _to_datetime_with_format(
  File "D:\soft\anaconda3\lib\site-packages\pandas\core\tools\datetimes.py", line 514, in _to_datetime_with_format
    raise err
  File "D:\soft\anaconda3\lib\site-packages\pandas\core\tools\datetimes.py", line 501, in _to_datetime_with_format
    res = _array_strptime_with_fallback(
  File "D:\soft\anaconda3\lib\site-packages\pandas\core\tools\datetimes.py", line 437, in _array_strptime_with_fallback
    result, timezones = array_strptime(arg, fmt, exact=exact, errors=errors)
  File "pandas\_libs\tslibs\strptime.pyx", line 150, in pandas._libs.tslibs.strptime.array_strptime
ValueError: time data '07/07/2023 5:50:41 AM' does not match format '%Y%m%d%H%M%S' (match)
Stack (most recent call last):
  File "D:\Ina\ETL_XdmLib_2.A.13\ETL_XdmLib_2.A.13\EDAETL\ETL_TABLE\ETL_FT_SD_TO_XSIFF\ETL_FT_SD_TO_XSIFF.py", line 597, in <module>
    XdmLib.CustomFuction.file2db_init(do_file, before_do_file, after_do_file,
  File "D:\Ina\ETL_XdmLib_2.A.13\ETL_XdmLib_2.A.13\EDAETL\ETL_TABLE\ETL_FT_SD_TO_XSIFF\../..\XdmLib\CustomFuction.py", line 596, in file2db_init
    res = do_file(file_root_source_path,
  File "D:\Ina\ETL_XdmLib_2.A.13\ETL_XdmLib_2.A.13\EDAETL\ETL_TABLE\ETL_FT_SD_TO_XSIFF\ETL_FT_SD_TO_XSIFF.py", line 417, in do_file
    log.error(ex, exc_info=True, stack_info=True)
2023-10-26 14:27:10.990 - __init__   [ERROR   ] File:XWECYQH20-CW_GD600MLS100L6S.xlsx Move To Error Folder
                                                Error: None
2023-10-26 14:27:11.702 - ETL_FT_SD_TO_XSIFF [ERROR   ] time data '07/04/2023 11:26:41 PM' does not match format '%Y%m%d%H%M%S' (match)
Traceback (most recent call last):
  File "D:\soft\anaconda3\lib\site-packages\pandas\core\tools\datetimes.py", line 510, in _to_datetime_with_format
    values, tz = conversion.datetime_to_datetime64(arg)
  File "pandas\_libs\tslibs\conversion.pyx", line 360, in pandas._libs.tslibs.conversion.datetime_to_datetime64
TypeError: Unrecognized value type: <class 'str'>

During handling of the above exception, another exception occurred:

Traceback (most recent call last):
  File "D:\Ina\ETL_XdmLib_2.A.13\ETL_XdmLib_2.A.13\EDAETL\ETL_TABLE\ETL_FT_SD_TO_XSIFF\ETL_FT_SD_TO_XSIFF.py", line 251, in do_file
    filtered_df['Test Date.'] = pd.to_datetime(filtered_df['Test Date.'], format='%Y%m%d%H%M%S')
  File "D:\soft\anaconda3\lib\site-packages\pandas\core\tools\datetimes.py", line 1051, in to_datetime
    values = convert_listlike(arg._values, format)
  File "D:\soft\anaconda3\lib\site-packages\pandas\core\tools\datetimes.py", line 394, in _convert_listlike_datetimes
    res = _to_datetime_with_format(
  File "D:\soft\anaconda3\lib\site-packages\pandas\core\tools\datetimes.py", line 514, in _to_datetime_with_format
    raise err
  File "D:\soft\anaconda3\lib\site-packages\pandas\core\tools\datetimes.py", line 501, in _to_datetime_with_format
    res = _array_strptime_with_fallback(
  File "D:\soft\anaconda3\lib\site-packages\pandas\core\tools\datetimes.py", line 437, in _array_strptime_with_fallback
    result, timezones = array_strptime(arg, fmt, exact=exact, errors=errors)
  File "pandas\_libs\tslibs\strptime.pyx", line 150, in pandas._libs.tslibs.strptime.array_strptime
ValueError: time data '07/04/2023 11:26:41 PM' does not match format '%Y%m%d%H%M%S' (match)
Stack (most recent call last):
  File "D:\Ina\ETL_XdmLib_2.A.13\ETL_XdmLib_2.A.13\EDAETL\ETL_TABLE\ETL_FT_SD_TO_XSIFF\ETL_FT_SD_TO_XSIFF.py", line 597, in <module>
    XdmLib.CustomFuction.file2db_init(do_file, before_do_file, after_do_file,
  File "D:\Ina\ETL_XdmLib_2.A.13\ETL_XdmLib_2.A.13\EDAETL\ETL_TABLE\ETL_FT_SD_TO_XSIFF\../..\XdmLib\CustomFuction.py", line 596, in file2db_init
    res = do_file(file_root_source_path,
  File "D:\Ina\ETL_XdmLib_2.A.13\ETL_XdmLib_2.A.13\EDAETL\ETL_TABLE\ETL_FT_SD_TO_XSIFF\ETL_FT_SD_TO_XSIFF.py", line 417, in do_file
    log.error(ex, exc_info=True, stack_info=True)
2023-10-26 14:27:14.625 - __init__   [ERROR   ] File:XWECYQH62-GW_GD600MLS100L6S-GW.xlsx Move To Error Folder
                                                Error: None
2023-10-26 14:28:33.909 - ETL_FT_SD_TO_XSIFF [ERROR   ] Not the correct documentation:  [Serial no.] This column is numeric only.
2023-10-26 14:28:36.869 - __init__   [ERROR   ] File:QG35-CW_GD400TAS100L6S.xlsx Move To Error Folder
                                                Error: None
2023-10-26 14:28:38.581 - ETL_FT_SD_TO_XSIFF [ERROR   ] The parameter value does not meet the requirements and contains a value that is not numeric or non-null: ∞
2023-10-26 14:28:41.550 - __init__   [ERROR   ] File:XWECYQH62-GW_GD600MLS100L6S-GW.xlsx Move To Error Folder
                                                Error: None
2023-10-26 14:55:01.160 - __init__   [ERROR   ] Access XDM Loader control table fail.
2023-10-26 15:03:48.550 - ETL_FT_SD_TO_XSIFF [ERROR   ] Not the correct documentation:  [Serial no.] This column is numeric only.
2023-10-26 15:03:51.637 - __init__   [ERROR   ] File:QG35-CW_GD400TAS100L6S.xlsx Move To Error Folder
                                                Error: None
2023-10-26 15:03:53.279 - ETL_FT_SD_TO_XSIFF [ERROR   ] The parameter value does not meet the requirements and contains a value that is not numeric or non-null: ∞
2023-10-26 15:03:56.277 - __init__   [ERROR   ] File:XWECYQH62-GW_GD600MLS100L6S-GW.xlsx Move To Error Folder
                                                Error: None
2023-10-26 15:27:54.780 - ETL_FT_SD_TO_XSIFF [ERROR   ] Not the correct documentation:  [Serial no.] This column is numeric only.
2023-10-26 15:27:57.754 - __init__   [ERROR   ] File:QG35-CW_GD400TAS100L6S.xlsx Move To Error Folder
                                                Error: None
2023-10-26 15:27:59.466 - ETL_FT_SD_TO_XSIFF [ERROR   ] The parameter value does not meet the requirements and contains a value that is not numeric or non-null: ∞
2023-10-26 15:28:02.398 - __init__   [ERROR   ] File:XWECYQH62-GW_GD600MLS100L6S-GW.xlsx Move To Error Folder
                                                Error: None
2023-10-26 15:53:29.120 - ETL_FT_SD_TO_XSIFF [ERROR   ] Not the correct documentation:  [Serial no.] This column is numeric only.
2023-10-26 15:53:32.207 - __init__   [ERROR   ] File:QG35-CW_GD400TAS100L6S.xlsx Move To Error Folder
                                                Error: None
2023-10-26 15:53:32.472 - ETL_FT_SD_TO_XSIFF [ERROR   ] name 'spec' is not defined
Traceback (most recent call last):
  File "D:\Ina\ETL_XdmLib_2.A.13\ETL_XdmLib_2.A.13\EDAETL\ETL_TABLE\ETL_FT_SD_TO_XSIFF\ETL_FT_SD_TO_XSIFF.py", line 407, in do_file
    new_spec = [parameter_no, parameter,parameter_unit[spec]] + [""] * 8
NameError: name 'spec' is not defined
Stack (most recent call last):
  File "D:\Ina\ETL_XdmLib_2.A.13\ETL_XdmLib_2.A.13\EDAETL\ETL_TABLE\ETL_FT_SD_TO_XSIFF\ETL_FT_SD_TO_XSIFF.py", line 595, in <module>
    XdmLib.CustomFuction.file2db_init(do_file, before_do_file, after_do_file,
  File "D:\Ina\ETL_XdmLib_2.A.13\ETL_XdmLib_2.A.13\EDAETL\ETL_TABLE\ETL_FT_SD_TO_XSIFF\../..\XdmLib\CustomFuction.py", line 596, in file2db_init
    res = do_file(file_root_source_path,
  File "D:\Ina\ETL_XdmLib_2.A.13\ETL_XdmLib_2.A.13\EDAETL\ETL_TABLE\ETL_FT_SD_TO_XSIFF\ETL_FT_SD_TO_XSIFF.py", line 414, in do_file
    log.error(ex, exc_info=True, stack_info=True)
2023-10-26 15:53:35.480 - __init__   [ERROR   ] File:TLECGQG81-CW_阳光GD200FYS100L6S.xlsx Move To Error Folder
                                                Error: None
2023-10-26 15:53:36.224 - ETL_FT_SD_TO_XSIFF [ERROR   ] name 'spec' is not defined
Traceback (most recent call last):
  File "D:\Ina\ETL_XdmLib_2.A.13\ETL_XdmLib_2.A.13\EDAETL\ETL_TABLE\ETL_FT_SD_TO_XSIFF\ETL_FT_SD_TO_XSIFF.py", line 407, in do_file
    new_spec = [parameter_no, parameter,parameter_unit[spec]] + [""] * 8
NameError: name 'spec' is not defined
Stack (most recent call last):
  File "D:\Ina\ETL_XdmLib_2.A.13\ETL_XdmLib_2.A.13\EDAETL\ETL_TABLE\ETL_FT_SD_TO_XSIFF\ETL_FT_SD_TO_XSIFF.py", line 595, in <module>
    XdmLib.CustomFuction.file2db_init(do_file, before_do_file, after_do_file,
  File "D:\Ina\ETL_XdmLib_2.A.13\ETL_XdmLib_2.A.13\EDAETL\ETL_TABLE\ETL_FT_SD_TO_XSIFF\../..\XdmLib\CustomFuction.py", line 596, in file2db_init
    res = do_file(file_root_source_path,
  File "D:\Ina\ETL_XdmLib_2.A.13\ETL_XdmLib_2.A.13\EDAETL\ETL_TABLE\ETL_FT_SD_TO_XSIFF\ETL_FT_SD_TO_XSIFF.py", line 414, in do_file
    log.error(ex, exc_info=True, stack_info=True)
2023-10-26 15:53:39.231 - __init__   [ERROR   ] File:XWECYQH20-CW_GD600MLS100L6S.xlsx Move To Error Folder
                                                Error: None
2023-10-26 15:53:39.907 - ETL_FT_SD_TO_XSIFF [ERROR   ] name 'spec' is not defined
Traceback (most recent call last):
  File "D:\Ina\ETL_XdmLib_2.A.13\ETL_XdmLib_2.A.13\EDAETL\ETL_TABLE\ETL_FT_SD_TO_XSIFF\ETL_FT_SD_TO_XSIFF.py", line 407, in do_file
    new_spec = [parameter_no, parameter,parameter_unit[spec]] + [""] * 8
NameError: name 'spec' is not defined
Stack (most recent call last):
  File "D:\Ina\ETL_XdmLib_2.A.13\ETL_XdmLib_2.A.13\EDAETL\ETL_TABLE\ETL_FT_SD_TO_XSIFF\ETL_FT_SD_TO_XSIFF.py", line 595, in <module>
    XdmLib.CustomFuction.file2db_init(do_file, before_do_file, after_do_file,
  File "D:\Ina\ETL_XdmLib_2.A.13\ETL_XdmLib_2.A.13\EDAETL\ETL_TABLE\ETL_FT_SD_TO_XSIFF\../..\XdmLib\CustomFuction.py", line 596, in file2db_init
    res = do_file(file_root_source_path,
  File "D:\Ina\ETL_XdmLib_2.A.13\ETL_XdmLib_2.A.13\EDAETL\ETL_TABLE\ETL_FT_SD_TO_XSIFF\ETL_FT_SD_TO_XSIFF.py", line 414, in do_file
    log.error(ex, exc_info=True, stack_info=True)
2023-10-26 15:53:42.998 - __init__   [ERROR   ] File:XWECYQH62-GW_GD600MLS100L6S-GW.xlsx Move To Error Folder
                                                Error: None
2023-10-26 15:57:31.466 - ETL_FT_SD_TO_XSIFF [ERROR   ] Not the correct documentation:  [Serial no.] This column is numeric only.
2023-10-26 15:57:34.541 - __init__   [ERROR   ] File:QG35-CW_GD400TAS100L6S.xlsx Move To Error Folder
                                                Error: None
2023-10-26 15:57:34.799 - ETL_FT_SD_TO_XSIFF [ERROR   ] Length mismatch: Expected axis has 11 elements, new values have 10 elements
Traceback (most recent call last):
  File "D:\Ina\ETL_XdmLib_2.A.13\ETL_XdmLib_2.A.13\EDAETL\ETL_TABLE\ETL_FT_SD_TO_XSIFF\ETL_FT_SD_TO_XSIFF.py", line 449, in do_file
    spec_df.columns = ["ParameterNo", "ParameterName", "Unit", "SpecLow", "SpecHigh", "ControlLow",
  File "D:\soft\anaconda3\lib\site-packages\pandas\core\generic.py", line 5588, in __setattr__
    return object.__setattr__(self, name, value)
  File "pandas\_libs\properties.pyx", line 70, in pandas._libs.properties.AxisProperty.__set__
  File "D:\soft\anaconda3\lib\site-packages\pandas\core\generic.py", line 769, in _set_axis
    self._mgr.set_axis(axis, labels)
  File "D:\soft\anaconda3\lib\site-packages\pandas\core\internals\managers.py", line 214, in set_axis
    self._validate_set_axis(axis, new_labels)
  File "D:\soft\anaconda3\lib\site-packages\pandas\core\internals\base.py", line 69, in _validate_set_axis
    raise ValueError(
ValueError: Length mismatch: Expected axis has 11 elements, new values have 10 elements
Stack (most recent call last):
  File "D:\Ina\ETL_XdmLib_2.A.13\ETL_XdmLib_2.A.13\EDAETL\ETL_TABLE\ETL_FT_SD_TO_XSIFF\ETL_FT_SD_TO_XSIFF.py", line 595, in <module>
    XdmLib.CustomFuction.file2db_init(do_file, before_do_file, after_do_file,
  File "D:\Ina\ETL_XdmLib_2.A.13\ETL_XdmLib_2.A.13\EDAETL\ETL_TABLE\ETL_FT_SD_TO_XSIFF\../..\XdmLib\CustomFuction.py", line 596, in file2db_init
    res = do_file(file_root_source_path,
  File "D:\Ina\ETL_XdmLib_2.A.13\ETL_XdmLib_2.A.13\EDAETL\ETL_TABLE\ETL_FT_SD_TO_XSIFF\ETL_FT_SD_TO_XSIFF.py", line 500, in do_file
    log.error(ex, exc_info=True, stack_info=True)
2023-10-26 15:57:37.900 - __init__   [ERROR   ] File:TLECGQG81-CW_阳光GD200FYS100L6S.xlsx Move To Error Folder
                                                Error: None
2023-10-26 15:57:38.679 - ETL_FT_SD_TO_XSIFF [ERROR   ] Length mismatch: Expected axis has 11 elements, new values have 10 elements
Traceback (most recent call last):
  File "D:\Ina\ETL_XdmLib_2.A.13\ETL_XdmLib_2.A.13\EDAETL\ETL_TABLE\ETL_FT_SD_TO_XSIFF\ETL_FT_SD_TO_XSIFF.py", line 449, in do_file
    spec_df.columns = ["ParameterNo", "ParameterName", "Unit", "SpecLow", "SpecHigh", "ControlLow",
  File "D:\soft\anaconda3\lib\site-packages\pandas\core\generic.py", line 5588, in __setattr__
    return object.__setattr__(self, name, value)
  File "pandas\_libs\properties.pyx", line 70, in pandas._libs.properties.AxisProperty.__set__
  File "D:\soft\anaconda3\lib\site-packages\pandas\core\generic.py", line 769, in _set_axis
    self._mgr.set_axis(axis, labels)
  File "D:\soft\anaconda3\lib\site-packages\pandas\core\internals\managers.py", line 214, in set_axis
    self._validate_set_axis(axis, new_labels)
  File "D:\soft\anaconda3\lib\site-packages\pandas\core\internals\base.py", line 69, in _validate_set_axis
    raise ValueError(
ValueError: Length mismatch: Expected axis has 11 elements, new values have 10 elements
Stack (most recent call last):
  File "D:\Ina\ETL_XdmLib_2.A.13\ETL_XdmLib_2.A.13\EDAETL\ETL_TABLE\ETL_FT_SD_TO_XSIFF\ETL_FT_SD_TO_XSIFF.py", line 595, in <module>
    XdmLib.CustomFuction.file2db_init(do_file, before_do_file, after_do_file,
  File "D:\Ina\ETL_XdmLib_2.A.13\ETL_XdmLib_2.A.13\EDAETL\ETL_TABLE\ETL_FT_SD_TO_XSIFF\../..\XdmLib\CustomFuction.py", line 596, in file2db_init
    res = do_file(file_root_source_path,
  File "D:\Ina\ETL_XdmLib_2.A.13\ETL_XdmLib_2.A.13\EDAETL\ETL_TABLE\ETL_FT_SD_TO_XSIFF\ETL_FT_SD_TO_XSIFF.py", line 500, in do_file
    log.error(ex, exc_info=True, stack_info=True)
2023-10-26 15:57:41.663 - __init__   [ERROR   ] File:XWECYQH20-CW_GD600MLS100L6S.xlsx Move To Error Folder
                                                Error: None
2023-10-26 15:57:42.314 - ETL_FT_SD_TO_XSIFF [ERROR   ] The parameter value does not meet the requirements and contains a value that is not numeric or non-null: ∞
2023-10-26 15:57:45.241 - __init__   [ERROR   ] File:XWECYQH62-GW_GD600MLS100L6S-GW.xlsx Move To Error Folder
                                                Error: None
2023-10-26 16:01:05.166 - ETL_FT_SD_TO_XSIFF [ERROR   ] Not the correct documentation:  [Serial no.] This column is numeric only.
2023-10-26 16:01:08.251 - __init__   [ERROR   ] File:QG35-CW_GD400TAS100L6S.xlsx Move To Error Folder
                                                Error: None
2023-10-26 16:01:09.868 - ETL_FT_SD_TO_XSIFF [ERROR   ] The parameter value does not meet the requirements and contains a value that is not numeric or non-null: ∞
2023-10-26 16:01:12.928 - __init__   [ERROR   ] File:XWECYQH62-GW_GD600MLS100L6S-GW.xlsx Move To Error Folder
                                                Error: None
