2023-10-24 09:32:14.784 - __init__   [ERROR   ] Access XDM Loader control table fail.
2023-10-24 09:32:34.321 - CustomFuction [ERROR   ] index 2 is out of bounds for axis 0 with size 1
Traceback (most recent call last):
  File "D:\Ina\ETL_XdmLib_2.A.13\ETL_XdmLib_2.A.13\EDAETL\ETL_TABLE\ETL_FT_SD_TO_XSIFF\../..\XdmLib\CustomFuction.py", line 596, in file2db_init
    res = do_file(file_root_source_path,
  File "D:\Ina\ETL_XdmLib_2.A.13\ETL_XdmLib_2.A.13\EDAETL\ETL_TABLE\ETL_FT_SD_TO_XSIFF\ETL_FT_SD_TO_XSIFF.py", line 365, in do_file
    raise ex
  File "D:\Ina\ETL_XdmLib_2.A.13\ETL_XdmLib_2.A.13\EDAETL\ETL_TABLE\ETL_FT_SD_TO_XSIFF\ETL_FT_SD_TO_XSIFF.py", line 205, in do_file
    temp_value = source_data_df.iat[2, 1]
  File "D:\soft\anaconda3\lib\site-packages\pandas\core\indexing.py", line 2221, in __getitem__
    return self.obj._get_value(*key, takeable=self._takeable)
  File "D:\soft\anaconda3\lib\site-packages\pandas\core\frame.py", line 3613, in _get_value
    return series._values[index]
IndexError: index 2 is out of bounds for axis 0 with size 1
Stack (most recent call last):
  File "D:\Ina\ETL_XdmLib_2.A.13\ETL_XdmLib_2.A.13\EDAETL\ETL_TABLE\ETL_FT_SD_TO_XSIFF\ETL_FT_SD_TO_XSIFF.py", line 545, in <module>
    XdmLib.CustomFuction.file2db_init(do_file, before_do_file, after_do_file,
  File "D:\Ina\ETL_XdmLib_2.A.13\ETL_XdmLib_2.A.13\EDAETL\ETL_TABLE\ETL_FT_SD_TO_XSIFF\../..\XdmLib\CustomFuction.py", line 631, in file2db_init
    log.error(ex, exc_info=True, stack_info=True)
2023-10-24 09:44:39.480 - CustomFuction [ERROR   ] index 2 is out of bounds for axis 0 with size 1
Traceback (most recent call last):
  File "D:\Ina\ETL_XdmLib_2.A.13\ETL_XdmLib_2.A.13\EDAETL\ETL_TABLE\ETL_FT_SD_TO_XSIFF\../..\XdmLib\CustomFuction.py", line 596, in file2db_init
    res = do_file(file_root_source_path,
  File "D:\Ina\ETL_XdmLib_2.A.13\ETL_XdmLib_2.A.13\EDAETL\ETL_TABLE\ETL_FT_SD_TO_XSIFF\ETL_FT_SD_TO_XSIFF.py", line 365, in do_file
    raise ex
  File "D:\Ina\ETL_XdmLib_2.A.13\ETL_XdmLib_2.A.13\EDAETL\ETL_TABLE\ETL_FT_SD_TO_XSIFF\ETL_FT_SD_TO_XSIFF.py", line 205, in do_file
    temp_value = source_data_df.iat[2, 1]
  File "D:\soft\anaconda3\lib\site-packages\pandas\core\indexing.py", line 2221, in __getitem__
    return self.obj._get_value(*key, takeable=self._takeable)
  File "D:\soft\anaconda3\lib\site-packages\pandas\core\frame.py", line 3613, in _get_value
    return series._values[index]
IndexError: index 2 is out of bounds for axis 0 with size 1
Stack (most recent call last):
  File "D:\Ina\ETL_XdmLib_2.A.13\ETL_XdmLib_2.A.13\EDAETL\ETL_TABLE\ETL_FT_SD_TO_XSIFF\ETL_FT_SD_TO_XSIFF.py", line 545, in <module>
    XdmLib.CustomFuction.file2db_init(do_file, before_do_file, after_do_file,
  File "D:\Ina\ETL_XdmLib_2.A.13\ETL_XdmLib_2.A.13\EDAETL\ETL_TABLE\ETL_FT_SD_TO_XSIFF\../..\XdmLib\CustomFuction.py", line 631, in file2db_init
    log.error(ex, exc_info=True, stack_info=True)
2023-10-24 09:58:01.321 - CustomFuction [ERROR   ] Move File Error
2023-10-24 09:58:01.323 - CustomFuction [ERROR   ] 'D:\\Ina\\ETL_XdmLib_2.A.13\\ETL_XdmLib_2.A.13\\EDAETL\\ETL_TABLE\\ETL_FT_SD_TO_XSIFF\\Data\\Source\\StarPower\\FT\\Module\\UNISIC\\Dynamic\\GW\\TLECGQG81-CW_阳光GD200FYS100L6S.xlsx' and 'D:\\Ina\\ETL_XdmLib_2.A.13\\ETL_XdmLib_2.A.13\\EDAETL\\ETL_TABLE\\ETL_FT_SD_TO_XSIFF\\Data\\Source\\StarPower\\FT\\Module\\UNISIC\\Dynamic\\GW\\TLECGQG81-CW_阳光GD200FYS100L6S.xlsx' are the same file
Traceback (most recent call last):
  File "D:\soft\anaconda3\lib\shutil.py", line 823, in move
    os.rename(src, real_dst)
PermissionError: [WinError 32] 另一个程序正在使用此文件，进程无法访问。: 'D:\\Ina\\ETL_XdmLib_2.A.13\\ETL_XdmLib_2.A.13\\EDAETL\\ETL_TABLE\\ETL_FT_SD_TO_XSIFF\\Data\\Source\\StarPower\\FT\\Module\\UNISIC\\Dynamic\\GW\\TLECGQG81-CW_阳光GD200FYS100L6S.xlsx' -> 'D:\\Ina\\ETL_XdmLib_2.A.13\\ETL_XdmLib_2.A.13\\EDAETL\\ETL_TABLE\\ETL_FT_SD_TO_XSIFF\\Data\\Source\\StarPower\\FT\\Module\\UNISIC\\Dynamic\\GW\\TLECGQG81-CW_阳光GD200FYS100L6S.xlsx'

During handling of the above exception, another exception occurred:

Traceback (most recent call last):
  File "D:\Ina\ETL_XdmLib_2.A.13\ETL_XdmLib_2.A.13\EDAETL\ETL_TABLE\ETL_FT_SD_TO_XSIFF\../..\XdmLib\CustomFuction.py", line 1035, in move_file
    msg = shutil.move(os.path.join(source_path, fileName),
  File "D:\soft\anaconda3\lib\shutil.py", line 843, in move
    copy_function(src, real_dst)
  File "D:\soft\anaconda3\lib\shutil.py", line 444, in copy2
    copyfile(src, dst, follow_symlinks=follow_symlinks)
  File "D:\soft\anaconda3\lib\shutil.py", line 244, in copyfile
    raise SameFileError("{!r} and {!r} are the same file".format(src, dst))
shutil.SameFileError: 'D:\\Ina\\ETL_XdmLib_2.A.13\\ETL_XdmLib_2.A.13\\EDAETL\\ETL_TABLE\\ETL_FT_SD_TO_XSIFF\\Data\\Source\\StarPower\\FT\\Module\\UNISIC\\Dynamic\\GW\\TLECGQG81-CW_阳光GD200FYS100L6S.xlsx' and 'D:\\Ina\\ETL_XdmLib_2.A.13\\ETL_XdmLib_2.A.13\\EDAETL\\ETL_TABLE\\ETL_FT_SD_TO_XSIFF\\Data\\Source\\StarPower\\FT\\Module\\UNISIC\\Dynamic\\GW\\TLECGQG81-CW_阳光GD200FYS100L6S.xlsx' are the same file
Stack (most recent call last):
  File "D:\Ina\ETL_XdmLib_2.A.13\ETL_XdmLib_2.A.13\EDAETL\ETL_TABLE\ETL_FT_SD_TO_XSIFF\ETL_FT_SD_TO_XSIFF.py", line 545, in <module>
    XdmLib.CustomFuction.file2db_init(do_file, before_do_file, after_do_file,
  File "D:\Ina\ETL_XdmLib_2.A.13\ETL_XdmLib_2.A.13\EDAETL\ETL_TABLE\ETL_FT_SD_TO_XSIFF\../..\XdmLib\CustomFuction.py", line 629, in file2db_init
    move_file_self(move_file_info)
  File "D:\Ina\ETL_XdmLib_2.A.13\ETL_XdmLib_2.A.13\EDAETL\ETL_TABLE\ETL_FT_SD_TO_XSIFF\../..\XdmLib\CustomFuction.py", line 1044, in move_file
    log.error(ex, exc_info=True, stack_info=True)
2023-10-24 09:58:01.331 - CustomFuction [ERROR   ] [Errno 13] Permission denied: 'D:\\Ina\\ETL_XdmLib_2.A.13\\ETL_XdmLib_2.A.13\\EDAETL\\ETL_TABLE\\ETL_FT_SD_TO_XSIFF\\Data\\Source\\StarPower\\FT\\Module\\UNISIC\\Dynamic\\GW\\~$TLECGQG81-CW_阳光GD200FYS100L6S.xlsx'
Traceback (most recent call last):
  File "D:\Ina\ETL_XdmLib_2.A.13\ETL_XdmLib_2.A.13\EDAETL\ETL_TABLE\ETL_FT_SD_TO_XSIFF\../..\XdmLib\CustomFuction.py", line 596, in file2db_init
    res = do_file(file_root_source_path,
  File "D:\Ina\ETL_XdmLib_2.A.13\ETL_XdmLib_2.A.13\EDAETL\ETL_TABLE\ETL_FT_SD_TO_XSIFF\ETL_FT_SD_TO_XSIFF.py", line 365, in do_file
    raise ex
  File "D:\Ina\ETL_XdmLib_2.A.13\ETL_XdmLib_2.A.13\EDAETL\ETL_TABLE\ETL_FT_SD_TO_XSIFF\ETL_FT_SD_TO_XSIFF.py", line 187, in do_file
    source_data_df = pd.read_excel(file_path, skiprows=2)
  File "D:\soft\anaconda3\lib\site-packages\pandas\util\_decorators.py", line 311, in wrapper
    return func(*args, **kwargs)
  File "D:\soft\anaconda3\lib\site-packages\pandas\io\excel\_base.py", line 457, in read_excel
    io = ExcelFile(io, storage_options=storage_options, engine=engine)
  File "D:\soft\anaconda3\lib\site-packages\pandas\io\excel\_base.py", line 1376, in __init__
    ext = inspect_excel_format(
  File "D:\soft\anaconda3\lib\site-packages\pandas\io\excel\_base.py", line 1250, in inspect_excel_format
    with get_handle(
  File "D:\soft\anaconda3\lib\site-packages\pandas\io\common.py", line 798, in get_handle
    handle = open(handle, ioargs.mode)
PermissionError: [Errno 13] Permission denied: 'D:\\Ina\\ETL_XdmLib_2.A.13\\ETL_XdmLib_2.A.13\\EDAETL\\ETL_TABLE\\ETL_FT_SD_TO_XSIFF\\Data\\Source\\StarPower\\FT\\Module\\UNISIC\\Dynamic\\GW\\~$TLECGQG81-CW_阳光GD200FYS100L6S.xlsx'
Stack (most recent call last):
  File "D:\Ina\ETL_XdmLib_2.A.13\ETL_XdmLib_2.A.13\EDAETL\ETL_TABLE\ETL_FT_SD_TO_XSIFF\ETL_FT_SD_TO_XSIFF.py", line 545, in <module>
    XdmLib.CustomFuction.file2db_init(do_file, before_do_file, after_do_file,
  File "D:\Ina\ETL_XdmLib_2.A.13\ETL_XdmLib_2.A.13\EDAETL\ETL_TABLE\ETL_FT_SD_TO_XSIFF\../..\XdmLib\CustomFuction.py", line 631, in file2db_init
    log.error(ex, exc_info=True, stack_info=True)
2023-10-24 09:58:01.360 - CustomFuction [ERROR   ] Move File Error
2023-10-24 09:58:01.361 - CustomFuction [ERROR   ] 'D:\\Ina\\ETL_XdmLib_2.A.13\\ETL_XdmLib_2.A.13\\EDAETL\\ETL_TABLE\\ETL_FT_SD_TO_XSIFF\\Data\\Source\\StarPower\\FT\\Module\\UNISIC\\Dynamic\\GW\\~$TLECGQG81-CW_阳光GD200FYS100L6S.xlsx' and 'D:\\Ina\\ETL_XdmLib_2.A.13\\ETL_XdmLib_2.A.13\\EDAETL\\ETL_TABLE\\ETL_FT_SD_TO_XSIFF\\Data\\Source\\StarPower\\FT\\Module\\UNISIC\\Dynamic\\GW\\~$TLECGQG81-CW_阳光GD200FYS100L6S.xlsx' are the same file
Traceback (most recent call last):
  File "D:\Ina\ETL_XdmLib_2.A.13\ETL_XdmLib_2.A.13\EDAETL\ETL_TABLE\ETL_FT_SD_TO_XSIFF\../..\XdmLib\CustomFuction.py", line 596, in file2db_init
    res = do_file(file_root_source_path,
  File "D:\Ina\ETL_XdmLib_2.A.13\ETL_XdmLib_2.A.13\EDAETL\ETL_TABLE\ETL_FT_SD_TO_XSIFF\ETL_FT_SD_TO_XSIFF.py", line 365, in do_file
    raise ex
  File "D:\Ina\ETL_XdmLib_2.A.13\ETL_XdmLib_2.A.13\EDAETL\ETL_TABLE\ETL_FT_SD_TO_XSIFF\ETL_FT_SD_TO_XSIFF.py", line 187, in do_file
    source_data_df = pd.read_excel(file_path, skiprows=2)
  File "D:\soft\anaconda3\lib\site-packages\pandas\util\_decorators.py", line 311, in wrapper
    return func(*args, **kwargs)
  File "D:\soft\anaconda3\lib\site-packages\pandas\io\excel\_base.py", line 457, in read_excel
    io = ExcelFile(io, storage_options=storage_options, engine=engine)
  File "D:\soft\anaconda3\lib\site-packages\pandas\io\excel\_base.py", line 1376, in __init__
    ext = inspect_excel_format(
  File "D:\soft\anaconda3\lib\site-packages\pandas\io\excel\_base.py", line 1250, in inspect_excel_format
    with get_handle(
  File "D:\soft\anaconda3\lib\site-packages\pandas\io\common.py", line 798, in get_handle
    handle = open(handle, ioargs.mode)
PermissionError: [Errno 13] Permission denied: 'D:\\Ina\\ETL_XdmLib_2.A.13\\ETL_XdmLib_2.A.13\\EDAETL\\ETL_TABLE\\ETL_FT_SD_TO_XSIFF\\Data\\Source\\StarPower\\FT\\Module\\UNISIC\\Dynamic\\GW\\~$TLECGQG81-CW_阳光GD200FYS100L6S.xlsx'

During handling of the above exception, another exception occurred:

Traceback (most recent call last):
  File "D:\soft\anaconda3\lib\shutil.py", line 823, in move
    os.rename(src, real_dst)
PermissionError: [WinError 32] 另一个程序正在使用此文件，进程无法访问。: 'D:\\Ina\\ETL_XdmLib_2.A.13\\ETL_XdmLib_2.A.13\\EDAETL\\ETL_TABLE\\ETL_FT_SD_TO_XSIFF\\Data\\Source\\StarPower\\FT\\Module\\UNISIC\\Dynamic\\GW\\~$TLECGQG81-CW_阳光GD200FYS100L6S.xlsx' -> 'D:\\Ina\\ETL_XdmLib_2.A.13\\ETL_XdmLib_2.A.13\\EDAETL\\ETL_TABLE\\ETL_FT_SD_TO_XSIFF\\Data\\Source\\StarPower\\FT\\Module\\UNISIC\\Dynamic\\GW\\~$TLECGQG81-CW_阳光GD200FYS100L6S.xlsx'

During handling of the above exception, another exception occurred:

Traceback (most recent call last):
  File "D:\Ina\ETL_XdmLib_2.A.13\ETL_XdmLib_2.A.13\EDAETL\ETL_TABLE\ETL_FT_SD_TO_XSIFF\../..\XdmLib\CustomFuction.py", line 1035, in move_file
    msg = shutil.move(os.path.join(source_path, fileName),
  File "D:\soft\anaconda3\lib\shutil.py", line 843, in move
    copy_function(src, real_dst)
  File "D:\soft\anaconda3\lib\shutil.py", line 444, in copy2
    copyfile(src, dst, follow_symlinks=follow_symlinks)
  File "D:\soft\anaconda3\lib\shutil.py", line 244, in copyfile
    raise SameFileError("{!r} and {!r} are the same file".format(src, dst))
shutil.SameFileError: 'D:\\Ina\\ETL_XdmLib_2.A.13\\ETL_XdmLib_2.A.13\\EDAETL\\ETL_TABLE\\ETL_FT_SD_TO_XSIFF\\Data\\Source\\StarPower\\FT\\Module\\UNISIC\\Dynamic\\GW\\~$TLECGQG81-CW_阳光GD200FYS100L6S.xlsx' and 'D:\\Ina\\ETL_XdmLib_2.A.13\\ETL_XdmLib_2.A.13\\EDAETL\\ETL_TABLE\\ETL_FT_SD_TO_XSIFF\\Data\\Source\\StarPower\\FT\\Module\\UNISIC\\Dynamic\\GW\\~$TLECGQG81-CW_阳光GD200FYS100L6S.xlsx' are the same file
Stack (most recent call last):
  File "D:\Ina\ETL_XdmLib_2.A.13\ETL_XdmLib_2.A.13\EDAETL\ETL_TABLE\ETL_FT_SD_TO_XSIFF\ETL_FT_SD_TO_XSIFF.py", line 545, in <module>
    XdmLib.CustomFuction.file2db_init(do_file, before_do_file, after_do_file,
  File "D:\Ina\ETL_XdmLib_2.A.13\ETL_XdmLib_2.A.13\EDAETL\ETL_TABLE\ETL_FT_SD_TO_XSIFF\../..\XdmLib\CustomFuction.py", line 646, in file2db_init
    move_file_self(move_file_info)
  File "D:\Ina\ETL_XdmLib_2.A.13\ETL_XdmLib_2.A.13\EDAETL\ETL_TABLE\ETL_FT_SD_TO_XSIFF\../..\XdmLib\CustomFuction.py", line 1044, in move_file
    log.error(ex, exc_info=True, stack_info=True)
2023-10-24 15:42:02.515 - __init__   [ERROR   ] Access XDM Loader control table fail.
2023-10-24 15:43:04.897 - CustomFuction [ERROR   ] Excel xlsx file; not supported
Traceback (most recent call last):
  File "../..\XdmLib\CustomFuction.py", line 597, in file2db_init
    file, pre_params, db_src, db_tgt)
  File "D:/Ina/ETL_XdmLib_2.A.13/ETL_XdmLib_2.A.13/EDAETL/ETL_TABLE/ETL_FT_SD_TO_XSIFF/ETL_FT_SD_TO_XSIFF.py", line 370, in do_file
    raise ex
  File "D:/Ina/ETL_XdmLib_2.A.13/ETL_XdmLib_2.A.13/EDAETL/ETL_TABLE/ETL_FT_SD_TO_XSIFF/ETL_FT_SD_TO_XSIFF.py", line 187, in do_file
    source_data_df = pd.read_excel(file_path, skiprows=2)
  File "D:\Python37\lib\site-packages\pandas\util\_decorators.py", line 296, in wrapper
    return func(*args, **kwargs)
  File "D:\Python37\lib\site-packages\pandas\io\excel\_base.py", line 304, in read_excel
    io = ExcelFile(io, engine=engine)
  File "D:\Python37\lib\site-packages\pandas\io\excel\_base.py", line 867, in __init__
    self._reader = self._engines[engine](self._io)
  File "D:\Python37\lib\site-packages\pandas\io\excel\_xlrd.py", line 22, in __init__
    super().__init__(filepath_or_buffer)
  File "D:\Python37\lib\site-packages\pandas\io\excel\_base.py", line 353, in __init__
    self.book = self.load_workbook(filepath_or_buffer)
  File "D:\Python37\lib\site-packages\pandas\io\excel\_xlrd.py", line 37, in load_workbook
    return open_workbook(filepath_or_buffer)
  File "D:\Python37\lib\site-packages\xlrd\__init__.py", line 170, in open_workbook
    raise XLRDError(FILE_FORMAT_DESCRIPTIONS[file_format]+'; not supported')
xlrd.biffh.XLRDError: Excel xlsx file; not supported
Stack (most recent call last):
  File "D:/Ina/ETL_XdmLib_2.A.13/ETL_XdmLib_2.A.13/EDAETL/ETL_TABLE/ETL_FT_SD_TO_XSIFF/ETL_FT_SD_TO_XSIFF.py", line 551, in <module>
    skip_file, None, log, config, config_sql)
  File "../..\XdmLib\CustomFuction.py", line 631, in file2db_init
    log.error(ex, exc_info=True, stack_info=True)
2023-10-24 15:43:04.923 - CustomFuction [ERROR   ] Move File Error
2023-10-24 15:43:04.923 - CustomFuction [ERROR   ] 'D:\\Ina\\ETL_XdmLib_2.A.13\\ETL_XdmLib_2.A.13\\EDAETL\\ETL_TABLE\\ETL_FT_SD_TO_XSIFF\\Data\\Source\\StarPower\\FT\\Module\\UNISIC\\Dynamic\\GW\\TLECGQG81-CW_阳光GD200FYS100L6S.xlsx' and 'D:\\Ina\\ETL_XdmLib_2.A.13\\ETL_XdmLib_2.A.13\\EDAETL\\ETL_TABLE\\ETL_FT_SD_TO_XSIFF\\Data\\Source\\StarPower\\FT\\Module\\UNISIC\\Dynamic\\GW\\TLECGQG81-CW_阳光GD200FYS100L6S.xlsx' are the same file
Traceback (most recent call last):
  File "../..\XdmLib\CustomFuction.py", line 597, in file2db_init
    file, pre_params, db_src, db_tgt)
  File "D:/Ina/ETL_XdmLib_2.A.13/ETL_XdmLib_2.A.13/EDAETL/ETL_TABLE/ETL_FT_SD_TO_XSIFF/ETL_FT_SD_TO_XSIFF.py", line 370, in do_file
    raise ex
  File "D:/Ina/ETL_XdmLib_2.A.13/ETL_XdmLib_2.A.13/EDAETL/ETL_TABLE/ETL_FT_SD_TO_XSIFF/ETL_FT_SD_TO_XSIFF.py", line 187, in do_file
    source_data_df = pd.read_excel(file_path, skiprows=2)
  File "D:\Python37\lib\site-packages\pandas\util\_decorators.py", line 296, in wrapper
    return func(*args, **kwargs)
  File "D:\Python37\lib\site-packages\pandas\io\excel\_base.py", line 304, in read_excel
    io = ExcelFile(io, engine=engine)
  File "D:\Python37\lib\site-packages\pandas\io\excel\_base.py", line 867, in __init__
    self._reader = self._engines[engine](self._io)
  File "D:\Python37\lib\site-packages\pandas\io\excel\_xlrd.py", line 22, in __init__
    super().__init__(filepath_or_buffer)
  File "D:\Python37\lib\site-packages\pandas\io\excel\_base.py", line 353, in __init__
    self.book = self.load_workbook(filepath_or_buffer)
  File "D:\Python37\lib\site-packages\pandas\io\excel\_xlrd.py", line 37, in load_workbook
    return open_workbook(filepath_or_buffer)
  File "D:\Python37\lib\site-packages\xlrd\__init__.py", line 170, in open_workbook
    raise XLRDError(FILE_FORMAT_DESCRIPTIONS[file_format]+'; not supported')
xlrd.biffh.XLRDError: Excel xlsx file; not supported

During handling of the above exception, another exception occurred:

Traceback (most recent call last):
  File "D:\Python37\lib\shutil.py", line 557, in move
    os.rename(src, real_dst)
PermissionError: [WinError 32] 另一个程序正在使用此文件，进程无法访问。: 'D:\\Ina\\ETL_XdmLib_2.A.13\\ETL_XdmLib_2.A.13\\EDAETL\\ETL_TABLE\\ETL_FT_SD_TO_XSIFF\\Data\\Source\\StarPower\\FT\\Module\\UNISIC\\Dynamic\\GW\\TLECGQG81-CW_阳光GD200FYS100L6S.xlsx' -> 'D:\\Ina\\ETL_XdmLib_2.A.13\\ETL_XdmLib_2.A.13\\EDAETL\\ETL_TABLE\\ETL_FT_SD_TO_XSIFF\\Data\\Source\\StarPower\\FT\\Module\\UNISIC\\Dynamic\\GW\\TLECGQG81-CW_阳光GD200FYS100L6S.xlsx'

During handling of the above exception, another exception occurred:

Traceback (most recent call last):
  File "../..\XdmLib\CustomFuction.py", line 1036, in move_file
    os.path.join(target_path, fileName))
  File "D:\Python37\lib\shutil.py", line 571, in move
    copy_function(src, real_dst)
  File "D:\Python37\lib\shutil.py", line 257, in copy2
    copyfile(src, dst, follow_symlinks=follow_symlinks)
  File "D:\Python37\lib\shutil.py", line 104, in copyfile
    raise SameFileError("{!r} and {!r} are the same file".format(src, dst))
shutil.SameFileError: 'D:\\Ina\\ETL_XdmLib_2.A.13\\ETL_XdmLib_2.A.13\\EDAETL\\ETL_TABLE\\ETL_FT_SD_TO_XSIFF\\Data\\Source\\StarPower\\FT\\Module\\UNISIC\\Dynamic\\GW\\TLECGQG81-CW_阳光GD200FYS100L6S.xlsx' and 'D:\\Ina\\ETL_XdmLib_2.A.13\\ETL_XdmLib_2.A.13\\EDAETL\\ETL_TABLE\\ETL_FT_SD_TO_XSIFF\\Data\\Source\\StarPower\\FT\\Module\\UNISIC\\Dynamic\\GW\\TLECGQG81-CW_阳光GD200FYS100L6S.xlsx' are the same file
Stack (most recent call last):
  File "D:/Ina/ETL_XdmLib_2.A.13/ETL_XdmLib_2.A.13/EDAETL/ETL_TABLE/ETL_FT_SD_TO_XSIFF/ETL_FT_SD_TO_XSIFF.py", line 551, in <module>
    skip_file, None, log, config, config_sql)
  File "../..\XdmLib\CustomFuction.py", line 646, in file2db_init
    move_file_self(move_file_info)
  File "../..\XdmLib\CustomFuction.py", line 1044, in move_file
    log.error(ex, exc_info=True, stack_info=True)
2023-10-24 15:43:06.029 - CustomFuction [ERROR   ] [Errno 13] Permission denied: 'D:\\Ina\\ETL_XdmLib_2.A.13\\ETL_XdmLib_2.A.13\\EDAETL\\ETL_TABLE\\ETL_FT_SD_TO_XSIFF\\Data\\Source\\StarPower\\FT\\Module\\UNISIC\\Dynamic\\GW\\~$TLECGQG81-CW_阳光GD200FYS100L6S.xlsx'
Traceback (most recent call last):
  File "../..\XdmLib\CustomFuction.py", line 597, in file2db_init
    file, pre_params, db_src, db_tgt)
  File "D:/Ina/ETL_XdmLib_2.A.13/ETL_XdmLib_2.A.13/EDAETL/ETL_TABLE/ETL_FT_SD_TO_XSIFF/ETL_FT_SD_TO_XSIFF.py", line 370, in do_file
    raise ex
  File "D:/Ina/ETL_XdmLib_2.A.13/ETL_XdmLib_2.A.13/EDAETL/ETL_TABLE/ETL_FT_SD_TO_XSIFF/ETL_FT_SD_TO_XSIFF.py", line 187, in do_file
    source_data_df = pd.read_excel(file_path, skiprows=2)
  File "D:\Python37\lib\site-packages\pandas\util\_decorators.py", line 296, in wrapper
    return func(*args, **kwargs)
  File "D:\Python37\lib\site-packages\pandas\io\excel\_base.py", line 304, in read_excel
    io = ExcelFile(io, engine=engine)
  File "D:\Python37\lib\site-packages\pandas\io\excel\_base.py", line 867, in __init__
    self._reader = self._engines[engine](self._io)
  File "D:\Python37\lib\site-packages\pandas\io\excel\_xlrd.py", line 22, in __init__
    super().__init__(filepath_or_buffer)
  File "D:\Python37\lib\site-packages\pandas\io\excel\_base.py", line 353, in __init__
    self.book = self.load_workbook(filepath_or_buffer)
  File "D:\Python37\lib\site-packages\pandas\io\excel\_xlrd.py", line 37, in load_workbook
    return open_workbook(filepath_or_buffer)
  File "D:\Python37\lib\site-packages\xlrd\__init__.py", line 166, in open_workbook
    file_format = inspect_format(filename, file_contents)
  File "D:\Python37\lib\site-packages\xlrd\__init__.py", line 60, in inspect_format
    with open(path, "rb") as f:
PermissionError: [Errno 13] Permission denied: 'D:\\Ina\\ETL_XdmLib_2.A.13\\ETL_XdmLib_2.A.13\\EDAETL\\ETL_TABLE\\ETL_FT_SD_TO_XSIFF\\Data\\Source\\StarPower\\FT\\Module\\UNISIC\\Dynamic\\GW\\~$TLECGQG81-CW_阳光GD200FYS100L6S.xlsx'
Stack (most recent call last):
  File "D:/Ina/ETL_XdmLib_2.A.13/ETL_XdmLib_2.A.13/EDAETL/ETL_TABLE/ETL_FT_SD_TO_XSIFF/ETL_FT_SD_TO_XSIFF.py", line 551, in <module>
    skip_file, None, log, config, config_sql)
  File "../..\XdmLib\CustomFuction.py", line 631, in file2db_init
    log.error(ex, exc_info=True, stack_info=True)
2023-10-24 15:43:06.053 - CustomFuction [ERROR   ] Move File Error
2023-10-24 15:43:06.055 - CustomFuction [ERROR   ] 'D:\\Ina\\ETL_XdmLib_2.A.13\\ETL_XdmLib_2.A.13\\EDAETL\\ETL_TABLE\\ETL_FT_SD_TO_XSIFF\\Data\\Source\\StarPower\\FT\\Module\\UNISIC\\Dynamic\\GW\\~$TLECGQG81-CW_阳光GD200FYS100L6S.xlsx' and 'D:\\Ina\\ETL_XdmLib_2.A.13\\ETL_XdmLib_2.A.13\\EDAETL\\ETL_TABLE\\ETL_FT_SD_TO_XSIFF\\Data\\Source\\StarPower\\FT\\Module\\UNISIC\\Dynamic\\GW\\~$TLECGQG81-CW_阳光GD200FYS100L6S.xlsx' are the same file
Traceback (most recent call last):
  File "../..\XdmLib\CustomFuction.py", line 597, in file2db_init
    file, pre_params, db_src, db_tgt)
  File "D:/Ina/ETL_XdmLib_2.A.13/ETL_XdmLib_2.A.13/EDAETL/ETL_TABLE/ETL_FT_SD_TO_XSIFF/ETL_FT_SD_TO_XSIFF.py", line 370, in do_file
    raise ex
  File "D:/Ina/ETL_XdmLib_2.A.13/ETL_XdmLib_2.A.13/EDAETL/ETL_TABLE/ETL_FT_SD_TO_XSIFF/ETL_FT_SD_TO_XSIFF.py", line 187, in do_file
    source_data_df = pd.read_excel(file_path, skiprows=2)
  File "D:\Python37\lib\site-packages\pandas\util\_decorators.py", line 296, in wrapper
    return func(*args, **kwargs)
  File "D:\Python37\lib\site-packages\pandas\io\excel\_base.py", line 304, in read_excel
    io = ExcelFile(io, engine=engine)
  File "D:\Python37\lib\site-packages\pandas\io\excel\_base.py", line 867, in __init__
    self._reader = self._engines[engine](self._io)
  File "D:\Python37\lib\site-packages\pandas\io\excel\_xlrd.py", line 22, in __init__
    super().__init__(filepath_or_buffer)
  File "D:\Python37\lib\site-packages\pandas\io\excel\_base.py", line 353, in __init__
    self.book = self.load_workbook(filepath_or_buffer)
  File "D:\Python37\lib\site-packages\pandas\io\excel\_xlrd.py", line 37, in load_workbook
    return open_workbook(filepath_or_buffer)
  File "D:\Python37\lib\site-packages\xlrd\__init__.py", line 166, in open_workbook
    file_format = inspect_format(filename, file_contents)
  File "D:\Python37\lib\site-packages\xlrd\__init__.py", line 60, in inspect_format
    with open(path, "rb") as f:
PermissionError: [Errno 13] Permission denied: 'D:\\Ina\\ETL_XdmLib_2.A.13\\ETL_XdmLib_2.A.13\\EDAETL\\ETL_TABLE\\ETL_FT_SD_TO_XSIFF\\Data\\Source\\StarPower\\FT\\Module\\UNISIC\\Dynamic\\GW\\~$TLECGQG81-CW_阳光GD200FYS100L6S.xlsx'

During handling of the above exception, another exception occurred:

Traceback (most recent call last):
  File "D:\Python37\lib\shutil.py", line 557, in move
    os.rename(src, real_dst)
PermissionError: [WinError 32] 另一个程序正在使用此文件，进程无法访问。: 'D:\\Ina\\ETL_XdmLib_2.A.13\\ETL_XdmLib_2.A.13\\EDAETL\\ETL_TABLE\\ETL_FT_SD_TO_XSIFF\\Data\\Source\\StarPower\\FT\\Module\\UNISIC\\Dynamic\\GW\\~$TLECGQG81-CW_阳光GD200FYS100L6S.xlsx' -> 'D:\\Ina\\ETL_XdmLib_2.A.13\\ETL_XdmLib_2.A.13\\EDAETL\\ETL_TABLE\\ETL_FT_SD_TO_XSIFF\\Data\\Source\\StarPower\\FT\\Module\\UNISIC\\Dynamic\\GW\\~$TLECGQG81-CW_阳光GD200FYS100L6S.xlsx'

During handling of the above exception, another exception occurred:

Traceback (most recent call last):
  File "../..\XdmLib\CustomFuction.py", line 1036, in move_file
    os.path.join(target_path, fileName))
  File "D:\Python37\lib\shutil.py", line 571, in move
    copy_function(src, real_dst)
  File "D:\Python37\lib\shutil.py", line 257, in copy2
    copyfile(src, dst, follow_symlinks=follow_symlinks)
  File "D:\Python37\lib\shutil.py", line 104, in copyfile
    raise SameFileError("{!r} and {!r} are the same file".format(src, dst))
shutil.SameFileError: 'D:\\Ina\\ETL_XdmLib_2.A.13\\ETL_XdmLib_2.A.13\\EDAETL\\ETL_TABLE\\ETL_FT_SD_TO_XSIFF\\Data\\Source\\StarPower\\FT\\Module\\UNISIC\\Dynamic\\GW\\~$TLECGQG81-CW_阳光GD200FYS100L6S.xlsx' and 'D:\\Ina\\ETL_XdmLib_2.A.13\\ETL_XdmLib_2.A.13\\EDAETL\\ETL_TABLE\\ETL_FT_SD_TO_XSIFF\\Data\\Source\\StarPower\\FT\\Module\\UNISIC\\Dynamic\\GW\\~$TLECGQG81-CW_阳光GD200FYS100L6S.xlsx' are the same file
Stack (most recent call last):
  File "D:/Ina/ETL_XdmLib_2.A.13/ETL_XdmLib_2.A.13/EDAETL/ETL_TABLE/ETL_FT_SD_TO_XSIFF/ETL_FT_SD_TO_XSIFF.py", line 551, in <module>
    skip_file, None, log, config, config_sql)
  File "../..\XdmLib\CustomFuction.py", line 646, in file2db_init
    move_file_self(move_file_info)
  File "../..\XdmLib\CustomFuction.py", line 1044, in move_file
    log.error(ex, exc_info=True, stack_info=True)
2023-10-24 15:44:18.810 - CustomFuction [ERROR   ] Excel xlsx file; not supported
Traceback (most recent call last):
  File "../..\XdmLib\CustomFuction.py", line 597, in file2db_init
    file, pre_params, db_src, db_tgt)
  File "D:/Ina/ETL_XdmLib_2.A.13/ETL_XdmLib_2.A.13/EDAETL/ETL_TABLE/ETL_FT_SD_TO_XSIFF/ETL_FT_SD_TO_XSIFF.py", line 370, in do_file
    raise ex
  File "D:/Ina/ETL_XdmLib_2.A.13/ETL_XdmLib_2.A.13/EDAETL/ETL_TABLE/ETL_FT_SD_TO_XSIFF/ETL_FT_SD_TO_XSIFF.py", line 187, in do_file
    source_data_df = pd.read_excel(file_path, skiprows=2)
  File "D:\Python37\lib\site-packages\pandas\util\_decorators.py", line 296, in wrapper
    return func(*args, **kwargs)
  File "D:\Python37\lib\site-packages\pandas\io\excel\_base.py", line 304, in read_excel
    io = ExcelFile(io, engine=engine)
  File "D:\Python37\lib\site-packages\pandas\io\excel\_base.py", line 867, in __init__
    self._reader = self._engines[engine](self._io)
  File "D:\Python37\lib\site-packages\pandas\io\excel\_xlrd.py", line 22, in __init__
    super().__init__(filepath_or_buffer)
  File "D:\Python37\lib\site-packages\pandas\io\excel\_base.py", line 353, in __init__
    self.book = self.load_workbook(filepath_or_buffer)
  File "D:\Python37\lib\site-packages\pandas\io\excel\_xlrd.py", line 37, in load_workbook
    return open_workbook(filepath_or_buffer)
  File "D:\Python37\lib\site-packages\xlrd\__init__.py", line 170, in open_workbook
    raise XLRDError(FILE_FORMAT_DESCRIPTIONS[file_format]+'; not supported')
xlrd.biffh.XLRDError: Excel xlsx file; not supported
Stack (most recent call last):
  File "D:/Ina/ETL_XdmLib_2.A.13/ETL_XdmLib_2.A.13/EDAETL/ETL_TABLE/ETL_FT_SD_TO_XSIFF/ETL_FT_SD_TO_XSIFF.py", line 551, in <module>
    skip_file, None, log, config, config_sql)
  File "../..\XdmLib\CustomFuction.py", line 631, in file2db_init
    log.error(ex, exc_info=True, stack_info=True)
2023-10-24 15:44:19.828 - CustomFuction [ERROR   ] Excel xlsx file; not supported
Traceback (most recent call last):
  File "../..\XdmLib\CustomFuction.py", line 597, in file2db_init
    file, pre_params, db_src, db_tgt)
  File "D:/Ina/ETL_XdmLib_2.A.13/ETL_XdmLib_2.A.13/EDAETL/ETL_TABLE/ETL_FT_SD_TO_XSIFF/ETL_FT_SD_TO_XSIFF.py", line 370, in do_file
    raise ex
  File "D:/Ina/ETL_XdmLib_2.A.13/ETL_XdmLib_2.A.13/EDAETL/ETL_TABLE/ETL_FT_SD_TO_XSIFF/ETL_FT_SD_TO_XSIFF.py", line 187, in do_file
    source_data_df = pd.read_excel(file_path, skiprows=2)
  File "D:\Python37\lib\site-packages\pandas\util\_decorators.py", line 296, in wrapper
    return func(*args, **kwargs)
  File "D:\Python37\lib\site-packages\pandas\io\excel\_base.py", line 304, in read_excel
    io = ExcelFile(io, engine=engine)
  File "D:\Python37\lib\site-packages\pandas\io\excel\_base.py", line 867, in __init__
    self._reader = self._engines[engine](self._io)
  File "D:\Python37\lib\site-packages\pandas\io\excel\_xlrd.py", line 22, in __init__
    super().__init__(filepath_or_buffer)
  File "D:\Python37\lib\site-packages\pandas\io\excel\_base.py", line 353, in __init__
    self.book = self.load_workbook(filepath_or_buffer)
  File "D:\Python37\lib\site-packages\pandas\io\excel\_xlrd.py", line 37, in load_workbook
    return open_workbook(filepath_or_buffer)
  File "D:\Python37\lib\site-packages\xlrd\__init__.py", line 170, in open_workbook
    raise XLRDError(FILE_FORMAT_DESCRIPTIONS[file_format]+'; not supported')
xlrd.biffh.XLRDError: Excel xlsx file; not supported
Stack (most recent call last):
  File "D:/Ina/ETL_XdmLib_2.A.13/ETL_XdmLib_2.A.13/EDAETL/ETL_TABLE/ETL_FT_SD_TO_XSIFF/ETL_FT_SD_TO_XSIFF.py", line 551, in <module>
    skip_file, None, log, config, config_sql)
  File "../..\XdmLib\CustomFuction.py", line 631, in file2db_init
    log.error(ex, exc_info=True, stack_info=True)
2023-10-24 15:54:10.188 - CustomFuction [ERROR   ] Excel xlsx file; not supported
Traceback (most recent call last):
  File "../..\XdmLib\CustomFuction.py", line 597, in file2db_init
    file, pre_params, db_src, db_tgt)
  File "D:/Ina/ETL_XdmLib_2.A.13/ETL_XdmLib_2.A.13/EDAETL/ETL_TABLE/ETL_FT_SD_TO_XSIFF/ETL_FT_SD_TO_XSIFF.py", line 370, in do_file
    raise ex
  File "D:/Ina/ETL_XdmLib_2.A.13/ETL_XdmLib_2.A.13/EDAETL/ETL_TABLE/ETL_FT_SD_TO_XSIFF/ETL_FT_SD_TO_XSIFF.py", line 187, in do_file
    source_data_df = pd.read_excel(file_path, skiprows=2)
  File "D:\Python37\lib\site-packages\pandas\util\_decorators.py", line 296, in wrapper
    return func(*args, **kwargs)
  File "D:\Python37\lib\site-packages\pandas\io\excel\_base.py", line 304, in read_excel
    io = ExcelFile(io, engine=engine)
  File "D:\Python37\lib\site-packages\pandas\io\excel\_base.py", line 867, in __init__
    self._reader = self._engines[engine](self._io)
  File "D:\Python37\lib\site-packages\pandas\io\excel\_xlrd.py", line 22, in __init__
    super().__init__(filepath_or_buffer)
  File "D:\Python37\lib\site-packages\pandas\io\excel\_base.py", line 353, in __init__
    self.book = self.load_workbook(filepath_or_buffer)
  File "D:\Python37\lib\site-packages\pandas\io\excel\_xlrd.py", line 37, in load_workbook
    return open_workbook(filepath_or_buffer)
  File "D:\Python37\lib\site-packages\xlrd\__init__.py", line 170, in open_workbook
    raise XLRDError(FILE_FORMAT_DESCRIPTIONS[file_format]+'; not supported')
xlrd.biffh.XLRDError: Excel xlsx file; not supported
Stack (most recent call last):
  File "D:/Ina/ETL_XdmLib_2.A.13/ETL_XdmLib_2.A.13/EDAETL/ETL_TABLE/ETL_FT_SD_TO_XSIFF/ETL_FT_SD_TO_XSIFF.py", line 551, in <module>
    skip_file, None, log, config, config_sql)
  File "../..\XdmLib\CustomFuction.py", line 631, in file2db_init
    log.error(ex, exc_info=True, stack_info=True)
2023-10-24 15:54:11.217 - CustomFuction [ERROR   ] Excel xlsx file; not supported
Traceback (most recent call last):
  File "../..\XdmLib\CustomFuction.py", line 597, in file2db_init
    file, pre_params, db_src, db_tgt)
  File "D:/Ina/ETL_XdmLib_2.A.13/ETL_XdmLib_2.A.13/EDAETL/ETL_TABLE/ETL_FT_SD_TO_XSIFF/ETL_FT_SD_TO_XSIFF.py", line 370, in do_file
    raise ex
  File "D:/Ina/ETL_XdmLib_2.A.13/ETL_XdmLib_2.A.13/EDAETL/ETL_TABLE/ETL_FT_SD_TO_XSIFF/ETL_FT_SD_TO_XSIFF.py", line 187, in do_file
    source_data_df = pd.read_excel(file_path, skiprows=2)
  File "D:\Python37\lib\site-packages\pandas\util\_decorators.py", line 296, in wrapper
    return func(*args, **kwargs)
  File "D:\Python37\lib\site-packages\pandas\io\excel\_base.py", line 304, in read_excel
    io = ExcelFile(io, engine=engine)
  File "D:\Python37\lib\site-packages\pandas\io\excel\_base.py", line 867, in __init__
    self._reader = self._engines[engine](self._io)
  File "D:\Python37\lib\site-packages\pandas\io\excel\_xlrd.py", line 22, in __init__
    super().__init__(filepath_or_buffer)
  File "D:\Python37\lib\site-packages\pandas\io\excel\_base.py", line 353, in __init__
    self.book = self.load_workbook(filepath_or_buffer)
  File "D:\Python37\lib\site-packages\pandas\io\excel\_xlrd.py", line 37, in load_workbook
    return open_workbook(filepath_or_buffer)
  File "D:\Python37\lib\site-packages\xlrd\__init__.py", line 170, in open_workbook
    raise XLRDError(FILE_FORMAT_DESCRIPTIONS[file_format]+'; not supported')
xlrd.biffh.XLRDError: Excel xlsx file; not supported
Stack (most recent call last):
  File "D:/Ina/ETL_XdmLib_2.A.13/ETL_XdmLib_2.A.13/EDAETL/ETL_TABLE/ETL_FT_SD_TO_XSIFF/ETL_FT_SD_TO_XSIFF.py", line 551, in <module>
    skip_file, None, log, config, config_sql)
  File "../..\XdmLib\CustomFuction.py", line 631, in file2db_init
    log.error(ex, exc_info=True, stack_info=True)
2023-10-24 15:57:05.938 - CustomFuction [ERROR   ] Missing optional dependency 'openpyxl'.  Use pip or conda to install openpyxl.
Traceback (most recent call last):
  File "../..\XdmLib\CustomFuction.py", line 597, in file2db_init
    file, pre_params, db_src, db_tgt)
  File "D:/Ina/ETL_XdmLib_2.A.13/ETL_XdmLib_2.A.13/EDAETL/ETL_TABLE/ETL_FT_SD_TO_XSIFF/ETL_FT_SD_TO_XSIFF.py", line 370, in do_file
    raise ex
  File "D:/Ina/ETL_XdmLib_2.A.13/ETL_XdmLib_2.A.13/EDAETL/ETL_TABLE/ETL_FT_SD_TO_XSIFF/ETL_FT_SD_TO_XSIFF.py", line 187, in do_file
    source_data_df = pd.read_excel(file_path, skiprows=2,engine='openpyxl')
  File "D:\Python37\lib\site-packages\pandas\util\_decorators.py", line 296, in wrapper
    return func(*args, **kwargs)
  File "D:\Python37\lib\site-packages\pandas\io\excel\_base.py", line 304, in read_excel
    io = ExcelFile(io, engine=engine)
  File "D:\Python37\lib\site-packages\pandas\io\excel\_base.py", line 867, in __init__
    self._reader = self._engines[engine](self._io)
  File "D:\Python37\lib\site-packages\pandas\io\excel\_openpyxl.py", line 479, in __init__
    import_optional_dependency("openpyxl")
  File "D:\Python37\lib\site-packages\pandas\compat\_optional.py", line 110, in import_optional_dependency
    raise ImportError(msg) from None
ImportError: Missing optional dependency 'openpyxl'.  Use pip or conda to install openpyxl.
Stack (most recent call last):
  File "D:/Ina/ETL_XdmLib_2.A.13/ETL_XdmLib_2.A.13/EDAETL/ETL_TABLE/ETL_FT_SD_TO_XSIFF/ETL_FT_SD_TO_XSIFF.py", line 551, in <module>
    skip_file, None, log, config, config_sql)
  File "../..\XdmLib\CustomFuction.py", line 631, in file2db_init
    log.error(ex, exc_info=True, stack_info=True)
2023-10-24 15:57:06.918 - CustomFuction [ERROR   ] Missing optional dependency 'openpyxl'.  Use pip or conda to install openpyxl.
Traceback (most recent call last):
  File "../..\XdmLib\CustomFuction.py", line 597, in file2db_init
    file, pre_params, db_src, db_tgt)
  File "D:/Ina/ETL_XdmLib_2.A.13/ETL_XdmLib_2.A.13/EDAETL/ETL_TABLE/ETL_FT_SD_TO_XSIFF/ETL_FT_SD_TO_XSIFF.py", line 370, in do_file
    raise ex
  File "D:/Ina/ETL_XdmLib_2.A.13/ETL_XdmLib_2.A.13/EDAETL/ETL_TABLE/ETL_FT_SD_TO_XSIFF/ETL_FT_SD_TO_XSIFF.py", line 187, in do_file
    source_data_df = pd.read_excel(file_path, skiprows=2,engine='openpyxl')
  File "D:\Python37\lib\site-packages\pandas\util\_decorators.py", line 296, in wrapper
    return func(*args, **kwargs)
  File "D:\Python37\lib\site-packages\pandas\io\excel\_base.py", line 304, in read_excel
    io = ExcelFile(io, engine=engine)
  File "D:\Python37\lib\site-packages\pandas\io\excel\_base.py", line 867, in __init__
    self._reader = self._engines[engine](self._io)
  File "D:\Python37\lib\site-packages\pandas\io\excel\_openpyxl.py", line 479, in __init__
    import_optional_dependency("openpyxl")
  File "D:\Python37\lib\site-packages\pandas\compat\_optional.py", line 110, in import_optional_dependency
    raise ImportError(msg) from None
ImportError: Missing optional dependency 'openpyxl'.  Use pip or conda to install openpyxl.
Stack (most recent call last):
  File "D:/Ina/ETL_XdmLib_2.A.13/ETL_XdmLib_2.A.13/EDAETL/ETL_TABLE/ETL_FT_SD_TO_XSIFF/ETL_FT_SD_TO_XSIFF.py", line 551, in <module>
    skip_file, None, log, config, config_sql)
  File "../..\XdmLib\CustomFuction.py", line 631, in file2db_init
    log.error(ex, exc_info=True, stack_info=True)
2023-10-24 16:11:49.655 - ETL_FT_SD_TO_XSIFF [ERROR   ] list index out of range
2023-10-24 16:11:49.657 - ETL_FT_SD_TO_XSIFF [ERROR   ] local variable 'Lot' referenced before assignment
2023-10-24 16:11:49.658 - ETL_FT_SD_TO_XSIFF [ERROR   ] local variable 'bin_def_df' referenced before assignment
2023-10-24 16:11:49.663 - CustomFuction [ERROR   ] local variable 'xsiff_file_name' referenced before assignment
Traceback (most recent call last):
  File "D:\Ina\ETL_XdmLib_2.A.13\ETL_XdmLib_2.A.13\EDAETL\ETL_TABLE\ETL_FT_SD_TO_XSIFF\../..\XdmLib\CustomFuction.py", line 596, in file2db_init
    res = do_file(file_root_source_path,
  File "D:\Ina\ETL_XdmLib_2.A.13\ETL_XdmLib_2.A.13\EDAETL\ETL_TABLE\ETL_FT_SD_TO_XSIFF\ETL_FT_SD_TO_XSIFF.py", line 496, in do_file
    log.info(f'Converter {file_name} to {xsiff_file_name} ;Total Used:{te_t - ts_t}')
UnboundLocalError: local variable 'xsiff_file_name' referenced before assignment
Stack (most recent call last):
  File "D:\Ina\ETL_XdmLib_2.A.13\ETL_XdmLib_2.A.13\EDAETL\ETL_TABLE\ETL_FT_SD_TO_XSIFF\ETL_FT_SD_TO_XSIFF.py", line 550, in <module>
    XdmLib.CustomFuction.file2db_init(do_file, before_do_file, after_do_file,
  File "D:\Ina\ETL_XdmLib_2.A.13\ETL_XdmLib_2.A.13\EDAETL\ETL_TABLE\ETL_FT_SD_TO_XSIFF\../..\XdmLib\CustomFuction.py", line 631, in file2db_init
    log.error(ex, exc_info=True, stack_info=True)
2023-10-24 16:15:02.800 - ETL_FT_SD_TO_XSIFF [ERROR   ] list index out of range
Traceback (most recent call last):
  File "D:\Ina\ETL_XdmLib_2.A.13\ETL_XdmLib_2.A.13\EDAETL\ETL_TABLE\ETL_FT_SD_TO_XSIFF\ETL_FT_SD_TO_XSIFF.py", line 207, in do_file
    FtLot = temp_value.split(' ')[1][:9]
IndexError: list index out of range
Stack (most recent call last):
  File "D:\Ina\ETL_XdmLib_2.A.13\ETL_XdmLib_2.A.13\EDAETL\ETL_TABLE\ETL_FT_SD_TO_XSIFF\ETL_FT_SD_TO_XSIFF.py", line 550, in <module>
    XdmLib.CustomFuction.file2db_init(do_file, before_do_file, after_do_file,
  File "D:\Ina\ETL_XdmLib_2.A.13\ETL_XdmLib_2.A.13\EDAETL\ETL_TABLE\ETL_FT_SD_TO_XSIFF\../..\XdmLib\CustomFuction.py", line 596, in file2db_init
    res = do_file(file_root_source_path,
  File "D:\Ina\ETL_XdmLib_2.A.13\ETL_XdmLib_2.A.13\EDAETL\ETL_TABLE\ETL_FT_SD_TO_XSIFF\ETL_FT_SD_TO_XSIFF.py", line 366, in do_file
    log.error(ex, exc_info=True, stack_info=True)
2023-10-24 16:15:02.801 - ETL_FT_SD_TO_XSIFF [ERROR   ] local variable 'Lot' referenced before assignment
Traceback (most recent call last):
  File "D:\Ina\ETL_XdmLib_2.A.13\ETL_XdmLib_2.A.13\EDAETL\ETL_TABLE\ETL_FT_SD_TO_XSIFF\ETL_FT_SD_TO_XSIFF.py", line 414, in do_file
    'Lot': Lot,
UnboundLocalError: local variable 'Lot' referenced before assignment
Stack (most recent call last):
  File "D:\Ina\ETL_XdmLib_2.A.13\ETL_XdmLib_2.A.13\EDAETL\ETL_TABLE\ETL_FT_SD_TO_XSIFF\ETL_FT_SD_TO_XSIFF.py", line 550, in <module>
    XdmLib.CustomFuction.file2db_init(do_file, before_do_file, after_do_file,
  File "D:\Ina\ETL_XdmLib_2.A.13\ETL_XdmLib_2.A.13\EDAETL\ETL_TABLE\ETL_FT_SD_TO_XSIFF\../..\XdmLib\CustomFuction.py", line 596, in file2db_init
    res = do_file(file_root_source_path,
  File "D:\Ina\ETL_XdmLib_2.A.13\ETL_XdmLib_2.A.13\EDAETL\ETL_TABLE\ETL_FT_SD_TO_XSIFF\ETL_FT_SD_TO_XSIFF.py", line 455, in do_file
    log.error(ex, exc_info=True, stack_info=True)
2023-10-24 16:15:02.803 - ETL_FT_SD_TO_XSIFF [ERROR   ] local variable 'bin_def_df' referenced before assignment
Traceback (most recent call last):
  File "D:\Ina\ETL_XdmLib_2.A.13\ETL_XdmLib_2.A.13\EDAETL\ETL_TABLE\ETL_FT_SD_TO_XSIFF\ETL_FT_SD_TO_XSIFF.py", line 466, in do_file
    bin_def_df = pd.DataFrame(data=bin_def_df, dtype=object)
UnboundLocalError: local variable 'bin_def_df' referenced before assignment
Stack (most recent call last):
  File "D:\Ina\ETL_XdmLib_2.A.13\ETL_XdmLib_2.A.13\EDAETL\ETL_TABLE\ETL_FT_SD_TO_XSIFF\ETL_FT_SD_TO_XSIFF.py", line 550, in <module>
    XdmLib.CustomFuction.file2db_init(do_file, before_do_file, after_do_file,
  File "D:\Ina\ETL_XdmLib_2.A.13\ETL_XdmLib_2.A.13\EDAETL\ETL_TABLE\ETL_FT_SD_TO_XSIFF\../..\XdmLib\CustomFuction.py", line 596, in file2db_init
    res = do_file(file_root_source_path,
  File "D:\Ina\ETL_XdmLib_2.A.13\ETL_XdmLib_2.A.13\EDAETL\ETL_TABLE\ETL_FT_SD_TO_XSIFF\ETL_FT_SD_TO_XSIFF.py", line 489, in do_file
    log.error(ex, exc_info=True, stack_info=True)
2023-10-24 16:15:02.804 - CustomFuction [ERROR   ] local variable 'xsiff_file_name' referenced before assignment
Traceback (most recent call last):
  File "D:\Ina\ETL_XdmLib_2.A.13\ETL_XdmLib_2.A.13\EDAETL\ETL_TABLE\ETL_FT_SD_TO_XSIFF\../..\XdmLib\CustomFuction.py", line 596, in file2db_init
    res = do_file(file_root_source_path,
  File "D:\Ina\ETL_XdmLib_2.A.13\ETL_XdmLib_2.A.13\EDAETL\ETL_TABLE\ETL_FT_SD_TO_XSIFF\ETL_FT_SD_TO_XSIFF.py", line 496, in do_file
    log.info(f'Converter {file_name} to {xsiff_file_name} ;Total Used:{te_t - ts_t}')
UnboundLocalError: local variable 'xsiff_file_name' referenced before assignment
Stack (most recent call last):
  File "D:\Ina\ETL_XdmLib_2.A.13\ETL_XdmLib_2.A.13\EDAETL\ETL_TABLE\ETL_FT_SD_TO_XSIFF\ETL_FT_SD_TO_XSIFF.py", line 550, in <module>
    XdmLib.CustomFuction.file2db_init(do_file, before_do_file, after_do_file,
  File "D:\Ina\ETL_XdmLib_2.A.13\ETL_XdmLib_2.A.13\EDAETL\ETL_TABLE\ETL_FT_SD_TO_XSIFF\../..\XdmLib\CustomFuction.py", line 631, in file2db_init
    log.error(ex, exc_info=True, stack_info=True)
2023-10-24 16:17:51.976 - ETL_FT_SD_TO_XSIFF [ERROR   ] list index out of range
Traceback (most recent call last):
  File "D:\Ina\ETL_XdmLib_2.A.13\ETL_XdmLib_2.A.13\EDAETL\ETL_TABLE\ETL_FT_SD_TO_XSIFF\ETL_FT_SD_TO_XSIFF.py", line 207, in do_file
    FtLot = temp_value.split(' ')[1][:9]
IndexError: list index out of range
Stack (most recent call last):
  File "D:\Ina\ETL_XdmLib_2.A.13\ETL_XdmLib_2.A.13\EDAETL\ETL_TABLE\ETL_FT_SD_TO_XSIFF\ETL_FT_SD_TO_XSIFF.py", line 550, in <module>
    XdmLib.CustomFuction.file2db_init(do_file, before_do_file, after_do_file,
  File "D:\Ina\ETL_XdmLib_2.A.13\ETL_XdmLib_2.A.13\EDAETL\ETL_TABLE\ETL_FT_SD_TO_XSIFF\../..\XdmLib\CustomFuction.py", line 596, in file2db_init
    res = do_file(file_root_source_path,
  File "D:\Ina\ETL_XdmLib_2.A.13\ETL_XdmLib_2.A.13\EDAETL\ETL_TABLE\ETL_FT_SD_TO_XSIFF\ETL_FT_SD_TO_XSIFF.py", line 366, in do_file
    log.error(ex, exc_info=True, stack_info=True)
2023-10-24 16:17:51.978 - ETL_FT_SD_TO_XSIFF [ERROR   ] local variable 'Lot' referenced before assignment
Traceback (most recent call last):
  File "D:\Ina\ETL_XdmLib_2.A.13\ETL_XdmLib_2.A.13\EDAETL\ETL_TABLE\ETL_FT_SD_TO_XSIFF\ETL_FT_SD_TO_XSIFF.py", line 414, in do_file
    'Lot': Lot,
UnboundLocalError: local variable 'Lot' referenced before assignment
Stack (most recent call last):
  File "D:\Ina\ETL_XdmLib_2.A.13\ETL_XdmLib_2.A.13\EDAETL\ETL_TABLE\ETL_FT_SD_TO_XSIFF\ETL_FT_SD_TO_XSIFF.py", line 550, in <module>
    XdmLib.CustomFuction.file2db_init(do_file, before_do_file, after_do_file,
  File "D:\Ina\ETL_XdmLib_2.A.13\ETL_XdmLib_2.A.13\EDAETL\ETL_TABLE\ETL_FT_SD_TO_XSIFF\../..\XdmLib\CustomFuction.py", line 596, in file2db_init
    res = do_file(file_root_source_path,
  File "D:\Ina\ETL_XdmLib_2.A.13\ETL_XdmLib_2.A.13\EDAETL\ETL_TABLE\ETL_FT_SD_TO_XSIFF\ETL_FT_SD_TO_XSIFF.py", line 455, in do_file
    log.error(ex, exc_info=True, stack_info=True)
2023-10-24 16:17:51.979 - ETL_FT_SD_TO_XSIFF [ERROR   ] local variable 'bin_def_df' referenced before assignment
Traceback (most recent call last):
  File "D:\Ina\ETL_XdmLib_2.A.13\ETL_XdmLib_2.A.13\EDAETL\ETL_TABLE\ETL_FT_SD_TO_XSIFF\ETL_FT_SD_TO_XSIFF.py", line 466, in do_file
    bin_def_df = pd.DataFrame(data=bin_def_df, dtype=object)
UnboundLocalError: local variable 'bin_def_df' referenced before assignment
Stack (most recent call last):
  File "D:\Ina\ETL_XdmLib_2.A.13\ETL_XdmLib_2.A.13\EDAETL\ETL_TABLE\ETL_FT_SD_TO_XSIFF\ETL_FT_SD_TO_XSIFF.py", line 550, in <module>
    XdmLib.CustomFuction.file2db_init(do_file, before_do_file, after_do_file,
  File "D:\Ina\ETL_XdmLib_2.A.13\ETL_XdmLib_2.A.13\EDAETL\ETL_TABLE\ETL_FT_SD_TO_XSIFF\../..\XdmLib\CustomFuction.py", line 596, in file2db_init
    res = do_file(file_root_source_path,
  File "D:\Ina\ETL_XdmLib_2.A.13\ETL_XdmLib_2.A.13\EDAETL\ETL_TABLE\ETL_FT_SD_TO_XSIFF\ETL_FT_SD_TO_XSIFF.py", line 489, in do_file
    log.error(ex, exc_info=True, stack_info=True)
2023-10-24 16:17:51.980 - CustomFuction [ERROR   ] local variable 'xsiff_file_name' referenced before assignment
Traceback (most recent call last):
  File "D:\Ina\ETL_XdmLib_2.A.13\ETL_XdmLib_2.A.13\EDAETL\ETL_TABLE\ETL_FT_SD_TO_XSIFF\../..\XdmLib\CustomFuction.py", line 596, in file2db_init
    res = do_file(file_root_source_path,
  File "D:\Ina\ETL_XdmLib_2.A.13\ETL_XdmLib_2.A.13\EDAETL\ETL_TABLE\ETL_FT_SD_TO_XSIFF\ETL_FT_SD_TO_XSIFF.py", line 496, in do_file
    log.info(f'Converter {file_name} to {xsiff_file_name} ;Total Used:{te_t - ts_t}')
UnboundLocalError: local variable 'xsiff_file_name' referenced before assignment
Stack (most recent call last):
  File "D:\Ina\ETL_XdmLib_2.A.13\ETL_XdmLib_2.A.13\EDAETL\ETL_TABLE\ETL_FT_SD_TO_XSIFF\ETL_FT_SD_TO_XSIFF.py", line 550, in <module>
    XdmLib.CustomFuction.file2db_init(do_file, before_do_file, after_do_file,
  File "D:\Ina\ETL_XdmLib_2.A.13\ETL_XdmLib_2.A.13\EDAETL\ETL_TABLE\ETL_FT_SD_TO_XSIFF\../..\XdmLib\CustomFuction.py", line 631, in file2db_init
    log.error(ex, exc_info=True, stack_info=True)
2023-10-24 16:23:15.119 - ETL_FT_SD_TO_XSIFF [ERROR   ] list index out of range
Traceback (most recent call last):
  File "D:\Ina\ETL_XdmLib_2.A.13\ETL_XdmLib_2.A.13\EDAETL\ETL_TABLE\ETL_FT_SD_TO_XSIFF\ETL_FT_SD_TO_XSIFF.py", line 207, in do_file
    FtLot = temp_value.split(' ')[1][:9]
IndexError: list index out of range
Stack (most recent call last):
  File "D:\Ina\ETL_XdmLib_2.A.13\ETL_XdmLib_2.A.13\EDAETL\ETL_TABLE\ETL_FT_SD_TO_XSIFF\ETL_FT_SD_TO_XSIFF.py", line 553, in <module>
    XdmLib.CustomFuction.file2db_init(do_file, before_do_file, after_do_file,
  File "D:\Ina\ETL_XdmLib_2.A.13\ETL_XdmLib_2.A.13\EDAETL\ETL_TABLE\ETL_FT_SD_TO_XSIFF\../..\XdmLib\CustomFuction.py", line 596, in file2db_init
    res = do_file(file_root_source_path,
  File "D:\Ina\ETL_XdmLib_2.A.13\ETL_XdmLib_2.A.13\EDAETL\ETL_TABLE\ETL_FT_SD_TO_XSIFF\ETL_FT_SD_TO_XSIFF.py", line 366, in do_file
    log.error(ex, exc_info=True, stack_info=True)
2023-10-24 16:23:23.279 - __init__   [ERROR   ] File:QG35-CW_GD400TAS100L6S.xlsx Move To Error Folder
                                                Error: QG35-CW_GD400TAS100L6S.xlsx
2023-10-24 16:36:51.485 - ETL_FT_SD_TO_XSIFF [ERROR   ] 'Serial no'
Traceback (most recent call last):
  File "D:\soft\anaconda3\lib\site-packages\pandas\core\indexes\base.py", line 3621, in get_loc
    return self._engine.get_loc(casted_key)
  File "pandas\_libs\index.pyx", line 136, in pandas._libs.index.IndexEngine.get_loc
  File "pandas\_libs\index.pyx", line 163, in pandas._libs.index.IndexEngine.get_loc
  File "pandas\_libs\hashtable_class_helper.pxi", line 5198, in pandas._libs.hashtable.PyObjectHashTable.get_item
  File "pandas\_libs\hashtable_class_helper.pxi", line 5206, in pandas._libs.hashtable.PyObjectHashTable.get_item
KeyError: 'Serial no'

The above exception was the direct cause of the following exception:

Traceback (most recent call last):
  File "D:\Ina\ETL_XdmLib_2.A.13\ETL_XdmLib_2.A.13\EDAETL\ETL_TABLE\ETL_FT_SD_TO_XSIFF\ETL_FT_SD_TO_XSIFF.py", line 191, in do_file
    if source_data_df['Serial no'][1:].str.isnumeric().all():
  File "D:\soft\anaconda3\lib\site-packages\pandas\core\frame.py", line 3505, in __getitem__
    indexer = self.columns.get_loc(key)
  File "D:\soft\anaconda3\lib\site-packages\pandas\core\indexes\base.py", line 3623, in get_loc
    raise KeyError(key) from err
KeyError: 'Serial no'
Stack (most recent call last):
  File "D:\Ina\ETL_XdmLib_2.A.13\ETL_XdmLib_2.A.13\EDAETL\ETL_TABLE\ETL_FT_SD_TO_XSIFF\ETL_FT_SD_TO_XSIFF.py", line 559, in <module>
    XdmLib.CustomFuction.file2db_init(do_file, before_do_file, after_do_file,
  File "D:\Ina\ETL_XdmLib_2.A.13\ETL_XdmLib_2.A.13\EDAETL\ETL_TABLE\ETL_FT_SD_TO_XSIFF\../..\XdmLib\CustomFuction.py", line 596, in file2db_init
    res = do_file(file_root_source_path,
  File "D:\Ina\ETL_XdmLib_2.A.13\ETL_XdmLib_2.A.13\EDAETL\ETL_TABLE\ETL_FT_SD_TO_XSIFF\ETL_FT_SD_TO_XSIFF.py", line 372, in do_file
    log.error(ex, exc_info=True, stack_info=True)
2023-10-24 16:36:54.580 - __init__   [ERROR   ] File:QG35-CW_GD400TAS100L6S.xlsx Move To Error Folder
                                                Error: QG35-CW_GD400TAS100L6S.xlsx
2023-10-24 16:36:55.332 - ETL_FT_SD_TO_XSIFF [ERROR   ] 'Serial no'
Traceback (most recent call last):
  File "D:\soft\anaconda3\lib\site-packages\pandas\core\indexes\base.py", line 3621, in get_loc
    return self._engine.get_loc(casted_key)
  File "pandas\_libs\index.pyx", line 136, in pandas._libs.index.IndexEngine.get_loc
  File "pandas\_libs\index.pyx", line 163, in pandas._libs.index.IndexEngine.get_loc
  File "pandas\_libs\hashtable_class_helper.pxi", line 5198, in pandas._libs.hashtable.PyObjectHashTable.get_item
  File "pandas\_libs\hashtable_class_helper.pxi", line 5206, in pandas._libs.hashtable.PyObjectHashTable.get_item
KeyError: 'Serial no'

The above exception was the direct cause of the following exception:

Traceback (most recent call last):
  File "D:\Ina\ETL_XdmLib_2.A.13\ETL_XdmLib_2.A.13\EDAETL\ETL_TABLE\ETL_FT_SD_TO_XSIFF\ETL_FT_SD_TO_XSIFF.py", line 191, in do_file
    if source_data_df['Serial no'][1:].str.isnumeric().all():
  File "D:\soft\anaconda3\lib\site-packages\pandas\core\frame.py", line 3505, in __getitem__
    indexer = self.columns.get_loc(key)
  File "D:\soft\anaconda3\lib\site-packages\pandas\core\indexes\base.py", line 3623, in get_loc
    raise KeyError(key) from err
KeyError: 'Serial no'
Stack (most recent call last):
  File "D:\Ina\ETL_XdmLib_2.A.13\ETL_XdmLib_2.A.13\EDAETL\ETL_TABLE\ETL_FT_SD_TO_XSIFF\ETL_FT_SD_TO_XSIFF.py", line 559, in <module>
    XdmLib.CustomFuction.file2db_init(do_file, before_do_file, after_do_file,
  File "D:\Ina\ETL_XdmLib_2.A.13\ETL_XdmLib_2.A.13\EDAETL\ETL_TABLE\ETL_FT_SD_TO_XSIFF\../..\XdmLib\CustomFuction.py", line 596, in file2db_init
    res = do_file(file_root_source_path,
  File "D:\Ina\ETL_XdmLib_2.A.13\ETL_XdmLib_2.A.13\EDAETL\ETL_TABLE\ETL_FT_SD_TO_XSIFF\ETL_FT_SD_TO_XSIFF.py", line 372, in do_file
    log.error(ex, exc_info=True, stack_info=True)
2023-10-24 16:36:58.379 - __init__   [ERROR   ] File:XWECYQH20-CW_GD600MLS100L6S.xlsx Move To Error Folder
                                                Error: XWECYQH20-CW_GD600MLS100L6S.xlsx
2023-10-24 16:36:59.028 - ETL_FT_SD_TO_XSIFF [ERROR   ] 'Serial no'
Traceback (most recent call last):
  File "D:\soft\anaconda3\lib\site-packages\pandas\core\indexes\base.py", line 3621, in get_loc
    return self._engine.get_loc(casted_key)
  File "pandas\_libs\index.pyx", line 136, in pandas._libs.index.IndexEngine.get_loc
  File "pandas\_libs\index.pyx", line 163, in pandas._libs.index.IndexEngine.get_loc
  File "pandas\_libs\hashtable_class_helper.pxi", line 5198, in pandas._libs.hashtable.PyObjectHashTable.get_item
  File "pandas\_libs\hashtable_class_helper.pxi", line 5206, in pandas._libs.hashtable.PyObjectHashTable.get_item
KeyError: 'Serial no'

The above exception was the direct cause of the following exception:

Traceback (most recent call last):
  File "D:\Ina\ETL_XdmLib_2.A.13\ETL_XdmLib_2.A.13\EDAETL\ETL_TABLE\ETL_FT_SD_TO_XSIFF\ETL_FT_SD_TO_XSIFF.py", line 191, in do_file
    if source_data_df['Serial no'][1:].str.isnumeric().all():
  File "D:\soft\anaconda3\lib\site-packages\pandas\core\frame.py", line 3505, in __getitem__
    indexer = self.columns.get_loc(key)
  File "D:\soft\anaconda3\lib\site-packages\pandas\core\indexes\base.py", line 3623, in get_loc
    raise KeyError(key) from err
KeyError: 'Serial no'
Stack (most recent call last):
  File "D:\Ina\ETL_XdmLib_2.A.13\ETL_XdmLib_2.A.13\EDAETL\ETL_TABLE\ETL_FT_SD_TO_XSIFF\ETL_FT_SD_TO_XSIFF.py", line 559, in <module>
    XdmLib.CustomFuction.file2db_init(do_file, before_do_file, after_do_file,
  File "D:\Ina\ETL_XdmLib_2.A.13\ETL_XdmLib_2.A.13\EDAETL\ETL_TABLE\ETL_FT_SD_TO_XSIFF\../..\XdmLib\CustomFuction.py", line 596, in file2db_init
    res = do_file(file_root_source_path,
  File "D:\Ina\ETL_XdmLib_2.A.13\ETL_XdmLib_2.A.13\EDAETL\ETL_TABLE\ETL_FT_SD_TO_XSIFF\ETL_FT_SD_TO_XSIFF.py", line 372, in do_file
    log.error(ex, exc_info=True, stack_info=True)
2023-10-24 16:37:02.051 - __init__   [ERROR   ] File:XWECYQH62-GW_GD600MLS100L6S-GW.xlsx Move To Error Folder
                                                Error: XWECYQH62-GW_GD600MLS100L6S-GW.xlsx
2023-10-24 16:37:44.451 - __init__   [ERROR   ] File:QG35-CW_GD400TAS100L6S.xlsx Move To Error Folder
                                                Error: None
2023-10-24 16:44:33.171 - __init__   [ERROR   ] File:QG35-CW_GD400TAS100L6S.xlsx Move To Error Folder
                                                Error: None
2023-10-24 16:49:04.398 - __init__   [ERROR   ] File:QG35-CW_GD400TAS100L6S.xlsx Move To Error Folder
                                                Error: None
2023-10-24 16:52:12.796 - __init__   [ERROR   ] File:QG35-CW_GD400TAS100L6S.xlsx Move To Error Folder
                                                Error: None
2023-10-24 17:04:47.373 - __init__   [ERROR   ] File:QG35-CW_GD400TAS100L6S.xlsx Move To Error Folder
                                                Error: None
2023-10-24 17:07:26.649 - __init__   [ERROR   ] File:QG35-CW_GD400TAS100L6S.xlsx Move To Error Folder
                                                Error: None
2023-10-24 17:37:34.437 - __init__   [ERROR   ] File:QG35-CW_GD400TAS100L6S.xlsx Move To Error Folder
                                                Error: None
2023-10-24 18:06:37.181 - __init__   [ERROR   ] Check CustomFuction.pyc SHA256 Failed
2023-10-24 18:12:16.582 - __init__   [ERROR   ] Check CustomFuction.pyc SHA256 Failed
2023-10-24 18:13:19.494 - __init__   [ERROR   ] Check CustomFuction.pyc SHA256 Failed
2023-10-24 18:14:00.421 - __init__   [ERROR   ] Check CustomFuction.pyc SHA256 Failed
2023-10-24 18:14:23.114 - __init__   [ERROR   ] Check CustomFuction.pyc SHA256 Failed
