2023-12-19 14:38:26.068 - CustomFuction [ERROR   ] 'data'
Traceback (most recent call last):
  File "D:\Python37\lib\site-packages\pandas\core\indexes\base.py", line 2898, in get_loc
    return self._engine.get_loc(casted_key)
  File "pandas\_libs\index.pyx", line 70, in pandas._libs.index.IndexEngine.get_loc
  File "pandas\_libs\index.pyx", line 101, in pandas._libs.index.IndexEngine.get_loc
  File "pandas\_libs\hashtable_class_helper.pxi", line 1675, in pandas._libs.hashtable.PyObjectHashTable.get_item
  File "pandas\_libs\hashtable_class_helper.pxi", line 1683, in pandas._libs.hashtable.PyObjectHashTable.get_item
KeyError: 'data'

The above exception was the direct cause of the following exception:

Traceback (most recent call last):
  File "../..\XdmLib\CustomFuction.py", line 598, in file2db_init
    analysis_res.append(res['data'])
  File "D:\Python37\lib\site-packages\pandas\core\frame.py", line 2906, in __getitem__
    indexer = self.columns.get_loc(key)
  File "D:\Python37\lib\site-packages\pandas\core\indexes\base.py", line 2900, in get_loc
    raise KeyError(key) from err
KeyError: 'data'
Stack (most recent call last):
  File "D:/Ina/ETL_XdmLib_2.A.13/ETL_XdmLib_2.A.13/EDAETL/ETL_TABLE/ETL_FT_SD_TO_XSIFF/ETL_FT_SD_TO_XSIFF.py", line 514, in <module>
    skip_file, None, log, config, config_sql)
  File "../..\XdmLib\CustomFuction.py", line 631, in file2db_init
    log.error(ex, exc_info=True, stack_info=True)
2023-12-19 14:38:27.144 - CustomFuction [ERROR   ] 'data'
Traceback (most recent call last):
  File "D:\Python37\lib\site-packages\pandas\core\indexes\base.py", line 2898, in get_loc
    return self._engine.get_loc(casted_key)
  File "pandas\_libs\index.pyx", line 70, in pandas._libs.index.IndexEngine.get_loc
  File "pandas\_libs\index.pyx", line 101, in pandas._libs.index.IndexEngine.get_loc
  File "pandas\_libs\hashtable_class_helper.pxi", line 1675, in pandas._libs.hashtable.PyObjectHashTable.get_item
  File "pandas\_libs\hashtable_class_helper.pxi", line 1683, in pandas._libs.hashtable.PyObjectHashTable.get_item
KeyError: 'data'

The above exception was the direct cause of the following exception:

Traceback (most recent call last):
  File "../..\XdmLib\CustomFuction.py", line 598, in file2db_init
    analysis_res.append(res['data'])
  File "D:\Python37\lib\site-packages\pandas\core\frame.py", line 2906, in __getitem__
    indexer = self.columns.get_loc(key)
  File "D:\Python37\lib\site-packages\pandas\core\indexes\base.py", line 2900, in get_loc
    raise KeyError(key) from err
KeyError: 'data'
Stack (most recent call last):
  File "D:/Ina/ETL_XdmLib_2.A.13/ETL_XdmLib_2.A.13/EDAETL/ETL_TABLE/ETL_FT_SD_TO_XSIFF/ETL_FT_SD_TO_XSIFF.py", line 514, in <module>
    skip_file, None, log, config, config_sql)
  File "../..\XdmLib\CustomFuction.py", line 631, in file2db_init
    log.error(ex, exc_info=True, stack_info=True)
2023-12-19 14:38:27.933 - CustomFuction [ERROR   ] 'data'
Traceback (most recent call last):
  File "D:\Python37\lib\site-packages\pandas\core\indexes\base.py", line 2898, in get_loc
    return self._engine.get_loc(casted_key)
  File "pandas\_libs\index.pyx", line 70, in pandas._libs.index.IndexEngine.get_loc
  File "pandas\_libs\index.pyx", line 101, in pandas._libs.index.IndexEngine.get_loc
  File "pandas\_libs\hashtable_class_helper.pxi", line 1675, in pandas._libs.hashtable.PyObjectHashTable.get_item
  File "pandas\_libs\hashtable_class_helper.pxi", line 1683, in pandas._libs.hashtable.PyObjectHashTable.get_item
KeyError: 'data'

The above exception was the direct cause of the following exception:

Traceback (most recent call last):
  File "../..\XdmLib\CustomFuction.py", line 598, in file2db_init
    analysis_res.append(res['data'])
  File "D:\Python37\lib\site-packages\pandas\core\frame.py", line 2906, in __getitem__
    indexer = self.columns.get_loc(key)
  File "D:\Python37\lib\site-packages\pandas\core\indexes\base.py", line 2900, in get_loc
    raise KeyError(key) from err
KeyError: 'data'
Stack (most recent call last):
  File "D:/Ina/ETL_XdmLib_2.A.13/ETL_XdmLib_2.A.13/EDAETL/ETL_TABLE/ETL_FT_SD_TO_XSIFF/ETL_FT_SD_TO_XSIFF.py", line 514, in <module>
    skip_file, None, log, config, config_sql)
  File "../..\XdmLib\CustomFuction.py", line 631, in file2db_init
    log.error(ex, exc_info=True, stack_info=True)
2023-12-19 14:56:48.106 - CustomFuction [ERROR   ] 'data'
Traceback (most recent call last):
  File "D:\Python37\lib\site-packages\pandas\core\indexes\base.py", line 2898, in get_loc
    return self._engine.get_loc(casted_key)
  File "pandas\_libs\index.pyx", line 70, in pandas._libs.index.IndexEngine.get_loc
  File "pandas\_libs\index.pyx", line 101, in pandas._libs.index.IndexEngine.get_loc
  File "pandas\_libs\hashtable_class_helper.pxi", line 1675, in pandas._libs.hashtable.PyObjectHashTable.get_item
  File "pandas\_libs\hashtable_class_helper.pxi", line 1683, in pandas._libs.hashtable.PyObjectHashTable.get_item
KeyError: 'data'

The above exception was the direct cause of the following exception:

Traceback (most recent call last):
  File "../..\XdmLib\CustomFuction.py", line 598, in file2db_init
    analysis_res.append(res['data'])
  File "D:\Python37\lib\site-packages\pandas\core\frame.py", line 2906, in __getitem__
    indexer = self.columns.get_loc(key)
  File "D:\Python37\lib\site-packages\pandas\core\indexes\base.py", line 2900, in get_loc
    raise KeyError(key) from err
KeyError: 'data'
Stack (most recent call last):
  File "D:/Ina/ETL_XdmLib_2.A.13/ETL_XdmLib_2.A.13/EDAETL/ETL_TABLE/ETL_FT_SD_TO_XSIFF/ETL_FT_SD_TO_XSIFF.py", line 505, in <module>
    skip_file, None, log, config, config_sql)
  File "../..\XdmLib\CustomFuction.py", line 631, in file2db_init
    log.error(ex, exc_info=True, stack_info=True)
2023-12-19 14:56:48.853 - CustomFuction [ERROR   ] 'data'
Traceback (most recent call last):
  File "D:\Python37\lib\site-packages\pandas\core\indexes\base.py", line 2898, in get_loc
    return self._engine.get_loc(casted_key)
  File "pandas\_libs\index.pyx", line 70, in pandas._libs.index.IndexEngine.get_loc
  File "pandas\_libs\index.pyx", line 101, in pandas._libs.index.IndexEngine.get_loc
  File "pandas\_libs\hashtable_class_helper.pxi", line 1675, in pandas._libs.hashtable.PyObjectHashTable.get_item
  File "pandas\_libs\hashtable_class_helper.pxi", line 1683, in pandas._libs.hashtable.PyObjectHashTable.get_item
KeyError: 'data'

The above exception was the direct cause of the following exception:

Traceback (most recent call last):
  File "../..\XdmLib\CustomFuction.py", line 598, in file2db_init
    analysis_res.append(res['data'])
  File "D:\Python37\lib\site-packages\pandas\core\frame.py", line 2906, in __getitem__
    indexer = self.columns.get_loc(key)
  File "D:\Python37\lib\site-packages\pandas\core\indexes\base.py", line 2900, in get_loc
    raise KeyError(key) from err
KeyError: 'data'
Stack (most recent call last):
  File "D:/Ina/ETL_XdmLib_2.A.13/ETL_XdmLib_2.A.13/EDAETL/ETL_TABLE/ETL_FT_SD_TO_XSIFF/ETL_FT_SD_TO_XSIFF.py", line 505, in <module>
    skip_file, None, log, config, config_sql)
  File "../..\XdmLib\CustomFuction.py", line 631, in file2db_init
    log.error(ex, exc_info=True, stack_info=True)
2023-12-19 15:08:22.405 - ETL_FT_SD_TO_XSIFF [ERROR   ] Missing valid table header:Index([], dtype='object')
2023-12-19 15:08:22.610 - __init__   [ERROR   ] File:XWECYQH20-CW_GD600MLS100L6S_缺Test_no.测试.xlsx Move To Error Folder
                                                Error: None
2023-12-19 15:11:05.729 - ETL_FT_SD_TO_XSIFF [ERROR   ] [Serial no.] This column is numeric only.
2023-12-19 15:11:05.905 - __init__   [ERROR   ] File:QG35-CW_GD400TAS100L6S.xlsx Move To Error Folder
                                                Error: None
2023-12-19 15:11:07.664 - ETL_FT_SD_TO_XSIFF [ERROR   ] Missing valid table header:Index([], dtype='object')
2023-12-19 15:11:07.833 - __init__   [ERROR   ] File:XWECYQH20-CW_GD600MLS100L6S_缺Test_no.测试.xlsx Move To Error Folder
                                                Error: None
2023-12-19 16:26:29.262 - ETL_FT_SD_TO_XSIFF [ERROR   ] local variable 'filtered_df' referenced before assignment
Traceback (most recent call last):
  File "D:/Ina/ETL_XdmLib_2.A.13/ETL_XdmLib_2.A.13/EDAETL/ETL_TABLE/ETL_FT_SD_TO_XSIFF/ETL_FT_SD_TO_XSIFF.py", line 212, in do_file
    filtered_df.loc[:, 'Test Date.'] = filtered_df['Test Date.'].str.replace('上午', 'AM')
UnboundLocalError: local variable 'filtered_df' referenced before assignment
Stack (most recent call last):
  File "D:/Ina/ETL_XdmLib_2.A.13/ETL_XdmLib_2.A.13/EDAETL/ETL_TABLE/ETL_FT_SD_TO_XSIFF/ETL_FT_SD_TO_XSIFF.py", line 537, in <module>
    skip_file, None, log, config, config_sql)
  File "../..\XdmLib\CustomFuction.py", line 597, in file2db_init
    file, pre_params, db_src, db_tgt)
  File "D:/Ina/ETL_XdmLib_2.A.13/ETL_XdmLib_2.A.13/EDAETL/ETL_TABLE/ETL_FT_SD_TO_XSIFF/ETL_FT_SD_TO_XSIFF.py", line 362, in do_file
    log.error(ex, exc_info=True, stack_info=True)
2023-12-19 16:26:29.449 - __init__   [ERROR   ] File:XWECZS889-GW_新阳光GD600MLS100L6S-GW.xlsx Move To Error Folder
                                                Error: None
2023-12-19 16:28:40.651 - ETL_FT_SD_TO_XSIFF [ERROR   ] time data '2023-11-04 20:35:20' does not match format '%m/%d/%Y %I:%M:%S %p' (match)
Traceback (most recent call last):
  File "D:\Python37\lib\site-packages\pandas\core\tools\datetimes.py", line 450, in _convert_listlike_datetimes
    values, tz = conversion.datetime_to_datetime64(arg)
  File "pandas\_libs\tslibs\conversion.pyx", line 350, in pandas._libs.tslibs.conversion.datetime_to_datetime64
TypeError: Unrecognized value type: <class 'str'>

During handling of the above exception, another exception occurred:

Traceback (most recent call last):
  File "D:/Ina/ETL_XdmLib_2.A.13/ETL_XdmLib_2.A.13/EDAETL/ETL_TABLE/ETL_FT_SD_TO_XSIFF/ETL_FT_SD_TO_XSIFF.py", line 220, in do_file
    filtered_df['Test Date.'] = pd.to_datetime(filtered_df['Test Date.'], format='%m/%d/%Y %I:%M:%S %p')
  File "D:\Python37\lib\site-packages\pandas\core\tools\datetimes.py", line 803, in to_datetime
    values = convert_listlike(arg._values, format)
  File "D:\Python37\lib\site-packages\pandas\core\tools\datetimes.py", line 454, in _convert_listlike_datetimes
    raise e
  File "D:\Python37\lib\site-packages\pandas\core\tools\datetimes.py", line 418, in _convert_listlike_datetimes
    arg, format, exact=exact, errors=errors
  File "pandas\_libs\tslibs\strptime.pyx", line 144, in pandas._libs.tslibs.strptime.array_strptime
ValueError: time data '2023-11-04 20:35:20' does not match format '%m/%d/%Y %I:%M:%S %p' (match)
Stack (most recent call last):
  File "D:/Ina/ETL_XdmLib_2.A.13/ETL_XdmLib_2.A.13/EDAETL/ETL_TABLE/ETL_FT_SD_TO_XSIFF/ETL_FT_SD_TO_XSIFF.py", line 537, in <module>
    skip_file, None, log, config, config_sql)
  File "../..\XdmLib\CustomFuction.py", line 597, in file2db_init
    file, pre_params, db_src, db_tgt)
  File "D:/Ina/ETL_XdmLib_2.A.13/ETL_XdmLib_2.A.13/EDAETL/ETL_TABLE/ETL_FT_SD_TO_XSIFF/ETL_FT_SD_TO_XSIFF.py", line 362, in do_file
    log.error(ex, exc_info=True, stack_info=True)
2023-12-19 16:28:40.793 - __init__   [ERROR   ] File:XWECZS889-GW_新阳光GD600MLS100L6S-GW.xlsx Move To Error Folder
                                                Error: None
2023-12-19 16:37:06.052 - ETL_FT_SD_TO_XSIFF [ERROR   ] time data '2023-11-04 20:35:20' does not match format '%m/%d/%Y %I:%M:%S %p' (match)
Traceback (most recent call last):
  File "D:\Python37\lib\site-packages\pandas\core\tools\datetimes.py", line 450, in _convert_listlike_datetimes
    values, tz = conversion.datetime_to_datetime64(arg)
  File "pandas\_libs\tslibs\conversion.pyx", line 350, in pandas._libs.tslibs.conversion.datetime_to_datetime64
TypeError: Unrecognized value type: <class 'str'>

During handling of the above exception, another exception occurred:

Traceback (most recent call last):
  File "D:/Ina/ETL_XdmLib_2.A.13/ETL_XdmLib_2.A.13/EDAETL/ETL_TABLE/ETL_FT_SD_TO_XSIFF/ETL_FT_SD_TO_XSIFF.py", line 220, in do_file
    filtered_df['Test Date.'] = pd.to_datetime(filtered_df['Test Date.'], format='%m/%d/%Y %I:%M:%S %p')
  File "D:\Python37\lib\site-packages\pandas\core\tools\datetimes.py", line 803, in to_datetime
    values = convert_listlike(arg._values, format)
  File "D:\Python37\lib\site-packages\pandas\core\tools\datetimes.py", line 454, in _convert_listlike_datetimes
    raise e
  File "D:\Python37\lib\site-packages\pandas\core\tools\datetimes.py", line 418, in _convert_listlike_datetimes
    arg, format, exact=exact, errors=errors
  File "pandas\_libs\tslibs\strptime.pyx", line 144, in pandas._libs.tslibs.strptime.array_strptime
ValueError: time data '2023-11-04 20:35:20' does not match format '%m/%d/%Y %I:%M:%S %p' (match)
Stack (most recent call last):
  File "D:/Ina/ETL_XdmLib_2.A.13/ETL_XdmLib_2.A.13/EDAETL/ETL_TABLE/ETL_FT_SD_TO_XSIFF/ETL_FT_SD_TO_XSIFF.py", line 537, in <module>
    skip_file, None, log, config, config_sql)
  File "../..\XdmLib\CustomFuction.py", line 597, in file2db_init
    file, pre_params, db_src, db_tgt)
  File "D:/Ina/ETL_XdmLib_2.A.13/ETL_XdmLib_2.A.13/EDAETL/ETL_TABLE/ETL_FT_SD_TO_XSIFF/ETL_FT_SD_TO_XSIFF.py", line 362, in do_file
    log.error(ex, exc_info=True, stack_info=True)
2023-12-19 16:37:06.306 - __init__   [ERROR   ] File:XWECZS889-GW_新阳光GD600MLS100L6S-GW.xlsx Move To Error Folder
                                                Error: None
2023-12-19 16:38:09.980 - ETL_FT_SD_TO_XSIFF [ERROR   ] name 'smin_time' is not defined
Traceback (most recent call last):
  File "D:/Ina/ETL_XdmLib_2.A.13/ETL_XdmLib_2.A.13/EDAETL/ETL_TABLE/ETL_FT_SD_TO_XSIFF/ETL_FT_SD_TO_XSIFF.py", line 207, in do_file
    StartTime = smin_time
NameError: name 'smin_time' is not defined
Stack (most recent call last):
  File "D:/Ina/ETL_XdmLib_2.A.13/ETL_XdmLib_2.A.13/EDAETL/ETL_TABLE/ETL_FT_SD_TO_XSIFF/ETL_FT_SD_TO_XSIFF.py", line 537, in <module>
    skip_file, None, log, config, config_sql)
  File "../..\XdmLib\CustomFuction.py", line 597, in file2db_init
    file, pre_params, db_src, db_tgt)
  File "D:/Ina/ETL_XdmLib_2.A.13/ETL_XdmLib_2.A.13/EDAETL/ETL_TABLE/ETL_FT_SD_TO_XSIFF/ETL_FT_SD_TO_XSIFF.py", line 362, in do_file
    log.error(ex, exc_info=True, stack_info=True)
2023-12-19 16:38:10.142 - __init__   [ERROR   ] File:XWECZS889-GW_新阳光GD600MLS100L6S-GW.xlsx Move To Error Folder
                                                Error: None
2023-12-19 16:38:38.606 - ETL_FT_SD_TO_XSIFF [ERROR   ] 'NO LEG'
Traceback (most recent call last):
  File "D:\Python37\lib\site-packages\pandas\core\indexes\base.py", line 2898, in get_loc
    return self._engine.get_loc(casted_key)
  File "pandas\_libs\index.pyx", line 70, in pandas._libs.index.IndexEngine.get_loc
  File "pandas\_libs\index.pyx", line 101, in pandas._libs.index.IndexEngine.get_loc
  File "pandas\_libs\hashtable_class_helper.pxi", line 1675, in pandas._libs.hashtable.PyObjectHashTable.get_item
  File "pandas\_libs\hashtable_class_helper.pxi", line 1683, in pandas._libs.hashtable.PyObjectHashTable.get_item
KeyError: 'NO LEG'

The above exception was the direct cause of the following exception:

Traceback (most recent call last):
  File "D:/Ina/ETL_XdmLib_2.A.13/ETL_XdmLib_2.A.13/EDAETL/ETL_TABLE/ETL_FT_SD_TO_XSIFF/ETL_FT_SD_TO_XSIFF.py", line 258, in do_file
    bin_desc = row['Pass/Fail'] + '-' + row['NO LEG']
  File "D:\Python37\lib\site-packages\pandas\core\series.py", line 882, in __getitem__
    return self._get_value(key)
  File "D:\Python37\lib\site-packages\pandas\core\series.py", line 990, in _get_value
    loc = self.index.get_loc(label)
  File "D:\Python37\lib\site-packages\pandas\core\indexes\base.py", line 2900, in get_loc
    raise KeyError(key) from err
KeyError: 'NO LEG'
Stack (most recent call last):
  File "D:/Ina/ETL_XdmLib_2.A.13/ETL_XdmLib_2.A.13/EDAETL/ETL_TABLE/ETL_FT_SD_TO_XSIFF/ETL_FT_SD_TO_XSIFF.py", line 537, in <module>
    skip_file, None, log, config, config_sql)
  File "../..\XdmLib\CustomFuction.py", line 597, in file2db_init
    file, pre_params, db_src, db_tgt)
  File "D:/Ina/ETL_XdmLib_2.A.13/ETL_XdmLib_2.A.13/EDAETL/ETL_TABLE/ETL_FT_SD_TO_XSIFF/ETL_FT_SD_TO_XSIFF.py", line 362, in do_file
    log.error(ex, exc_info=True, stack_info=True)
2023-12-19 16:38:38.763 - __init__   [ERROR   ] File:XWECZS889-GW_新阳光GD600MLS100L6S-GW.xlsx Move To Error Folder
                                                Error: None
2023-12-19 16:43:46.945 - ETL_FT_SD_TO_XSIFF [ERROR   ] unhashable type: 'Index'
Traceback (most recent call last):
  File "D:/Ina/ETL_XdmLib_2.A.13/ETL_XdmLib_2.A.13/EDAETL/ETL_TABLE/ETL_FT_SD_TO_XSIFF/ETL_FT_SD_TO_XSIFF.py", line 261, in do_file
    if not bin_disc_dict.get(bin_desc):
  File "D:\Python37\lib\site-packages\pandas\core\indexes\base.py", line 4081, in __hash__
    raise TypeError(f"unhashable type: {repr(type(self).__name__)}")
TypeError: unhashable type: 'Index'
Stack (most recent call last):
  File "D:\soft\PyCharm Community Edition 2022.1.3\plugins\python-ce\helpers\pydev\pydevd.py", line 2181, in <module>
    main()
  File "D:\soft\PyCharm Community Edition 2022.1.3\plugins\python-ce\helpers\pydev\pydevd.py", line 2172, in main
    globals = debugger.run(setup['file'], None, None, is_module)
  File "D:\soft\PyCharm Community Edition 2022.1.3\plugins\python-ce\helpers\pydev\pydevd.py", line 1484, in run
    return self._exec(is_module, entry_point_fn, module_name, file, globals, locals)
  File "D:\soft\PyCharm Community Edition 2022.1.3\plugins\python-ce\helpers\pydev\pydevd.py", line 1491, in _exec
    pydev_imports.execfile(file, globals, locals)  # execute the script
  File "D:\soft\PyCharm Community Edition 2022.1.3\plugins\python-ce\helpers\pydev\_pydev_imps\_pydev_execfile.py", line 18, in execfile
    exec(compile(contents+"\n", file, 'exec'), glob, loc)
  File "D:/Ina/ETL_XdmLib_2.A.13/ETL_XdmLib_2.A.13/EDAETL/ETL_TABLE/ETL_FT_SD_TO_XSIFF/ETL_FT_SD_TO_XSIFF.py", line 538, in <module>
    skip_file, None, log, config, config_sql)
  File "../..\XdmLib\CustomFuction.py", line 597, in file2db_init
    file, pre_params, db_src, db_tgt)
  File "D:/Ina/ETL_XdmLib_2.A.13/ETL_XdmLib_2.A.13/EDAETL/ETL_TABLE/ETL_FT_SD_TO_XSIFF/ETL_FT_SD_TO_XSIFF.py", line 363, in do_file
    log.error(ex, exc_info=True, stack_info=True)
2023-12-19 16:43:47.203 - __init__   [ERROR   ] File:XWECZS889-GW_新阳光GD600MLS100L6S-GW.xlsx Move To Error Folder
                                                Error: None
2023-12-19 17:02:49.003 - ETL_FT_SD_TO_XSIFF [ERROR   ] [Serial no.] This column is numeric only.
2023-12-19 17:02:49.172 - __init__   [ERROR   ] File:QG35-CW_GD400TAS100L6S.xlsx Move To Error Folder
                                                Error: None
2023-12-19 17:02:49.441 - ETL_FT_SD_TO_XSIFF [ERROR   ] 'Test Date.'
Traceback (most recent call last):
  File "D:\Python37\lib\site-packages\pandas\core\indexes\base.py", line 2898, in get_loc
    return self._engine.get_loc(casted_key)
  File "pandas\_libs\index.pyx", line 70, in pandas._libs.index.IndexEngine.get_loc
  File "pandas\_libs\index.pyx", line 101, in pandas._libs.index.IndexEngine.get_loc
  File "pandas\_libs\hashtable_class_helper.pxi", line 1675, in pandas._libs.hashtable.PyObjectHashTable.get_item
  File "pandas\_libs\hashtable_class_helper.pxi", line 1683, in pandas._libs.hashtable.PyObjectHashTable.get_item
KeyError: 'Test Date.'

The above exception was the direct cause of the following exception:

Traceback (most recent call last):
  File "D:/Ina/ETL_XdmLib_2.A.13/ETL_XdmLib_2.A.13/EDAETL/ETL_TABLE/ETL_FT_SD_TO_XSIFF/ETL_FT_SD_TO_XSIFF.py", line 170, in do_file
    filtered_dfA = source_data_df[source_data_df['Test Date.'] != '.']
  File "D:\Python37\lib\site-packages\pandas\core\frame.py", line 2906, in __getitem__
    indexer = self.columns.get_loc(key)
  File "D:\Python37\lib\site-packages\pandas\core\indexes\base.py", line 2900, in get_loc
    raise KeyError(key) from err
KeyError: 'Test Date.'
Stack (most recent call last):
  File "D:/Ina/ETL_XdmLib_2.A.13/ETL_XdmLib_2.A.13/EDAETL/ETL_TABLE/ETL_FT_SD_TO_XSIFF/ETL_FT_SD_TO_XSIFF.py", line 506, in <module>
    skip_file, None, log, config, config_sql)
  File "../..\XdmLib\CustomFuction.py", line 597, in file2db_init
    file, pre_params, db_src, db_tgt)
  File "D:/Ina/ETL_XdmLib_2.A.13/ETL_XdmLib_2.A.13/EDAETL/ETL_TABLE/ETL_FT_SD_TO_XSIFF/ETL_FT_SD_TO_XSIFF.py", line 331, in do_file
    log.error(ex, exc_info=True, stack_info=True)
2023-12-19 17:02:49.583 - __init__   [ERROR   ] File:TLECGQG81-CW_阳光GD200FYS100L6S.xlsx Move To Error Folder
                                                Error: None
2023-12-19 17:02:50.503 - ETL_FT_SD_TO_XSIFF [ERROR   ] 'Test Date.'
Traceback (most recent call last):
  File "D:\Python37\lib\site-packages\pandas\core\indexes\base.py", line 2898, in get_loc
    return self._engine.get_loc(casted_key)
  File "pandas\_libs\index.pyx", line 70, in pandas._libs.index.IndexEngine.get_loc
  File "pandas\_libs\index.pyx", line 101, in pandas._libs.index.IndexEngine.get_loc
  File "pandas\_libs\hashtable_class_helper.pxi", line 1675, in pandas._libs.hashtable.PyObjectHashTable.get_item
  File "pandas\_libs\hashtable_class_helper.pxi", line 1683, in pandas._libs.hashtable.PyObjectHashTable.get_item
KeyError: 'Test Date.'

The above exception was the direct cause of the following exception:

Traceback (most recent call last):
  File "D:/Ina/ETL_XdmLib_2.A.13/ETL_XdmLib_2.A.13/EDAETL/ETL_TABLE/ETL_FT_SD_TO_XSIFF/ETL_FT_SD_TO_XSIFF.py", line 170, in do_file
    filtered_dfA = source_data_df[source_data_df['Test Date.'] != '.']
  File "D:\Python37\lib\site-packages\pandas\core\frame.py", line 2906, in __getitem__
    indexer = self.columns.get_loc(key)
  File "D:\Python37\lib\site-packages\pandas\core\indexes\base.py", line 2900, in get_loc
    raise KeyError(key) from err
KeyError: 'Test Date.'
Stack (most recent call last):
  File "D:/Ina/ETL_XdmLib_2.A.13/ETL_XdmLib_2.A.13/EDAETL/ETL_TABLE/ETL_FT_SD_TO_XSIFF/ETL_FT_SD_TO_XSIFF.py", line 506, in <module>
    skip_file, None, log, config, config_sql)
  File "../..\XdmLib\CustomFuction.py", line 597, in file2db_init
    file, pre_params, db_src, db_tgt)
  File "D:/Ina/ETL_XdmLib_2.A.13/ETL_XdmLib_2.A.13/EDAETL/ETL_TABLE/ETL_FT_SD_TO_XSIFF/ETL_FT_SD_TO_XSIFF.py", line 331, in do_file
    log.error(ex, exc_info=True, stack_info=True)
2023-12-19 17:02:50.686 - __init__   [ERROR   ] File:XWECYQH20-CW_GD600MLS100L6S.xlsx Move To Error Folder
                                                Error: None
2023-12-19 17:02:51.622 - ETL_FT_SD_TO_XSIFF [ERROR   ] 'Test Date.'
Traceback (most recent call last):
  File "D:\Python37\lib\site-packages\pandas\core\indexes\base.py", line 2898, in get_loc
    return self._engine.get_loc(casted_key)
  File "pandas\_libs\index.pyx", line 70, in pandas._libs.index.IndexEngine.get_loc
  File "pandas\_libs\index.pyx", line 101, in pandas._libs.index.IndexEngine.get_loc
  File "pandas\_libs\hashtable_class_helper.pxi", line 1675, in pandas._libs.hashtable.PyObjectHashTable.get_item
  File "pandas\_libs\hashtable_class_helper.pxi", line 1683, in pandas._libs.hashtable.PyObjectHashTable.get_item
KeyError: 'Test Date.'

The above exception was the direct cause of the following exception:

Traceback (most recent call last):
  File "D:/Ina/ETL_XdmLib_2.A.13/ETL_XdmLib_2.A.13/EDAETL/ETL_TABLE/ETL_FT_SD_TO_XSIFF/ETL_FT_SD_TO_XSIFF.py", line 170, in do_file
    filtered_dfA = source_data_df[source_data_df['Test Date.'] != '.']
  File "D:\Python37\lib\site-packages\pandas\core\frame.py", line 2906, in __getitem__
    indexer = self.columns.get_loc(key)
  File "D:\Python37\lib\site-packages\pandas\core\indexes\base.py", line 2900, in get_loc
    raise KeyError(key) from err
KeyError: 'Test Date.'
Stack (most recent call last):
  File "D:/Ina/ETL_XdmLib_2.A.13/ETL_XdmLib_2.A.13/EDAETL/ETL_TABLE/ETL_FT_SD_TO_XSIFF/ETL_FT_SD_TO_XSIFF.py", line 506, in <module>
    skip_file, None, log, config, config_sql)
  File "../..\XdmLib\CustomFuction.py", line 597, in file2db_init
    file, pre_params, db_src, db_tgt)
  File "D:/Ina/ETL_XdmLib_2.A.13/ETL_XdmLib_2.A.13/EDAETL/ETL_TABLE/ETL_FT_SD_TO_XSIFF/ETL_FT_SD_TO_XSIFF.py", line 331, in do_file
    log.error(ex, exc_info=True, stack_info=True)
2023-12-19 17:02:51.812 - __init__   [ERROR   ] File:XWECYQH20-CW_GD600MLS100L6S_少前两行测试.xlsx Move To Error Folder
                                                Error: None
2023-12-19 17:02:52.637 - ETL_FT_SD_TO_XSIFF [ERROR   ] Missing valid table header:Index([], dtype='object')
2023-12-19 17:02:52.784 - __init__   [ERROR   ] File:XWECYQH20-CW_GD600MLS100L6S_缺Test_no.测试.xlsx Move To Error Folder
                                                Error: None
2023-12-19 17:02:53.554 - ETL_FT_SD_TO_XSIFF [ERROR   ] 'Test Date.'
Traceback (most recent call last):
  File "D:\Python37\lib\site-packages\pandas\core\indexes\base.py", line 2898, in get_loc
    return self._engine.get_loc(casted_key)
  File "pandas\_libs\index.pyx", line 70, in pandas._libs.index.IndexEngine.get_loc
  File "pandas\_libs\index.pyx", line 101, in pandas._libs.index.IndexEngine.get_loc
  File "pandas\_libs\hashtable_class_helper.pxi", line 1675, in pandas._libs.hashtable.PyObjectHashTable.get_item
  File "pandas\_libs\hashtable_class_helper.pxi", line 1683, in pandas._libs.hashtable.PyObjectHashTable.get_item
KeyError: 'Test Date.'

The above exception was the direct cause of the following exception:

Traceback (most recent call last):
  File "D:/Ina/ETL_XdmLib_2.A.13/ETL_XdmLib_2.A.13/EDAETL/ETL_TABLE/ETL_FT_SD_TO_XSIFF/ETL_FT_SD_TO_XSIFF.py", line 170, in do_file
    filtered_dfA = source_data_df[source_data_df['Test Date.'] != '.']
  File "D:\Python37\lib\site-packages\pandas\core\frame.py", line 2906, in __getitem__
    indexer = self.columns.get_loc(key)
  File "D:\Python37\lib\site-packages\pandas\core\indexes\base.py", line 2900, in get_loc
    raise KeyError(key) from err
KeyError: 'Test Date.'
Stack (most recent call last):
  File "D:/Ina/ETL_XdmLib_2.A.13/ETL_XdmLib_2.A.13/EDAETL/ETL_TABLE/ETL_FT_SD_TO_XSIFF/ETL_FT_SD_TO_XSIFF.py", line 506, in <module>
    skip_file, None, log, config, config_sql)
  File "../..\XdmLib\CustomFuction.py", line 597, in file2db_init
    file, pre_params, db_src, db_tgt)
  File "D:/Ina/ETL_XdmLib_2.A.13/ETL_XdmLib_2.A.13/EDAETL/ETL_TABLE/ETL_FT_SD_TO_XSIFF/ETL_FT_SD_TO_XSIFF.py", line 331, in do_file
    log.error(ex, exc_info=True, stack_info=True)
2023-12-19 17:02:53.700 - __init__   [ERROR   ] File:XWECYQH62-GW_GD600MLS100L6S-GW.xlsx Move To Error Folder
                                                Error: None
2023-12-19 17:02:54.673 - ETL_FT_SD_TO_XSIFF [ERROR   ] 'Test Date.'
Traceback (most recent call last):
  File "D:\Python37\lib\site-packages\pandas\core\indexes\base.py", line 2898, in get_loc
    return self._engine.get_loc(casted_key)
  File "pandas\_libs\index.pyx", line 70, in pandas._libs.index.IndexEngine.get_loc
  File "pandas\_libs\index.pyx", line 101, in pandas._libs.index.IndexEngine.get_loc
  File "pandas\_libs\hashtable_class_helper.pxi", line 1675, in pandas._libs.hashtable.PyObjectHashTable.get_item
  File "pandas\_libs\hashtable_class_helper.pxi", line 1683, in pandas._libs.hashtable.PyObjectHashTable.get_item
KeyError: 'Test Date.'

The above exception was the direct cause of the following exception:

Traceback (most recent call last):
  File "D:/Ina/ETL_XdmLib_2.A.13/ETL_XdmLib_2.A.13/EDAETL/ETL_TABLE/ETL_FT_SD_TO_XSIFF/ETL_FT_SD_TO_XSIFF.py", line 170, in do_file
    filtered_dfA = source_data_df[source_data_df['Test Date.'] != '.']
  File "D:\Python37\lib\site-packages\pandas\core\frame.py", line 2906, in __getitem__
    indexer = self.columns.get_loc(key)
  File "D:\Python37\lib\site-packages\pandas\core\indexes\base.py", line 2900, in get_loc
    raise KeyError(key) from err
KeyError: 'Test Date.'
Stack (most recent call last):
  File "D:/Ina/ETL_XdmLib_2.A.13/ETL_XdmLib_2.A.13/EDAETL/ETL_TABLE/ETL_FT_SD_TO_XSIFF/ETL_FT_SD_TO_XSIFF.py", line 506, in <module>
    skip_file, None, log, config, config_sql)
  File "../..\XdmLib\CustomFuction.py", line 597, in file2db_init
    file, pre_params, db_src, db_tgt)
  File "D:/Ina/ETL_XdmLib_2.A.13/ETL_XdmLib_2.A.13/EDAETL/ETL_TABLE/ETL_FT_SD_TO_XSIFF/ETL_FT_SD_TO_XSIFF.py", line 331, in do_file
    log.error(ex, exc_info=True, stack_info=True)
2023-12-19 17:02:54.835 - __init__   [ERROR   ] File:XWECZS889-GW_新阳光GD600MLS100L6S-GW.xlsx Move To Error Folder
                                                Error: None
2023-12-19 17:03:46.063 - ETL_FT_SD_TO_XSIFF [ERROR   ] [Serial no.] This column is numeric only.
2023-12-19 17:03:46.225 - __init__   [ERROR   ] File:QG35-CW_GD400TAS100L6S.xlsx Move To Error Folder
                                                Error: None
2023-12-19 17:03:46.383 - ETL_FT_SD_TO_XSIFF [ERROR   ] 'Test Date.'
Traceback (most recent call last):
  File "D:\Python37\lib\site-packages\pandas\core\indexes\base.py", line 2898, in get_loc
    return self._engine.get_loc(casted_key)
  File "pandas\_libs\index.pyx", line 70, in pandas._libs.index.IndexEngine.get_loc
  File "pandas\_libs\index.pyx", line 101, in pandas._libs.index.IndexEngine.get_loc
  File "pandas\_libs\hashtable_class_helper.pxi", line 1675, in pandas._libs.hashtable.PyObjectHashTable.get_item
  File "pandas\_libs\hashtable_class_helper.pxi", line 1683, in pandas._libs.hashtable.PyObjectHashTable.get_item
KeyError: 'Test Date.'

The above exception was the direct cause of the following exception:

Traceback (most recent call last):
  File "D:/Ina/ETL_XdmLib_2.A.13/ETL_XdmLib_2.A.13/EDAETL/ETL_TABLE/ETL_FT_SD_TO_XSIFF/ETL_FT_SD_TO_XSIFF.py", line 170, in do_file
    filtered_dfA = source_data_df[source_data_df['Test Date.'] != '.']
  File "D:\Python37\lib\site-packages\pandas\core\frame.py", line 2906, in __getitem__
    indexer = self.columns.get_loc(key)
  File "D:\Python37\lib\site-packages\pandas\core\indexes\base.py", line 2900, in get_loc
    raise KeyError(key) from err
KeyError: 'Test Date.'
Stack (most recent call last):
  File "D:/Ina/ETL_XdmLib_2.A.13/ETL_XdmLib_2.A.13/EDAETL/ETL_TABLE/ETL_FT_SD_TO_XSIFF/ETL_FT_SD_TO_XSIFF.py", line 506, in <module>
    skip_file, None, log, config, config_sql)
  File "../..\XdmLib\CustomFuction.py", line 597, in file2db_init
    file, pre_params, db_src, db_tgt)
  File "D:/Ina/ETL_XdmLib_2.A.13/ETL_XdmLib_2.A.13/EDAETL/ETL_TABLE/ETL_FT_SD_TO_XSIFF/ETL_FT_SD_TO_XSIFF.py", line 331, in do_file
    log.error(ex, exc_info=True, stack_info=True)
2023-12-19 17:03:46.571 - __init__   [ERROR   ] File:TLECGQG81-CW_阳光GD200FYS100L6S.xlsx Move To Error Folder
                                                Error: None
2023-12-19 17:03:47.475 - ETL_FT_SD_TO_XSIFF [ERROR   ] 'Test Date.'
Traceback (most recent call last):
  File "D:\Python37\lib\site-packages\pandas\core\indexes\base.py", line 2898, in get_loc
    return self._engine.get_loc(casted_key)
  File "pandas\_libs\index.pyx", line 70, in pandas._libs.index.IndexEngine.get_loc
  File "pandas\_libs\index.pyx", line 101, in pandas._libs.index.IndexEngine.get_loc
  File "pandas\_libs\hashtable_class_helper.pxi", line 1675, in pandas._libs.hashtable.PyObjectHashTable.get_item
  File "pandas\_libs\hashtable_class_helper.pxi", line 1683, in pandas._libs.hashtable.PyObjectHashTable.get_item
KeyError: 'Test Date.'

The above exception was the direct cause of the following exception:

Traceback (most recent call last):
  File "D:/Ina/ETL_XdmLib_2.A.13/ETL_XdmLib_2.A.13/EDAETL/ETL_TABLE/ETL_FT_SD_TO_XSIFF/ETL_FT_SD_TO_XSIFF.py", line 170, in do_file
    filtered_dfA = source_data_df[source_data_df['Test Date.'] != '.']
  File "D:\Python37\lib\site-packages\pandas\core\frame.py", line 2906, in __getitem__
    indexer = self.columns.get_loc(key)
  File "D:\Python37\lib\site-packages\pandas\core\indexes\base.py", line 2900, in get_loc
    raise KeyError(key) from err
KeyError: 'Test Date.'
Stack (most recent call last):
  File "D:/Ina/ETL_XdmLib_2.A.13/ETL_XdmLib_2.A.13/EDAETL/ETL_TABLE/ETL_FT_SD_TO_XSIFF/ETL_FT_SD_TO_XSIFF.py", line 506, in <module>
    skip_file, None, log, config, config_sql)
  File "../..\XdmLib\CustomFuction.py", line 597, in file2db_init
    file, pre_params, db_src, db_tgt)
  File "D:/Ina/ETL_XdmLib_2.A.13/ETL_XdmLib_2.A.13/EDAETL/ETL_TABLE/ETL_FT_SD_TO_XSIFF/ETL_FT_SD_TO_XSIFF.py", line 331, in do_file
    log.error(ex, exc_info=True, stack_info=True)
2023-12-19 17:03:47.643 - __init__   [ERROR   ] File:XWECYQH20-CW_GD600MLS100L6S.xlsx Move To Error Folder
                                                Error: None
2023-12-19 17:03:48.629 - ETL_FT_SD_TO_XSIFF [ERROR   ] 'Test Date.'
Traceback (most recent call last):
  File "D:\Python37\lib\site-packages\pandas\core\indexes\base.py", line 2898, in get_loc
    return self._engine.get_loc(casted_key)
  File "pandas\_libs\index.pyx", line 70, in pandas._libs.index.IndexEngine.get_loc
  File "pandas\_libs\index.pyx", line 101, in pandas._libs.index.IndexEngine.get_loc
  File "pandas\_libs\hashtable_class_helper.pxi", line 1675, in pandas._libs.hashtable.PyObjectHashTable.get_item
  File "pandas\_libs\hashtable_class_helper.pxi", line 1683, in pandas._libs.hashtable.PyObjectHashTable.get_item
KeyError: 'Test Date.'

The above exception was the direct cause of the following exception:

Traceback (most recent call last):
  File "D:/Ina/ETL_XdmLib_2.A.13/ETL_XdmLib_2.A.13/EDAETL/ETL_TABLE/ETL_FT_SD_TO_XSIFF/ETL_FT_SD_TO_XSIFF.py", line 170, in do_file
    filtered_dfA = source_data_df[source_data_df['Test Date.'] != '.']
  File "D:\Python37\lib\site-packages\pandas\core\frame.py", line 2906, in __getitem__
    indexer = self.columns.get_loc(key)
  File "D:\Python37\lib\site-packages\pandas\core\indexes\base.py", line 2900, in get_loc
    raise KeyError(key) from err
KeyError: 'Test Date.'
Stack (most recent call last):
  File "D:/Ina/ETL_XdmLib_2.A.13/ETL_XdmLib_2.A.13/EDAETL/ETL_TABLE/ETL_FT_SD_TO_XSIFF/ETL_FT_SD_TO_XSIFF.py", line 506, in <module>
    skip_file, None, log, config, config_sql)
  File "../..\XdmLib\CustomFuction.py", line 597, in file2db_init
    file, pre_params, db_src, db_tgt)
  File "D:/Ina/ETL_XdmLib_2.A.13/ETL_XdmLib_2.A.13/EDAETL/ETL_TABLE/ETL_FT_SD_TO_XSIFF/ETL_FT_SD_TO_XSIFF.py", line 331, in do_file
    log.error(ex, exc_info=True, stack_info=True)
2023-12-19 17:03:48.792 - __init__   [ERROR   ] File:XWECYQH20-CW_GD600MLS100L6S_少前两行测试.xlsx Move To Error Folder
                                                Error: None
2023-12-19 17:03:49.269 - ETL_FT_SD_TO_XSIFF [ERROR   ] Missing valid table header:Index([], dtype='object')
2023-12-19 17:03:49.406 - __init__   [ERROR   ] File:XWECYQH20-CW_GD600MLS100L6S_缺Test_no.测试.xlsx Move To Error Folder
                                                Error: None
2023-12-19 17:03:50.170 - ETL_FT_SD_TO_XSIFF [ERROR   ] 'Test Date.'
Traceback (most recent call last):
  File "D:\Python37\lib\site-packages\pandas\core\indexes\base.py", line 2898, in get_loc
    return self._engine.get_loc(casted_key)
  File "pandas\_libs\index.pyx", line 70, in pandas._libs.index.IndexEngine.get_loc
  File "pandas\_libs\index.pyx", line 101, in pandas._libs.index.IndexEngine.get_loc
  File "pandas\_libs\hashtable_class_helper.pxi", line 1675, in pandas._libs.hashtable.PyObjectHashTable.get_item
  File "pandas\_libs\hashtable_class_helper.pxi", line 1683, in pandas._libs.hashtable.PyObjectHashTable.get_item
KeyError: 'Test Date.'

The above exception was the direct cause of the following exception:

Traceback (most recent call last):
  File "D:/Ina/ETL_XdmLib_2.A.13/ETL_XdmLib_2.A.13/EDAETL/ETL_TABLE/ETL_FT_SD_TO_XSIFF/ETL_FT_SD_TO_XSIFF.py", line 170, in do_file
    filtered_dfA = source_data_df[source_data_df['Test Date.'] != '.']
  File "D:\Python37\lib\site-packages\pandas\core\frame.py", line 2906, in __getitem__
    indexer = self.columns.get_loc(key)
  File "D:\Python37\lib\site-packages\pandas\core\indexes\base.py", line 2900, in get_loc
    raise KeyError(key) from err
KeyError: 'Test Date.'
Stack (most recent call last):
  File "D:/Ina/ETL_XdmLib_2.A.13/ETL_XdmLib_2.A.13/EDAETL/ETL_TABLE/ETL_FT_SD_TO_XSIFF/ETL_FT_SD_TO_XSIFF.py", line 506, in <module>
    skip_file, None, log, config, config_sql)
  File "../..\XdmLib\CustomFuction.py", line 597, in file2db_init
    file, pre_params, db_src, db_tgt)
  File "D:/Ina/ETL_XdmLib_2.A.13/ETL_XdmLib_2.A.13/EDAETL/ETL_TABLE/ETL_FT_SD_TO_XSIFF/ETL_FT_SD_TO_XSIFF.py", line 331, in do_file
    log.error(ex, exc_info=True, stack_info=True)
2023-12-19 17:03:50.329 - __init__   [ERROR   ] File:XWECYQH62-GW_GD600MLS100L6S-GW.xlsx Move To Error Folder
                                                Error: None
2023-12-19 17:05:42.682 - ETL_FT_SD_TO_XSIFF [ERROR   ] [Serial no.] This column is numeric only.
2023-12-19 17:05:42.904 - __init__   [ERROR   ] File:QG35-CW_GD400TAS100L6S.xlsx Move To Error Folder
                                                Error: None
2023-12-19 17:08:30.481 - ETL_FT_SD_TO_XSIFF [ERROR   ] [Serial no.] This column is numeric only.
2023-12-19 17:08:30.688 - __init__   [ERROR   ] File:QG35-CW_GD400TAS100L6S.xlsx Move To Error Folder
                                                Error: None
2023-12-19 17:08:34.309 - ETL_FT_SD_TO_XSIFF [ERROR   ] Missing valid table header:Index([], dtype='object')
2023-12-19 17:08:34.511 - __init__   [ERROR   ] File:XWECYQH20-CW_GD600MLS100L6S_缺Test_no.测试.xlsx Move To Error Folder
                                                Error: None
2023-12-19 17:12:37.855 - ETL_FT_SD_TO_XSIFF [ERROR   ] [Serial no.] has no spaces or valid part cannot be obtained:0000
2023-12-19 17:12:38.046 - __init__   [ERROR   ] File:XLECHQ217-CW-FC_新阳光GD200FYS100L6S-CW.xlsx Move To Error Folder
                                                Error: None
2023-12-19 17:15:39.003 - ETL_FT_SD_TO_XSIFF [ERROR   ] [Serial no.] has no spaces or valid part cannot be obtained:0000
2023-12-19 17:15:39.167 - __init__   [ERROR   ] File:XLECHQ217-CW-FC_新阳光GD200FYS100L6S-CW.xlsx Move To Error Folder
                                                Error: None
2023-12-19 17:16:07.922 - ETL_FT_SD_TO_XSIFF [ERROR   ] [Serial no.] has no spaces or valid part cannot be obtained:0000
2023-12-19 17:16:08.149 - __init__   [ERROR   ] File:XLECHQ217-CW-FC_新阳光GD200FYS100L6S-CW.xlsx Move To Error Folder
                                                Error: None
