2023-10-25 09:24:12.703 - __init__   [ERROR   ] File:QG35-CW_GD400TAS100L6S.xlsx Move To Error Folder
                                                Error: None
2023-10-25 09:30:18.472 - ETL_FT_SD_TO_XSIFF [ERROR   ] list indices must be integers or slices, not str
Traceback (most recent call last):
  File "D:/Ina/ETL_XdmLib_2.A.13/ETL_XdmLib_2.A.13/EDAETL/ETL_TABLE/ETL_FT_SD_TO_XSIFF/ETL_FT_SD_TO_XSIFF.py", line 460, in do_file
    if variables_to_check[variable_name].isnull().any():
TypeError: list indices must be integers or slices, not str
Stack (most recent call last):
  File "D:\soft\PyCharm Community Edition 2022.1.3\plugins\python-ce\helpers\pydev\pydevd.py", line 2181, in <module>
    main()
  File "D:\soft\PyCharm Community Edition 2022.1.3\plugins\python-ce\helpers\pydev\pydevd.py", line 2172, in main
    globals = debugger.run(setup['file'], None, None, is_module)
  File "D:\soft\PyCharm Community Edition 2022.1.3\plugins\python-ce\helpers\pydev\pydevd.py", line 1484, in run
    return self._exec(is_module, entry_point_fn, module_name, file, globals, locals)
  File "D:\soft\PyCharm Community Edition 2022.1.3\plugins\python-ce\helpers\pydev\pydevd.py", line 1491, in _exec
    pydev_imports.execfile(file, globals, locals)  # execute the script
  File "D:\soft\PyCharm Community Edition 2022.1.3\plugins\python-ce\helpers\pydev\_pydev_imps\_pydev_execfile.py", line 18, in execfile
    exec(compile(contents+"\n", file, 'exec'), glob, loc)
  File "D:/Ina/ETL_XdmLib_2.A.13/ETL_XdmLib_2.A.13/EDAETL/ETL_TABLE/ETL_FT_SD_TO_XSIFF/ETL_FT_SD_TO_XSIFF.py", line 577, in <module>
    XdmLib.CustomFuction.file2db_init(do_file, before_do_file, after_do_file,
  File "D:\Ina\ETL_XdmLib_2.A.13\ETL_XdmLib_2.A.13\EDAETL\ETL_TABLE\ETL_FT_SD_TO_XSIFF\../..\XdmLib\CustomFuction.py", line 596, in file2db_init
    res = do_file(file_root_source_path,
  File "D:/Ina/ETL_XdmLib_2.A.13/ETL_XdmLib_2.A.13/EDAETL/ETL_TABLE/ETL_FT_SD_TO_XSIFF/ETL_FT_SD_TO_XSIFF.py", line 481, in do_file
    log.error(ex, exc_info=True, stack_info=True)
2023-10-25 09:30:40.188 - ETL_FT_SD_TO_XSIFF [ERROR   ] list indices must be integers or slices, not str
Traceback (most recent call last):
  File "D:\Ina\ETL_XdmLib_2.A.13\ETL_XdmLib_2.A.13\EDAETL\ETL_TABLE\ETL_FT_SD_TO_XSIFF\ETL_FT_SD_TO_XSIFF.py", line 460, in do_file
    if variables_to_check[variable_name].isnull().any():
TypeError: list indices must be integers or slices, not str
Stack (most recent call last):
  File "D:\Ina\ETL_XdmLib_2.A.13\ETL_XdmLib_2.A.13\EDAETL\ETL_TABLE\ETL_FT_SD_TO_XSIFF\ETL_FT_SD_TO_XSIFF.py", line 577, in <module>
    XdmLib.CustomFuction.file2db_init(do_file, before_do_file, after_do_file,
  File "D:\Ina\ETL_XdmLib_2.A.13\ETL_XdmLib_2.A.13\EDAETL\ETL_TABLE\ETL_FT_SD_TO_XSIFF\../..\XdmLib\CustomFuction.py", line 596, in file2db_init
    res = do_file(file_root_source_path,
  File "D:\Ina\ETL_XdmLib_2.A.13\ETL_XdmLib_2.A.13\EDAETL\ETL_TABLE\ETL_FT_SD_TO_XSIFF\ETL_FT_SD_TO_XSIFF.py", line 481, in do_file
    log.error(ex, exc_info=True, stack_info=True)
2023-10-25 09:30:43.098 - __init__   [ERROR   ] File:TLECGQG81-CW_阳光GD200FYS100L6S.xlsx Move To Error Folder
                                                Error: None
2023-10-25 09:30:44.306 - ETL_FT_SD_TO_XSIFF [ERROR   ] list indices must be integers or slices, not str
Traceback (most recent call last):
  File "D:\Ina\ETL_XdmLib_2.A.13\ETL_XdmLib_2.A.13\EDAETL\ETL_TABLE\ETL_FT_SD_TO_XSIFF\ETL_FT_SD_TO_XSIFF.py", line 460, in do_file
    if variables_to_check[variable_name].isnull().any():
TypeError: list indices must be integers or slices, not str
Stack (most recent call last):
  File "D:\Ina\ETL_XdmLib_2.A.13\ETL_XdmLib_2.A.13\EDAETL\ETL_TABLE\ETL_FT_SD_TO_XSIFF\ETL_FT_SD_TO_XSIFF.py", line 577, in <module>
    XdmLib.CustomFuction.file2db_init(do_file, before_do_file, after_do_file,
  File "D:\Ina\ETL_XdmLib_2.A.13\ETL_XdmLib_2.A.13\EDAETL\ETL_TABLE\ETL_FT_SD_TO_XSIFF\../..\XdmLib\CustomFuction.py", line 596, in file2db_init
    res = do_file(file_root_source_path,
  File "D:\Ina\ETL_XdmLib_2.A.13\ETL_XdmLib_2.A.13\EDAETL\ETL_TABLE\ETL_FT_SD_TO_XSIFF\ETL_FT_SD_TO_XSIFF.py", line 481, in do_file
    log.error(ex, exc_info=True, stack_info=True)
2023-10-25 09:30:47.193 - __init__   [ERROR   ] File:XWECYQH20-CW_GD600MLS100L6S.xlsx Move To Error Folder
                                                Error: None
2023-10-25 09:30:48.077 - ETL_FT_SD_TO_XSIFF [ERROR   ] list indices must be integers or slices, not str
Traceback (most recent call last):
  File "D:\Ina\ETL_XdmLib_2.A.13\ETL_XdmLib_2.A.13\EDAETL\ETL_TABLE\ETL_FT_SD_TO_XSIFF\ETL_FT_SD_TO_XSIFF.py", line 460, in do_file
    if variables_to_check[variable_name].isnull().any():
TypeError: list indices must be integers or slices, not str
Stack (most recent call last):
  File "D:\Ina\ETL_XdmLib_2.A.13\ETL_XdmLib_2.A.13\EDAETL\ETL_TABLE\ETL_FT_SD_TO_XSIFF\ETL_FT_SD_TO_XSIFF.py", line 577, in <module>
    XdmLib.CustomFuction.file2db_init(do_file, before_do_file, after_do_file,
  File "D:\Ina\ETL_XdmLib_2.A.13\ETL_XdmLib_2.A.13\EDAETL\ETL_TABLE\ETL_FT_SD_TO_XSIFF\../..\XdmLib\CustomFuction.py", line 596, in file2db_init
    res = do_file(file_root_source_path,
  File "D:\Ina\ETL_XdmLib_2.A.13\ETL_XdmLib_2.A.13\EDAETL\ETL_TABLE\ETL_FT_SD_TO_XSIFF\ETL_FT_SD_TO_XSIFF.py", line 481, in do_file
    log.error(ex, exc_info=True, stack_info=True)
2023-10-25 09:30:50.980 - __init__   [ERROR   ] File:XWECYQH62-GW_GD600MLS100L6S-GW.xlsx Move To Error Folder
                                                Error: None
2023-10-25 09:33:02.680 - __init__   [ERROR   ] File:QG35-CW_GD400TAS100L6S.xlsx Move To Error Folder
                                                Error: None
2023-10-25 09:33:03.013 - ETL_FT_SD_TO_XSIFF [ERROR   ] not enough values to unpack (expected 2, got 0)
Traceback (most recent call last):
  File "D:\Ina\ETL_XdmLib_2.A.13\ETL_XdmLib_2.A.13\EDAETL\ETL_TABLE\ETL_FT_SD_TO_XSIFF\ETL_FT_SD_TO_XSIFF.py", line 459, in do_file
    for i , variable_name in variables_to_check:
ValueError: not enough values to unpack (expected 2, got 0)
Stack (most recent call last):
  File "D:\Ina\ETL_XdmLib_2.A.13\ETL_XdmLib_2.A.13\EDAETL\ETL_TABLE\ETL_FT_SD_TO_XSIFF\ETL_FT_SD_TO_XSIFF.py", line 577, in <module>
    XdmLib.CustomFuction.file2db_init(do_file, before_do_file, after_do_file,
  File "D:\Ina\ETL_XdmLib_2.A.13\ETL_XdmLib_2.A.13\EDAETL\ETL_TABLE\ETL_FT_SD_TO_XSIFF\../..\XdmLib\CustomFuction.py", line 596, in file2db_init
    res = do_file(file_root_source_path,
  File "D:\Ina\ETL_XdmLib_2.A.13\ETL_XdmLib_2.A.13\EDAETL\ETL_TABLE\ETL_FT_SD_TO_XSIFF\ETL_FT_SD_TO_XSIFF.py", line 481, in do_file
    log.error(ex, exc_info=True, stack_info=True)
2023-10-25 09:33:05.980 - __init__   [ERROR   ] File:TLECGQG81-CW_阳光GD200FYS100L6S.xlsx Move To Error Folder
                                                Error: None
2023-10-25 09:33:06.883 - ETL_FT_SD_TO_XSIFF [ERROR   ] not enough values to unpack (expected 2, got 0)
Traceback (most recent call last):
  File "D:\Ina\ETL_XdmLib_2.A.13\ETL_XdmLib_2.A.13\EDAETL\ETL_TABLE\ETL_FT_SD_TO_XSIFF\ETL_FT_SD_TO_XSIFF.py", line 459, in do_file
    for i , variable_name in variables_to_check:
ValueError: not enough values to unpack (expected 2, got 0)
Stack (most recent call last):
  File "D:\Ina\ETL_XdmLib_2.A.13\ETL_XdmLib_2.A.13\EDAETL\ETL_TABLE\ETL_FT_SD_TO_XSIFF\ETL_FT_SD_TO_XSIFF.py", line 577, in <module>
    XdmLib.CustomFuction.file2db_init(do_file, before_do_file, after_do_file,
  File "D:\Ina\ETL_XdmLib_2.A.13\ETL_XdmLib_2.A.13\EDAETL\ETL_TABLE\ETL_FT_SD_TO_XSIFF\../..\XdmLib\CustomFuction.py", line 596, in file2db_init
    res = do_file(file_root_source_path,
  File "D:\Ina\ETL_XdmLib_2.A.13\ETL_XdmLib_2.A.13\EDAETL\ETL_TABLE\ETL_FT_SD_TO_XSIFF\ETL_FT_SD_TO_XSIFF.py", line 481, in do_file
    log.error(ex, exc_info=True, stack_info=True)
2023-10-25 09:33:09.810 - __init__   [ERROR   ] File:XWECYQH20-CW_GD600MLS100L6S.xlsx Move To Error Folder
                                                Error: None
2023-10-25 09:33:10.683 - ETL_FT_SD_TO_XSIFF [ERROR   ] not enough values to unpack (expected 2, got 0)
Traceback (most recent call last):
  File "D:\Ina\ETL_XdmLib_2.A.13\ETL_XdmLib_2.A.13\EDAETL\ETL_TABLE\ETL_FT_SD_TO_XSIFF\ETL_FT_SD_TO_XSIFF.py", line 459, in do_file
    for i , variable_name in variables_to_check:
ValueError: not enough values to unpack (expected 2, got 0)
Stack (most recent call last):
  File "D:\Ina\ETL_XdmLib_2.A.13\ETL_XdmLib_2.A.13\EDAETL\ETL_TABLE\ETL_FT_SD_TO_XSIFF\ETL_FT_SD_TO_XSIFF.py", line 577, in <module>
    XdmLib.CustomFuction.file2db_init(do_file, before_do_file, after_do_file,
  File "D:\Ina\ETL_XdmLib_2.A.13\ETL_XdmLib_2.A.13\EDAETL\ETL_TABLE\ETL_FT_SD_TO_XSIFF\../..\XdmLib\CustomFuction.py", line 596, in file2db_init
    res = do_file(file_root_source_path,
  File "D:\Ina\ETL_XdmLib_2.A.13\ETL_XdmLib_2.A.13\EDAETL\ETL_TABLE\ETL_FT_SD_TO_XSIFF\ETL_FT_SD_TO_XSIFF.py", line 481, in do_file
    log.error(ex, exc_info=True, stack_info=True)
2023-10-25 09:33:13.582 - __init__   [ERROR   ] File:XWECYQH62-GW_GD600MLS100L6S-GW.xlsx Move To Error Folder
                                                Error: None
2023-10-25 09:34:21.420 - __init__   [ERROR   ] File:QG35-CW_GD400TAS100L6S.xlsx Move To Error Folder
                                                Error: None
2023-10-25 09:34:22.031 - ETL_FT_SD_TO_XSIFF [ERROR   ]  列包含空值
2023-10-25 09:34:24.927 - __init__   [ERROR   ] File:TLECGQG81-CW_阳光GD200FYS100L6S.xlsx Move To Error Folder
                                                Error: None
2023-10-25 09:34:25.970 - ETL_FT_SD_TO_XSIFF [ERROR   ]  列包含空值
2023-10-25 09:34:28.868 - __init__   [ERROR   ] File:XWECYQH20-CW_GD600MLS100L6S.xlsx Move To Error Folder
                                                Error: None
2023-10-25 09:34:29.811 - ETL_FT_SD_TO_XSIFF [ERROR   ]  列包含空值
2023-10-25 09:34:32.728 - __init__   [ERROR   ] File:XWECYQH62-GW_GD600MLS100L6S-GW.xlsx Move To Error Folder
                                                Error: None
2023-10-25 09:39:02.150 - __init__   [ERROR   ] File:QG35-CW_GD400TAS100L6S.xlsx Move To Error Folder
                                                Error: None
2023-10-25 09:39:02.486 - ETL_FT_SD_TO_XSIFF [ERROR   ] FtLot 是空值
2023-10-25 09:39:05.418 - __init__   [ERROR   ] File:TLECGQG81-CW_阳光GD200FYS100L6S.xlsx Move To Error Folder
                                                Error: None
2023-10-25 09:39:06.355 - ETL_FT_SD_TO_XSIFF [ERROR   ] FtLot 是空值
2023-10-25 09:39:09.292 - __init__   [ERROR   ] File:XWECYQH20-CW_GD600MLS100L6S.xlsx Move To Error Folder
                                                Error: None
2023-10-25 09:39:10.122 - ETL_FT_SD_TO_XSIFF [ERROR   ] FtLot 是空值
2023-10-25 09:39:13.067 - __init__   [ERROR   ] File:XWECYQH62-GW_GD600MLS100L6S-GW.xlsx Move To Error Folder
                                                Error: None
2023-10-25 10:40:14.762 - __init__   [ERROR   ] Check CustomFuction.pyc SHA256 Failed
2023-10-25 11:06:25.990 - __init__   [ERROR   ] Check CustomFuction.pyc SHA256 Failed
2023-10-25 11:07:18.586 - __init__   [ERROR   ] Check CustomFuction.pyc SHA256 Failed
2023-10-25 11:08:29.841 - ETL_FT_SD_TO_XSIFF [ERROR   ] Excel xlsx file; not supported
Traceback (most recent call last):
  File "D:/Ina/ETL_XdmLib_2.A.13/ETL_XdmLib_2.A.13/EDAETL/ETL_TABLE/ETL_FT_SD_TO_XSIFF/ETL_FT_SD_TO_XSIFF.py", line 187, in do_file
    source_data_df = pd.read_excel(file_path, skiprows=2)
  File "D:\Python37\lib\site-packages\pandas\util\_decorators.py", line 296, in wrapper
    return func(*args, **kwargs)
  File "D:\Python37\lib\site-packages\pandas\io\excel\_base.py", line 304, in read_excel
    io = ExcelFile(io, engine=engine)
  File "D:\Python37\lib\site-packages\pandas\io\excel\_base.py", line 867, in __init__
    self._reader = self._engines[engine](self._io)
  File "D:\Python37\lib\site-packages\pandas\io\excel\_xlrd.py", line 22, in __init__
    super().__init__(filepath_or_buffer)
  File "D:\Python37\lib\site-packages\pandas\io\excel\_base.py", line 353, in __init__
    self.book = self.load_workbook(filepath_or_buffer)
  File "D:\Python37\lib\site-packages\pandas\io\excel\_xlrd.py", line 37, in load_workbook
    return open_workbook(filepath_or_buffer)
  File "D:\Python37\lib\site-packages\xlrd\__init__.py", line 170, in open_workbook
    raise XLRDError(FILE_FORMAT_DESCRIPTIONS[file_format]+'; not supported')
xlrd.biffh.XLRDError: Excel xlsx file; not supported
Stack (most recent call last):
  File "D:/Ina/ETL_XdmLib_2.A.13/ETL_XdmLib_2.A.13/EDAETL/ETL_TABLE/ETL_FT_SD_TO_XSIFF/ETL_FT_SD_TO_XSIFF.py", line 546, in <module>
    skip_file, None, log, config, config_sql)
  File "../..\XdmLib\CustomFuction.py", line 597, in file2db_init
    file, pre_params, db_src, db_tgt)
  File "D:/Ina/ETL_XdmLib_2.A.13/ETL_XdmLib_2.A.13/EDAETL/ETL_TABLE/ETL_FT_SD_TO_XSIFF/ETL_FT_SD_TO_XSIFF.py", line 371, in do_file
    log.error(ex, exc_info=True, stack_info=True)
2023-10-25 11:08:30.592 - __init__   [ERROR   ] File:QG35-CW_GD400TAS100L6S.xlsx Move To Error Folder
                                                Error: None
2023-10-25 11:08:30.675 - ETL_FT_SD_TO_XSIFF [ERROR   ] Excel xlsx file; not supported
Traceback (most recent call last):
  File "D:/Ina/ETL_XdmLib_2.A.13/ETL_XdmLib_2.A.13/EDAETL/ETL_TABLE/ETL_FT_SD_TO_XSIFF/ETL_FT_SD_TO_XSIFF.py", line 187, in do_file
    source_data_df = pd.read_excel(file_path, skiprows=2)
  File "D:\Python37\lib\site-packages\pandas\util\_decorators.py", line 296, in wrapper
    return func(*args, **kwargs)
  File "D:\Python37\lib\site-packages\pandas\io\excel\_base.py", line 304, in read_excel
    io = ExcelFile(io, engine=engine)
  File "D:\Python37\lib\site-packages\pandas\io\excel\_base.py", line 867, in __init__
    self._reader = self._engines[engine](self._io)
  File "D:\Python37\lib\site-packages\pandas\io\excel\_xlrd.py", line 22, in __init__
    super().__init__(filepath_or_buffer)
  File "D:\Python37\lib\site-packages\pandas\io\excel\_base.py", line 353, in __init__
    self.book = self.load_workbook(filepath_or_buffer)
  File "D:\Python37\lib\site-packages\pandas\io\excel\_xlrd.py", line 37, in load_workbook
    return open_workbook(filepath_or_buffer)
  File "D:\Python37\lib\site-packages\xlrd\__init__.py", line 170, in open_workbook
    raise XLRDError(FILE_FORMAT_DESCRIPTIONS[file_format]+'; not supported')
xlrd.biffh.XLRDError: Excel xlsx file; not supported
Stack (most recent call last):
  File "D:/Ina/ETL_XdmLib_2.A.13/ETL_XdmLib_2.A.13/EDAETL/ETL_TABLE/ETL_FT_SD_TO_XSIFF/ETL_FT_SD_TO_XSIFF.py", line 546, in <module>
    skip_file, None, log, config, config_sql)
  File "../..\XdmLib\CustomFuction.py", line 597, in file2db_init
    file, pre_params, db_src, db_tgt)
  File "D:/Ina/ETL_XdmLib_2.A.13/ETL_XdmLib_2.A.13/EDAETL/ETL_TABLE/ETL_FT_SD_TO_XSIFF/ETL_FT_SD_TO_XSIFF.py", line 371, in do_file
    log.error(ex, exc_info=True, stack_info=True)
2023-10-25 11:08:31.390 - __init__   [ERROR   ] File:TLECGQG81-CW_阳光GD200FYS100L6S.xlsx Move To Error Folder
                                                Error: None
2023-10-25 11:08:31.478 - ETL_FT_SD_TO_XSIFF [ERROR   ] Excel xlsx file; not supported
Traceback (most recent call last):
  File "D:/Ina/ETL_XdmLib_2.A.13/ETL_XdmLib_2.A.13/EDAETL/ETL_TABLE/ETL_FT_SD_TO_XSIFF/ETL_FT_SD_TO_XSIFF.py", line 187, in do_file
    source_data_df = pd.read_excel(file_path, skiprows=2)
  File "D:\Python37\lib\site-packages\pandas\util\_decorators.py", line 296, in wrapper
    return func(*args, **kwargs)
  File "D:\Python37\lib\site-packages\pandas\io\excel\_base.py", line 304, in read_excel
    io = ExcelFile(io, engine=engine)
  File "D:\Python37\lib\site-packages\pandas\io\excel\_base.py", line 867, in __init__
    self._reader = self._engines[engine](self._io)
  File "D:\Python37\lib\site-packages\pandas\io\excel\_xlrd.py", line 22, in __init__
    super().__init__(filepath_or_buffer)
  File "D:\Python37\lib\site-packages\pandas\io\excel\_base.py", line 353, in __init__
    self.book = self.load_workbook(filepath_or_buffer)
  File "D:\Python37\lib\site-packages\pandas\io\excel\_xlrd.py", line 37, in load_workbook
    return open_workbook(filepath_or_buffer)
  File "D:\Python37\lib\site-packages\xlrd\__init__.py", line 170, in open_workbook
    raise XLRDError(FILE_FORMAT_DESCRIPTIONS[file_format]+'; not supported')
xlrd.biffh.XLRDError: Excel xlsx file; not supported
Stack (most recent call last):
  File "D:/Ina/ETL_XdmLib_2.A.13/ETL_XdmLib_2.A.13/EDAETL/ETL_TABLE/ETL_FT_SD_TO_XSIFF/ETL_FT_SD_TO_XSIFF.py", line 546, in <module>
    skip_file, None, log, config, config_sql)
  File "../..\XdmLib\CustomFuction.py", line 597, in file2db_init
    file, pre_params, db_src, db_tgt)
  File "D:/Ina/ETL_XdmLib_2.A.13/ETL_XdmLib_2.A.13/EDAETL/ETL_TABLE/ETL_FT_SD_TO_XSIFF/ETL_FT_SD_TO_XSIFF.py", line 371, in do_file
    log.error(ex, exc_info=True, stack_info=True)
2023-10-25 11:08:32.201 - __init__   [ERROR   ] File:XWECYQH20-CW_GD600MLS100L6S.xlsx Move To Error Folder
                                                Error: None
2023-10-25 11:08:32.287 - ETL_FT_SD_TO_XSIFF [ERROR   ] Excel xlsx file; not supported
Traceback (most recent call last):
  File "D:/Ina/ETL_XdmLib_2.A.13/ETL_XdmLib_2.A.13/EDAETL/ETL_TABLE/ETL_FT_SD_TO_XSIFF/ETL_FT_SD_TO_XSIFF.py", line 187, in do_file
    source_data_df = pd.read_excel(file_path, skiprows=2)
  File "D:\Python37\lib\site-packages\pandas\util\_decorators.py", line 296, in wrapper
    return func(*args, **kwargs)
  File "D:\Python37\lib\site-packages\pandas\io\excel\_base.py", line 304, in read_excel
    io = ExcelFile(io, engine=engine)
  File "D:\Python37\lib\site-packages\pandas\io\excel\_base.py", line 867, in __init__
    self._reader = self._engines[engine](self._io)
  File "D:\Python37\lib\site-packages\pandas\io\excel\_xlrd.py", line 22, in __init__
    super().__init__(filepath_or_buffer)
  File "D:\Python37\lib\site-packages\pandas\io\excel\_base.py", line 353, in __init__
    self.book = self.load_workbook(filepath_or_buffer)
  File "D:\Python37\lib\site-packages\pandas\io\excel\_xlrd.py", line 37, in load_workbook
    return open_workbook(filepath_or_buffer)
  File "D:\Python37\lib\site-packages\xlrd\__init__.py", line 170, in open_workbook
    raise XLRDError(FILE_FORMAT_DESCRIPTIONS[file_format]+'; not supported')
xlrd.biffh.XLRDError: Excel xlsx file; not supported
Stack (most recent call last):
  File "D:/Ina/ETL_XdmLib_2.A.13/ETL_XdmLib_2.A.13/EDAETL/ETL_TABLE/ETL_FT_SD_TO_XSIFF/ETL_FT_SD_TO_XSIFF.py", line 546, in <module>
    skip_file, None, log, config, config_sql)
  File "../..\XdmLib\CustomFuction.py", line 597, in file2db_init
    file, pre_params, db_src, db_tgt)
  File "D:/Ina/ETL_XdmLib_2.A.13/ETL_XdmLib_2.A.13/EDAETL/ETL_TABLE/ETL_FT_SD_TO_XSIFF/ETL_FT_SD_TO_XSIFF.py", line 371, in do_file
    log.error(ex, exc_info=True, stack_info=True)
2023-10-25 11:08:33.005 - __init__   [ERROR   ] File:XWECYQH62-GW_GD600MLS100L6S-GW.xlsx Move To Error Folder
                                                Error: None
2023-10-25 15:17:54.816 - ETL_FT_SD_TO_XSIFF [ERROR   ] Excel xlsx file; not supported
Traceback (most recent call last):
  File "D:/Ina/ETL_XdmLib_2.A.13/ETL_XdmLib_2.A.13/EDAETL/ETL_TABLE/ETL_FT_SD_TO_XSIFF/ETL_FT_SD_TO_XSIFF.py", line 187, in do_file
    source_data_df = pd.read_excel(file_path, skiprows=2)
  File "D:\Python37\lib\site-packages\pandas\util\_decorators.py", line 296, in wrapper
    return func(*args, **kwargs)
  File "D:\Python37\lib\site-packages\pandas\io\excel\_base.py", line 304, in read_excel
    io = ExcelFile(io, engine=engine)
  File "D:\Python37\lib\site-packages\pandas\io\excel\_base.py", line 867, in __init__
    self._reader = self._engines[engine](self._io)
  File "D:\Python37\lib\site-packages\pandas\io\excel\_xlrd.py", line 22, in __init__
    super().__init__(filepath_or_buffer)
  File "D:\Python37\lib\site-packages\pandas\io\excel\_base.py", line 353, in __init__
    self.book = self.load_workbook(filepath_or_buffer)
  File "D:\Python37\lib\site-packages\pandas\io\excel\_xlrd.py", line 37, in load_workbook
    return open_workbook(filepath_or_buffer)
  File "D:\Python37\lib\site-packages\xlrd\__init__.py", line 170, in open_workbook
    raise XLRDError(FILE_FORMAT_DESCRIPTIONS[file_format]+'; not supported')
xlrd.biffh.XLRDError: Excel xlsx file; not supported
Stack (most recent call last):
  File "D:/Ina/ETL_XdmLib_2.A.13/ETL_XdmLib_2.A.13/EDAETL/ETL_TABLE/ETL_FT_SD_TO_XSIFF/ETL_FT_SD_TO_XSIFF.py", line 545, in <module>
    skip_file, None, log, config, config_sql)
  File "../..\XdmLib\CustomFuction.py", line 597, in file2db_init
    file, pre_params, db_src, db_tgt)
  File "D:/Ina/ETL_XdmLib_2.A.13/ETL_XdmLib_2.A.13/EDAETL/ETL_TABLE/ETL_FT_SD_TO_XSIFF/ETL_FT_SD_TO_XSIFF.py", line 371, in do_file
    log.error(ex, exc_info=True, stack_info=True)
2023-10-25 15:18:00.414 - __init__   [ERROR   ] File:QG35-CW_GD400TAS100L6S.xlsx Move To Error Folder
                                                Error: None
2023-10-25 15:18:00.510 - ETL_FT_SD_TO_XSIFF [ERROR   ] Excel xlsx file; not supported
Traceback (most recent call last):
  File "D:/Ina/ETL_XdmLib_2.A.13/ETL_XdmLib_2.A.13/EDAETL/ETL_TABLE/ETL_FT_SD_TO_XSIFF/ETL_FT_SD_TO_XSIFF.py", line 187, in do_file
    source_data_df = pd.read_excel(file_path, skiprows=2)
  File "D:\Python37\lib\site-packages\pandas\util\_decorators.py", line 296, in wrapper
    return func(*args, **kwargs)
  File "D:\Python37\lib\site-packages\pandas\io\excel\_base.py", line 304, in read_excel
    io = ExcelFile(io, engine=engine)
  File "D:\Python37\lib\site-packages\pandas\io\excel\_base.py", line 867, in __init__
    self._reader = self._engines[engine](self._io)
  File "D:\Python37\lib\site-packages\pandas\io\excel\_xlrd.py", line 22, in __init__
    super().__init__(filepath_or_buffer)
  File "D:\Python37\lib\site-packages\pandas\io\excel\_base.py", line 353, in __init__
    self.book = self.load_workbook(filepath_or_buffer)
  File "D:\Python37\lib\site-packages\pandas\io\excel\_xlrd.py", line 37, in load_workbook
    return open_workbook(filepath_or_buffer)
  File "D:\Python37\lib\site-packages\xlrd\__init__.py", line 170, in open_workbook
    raise XLRDError(FILE_FORMAT_DESCRIPTIONS[file_format]+'; not supported')
xlrd.biffh.XLRDError: Excel xlsx file; not supported
Stack (most recent call last):
  File "D:/Ina/ETL_XdmLib_2.A.13/ETL_XdmLib_2.A.13/EDAETL/ETL_TABLE/ETL_FT_SD_TO_XSIFF/ETL_FT_SD_TO_XSIFF.py", line 545, in <module>
    skip_file, None, log, config, config_sql)
  File "../..\XdmLib\CustomFuction.py", line 597, in file2db_init
    file, pre_params, db_src, db_tgt)
  File "D:/Ina/ETL_XdmLib_2.A.13/ETL_XdmLib_2.A.13/EDAETL/ETL_TABLE/ETL_FT_SD_TO_XSIFF/ETL_FT_SD_TO_XSIFF.py", line 371, in do_file
    log.error(ex, exc_info=True, stack_info=True)
2023-10-25 15:18:05.660 - __init__   [ERROR   ] File:TLECGQG81-CW_阳光GD200FYS100L6S.xlsx Move To Error Folder
                                                Error: None
2023-10-25 15:18:05.764 - ETL_FT_SD_TO_XSIFF [ERROR   ] Excel xlsx file; not supported
Traceback (most recent call last):
  File "D:/Ina/ETL_XdmLib_2.A.13/ETL_XdmLib_2.A.13/EDAETL/ETL_TABLE/ETL_FT_SD_TO_XSIFF/ETL_FT_SD_TO_XSIFF.py", line 187, in do_file
    source_data_df = pd.read_excel(file_path, skiprows=2)
  File "D:\Python37\lib\site-packages\pandas\util\_decorators.py", line 296, in wrapper
    return func(*args, **kwargs)
  File "D:\Python37\lib\site-packages\pandas\io\excel\_base.py", line 304, in read_excel
    io = ExcelFile(io, engine=engine)
  File "D:\Python37\lib\site-packages\pandas\io\excel\_base.py", line 867, in __init__
    self._reader = self._engines[engine](self._io)
  File "D:\Python37\lib\site-packages\pandas\io\excel\_xlrd.py", line 22, in __init__
    super().__init__(filepath_or_buffer)
  File "D:\Python37\lib\site-packages\pandas\io\excel\_base.py", line 353, in __init__
    self.book = self.load_workbook(filepath_or_buffer)
  File "D:\Python37\lib\site-packages\pandas\io\excel\_xlrd.py", line 37, in load_workbook
    return open_workbook(filepath_or_buffer)
  File "D:\Python37\lib\site-packages\xlrd\__init__.py", line 170, in open_workbook
    raise XLRDError(FILE_FORMAT_DESCRIPTIONS[file_format]+'; not supported')
xlrd.biffh.XLRDError: Excel xlsx file; not supported
Stack (most recent call last):
  File "D:/Ina/ETL_XdmLib_2.A.13/ETL_XdmLib_2.A.13/EDAETL/ETL_TABLE/ETL_FT_SD_TO_XSIFF/ETL_FT_SD_TO_XSIFF.py", line 545, in <module>
    skip_file, None, log, config, config_sql)
  File "../..\XdmLib\CustomFuction.py", line 597, in file2db_init
    file, pre_params, db_src, db_tgt)
  File "D:/Ina/ETL_XdmLib_2.A.13/ETL_XdmLib_2.A.13/EDAETL/ETL_TABLE/ETL_FT_SD_TO_XSIFF/ETL_FT_SD_TO_XSIFF.py", line 371, in do_file
    log.error(ex, exc_info=True, stack_info=True)
2023-10-25 15:18:10.868 - __init__   [ERROR   ] File:XWECYQH20-CW_GD600MLS100L6S.xlsx Move To Error Folder
                                                Error: None
2023-10-25 15:18:10.962 - ETL_FT_SD_TO_XSIFF [ERROR   ] Excel xlsx file; not supported
Traceback (most recent call last):
  File "D:/Ina/ETL_XdmLib_2.A.13/ETL_XdmLib_2.A.13/EDAETL/ETL_TABLE/ETL_FT_SD_TO_XSIFF/ETL_FT_SD_TO_XSIFF.py", line 187, in do_file
    source_data_df = pd.read_excel(file_path, skiprows=2)
  File "D:\Python37\lib\site-packages\pandas\util\_decorators.py", line 296, in wrapper
    return func(*args, **kwargs)
  File "D:\Python37\lib\site-packages\pandas\io\excel\_base.py", line 304, in read_excel
    io = ExcelFile(io, engine=engine)
  File "D:\Python37\lib\site-packages\pandas\io\excel\_base.py", line 867, in __init__
    self._reader = self._engines[engine](self._io)
  File "D:\Python37\lib\site-packages\pandas\io\excel\_xlrd.py", line 22, in __init__
    super().__init__(filepath_or_buffer)
  File "D:\Python37\lib\site-packages\pandas\io\excel\_base.py", line 353, in __init__
    self.book = self.load_workbook(filepath_or_buffer)
  File "D:\Python37\lib\site-packages\pandas\io\excel\_xlrd.py", line 37, in load_workbook
    return open_workbook(filepath_or_buffer)
  File "D:\Python37\lib\site-packages\xlrd\__init__.py", line 170, in open_workbook
    raise XLRDError(FILE_FORMAT_DESCRIPTIONS[file_format]+'; not supported')
xlrd.biffh.XLRDError: Excel xlsx file; not supported
Stack (most recent call last):
  File "D:/Ina/ETL_XdmLib_2.A.13/ETL_XdmLib_2.A.13/EDAETL/ETL_TABLE/ETL_FT_SD_TO_XSIFF/ETL_FT_SD_TO_XSIFF.py", line 545, in <module>
    skip_file, None, log, config, config_sql)
  File "../..\XdmLib\CustomFuction.py", line 597, in file2db_init
    file, pre_params, db_src, db_tgt)
  File "D:/Ina/ETL_XdmLib_2.A.13/ETL_XdmLib_2.A.13/EDAETL/ETL_TABLE/ETL_FT_SD_TO_XSIFF/ETL_FT_SD_TO_XSIFF.py", line 371, in do_file
    log.error(ex, exc_info=True, stack_info=True)
2023-10-25 15:18:16.128 - __init__   [ERROR   ] File:XWECYQH62-GW_GD600MLS100L6S-GW.xlsx Move To Error Folder
                                                Error: None
2023-10-25 15:24:33.853 - ETL_FT_SD_TO_XSIFF [ERROR   ] Excel xlsx file; not supported
Traceback (most recent call last):
  File "D:/Ina/ETL_XdmLib_2.A.13/ETL_XdmLib_2.A.13/EDAETL/ETL_TABLE/ETL_FT_SD_TO_XSIFF/ETL_FT_SD_TO_XSIFF.py", line 187, in do_file
    source_data_df = pd.read_excel(file_path, skiprows=2)
  File "D:\Python37\lib\site-packages\pandas\util\_decorators.py", line 296, in wrapper
    return func(*args, **kwargs)
  File "D:\Python37\lib\site-packages\pandas\io\excel\_base.py", line 304, in read_excel
    io = ExcelFile(io, engine=engine)
  File "D:\Python37\lib\site-packages\pandas\io\excel\_base.py", line 867, in __init__
    self._reader = self._engines[engine](self._io)
  File "D:\Python37\lib\site-packages\pandas\io\excel\_xlrd.py", line 22, in __init__
    super().__init__(filepath_or_buffer)
  File "D:\Python37\lib\site-packages\pandas\io\excel\_base.py", line 353, in __init__
    self.book = self.load_workbook(filepath_or_buffer)
  File "D:\Python37\lib\site-packages\pandas\io\excel\_xlrd.py", line 37, in load_workbook
    return open_workbook(filepath_or_buffer)
  File "D:\Python37\lib\site-packages\xlrd\__init__.py", line 170, in open_workbook
    raise XLRDError(FILE_FORMAT_DESCRIPTIONS[file_format]+'; not supported')
xlrd.biffh.XLRDError: Excel xlsx file; not supported
Stack (most recent call last):
  File "D:/Ina/ETL_XdmLib_2.A.13/ETL_XdmLib_2.A.13/EDAETL/ETL_TABLE/ETL_FT_SD_TO_XSIFF/ETL_FT_SD_TO_XSIFF.py", line 545, in <module>
    skip_file, None, log, config, config_sql)
  File "../..\XdmLib\CustomFuction.py", line 597, in file2db_init
    file, pre_params, db_src, db_tgt)
  File "D:/Ina/ETL_XdmLib_2.A.13/ETL_XdmLib_2.A.13/EDAETL/ETL_TABLE/ETL_FT_SD_TO_XSIFF/ETL_FT_SD_TO_XSIFF.py", line 371, in do_file
    log.error(ex, exc_info=True, stack_info=True)
2023-10-25 15:24:39.108 - __init__   [ERROR   ] File:QG35-CW_GD400TAS100L6S.xlsx Move To Error Folder
                                                Error: None
2023-10-25 15:24:39.189 - ETL_FT_SD_TO_XSIFF [ERROR   ] Excel xlsx file; not supported
Traceback (most recent call last):
  File "D:/Ina/ETL_XdmLib_2.A.13/ETL_XdmLib_2.A.13/EDAETL/ETL_TABLE/ETL_FT_SD_TO_XSIFF/ETL_FT_SD_TO_XSIFF.py", line 187, in do_file
    source_data_df = pd.read_excel(file_path, skiprows=2)
  File "D:\Python37\lib\site-packages\pandas\util\_decorators.py", line 296, in wrapper
    return func(*args, **kwargs)
  File "D:\Python37\lib\site-packages\pandas\io\excel\_base.py", line 304, in read_excel
    io = ExcelFile(io, engine=engine)
  File "D:\Python37\lib\site-packages\pandas\io\excel\_base.py", line 867, in __init__
    self._reader = self._engines[engine](self._io)
  File "D:\Python37\lib\site-packages\pandas\io\excel\_xlrd.py", line 22, in __init__
    super().__init__(filepath_or_buffer)
  File "D:\Python37\lib\site-packages\pandas\io\excel\_base.py", line 353, in __init__
    self.book = self.load_workbook(filepath_or_buffer)
  File "D:\Python37\lib\site-packages\pandas\io\excel\_xlrd.py", line 37, in load_workbook
    return open_workbook(filepath_or_buffer)
  File "D:\Python37\lib\site-packages\xlrd\__init__.py", line 170, in open_workbook
    raise XLRDError(FILE_FORMAT_DESCRIPTIONS[file_format]+'; not supported')
xlrd.biffh.XLRDError: Excel xlsx file; not supported
Stack (most recent call last):
  File "D:/Ina/ETL_XdmLib_2.A.13/ETL_XdmLib_2.A.13/EDAETL/ETL_TABLE/ETL_FT_SD_TO_XSIFF/ETL_FT_SD_TO_XSIFF.py", line 545, in <module>
    skip_file, None, log, config, config_sql)
  File "../..\XdmLib\CustomFuction.py", line 597, in file2db_init
    file, pre_params, db_src, db_tgt)
  File "D:/Ina/ETL_XdmLib_2.A.13/ETL_XdmLib_2.A.13/EDAETL/ETL_TABLE/ETL_FT_SD_TO_XSIFF/ETL_FT_SD_TO_XSIFF.py", line 371, in do_file
    log.error(ex, exc_info=True, stack_info=True)
2023-10-25 15:24:44.309 - __init__   [ERROR   ] File:TLECGQG81-CW_阳光GD200FYS100L6S.xlsx Move To Error Folder
                                                Error: None
2023-10-25 15:24:44.402 - ETL_FT_SD_TO_XSIFF [ERROR   ] Excel xlsx file; not supported
Traceback (most recent call last):
  File "D:/Ina/ETL_XdmLib_2.A.13/ETL_XdmLib_2.A.13/EDAETL/ETL_TABLE/ETL_FT_SD_TO_XSIFF/ETL_FT_SD_TO_XSIFF.py", line 187, in do_file
    source_data_df = pd.read_excel(file_path, skiprows=2)
  File "D:\Python37\lib\site-packages\pandas\util\_decorators.py", line 296, in wrapper
    return func(*args, **kwargs)
  File "D:\Python37\lib\site-packages\pandas\io\excel\_base.py", line 304, in read_excel
    io = ExcelFile(io, engine=engine)
  File "D:\Python37\lib\site-packages\pandas\io\excel\_base.py", line 867, in __init__
    self._reader = self._engines[engine](self._io)
  File "D:\Python37\lib\site-packages\pandas\io\excel\_xlrd.py", line 22, in __init__
    super().__init__(filepath_or_buffer)
  File "D:\Python37\lib\site-packages\pandas\io\excel\_base.py", line 353, in __init__
    self.book = self.load_workbook(filepath_or_buffer)
  File "D:\Python37\lib\site-packages\pandas\io\excel\_xlrd.py", line 37, in load_workbook
    return open_workbook(filepath_or_buffer)
  File "D:\Python37\lib\site-packages\xlrd\__init__.py", line 170, in open_workbook
    raise XLRDError(FILE_FORMAT_DESCRIPTIONS[file_format]+'; not supported')
xlrd.biffh.XLRDError: Excel xlsx file; not supported
Stack (most recent call last):
  File "D:/Ina/ETL_XdmLib_2.A.13/ETL_XdmLib_2.A.13/EDAETL/ETL_TABLE/ETL_FT_SD_TO_XSIFF/ETL_FT_SD_TO_XSIFF.py", line 545, in <module>
    skip_file, None, log, config, config_sql)
  File "../..\XdmLib\CustomFuction.py", line 597, in file2db_init
    file, pre_params, db_src, db_tgt)
  File "D:/Ina/ETL_XdmLib_2.A.13/ETL_XdmLib_2.A.13/EDAETL/ETL_TABLE/ETL_FT_SD_TO_XSIFF/ETL_FT_SD_TO_XSIFF.py", line 371, in do_file
    log.error(ex, exc_info=True, stack_info=True)
2023-10-25 15:24:49.570 - __init__   [ERROR   ] File:XWECYQH20-CW_GD600MLS100L6S.xlsx Move To Error Folder
                                                Error: None
2023-10-25 15:24:49.664 - ETL_FT_SD_TO_XSIFF [ERROR   ] Excel xlsx file; not supported
Traceback (most recent call last):
  File "D:/Ina/ETL_XdmLib_2.A.13/ETL_XdmLib_2.A.13/EDAETL/ETL_TABLE/ETL_FT_SD_TO_XSIFF/ETL_FT_SD_TO_XSIFF.py", line 187, in do_file
    source_data_df = pd.read_excel(file_path, skiprows=2)
  File "D:\Python37\lib\site-packages\pandas\util\_decorators.py", line 296, in wrapper
    return func(*args, **kwargs)
  File "D:\Python37\lib\site-packages\pandas\io\excel\_base.py", line 304, in read_excel
    io = ExcelFile(io, engine=engine)
  File "D:\Python37\lib\site-packages\pandas\io\excel\_base.py", line 867, in __init__
    self._reader = self._engines[engine](self._io)
  File "D:\Python37\lib\site-packages\pandas\io\excel\_xlrd.py", line 22, in __init__
    super().__init__(filepath_or_buffer)
  File "D:\Python37\lib\site-packages\pandas\io\excel\_base.py", line 353, in __init__
    self.book = self.load_workbook(filepath_or_buffer)
  File "D:\Python37\lib\site-packages\pandas\io\excel\_xlrd.py", line 37, in load_workbook
    return open_workbook(filepath_or_buffer)
  File "D:\Python37\lib\site-packages\xlrd\__init__.py", line 170, in open_workbook
    raise XLRDError(FILE_FORMAT_DESCRIPTIONS[file_format]+'; not supported')
xlrd.biffh.XLRDError: Excel xlsx file; not supported
Stack (most recent call last):
  File "D:/Ina/ETL_XdmLib_2.A.13/ETL_XdmLib_2.A.13/EDAETL/ETL_TABLE/ETL_FT_SD_TO_XSIFF/ETL_FT_SD_TO_XSIFF.py", line 545, in <module>
    skip_file, None, log, config, config_sql)
  File "../..\XdmLib\CustomFuction.py", line 597, in file2db_init
    file, pre_params, db_src, db_tgt)
  File "D:/Ina/ETL_XdmLib_2.A.13/ETL_XdmLib_2.A.13/EDAETL/ETL_TABLE/ETL_FT_SD_TO_XSIFF/ETL_FT_SD_TO_XSIFF.py", line 371, in do_file
    log.error(ex, exc_info=True, stack_info=True)
2023-10-25 15:24:54.831 - __init__   [ERROR   ] File:XWECYQH62-GW_GD600MLS100L6S-GW.xlsx Move To Error Folder
                                                Error: None
2023-10-25 15:36:51.463 - __init__   [ERROR   ] File:QG35-CW_GD400TAS100L6S.xlsx Move To Error Folder
                                                Error: None
2023-10-25 15:36:52.465 - ETL_FT_SD_TO_XSIFF [ERROR   ] local variable 'result' referenced before assignment
Traceback (most recent call last):
  File "D:\Ina\ETL_XdmLib_2.A.13\ETL_XdmLib_2.A.13\EDAETL\ETL_TABLE\ETL_FT_SD_TO_XSIFF\ETL_FT_SD_TO_XSIFF.py", line 446, in do_file
    return result
UnboundLocalError: local variable 'result' referenced before assignment
Stack (most recent call last):
  File "D:\Ina\ETL_XdmLib_2.A.13\ETL_XdmLib_2.A.13\EDAETL\ETL_TABLE\ETL_FT_SD_TO_XSIFF\ETL_FT_SD_TO_XSIFF.py", line 544, in <module>
    XdmLib.CustomFuction.file2db_init(do_file, before_do_file, after_do_file,
  File "D:\Ina\ETL_XdmLib_2.A.13\ETL_XdmLib_2.A.13\EDAETL\ETL_TABLE\ETL_FT_SD_TO_XSIFF\../..\XdmLib\CustomFuction.py", line 596, in file2db_init
    res = do_file(file_root_source_path,
  File "D:\Ina\ETL_XdmLib_2.A.13\ETL_XdmLib_2.A.13\EDAETL\ETL_TABLE\ETL_FT_SD_TO_XSIFF\ETL_FT_SD_TO_XSIFF.py", line 449, in do_file
    log.error(ex, exc_info=True, stack_info=True)
2023-10-25 15:36:59.894 - __init__   [ERROR   ] File:TLECGQG81-CW_阳光GD200FYS100L6S.xlsx Move To Error Folder
                                                Error: None
2023-10-25 15:37:03.036 - ETL_FT_SD_TO_XSIFF [ERROR   ] local variable 'result' referenced before assignment
Traceback (most recent call last):
  File "D:\Ina\ETL_XdmLib_2.A.13\ETL_XdmLib_2.A.13\EDAETL\ETL_TABLE\ETL_FT_SD_TO_XSIFF\ETL_FT_SD_TO_XSIFF.py", line 446, in do_file
    return result
UnboundLocalError: local variable 'result' referenced before assignment
Stack (most recent call last):
  File "D:\Ina\ETL_XdmLib_2.A.13\ETL_XdmLib_2.A.13\EDAETL\ETL_TABLE\ETL_FT_SD_TO_XSIFF\ETL_FT_SD_TO_XSIFF.py", line 544, in <module>
    XdmLib.CustomFuction.file2db_init(do_file, before_do_file, after_do_file,
  File "D:\Ina\ETL_XdmLib_2.A.13\ETL_XdmLib_2.A.13\EDAETL\ETL_TABLE\ETL_FT_SD_TO_XSIFF\../..\XdmLib\CustomFuction.py", line 596, in file2db_init
    res = do_file(file_root_source_path,
  File "D:\Ina\ETL_XdmLib_2.A.13\ETL_XdmLib_2.A.13\EDAETL\ETL_TABLE\ETL_FT_SD_TO_XSIFF\ETL_FT_SD_TO_XSIFF.py", line 449, in do_file
    log.error(ex, exc_info=True, stack_info=True)
2023-10-25 15:37:10.323 - __init__   [ERROR   ] File:XWECYQH20-CW_GD600MLS100L6S.xlsx Move To Error Folder
                                                Error: None
2023-10-25 15:37:11.926 - ETL_FT_SD_TO_XSIFF [ERROR   ] local variable 'result' referenced before assignment
Traceback (most recent call last):
  File "D:\Ina\ETL_XdmLib_2.A.13\ETL_XdmLib_2.A.13\EDAETL\ETL_TABLE\ETL_FT_SD_TO_XSIFF\ETL_FT_SD_TO_XSIFF.py", line 446, in do_file
    return result
UnboundLocalError: local variable 'result' referenced before assignment
Stack (most recent call last):
  File "D:\Ina\ETL_XdmLib_2.A.13\ETL_XdmLib_2.A.13\EDAETL\ETL_TABLE\ETL_FT_SD_TO_XSIFF\ETL_FT_SD_TO_XSIFF.py", line 544, in <module>
    XdmLib.CustomFuction.file2db_init(do_file, before_do_file, after_do_file,
  File "D:\Ina\ETL_XdmLib_2.A.13\ETL_XdmLib_2.A.13\EDAETL\ETL_TABLE\ETL_FT_SD_TO_XSIFF\../..\XdmLib\CustomFuction.py", line 596, in file2db_init
    res = do_file(file_root_source_path,
  File "D:\Ina\ETL_XdmLib_2.A.13\ETL_XdmLib_2.A.13\EDAETL\ETL_TABLE\ETL_FT_SD_TO_XSIFF\ETL_FT_SD_TO_XSIFF.py", line 449, in do_file
    log.error(ex, exc_info=True, stack_info=True)
2023-10-25 15:37:19.339 - __init__   [ERROR   ] File:XWECYQH62-GW_GD600MLS100L6S-GW.xlsx Move To Error Folder
                                                Error: None
2023-10-25 15:50:00.830 - __init__   [ERROR   ] File:QG35-CW_GD400TAS100L6S.xlsx Move To Error Folder
                                                Error: None
2023-10-25 15:50:01.579 - CustomFuction [ERROR   ] 'data'
Traceback (most recent call last):
  File "D:\Ina\ETL_XdmLib_2.A.13\ETL_XdmLib_2.A.13\EDAETL\ETL_TABLE\ETL_FT_SD_TO_XSIFF\../..\XdmLib\CustomFuction.py", line 598, in file2db_init
    analysis_res.append(res['data'])
KeyError: 'data'
Stack (most recent call last):
  File "D:\Ina\ETL_XdmLib_2.A.13\ETL_XdmLib_2.A.13\EDAETL\ETL_TABLE\ETL_FT_SD_TO_XSIFF\ETL_FT_SD_TO_XSIFF.py", line 575, in <module>
    XdmLib.CustomFuction.file2db_init(do_file, before_do_file, after_do_file,
  File "D:\Ina\ETL_XdmLib_2.A.13\ETL_XdmLib_2.A.13\EDAETL\ETL_TABLE\ETL_FT_SD_TO_XSIFF\../..\XdmLib\CustomFuction.py", line 631, in file2db_init
    log.error(ex, exc_info=True, stack_info=True)
2023-10-25 15:50:11.650 - CustomFuction [ERROR   ] 'data'
Traceback (most recent call last):
  File "D:\Ina\ETL_XdmLib_2.A.13\ETL_XdmLib_2.A.13\EDAETL\ETL_TABLE\ETL_FT_SD_TO_XSIFF\../..\XdmLib\CustomFuction.py", line 598, in file2db_init
    analysis_res.append(res['data'])
KeyError: 'data'
Stack (most recent call last):
  File "D:\Ina\ETL_XdmLib_2.A.13\ETL_XdmLib_2.A.13\EDAETL\ETL_TABLE\ETL_FT_SD_TO_XSIFF\ETL_FT_SD_TO_XSIFF.py", line 575, in <module>
    XdmLib.CustomFuction.file2db_init(do_file, before_do_file, after_do_file,
  File "D:\Ina\ETL_XdmLib_2.A.13\ETL_XdmLib_2.A.13\EDAETL\ETL_TABLE\ETL_FT_SD_TO_XSIFF\../..\XdmLib\CustomFuction.py", line 631, in file2db_init
    log.error(ex, exc_info=True, stack_info=True)
2023-10-25 15:50:22.322 - CustomFuction [ERROR   ] 'data'
Traceback (most recent call last):
  File "D:\Ina\ETL_XdmLib_2.A.13\ETL_XdmLib_2.A.13\EDAETL\ETL_TABLE\ETL_FT_SD_TO_XSIFF\../..\XdmLib\CustomFuction.py", line 598, in file2db_init
    analysis_res.append(res['data'])
KeyError: 'data'
Stack (most recent call last):
  File "D:\Ina\ETL_XdmLib_2.A.13\ETL_XdmLib_2.A.13\EDAETL\ETL_TABLE\ETL_FT_SD_TO_XSIFF\ETL_FT_SD_TO_XSIFF.py", line 575, in <module>
    XdmLib.CustomFuction.file2db_init(do_file, before_do_file, after_do_file,
  File "D:\Ina\ETL_XdmLib_2.A.13\ETL_XdmLib_2.A.13\EDAETL\ETL_TABLE\ETL_FT_SD_TO_XSIFF\../..\XdmLib\CustomFuction.py", line 631, in file2db_init
    log.error(ex, exc_info=True, stack_info=True)
2023-10-25 15:52:48.603 - __init__   [ERROR   ] File:QG35-CW_GD400TAS100L6S.xlsx Move To Error Folder
                                                Error: None
2023-10-25 15:52:49.259 - CustomFuction [ERROR   ] 'status'
Traceback (most recent call last):
  File "D:\Ina\ETL_XdmLib_2.A.13\ETL_XdmLib_2.A.13\EDAETL\ETL_TABLE\ETL_FT_SD_TO_XSIFF\../..\XdmLib\CustomFuction.py", line 604, in file2db_init
    if res['status'] == 'archive':
KeyError: 'status'
Stack (most recent call last):
  File "D:\Ina\ETL_XdmLib_2.A.13\ETL_XdmLib_2.A.13\EDAETL\ETL_TABLE\ETL_FT_SD_TO_XSIFF\ETL_FT_SD_TO_XSIFF.py", line 575, in <module>
    XdmLib.CustomFuction.file2db_init(do_file, before_do_file, after_do_file,
  File "D:\Ina\ETL_XdmLib_2.A.13\ETL_XdmLib_2.A.13\EDAETL\ETL_TABLE\ETL_FT_SD_TO_XSIFF\../..\XdmLib\CustomFuction.py", line 631, in file2db_init
    log.error(ex, exc_info=True, stack_info=True)
2023-10-25 15:52:59.063 - CustomFuction [ERROR   ] 'status'
Traceback (most recent call last):
  File "D:\Ina\ETL_XdmLib_2.A.13\ETL_XdmLib_2.A.13\EDAETL\ETL_TABLE\ETL_FT_SD_TO_XSIFF\../..\XdmLib\CustomFuction.py", line 604, in file2db_init
    if res['status'] == 'archive':
KeyError: 'status'
Stack (most recent call last):
  File "D:\Ina\ETL_XdmLib_2.A.13\ETL_XdmLib_2.A.13\EDAETL\ETL_TABLE\ETL_FT_SD_TO_XSIFF\ETL_FT_SD_TO_XSIFF.py", line 575, in <module>
    XdmLib.CustomFuction.file2db_init(do_file, before_do_file, after_do_file,
  File "D:\Ina\ETL_XdmLib_2.A.13\ETL_XdmLib_2.A.13\EDAETL\ETL_TABLE\ETL_FT_SD_TO_XSIFF\../..\XdmLib\CustomFuction.py", line 631, in file2db_init
    log.error(ex, exc_info=True, stack_info=True)
2023-10-25 15:53:08.753 - CustomFuction [ERROR   ] 'status'
Traceback (most recent call last):
  File "D:\Ina\ETL_XdmLib_2.A.13\ETL_XdmLib_2.A.13\EDAETL\ETL_TABLE\ETL_FT_SD_TO_XSIFF\../..\XdmLib\CustomFuction.py", line 604, in file2db_init
    if res['status'] == 'archive':
KeyError: 'status'
Stack (most recent call last):
  File "D:\Ina\ETL_XdmLib_2.A.13\ETL_XdmLib_2.A.13\EDAETL\ETL_TABLE\ETL_FT_SD_TO_XSIFF\ETL_FT_SD_TO_XSIFF.py", line 575, in <module>
    XdmLib.CustomFuction.file2db_init(do_file, before_do_file, after_do_file,
  File "D:\Ina\ETL_XdmLib_2.A.13\ETL_XdmLib_2.A.13\EDAETL\ETL_TABLE\ETL_FT_SD_TO_XSIFF\../..\XdmLib\CustomFuction.py", line 631, in file2db_init
    log.error(ex, exc_info=True, stack_info=True)
2023-10-25 16:27:25.507 - ETL_FT_SD_TO_XSIFF [ERROR   ] list index out of range
Traceback (most recent call last):
  File "D:\Ina\ETL_XdmLib_2.A.13\ETL_XdmLib_2.A.13\EDAETL\ETL_TABLE\ETL_FT_SD_TO_XSIFF\ETL_FT_SD_TO_XSIFF.py", line 212, in do_file
    FtLot = temp_value.split(' ')[1][:9]
IndexError: list index out of range
Stack (most recent call last):
  File "D:\Ina\ETL_XdmLib_2.A.13\ETL_XdmLib_2.A.13\EDAETL\ETL_TABLE\ETL_FT_SD_TO_XSIFF\ETL_FT_SD_TO_XSIFF.py", line 564, in <module>
    XdmLib.CustomFuction.file2db_init(do_file, before_do_file, after_do_file,
  File "D:\Ina\ETL_XdmLib_2.A.13\ETL_XdmLib_2.A.13\EDAETL\ETL_TABLE\ETL_FT_SD_TO_XSIFF\../..\XdmLib\CustomFuction.py", line 596, in file2db_init
    res = do_file(file_root_source_path,
  File "D:\Ina\ETL_XdmLib_2.A.13\ETL_XdmLib_2.A.13\EDAETL\ETL_TABLE\ETL_FT_SD_TO_XSIFF\ETL_FT_SD_TO_XSIFF.py", line 382, in do_file
    log.error(ex, exc_info=True, stack_info=True)
2023-10-25 16:27:32.827 - __init__   [ERROR   ] File:QG35-CW_GD400TAS100L6S.xlsx Move To Error Folder
                                                Error: None
2023-10-25 16:27:33.081 - ETL_FT_SD_TO_XSIFF [ERROR   ] name 'logging' is not defined
Traceback (most recent call last):
  File "D:\Ina\ETL_XdmLib_2.A.13\ETL_XdmLib_2.A.13\EDAETL\ETL_TABLE\ETL_FT_SD_TO_XSIFF\ETL_FT_SD_TO_XSIFF.py", line 324, in do_file
    logging.error(log_message)
NameError: name 'logging' is not defined
Stack (most recent call last):
  File "D:\Ina\ETL_XdmLib_2.A.13\ETL_XdmLib_2.A.13\EDAETL\ETL_TABLE\ETL_FT_SD_TO_XSIFF\ETL_FT_SD_TO_XSIFF.py", line 564, in <module>
    XdmLib.CustomFuction.file2db_init(do_file, before_do_file, after_do_file,
  File "D:\Ina\ETL_XdmLib_2.A.13\ETL_XdmLib_2.A.13\EDAETL\ETL_TABLE\ETL_FT_SD_TO_XSIFF\../..\XdmLib\CustomFuction.py", line 596, in file2db_init
    res = do_file(file_root_source_path,
  File "D:\Ina\ETL_XdmLib_2.A.13\ETL_XdmLib_2.A.13\EDAETL\ETL_TABLE\ETL_FT_SD_TO_XSIFF\ETL_FT_SD_TO_XSIFF.py", line 382, in do_file
    log.error(ex, exc_info=True, stack_info=True)
2023-10-25 16:27:40.356 - __init__   [ERROR   ] File:TLECGQG81-CW_阳光GD200FYS100L6S.xlsx Move To Error Folder
                                                Error: None
2023-10-25 16:27:41.085 - ETL_FT_SD_TO_XSIFF [ERROR   ] name 'logging' is not defined
Traceback (most recent call last):
  File "D:\Ina\ETL_XdmLib_2.A.13\ETL_XdmLib_2.A.13\EDAETL\ETL_TABLE\ETL_FT_SD_TO_XSIFF\ETL_FT_SD_TO_XSIFF.py", line 324, in do_file
    logging.error(log_message)
NameError: name 'logging' is not defined
Stack (most recent call last):
  File "D:\Ina\ETL_XdmLib_2.A.13\ETL_XdmLib_2.A.13\EDAETL\ETL_TABLE\ETL_FT_SD_TO_XSIFF\ETL_FT_SD_TO_XSIFF.py", line 564, in <module>
    XdmLib.CustomFuction.file2db_init(do_file, before_do_file, after_do_file,
  File "D:\Ina\ETL_XdmLib_2.A.13\ETL_XdmLib_2.A.13\EDAETL\ETL_TABLE\ETL_FT_SD_TO_XSIFF\../..\XdmLib\CustomFuction.py", line 596, in file2db_init
    res = do_file(file_root_source_path,
  File "D:\Ina\ETL_XdmLib_2.A.13\ETL_XdmLib_2.A.13\EDAETL\ETL_TABLE\ETL_FT_SD_TO_XSIFF\ETL_FT_SD_TO_XSIFF.py", line 382, in do_file
    log.error(ex, exc_info=True, stack_info=True)
2023-10-25 16:27:48.342 - __init__   [ERROR   ] File:XWECYQH20-CW_GD600MLS100L6S.xlsx Move To Error Folder
                                                Error: None
2023-10-25 16:27:48.965 - ETL_FT_SD_TO_XSIFF [ERROR   ] name 'logging' is not defined
Traceback (most recent call last):
  File "D:\Ina\ETL_XdmLib_2.A.13\ETL_XdmLib_2.A.13\EDAETL\ETL_TABLE\ETL_FT_SD_TO_XSIFF\ETL_FT_SD_TO_XSIFF.py", line 324, in do_file
    logging.error(log_message)
NameError: name 'logging' is not defined
Stack (most recent call last):
  File "D:\Ina\ETL_XdmLib_2.A.13\ETL_XdmLib_2.A.13\EDAETL\ETL_TABLE\ETL_FT_SD_TO_XSIFF\ETL_FT_SD_TO_XSIFF.py", line 564, in <module>
    XdmLib.CustomFuction.file2db_init(do_file, before_do_file, after_do_file,
  File "D:\Ina\ETL_XdmLib_2.A.13\ETL_XdmLib_2.A.13\EDAETL\ETL_TABLE\ETL_FT_SD_TO_XSIFF\../..\XdmLib\CustomFuction.py", line 596, in file2db_init
    res = do_file(file_root_source_path,
  File "D:\Ina\ETL_XdmLib_2.A.13\ETL_XdmLib_2.A.13\EDAETL\ETL_TABLE\ETL_FT_SD_TO_XSIFF\ETL_FT_SD_TO_XSIFF.py", line 382, in do_file
    log.error(ex, exc_info=True, stack_info=True)
2023-10-25 16:27:56.137 - __init__   [ERROR   ] File:XWECYQH62-GW_GD600MLS100L6S-GW.xlsx Move To Error Folder
                                                Error: None
2023-10-25 16:34:01.945 - __init__   [ERROR   ] File:QG35-CW_GD400TAS100L6S.xlsx Move To Error Folder
                                                Error: None
2023-10-25 16:34:02.239 - ETL_FT_SD_TO_XSIFF [ERROR   ] 缺少有效表头，列名包含数字: L1[(V)]
2023-10-25 16:34:09.563 - __init__   [ERROR   ] File:TLECGQG81-CW_阳光GD200FYS100L6S.xlsx Move To Error Folder
                                                Error: None
2023-10-25 16:34:10.335 - ETL_FT_SD_TO_XSIFF [ERROR   ] 缺少有效表头，列名包含数字: L1[(V)]
2023-10-25 16:34:17.660 - __init__   [ERROR   ] File:XWECYQH20-CW_GD600MLS100L6S.xlsx Move To Error Folder
                                                Error: None
2023-10-25 16:34:18.320 - ETL_FT_SD_TO_XSIFF [ERROR   ] 缺少有效表头，列名包含数字: L1[(V)]
2023-10-25 16:34:25.608 - __init__   [ERROR   ] File:XWECYQH62-GW_GD600MLS100L6S-GW.xlsx Move To Error Folder
                                                Error: None
2023-10-25 16:41:44.697 - __init__   [ERROR   ] File:QG35-CW_GD400TAS100L6S.xlsx Move To Error Folder
                                                Error: None
2023-10-25 17:28:18.845 - base       [ERROR   ] Exception during reset or similar
Traceback (most recent call last):
  File "D:\soft\anaconda3\lib\site-packages\sqlalchemy\pool\base.py", line 739, in _finalize_fairy
    fairy._reset(pool)
  File "D:\soft\anaconda3\lib\site-packages\sqlalchemy\pool\base.py", line 988, in _reset
    pool._dialect.do_rollback(self)
  File "D:\soft\anaconda3\lib\site-packages\sqlalchemy\engine\default.py", line 682, in do_rollback
    dbapi_connection.rollback()
KeyboardInterrupt
2023-10-25 17:30:13.988 - ETL_FT_SD_TO_XSIFF [ERROR   ] Not the correct documentation:  [Serial no.] This column is numeric only.
2023-10-25 17:30:21.307 - __init__   [ERROR   ] File:QG35-CW_GD400TAS100L6S.xlsx Move To Error Folder
                                                Error: None
2023-10-25 17:30:23.191 - ETL_FT_SD_TO_XSIFF [ERROR   ] name 'logging' is not defined
Traceback (most recent call last):
  File "D:\Ina\ETL_XdmLib_2.A.13\ETL_XdmLib_2.A.13\EDAETL\ETL_TABLE\ETL_FT_SD_TO_XSIFF\ETL_FT_SD_TO_XSIFF.py", line 357, in do_file
    logging.error(log_message)
NameError: name 'logging' is not defined

During handling of the above exception, another exception occurred:

Traceback (most recent call last):
  File "D:\Ina\ETL_XdmLib_2.A.13\ETL_XdmLib_2.A.13\EDAETL\ETL_TABLE\ETL_FT_SD_TO_XSIFF\ETL_FT_SD_TO_XSIFF.py", line 366, in do_file
    logging.error(log_message)
NameError: name 'logging' is not defined
Stack (most recent call last):
  File "D:\Ina\ETL_XdmLib_2.A.13\ETL_XdmLib_2.A.13\EDAETL\ETL_TABLE\ETL_FT_SD_TO_XSIFF\ETL_FT_SD_TO_XSIFF.py", line 574, in <module>
    XdmLib.CustomFuction.file2db_init(do_file, before_do_file, after_do_file,
  File "D:\Ina\ETL_XdmLib_2.A.13\ETL_XdmLib_2.A.13\EDAETL\ETL_TABLE\ETL_FT_SD_TO_XSIFF\../..\XdmLib\CustomFuction.py", line 596, in file2db_init
    res = do_file(file_root_source_path,
  File "D:\Ina\ETL_XdmLib_2.A.13\ETL_XdmLib_2.A.13\EDAETL\ETL_TABLE\ETL_FT_SD_TO_XSIFF\ETL_FT_SD_TO_XSIFF.py", line 394, in do_file
    log.error(ex, exc_info=True, stack_info=True)
2023-10-25 17:30:30.494 - __init__   [ERROR   ] File:XWECYQH62-GW_GD600MLS100L6S-GW.xlsx Move To Error Folder
                                                Error: None
2023-10-25 17:31:46.214 - ETL_FT_SD_TO_XSIFF [ERROR   ] Not the correct documentation:  [Serial no.] This column is numeric only.
2023-10-25 17:31:53.519 - __init__   [ERROR   ] File:QG35-CW_GD400TAS100L6S.xlsx Move To Error Folder
                                                Error: None
2023-10-25 17:31:55.232 - ETL_FT_SD_TO_XSIFF [ERROR   ] 参数值不符合要求，包含非数值型或非空值的值: -1.00
2023-10-25 17:32:02.522 - __init__   [ERROR   ] File:XWECYQH62-GW_GD600MLS100L6S-GW.xlsx Move To Error Folder
                                                Error: None
2023-10-25 17:40:30.117 - ETL_FT_SD_TO_XSIFF [ERROR   ] Not the correct documentation:  [Serial no.] This column is numeric only.
2023-10-25 17:40:33.061 - __init__   [ERROR   ] File:QG35-CW_GD400TAS100L6S.xlsx Move To Error Folder
                                                Error: None
2023-10-25 17:40:34.833 - ETL_FT_SD_TO_XSIFF [ERROR   ] 参数值不符合要求，包含非数值型或非空值的值: ∞
2023-10-25 17:40:37.772 - __init__   [ERROR   ] File:XWECYQH62-GW_GD600MLS100L6S-GW.xlsx Move To Error Folder
                                                Error: None
