2023-07-07 11:24:02.752 - CustomFuction [ERROR   ] 'WAFER_KEY'
Traceback (most recent call last):
  File "D:\soft\anaconda3\lib\site-packages\pandas\core\indexes\base.py", line 3621, in get_loc
    return self._engine.get_loc(casted_key)
  File "pandas\_libs\index.pyx", line 136, in pandas._libs.index.IndexEngine.get_loc
  File "pandas\_libs\index.pyx", line 163, in pandas._libs.index.IndexEngine.get_loc
  File "pandas\_libs\hashtable_class_helper.pxi", line 5198, in pandas._libs.hashtable.PyObjectHashTable.get_item
  File "pandas\_libs\hashtable_class_helper.pxi", line 5206, in pandas._libs.hashtable.PyObjectHashTable.get_item
KeyError: 'WAFER_KEY'

The above exception was the direct cause of the following exception:

Traceback (most recent call last):
  File "D:\INA\ETL_XdmLib_2.A.13\ETL_XdmLib_2.A.13\EDAETL\ETL_TABLE\DBtoDB_TEST_INA\../..\XdmLib\CustomFuction.py", line 103, in db2db_his_init_fullUpdate
    main_logic(db_src, db_tgt)
  File "D:\INA\ETL_XdmLib_2.A.13\ETL_XdmLib_2.A.13\EDAETL\ETL_TABLE\DBtoDB_TEST_INA\TEST_INA_DEFECT_Q5_RESULT.py", line 76, in main_logic
    row['WAFER_KEY'], row['DEFECT_ITEM']))
  File "D:\soft\anaconda3\lib\site-packages\pandas\core\series.py", line 958, in __getitem__
    return self._get_value(key)
  File "D:\soft\anaconda3\lib\site-packages\pandas\core\series.py", line 1069, in _get_value
    loc = self.index.get_loc(label)
  File "D:\soft\anaconda3\lib\site-packages\pandas\core\indexes\base.py", line 3623, in get_loc
    raise KeyError(key) from err
KeyError: 'WAFER_KEY'
Stack (most recent call last):
  File "D:\INA\ETL_XdmLib_2.A.13\ETL_XdmLib_2.A.13\EDAETL\ETL_TABLE\DBtoDB_TEST_INA\TEST_INA_DEFECT_Q5_RESULT.py", line 127, in <module>
    XdmLib.CustomFuction.db2db_his_init_fullUpdate(
  File "D:\INA\ETL_XdmLib_2.A.13\ETL_XdmLib_2.A.13\EDAETL\ETL_TABLE\DBtoDB_TEST_INA\../..\XdmLib\CustomFuction.py", line 118, in db2db_his_init_fullUpdate
    log.error(ex, exc_info=True, stack_info=True)
2023-07-07 11:24:08.063 - __init__   [ERROR   ] 程序运行错误,错误见明细
                                                Error: 'WAFER_KEY'
2023-07-07 11:57:56.000 - CustomFuction [ERROR   ] ORA-00933: SQL 命令未正确结束
Traceback (most recent call last):
  File "D:\INA\ETL_XdmLib_2.A.13\ETL_XdmLib_2.A.13\EDAETL\ETL_TABLE\DBtoDB_TEST_INA\../..\XdmLib\CustomFuction.py", line 103, in db2db_his_init_fullUpdate
    main_logic(db_src, db_tgt)
  File "D:\INA\ETL_XdmLib_2.A.13\ETL_XdmLib_2.A.13\EDAETL\ETL_TABLE\DBtoDB_TEST_INA\TEST_INA_DEFECT_Q5_RESULT.py", line 55, in main_logic
    result = db_src.execute(
  File "D:\INA\ETL_XdmLib_2.A.13\ETL_XdmLib_2.A.13\EDAETL\ETL_TABLE\DBtoDB_TEST_INA\../..\XdmLib\Database.py", line 248, in execute
    return self.cursor.execute(statement , *parameters,**keywordParameters)
cx_Oracle.DatabaseError: ORA-00933: SQL 命令未正确结束
Stack (most recent call last):
  File "D:\INA\ETL_XdmLib_2.A.13\ETL_XdmLib_2.A.13\EDAETL\ETL_TABLE\DBtoDB_TEST_INA\TEST_INA_DEFECT_Q5_RESULT.py", line 127, in <module>
    XdmLib.CustomFuction.db2db_his_init_fullUpdate(
  File "D:\INA\ETL_XdmLib_2.A.13\ETL_XdmLib_2.A.13\EDAETL\ETL_TABLE\DBtoDB_TEST_INA\../..\XdmLib\CustomFuction.py", line 118, in db2db_his_init_fullUpdate
    log.error(ex, exc_info=True, stack_info=True)
2023-07-07 11:58:01.247 - __init__   [ERROR   ] 程序运行错误,错误见明细
                                                Error: ORA-00933: SQL 命令未正确结束
2023-07-07 13:15:00.152 - CustomFuction [ERROR   ] ORA-00933: SQL 命令未正确结束
Traceback (most recent call last):
  File "D:\INA\ETL_XdmLib_2.A.13\ETL_XdmLib_2.A.13\EDAETL\ETL_TABLE\DBtoDB_TEST_INA\../..\XdmLib\CustomFuction.py", line 103, in db2db_his_init_fullUpdate
    main_logic(db_src, db_tgt)
  File "D:\INA\ETL_XdmLib_2.A.13\ETL_XdmLib_2.A.13\EDAETL\ETL_TABLE\DBtoDB_TEST_INA\TEST_INA_DEFECT_Q5_RESULT.py", line 55, in main_logic
    result = db_src.execute(
  File "D:\INA\ETL_XdmLib_2.A.13\ETL_XdmLib_2.A.13\EDAETL\ETL_TABLE\DBtoDB_TEST_INA\../..\XdmLib\Database.py", line 248, in execute
    return self.cursor.execute(statement , *parameters,**keywordParameters)
cx_Oracle.DatabaseError: ORA-00933: SQL 命令未正确结束
Stack (most recent call last):
  File "D:\INA\ETL_XdmLib_2.A.13\ETL_XdmLib_2.A.13\EDAETL\ETL_TABLE\DBtoDB_TEST_INA\TEST_INA_DEFECT_Q5_RESULT.py", line 127, in <module>
    XdmLib.CustomFuction.db2db_his_init_fullUpdate(
  File "D:\INA\ETL_XdmLib_2.A.13\ETL_XdmLib_2.A.13\EDAETL\ETL_TABLE\DBtoDB_TEST_INA\../..\XdmLib\CustomFuction.py", line 118, in db2db_his_init_fullUpdate
    log.error(ex, exc_info=True, stack_info=True)
2023-07-07 13:15:05.474 - __init__   [ERROR   ] 程序运行错误,错误见明细
                                                Error: ORA-00933: SQL 命令未正确结束
