2023-07-21 14:03:31.470 - __init__   [ERROR   ] Access XDM Loader control table fail.
2023-07-21 14:12:33.735 - CustomFuction [ERROR   ] Move File Error
2023-07-21 14:12:33.766 - CustomFuction [ERROR   ] [WinError 32] 另一个程序正在使用此文件，进程无法访问。: '.\\\\Data\\\\Source\\新建文本文档.csv'
Traceback (most recent call last):
  File "D:\soft\anaconda3\lib\shutil.py", line 823, in move
    os.rename(src, real_dst)
PermissionError: [WinError 32] 另一个程序正在使用此文件，进程无法访问。: '.\\\\Data\\\\Source\\新建文本文档.csv' -> 'Data\\Skip\\新建文本文档.csv'

During handling of the above exception, another exception occurred:

Traceback (most recent call last):
  File "D:\Ina\ETL_XdmLib_2.A.13\ETL_XdmLib_2.A.13\EDAETL\ETL_TABLE\ETL_TEST_INA_WAT_TO_XSIFF\../..\XdmLib\CustomFuction.py", line 1035, in move_file
    msg = shutil.move(os.path.join(source_path, fileName),
  File "D:\soft\anaconda3\lib\shutil.py", line 844, in move
    os.unlink(src)
PermissionError: [WinError 32] 另一个程序正在使用此文件，进程无法访问。: '.\\\\Data\\\\Source\\新建文本文档.csv'
Stack (most recent call last):
  File "D:\soft\PyCharm Community Edition 2022.1.3\plugins\python-ce\helpers\pydev\pydevd.py", line 2181, in <module>
    main()
  File "D:\soft\PyCharm Community Edition 2022.1.3\plugins\python-ce\helpers\pydev\pydevd.py", line 2172, in main
    globals = debugger.run(setup['file'], None, None, is_module)
  File "D:\soft\PyCharm Community Edition 2022.1.3\plugins\python-ce\helpers\pydev\pydevd.py", line 1484, in run
    return self._exec(is_module, entry_point_fn, module_name, file, globals, locals)
  File "D:\soft\PyCharm Community Edition 2022.1.3\plugins\python-ce\helpers\pydev\pydevd.py", line 1491, in _exec
    pydev_imports.execfile(file, globals, locals)  # execute the script
  File "D:\soft\PyCharm Community Edition 2022.1.3\plugins\python-ce\helpers\pydev\_pydev_imps\_pydev_execfile.py", line 18, in execfile
    exec(compile(contents+"\n", file, 'exec'), glob, loc)
  File "D:/Ina/ETL_XdmLib_2.A.13/ETL_XdmLib_2.A.13/EDAETL/ETL_TABLE/ETL_TEST_INA_WAT_TO_XSIFF/ETL_TEST_INA_TO_XSIFF.py", line 441, in <module>
    XdmLib.CustomFuction.file2db_init(
  File "D:\Ina\ETL_XdmLib_2.A.13\ETL_XdmLib_2.A.13\EDAETL\ETL_TABLE\ETL_TEST_INA_WAT_TO_XSIFF\../..\XdmLib\CustomFuction.py", line 629, in file2db_init
    move_file_self(move_file_info)
  File "D:\Ina\ETL_XdmLib_2.A.13\ETL_XdmLib_2.A.13\EDAETL\ETL_TABLE\ETL_TEST_INA_WAT_TO_XSIFF\../..\XdmLib\CustomFuction.py", line 1044, in move_file
    log.error(ex, exc_info=True, stack_info=True)
2023-07-21 14:14:09.681 - CustomFuction [ERROR   ] Move File Error
2023-07-21 14:14:09.686 - CustomFuction [ERROR   ] [WinError 32] 另一个程序正在使用此文件，进程无法访问。: '.\\\\Data\\\\Source\\新建文本文档.csv'
Traceback (most recent call last):
  File "D:\soft\anaconda3\lib\shutil.py", line 823, in move
    os.rename(src, real_dst)
PermissionError: [WinError 32] 另一个程序正在使用此文件，进程无法访问。: '.\\\\Data\\\\Source\\新建文本文档.csv' -> 'Data\\Skip\\新建文本文档.csv'

During handling of the above exception, another exception occurred:

Traceback (most recent call last):
  File "D:\Ina\ETL_XdmLib_2.A.13\ETL_XdmLib_2.A.13\EDAETL\ETL_TABLE\ETL_TEST_INA_WAT_TO_XSIFF\../..\XdmLib\CustomFuction.py", line 1035, in move_file
    msg = shutil.move(os.path.join(source_path, fileName),
  File "D:\soft\anaconda3\lib\shutil.py", line 844, in move
    os.unlink(src)
PermissionError: [WinError 32] 另一个程序正在使用此文件，进程无法访问。: '.\\\\Data\\\\Source\\新建文本文档.csv'
Stack (most recent call last):
  File "D:\soft\PyCharm Community Edition 2022.1.3\plugins\python-ce\helpers\pydev\pydevd.py", line 2181, in <module>
    main()
  File "D:\soft\PyCharm Community Edition 2022.1.3\plugins\python-ce\helpers\pydev\pydevd.py", line 2172, in main
    globals = debugger.run(setup['file'], None, None, is_module)
  File "D:\soft\PyCharm Community Edition 2022.1.3\plugins\python-ce\helpers\pydev\pydevd.py", line 1484, in run
    return self._exec(is_module, entry_point_fn, module_name, file, globals, locals)
  File "D:\soft\PyCharm Community Edition 2022.1.3\plugins\python-ce\helpers\pydev\pydevd.py", line 1491, in _exec
    pydev_imports.execfile(file, globals, locals)  # execute the script
  File "D:\soft\PyCharm Community Edition 2022.1.3\plugins\python-ce\helpers\pydev\_pydev_imps\_pydev_execfile.py", line 18, in execfile
    exec(compile(contents+"\n", file, 'exec'), glob, loc)
  File "D:/Ina/ETL_XdmLib_2.A.13/ETL_XdmLib_2.A.13/EDAETL/ETL_TABLE/ETL_TEST_INA_WAT_TO_XSIFF/ETL_TEST_INA_TO_XSIFF.py", line 441, in <module>
    XdmLib.CustomFuction.file2db_init(
  File "D:\Ina\ETL_XdmLib_2.A.13\ETL_XdmLib_2.A.13\EDAETL\ETL_TABLE\ETL_TEST_INA_WAT_TO_XSIFF\../..\XdmLib\CustomFuction.py", line 629, in file2db_init
    move_file_self(move_file_info)
  File "D:\Ina\ETL_XdmLib_2.A.13\ETL_XdmLib_2.A.13\EDAETL\ETL_TABLE\ETL_TEST_INA_WAT_TO_XSIFF\../..\XdmLib\CustomFuction.py", line 1044, in move_file
    log.error(ex, exc_info=True, stack_info=True)
2023-07-21 14:15:35.251 - CustomFuction [ERROR   ] local variable 'paraDict' referenced before assignment
Traceback (most recent call last):
  File "D:\Ina\ETL_XdmLib_2.A.13\ETL_XdmLib_2.A.13\EDAETL\ETL_TABLE\ETL_TEST_INA_WAT_TO_XSIFF\../..\XdmLib\CustomFuction.py", line 596, in file2db_init
    res = do_file(file_root_source_path,
  File "D:\Ina\ETL_XdmLib_2.A.13\ETL_XdmLib_2.A.13\EDAETL\ETL_TABLE\ETL_TEST_INA_WAT_TO_XSIFF\ETL_TEST_INA_TO_XSIFF.py", line 292, in do_file
    'Product':paraDict['DESIGN_ID'],
UnboundLocalError: local variable 'paraDict' referenced before assignment
Stack (most recent call last):
  File "D:\Ina\ETL_XdmLib_2.A.13\ETL_XdmLib_2.A.13\EDAETL\ETL_TABLE\ETL_TEST_INA_WAT_TO_XSIFF\ETL_TEST_INA_TO_XSIFF.py", line 441, in <module>
    XdmLib.CustomFuction.file2db_init(
  File "D:\Ina\ETL_XdmLib_2.A.13\ETL_XdmLib_2.A.13\EDAETL\ETL_TABLE\ETL_TEST_INA_WAT_TO_XSIFF\../..\XdmLib\CustomFuction.py", line 631, in file2db_init
    log.error(ex, exc_info=True, stack_info=True)
2023-07-21 14:15:38.276 - CustomFuction [ERROR   ] Move File Error
2023-07-21 14:15:38.277 - CustomFuction [ERROR   ] [WinError 32] 另一个程序正在使用此文件，进程无法访问。: '.\\\\Data\\\\Source\\新建文本文档.csv'
Traceback (most recent call last):
  File "D:\soft\anaconda3\lib\shutil.py", line 823, in move
    os.rename(src, real_dst)
PermissionError: [WinError 32] 另一个程序正在使用此文件，进程无法访问。: '.\\\\Data\\\\Source\\新建文本文档.csv' -> 'Data\\Skip\\新建文本文档.csv'

During handling of the above exception, another exception occurred:

Traceback (most recent call last):
  File "D:\Ina\ETL_XdmLib_2.A.13\ETL_XdmLib_2.A.13\EDAETL\ETL_TABLE\ETL_TEST_INA_WAT_TO_XSIFF\../..\XdmLib\CustomFuction.py", line 1035, in move_file
    msg = shutil.move(os.path.join(source_path, fileName),
  File "D:\soft\anaconda3\lib\shutil.py", line 844, in move
    os.unlink(src)
PermissionError: [WinError 32] 另一个程序正在使用此文件，进程无法访问。: '.\\\\Data\\\\Source\\新建文本文档.csv'
Stack (most recent call last):
  File "D:\Ina\ETL_XdmLib_2.A.13\ETL_XdmLib_2.A.13\EDAETL\ETL_TABLE\ETL_TEST_INA_WAT_TO_XSIFF\ETL_TEST_INA_TO_XSIFF.py", line 441, in <module>
    XdmLib.CustomFuction.file2db_init(
  File "D:\Ina\ETL_XdmLib_2.A.13\ETL_XdmLib_2.A.13\EDAETL\ETL_TABLE\ETL_TEST_INA_WAT_TO_XSIFF\../..\XdmLib\CustomFuction.py", line 629, in file2db_init
    move_file_self(move_file_info)
  File "D:\Ina\ETL_XdmLib_2.A.13\ETL_XdmLib_2.A.13\EDAETL\ETL_TABLE\ETL_TEST_INA_WAT_TO_XSIFF\../..\XdmLib\CustomFuction.py", line 1044, in move_file
    log.error(ex, exc_info=True, stack_info=True)
2023-07-21 14:17:17.930 - CustomFuction [ERROR   ] local variable 'paraDict' referenced before assignment
Traceback (most recent call last):
  File "D:\Ina\ETL_XdmLib_2.A.13\ETL_XdmLib_2.A.13\EDAETL\ETL_TABLE\ETL_TEST_INA_WAT_TO_XSIFF\../..\XdmLib\CustomFuction.py", line 596, in file2db_init
    res = do_file(file_root_source_path,
  File "D:\Ina\ETL_XdmLib_2.A.13\ETL_XdmLib_2.A.13\EDAETL\ETL_TABLE\ETL_TEST_INA_WAT_TO_XSIFF\ETL_TEST_INA_TO_XSIFF.py", line 292, in do_file
    'Product':paraDict['DESIGN_ID'],
UnboundLocalError: local variable 'paraDict' referenced before assignment
Stack (most recent call last):
  File "D:\Ina\ETL_XdmLib_2.A.13\ETL_XdmLib_2.A.13\EDAETL\ETL_TABLE\ETL_TEST_INA_WAT_TO_XSIFF\ETL_TEST_INA_TO_XSIFF.py", line 441, in <module>
    XdmLib.CustomFuction.file2db_init(
  File "D:\Ina\ETL_XdmLib_2.A.13\ETL_XdmLib_2.A.13\EDAETL\ETL_TABLE\ETL_TEST_INA_WAT_TO_XSIFF\../..\XdmLib\CustomFuction.py", line 631, in file2db_init
    log.error(ex, exc_info=True, stack_info=True)
2023-07-21 14:18:35.269 - CustomFuction [ERROR   ] type object 'datetime.datetime' has no attribute 'datetime'
Traceback (most recent call last):
  File "D:\Ina\ETL_XdmLib_2.A.13\ETL_XdmLib_2.A.13\EDAETL\ETL_TABLE\ETL_TEST_INA_WAT_TO_XSIFF\../..\XdmLib\CustomFuction.py", line 596, in file2db_init
    res = do_file(file_root_source_path,
  File "D:\Ina\ETL_XdmLib_2.A.13\ETL_XdmLib_2.A.13\EDAETL\ETL_TABLE\ETL_TEST_INA_WAT_TO_XSIFF\ETL_TEST_INA_TO_XSIFF.py", line 317, in do_file
    ts_t = datetime.datetime.now()
AttributeError: type object 'datetime.datetime' has no attribute 'datetime'
Stack (most recent call last):
  File "D:\Ina\ETL_XdmLib_2.A.13\ETL_XdmLib_2.A.13\EDAETL\ETL_TABLE\ETL_TEST_INA_WAT_TO_XSIFF\ETL_TEST_INA_TO_XSIFF.py", line 441, in <module>
    XdmLib.CustomFuction.file2db_init(
  File "D:\Ina\ETL_XdmLib_2.A.13\ETL_XdmLib_2.A.13\EDAETL\ETL_TABLE\ETL_TEST_INA_WAT_TO_XSIFF\../..\XdmLib\CustomFuction.py", line 631, in file2db_init
    log.error(ex, exc_info=True, stack_info=True)
2023-07-21 14:18:35.290 - CustomFuction [ERROR   ] Move File Error
2023-07-21 14:18:35.291 - CustomFuction [ERROR   ] '.\\\\Data\\\\Source\\2022111517445900_0625682.002_PUIXE010MXE3.ad5' and 'Data\\Source\\2022111517445900_0625682.002_PUIXE010MXE3.ad5' are the same file
Traceback (most recent call last):
  File "D:\Ina\ETL_XdmLib_2.A.13\ETL_XdmLib_2.A.13\EDAETL\ETL_TABLE\ETL_TEST_INA_WAT_TO_XSIFF\../..\XdmLib\CustomFuction.py", line 596, in file2db_init
    res = do_file(file_root_source_path,
  File "D:\Ina\ETL_XdmLib_2.A.13\ETL_XdmLib_2.A.13\EDAETL\ETL_TABLE\ETL_TEST_INA_WAT_TO_XSIFF\ETL_TEST_INA_TO_XSIFF.py", line 317, in do_file
    ts_t = datetime.datetime.now()
AttributeError: type object 'datetime.datetime' has no attribute 'datetime'

During handling of the above exception, another exception occurred:

Traceback (most recent call last):
  File "D:\soft\anaconda3\lib\shutil.py", line 823, in move
    os.rename(src, real_dst)
PermissionError: [WinError 32] 另一个程序正在使用此文件，进程无法访问。: '.\\\\Data\\\\Source\\2022111517445900_0625682.002_PUIXE010MXE3.ad5' -> 'Data\\Source\\2022111517445900_0625682.002_PUIXE010MXE3.ad5'

During handling of the above exception, another exception occurred:

Traceback (most recent call last):
  File "D:\Ina\ETL_XdmLib_2.A.13\ETL_XdmLib_2.A.13\EDAETL\ETL_TABLE\ETL_TEST_INA_WAT_TO_XSIFF\../..\XdmLib\CustomFuction.py", line 1035, in move_file
    msg = shutil.move(os.path.join(source_path, fileName),
  File "D:\soft\anaconda3\lib\shutil.py", line 843, in move
    copy_function(src, real_dst)
  File "D:\soft\anaconda3\lib\shutil.py", line 444, in copy2
    copyfile(src, dst, follow_symlinks=follow_symlinks)
  File "D:\soft\anaconda3\lib\shutil.py", line 244, in copyfile
    raise SameFileError("{!r} and {!r} are the same file".format(src, dst))
shutil.SameFileError: '.\\\\Data\\\\Source\\2022111517445900_0625682.002_PUIXE010MXE3.ad5' and 'Data\\Source\\2022111517445900_0625682.002_PUIXE010MXE3.ad5' are the same file
Stack (most recent call last):
  File "D:\Ina\ETL_XdmLib_2.A.13\ETL_XdmLib_2.A.13\EDAETL\ETL_TABLE\ETL_TEST_INA_WAT_TO_XSIFF\ETL_TEST_INA_TO_XSIFF.py", line 441, in <module>
    XdmLib.CustomFuction.file2db_init(
  File "D:\Ina\ETL_XdmLib_2.A.13\ETL_XdmLib_2.A.13\EDAETL\ETL_TABLE\ETL_TEST_INA_WAT_TO_XSIFF\../..\XdmLib\CustomFuction.py", line 646, in file2db_init
    move_file_self(move_file_info)
  File "D:\Ina\ETL_XdmLib_2.A.13\ETL_XdmLib_2.A.13\EDAETL\ETL_TABLE\ETL_TEST_INA_WAT_TO_XSIFF\../..\XdmLib\CustomFuction.py", line 1044, in move_file
    log.error(ex, exc_info=True, stack_info=True)
2023-07-21 14:20:22.626 - CustomFuction [ERROR   ] type object 'datetime.datetime' has no attribute 'datetime'
Traceback (most recent call last):
  File "D:\Ina\ETL_XdmLib_2.A.13\ETL_XdmLib_2.A.13\EDAETL\ETL_TABLE\ETL_TEST_INA_WAT_TO_XSIFF\../..\XdmLib\CustomFuction.py", line 596, in file2db_init
    res = do_file(file_root_source_path,
  File "D:\Ina\ETL_XdmLib_2.A.13\ETL_XdmLib_2.A.13\EDAETL\ETL_TABLE\ETL_TEST_INA_WAT_TO_XSIFF\ETL_TEST_INA_TO_XSIFF.py", line 317, in do_file
    ts_t = datetime.datetime.now()
AttributeError: type object 'datetime.datetime' has no attribute 'datetime'
Stack (most recent call last):
  File "D:\Ina\ETL_XdmLib_2.A.13\ETL_XdmLib_2.A.13\EDAETL\ETL_TABLE\ETL_TEST_INA_WAT_TO_XSIFF\ETL_TEST_INA_TO_XSIFF.py", line 441, in <module>
    XdmLib.CustomFuction.file2db_init(
  File "D:\Ina\ETL_XdmLib_2.A.13\ETL_XdmLib_2.A.13\EDAETL\ETL_TABLE\ETL_TEST_INA_WAT_TO_XSIFF\../..\XdmLib\CustomFuction.py", line 631, in file2db_init
    log.error(ex, exc_info=True, stack_info=True)
2023-07-21 14:20:22.644 - CustomFuction [ERROR   ] Move File Error
2023-07-21 14:20:22.645 - CustomFuction [ERROR   ] [WinError 32] 另一个程序正在使用此文件，进程无法访问。: '.\\\\Data\\\\Source\\2022111517445900_0625682.002_PUIXE010MXE3.ad5'
Traceback (most recent call last):
  File "D:\Ina\ETL_XdmLib_2.A.13\ETL_XdmLib_2.A.13\EDAETL\ETL_TABLE\ETL_TEST_INA_WAT_TO_XSIFF\../..\XdmLib\CustomFuction.py", line 596, in file2db_init
    res = do_file(file_root_source_path,
  File "D:\Ina\ETL_XdmLib_2.A.13\ETL_XdmLib_2.A.13\EDAETL\ETL_TABLE\ETL_TEST_INA_WAT_TO_XSIFF\ETL_TEST_INA_TO_XSIFF.py", line 317, in do_file
    ts_t = datetime.datetime.now()
AttributeError: type object 'datetime.datetime' has no attribute 'datetime'

During handling of the above exception, another exception occurred:

Traceback (most recent call last):
  File "D:\soft\anaconda3\lib\shutil.py", line 823, in move
    os.rename(src, real_dst)
PermissionError: [WinError 32] 另一个程序正在使用此文件，进程无法访问。: '.\\\\Data\\\\Source\\2022111517445900_0625682.002_PUIXE010MXE3.ad5' -> 'Data\\ERROR\\2022111517445900_0625682.002_PUIXE010MXE3.ad5'

During handling of the above exception, another exception occurred:

Traceback (most recent call last):
  File "D:\Ina\ETL_XdmLib_2.A.13\ETL_XdmLib_2.A.13\EDAETL\ETL_TABLE\ETL_TEST_INA_WAT_TO_XSIFF\../..\XdmLib\CustomFuction.py", line 1035, in move_file
    msg = shutil.move(os.path.join(source_path, fileName),
  File "D:\soft\anaconda3\lib\shutil.py", line 844, in move
    os.unlink(src)
PermissionError: [WinError 32] 另一个程序正在使用此文件，进程无法访问。: '.\\\\Data\\\\Source\\2022111517445900_0625682.002_PUIXE010MXE3.ad5'
Stack (most recent call last):
  File "D:\Ina\ETL_XdmLib_2.A.13\ETL_XdmLib_2.A.13\EDAETL\ETL_TABLE\ETL_TEST_INA_WAT_TO_XSIFF\ETL_TEST_INA_TO_XSIFF.py", line 441, in <module>
    XdmLib.CustomFuction.file2db_init(
  File "D:\Ina\ETL_XdmLib_2.A.13\ETL_XdmLib_2.A.13\EDAETL\ETL_TABLE\ETL_TEST_INA_WAT_TO_XSIFF\../..\XdmLib\CustomFuction.py", line 646, in file2db_init
    move_file_self(move_file_info)
  File "D:\Ina\ETL_XdmLib_2.A.13\ETL_XdmLib_2.A.13\EDAETL\ETL_TABLE\ETL_TEST_INA_WAT_TO_XSIFF\../..\XdmLib\CustomFuction.py", line 1044, in move_file
    log.error(ex, exc_info=True, stack_info=True)
2023-07-21 14:52:50.142 - CustomFuction [ERROR   ] type object 'datetime.datetime' has no attribute 'datetime'
Traceback (most recent call last):
  File "D:\Ina\ETL_XdmLib_2.A.13\ETL_XdmLib_2.A.13\EDAETL\ETL_TABLE\ETL_TEST_INA_WAT_TO_XSIFF\../..\XdmLib\CustomFuction.py", line 596, in file2db_init
    res = do_file(file_root_source_path,
  File "D:\Ina\ETL_XdmLib_2.A.13\ETL_XdmLib_2.A.13\EDAETL\ETL_TABLE\ETL_TEST_INA_WAT_TO_XSIFF\ETL_TEST_INA_TO_XSIFF.py", line 317, in do_file
    ts_t = datetime.datetime.now()
AttributeError: type object 'datetime.datetime' has no attribute 'datetime'
Stack (most recent call last):
  File "D:\Ina\ETL_XdmLib_2.A.13\ETL_XdmLib_2.A.13\EDAETL\ETL_TABLE\ETL_TEST_INA_WAT_TO_XSIFF\ETL_TEST_INA_TO_XSIFF.py", line 441, in <module>
    XdmLib.CustomFuction.file2db_init(
  File "D:\Ina\ETL_XdmLib_2.A.13\ETL_XdmLib_2.A.13\EDAETL\ETL_TABLE\ETL_TEST_INA_WAT_TO_XSIFF\../..\XdmLib\CustomFuction.py", line 631, in file2db_init
    log.error(ex, exc_info=True, stack_info=True)
2023-07-21 14:52:50.162 - CustomFuction [ERROR   ] Move File Error
2023-07-21 14:52:50.163 - CustomFuction [ERROR   ] [WinError 32] 另一个程序正在使用此文件，进程无法访问。: '.\\\\Data\\\\Source\\2022111517445900_0625682.002_PUIXE010MXE3.ad5'
Traceback (most recent call last):
  File "D:\Ina\ETL_XdmLib_2.A.13\ETL_XdmLib_2.A.13\EDAETL\ETL_TABLE\ETL_TEST_INA_WAT_TO_XSIFF\../..\XdmLib\CustomFuction.py", line 596, in file2db_init
    res = do_file(file_root_source_path,
  File "D:\Ina\ETL_XdmLib_2.A.13\ETL_XdmLib_2.A.13\EDAETL\ETL_TABLE\ETL_TEST_INA_WAT_TO_XSIFF\ETL_TEST_INA_TO_XSIFF.py", line 317, in do_file
    ts_t = datetime.datetime.now()
AttributeError: type object 'datetime.datetime' has no attribute 'datetime'

During handling of the above exception, another exception occurred:

Traceback (most recent call last):
  File "D:\soft\anaconda3\lib\shutil.py", line 823, in move
    os.rename(src, real_dst)
PermissionError: [WinError 32] 另一个程序正在使用此文件，进程无法访问。: '.\\\\Data\\\\Source\\2022111517445900_0625682.002_PUIXE010MXE3.ad5' -> 'Data\\ERROR\\2022111517445900_0625682.002_PUIXE010MXE3.ad5'

During handling of the above exception, another exception occurred:

Traceback (most recent call last):
  File "D:\Ina\ETL_XdmLib_2.A.13\ETL_XdmLib_2.A.13\EDAETL\ETL_TABLE\ETL_TEST_INA_WAT_TO_XSIFF\../..\XdmLib\CustomFuction.py", line 1035, in move_file
    msg = shutil.move(os.path.join(source_path, fileName),
  File "D:\soft\anaconda3\lib\shutil.py", line 844, in move
    os.unlink(src)
PermissionError: [WinError 32] 另一个程序正在使用此文件，进程无法访问。: '.\\\\Data\\\\Source\\2022111517445900_0625682.002_PUIXE010MXE3.ad5'
Stack (most recent call last):
  File "D:\Ina\ETL_XdmLib_2.A.13\ETL_XdmLib_2.A.13\EDAETL\ETL_TABLE\ETL_TEST_INA_WAT_TO_XSIFF\ETL_TEST_INA_TO_XSIFF.py", line 441, in <module>
    XdmLib.CustomFuction.file2db_init(
  File "D:\Ina\ETL_XdmLib_2.A.13\ETL_XdmLib_2.A.13\EDAETL\ETL_TABLE\ETL_TEST_INA_WAT_TO_XSIFF\../..\XdmLib\CustomFuction.py", line 646, in file2db_init
    move_file_self(move_file_info)
  File "D:\Ina\ETL_XdmLib_2.A.13\ETL_XdmLib_2.A.13\EDAETL\ETL_TABLE\ETL_TEST_INA_WAT_TO_XSIFF\../..\XdmLib\CustomFuction.py", line 1044, in move_file
    log.error(ex, exc_info=True, stack_info=True)
2023-07-21 14:56:23.313 - CustomFuction [ERROR   ] module 'datetime' has no attribute 'strptime'
Traceback (most recent call last):
  File "D:\Ina\ETL_XdmLib_2.A.13\ETL_XdmLib_2.A.13\EDAETL\ETL_TABLE\ETL_TEST_INA_WAT_TO_XSIFF\../..\XdmLib\CustomFuction.py", line 596, in file2db_init
    res = do_file(file_root_source_path,
  File "D:\Ina\ETL_XdmLib_2.A.13\ETL_XdmLib_2.A.13\EDAETL\ETL_TABLE\ETL_TEST_INA_WAT_TO_XSIFF\ETL_TEST_INA_TO_XSIFF.py", line 209, in do_file
    date_object = datetime.strptime(File_Creation_DateTime_Str, '%m/%d/%Y %S:%M:%H')
AttributeError: module 'datetime' has no attribute 'strptime'
Stack (most recent call last):
  File "D:\Ina\ETL_XdmLib_2.A.13\ETL_XdmLib_2.A.13\EDAETL\ETL_TABLE\ETL_TEST_INA_WAT_TO_XSIFF\ETL_TEST_INA_TO_XSIFF.py", line 441, in <module>
    XdmLib.CustomFuction.file2db_init(
  File "D:\Ina\ETL_XdmLib_2.A.13\ETL_XdmLib_2.A.13\EDAETL\ETL_TABLE\ETL_TEST_INA_WAT_TO_XSIFF\../..\XdmLib\CustomFuction.py", line 631, in file2db_init
    log.error(ex, exc_info=True, stack_info=True)
2023-07-21 14:56:23.343 - CustomFuction [ERROR   ] Move File Error
2023-07-21 14:56:23.346 - CustomFuction [ERROR   ] [WinError 32] 另一个程序正在使用此文件，进程无法访问。: '.\\\\Data\\\\Source\\2022111517445900_0625682.002_PUIXE010MXE3.ad5'
Traceback (most recent call last):
  File "D:\Ina\ETL_XdmLib_2.A.13\ETL_XdmLib_2.A.13\EDAETL\ETL_TABLE\ETL_TEST_INA_WAT_TO_XSIFF\../..\XdmLib\CustomFuction.py", line 596, in file2db_init
    res = do_file(file_root_source_path,
  File "D:\Ina\ETL_XdmLib_2.A.13\ETL_XdmLib_2.A.13\EDAETL\ETL_TABLE\ETL_TEST_INA_WAT_TO_XSIFF\ETL_TEST_INA_TO_XSIFF.py", line 209, in do_file
    date_object = datetime.strptime(File_Creation_DateTime_Str, '%m/%d/%Y %S:%M:%H')
AttributeError: module 'datetime' has no attribute 'strptime'

During handling of the above exception, another exception occurred:

Traceback (most recent call last):
  File "D:\soft\anaconda3\lib\shutil.py", line 823, in move
    os.rename(src, real_dst)
PermissionError: [WinError 32] 另一个程序正在使用此文件，进程无法访问。: '.\\\\Data\\\\Source\\2022111517445900_0625682.002_PUIXE010MXE3.ad5' -> 'Data\\ERROR\\2022111517445900_0625682.002_PUIXE010MXE3.ad5'

During handling of the above exception, another exception occurred:

Traceback (most recent call last):
  File "D:\Ina\ETL_XdmLib_2.A.13\ETL_XdmLib_2.A.13\EDAETL\ETL_TABLE\ETL_TEST_INA_WAT_TO_XSIFF\../..\XdmLib\CustomFuction.py", line 1035, in move_file
    msg = shutil.move(os.path.join(source_path, fileName),
  File "D:\soft\anaconda3\lib\shutil.py", line 844, in move
    os.unlink(src)
PermissionError: [WinError 32] 另一个程序正在使用此文件，进程无法访问。: '.\\\\Data\\\\Source\\2022111517445900_0625682.002_PUIXE010MXE3.ad5'
Stack (most recent call last):
  File "D:\Ina\ETL_XdmLib_2.A.13\ETL_XdmLib_2.A.13\EDAETL\ETL_TABLE\ETL_TEST_INA_WAT_TO_XSIFF\ETL_TEST_INA_TO_XSIFF.py", line 441, in <module>
    XdmLib.CustomFuction.file2db_init(
  File "D:\Ina\ETL_XdmLib_2.A.13\ETL_XdmLib_2.A.13\EDAETL\ETL_TABLE\ETL_TEST_INA_WAT_TO_XSIFF\../..\XdmLib\CustomFuction.py", line 646, in file2db_init
    move_file_self(move_file_info)
  File "D:\Ina\ETL_XdmLib_2.A.13\ETL_XdmLib_2.A.13\EDAETL\ETL_TABLE\ETL_TEST_INA_WAT_TO_XSIFF\../..\XdmLib\CustomFuction.py", line 1044, in move_file
    log.error(ex, exc_info=True, stack_info=True)
2023-07-21 15:03:06.452 - CustomFuction [ERROR   ] module 'datetime' has no attribute 'strptime'
Traceback (most recent call last):
  File "D:\Ina\ETL_XdmLib_2.A.13\ETL_XdmLib_2.A.13\EDAETL\ETL_TABLE\ETL_TEST_INA_WAT_TO_XSIFF\../..\XdmLib\CustomFuction.py", line 596, in file2db_init
    res = do_file(file_root_source_path,
  File "D:\Ina\ETL_XdmLib_2.A.13\ETL_XdmLib_2.A.13\EDAETL\ETL_TABLE\ETL_TEST_INA_WAT_TO_XSIFF\ETL_TEST_INA_TO_XSIFF.py", line 209, in do_file
    date_object = datetime.strptime(File_Creation_DateTime_Str, '%m/%d/%Y %S:%M:%H')
AttributeError: module 'datetime' has no attribute 'strptime'
Stack (most recent call last):
  File "D:\Ina\ETL_XdmLib_2.A.13\ETL_XdmLib_2.A.13\EDAETL\ETL_TABLE\ETL_TEST_INA_WAT_TO_XSIFF\ETL_TEST_INA_TO_XSIFF.py", line 441, in <module>
    XdmLib.CustomFuction.file2db_init(
  File "D:\Ina\ETL_XdmLib_2.A.13\ETL_XdmLib_2.A.13\EDAETL\ETL_TABLE\ETL_TEST_INA_WAT_TO_XSIFF\../..\XdmLib\CustomFuction.py", line 631, in file2db_init
    log.error(ex, exc_info=True, stack_info=True)
2023-07-21 15:03:06.484 - CustomFuction [ERROR   ] Move File Error
2023-07-21 15:03:06.487 - CustomFuction [ERROR   ] [WinError 32] 另一个程序正在使用此文件，进程无法访问。: '.\\\\Data\\\\Source\\2022111517445900_0625682.002_PUIXE010MXE3.ad5'
Traceback (most recent call last):
  File "D:\Ina\ETL_XdmLib_2.A.13\ETL_XdmLib_2.A.13\EDAETL\ETL_TABLE\ETL_TEST_INA_WAT_TO_XSIFF\../..\XdmLib\CustomFuction.py", line 596, in file2db_init
    res = do_file(file_root_source_path,
  File "D:\Ina\ETL_XdmLib_2.A.13\ETL_XdmLib_2.A.13\EDAETL\ETL_TABLE\ETL_TEST_INA_WAT_TO_XSIFF\ETL_TEST_INA_TO_XSIFF.py", line 209, in do_file
    date_object = datetime.strptime(File_Creation_DateTime_Str, '%m/%d/%Y %S:%M:%H')
AttributeError: module 'datetime' has no attribute 'strptime'

During handling of the above exception, another exception occurred:

Traceback (most recent call last):
  File "D:\soft\anaconda3\lib\shutil.py", line 823, in move
    os.rename(src, real_dst)
PermissionError: [WinError 32] 另一个程序正在使用此文件，进程无法访问。: '.\\\\Data\\\\Source\\2022111517445900_0625682.002_PUIXE010MXE3.ad5' -> 'Data\\ERROR\\2022111517445900_0625682.002_PUIXE010MXE3.ad5'

During handling of the above exception, another exception occurred:

Traceback (most recent call last):
  File "D:\Ina\ETL_XdmLib_2.A.13\ETL_XdmLib_2.A.13\EDAETL\ETL_TABLE\ETL_TEST_INA_WAT_TO_XSIFF\../..\XdmLib\CustomFuction.py", line 1035, in move_file
    msg = shutil.move(os.path.join(source_path, fileName),
  File "D:\soft\anaconda3\lib\shutil.py", line 844, in move
    os.unlink(src)
PermissionError: [WinError 32] 另一个程序正在使用此文件，进程无法访问。: '.\\\\Data\\\\Source\\2022111517445900_0625682.002_PUIXE010MXE3.ad5'
Stack (most recent call last):
  File "D:\Ina\ETL_XdmLib_2.A.13\ETL_XdmLib_2.A.13\EDAETL\ETL_TABLE\ETL_TEST_INA_WAT_TO_XSIFF\ETL_TEST_INA_TO_XSIFF.py", line 441, in <module>
    XdmLib.CustomFuction.file2db_init(
  File "D:\Ina\ETL_XdmLib_2.A.13\ETL_XdmLib_2.A.13\EDAETL\ETL_TABLE\ETL_TEST_INA_WAT_TO_XSIFF\../..\XdmLib\CustomFuction.py", line 646, in file2db_init
    move_file_self(move_file_info)
  File "D:\Ina\ETL_XdmLib_2.A.13\ETL_XdmLib_2.A.13\EDAETL\ETL_TABLE\ETL_TEST_INA_WAT_TO_XSIFF\../..\XdmLib\CustomFuction.py", line 1044, in move_file
    log.error(ex, exc_info=True, stack_info=True)
2023-07-21 15:07:11.271 - CustomFuction [ERROR   ] module 'datetime' has no attribute 'strptime'
Traceback (most recent call last):
  File "D:\Ina\ETL_XdmLib_2.A.13\ETL_XdmLib_2.A.13\EDAETL\ETL_TABLE\ETL_TEST_INA_WAT_TO_XSIFF\../..\XdmLib\CustomFuction.py", line 596, in file2db_init
    res = do_file(file_root_source_path,
  File "D:\Ina\ETL_XdmLib_2.A.13\ETL_XdmLib_2.A.13\EDAETL\ETL_TABLE\ETL_TEST_INA_WAT_TO_XSIFF\ETL_TEST_INA_TO_XSIFF.py", line 209, in do_file
    date_object = datetime.strptime(File_Creation_DateTime_Str, '%m/%d/%Y %S:%M:%H')
AttributeError: module 'datetime' has no attribute 'strptime'
Stack (most recent call last):
  File "D:\Ina\ETL_XdmLib_2.A.13\ETL_XdmLib_2.A.13\EDAETL\ETL_TABLE\ETL_TEST_INA_WAT_TO_XSIFF\ETL_TEST_INA_TO_XSIFF.py", line 441, in <module>
    XdmLib.CustomFuction.file2db_init(
  File "D:\Ina\ETL_XdmLib_2.A.13\ETL_XdmLib_2.A.13\EDAETL\ETL_TABLE\ETL_TEST_INA_WAT_TO_XSIFF\../..\XdmLib\CustomFuction.py", line 631, in file2db_init
    log.error(ex, exc_info=True, stack_info=True)
2023-07-21 15:07:11.301 - CustomFuction [ERROR   ] Move File Error
2023-07-21 15:07:11.305 - CustomFuction [ERROR   ] [WinError 32] 另一个程序正在使用此文件，进程无法访问。: '.\\\\Data\\\\Source\\2022111517445900_0625682.002_PUIXE010MXE3.ad5'
Traceback (most recent call last):
  File "D:\Ina\ETL_XdmLib_2.A.13\ETL_XdmLib_2.A.13\EDAETL\ETL_TABLE\ETL_TEST_INA_WAT_TO_XSIFF\../..\XdmLib\CustomFuction.py", line 596, in file2db_init
    res = do_file(file_root_source_path,
  File "D:\Ina\ETL_XdmLib_2.A.13\ETL_XdmLib_2.A.13\EDAETL\ETL_TABLE\ETL_TEST_INA_WAT_TO_XSIFF\ETL_TEST_INA_TO_XSIFF.py", line 209, in do_file
    date_object = datetime.strptime(File_Creation_DateTime_Str, '%m/%d/%Y %S:%M:%H')
AttributeError: module 'datetime' has no attribute 'strptime'

During handling of the above exception, another exception occurred:

Traceback (most recent call last):
  File "D:\soft\anaconda3\lib\shutil.py", line 823, in move
    os.rename(src, real_dst)
PermissionError: [WinError 32] 另一个程序正在使用此文件，进程无法访问。: '.\\\\Data\\\\Source\\2022111517445900_0625682.002_PUIXE010MXE3.ad5' -> 'Data\\ERROR\\2022111517445900_0625682.002_PUIXE010MXE3.ad5'

During handling of the above exception, another exception occurred:

Traceback (most recent call last):
  File "D:\Ina\ETL_XdmLib_2.A.13\ETL_XdmLib_2.A.13\EDAETL\ETL_TABLE\ETL_TEST_INA_WAT_TO_XSIFF\../..\XdmLib\CustomFuction.py", line 1035, in move_file
    msg = shutil.move(os.path.join(source_path, fileName),
  File "D:\soft\anaconda3\lib\shutil.py", line 844, in move
    os.unlink(src)
PermissionError: [WinError 32] 另一个程序正在使用此文件，进程无法访问。: '.\\\\Data\\\\Source\\2022111517445900_0625682.002_PUIXE010MXE3.ad5'
Stack (most recent call last):
  File "D:\Ina\ETL_XdmLib_2.A.13\ETL_XdmLib_2.A.13\EDAETL\ETL_TABLE\ETL_TEST_INA_WAT_TO_XSIFF\ETL_TEST_INA_TO_XSIFF.py", line 441, in <module>
    XdmLib.CustomFuction.file2db_init(
  File "D:\Ina\ETL_XdmLib_2.A.13\ETL_XdmLib_2.A.13\EDAETL\ETL_TABLE\ETL_TEST_INA_WAT_TO_XSIFF\../..\XdmLib\CustomFuction.py", line 646, in file2db_init
    move_file_self(move_file_info)
  File "D:\Ina\ETL_XdmLib_2.A.13\ETL_XdmLib_2.A.13\EDAETL\ETL_TABLE\ETL_TEST_INA_WAT_TO_XSIFF\../..\XdmLib\CustomFuction.py", line 1044, in move_file
    log.error(ex, exc_info=True, stack_info=True)
2023-07-21 15:08:00.014 - CustomFuction [ERROR   ] type object 'datetime.datetime' has no attribute 'datetime'
Traceback (most recent call last):
  File "D:\Ina\ETL_XdmLib_2.A.13\ETL_XdmLib_2.A.13\EDAETL\ETL_TABLE\ETL_TEST_INA_WAT_TO_XSIFF\../..\XdmLib\CustomFuction.py", line 596, in file2db_init
    res = do_file(file_root_source_path,
  File "D:\Ina\ETL_XdmLib_2.A.13\ETL_XdmLib_2.A.13\EDAETL\ETL_TABLE\ETL_TEST_INA_WAT_TO_XSIFF\ETL_TEST_INA_TO_XSIFF.py", line 327, in do_file
    e_t = datetime.datetime.now()
AttributeError: type object 'datetime.datetime' has no attribute 'datetime'
Stack (most recent call last):
  File "D:\Ina\ETL_XdmLib_2.A.13\ETL_XdmLib_2.A.13\EDAETL\ETL_TABLE\ETL_TEST_INA_WAT_TO_XSIFF\ETL_TEST_INA_TO_XSIFF.py", line 441, in <module>
    XdmLib.CustomFuction.file2db_init(
  File "D:\Ina\ETL_XdmLib_2.A.13\ETL_XdmLib_2.A.13\EDAETL\ETL_TABLE\ETL_TEST_INA_WAT_TO_XSIFF\../..\XdmLib\CustomFuction.py", line 631, in file2db_init
    log.error(ex, exc_info=True, stack_info=True)
2023-07-21 15:08:00.032 - CustomFuction [ERROR   ] Move File Error
2023-07-21 15:08:00.033 - CustomFuction [ERROR   ] [WinError 32] 另一个程序正在使用此文件，进程无法访问。: '.\\\\Data\\\\Source\\2022111517445900_0625682.002_PUIXE010MXE3.ad5'
Traceback (most recent call last):
  File "D:\Ina\ETL_XdmLib_2.A.13\ETL_XdmLib_2.A.13\EDAETL\ETL_TABLE\ETL_TEST_INA_WAT_TO_XSIFF\../..\XdmLib\CustomFuction.py", line 596, in file2db_init
    res = do_file(file_root_source_path,
  File "D:\Ina\ETL_XdmLib_2.A.13\ETL_XdmLib_2.A.13\EDAETL\ETL_TABLE\ETL_TEST_INA_WAT_TO_XSIFF\ETL_TEST_INA_TO_XSIFF.py", line 327, in do_file
    e_t = datetime.datetime.now()
AttributeError: type object 'datetime.datetime' has no attribute 'datetime'

During handling of the above exception, another exception occurred:

Traceback (most recent call last):
  File "D:\soft\anaconda3\lib\shutil.py", line 823, in move
    os.rename(src, real_dst)
PermissionError: [WinError 32] 另一个程序正在使用此文件，进程无法访问。: '.\\\\Data\\\\Source\\2022111517445900_0625682.002_PUIXE010MXE3.ad5' -> 'Data\\ERROR\\2022111517445900_0625682.002_PUIXE010MXE3.ad5'

During handling of the above exception, another exception occurred:

Traceback (most recent call last):
  File "D:\Ina\ETL_XdmLib_2.A.13\ETL_XdmLib_2.A.13\EDAETL\ETL_TABLE\ETL_TEST_INA_WAT_TO_XSIFF\../..\XdmLib\CustomFuction.py", line 1035, in move_file
    msg = shutil.move(os.path.join(source_path, fileName),
  File "D:\soft\anaconda3\lib\shutil.py", line 844, in move
    os.unlink(src)
PermissionError: [WinError 32] 另一个程序正在使用此文件，进程无法访问。: '.\\\\Data\\\\Source\\2022111517445900_0625682.002_PUIXE010MXE3.ad5'
Stack (most recent call last):
  File "D:\Ina\ETL_XdmLib_2.A.13\ETL_XdmLib_2.A.13\EDAETL\ETL_TABLE\ETL_TEST_INA_WAT_TO_XSIFF\ETL_TEST_INA_TO_XSIFF.py", line 441, in <module>
    XdmLib.CustomFuction.file2db_init(
  File "D:\Ina\ETL_XdmLib_2.A.13\ETL_XdmLib_2.A.13\EDAETL\ETL_TABLE\ETL_TEST_INA_WAT_TO_XSIFF\../..\XdmLib\CustomFuction.py", line 646, in file2db_init
    move_file_self(move_file_info)
  File "D:\Ina\ETL_XdmLib_2.A.13\ETL_XdmLib_2.A.13\EDAETL\ETL_TABLE\ETL_TEST_INA_WAT_TO_XSIFF\../..\XdmLib\CustomFuction.py", line 1044, in move_file
    log.error(ex, exc_info=True, stack_info=True)
2023-07-21 15:14:52.266 - CustomFuction [ERROR   ] type object 'datetime.datetime' has no attribute 'datetime'
Traceback (most recent call last):
  File "D:\Ina\ETL_XdmLib_2.A.13\ETL_XdmLib_2.A.13\EDAETL\ETL_TABLE\ETL_TEST_INA_WAT_TO_XSIFF\../..\XdmLib\CustomFuction.py", line 596, in file2db_init
    res = do_file(file_root_source_path,
  File "D:/Ina/ETL_XdmLib_2.A.13/ETL_XdmLib_2.A.13/EDAETL/ETL_TABLE/ETL_TEST_INA_WAT_TO_XSIFF/ETL_TEST_INA_TO_XSIFF.py", line 327, in do_file
    e_t = datetime.datetime.now()
AttributeError: type object 'datetime.datetime' has no attribute 'datetime'
Stack (most recent call last):
  File "D:\soft\PyCharm Community Edition 2022.1.3\plugins\python-ce\helpers\pydev\pydevd.py", line 2181, in <module>
    main()
  File "D:\soft\PyCharm Community Edition 2022.1.3\plugins\python-ce\helpers\pydev\pydevd.py", line 2172, in main
    globals = debugger.run(setup['file'], None, None, is_module)
  File "D:\soft\PyCharm Community Edition 2022.1.3\plugins\python-ce\helpers\pydev\pydevd.py", line 1484, in run
    return self._exec(is_module, entry_point_fn, module_name, file, globals, locals)
  File "D:\soft\PyCharm Community Edition 2022.1.3\plugins\python-ce\helpers\pydev\pydevd.py", line 1491, in _exec
    pydev_imports.execfile(file, globals, locals)  # execute the script
  File "D:\soft\PyCharm Community Edition 2022.1.3\plugins\python-ce\helpers\pydev\_pydev_imps\_pydev_execfile.py", line 18, in execfile
    exec(compile(contents+"\n", file, 'exec'), glob, loc)
  File "D:/Ina/ETL_XdmLib_2.A.13/ETL_XdmLib_2.A.13/EDAETL/ETL_TABLE/ETL_TEST_INA_WAT_TO_XSIFF/ETL_TEST_INA_TO_XSIFF.py", line 441, in <module>
    XdmLib.CustomFuction.file2db_init(
  File "D:\Ina\ETL_XdmLib_2.A.13\ETL_XdmLib_2.A.13\EDAETL\ETL_TABLE\ETL_TEST_INA_WAT_TO_XSIFF\../..\XdmLib\CustomFuction.py", line 631, in file2db_init
    log.error(ex, exc_info=True, stack_info=True)
2023-07-21 15:14:52.287 - CustomFuction [ERROR   ] Move File Error
2023-07-21 15:14:52.287 - CustomFuction [ERROR   ] [WinError 32] 另一个程序正在使用此文件，进程无法访问。: '.\\\\Data\\\\Source\\2022111517445900_0625682.002_PUIXE010MXE3.ad5'
Traceback (most recent call last):
  File "D:\Ina\ETL_XdmLib_2.A.13\ETL_XdmLib_2.A.13\EDAETL\ETL_TABLE\ETL_TEST_INA_WAT_TO_XSIFF\../..\XdmLib\CustomFuction.py", line 596, in file2db_init
    res = do_file(file_root_source_path,
  File "D:/Ina/ETL_XdmLib_2.A.13/ETL_XdmLib_2.A.13/EDAETL/ETL_TABLE/ETL_TEST_INA_WAT_TO_XSIFF/ETL_TEST_INA_TO_XSIFF.py", line 327, in do_file
    e_t = datetime.datetime.now()
AttributeError: type object 'datetime.datetime' has no attribute 'datetime'

During handling of the above exception, another exception occurred:

Traceback (most recent call last):
  File "D:\soft\anaconda3\lib\shutil.py", line 823, in move
    os.rename(src, real_dst)
PermissionError: [WinError 32] 另一个程序正在使用此文件，进程无法访问。: '.\\\\Data\\\\Source\\2022111517445900_0625682.002_PUIXE010MXE3.ad5' -> 'Data\\ERROR\\2022111517445900_0625682.002_PUIXE010MXE3.ad5'

During handling of the above exception, another exception occurred:

Traceback (most recent call last):
  File "D:\Ina\ETL_XdmLib_2.A.13\ETL_XdmLib_2.A.13\EDAETL\ETL_TABLE\ETL_TEST_INA_WAT_TO_XSIFF\../..\XdmLib\CustomFuction.py", line 1035, in move_file
    msg = shutil.move(os.path.join(source_path, fileName),
  File "D:\soft\anaconda3\lib\shutil.py", line 844, in move
    os.unlink(src)
PermissionError: [WinError 32] 另一个程序正在使用此文件，进程无法访问。: '.\\\\Data\\\\Source\\2022111517445900_0625682.002_PUIXE010MXE3.ad5'
Stack (most recent call last):
  File "D:\soft\PyCharm Community Edition 2022.1.3\plugins\python-ce\helpers\pydev\pydevd.py", line 2181, in <module>
    main()
  File "D:\soft\PyCharm Community Edition 2022.1.3\plugins\python-ce\helpers\pydev\pydevd.py", line 2172, in main
    globals = debugger.run(setup['file'], None, None, is_module)
  File "D:\soft\PyCharm Community Edition 2022.1.3\plugins\python-ce\helpers\pydev\pydevd.py", line 1484, in run
    return self._exec(is_module, entry_point_fn, module_name, file, globals, locals)
  File "D:\soft\PyCharm Community Edition 2022.1.3\plugins\python-ce\helpers\pydev\pydevd.py", line 1491, in _exec
    pydev_imports.execfile(file, globals, locals)  # execute the script
  File "D:\soft\PyCharm Community Edition 2022.1.3\plugins\python-ce\helpers\pydev\_pydev_imps\_pydev_execfile.py", line 18, in execfile
    exec(compile(contents+"\n", file, 'exec'), glob, loc)
  File "D:/Ina/ETL_XdmLib_2.A.13/ETL_XdmLib_2.A.13/EDAETL/ETL_TABLE/ETL_TEST_INA_WAT_TO_XSIFF/ETL_TEST_INA_TO_XSIFF.py", line 441, in <module>
    XdmLib.CustomFuction.file2db_init(
  File "D:\Ina\ETL_XdmLib_2.A.13\ETL_XdmLib_2.A.13\EDAETL\ETL_TABLE\ETL_TEST_INA_WAT_TO_XSIFF\../..\XdmLib\CustomFuction.py", line 646, in file2db_init
    move_file_self(move_file_info)
  File "D:\Ina\ETL_XdmLib_2.A.13\ETL_XdmLib_2.A.13\EDAETL\ETL_TABLE\ETL_TEST_INA_WAT_TO_XSIFF\../..\XdmLib\CustomFuction.py", line 1044, in move_file
    log.error(ex, exc_info=True, stack_info=True)
2023-07-21 15:17:38.755 - CustomFuction [ERROR   ] type object 'datetime.datetime' has no attribute 'datetime'
Traceback (most recent call last):
  File "D:\Ina\ETL_XdmLib_2.A.13\ETL_XdmLib_2.A.13\EDAETL\ETL_TABLE\ETL_TEST_INA_WAT_TO_XSIFF\../..\XdmLib\CustomFuction.py", line 596, in file2db_init
    res = do_file(file_root_source_path,
  File "D:\Ina\ETL_XdmLib_2.A.13\ETL_XdmLib_2.A.13\EDAETL\ETL_TABLE\ETL_TEST_INA_WAT_TO_XSIFF\ETL_TEST_INA_TO_XSIFF.py", line 337, in do_file
    e_t = datetime.datetime.now()
AttributeError: type object 'datetime.datetime' has no attribute 'datetime'
Stack (most recent call last):
  File "D:\Ina\ETL_XdmLib_2.A.13\ETL_XdmLib_2.A.13\EDAETL\ETL_TABLE\ETL_TEST_INA_WAT_TO_XSIFF\ETL_TEST_INA_TO_XSIFF.py", line 441, in <module>
    XdmLib.CustomFuction.file2db_init(
  File "D:\Ina\ETL_XdmLib_2.A.13\ETL_XdmLib_2.A.13\EDAETL\ETL_TABLE\ETL_TEST_INA_WAT_TO_XSIFF\../..\XdmLib\CustomFuction.py", line 631, in file2db_init
    log.error(ex, exc_info=True, stack_info=True)
2023-07-21 15:17:38.775 - CustomFuction [ERROR   ] Move File Error
2023-07-21 15:17:38.776 - CustomFuction [ERROR   ] [WinError 32] 另一个程序正在使用此文件，进程无法访问。: '.\\\\Data\\\\Source\\2022111517445900_0625682.002_PUIXE010MXE3.ad5'
Traceback (most recent call last):
  File "D:\Ina\ETL_XdmLib_2.A.13\ETL_XdmLib_2.A.13\EDAETL\ETL_TABLE\ETL_TEST_INA_WAT_TO_XSIFF\../..\XdmLib\CustomFuction.py", line 596, in file2db_init
    res = do_file(file_root_source_path,
  File "D:\Ina\ETL_XdmLib_2.A.13\ETL_XdmLib_2.A.13\EDAETL\ETL_TABLE\ETL_TEST_INA_WAT_TO_XSIFF\ETL_TEST_INA_TO_XSIFF.py", line 337, in do_file
    e_t = datetime.datetime.now()
AttributeError: type object 'datetime.datetime' has no attribute 'datetime'

During handling of the above exception, another exception occurred:

Traceback (most recent call last):
  File "D:\soft\anaconda3\lib\shutil.py", line 823, in move
    os.rename(src, real_dst)
PermissionError: [WinError 32] 另一个程序正在使用此文件，进程无法访问。: '.\\\\Data\\\\Source\\2022111517445900_0625682.002_PUIXE010MXE3.ad5' -> 'Data\\ERROR\\2022111517445900_0625682.002_PUIXE010MXE3.ad5'

During handling of the above exception, another exception occurred:

Traceback (most recent call last):
  File "D:\Ina\ETL_XdmLib_2.A.13\ETL_XdmLib_2.A.13\EDAETL\ETL_TABLE\ETL_TEST_INA_WAT_TO_XSIFF\../..\XdmLib\CustomFuction.py", line 1035, in move_file
    msg = shutil.move(os.path.join(source_path, fileName),
  File "D:\soft\anaconda3\lib\shutil.py", line 844, in move
    os.unlink(src)
PermissionError: [WinError 32] 另一个程序正在使用此文件，进程无法访问。: '.\\\\Data\\\\Source\\2022111517445900_0625682.002_PUIXE010MXE3.ad5'
Stack (most recent call last):
  File "D:\Ina\ETL_XdmLib_2.A.13\ETL_XdmLib_2.A.13\EDAETL\ETL_TABLE\ETL_TEST_INA_WAT_TO_XSIFF\ETL_TEST_INA_TO_XSIFF.py", line 441, in <module>
    XdmLib.CustomFuction.file2db_init(
  File "D:\Ina\ETL_XdmLib_2.A.13\ETL_XdmLib_2.A.13\EDAETL\ETL_TABLE\ETL_TEST_INA_WAT_TO_XSIFF\../..\XdmLib\CustomFuction.py", line 646, in file2db_init
    move_file_self(move_file_info)
  File "D:\Ina\ETL_XdmLib_2.A.13\ETL_XdmLib_2.A.13\EDAETL\ETL_TABLE\ETL_TEST_INA_WAT_TO_XSIFF\../..\XdmLib\CustomFuction.py", line 1044, in move_file
    log.error(ex, exc_info=True, stack_info=True)
2023-07-21 15:41:10.804 - CustomFuction [ERROR   ] list.append() takes exactly one argument (9 given)
Traceback (most recent call last):
  File "D:\Ina\ETL_XdmLib_2.A.13\ETL_XdmLib_2.A.13\EDAETL\ETL_TABLE\ETL_TEST_INA_WAT_TO_XSIFF\../..\XdmLib\CustomFuction.py", line 596, in file2db_init
    res = do_file(file_root_source_path,
  File "D:\Ina\ETL_XdmLib_2.A.13\ETL_XdmLib_2.A.13\EDAETL\ETL_TABLE\ETL_TEST_INA_WAT_TO_XSIFF\ETL_TEST_INA_TO_XSIFF.py", line 255, in do_file
    SpecLimitList.append(ParameterNo,ParameterName,UnitValue,'NULL','NULL','NULL','NULL',ValidLowValue,ValidHighValue)
TypeError: list.append() takes exactly one argument (9 given)
Stack (most recent call last):
  File "D:\Ina\ETL_XdmLib_2.A.13\ETL_XdmLib_2.A.13\EDAETL\ETL_TABLE\ETL_TEST_INA_WAT_TO_XSIFF\ETL_TEST_INA_TO_XSIFF.py", line 443, in <module>
    XdmLib.CustomFuction.file2db_init(
  File "D:\Ina\ETL_XdmLib_2.A.13\ETL_XdmLib_2.A.13\EDAETL\ETL_TABLE\ETL_TEST_INA_WAT_TO_XSIFF\../..\XdmLib\CustomFuction.py", line 631, in file2db_init
    log.error(ex, exc_info=True, stack_info=True)
2023-07-21 15:41:10.827 - CustomFuction [ERROR   ] Move File Error
2023-07-21 15:41:10.828 - CustomFuction [ERROR   ] [WinError 32] 另一个程序正在使用此文件，进程无法访问。: '.\\\\Data\\\\Source\\2022111517445900_0625682.002_PUIXE010MXE3.ad5'
Traceback (most recent call last):
  File "D:\Ina\ETL_XdmLib_2.A.13\ETL_XdmLib_2.A.13\EDAETL\ETL_TABLE\ETL_TEST_INA_WAT_TO_XSIFF\../..\XdmLib\CustomFuction.py", line 596, in file2db_init
    res = do_file(file_root_source_path,
  File "D:\Ina\ETL_XdmLib_2.A.13\ETL_XdmLib_2.A.13\EDAETL\ETL_TABLE\ETL_TEST_INA_WAT_TO_XSIFF\ETL_TEST_INA_TO_XSIFF.py", line 255, in do_file
    SpecLimitList.append(ParameterNo,ParameterName,UnitValue,'NULL','NULL','NULL','NULL',ValidLowValue,ValidHighValue)
TypeError: list.append() takes exactly one argument (9 given)

During handling of the above exception, another exception occurred:

Traceback (most recent call last):
  File "D:\soft\anaconda3\lib\shutil.py", line 823, in move
    os.rename(src, real_dst)
PermissionError: [WinError 32] 另一个程序正在使用此文件，进程无法访问。: '.\\\\Data\\\\Source\\2022111517445900_0625682.002_PUIXE010MXE3.ad5' -> 'Data\\ERROR\\2022111517445900_0625682.002_PUIXE010MXE3.ad5'

During handling of the above exception, another exception occurred:

Traceback (most recent call last):
  File "D:\Ina\ETL_XdmLib_2.A.13\ETL_XdmLib_2.A.13\EDAETL\ETL_TABLE\ETL_TEST_INA_WAT_TO_XSIFF\../..\XdmLib\CustomFuction.py", line 1035, in move_file
    msg = shutil.move(os.path.join(source_path, fileName),
  File "D:\soft\anaconda3\lib\shutil.py", line 844, in move
    os.unlink(src)
PermissionError: [WinError 32] 另一个程序正在使用此文件，进程无法访问。: '.\\\\Data\\\\Source\\2022111517445900_0625682.002_PUIXE010MXE3.ad5'
Stack (most recent call last):
  File "D:\Ina\ETL_XdmLib_2.A.13\ETL_XdmLib_2.A.13\EDAETL\ETL_TABLE\ETL_TEST_INA_WAT_TO_XSIFF\ETL_TEST_INA_TO_XSIFF.py", line 443, in <module>
    XdmLib.CustomFuction.file2db_init(
  File "D:\Ina\ETL_XdmLib_2.A.13\ETL_XdmLib_2.A.13\EDAETL\ETL_TABLE\ETL_TEST_INA_WAT_TO_XSIFF\../..\XdmLib\CustomFuction.py", line 646, in file2db_init
    move_file_self(move_file_info)
  File "D:\Ina\ETL_XdmLib_2.A.13\ETL_XdmLib_2.A.13\EDAETL\ETL_TABLE\ETL_TEST_INA_WAT_TO_XSIFF\../..\XdmLib\CustomFuction.py", line 1044, in move_file
    log.error(ex, exc_info=True, stack_info=True)
2023-07-21 15:42:01.931 - CustomFuction [ERROR   ] list.append() takes exactly one argument (9 given)
Traceback (most recent call last):
  File "D:\Ina\ETL_XdmLib_2.A.13\ETL_XdmLib_2.A.13\EDAETL\ETL_TABLE\ETL_TEST_INA_WAT_TO_XSIFF\../..\XdmLib\CustomFuction.py", line 596, in file2db_init
    res = do_file(file_root_source_path,
  File "D:\Ina\ETL_XdmLib_2.A.13\ETL_XdmLib_2.A.13\EDAETL\ETL_TABLE\ETL_TEST_INA_WAT_TO_XSIFF\ETL_TEST_INA_TO_XSIFF.py", line 255, in do_file
    SpecLimitList.append(ParameterNo,ParameterName,UnitValue,'NULL','NULL','NULL','NULL',ValidLowValue,ValidHighValue)
TypeError: list.append() takes exactly one argument (9 given)
Stack (most recent call last):
  File "D:\Ina\ETL_XdmLib_2.A.13\ETL_XdmLib_2.A.13\EDAETL\ETL_TABLE\ETL_TEST_INA_WAT_TO_XSIFF\ETL_TEST_INA_TO_XSIFF.py", line 443, in <module>
    XdmLib.CustomFuction.file2db_init(
  File "D:\Ina\ETL_XdmLib_2.A.13\ETL_XdmLib_2.A.13\EDAETL\ETL_TABLE\ETL_TEST_INA_WAT_TO_XSIFF\../..\XdmLib\CustomFuction.py", line 631, in file2db_init
    log.error(ex, exc_info=True, stack_info=True)
2023-07-21 15:42:01.954 - CustomFuction [ERROR   ] Move File Error
2023-07-21 15:42:01.955 - CustomFuction [ERROR   ] [WinError 32] 另一个程序正在使用此文件，进程无法访问。: '.\\\\Data\\\\Source\\2022111517445900_0625682.002_PUIXE010MXE3.ad5'
Traceback (most recent call last):
  File "D:\Ina\ETL_XdmLib_2.A.13\ETL_XdmLib_2.A.13\EDAETL\ETL_TABLE\ETL_TEST_INA_WAT_TO_XSIFF\../..\XdmLib\CustomFuction.py", line 596, in file2db_init
    res = do_file(file_root_source_path,
  File "D:\Ina\ETL_XdmLib_2.A.13\ETL_XdmLib_2.A.13\EDAETL\ETL_TABLE\ETL_TEST_INA_WAT_TO_XSIFF\ETL_TEST_INA_TO_XSIFF.py", line 255, in do_file
    SpecLimitList.append(ParameterNo,ParameterName,UnitValue,'NULL','NULL','NULL','NULL',ValidLowValue,ValidHighValue)
TypeError: list.append() takes exactly one argument (9 given)

During handling of the above exception, another exception occurred:

Traceback (most recent call last):
  File "D:\soft\anaconda3\lib\shutil.py", line 823, in move
    os.rename(src, real_dst)
PermissionError: [WinError 32] 另一个程序正在使用此文件，进程无法访问。: '.\\\\Data\\\\Source\\2022111517445900_0625682.002_PUIXE010MXE3.ad5' -> 'Data\\ERROR\\2022111517445900_0625682.002_PUIXE010MXE3.ad5'

During handling of the above exception, another exception occurred:

Traceback (most recent call last):
  File "D:\Ina\ETL_XdmLib_2.A.13\ETL_XdmLib_2.A.13\EDAETL\ETL_TABLE\ETL_TEST_INA_WAT_TO_XSIFF\../..\XdmLib\CustomFuction.py", line 1035, in move_file
    msg = shutil.move(os.path.join(source_path, fileName),
  File "D:\soft\anaconda3\lib\shutil.py", line 844, in move
    os.unlink(src)
PermissionError: [WinError 32] 另一个程序正在使用此文件，进程无法访问。: '.\\\\Data\\\\Source\\2022111517445900_0625682.002_PUIXE010MXE3.ad5'
Stack (most recent call last):
  File "D:\Ina\ETL_XdmLib_2.A.13\ETL_XdmLib_2.A.13\EDAETL\ETL_TABLE\ETL_TEST_INA_WAT_TO_XSIFF\ETL_TEST_INA_TO_XSIFF.py", line 443, in <module>
    XdmLib.CustomFuction.file2db_init(
  File "D:\Ina\ETL_XdmLib_2.A.13\ETL_XdmLib_2.A.13\EDAETL\ETL_TABLE\ETL_TEST_INA_WAT_TO_XSIFF\../..\XdmLib\CustomFuction.py", line 646, in file2db_init
    move_file_self(move_file_info)
  File "D:\Ina\ETL_XdmLib_2.A.13\ETL_XdmLib_2.A.13\EDAETL\ETL_TABLE\ETL_TEST_INA_WAT_TO_XSIFF\../..\XdmLib\CustomFuction.py", line 1044, in move_file
    log.error(ex, exc_info=True, stack_info=True)
2023-07-21 15:42:27.952 - CustomFuction [ERROR   ] list.append() takes exactly one argument (9 given)
Traceback (most recent call last):
  File "D:\Ina\ETL_XdmLib_2.A.13\ETL_XdmLib_2.A.13\EDAETL\ETL_TABLE\ETL_TEST_INA_WAT_TO_XSIFF\../..\XdmLib\CustomFuction.py", line 596, in file2db_init
    res = do_file(file_root_source_path,
  File "D:\Ina\ETL_XdmLib_2.A.13\ETL_XdmLib_2.A.13\EDAETL\ETL_TABLE\ETL_TEST_INA_WAT_TO_XSIFF\ETL_TEST_INA_TO_XSIFF.py", line 255, in do_file
    SpecLimitList.append(ParameterNo,ParameterName,UnitValue,'NULL','NULL','NULL','NULL',ValidLowValue,ValidHighValue)
TypeError: list.append() takes exactly one argument (9 given)
Stack (most recent call last):
  File "D:\Ina\ETL_XdmLib_2.A.13\ETL_XdmLib_2.A.13\EDAETL\ETL_TABLE\ETL_TEST_INA_WAT_TO_XSIFF\ETL_TEST_INA_TO_XSIFF.py", line 443, in <module>
    XdmLib.CustomFuction.file2db_init(
  File "D:\Ina\ETL_XdmLib_2.A.13\ETL_XdmLib_2.A.13\EDAETL\ETL_TABLE\ETL_TEST_INA_WAT_TO_XSIFF\../..\XdmLib\CustomFuction.py", line 631, in file2db_init
    log.error(ex, exc_info=True, stack_info=True)
2023-07-21 15:42:27.982 - CustomFuction [ERROR   ] Move File Error
2023-07-21 15:42:27.985 - CustomFuction [ERROR   ] [WinError 32] 另一个程序正在使用此文件，进程无法访问。: '.\\\\Data\\\\Source\\2022111517445900_0625682.002_PUIXE010MXE3.ad5'
Traceback (most recent call last):
  File "D:\Ina\ETL_XdmLib_2.A.13\ETL_XdmLib_2.A.13\EDAETL\ETL_TABLE\ETL_TEST_INA_WAT_TO_XSIFF\../..\XdmLib\CustomFuction.py", line 596, in file2db_init
    res = do_file(file_root_source_path,
  File "D:\Ina\ETL_XdmLib_2.A.13\ETL_XdmLib_2.A.13\EDAETL\ETL_TABLE\ETL_TEST_INA_WAT_TO_XSIFF\ETL_TEST_INA_TO_XSIFF.py", line 255, in do_file
    SpecLimitList.append(ParameterNo,ParameterName,UnitValue,'NULL','NULL','NULL','NULL',ValidLowValue,ValidHighValue)
TypeError: list.append() takes exactly one argument (9 given)

During handling of the above exception, another exception occurred:

Traceback (most recent call last):
  File "D:\soft\anaconda3\lib\shutil.py", line 823, in move
    os.rename(src, real_dst)
PermissionError: [WinError 32] 另一个程序正在使用此文件，进程无法访问。: '.\\\\Data\\\\Source\\2022111517445900_0625682.002_PUIXE010MXE3.ad5' -> 'Data\\ERROR\\2022111517445900_0625682.002_PUIXE010MXE3.ad5'

During handling of the above exception, another exception occurred:

Traceback (most recent call last):
  File "D:\Ina\ETL_XdmLib_2.A.13\ETL_XdmLib_2.A.13\EDAETL\ETL_TABLE\ETL_TEST_INA_WAT_TO_XSIFF\../..\XdmLib\CustomFuction.py", line 1035, in move_file
    msg = shutil.move(os.path.join(source_path, fileName),
  File "D:\soft\anaconda3\lib\shutil.py", line 844, in move
    os.unlink(src)
PermissionError: [WinError 32] 另一个程序正在使用此文件，进程无法访问。: '.\\\\Data\\\\Source\\2022111517445900_0625682.002_PUIXE010MXE3.ad5'
Stack (most recent call last):
  File "D:\Ina\ETL_XdmLib_2.A.13\ETL_XdmLib_2.A.13\EDAETL\ETL_TABLE\ETL_TEST_INA_WAT_TO_XSIFF\ETL_TEST_INA_TO_XSIFF.py", line 443, in <module>
    XdmLib.CustomFuction.file2db_init(
  File "D:\Ina\ETL_XdmLib_2.A.13\ETL_XdmLib_2.A.13\EDAETL\ETL_TABLE\ETL_TEST_INA_WAT_TO_XSIFF\../..\XdmLib\CustomFuction.py", line 646, in file2db_init
    move_file_self(move_file_info)
  File "D:\Ina\ETL_XdmLib_2.A.13\ETL_XdmLib_2.A.13\EDAETL\ETL_TABLE\ETL_TEST_INA_WAT_TO_XSIFF\../..\XdmLib\CustomFuction.py", line 1044, in move_file
    log.error(ex, exc_info=True, stack_info=True)
2023-07-21 15:43:49.467 - CustomFuction [ERROR   ] list.append() takes exactly one argument (9 given)
Traceback (most recent call last):
  File "D:\Ina\ETL_XdmLib_2.A.13\ETL_XdmLib_2.A.13\EDAETL\ETL_TABLE\ETL_TEST_INA_WAT_TO_XSIFF\../..\XdmLib\CustomFuction.py", line 596, in file2db_init
    res = do_file(file_root_source_path,
  File "D:\Ina\ETL_XdmLib_2.A.13\ETL_XdmLib_2.A.13\EDAETL\ETL_TABLE\ETL_TEST_INA_WAT_TO_XSIFF\ETL_TEST_INA_TO_XSIFF.py", line 255, in do_file
    SpecLimitList.append(ParameterNo,ParameterName,UnitValue,'NULL','NULL','NULL','NULL',ValidLowValue,ValidHighValue)
TypeError: list.append() takes exactly one argument (9 given)
Stack (most recent call last):
  File "D:\Ina\ETL_XdmLib_2.A.13\ETL_XdmLib_2.A.13\EDAETL\ETL_TABLE\ETL_TEST_INA_WAT_TO_XSIFF\ETL_TEST_INA_TO_XSIFF.py", line 443, in <module>
    XdmLib.CustomFuction.file2db_init(
  File "D:\Ina\ETL_XdmLib_2.A.13\ETL_XdmLib_2.A.13\EDAETL\ETL_TABLE\ETL_TEST_INA_WAT_TO_XSIFF\../..\XdmLib\CustomFuction.py", line 631, in file2db_init
    log.error(ex, exc_info=True, stack_info=True)
2023-07-21 15:43:49.491 - CustomFuction [ERROR   ] Move File Error
2023-07-21 15:43:49.492 - CustomFuction [ERROR   ] [WinError 32] 另一个程序正在使用此文件，进程无法访问。: '.\\\\Data\\\\Source\\2022111517445900_0625682.002_PUIXE010MXE3.ad5'
Traceback (most recent call last):
  File "D:\Ina\ETL_XdmLib_2.A.13\ETL_XdmLib_2.A.13\EDAETL\ETL_TABLE\ETL_TEST_INA_WAT_TO_XSIFF\../..\XdmLib\CustomFuction.py", line 596, in file2db_init
    res = do_file(file_root_source_path,
  File "D:\Ina\ETL_XdmLib_2.A.13\ETL_XdmLib_2.A.13\EDAETL\ETL_TABLE\ETL_TEST_INA_WAT_TO_XSIFF\ETL_TEST_INA_TO_XSIFF.py", line 255, in do_file
    SpecLimitList.append(ParameterNo,ParameterName,UnitValue,'NULL','NULL','NULL','NULL',ValidLowValue,ValidHighValue)
TypeError: list.append() takes exactly one argument (9 given)

During handling of the above exception, another exception occurred:

Traceback (most recent call last):
  File "D:\soft\anaconda3\lib\shutil.py", line 823, in move
    os.rename(src, real_dst)
PermissionError: [WinError 32] 另一个程序正在使用此文件，进程无法访问。: '.\\\\Data\\\\Source\\2022111517445900_0625682.002_PUIXE010MXE3.ad5' -> 'Data\\ERROR\\2022111517445900_0625682.002_PUIXE010MXE3.ad5'

During handling of the above exception, another exception occurred:

Traceback (most recent call last):
  File "D:\Ina\ETL_XdmLib_2.A.13\ETL_XdmLib_2.A.13\EDAETL\ETL_TABLE\ETL_TEST_INA_WAT_TO_XSIFF\../..\XdmLib\CustomFuction.py", line 1035, in move_file
    msg = shutil.move(os.path.join(source_path, fileName),
  File "D:\soft\anaconda3\lib\shutil.py", line 844, in move
    os.unlink(src)
PermissionError: [WinError 32] 另一个程序正在使用此文件，进程无法访问。: '.\\\\Data\\\\Source\\2022111517445900_0625682.002_PUIXE010MXE3.ad5'
Stack (most recent call last):
  File "D:\Ina\ETL_XdmLib_2.A.13\ETL_XdmLib_2.A.13\EDAETL\ETL_TABLE\ETL_TEST_INA_WAT_TO_XSIFF\ETL_TEST_INA_TO_XSIFF.py", line 443, in <module>
    XdmLib.CustomFuction.file2db_init(
  File "D:\Ina\ETL_XdmLib_2.A.13\ETL_XdmLib_2.A.13\EDAETL\ETL_TABLE\ETL_TEST_INA_WAT_TO_XSIFF\../..\XdmLib\CustomFuction.py", line 646, in file2db_init
    move_file_self(move_file_info)
  File "D:\Ina\ETL_XdmLib_2.A.13\ETL_XdmLib_2.A.13\EDAETL\ETL_TABLE\ETL_TEST_INA_WAT_TO_XSIFF\../..\XdmLib\CustomFuction.py", line 1044, in move_file
    log.error(ex, exc_info=True, stack_info=True)
2023-07-21 15:57:05.758 - CustomFuction [ERROR   ] name 'fileName' is not defined
Traceback (most recent call last):
  File "D:\Ina\ETL_XdmLib_2.A.13\ETL_XdmLib_2.A.13\EDAETL\ETL_TABLE\ETL_TEST_INA_WAT_TO_XSIFF\../..\XdmLib\CustomFuction.py", line 596, in file2db_init
    res = do_file(file_root_source_path,
  File "D:\Ina\ETL_XdmLib_2.A.13\ETL_XdmLib_2.A.13\EDAETL\ETL_TABLE\ETL_TEST_INA_WAT_TO_XSIFF\ETL_TEST_INA_TO_XSIFF.py", line 302, in do_file
    'SrcFileName': fileName
NameError: name 'fileName' is not defined
Stack (most recent call last):
  File "D:\Ina\ETL_XdmLib_2.A.13\ETL_XdmLib_2.A.13\EDAETL\ETL_TABLE\ETL_TEST_INA_WAT_TO_XSIFF\ETL_TEST_INA_TO_XSIFF.py", line 434, in <module>
    XdmLib.CustomFuction.file2db_init(
  File "D:\Ina\ETL_XdmLib_2.A.13\ETL_XdmLib_2.A.13\EDAETL\ETL_TABLE\ETL_TEST_INA_WAT_TO_XSIFF\../..\XdmLib\CustomFuction.py", line 631, in file2db_init
    log.error(ex, exc_info=True, stack_info=True)
2023-07-21 15:57:05.776 - CustomFuction [ERROR   ] Move File Error
2023-07-21 15:57:05.777 - CustomFuction [ERROR   ] [WinError 32] 另一个程序正在使用此文件，进程无法访问。: '.\\\\Data\\\\Source\\2022111517445900_0625682.002_PUIXE010MXE3.ad5'
Traceback (most recent call last):
  File "D:\Ina\ETL_XdmLib_2.A.13\ETL_XdmLib_2.A.13\EDAETL\ETL_TABLE\ETL_TEST_INA_WAT_TO_XSIFF\../..\XdmLib\CustomFuction.py", line 596, in file2db_init
    res = do_file(file_root_source_path,
  File "D:\Ina\ETL_XdmLib_2.A.13\ETL_XdmLib_2.A.13\EDAETL\ETL_TABLE\ETL_TEST_INA_WAT_TO_XSIFF\ETL_TEST_INA_TO_XSIFF.py", line 302, in do_file
    'SrcFileName': fileName
NameError: name 'fileName' is not defined

During handling of the above exception, another exception occurred:

Traceback (most recent call last):
  File "D:\soft\anaconda3\lib\shutil.py", line 823, in move
    os.rename(src, real_dst)
PermissionError: [WinError 32] 另一个程序正在使用此文件，进程无法访问。: '.\\\\Data\\\\Source\\2022111517445900_0625682.002_PUIXE010MXE3.ad5' -> 'Data\\ERROR\\2022111517445900_0625682.002_PUIXE010MXE3.ad5'

During handling of the above exception, another exception occurred:

Traceback (most recent call last):
  File "D:\Ina\ETL_XdmLib_2.A.13\ETL_XdmLib_2.A.13\EDAETL\ETL_TABLE\ETL_TEST_INA_WAT_TO_XSIFF\../..\XdmLib\CustomFuction.py", line 1035, in move_file
    msg = shutil.move(os.path.join(source_path, fileName),
  File "D:\soft\anaconda3\lib\shutil.py", line 844, in move
    os.unlink(src)
PermissionError: [WinError 32] 另一个程序正在使用此文件，进程无法访问。: '.\\\\Data\\\\Source\\2022111517445900_0625682.002_PUIXE010MXE3.ad5'
Stack (most recent call last):
  File "D:\Ina\ETL_XdmLib_2.A.13\ETL_XdmLib_2.A.13\EDAETL\ETL_TABLE\ETL_TEST_INA_WAT_TO_XSIFF\ETL_TEST_INA_TO_XSIFF.py", line 434, in <module>
    XdmLib.CustomFuction.file2db_init(
  File "D:\Ina\ETL_XdmLib_2.A.13\ETL_XdmLib_2.A.13\EDAETL\ETL_TABLE\ETL_TEST_INA_WAT_TO_XSIFF\../..\XdmLib\CustomFuction.py", line 646, in file2db_init
    move_file_self(move_file_info)
  File "D:\Ina\ETL_XdmLib_2.A.13\ETL_XdmLib_2.A.13\EDAETL\ETL_TABLE\ETL_TEST_INA_WAT_TO_XSIFF\../..\XdmLib\CustomFuction.py", line 1044, in move_file
    log.error(ex, exc_info=True, stack_info=True)
2023-07-21 15:59:53.916 - CustomFuction [ERROR   ] name 'fileName' is not defined
Traceback (most recent call last):
  File "D:\Ina\ETL_XdmLib_2.A.13\ETL_XdmLib_2.A.13\EDAETL\ETL_TABLE\ETL_TEST_INA_WAT_TO_XSIFF\../..\XdmLib\CustomFuction.py", line 596, in file2db_init
    res = do_file(file_root_source_path,
  File "D:\Ina\ETL_XdmLib_2.A.13\ETL_XdmLib_2.A.13\EDAETL\ETL_TABLE\ETL_TEST_INA_WAT_TO_XSIFF\ETL_TEST_INA_TO_XSIFF.py", line 303, in do_file
    'SrcFileName': fileName
NameError: name 'fileName' is not defined
Stack (most recent call last):
  File "D:\Ina\ETL_XdmLib_2.A.13\ETL_XdmLib_2.A.13\EDAETL\ETL_TABLE\ETL_TEST_INA_WAT_TO_XSIFF\ETL_TEST_INA_TO_XSIFF.py", line 435, in <module>
    XdmLib.CustomFuction.file2db_init(
  File "D:\Ina\ETL_XdmLib_2.A.13\ETL_XdmLib_2.A.13\EDAETL\ETL_TABLE\ETL_TEST_INA_WAT_TO_XSIFF\../..\XdmLib\CustomFuction.py", line 631, in file2db_init
    log.error(ex, exc_info=True, stack_info=True)
2023-07-21 15:59:53.936 - CustomFuction [ERROR   ] Move File Error
2023-07-21 15:59:53.937 - CustomFuction [ERROR   ] [WinError 32] 另一个程序正在使用此文件，进程无法访问。: '.\\\\Data\\\\Source\\2022111517445900_0625682.002_PUIXE010MXE3.ad5'
Traceback (most recent call last):
  File "D:\Ina\ETL_XdmLib_2.A.13\ETL_XdmLib_2.A.13\EDAETL\ETL_TABLE\ETL_TEST_INA_WAT_TO_XSIFF\../..\XdmLib\CustomFuction.py", line 596, in file2db_init
    res = do_file(file_root_source_path,
  File "D:\Ina\ETL_XdmLib_2.A.13\ETL_XdmLib_2.A.13\EDAETL\ETL_TABLE\ETL_TEST_INA_WAT_TO_XSIFF\ETL_TEST_INA_TO_XSIFF.py", line 303, in do_file
    'SrcFileName': fileName
NameError: name 'fileName' is not defined

During handling of the above exception, another exception occurred:

Traceback (most recent call last):
  File "D:\soft\anaconda3\lib\shutil.py", line 823, in move
    os.rename(src, real_dst)
PermissionError: [WinError 32] 另一个程序正在使用此文件，进程无法访问。: '.\\\\Data\\\\Source\\2022111517445900_0625682.002_PUIXE010MXE3.ad5' -> 'Data\\ERROR\\2022111517445900_0625682.002_PUIXE010MXE3.ad5'

During handling of the above exception, another exception occurred:

Traceback (most recent call last):
  File "D:\Ina\ETL_XdmLib_2.A.13\ETL_XdmLib_2.A.13\EDAETL\ETL_TABLE\ETL_TEST_INA_WAT_TO_XSIFF\../..\XdmLib\CustomFuction.py", line 1035, in move_file
    msg = shutil.move(os.path.join(source_path, fileName),
  File "D:\soft\anaconda3\lib\shutil.py", line 844, in move
    os.unlink(src)
PermissionError: [WinError 32] 另一个程序正在使用此文件，进程无法访问。: '.\\\\Data\\\\Source\\2022111517445900_0625682.002_PUIXE010MXE3.ad5'
Stack (most recent call last):
  File "D:\Ina\ETL_XdmLib_2.A.13\ETL_XdmLib_2.A.13\EDAETL\ETL_TABLE\ETL_TEST_INA_WAT_TO_XSIFF\ETL_TEST_INA_TO_XSIFF.py", line 435, in <module>
    XdmLib.CustomFuction.file2db_init(
  File "D:\Ina\ETL_XdmLib_2.A.13\ETL_XdmLib_2.A.13\EDAETL\ETL_TABLE\ETL_TEST_INA_WAT_TO_XSIFF\../..\XdmLib\CustomFuction.py", line 646, in file2db_init
    move_file_self(move_file_info)
  File "D:\Ina\ETL_XdmLib_2.A.13\ETL_XdmLib_2.A.13\EDAETL\ETL_TABLE\ETL_TEST_INA_WAT_TO_XSIFF\../..\XdmLib\CustomFuction.py", line 1044, in move_file
    log.error(ex, exc_info=True, stack_info=True)
2023-07-21 16:04:16.619 - CustomFuction [ERROR   ] name 'fileName' is not defined
Traceback (most recent call last):
  File "D:\Ina\ETL_XdmLib_2.A.13\ETL_XdmLib_2.A.13\EDAETL\ETL_TABLE\ETL_TEST_INA_WAT_TO_XSIFF\../..\XdmLib\CustomFuction.py", line 596, in file2db_init
    res = do_file(file_root_source_path,
  File "D:\Ina\ETL_XdmLib_2.A.13\ETL_XdmLib_2.A.13\EDAETL\ETL_TABLE\ETL_TEST_INA_WAT_TO_XSIFF\ETL_TEST_INA_TO_XSIFF.py", line 303, in do_file
    'SrcFileName': fileName
NameError: name 'fileName' is not defined
Stack (most recent call last):
  File "D:\Ina\ETL_XdmLib_2.A.13\ETL_XdmLib_2.A.13\EDAETL\ETL_TABLE\ETL_TEST_INA_WAT_TO_XSIFF\ETL_TEST_INA_TO_XSIFF.py", line 436, in <module>
    XdmLib.CustomFuction.file2db_init(
  File "D:\Ina\ETL_XdmLib_2.A.13\ETL_XdmLib_2.A.13\EDAETL\ETL_TABLE\ETL_TEST_INA_WAT_TO_XSIFF\../..\XdmLib\CustomFuction.py", line 631, in file2db_init
    log.error(ex, exc_info=True, stack_info=True)
2023-07-21 16:04:16.638 - CustomFuction [ERROR   ] Move File Error
2023-07-21 16:04:16.639 - CustomFuction [ERROR   ] [WinError 32] 另一个程序正在使用此文件，进程无法访问。: '.\\\\Data\\\\Source\\2022111517445900_0625682.002_PUIXE010MXE3.ad5'
Traceback (most recent call last):
  File "D:\Ina\ETL_XdmLib_2.A.13\ETL_XdmLib_2.A.13\EDAETL\ETL_TABLE\ETL_TEST_INA_WAT_TO_XSIFF\../..\XdmLib\CustomFuction.py", line 596, in file2db_init
    res = do_file(file_root_source_path,
  File "D:\Ina\ETL_XdmLib_2.A.13\ETL_XdmLib_2.A.13\EDAETL\ETL_TABLE\ETL_TEST_INA_WAT_TO_XSIFF\ETL_TEST_INA_TO_XSIFF.py", line 303, in do_file
    'SrcFileName': fileName
NameError: name 'fileName' is not defined

During handling of the above exception, another exception occurred:

Traceback (most recent call last):
  File "D:\soft\anaconda3\lib\shutil.py", line 823, in move
    os.rename(src, real_dst)
PermissionError: [WinError 32] 另一个程序正在使用此文件，进程无法访问。: '.\\\\Data\\\\Source\\2022111517445900_0625682.002_PUIXE010MXE3.ad5' -> 'Data\\ERROR\\2022111517445900_0625682.002_PUIXE010MXE3.ad5'

During handling of the above exception, another exception occurred:

Traceback (most recent call last):
  File "D:\Ina\ETL_XdmLib_2.A.13\ETL_XdmLib_2.A.13\EDAETL\ETL_TABLE\ETL_TEST_INA_WAT_TO_XSIFF\../..\XdmLib\CustomFuction.py", line 1035, in move_file
    msg = shutil.move(os.path.join(source_path, fileName),
  File "D:\soft\anaconda3\lib\shutil.py", line 844, in move
    os.unlink(src)
PermissionError: [WinError 32] 另一个程序正在使用此文件，进程无法访问。: '.\\\\Data\\\\Source\\2022111517445900_0625682.002_PUIXE010MXE3.ad5'
Stack (most recent call last):
  File "D:\Ina\ETL_XdmLib_2.A.13\ETL_XdmLib_2.A.13\EDAETL\ETL_TABLE\ETL_TEST_INA_WAT_TO_XSIFF\ETL_TEST_INA_TO_XSIFF.py", line 436, in <module>
    XdmLib.CustomFuction.file2db_init(
  File "D:\Ina\ETL_XdmLib_2.A.13\ETL_XdmLib_2.A.13\EDAETL\ETL_TABLE\ETL_TEST_INA_WAT_TO_XSIFF\../..\XdmLib\CustomFuction.py", line 646, in file2db_init
    move_file_self(move_file_info)
  File "D:\Ina\ETL_XdmLib_2.A.13\ETL_XdmLib_2.A.13\EDAETL\ETL_TABLE\ETL_TEST_INA_WAT_TO_XSIFF\../..\XdmLib\CustomFuction.py", line 1044, in move_file
    log.error(ex, exc_info=True, stack_info=True)
2023-07-21 17:32:30.934 - CustomFuction [ERROR   ] name 'SiteId' is not defined
Traceback (most recent call last):
  File "D:\Ina\ETL_XdmLib_2.A.13\ETL_XdmLib_2.A.13\EDAETL\ETL_TABLE\ETL_TEST_INA_WAT_TO_XSIFF\../..\XdmLib\CustomFuction.py", line 596, in file2db_init
    res = do_file(file_root_source_path,
  File "D:\Ina\ETL_XdmLib_2.A.13\ETL_XdmLib_2.A.13\EDAETL\ETL_TABLE\ETL_TEST_INA_WAT_TO_XSIFF\ETL_TEST_INA_TO_XSIFF.py", line 249, in do_file
    process_HP(processList)
  File "D:\Ina\ETL_XdmLib_2.A.13\ETL_XdmLib_2.A.13\EDAETL\ETL_TABLE\ETL_TEST_INA_WAT_TO_XSIFF\ETL_TEST_INA_TO_XSIFF.py", line 84, in process_HP
    SiteId.append(processList[i].strip().split(' ')[1])
NameError: name 'SiteId' is not defined
Stack (most recent call last):
  File "D:\Ina\ETL_XdmLib_2.A.13\ETL_XdmLib_2.A.13\EDAETL\ETL_TABLE\ETL_TEST_INA_WAT_TO_XSIFF\ETL_TEST_INA_TO_XSIFF.py", line 429, in <module>
    XdmLib.CustomFuction.file2db_init(
  File "D:\Ina\ETL_XdmLib_2.A.13\ETL_XdmLib_2.A.13\EDAETL\ETL_TABLE\ETL_TEST_INA_WAT_TO_XSIFF\../..\XdmLib\CustomFuction.py", line 631, in file2db_init
    log.error(ex, exc_info=True, stack_info=True)
2023-07-21 17:32:30.956 - CustomFuction [ERROR   ] Move File Error
2023-07-21 17:32:30.957 - CustomFuction [ERROR   ] [WinError 32] 另一个程序正在使用此文件，进程无法访问。: '.\\\\Data\\\\Source\\2022111517445900_0625682.002_PUIXE010MXE3.ad5'
Traceback (most recent call last):
  File "D:\Ina\ETL_XdmLib_2.A.13\ETL_XdmLib_2.A.13\EDAETL\ETL_TABLE\ETL_TEST_INA_WAT_TO_XSIFF\../..\XdmLib\CustomFuction.py", line 596, in file2db_init
    res = do_file(file_root_source_path,
  File "D:\Ina\ETL_XdmLib_2.A.13\ETL_XdmLib_2.A.13\EDAETL\ETL_TABLE\ETL_TEST_INA_WAT_TO_XSIFF\ETL_TEST_INA_TO_XSIFF.py", line 249, in do_file
    process_HP(processList)
  File "D:\Ina\ETL_XdmLib_2.A.13\ETL_XdmLib_2.A.13\EDAETL\ETL_TABLE\ETL_TEST_INA_WAT_TO_XSIFF\ETL_TEST_INA_TO_XSIFF.py", line 84, in process_HP
    SiteId.append(processList[i].strip().split(' ')[1])
NameError: name 'SiteId' is not defined

During handling of the above exception, another exception occurred:

Traceback (most recent call last):
  File "D:\soft\anaconda3\lib\shutil.py", line 823, in move
    os.rename(src, real_dst)
PermissionError: [WinError 32] 另一个程序正在使用此文件，进程无法访问。: '.\\\\Data\\\\Source\\2022111517445900_0625682.002_PUIXE010MXE3.ad5' -> 'Data\\ERROR\\2022111517445900_0625682.002_PUIXE010MXE3.ad5'

During handling of the above exception, another exception occurred:

Traceback (most recent call last):
  File "D:\Ina\ETL_XdmLib_2.A.13\ETL_XdmLib_2.A.13\EDAETL\ETL_TABLE\ETL_TEST_INA_WAT_TO_XSIFF\../..\XdmLib\CustomFuction.py", line 1035, in move_file
    msg = shutil.move(os.path.join(source_path, fileName),
  File "D:\soft\anaconda3\lib\shutil.py", line 844, in move
    os.unlink(src)
PermissionError: [WinError 32] 另一个程序正在使用此文件，进程无法访问。: '.\\\\Data\\\\Source\\2022111517445900_0625682.002_PUIXE010MXE3.ad5'
Stack (most recent call last):
  File "D:\Ina\ETL_XdmLib_2.A.13\ETL_XdmLib_2.A.13\EDAETL\ETL_TABLE\ETL_TEST_INA_WAT_TO_XSIFF\ETL_TEST_INA_TO_XSIFF.py", line 429, in <module>
    XdmLib.CustomFuction.file2db_init(
  File "D:\Ina\ETL_XdmLib_2.A.13\ETL_XdmLib_2.A.13\EDAETL\ETL_TABLE\ETL_TEST_INA_WAT_TO_XSIFF\../..\XdmLib\CustomFuction.py", line 646, in file2db_init
    move_file_self(move_file_info)
  File "D:\Ina\ETL_XdmLib_2.A.13\ETL_XdmLib_2.A.13\EDAETL\ETL_TABLE\ETL_TEST_INA_WAT_TO_XSIFF\../..\XdmLib\CustomFuction.py", line 1044, in move_file
    log.error(ex, exc_info=True, stack_info=True)
2023-07-21 17:33:53.457 - CustomFuction [ERROR   ] name 'SiteId' is not defined
Traceback (most recent call last):
  File "D:\Ina\ETL_XdmLib_2.A.13\ETL_XdmLib_2.A.13\EDAETL\ETL_TABLE\ETL_TEST_INA_WAT_TO_XSIFF\../..\XdmLib\CustomFuction.py", line 596, in file2db_init
    res = do_file(file_root_source_path,
  File "D:\Ina\ETL_XdmLib_2.A.13\ETL_XdmLib_2.A.13\EDAETL\ETL_TABLE\ETL_TEST_INA_WAT_TO_XSIFF\ETL_TEST_INA_TO_XSIFF.py", line 249, in do_file
    process_HP(processList)
  File "D:\Ina\ETL_XdmLib_2.A.13\ETL_XdmLib_2.A.13\EDAETL\ETL_TABLE\ETL_TEST_INA_WAT_TO_XSIFF\ETL_TEST_INA_TO_XSIFF.py", line 88, in process_HP
    for i in range (0,len(SiteId)):
NameError: name 'SiteId' is not defined
Stack (most recent call last):
  File "D:\Ina\ETL_XdmLib_2.A.13\ETL_XdmLib_2.A.13\EDAETL\ETL_TABLE\ETL_TEST_INA_WAT_TO_XSIFF\ETL_TEST_INA_TO_XSIFF.py", line 429, in <module>
    XdmLib.CustomFuction.file2db_init(
  File "D:\Ina\ETL_XdmLib_2.A.13\ETL_XdmLib_2.A.13\EDAETL\ETL_TABLE\ETL_TEST_INA_WAT_TO_XSIFF\../..\XdmLib\CustomFuction.py", line 631, in file2db_init
    log.error(ex, exc_info=True, stack_info=True)
2023-07-21 17:33:53.476 - CustomFuction [ERROR   ] Move File Error
2023-07-21 17:33:53.477 - CustomFuction [ERROR   ] [WinError 32] 另一个程序正在使用此文件，进程无法访问。: '.\\\\Data\\\\Source\\2022111517445900_0625682.002_PUIXE010MXE3.ad5'
Traceback (most recent call last):
  File "D:\Ina\ETL_XdmLib_2.A.13\ETL_XdmLib_2.A.13\EDAETL\ETL_TABLE\ETL_TEST_INA_WAT_TO_XSIFF\../..\XdmLib\CustomFuction.py", line 596, in file2db_init
    res = do_file(file_root_source_path,
  File "D:\Ina\ETL_XdmLib_2.A.13\ETL_XdmLib_2.A.13\EDAETL\ETL_TABLE\ETL_TEST_INA_WAT_TO_XSIFF\ETL_TEST_INA_TO_XSIFF.py", line 249, in do_file
    process_HP(processList)
  File "D:\Ina\ETL_XdmLib_2.A.13\ETL_XdmLib_2.A.13\EDAETL\ETL_TABLE\ETL_TEST_INA_WAT_TO_XSIFF\ETL_TEST_INA_TO_XSIFF.py", line 88, in process_HP
    for i in range (0,len(SiteId)):
NameError: name 'SiteId' is not defined

During handling of the above exception, another exception occurred:

Traceback (most recent call last):
  File "D:\soft\anaconda3\lib\shutil.py", line 823, in move
    os.rename(src, real_dst)
PermissionError: [WinError 32] 另一个程序正在使用此文件，进程无法访问。: '.\\\\Data\\\\Source\\2022111517445900_0625682.002_PUIXE010MXE3.ad5' -> 'Data\\ERROR\\2022111517445900_0625682.002_PUIXE010MXE3.ad5'

During handling of the above exception, another exception occurred:

Traceback (most recent call last):
  File "D:\Ina\ETL_XdmLib_2.A.13\ETL_XdmLib_2.A.13\EDAETL\ETL_TABLE\ETL_TEST_INA_WAT_TO_XSIFF\../..\XdmLib\CustomFuction.py", line 1035, in move_file
    msg = shutil.move(os.path.join(source_path, fileName),
  File "D:\soft\anaconda3\lib\shutil.py", line 844, in move
    os.unlink(src)
PermissionError: [WinError 32] 另一个程序正在使用此文件，进程无法访问。: '.\\\\Data\\\\Source\\2022111517445900_0625682.002_PUIXE010MXE3.ad5'
Stack (most recent call last):
  File "D:\Ina\ETL_XdmLib_2.A.13\ETL_XdmLib_2.A.13\EDAETL\ETL_TABLE\ETL_TEST_INA_WAT_TO_XSIFF\ETL_TEST_INA_TO_XSIFF.py", line 429, in <module>
    XdmLib.CustomFuction.file2db_init(
  File "D:\Ina\ETL_XdmLib_2.A.13\ETL_XdmLib_2.A.13\EDAETL\ETL_TABLE\ETL_TEST_INA_WAT_TO_XSIFF\../..\XdmLib\CustomFuction.py", line 646, in file2db_init
    move_file_self(move_file_info)
  File "D:\Ina\ETL_XdmLib_2.A.13\ETL_XdmLib_2.A.13\EDAETL\ETL_TABLE\ETL_TEST_INA_WAT_TO_XSIFF\../..\XdmLib\CustomFuction.py", line 1044, in move_file
    log.error(ex, exc_info=True, stack_info=True)
