2023-11-02 13:14:16.257 - CustomFuction [ERROR   ] DPI-1080: connection was closed by ORA-3113
Traceback (most recent call last):
  File "../..\XdmLib\CustomFuction.py", line 605, in file2db_init
    db_tgt.commit()
  File "../..\XdmLib\Database.py", line 386, in commit
    return self.connection.commit()
cx_Oracle.DatabaseError: DPI-1080: connection was closed by ORA-3113
Stack (most recent call last):
  File "D:\soft\PyCharm Community Edition 2022.1.3\plugins\python-ce\helpers\pydev\pydevd.py", line 2181, in <module>
    main()
  File "D:\soft\PyCharm Community Edition 2022.1.3\plugins\python-ce\helpers\pydev\pydevd.py", line 2172, in main
    globals = debugger.run(setup['file'], None, None, is_module)
  File "D:\soft\PyCharm Community Edition 2022.1.3\plugins\python-ce\helpers\pydev\pydevd.py", line 1484, in run
    return self._exec(is_module, entry_point_fn, module_name, file, globals, locals)
  File "D:\soft\PyCharm Community Edition 2022.1.3\plugins\python-ce\helpers\pydev\pydevd.py", line 1491, in _exec
    pydev_imports.execfile(file, globals, locals)  # execute the script
  File "D:\soft\PyCharm Community Edition 2022.1.3\plugins\python-ce\helpers\pydev\_pydev_imps\_pydev_execfile.py", line 18, in execfile
    exec(compile(contents+"\n", file, 'exec'), glob, loc)
  File "D:/Ina/ETL_XdmLib_2.A.13/ETL_XdmLib_2.A.13/EDAETL/ETL_TABLE/ETL_LOT_XML_TO_XSIFF/ETL_LOT_XML_TO_XSIFF.py", line 289, in <module>
    do_file, before_do_file, after_do_file, skip_file, None, log, config, config_sql)
  File "../..\XdmLib\CustomFuction.py", line 631, in file2db_init
    log.error(ex, exc_info=True, stack_info=True)
2023-11-02 13:14:16.276 - CustomFuction [ERROR   ] DPI-1010: not connected
Traceback (most recent call last):
  File "../..\XdmLib\CustomFuction.py", line 605, in file2db_init
    db_tgt.commit()
  File "../..\XdmLib\Database.py", line 386, in commit
    return self.connection.commit()
cx_Oracle.DatabaseError: DPI-1080: connection was closed by ORA-3113

During handling of the above exception, another exception occurred:

Traceback (most recent call last):
  File "../..\XdmLib\CustomFuction.py", line 645, in file2db_init
    db_tgt.rollback()
  File "../..\XdmLib\Database.py", line 392, in rollback
    return self.connection.rollback()
cx_Oracle.DatabaseError: DPI-1010: not connected
Stack (most recent call last):
  File "D:\soft\PyCharm Community Edition 2022.1.3\plugins\python-ce\helpers\pydev\pydevd.py", line 2181, in <module>
    main()
  File "D:\soft\PyCharm Community Edition 2022.1.3\plugins\python-ce\helpers\pydev\pydevd.py", line 2172, in main
    globals = debugger.run(setup['file'], None, None, is_module)
  File "D:\soft\PyCharm Community Edition 2022.1.3\plugins\python-ce\helpers\pydev\pydevd.py", line 1484, in run
    return self._exec(is_module, entry_point_fn, module_name, file, globals, locals)
  File "D:\soft\PyCharm Community Edition 2022.1.3\plugins\python-ce\helpers\pydev\pydevd.py", line 1491, in _exec
    pydev_imports.execfile(file, globals, locals)  # execute the script
  File "D:\soft\PyCharm Community Edition 2022.1.3\plugins\python-ce\helpers\pydev\_pydev_imps\_pydev_execfile.py", line 18, in execfile
    exec(compile(contents+"\n", file, 'exec'), glob, loc)
  File "D:/Ina/ETL_XdmLib_2.A.13/ETL_XdmLib_2.A.13/EDAETL/ETL_TABLE/ETL_LOT_XML_TO_XSIFF/ETL_LOT_XML_TO_XSIFF.py", line 289, in <module>
    do_file, before_do_file, after_do_file, skip_file, None, log, config, config_sql)
  File "../..\XdmLib\CustomFuction.py", line 667, in file2db_init
    log.error(ex, exc_info=True, stack_info=True)
2023-11-02 13:14:35.531 - base       [ERROR   ] Exception during reset or similar
Traceback (most recent call last):
  File "../..\XdmLib\CustomFuction.py", line 605, in file2db_init
    db_tgt.commit()
  File "../..\XdmLib\Database.py", line 386, in commit
    return self.connection.commit()
cx_Oracle.DatabaseError: DPI-1080: connection was closed by ORA-3113

During handling of the above exception, another exception occurred:

Traceback (most recent call last):
  File "../..\XdmLib\CustomFuction.py", line 645, in file2db_init
    db_tgt.rollback()
  File "../..\XdmLib\Database.py", line 392, in rollback
    return self.connection.rollback()
cx_Oracle.DatabaseError: DPI-1010: not connected

During handling of the above exception, another exception occurred:

Traceback (most recent call last):
  File "../..\XdmLib\CustomFuction.py", line 674, in file2db_init
    db_tgt.rollback()
  File "../..\XdmLib\Database.py", line 392, in rollback
    return self.connection.rollback()
cx_Oracle.DatabaseError: DPI-1010: not connected

During handling of the above exception, another exception occurred:

Traceback (most recent call last):
  File "D:\Python37\lib\site-packages\sqlalchemy\pool\base.py", line 697, in _finalize_fairy
    fairy._reset(pool)
  File "D:\Python37\lib\site-packages\sqlalchemy\pool\base.py", line 893, in _reset
    pool._dialect.do_rollback(self)
  File "D:\Python37\lib\site-packages\sqlalchemy\engine\default.py", line 559, in do_rollback
    dbapi_connection.rollback()
cx_Oracle.DatabaseError: DPI-1080: connection was closed by ORA-3113
2023-11-02 13:14:54.931 - base       [ERROR   ] Exception closing connection <cx_Oracle.Connection to vidatest@(DESCRIPTION=(ADDRESS=(PROTOCOL=TCP)(HOST=192.168.1.73)(PORT=1521))(CONNECT_DATA=(SID=demodb)))>
Traceback (most recent call last):
  File "../..\XdmLib\CustomFuction.py", line 605, in file2db_init
    db_tgt.commit()
  File "../..\XdmLib\Database.py", line 386, in commit
    return self.connection.commit()
cx_Oracle.DatabaseError: DPI-1080: connection was closed by ORA-3113

During handling of the above exception, another exception occurred:

Traceback (most recent call last):
  File "../..\XdmLib\CustomFuction.py", line 645, in file2db_init
    db_tgt.rollback()
  File "../..\XdmLib\Database.py", line 392, in rollback
    return self.connection.rollback()
cx_Oracle.DatabaseError: DPI-1010: not connected

During handling of the above exception, another exception occurred:

Traceback (most recent call last):
  File "../..\XdmLib\CustomFuction.py", line 674, in file2db_init
    db_tgt.rollback()
  File "../..\XdmLib\Database.py", line 392, in rollback
    return self.connection.rollback()
cx_Oracle.DatabaseError: DPI-1010: not connected

During handling of the above exception, another exception occurred:

Traceback (most recent call last):
  File "D:\Python37\lib\site-packages\sqlalchemy\pool\base.py", line 270, in _close_connection
    self._dialect.do_close(connection)
  File "D:\Python37\lib\site-packages\sqlalchemy\engine\default.py", line 565, in do_close
    dbapi_connection.close()
cx_Oracle.DatabaseError: DPI-1080: connection was closed by ORA-3113
2023-11-02 13:14:55.079 - base       [ERROR   ] Exception during reset or similar
Traceback (most recent call last):
  File "../..\XdmLib\CustomFuction.py", line 605, in file2db_init
    db_tgt.commit()
  File "../..\XdmLib\Database.py", line 386, in commit
    return self.connection.commit()
cx_Oracle.DatabaseError: DPI-1080: connection was closed by ORA-3113

During handling of the above exception, another exception occurred:

Traceback (most recent call last):
  File "../..\XdmLib\CustomFuction.py", line 645, in file2db_init
    db_tgt.rollback()
  File "../..\XdmLib\Database.py", line 392, in rollback
    return self.connection.rollback()
cx_Oracle.DatabaseError: DPI-1010: not connected

During handling of the above exception, another exception occurred:

Traceback (most recent call last):
  File "../..\XdmLib\CustomFuction.py", line 674, in file2db_init
    db_tgt.rollback()
  File "../..\XdmLib\Database.py", line 392, in rollback
    return self.connection.rollback()
cx_Oracle.DatabaseError: DPI-1010: not connected

During handling of the above exception, another exception occurred:

Traceback (most recent call last):
  File "D:\Python37\lib\site-packages\sqlalchemy\pool\base.py", line 697, in _finalize_fairy
    fairy._reset(pool)
  File "D:\Python37\lib\site-packages\sqlalchemy\pool\base.py", line 893, in _reset
    pool._dialect.do_rollback(self)
  File "D:\Python37\lib\site-packages\sqlalchemy\engine\default.py", line 559, in do_rollback
    dbapi_connection.rollback()
cx_Oracle.DatabaseError: DPI-1010: not connected
2023-11-02 13:15:14.303 - base       [ERROR   ] Exception closing connection <cx_Oracle.Connection to vidatest@(DESCRIPTION=(ADDRESS=(PROTOCOL=TCP)(HOST=192.168.1.73)(PORT=1521))(CONNECT_DATA=(SID=demodb)))>
Traceback (most recent call last):
  File "../..\XdmLib\CustomFuction.py", line 605, in file2db_init
    db_tgt.commit()
  File "../..\XdmLib\Database.py", line 386, in commit
    return self.connection.commit()
cx_Oracle.DatabaseError: DPI-1080: connection was closed by ORA-3113

During handling of the above exception, another exception occurred:

Traceback (most recent call last):
  File "../..\XdmLib\CustomFuction.py", line 645, in file2db_init
    db_tgt.rollback()
  File "../..\XdmLib\Database.py", line 392, in rollback
    return self.connection.rollback()
cx_Oracle.DatabaseError: DPI-1010: not connected

During handling of the above exception, another exception occurred:

Traceback (most recent call last):
  File "../..\XdmLib\CustomFuction.py", line 674, in file2db_init
    db_tgt.rollback()
  File "../..\XdmLib\Database.py", line 392, in rollback
    return self.connection.rollback()
cx_Oracle.DatabaseError: DPI-1010: not connected

During handling of the above exception, another exception occurred:

Traceback (most recent call last):
  File "D:\Python37\lib\site-packages\sqlalchemy\pool\base.py", line 270, in _close_connection
    self._dialect.do_close(connection)
  File "D:\Python37\lib\site-packages\sqlalchemy\engine\default.py", line 565, in do_close
    dbapi_connection.close()
cx_Oracle.DatabaseError: DPI-1080: connection was closed by ORA-3113
2023-11-02 13:26:36.046 - ETL_LOT_XML_TO_XSIFF [ERROR   ] Attribute Content Is Missing From The Root Node
2023-11-02 13:26:36.980 - __init__   [ERROR   ] File:A22100029.05_1.lot Move To Error Folder
                                                Error: None
2023-11-02 13:27:40.323 - ETL_LOT_XML_TO_XSIFF [ERROR   ] 'list' object has no attribute 'attrib'
Traceback (most recent call last):
  File "D:/Ina/ETL_XdmLib_2.A.13/ETL_XdmLib_2.A.13/EDAETL/ETL_TABLE/ETL_LOT_XML_TO_XSIFF/ETL_LOT_XML_TO_XSIFF.py", line 152, in do_file
    adb_document_attributes = adb_document.attrib
AttributeError: 'list' object has no attribute 'attrib'
Stack (most recent call last):
  File "D:/Ina/ETL_XdmLib_2.A.13/ETL_XdmLib_2.A.13/EDAETL/ETL_TABLE/ETL_LOT_XML_TO_XSIFF/ETL_LOT_XML_TO_XSIFF.py", line 308, in <module>
    do_file, before_do_file, after_do_file, skip_file, None, log, config, config_sql)
  File "../..\XdmLib\CustomFuction.py", line 597, in file2db_init
    file, pre_params, db_src, db_tgt)
  File "D:/Ina/ETL_XdmLib_2.A.13/ETL_XdmLib_2.A.13/EDAETL/ETL_TABLE/ETL_LOT_XML_TO_XSIFF/ETL_LOT_XML_TO_XSIFF.py", line 180, in do_file
    log.error(ex, exc_info=True, stack_info=True)
2023-11-02 13:27:41.176 - __init__   [ERROR   ] File:A22100029.05_1.lot Move To Error Folder
                                                Error: None
2023-11-02 14:45:50.472 - ETL_LOT_XML_TO_XSIFF [ERROR   ] module 'datetime' has no attribute 'strptime'
Traceback (most recent call last):
  File "D:/Ina/ETL_XdmLib_2.A.13/ETL_XdmLib_2.A.13/EDAETL/ETL_TABLE/ETL_LOT_XML_TO_XSIFF/ETL_LOT_XML_TO_XSIFF.py", line 189, in do_file
    date_object = datetime.strptime(header_lot['StartTime'], '%Y/%m/%d_%H:%M:%S')
AttributeError: module 'datetime' has no attribute 'strptime'
Stack (most recent call last):
  File "D:/Ina/ETL_XdmLib_2.A.13/ETL_XdmLib_2.A.13/EDAETL/ETL_TABLE/ETL_LOT_XML_TO_XSIFF/ETL_LOT_XML_TO_XSIFF.py", line 345, in <module>
    do_file, before_do_file, after_do_file, skip_file, None, log, config, config_sql)
  File "../..\XdmLib\CustomFuction.py", line 597, in file2db_init
    file, pre_params, db_src, db_tgt)
  File "D:/Ina/ETL_XdmLib_2.A.13/ETL_XdmLib_2.A.13/EDAETL/ETL_TABLE/ETL_LOT_XML_TO_XSIFF/ETL_LOT_XML_TO_XSIFF.py", line 217, in do_file
    log.error(ex, exc_info=True, stack_info=True)
2023-11-02 14:45:51.413 - __init__   [ERROR   ] File:A22100029.05_1.lot Move To Error Folder
                                                Error: None
2023-11-02 14:50:51.067 - ETL_LOT_XML_TO_XSIFF [ERROR   ] module 'datetime' has no attribute 'strptime'
Traceback (most recent call last):
  File "D:/Ina/ETL_XdmLib_2.A.13/ETL_XdmLib_2.A.13/EDAETL/ETL_TABLE/ETL_LOT_XML_TO_XSIFF/ETL_LOT_XML_TO_XSIFF.py", line 189, in do_file
    date_object = datetime.strptime(a, '%Y/%m/%d_%H:%M:%S')
AttributeError: module 'datetime' has no attribute 'strptime'
Stack (most recent call last):
  File "D:/Ina/ETL_XdmLib_2.A.13/ETL_XdmLib_2.A.13/EDAETL/ETL_TABLE/ETL_LOT_XML_TO_XSIFF/ETL_LOT_XML_TO_XSIFF.py", line 345, in <module>
    do_file, before_do_file, after_do_file, skip_file, None, log, config, config_sql)
  File "../..\XdmLib\CustomFuction.py", line 597, in file2db_init
    file, pre_params, db_src, db_tgt)
  File "D:/Ina/ETL_XdmLib_2.A.13/ETL_XdmLib_2.A.13/EDAETL/ETL_TABLE/ETL_LOT_XML_TO_XSIFF/ETL_LOT_XML_TO_XSIFF.py", line 217, in do_file
    log.error(ex, exc_info=True, stack_info=True)
2023-11-02 14:50:52.165 - __init__   [ERROR   ] File:A22100029.05_1.lot Move To Error Folder
                                                Error: None
2023-11-02 14:53:12.903 - CustomFuction [ERROR   ] type object 'datetime.datetime' has no attribute 'datetime'
Traceback (most recent call last):
  File "../..\XdmLib\CustomFuction.py", line 597, in file2db_init
    file, pre_params, db_src, db_tgt)
  File "D:/Ina/ETL_XdmLib_2.A.13/ETL_XdmLib_2.A.13/EDAETL/ETL_TABLE/ETL_LOT_XML_TO_XSIFF/ETL_LOT_XML_TO_XSIFF.py", line 138, in do_file
    ts_t = datetime.datetime.now()
AttributeError: type object 'datetime.datetime' has no attribute 'datetime'
Stack (most recent call last):
  File "D:/Ina/ETL_XdmLib_2.A.13/ETL_XdmLib_2.A.13/EDAETL/ETL_TABLE/ETL_LOT_XML_TO_XSIFF/ETL_LOT_XML_TO_XSIFF.py", line 346, in <module>
    do_file, before_do_file, after_do_file, skip_file, None, log, config, config_sql)
  File "../..\XdmLib\CustomFuction.py", line 631, in file2db_init
    log.error(ex, exc_info=True, stack_info=True)
2023-11-02 14:54:43.991 - ETL_LOT_XML_TO_XSIFF [ERROR   ] 'WaferNumber'
Traceback (most recent call last):
  File "D:/Ina/ETL_XdmLib_2.A.13/ETL_XdmLib_2.A.13/EDAETL/ETL_TABLE/ETL_LOT_XML_TO_XSIFF/ETL_LOT_XML_TO_XSIFF.py", line 204, in do_file
    header['WaferNo'] = header_lot['WaferNumber']
KeyError: 'WaferNumber'
Stack (most recent call last):
  File "D:/Ina/ETL_XdmLib_2.A.13/ETL_XdmLib_2.A.13/EDAETL/ETL_TABLE/ETL_LOT_XML_TO_XSIFF/ETL_LOT_XML_TO_XSIFF.py", line 346, in <module>
    do_file, before_do_file, after_do_file, skip_file, None, log, config, config_sql)
  File "../..\XdmLib\CustomFuction.py", line 597, in file2db_init
    file, pre_params, db_src, db_tgt)
  File "D:/Ina/ETL_XdmLib_2.A.13/ETL_XdmLib_2.A.13/EDAETL/ETL_TABLE/ETL_LOT_XML_TO_XSIFF/ETL_LOT_XML_TO_XSIFF.py", line 218, in do_file
    log.error(ex, exc_info=True, stack_info=True)
2023-11-02 14:54:44.869 - __init__   [ERROR   ] File:A22100029.05_1.lot Move To Error Folder
                                                Error: None
2023-11-02 14:59:07.410 - __init__   [ERROR   ] Access XDM Loader control table fail.
2023-11-02 14:59:55.278 - __init__   [ERROR   ] Access XDM Loader control table fail.
2023-11-02 15:01:10.046 - __init__   [ERROR   ] Access XDM Loader control table fail.
2023-11-02 15:02:38.643 - __init__   [ERROR   ] Access XDM Loader control table fail.
2023-11-02 15:03:17.795 - __init__   [ERROR   ] Access XDM Loader control table fail.
2023-11-02 15:05:02.547 - __init__   [ERROR   ] Access XDM Loader control table fail.
2023-11-02 15:06:03.997 - __init__   [ERROR   ] Access XDM Loader control table fail.
2023-11-02 15:06:50.873 - __init__   [ERROR   ] Access XDM Loader control table fail.
2023-11-02 15:26:45.673 - ETL_LOT_XML_TO_XSIFF [ERROR   ] Unknown format code 'd' for object of type 'str'
Traceback (most recent call last):
  File "D:/Ina/ETL_XdmLib_2.A.13/ETL_XdmLib_2.A.13/EDAETL/ETL_TABLE/ETL_LOT_XML_TO_XSIFF/ETL_LOT_XML_TO_XSIFF.py", line 207, in do_file
    header['WaferNo'] = '{:02d}'.format(header_wafer['WaferNumber'])
ValueError: Unknown format code 'd' for object of type 'str'
Stack (most recent call last):
  File "D:/Ina/ETL_XdmLib_2.A.13/ETL_XdmLib_2.A.13/EDAETL/ETL_TABLE/ETL_LOT_XML_TO_XSIFF/ETL_LOT_XML_TO_XSIFF.py", line 349, in <module>
    do_file, before_do_file, after_do_file, skip_file, None, log, config, config_sql)
  File "../..\XdmLib\CustomFuction.py", line 597, in file2db_init
    file, pre_params, db_src, db_tgt)
  File "D:/Ina/ETL_XdmLib_2.A.13/ETL_XdmLib_2.A.13/EDAETL/ETL_TABLE/ETL_LOT_XML_TO_XSIFF/ETL_LOT_XML_TO_XSIFF.py", line 221, in do_file
    log.error(ex, exc_info=True, stack_info=True)
2023-11-02 15:26:46.600 - __init__   [ERROR   ] File:A22100029.05_1.lot Move To Error Folder
                                                Error: None
2023-11-02 15:51:29.058 - __init__   [ERROR   ] Access XDM Loader control table fail.
2023-11-02 15:52:21.067 - __init__   [ERROR   ] Access XDM Loader control table fail.
2023-11-02 15:53:31.747 - __init__   [ERROR   ] Access XDM Loader control table fail.
2023-11-02 16:07:31.400 - ETL_LOT_XML_TO_XSIFF [ERROR   ] name 'spec_lists' is not defined
Traceback (most recent call last):
  File "D:/Ina/ETL_XdmLib_2.A.13/ETL_XdmLib_2.A.13/EDAETL/ETL_TABLE/ETL_LOT_XML_TO_XSIFF/ETL_LOT_XML_TO_XSIFF.py", line 230, in do_file
    spec_df = pd.DataFrame(data=spec_lists, dtype=object)
NameError: name 'spec_lists' is not defined
Stack (most recent call last):
  File "D:/Ina/ETL_XdmLib_2.A.13/ETL_XdmLib_2.A.13/EDAETL/ETL_TABLE/ETL_LOT_XML_TO_XSIFF/ETL_LOT_XML_TO_XSIFF.py", line 388, in <module>
    do_file, before_do_file, after_do_file, skip_file, None, log, config, config_sql)
  File "../..\XdmLib\CustomFuction.py", line 597, in file2db_init
    file, pre_params, db_src, db_tgt)
  File "D:/Ina/ETL_XdmLib_2.A.13/ETL_XdmLib_2.A.13/EDAETL/ETL_TABLE/ETL_LOT_XML_TO_XSIFF/ETL_LOT_XML_TO_XSIFF.py", line 273, in do_file
    log.error(ex, exc_info=True, stack_info=True)
2023-11-02 16:07:32.327 - __init__   [ERROR   ] File:A22100029.05_1.lot Move To Error Folder
                                                Error: None
2023-11-02 16:11:35.452 - __init__   [ERROR   ] Access XDM Loader control table fail.
2023-11-02 17:49:03.043 - __init__   [ERROR   ] Access XDM Loader control table fail.
2023-11-02 17:49:46.982 - __init__   [ERROR   ] Access XDM Loader control table fail.
2023-11-02 17:50:54.157 - ETL_LOT_XML_TO_XSIFF [ERROR   ] name 't' is not defined
Traceback (most recent call last):
  File "D:/Ina/ETL_XdmLib_2.A.13/ETL_XdmLib_2.A.13/EDAETL/ETL_TABLE/ETL_LOT_XML_TO_XSIFF/ETL_LOT_XML_TO_XSIFF.py", line 250, in do_file
    t_split = t.text.split(',')
NameError: name 't' is not defined
Stack (most recent call last):
  File "D:/Ina/ETL_XdmLib_2.A.13/ETL_XdmLib_2.A.13/EDAETL/ETL_TABLE/ETL_LOT_XML_TO_XSIFF/ETL_LOT_XML_TO_XSIFF.py", line 429, in <module>
    do_file, before_do_file, after_do_file, skip_file, None, log, config, config_sql)
  File "../..\XdmLib\CustomFuction.py", line 597, in file2db_init
    file, pre_params, db_src, db_tgt)
  File "D:/Ina/ETL_XdmLib_2.A.13/ETL_XdmLib_2.A.13/EDAETL/ETL_TABLE/ETL_LOT_XML_TO_XSIFF/ETL_LOT_XML_TO_XSIFF.py", line 261, in do_file
    log.error(ex, exc_info=True, stack_info=True)
2023-11-02 17:50:54.983 - __init__   [ERROR   ] File:A22100029.05_1.lot Move To Error Folder
                                                Error: None
2023-11-02 17:51:31.605 - ETL_LOT_XML_TO_XSIFF [ERROR   ] 'list' object has no attribute 'split'
Traceback (most recent call last):
  File "D:/Ina/ETL_XdmLib_2.A.13/ETL_XdmLib_2.A.13/EDAETL/ETL_TABLE/ETL_LOT_XML_TO_XSIFF/ETL_LOT_XML_TO_XSIFF.py", line 250, in do_file
    t_split = t_values.split(',')
AttributeError: 'list' object has no attribute 'split'
Stack (most recent call last):
  File "D:/Ina/ETL_XdmLib_2.A.13/ETL_XdmLib_2.A.13/EDAETL/ETL_TABLE/ETL_LOT_XML_TO_XSIFF/ETL_LOT_XML_TO_XSIFF.py", line 429, in <module>
    do_file, before_do_file, after_do_file, skip_file, None, log, config, config_sql)
  File "../..\XdmLib\CustomFuction.py", line 597, in file2db_init
    file, pre_params, db_src, db_tgt)
  File "D:/Ina/ETL_XdmLib_2.A.13/ETL_XdmLib_2.A.13/EDAETL/ETL_TABLE/ETL_LOT_XML_TO_XSIFF/ETL_LOT_XML_TO_XSIFF.py", line 261, in do_file
    log.error(ex, exc_info=True, stack_info=True)
2023-11-02 17:51:32.739 - __init__   [ERROR   ] File:A22100029.05_1.lot Move To Error Folder
                                                Error: None
2023-11-02 17:55:48.479 - ETL_LOT_XML_TO_XSIFF [ERROR   ] '1905.51'
Traceback (most recent call last):
  File "D:/Ina/ETL_XdmLib_2.A.13/ETL_XdmLib_2.A.13/EDAETL/ETL_TABLE/ETL_LOT_XML_TO_XSIFF/ETL_LOT_XML_TO_XSIFF.py", line 254, in do_file
    value_dict[no_name_dict[lim.get('ID')]] = value_dict[t_split[1]]
KeyError: '1905.51'
Stack (most recent call last):
  File "D:/Ina/ETL_XdmLib_2.A.13/ETL_XdmLib_2.A.13/EDAETL/ETL_TABLE/ETL_LOT_XML_TO_XSIFF/ETL_LOT_XML_TO_XSIFF.py", line 430, in <module>
    do_file, before_do_file, after_do_file, skip_file, None, log, config, config_sql)
  File "../..\XdmLib\CustomFuction.py", line 597, in file2db_init
    file, pre_params, db_src, db_tgt)
  File "D:/Ina/ETL_XdmLib_2.A.13/ETL_XdmLib_2.A.13/EDAETL/ETL_TABLE/ETL_LOT_XML_TO_XSIFF/ETL_LOT_XML_TO_XSIFF.py", line 262, in do_file
    log.error(ex, exc_info=True, stack_info=True)
2023-11-02 17:55:49.295 - __init__   [ERROR   ] File:A22100029.05_1.lot Move To Error Folder
                                                Error: None
2023-11-02 17:56:57.223 - ETL_LOT_XML_TO_XSIFF [ERROR   ] '1695.92'
Traceback (most recent call last):
  File "D:/Ina/ETL_XdmLib_2.A.13/ETL_XdmLib_2.A.13/EDAETL/ETL_TABLE/ETL_LOT_XML_TO_XSIFF/ETL_LOT_XML_TO_XSIFF.py", line 254, in do_file
    value_dict[no_name_dict.keys] = value_dict[t_split[1]]
KeyError: '1695.92'
Stack (most recent call last):
  File "D:/Ina/ETL_XdmLib_2.A.13/ETL_XdmLib_2.A.13/EDAETL/ETL_TABLE/ETL_LOT_XML_TO_XSIFF/ETL_LOT_XML_TO_XSIFF.py", line 430, in <module>
    do_file, before_do_file, after_do_file, skip_file, None, log, config, config_sql)
  File "../..\XdmLib\CustomFuction.py", line 597, in file2db_init
    file, pre_params, db_src, db_tgt)
  File "D:/Ina/ETL_XdmLib_2.A.13/ETL_XdmLib_2.A.13/EDAETL/ETL_TABLE/ETL_LOT_XML_TO_XSIFF/ETL_LOT_XML_TO_XSIFF.py", line 262, in do_file
    log.error(ex, exc_info=True, stack_info=True)
2023-11-02 17:56:58.130 - __init__   [ERROR   ] File:A22100029.05_1.lot Move To Error Folder
                                                Error: None
2023-11-02 17:57:49.953 - ETL_LOT_XML_TO_XSIFF [ERROR   ] unhashable type: 'dict'
Traceback (most recent call last):
  File "D:/Ina/ETL_XdmLib_2.A.13/ETL_XdmLib_2.A.13/EDAETL/ETL_TABLE/ETL_LOT_XML_TO_XSIFF/ETL_LOT_XML_TO_XSIFF.py", line 255, in do_file
    data[value_dict]
TypeError: unhashable type: 'dict'
Stack (most recent call last):
  File "D:/Ina/ETL_XdmLib_2.A.13/ETL_XdmLib_2.A.13/EDAETL/ETL_TABLE/ETL_LOT_XML_TO_XSIFF/ETL_LOT_XML_TO_XSIFF.py", line 431, in <module>
    do_file, before_do_file, after_do_file, skip_file, None, log, config, config_sql)
  File "../..\XdmLib\CustomFuction.py", line 597, in file2db_init
    file, pre_params, db_src, db_tgt)
  File "D:/Ina/ETL_XdmLib_2.A.13/ETL_XdmLib_2.A.13/EDAETL/ETL_TABLE/ETL_LOT_XML_TO_XSIFF/ETL_LOT_XML_TO_XSIFF.py", line 263, in do_file
    log.error(ex, exc_info=True, stack_info=True)
2023-11-02 17:57:50.821 - __init__   [ERROR   ] File:A22100029.05_1.lot Move To Error Folder
                                                Error: None
2023-11-02 18:00:53.276 - ETL_LOT_XML_TO_XSIFF [ERROR   ] '1.05434e+06'
Traceback (most recent call last):
  File "D:/Ina/ETL_XdmLib_2.A.13/ETL_XdmLib_2.A.13/EDAETL/ETL_TABLE/ETL_LOT_XML_TO_XSIFF/ETL_LOT_XML_TO_XSIFF.py", line 254, in do_file
    value_dict[limits_dict['ParameterName']] = value_dict[t_split[1]]
KeyError: '1.05434e+06'
Stack (most recent call last):
  File "D:/Ina/ETL_XdmLib_2.A.13/ETL_XdmLib_2.A.13/EDAETL/ETL_TABLE/ETL_LOT_XML_TO_XSIFF/ETL_LOT_XML_TO_XSIFF.py", line 431, in <module>
    do_file, before_do_file, after_do_file, skip_file, None, log, config, config_sql)
  File "../..\XdmLib\CustomFuction.py", line 597, in file2db_init
    file, pre_params, db_src, db_tgt)
  File "D:/Ina/ETL_XdmLib_2.A.13/ETL_XdmLib_2.A.13/EDAETL/ETL_TABLE/ETL_LOT_XML_TO_XSIFF/ETL_LOT_XML_TO_XSIFF.py", line 263, in do_file
    log.error(ex, exc_info=True, stack_info=True)
2023-11-02 18:00:54.181 - __init__   [ERROR   ] File:A22100029.05_1.lot Move To Error Folder
                                                Error: None
