2023-11-27 20:20:49.183 - __init__   [INFO    ] # ===== [ XdmLib Ver. ] ===== #
2023-11-27 20:20:49.183 - __init__   [INFO    ] XdmLib Ver. 2.A.13
2023-11-27 20:20:49.184 - __init__   [INFO    ] # ===== [ XdmLib Ver. ] ===== #
2023-11-27 20:20:49.189 - __init__   [INFO    ] Console Quick Edit Disabled
2023-11-27 20:20:49.233 - __init__   [INFO    ] Server/Host Name: DESKTOP-J6AUF2I
2023-11-27 20:20:49.234 - __init__   [INFO    ] Archive setting non-setting, Archive files will be kept.
2023-11-27 20:20:49.234 - __init__   [INFO    ] Error setting non-setting, Error files will be kept.
2023-11-27 20:20:51.432 - __init__   [INFO    ] First run, initialize db table: 'xdm_prog_control'.
2023-11-27 20:20:51.556 - __init__   [INFO    ] Watching control file: D:\Ina\ETL_XdmLib_2.A.13\ETL_XdmLib_2.A.13\EDAETL\ETL_TABLE\ETL_XYN_XLSX_TO_KLARF\ETL_SICA88_TO_KLARF.py.*
2023-11-27 20:20:51.561 - __init__   [INFO    ] SetProcessStatus 0, Start time: 2023-11-27 20:20:49.153857
2023-11-27 20:20:53.272 - __init__   [INFO    ] Set process status code: 0.
2023-11-27 20:20:53.391 - Database   [INFO    ] Non set logging! Using default logging.
2023-11-27 20:20:54.106 - Database   [INFO    ] Non set logging! Using default logging.
2023-11-27 20:20:54.818 - Database   [INFO    ] Non set logging! Using default logging.
2023-11-27 20:20:55.565 - CustomFuction [ERROR   ] read_excel() got an unexpected keyword argument 'enqine'
Traceback (most recent call last):
  File "../..\XdmLib\CustomFuction.py", line 597, in file2db_init
    file, pre_params, db_src, db_tgt)
  File "D:/Ina/ETL_XdmLib_2.A.13/ETL_XdmLib_2.A.13/EDAETL/ETL_TABLE/ETL_XYN_XLSX_TO_KLARF/ETL_SICA88_TO_KLARF.py", line 25, in do_file
    Data = pd.read_excel(file_path,enqine = "openpyxl")
  File "D:\Python37\lib\site-packages\pandas\util\_decorators.py", line 296, in wrapper
    return func(*args, **kwargs)
TypeError: read_excel() got an unexpected keyword argument 'enqine'
Stack (most recent call last):
  File "D:/Ina/ETL_XdmLib_2.A.13/ETL_XdmLib_2.A.13/EDAETL/ETL_TABLE/ETL_XYN_XLSX_TO_KLARF/ETL_SICA88_TO_KLARF.py", line 115, in <module>
    do_file, before_do_file, after_do_file, skip_file, None, log, config, config_sql)
  File "../..\XdmLib\CustomFuction.py", line 631, in file2db_init
    log.error(ex, exc_info=True, stack_info=True)
2023-11-27 20:20:55.599 - CustomFuction [INFO    ] [ERROR] 40-4N46-DF07016.xlsx
2023-11-27 20:20:55.600 - CustomFuction [INFO    ] Move file: 40-4N46-DF07016.xlsx to ERROR folder: Data\ERROR\40-4N46-DF07016.xlsx.
2023-11-27 20:20:57.752 - CustomFuction [INFO    ] ========[ File End ]========
2023-11-27 20:20:57.753 - CustomFuction [INFO    ] ========[ Delete Empty Folder ]========
2023-11-27 20:20:57.902 - CustomFuction [INFO    ] ========== Finally ==========
2023-11-27 20:20:59.387 - __init__   [INFO    ] Set process status code: 5.
2023-11-27 20:22:40.100 - __init__   [INFO    ] # ===== [ XdmLib Ver. ] ===== #
2023-11-27 20:22:40.101 - __init__   [INFO    ] XdmLib Ver. 2.A.13
2023-11-27 20:22:40.101 - __init__   [INFO    ] # ===== [ XdmLib Ver. ] ===== #
2023-11-27 20:22:40.104 - __init__   [INFO    ] Console Quick Edit Disabled
2023-11-27 20:22:40.135 - __init__   [INFO    ] Server/Host Name: DESKTOP-J6AUF2I
2023-11-27 20:22:40.136 - __init__   [INFO    ] Archive setting non-setting, Archive files will be kept.
2023-11-27 20:22:40.136 - __init__   [INFO    ] Error setting non-setting, Error files will be kept.
2023-11-27 20:22:42.306 - __init__   [INFO    ] Server: DESKTOP-J6AUF2I, Status: 5, data_time_flg: None.
2023-11-27 20:22:42.987 - __init__   [INFO    ] Watching control file: D:\Ina\ETL_XdmLib_2.A.13\ETL_XdmLib_2.A.13\EDAETL\ETL_TABLE\ETL_XYN_XLSX_TO_KLARF\ETL_SICA88_TO_KLARF.py.*
2023-11-27 20:22:42.991 - __init__   [INFO    ] SetProcessStatus 0, Start time: 2023-11-27 20:22:40.078684
2023-11-27 20:22:44.514 - __init__   [INFO    ] Set process status code: 0.
2023-11-27 20:22:44.761 - Database   [INFO    ] Non set logging! Using default logging.
2023-11-27 20:22:45.418 - Database   [INFO    ] Non set logging! Using default logging.
2023-11-27 20:22:46.024 - Database   [INFO    ] Non set logging! Using default logging.
2023-11-27 20:22:46.633 - CustomFuction [ERROR   ] read_excel() got an unexpected keyword argument 'enqine'
Traceback (most recent call last):
  File "../..\XdmLib\CustomFuction.py", line 597, in file2db_init
    file, pre_params, db_src, db_tgt)
  File "D:/Ina/ETL_XdmLib_2.A.13/ETL_XdmLib_2.A.13/EDAETL/ETL_TABLE/ETL_XYN_XLSX_TO_KLARF/ETL_SICA88_TO_KLARF.py", line 27, in do_file
    Data = pd.read_excel(file_path,enqine = "openpyxl")
  File "D:\Python37\lib\site-packages\pandas\util\_decorators.py", line 296, in wrapper
    return func(*args, **kwargs)
TypeError: read_excel() got an unexpected keyword argument 'enqine'
Stack (most recent call last):
  File "D:/Ina/ETL_XdmLib_2.A.13/ETL_XdmLib_2.A.13/EDAETL/ETL_TABLE/ETL_XYN_XLSX_TO_KLARF/ETL_SICA88_TO_KLARF.py", line 117, in <module>
    do_file, before_do_file, after_do_file, skip_file, None, log, config, config_sql)
  File "../..\XdmLib\CustomFuction.py", line 631, in file2db_init
    log.error(ex, exc_info=True, stack_info=True)
2023-11-27 20:22:46.653 - CustomFuction [INFO    ] [ERROR] 40-4N46-DF07016.xlsx
2023-11-27 20:22:46.655 - CustomFuction [INFO    ] Move file: 40-4N46-DF07016.xlsx to ERROR folder: Data\ERROR\40-4N46-DF07016.xlsx.
2023-11-27 20:22:48.102 - CustomFuction [INFO    ] ========[ File End ]========
2023-11-27 20:22:48.103 - CustomFuction [INFO    ] ========[ Delete Empty Folder ]========
2023-11-27 20:22:48.277 - CustomFuction [INFO    ] ========== Finally ==========
2023-11-27 20:22:49.750 - __init__   [INFO    ] Set process status code: 5.
2023-11-27 20:24:54.151 - __init__   [INFO    ] # ===== [ XdmLib Ver. ] ===== #
2023-11-27 20:24:54.151 - __init__   [INFO    ] XdmLib Ver. 2.A.13
2023-11-27 20:24:54.152 - __init__   [INFO    ] # ===== [ XdmLib Ver. ] ===== #
2023-11-27 20:24:54.154 - __init__   [INFO    ] Console Quick Edit Disabled
2023-11-27 20:24:54.180 - __init__   [INFO    ] Server/Host Name: DESKTOP-J6AUF2I
2023-11-27 20:24:54.181 - __init__   [INFO    ] Archive setting non-setting, Archive files will be kept.
2023-11-27 20:24:54.181 - __init__   [INFO    ] Error setting non-setting, Error files will be kept.
2023-11-27 20:24:56.103 - __init__   [INFO    ] Server: DESKTOP-J6AUF2I, Status: 5, data_time_flg: None.
2023-11-27 20:24:56.773 - __init__   [INFO    ] Watching control file: D:\Ina\ETL_XdmLib_2.A.13\ETL_XdmLib_2.A.13\EDAETL\ETL_TABLE\ETL_XYN_XLSX_TO_KLARF\ETL_SICA88_TO_KLARF.py.*
2023-11-27 20:24:56.779 - __init__   [INFO    ] SetProcessStatus 0, Start time: 2023-11-27 20:24:54.124075
2023-11-27 20:24:58.616 - __init__   [INFO    ] Set process status code: 0.
2023-11-27 20:24:58.741 - Database   [INFO    ] Non set logging! Using default logging.
2023-11-27 20:24:59.560 - Database   [INFO    ] Non set logging! Using default logging.
2023-11-27 20:25:00.199 - Database   [INFO    ] Non set logging! Using default logging.
2023-11-27 20:25:00.865 - CustomFuction [ERROR   ] Missing optional dependency 'openpyxl'.  Use pip or conda to install openpyxl.
Traceback (most recent call last):
  File "../..\XdmLib\CustomFuction.py", line 597, in file2db_init
    file, pre_params, db_src, db_tgt)
  File "D:/Ina/ETL_XdmLib_2.A.13/ETL_XdmLib_2.A.13/EDAETL/ETL_TABLE/ETL_XYN_XLSX_TO_KLARF/ETL_SICA88_TO_KLARF.py", line 27, in do_file
    Data = pd.read_excel(file_path,engine = "openpyxl")
  File "D:\Python37\lib\site-packages\pandas\util\_decorators.py", line 296, in wrapper
    return func(*args, **kwargs)
  File "D:\Python37\lib\site-packages\pandas\io\excel\_base.py", line 304, in read_excel
    io = ExcelFile(io, engine=engine)
  File "D:\Python37\lib\site-packages\pandas\io\excel\_base.py", line 867, in __init__
    self._reader = self._engines[engine](self._io)
  File "D:\Python37\lib\site-packages\pandas\io\excel\_openpyxl.py", line 479, in __init__
    import_optional_dependency("openpyxl")
  File "D:\Python37\lib\site-packages\pandas\compat\_optional.py", line 110, in import_optional_dependency
    raise ImportError(msg) from None
ImportError: Missing optional dependency 'openpyxl'.  Use pip or conda to install openpyxl.
Stack (most recent call last):
  File "D:/Ina/ETL_XdmLib_2.A.13/ETL_XdmLib_2.A.13/EDAETL/ETL_TABLE/ETL_XYN_XLSX_TO_KLARF/ETL_SICA88_TO_KLARF.py", line 117, in <module>
    do_file, before_do_file, after_do_file, skip_file, None, log, config, config_sql)
  File "../..\XdmLib\CustomFuction.py", line 631, in file2db_init
    log.error(ex, exc_info=True, stack_info=True)
2023-11-27 20:25:00.925 - CustomFuction [INFO    ] [ERROR] 40-4N46-DF07016.xlsx
2023-11-27 20:25:00.928 - CustomFuction [INFO    ] Move file: 40-4N46-DF07016.xlsx to ERROR folder: Data\ERROR\40-4N46-DF07016.xlsx.
2023-11-27 20:25:02.536 - CustomFuction [INFO    ] ========[ File End ]========
2023-11-27 20:25:02.536 - CustomFuction [INFO    ] ========[ Delete Empty Folder ]========
2023-11-27 20:25:02.715 - CustomFuction [INFO    ] ========== Finally ==========
2023-11-27 20:25:04.230 - __init__   [INFO    ] Set process status code: 5.
2023-11-27 20:29:25.858 - __init__   [INFO    ] # ===== [ XdmLib Ver. ] ===== #
2023-11-27 20:29:25.861 - __init__   [INFO    ] XdmLib Ver. 2.A.13
2023-11-27 20:29:25.865 - __init__   [INFO    ] # ===== [ XdmLib Ver. ] ===== #
2023-11-27 20:29:25.873 - __init__   [INFO    ] Console Quick Edit Disabled
2023-11-27 20:29:25.934 - __init__   [INFO    ] Server/Host Name: DESKTOP-J6AUF2I
2023-11-27 20:29:25.936 - __init__   [INFO    ] Archive setting non-setting, Archive files will be kept.
2023-11-27 20:29:25.942 - __init__   [INFO    ] Error setting non-setting, Error files will be kept.
2023-11-27 20:29:30.295 - __init__   [INFO    ] Server: DESKTOP-J6AUF2I, Status: 5, data_time_flg: None.
2023-11-27 20:29:31.118 - __init__   [INFO    ] Watching control file: D:\Ina\ETL_XdmLib_2.A.13\ETL_XdmLib_2.A.13\EDAETL\ETL_TABLE\ETL_XYN_XLSX_TO_KLARF\ETL_SICA88_TO_KLARF.py.*
2023-11-27 20:29:31.131 - __init__   [INFO    ] SetProcessStatus 0, Start time: 2023-11-27 20:29:25.805927
2023-11-27 20:29:34.980 - __init__   [INFO    ] Set process status code: 0.
2023-11-27 20:29:35.131 - Database   [INFO    ] Non set logging! Using default logging.
2023-11-27 20:29:35.795 - Database   [INFO    ] Non set logging! Using default logging.
2023-11-27 20:29:36.315 - Database   [INFO    ] Non set logging! Using default logging.
2023-11-27 20:29:36.875 - CustomFuction [INFO    ] [Empty] Empty Folder : ./Data/Source
2023-11-27 20:29:36.877 - CustomFuction [INFO    ] ========[ File End ]========
2023-11-27 20:29:36.884 - CustomFuction [INFO    ] ========[ Delete Empty Folder ]========
2023-11-27 20:29:37.054 - CustomFuction [INFO    ] ========== Finally ==========
2023-11-27 20:29:40.818 - __init__   [INFO    ] Set process status code: 1, Last data time: None.
2023-11-27 20:30:34.796 - __init__   [INFO    ] # ===== [ XdmLib Ver. ] ===== #
2023-11-27 20:30:34.797 - __init__   [INFO    ] XdmLib Ver. 2.A.13
2023-11-27 20:30:34.798 - __init__   [INFO    ] # ===== [ XdmLib Ver. ] ===== #
2023-11-27 20:30:34.805 - __init__   [INFO    ] Console Quick Edit Disabled
2023-11-27 20:30:34.834 - __init__   [INFO    ] Server/Host Name: DESKTOP-J6AUF2I
2023-11-27 20:30:34.836 - __init__   [INFO    ] Archive setting non-setting, Archive files will be kept.
2023-11-27 20:30:34.839 - __init__   [INFO    ] Error setting non-setting, Error files will be kept.
2023-11-27 20:30:38.924 - __init__   [INFO    ] Server: DESKTOP-J6AUF2I, Status: 1, data_time_flg: None.
2023-11-27 20:30:39.641 - __init__   [INFO    ] Watching control file: D:\Ina\ETL_XdmLib_2.A.13\ETL_XdmLib_2.A.13\EDAETL\ETL_TABLE\ETL_XYN_XLSX_TO_KLARF\ETL_SICA88_TO_KLARF.py.*
2023-11-27 20:30:39.647 - __init__   [INFO    ] SetProcessStatus 0, Start time: 2023-11-27 20:30:34.772572
2023-11-27 20:30:43.530 - __init__   [INFO    ] Set process status code: 0.
2023-11-27 20:30:43.662 - Database   [INFO    ] Non set logging! Using default logging.
2023-11-27 20:30:44.205 - Database   [INFO    ] Non set logging! Using default logging.
2023-11-27 20:30:44.736 - Database   [INFO    ] Non set logging! Using default logging.
2023-11-27 20:30:47.317 - ETL_SICA88_TO_KLARF [INFO    ] Read Source File:0:00:02.042409
2023-11-27 20:30:47.329 - CustomFuction [ERROR   ] 'No.'
Traceback (most recent call last):
  File "D:\soft\anaconda3\lib\site-packages\pandas\core\indexes\base.py", line 3621, in get_loc
    return self._engine.get_loc(casted_key)
  File "pandas\_libs\index.pyx", line 136, in pandas._libs.index.IndexEngine.get_loc
  File "pandas\_libs\index.pyx", line 163, in pandas._libs.index.IndexEngine.get_loc
  File "pandas\_libs\hashtable_class_helper.pxi", line 5198, in pandas._libs.hashtable.PyObjectHashTable.get_item
  File "pandas\_libs\hashtable_class_helper.pxi", line 5206, in pandas._libs.hashtable.PyObjectHashTable.get_item
KeyError: 'No.'

The above exception was the direct cause of the following exception:

Traceback (most recent call last):
  File "D:\Ina\ETL_XdmLib_2.A.13\ETL_XdmLib_2.A.13\EDAETL\ETL_TABLE\ETL_XYN_XLSX_TO_KLARF\../..\XdmLib\CustomFuction.py", line 596, in file2db_init
    res = do_file(file_root_source_path,
  File "D:\Ina\ETL_XdmLib_2.A.13\ETL_XdmLib_2.A.13\EDAETL\ETL_TABLE\ETL_XYN_XLSX_TO_KLARF\ETL_SICA88_TO_KLARF.py", line 45, in do_file
    row['No.'],
  File "D:\soft\anaconda3\lib\site-packages\pandas\core\series.py", line 958, in __getitem__
    return self._get_value(key)
  File "D:\soft\anaconda3\lib\site-packages\pandas\core\series.py", line 1069, in _get_value
    loc = self.index.get_loc(label)
  File "D:\soft\anaconda3\lib\site-packages\pandas\core\indexes\base.py", line 3623, in get_loc
    raise KeyError(key) from err
KeyError: 'No.'
Stack (most recent call last):
  File "D:\Ina\ETL_XdmLib_2.A.13\ETL_XdmLib_2.A.13\EDAETL\ETL_TABLE\ETL_XYN_XLSX_TO_KLARF\ETL_SICA88_TO_KLARF.py", line 116, in <module>
    XdmLib.CustomFuction.file2db_init(
  File "D:\Ina\ETL_XdmLib_2.A.13\ETL_XdmLib_2.A.13\EDAETL\ETL_TABLE\ETL_XYN_XLSX_TO_KLARF\../..\XdmLib\CustomFuction.py", line 631, in file2db_init
    log.error(ex, exc_info=True, stack_info=True)
2023-11-27 20:30:47.579 - CustomFuction [INFO    ] [ERROR] 40-4N46-DF07016.xlsx
2023-11-27 20:30:47.584 - CustomFuction [INFO    ] Move file: 40-4N46-DF07016.xlsx to ERROR folder: Data\ERROR\40-4N46-DF07016.xlsx.
2023-11-27 20:30:51.711 - CustomFuction [INFO    ] ========[ File End ]========
2023-11-27 20:30:51.713 - CustomFuction [INFO    ] ========[ Delete Empty Folder ]========
2023-11-27 20:30:51.900 - CustomFuction [INFO    ] ========== Finally ==========
2023-11-27 20:30:55.703 - __init__   [INFO    ] Set process status code: 5.
2023-11-27 20:34:56.766 - __init__   [INFO    ] # ===== [ XdmLib Ver. ] ===== #
2023-11-27 20:34:56.767 - __init__   [INFO    ] XdmLib Ver. 2.A.13
2023-11-27 20:34:56.768 - __init__   [INFO    ] # ===== [ XdmLib Ver. ] ===== #
2023-11-27 20:34:56.771 - __init__   [INFO    ] Console Quick Edit Disabled
2023-11-27 20:34:56.815 - __init__   [INFO    ] Server/Host Name: DESKTOP-J6AUF2I
2023-11-27 20:34:56.815 - __init__   [INFO    ] Archive setting non-setting, Archive files will be kept.
2023-11-27 20:34:56.816 - __init__   [INFO    ] Error setting non-setting, Error files will be kept.
2023-11-27 20:34:58.925 - __init__   [INFO    ] Server: DESKTOP-J6AUF2I, Status: 5, data_time_flg: None.
2023-11-27 20:34:59.554 - __init__   [INFO    ] Watching control file: D:\Ina\ETL_XdmLib_2.A.13\ETL_XdmLib_2.A.13\EDAETL\ETL_TABLE\ETL_XYN_XLSX_TO_KLARF\ETL_SICA88_TO_KLARF.py.*
2023-11-27 20:34:59.558 - __init__   [INFO    ] SetProcessStatus 0, Start time: 2023-11-27 20:34:56.746812
2023-11-27 20:35:01.566 - __init__   [INFO    ] Set process status code: 0.
2023-11-27 20:35:01.681 - Database   [INFO    ] Non set logging! Using default logging.
2023-11-27 20:35:02.293 - Database   [INFO    ] Non set logging! Using default logging.
2023-11-27 20:35:02.883 - Database   [INFO    ] Non set logging! Using default logging.
2023-11-27 20:35:03.478 - CustomFuction [INFO    ] [Empty] Empty Folder : ./Data/Source
2023-11-27 20:35:03.478 - CustomFuction [INFO    ] ========[ File End ]========
2023-11-27 20:35:03.479 - CustomFuction [INFO    ] ========[ Delete Empty Folder ]========
2023-11-27 20:35:03.605 - CustomFuction [INFO    ] ========== Finally ==========
2023-11-27 20:35:05.270 - __init__   [INFO    ] Set process status code: 1, Last data time: None.
2023-11-27 20:35:23.605 - __init__   [INFO    ] # ===== [ XdmLib Ver. ] ===== #
2023-11-27 20:35:23.605 - __init__   [INFO    ] XdmLib Ver. 2.A.13
2023-11-27 20:35:23.605 - __init__   [INFO    ] # ===== [ XdmLib Ver. ] ===== #
2023-11-27 20:35:23.607 - __init__   [INFO    ] Console Quick Edit Disabled
2023-11-27 20:35:23.647 - __init__   [INFO    ] Server/Host Name: DESKTOP-J6AUF2I
2023-11-27 20:35:23.647 - __init__   [INFO    ] Archive setting non-setting, Archive files will be kept.
2023-11-27 20:35:23.648 - __init__   [INFO    ] Error setting non-setting, Error files will be kept.
2023-11-27 20:35:25.456 - __init__   [INFO    ] Server: DESKTOP-J6AUF2I, Status: 1, data_time_flg: None.
2023-11-27 20:35:26.069 - __init__   [INFO    ] Watching control file: D:\Ina\ETL_XdmLib_2.A.13\ETL_XdmLib_2.A.13\EDAETL\ETL_TABLE\ETL_XYN_XLSX_TO_KLARF\ETL_SICA88_TO_KLARF.py.*
2023-11-27 20:35:26.073 - __init__   [INFO    ] SetProcessStatus 0, Start time: 2023-11-27 20:35:23.589794
2023-11-27 20:35:27.952 - __init__   [INFO    ] Set process status code: 0.
2023-11-27 20:35:28.088 - Database   [INFO    ] Non set logging! Using default logging.
2023-11-27 20:35:28.801 - Database   [INFO    ] Non set logging! Using default logging.
2023-11-27 20:35:29.469 - Database   [INFO    ] Non set logging! Using default logging.
2023-11-27 20:35:30.182 - CustomFuction [ERROR   ] Missing optional dependency 'openpyxl'.  Use pip or conda to install openpyxl.
Traceback (most recent call last):
  File "../..\XdmLib\CustomFuction.py", line 597, in file2db_init
    file, pre_params, db_src, db_tgt)
  File "D:/Ina/ETL_XdmLib_2.A.13/ETL_XdmLib_2.A.13/EDAETL/ETL_TABLE/ETL_XYN_XLSX_TO_KLARF/ETL_SICA88_TO_KLARF.py", line 27, in do_file
    Data = pd.read_excel(file_path,engine = "openpyxl")
  File "D:\Python37\lib\site-packages\pandas\util\_decorators.py", line 296, in wrapper
    return func(*args, **kwargs)
  File "D:\Python37\lib\site-packages\pandas\io\excel\_base.py", line 304, in read_excel
    io = ExcelFile(io, engine=engine)
  File "D:\Python37\lib\site-packages\pandas\io\excel\_base.py", line 867, in __init__
    self._reader = self._engines[engine](self._io)
  File "D:\Python37\lib\site-packages\pandas\io\excel\_openpyxl.py", line 479, in __init__
    import_optional_dependency("openpyxl")
  File "D:\Python37\lib\site-packages\pandas\compat\_optional.py", line 110, in import_optional_dependency
    raise ImportError(msg) from None
ImportError: Missing optional dependency 'openpyxl'.  Use pip or conda to install openpyxl.
Stack (most recent call last):
  File "D:/Ina/ETL_XdmLib_2.A.13/ETL_XdmLib_2.A.13/EDAETL/ETL_TABLE/ETL_XYN_XLSX_TO_KLARF/ETL_SICA88_TO_KLARF.py", line 117, in <module>
    do_file, before_do_file, after_do_file, skip_file, None, log, config, config_sql)
  File "../..\XdmLib\CustomFuction.py", line 631, in file2db_init
    log.error(ex, exc_info=True, stack_info=True)
2023-11-27 20:35:30.227 - CustomFuction [INFO    ] [ERROR] 40-4N46-DF07016.xlsx
2023-11-27 20:35:30.230 - CustomFuction [INFO    ] Move file: 40-4N46-DF07016.xlsx to ERROR folder: Data\ERROR\40-4N46-DF07016.xlsx.
2023-11-27 20:35:31.663 - CustomFuction [INFO    ] ========[ File End ]========
2023-11-27 20:35:31.664 - CustomFuction [INFO    ] ========[ Delete Empty Folder ]========
2023-11-27 20:35:31.816 - CustomFuction [INFO    ] ========== Finally ==========
2023-11-27 20:35:33.199 - __init__   [INFO    ] Set process status code: 5.
2023-11-27 20:37:38.749 - __init__   [INFO    ] # ===== [ XdmLib Ver. ] ===== #
2023-11-27 20:37:38.749 - __init__   [INFO    ] XdmLib Ver. 2.A.13
2023-11-27 20:37:38.749 - __init__   [INFO    ] # ===== [ XdmLib Ver. ] ===== #
2023-11-27 20:37:38.751 - __init__   [INFO    ] Console Quick Edit Disabled
2023-11-27 20:37:38.781 - __init__   [INFO    ] Server/Host Name: DESKTOP-J6AUF2I
2023-11-27 20:37:38.781 - __init__   [INFO    ] Archive setting non-setting, Archive files will be kept.
2023-11-27 20:37:38.781 - __init__   [INFO    ] Error setting non-setting, Error files will be kept.
2023-11-27 20:37:40.407 - __init__   [INFO    ] Server: DESKTOP-J6AUF2I, Status: 5, data_time_flg: None.
2023-11-27 20:37:41.022 - __init__   [INFO    ] Watching control file: D:\Ina\ETL_XdmLib_2.A.13\ETL_XdmLib_2.A.13\EDAETL\ETL_TABLE\ETL_XYN_XLSX_TO_KLARF\ETL_SICA88_TO_KLARF.py.*
2023-11-27 20:37:41.028 - __init__   [INFO    ] SetProcessStatus 0, Start time: 2023-11-27 20:37:38.733740
2023-11-27 20:37:42.609 - __init__   [INFO    ] Set process status code: 0.
2023-11-27 20:37:42.732 - Database   [INFO    ] Non set logging! Using default logging.
2023-11-27 20:37:43.326 - Database   [INFO    ] Non set logging! Using default logging.
2023-11-27 20:37:43.861 - Database   [INFO    ] Non set logging! Using default logging.
2023-11-27 20:37:44.484 - CustomFuction [INFO    ] [Empty] Empty Folder : ./Data/Source
2023-11-27 20:37:44.484 - CustomFuction [INFO    ] ========[ File End ]========
2023-11-27 20:37:44.484 - CustomFuction [INFO    ] ========[ Delete Empty Folder ]========
2023-11-27 20:37:44.612 - CustomFuction [INFO    ] ========== Finally ==========
2023-11-27 20:37:46.005 - __init__   [INFO    ] Set process status code: 1, Last data time: None.
2023-11-27 20:38:02.097 - __init__   [INFO    ] # ===== [ XdmLib Ver. ] ===== #
2023-11-27 20:38:02.097 - __init__   [INFO    ] XdmLib Ver. 2.A.13
2023-11-27 20:38:02.098 - __init__   [INFO    ] # ===== [ XdmLib Ver. ] ===== #
2023-11-27 20:38:02.100 - __init__   [INFO    ] Console Quick Edit Disabled
2023-11-27 20:38:02.126 - __init__   [INFO    ] Server/Host Name: DESKTOP-J6AUF2I
2023-11-27 20:38:02.126 - __init__   [INFO    ] Archive setting non-setting, Archive files will be kept.
2023-11-27 20:38:02.126 - __init__   [INFO    ] Error setting non-setting, Error files will be kept.
2023-11-27 20:38:03.995 - __init__   [INFO    ] Server: DESKTOP-J6AUF2I, Status: 1, data_time_flg: None.
2023-11-27 20:38:04.758 - __init__   [INFO    ] Watching control file: D:\Ina\ETL_XdmLib_2.A.13\ETL_XdmLib_2.A.13\EDAETL\ETL_TABLE\ETL_XYN_XLSX_TO_KLARF\ETL_SICA88_TO_KLARF.py.*
2023-11-27 20:38:04.762 - __init__   [INFO    ] SetProcessStatus 0, Start time: 2023-11-27 20:38:02.077225
2023-11-27 20:38:06.892 - __init__   [INFO    ] Set process status code: 0.
2023-11-27 20:38:07.015 - Database   [INFO    ] Non set logging! Using default logging.
2023-11-27 20:38:07.698 - Database   [INFO    ] Non set logging! Using default logging.
2023-11-27 20:38:08.537 - Database   [INFO    ] Non set logging! Using default logging.
2023-11-27 20:38:09.264 - CustomFuction [ERROR   ] Missing optional dependency 'openpyxl'.  Use pip or conda to install openpyxl.
Traceback (most recent call last):
  File "../..\XdmLib\CustomFuction.py", line 597, in file2db_init
    file, pre_params, db_src, db_tgt)
  File "D:/Ina/ETL_XdmLib_2.A.13/ETL_XdmLib_2.A.13/EDAETL/ETL_TABLE/ETL_XYN_XLSX_TO_KLARF/ETL_SICA88_TO_KLARF.py", line 27, in do_file
    Data = pd.read_excel(file_path,engine = "openpyxl")
  File "D:\Python37\lib\site-packages\pandas\util\_decorators.py", line 296, in wrapper
    return func(*args, **kwargs)
  File "D:\Python37\lib\site-packages\pandas\io\excel\_base.py", line 304, in read_excel
    io = ExcelFile(io, engine=engine)
  File "D:\Python37\lib\site-packages\pandas\io\excel\_base.py", line 867, in __init__
    self._reader = self._engines[engine](self._io)
  File "D:\Python37\lib\site-packages\pandas\io\excel\_openpyxl.py", line 479, in __init__
    import_optional_dependency("openpyxl")
  File "D:\Python37\lib\site-packages\pandas\compat\_optional.py", line 110, in import_optional_dependency
    raise ImportError(msg) from None
ImportError: Missing optional dependency 'openpyxl'.  Use pip or conda to install openpyxl.
Stack (most recent call last):
  File "D:/Ina/ETL_XdmLib_2.A.13/ETL_XdmLib_2.A.13/EDAETL/ETL_TABLE/ETL_XYN_XLSX_TO_KLARF/ETL_SICA88_TO_KLARF.py", line 117, in <module>
    do_file, before_do_file, after_do_file, skip_file, None, log, config, config_sql)
  File "../..\XdmLib\CustomFuction.py", line 631, in file2db_init
    log.error(ex, exc_info=True, stack_info=True)
2023-11-27 20:38:09.298 - CustomFuction [INFO    ] [ERROR] 40-4N46-DF07016.xlsx
2023-11-27 20:38:09.300 - CustomFuction [INFO    ] Move file: 40-4N46-DF07016.xlsx to ERROR folder: Data\ERROR\40-4N46-DF07016.xlsx.
2023-11-27 20:38:10.943 - CustomFuction [INFO    ] ========[ File End ]========
2023-11-27 20:38:10.944 - CustomFuction [INFO    ] ========[ Delete Empty Folder ]========
2023-11-27 20:38:11.084 - CustomFuction [INFO    ] ========== Finally ==========
2023-11-27 20:38:12.937 - __init__   [INFO    ] Set process status code: 5.
2023-11-27 20:46:10.112 - __init__   [INFO    ] # ===== [ XdmLib Ver. ] ===== #
2023-11-27 20:46:10.113 - __init__   [INFO    ] XdmLib Ver. 2.A.13
2023-11-27 20:46:10.113 - __init__   [INFO    ] # ===== [ XdmLib Ver. ] ===== #
2023-11-27 20:46:10.118 - __init__   [INFO    ] Console Quick Edit Disabled
2023-11-27 20:46:10.179 - __init__   [INFO    ] Server/Host Name: DESKTOP-J6AUF2I
2023-11-27 20:46:10.181 - __init__   [INFO    ] Archive setting non-setting, Archive files will be kept.
2023-11-27 20:46:10.181 - __init__   [INFO    ] Error setting non-setting, Error files will be kept.
2023-11-27 20:46:37.837 - __init__   [INFO    ] # ===== [ XdmLib Ver. ] ===== #
2023-11-27 20:46:37.838 - __init__   [INFO    ] XdmLib Ver. 2.A.13
2023-11-27 20:46:37.838 - __init__   [INFO    ] # ===== [ XdmLib Ver. ] ===== #
2023-11-27 20:46:37.842 - __init__   [INFO    ] Console Quick Edit Disabled
2023-11-27 20:46:37.869 - __init__   [INFO    ] Server/Host Name: DESKTOP-J6AUF2I
2023-11-27 20:46:37.869 - __init__   [INFO    ] Archive setting non-setting, Archive files will be kept.
2023-11-27 20:46:37.870 - __init__   [INFO    ] Error setting non-setting, Error files will be kept.
2023-11-27 20:46:39.640 - __init__   [INFO    ] Server: DESKTOP-J6AUF2I, Status: 5, data_time_flg: None.
2023-11-27 20:46:40.248 - __init__   [INFO    ] Watching control file: D:\Ina\ETL_XdmLib_2.A.13\ETL_XdmLib_2.A.13\EDAETL\ETL_TABLE\ETL_XYN_XLSX_TO_KLARF\ETL_SICA88_TO_KLARF.py.*
2023-11-27 20:46:40.250 - __init__   [INFO    ] SetProcessStatus 0, Start time: 2023-11-27 20:46:37.816072
2023-11-27 20:46:42.031 - __init__   [INFO    ] Set process status code: 0.
2023-11-27 20:46:42.177 - Database   [INFO    ] Non set logging! Using default logging.
2023-11-27 20:46:42.875 - Database   [INFO    ] Non set logging! Using default logging.
2023-11-27 20:46:43.529 - Database   [INFO    ] Non set logging! Using default logging.
2023-11-27 20:46:45.412 - ETL_SICA88_TO_KLARF [INFO    ] Read Source File:0:00:01.277536
2023-11-27 20:46:45.419 - CustomFuction [ERROR   ] 'No.'
Traceback (most recent call last):
  File "D:\Python37\lib\site-packages\pandas\core\indexes\base.py", line 2898, in get_loc
    return self._engine.get_loc(casted_key)
  File "pandas\_libs\index.pyx", line 70, in pandas._libs.index.IndexEngine.get_loc
  File "pandas\_libs\index.pyx", line 101, in pandas._libs.index.IndexEngine.get_loc
  File "pandas\_libs\hashtable_class_helper.pxi", line 1675, in pandas._libs.hashtable.PyObjectHashTable.get_item
  File "pandas\_libs\hashtable_class_helper.pxi", line 1683, in pandas._libs.hashtable.PyObjectHashTable.get_item
KeyError: 'No.'

The above exception was the direct cause of the following exception:

Traceback (most recent call last):
  File "../..\XdmLib\CustomFuction.py", line 597, in file2db_init
    file, pre_params, db_src, db_tgt)
  File "D:/Ina/ETL_XdmLib_2.A.13/ETL_XdmLib_2.A.13/EDAETL/ETL_TABLE/ETL_XYN_XLSX_TO_KLARF/ETL_SICA88_TO_KLARF.py", line 45, in do_file
    row['No.'],
  File "D:\Python37\lib\site-packages\pandas\core\series.py", line 882, in __getitem__
    return self._get_value(key)
  File "D:\Python37\lib\site-packages\pandas\core\series.py", line 990, in _get_value
    loc = self.index.get_loc(label)
  File "D:\Python37\lib\site-packages\pandas\core\indexes\base.py", line 2900, in get_loc
    raise KeyError(key) from err
KeyError: 'No.'
Stack (most recent call last):
  File "D:/Ina/ETL_XdmLib_2.A.13/ETL_XdmLib_2.A.13/EDAETL/ETL_TABLE/ETL_XYN_XLSX_TO_KLARF/ETL_SICA88_TO_KLARF.py", line 117, in <module>
    do_file, before_do_file, after_do_file, skip_file, None, log, config, config_sql)
  File "../..\XdmLib\CustomFuction.py", line 631, in file2db_init
    log.error(ex, exc_info=True, stack_info=True)
2023-11-27 20:46:45.502 - CustomFuction [INFO    ] [ERROR] 40-4N46-DF07016.xlsx
2023-11-27 20:46:45.504 - CustomFuction [INFO    ] Move file: 40-4N46-DF07016.xlsx to ERROR folder: Data\ERROR\40-4N46-DF07016.xlsx.
2023-11-27 20:46:47.218 - CustomFuction [INFO    ] ========[ File End ]========
2023-11-27 20:46:47.219 - CustomFuction [INFO    ] ========[ Delete Empty Folder ]========
2023-11-27 20:46:47.361 - CustomFuction [INFO    ] ========== Finally ==========
2023-11-27 20:46:49.022 - __init__   [INFO    ] Set process status code: 5.
2023-11-27 20:47:38.335 - __init__   [INFO    ] # ===== [ XdmLib Ver. ] ===== #
2023-11-27 20:47:38.336 - __init__   [INFO    ] XdmLib Ver. 2.A.13
2023-11-27 20:47:38.336 - __init__   [INFO    ] # ===== [ XdmLib Ver. ] ===== #
2023-11-27 20:47:38.340 - __init__   [INFO    ] Console Quick Edit Disabled
2023-11-27 20:47:38.394 - __init__   [INFO    ] Server/Host Name: DESKTOP-J6AUF2I
2023-11-27 20:47:38.396 - __init__   [INFO    ] Archive setting non-setting, Archive files will be kept.
2023-11-27 20:47:38.397 - __init__   [INFO    ] Error setting non-setting, Error files will be kept.
2023-11-27 20:47:40.507 - __init__   [INFO    ] Server: DESKTOP-J6AUF2I, Status: 5, data_time_flg: None.
2023-11-27 20:47:41.215 - __init__   [INFO    ] Watching control file: D:\Ina\ETL_XdmLib_2.A.13\ETL_XdmLib_2.A.13\EDAETL\ETL_TABLE\ETL_XYN_XLSX_TO_KLARF\ETL_SICA88_TO_KLARF.py.*
2023-11-27 20:47:41.225 - __init__   [INFO    ] SetProcessStatus 0, Start time: 2023-11-27 20:47:38.252546
2023-11-27 20:47:43.209 - __init__   [INFO    ] Set process status code: 0.
2023-11-27 20:47:43.403 - Database   [INFO    ] Non set logging! Using default logging.
2023-11-27 20:47:44.541 - Database   [INFO    ] Non set logging! Using default logging.
2023-11-27 20:47:45.488 - Database   [INFO    ] Non set logging! Using default logging.
2023-11-27 20:47:58.440 - __init__   [INFO    ] # ===== [ XdmLib Ver. ] ===== #
2023-11-27 20:47:58.441 - __init__   [INFO    ] XdmLib Ver. 2.A.13
2023-11-27 20:47:58.441 - __init__   [INFO    ] # ===== [ XdmLib Ver. ] ===== #
2023-11-27 20:47:58.445 - __init__   [INFO    ] Console Quick Edit Disabled
2023-11-27 20:47:58.476 - __init__   [INFO    ] Server/Host Name: DESKTOP-J6AUF2I
2023-11-27 20:47:58.477 - __init__   [INFO    ] Archive setting non-setting, Archive files will be kept.
2023-11-27 20:47:58.477 - __init__   [INFO    ] Error setting non-setting, Error files will be kept.
2023-11-27 20:48:00.161 - __init__   [INFO    ] Server: DESKTOP-J6AUF2I, Status: 0, data_time_flg: None.
2023-11-27 20:48:00.162 - __init__   [WARNING ] The loader duplicate execute(Set attribute: 'ALLOW_DUPLICATE_EXECUTE = False' disable it).
2023-11-27 20:48:01.182 - __init__   [INFO    ] Watching control file: D:\Ina\ETL_XdmLib_2.A.13\ETL_XdmLib_2.A.13\EDAETL\ETL_TABLE\ETL_XYN_XLSX_TO_KLARF\ETL_SICA88_TO_KLARF.py.*
2023-11-27 20:48:01.191 - __init__   [INFO    ] SetProcessStatus 0, Start time: 2023-11-27 20:47:58.373310
2023-11-27 20:48:05.640 - __init__   [INFO    ] Set process status code: 0.
2023-11-27 20:48:05.825 - Database   [INFO    ] Non set logging! Using default logging.
2023-11-27 20:48:06.852 - Database   [INFO    ] Non set logging! Using default logging.
2023-11-27 20:48:07.638 - Database   [INFO    ] Non set logging! Using default logging.
2023-11-27 20:48:09.960 - ETL_SICA88_TO_KLARF [INFO    ] Read Source File:0:00:01.390120
2023-11-27 20:49:58.712 - __init__   [INFO    ] # ===== [ XdmLib Ver. ] ===== #
2023-11-27 20:49:58.713 - __init__   [INFO    ] XdmLib Ver. 2.A.13
2023-11-27 20:49:58.713 - __init__   [INFO    ] # ===== [ XdmLib Ver. ] ===== #
2023-11-27 20:49:58.715 - __init__   [INFO    ] Console Quick Edit Disabled
2023-11-27 20:49:58.744 - __init__   [INFO    ] Server/Host Name: DESKTOP-J6AUF2I
2023-11-27 20:49:58.745 - __init__   [INFO    ] Archive setting non-setting, Archive files will be kept.
2023-11-27 20:49:58.746 - __init__   [INFO    ] Error setting non-setting, Error files will be kept.
2023-11-27 20:50:00.476 - __init__   [INFO    ] Server: DESKTOP-J6AUF2I, Status: 0, data_time_flg: None.
2023-11-27 20:50:00.477 - __init__   [WARNING ] The loader duplicate execute(Set attribute: 'ALLOW_DUPLICATE_EXECUTE = False' disable it).
2023-11-27 20:50:01.100 - __init__   [INFO    ] Watching control file: D:\Ina\ETL_XdmLib_2.A.13\ETL_XdmLib_2.A.13\EDAETL\ETL_TABLE\ETL_XYN_XLSX_TO_KLARF\ETL_SICA88_TO_KLARF.py.*
2023-11-27 20:50:01.103 - __init__   [INFO    ] SetProcessStatus 0, Start time: 2023-11-27 20:49:58.659429
2023-11-27 20:50:03.399 - __init__   [INFO    ] Set process status code: 0.
2023-11-27 20:50:03.585 - Database   [INFO    ] Non set logging! Using default logging.
2023-11-27 20:50:04.717 - Database   [INFO    ] Non set logging! Using default logging.
2023-11-27 20:50:05.743 - Database   [INFO    ] Non set logging! Using default logging.
2023-11-27 20:50:08.032 - ETL_SICA88_TO_KLARF [INFO    ] Read Source File:0:00:01.225848
2023-11-27 20:50:20.986 - CustomFuction [ERROR   ] 'NO.'
Traceback (most recent call last):
  File "D:\Python37\lib\site-packages\pandas\core\indexes\base.py", line 2898, in get_loc
    return self._engine.get_loc(casted_key)
  File "pandas\_libs\index.pyx", line 70, in pandas._libs.index.IndexEngine.get_loc
  File "pandas\_libs\index.pyx", line 101, in pandas._libs.index.IndexEngine.get_loc
  File "pandas\_libs\hashtable_class_helper.pxi", line 1675, in pandas._libs.hashtable.PyObjectHashTable.get_item
  File "pandas\_libs\hashtable_class_helper.pxi", line 1683, in pandas._libs.hashtable.PyObjectHashTable.get_item
KeyError: 'NO.'

The above exception was the direct cause of the following exception:

Traceback (most recent call last):
  File "../..\XdmLib\CustomFuction.py", line 597, in file2db_init
    file, pre_params, db_src, db_tgt)
  File "D:/Ina/ETL_XdmLib_2.A.13/ETL_XdmLib_2.A.13/EDAETL/ETL_TABLE/ETL_XYN_XLSX_TO_KLARF/ETL_SICA88_TO_KLARF.py", line 45, in do_file
    row['NO.'],
  File "D:\Python37\lib\site-packages\pandas\core\series.py", line 882, in __getitem__
    return self._get_value(key)
  File "D:\Python37\lib\site-packages\pandas\core\series.py", line 990, in _get_value
    loc = self.index.get_loc(label)
  File "D:\Python37\lib\site-packages\pandas\core\indexes\base.py", line 2900, in get_loc
    raise KeyError(key) from err
KeyError: 'NO.'
Stack (most recent call last):
  File "D:\soft\PyCharm Community Edition 2022.1.3\plugins\python-ce\helpers\pydev\pydevd.py", line 2181, in <module>
    main()
  File "D:\soft\PyCharm Community Edition 2022.1.3\plugins\python-ce\helpers\pydev\pydevd.py", line 2172, in main
    globals = debugger.run(setup['file'], None, None, is_module)
  File "D:\soft\PyCharm Community Edition 2022.1.3\plugins\python-ce\helpers\pydev\pydevd.py", line 1484, in run
    return self._exec(is_module, entry_point_fn, module_name, file, globals, locals)
  File "D:\soft\PyCharm Community Edition 2022.1.3\plugins\python-ce\helpers\pydev\pydevd.py", line 1491, in _exec
    pydev_imports.execfile(file, globals, locals)  # execute the script
  File "D:\soft\PyCharm Community Edition 2022.1.3\plugins\python-ce\helpers\pydev\_pydev_imps\_pydev_execfile.py", line 18, in execfile
    exec(compile(contents+"\n", file, 'exec'), glob, loc)
  File "D:/Ina/ETL_XdmLib_2.A.13/ETL_XdmLib_2.A.13/EDAETL/ETL_TABLE/ETL_XYN_XLSX_TO_KLARF/ETL_SICA88_TO_KLARF.py", line 117, in <module>
    do_file, before_do_file, after_do_file, skip_file, None, log, config, config_sql)
  File "../..\XdmLib\CustomFuction.py", line 631, in file2db_init
    log.error(ex, exc_info=True, stack_info=True)
2023-11-27 20:50:21.197 - CustomFuction [INFO    ] [ERROR] 40-4N46-DF07016.xlsx
2023-11-27 20:50:21.200 - CustomFuction [INFO    ] Move file: 40-4N46-DF07016.xlsx to ERROR folder: Data\ERROR\40-4N46-DF07016.xlsx.
2023-11-27 20:50:22.833 - CustomFuction [INFO    ] ========[ File End ]========
2023-11-27 20:50:22.834 - CustomFuction [INFO    ] ========[ Delete Empty Folder ]========
2023-11-27 20:50:23.249 - CustomFuction [INFO    ] ========== Finally ==========
2023-11-27 20:50:25.966 - __init__   [INFO    ] Set process status code: 5.
2023-11-27 20:50:37.879 - __init__   [INFO    ] # ===== [ XdmLib Ver. ] ===== #
2023-11-27 20:50:37.879 - __init__   [INFO    ] XdmLib Ver. 2.A.13
2023-11-27 20:50:37.880 - __init__   [INFO    ] # ===== [ XdmLib Ver. ] ===== #
2023-11-27 20:50:37.881 - __init__   [INFO    ] Console Quick Edit Disabled
2023-11-27 20:50:37.909 - __init__   [INFO    ] Server/Host Name: DESKTOP-J6AUF2I
2023-11-27 20:50:37.909 - __init__   [INFO    ] Archive setting non-setting, Archive files will be kept.
2023-11-27 20:50:37.910 - __init__   [INFO    ] Error setting non-setting, Error files will be kept.
2023-11-27 20:50:40.270 - __init__   [INFO    ] Server: DESKTOP-J6AUF2I, Status: 5, data_time_flg: None.
2023-11-27 20:50:41.009 - __init__   [INFO    ] Watching control file: D:\Ina\ETL_XdmLib_2.A.13\ETL_XdmLib_2.A.13\EDAETL\ETL_TABLE\ETL_XYN_XLSX_TO_KLARF\ETL_SICA88_TO_KLARF.py.*
2023-11-27 20:50:41.018 - __init__   [INFO    ] SetProcessStatus 0, Start time: 2023-11-27 20:50:37.844888
2023-11-27 20:50:43.683 - __init__   [INFO    ] Set process status code: 0.
2023-11-27 20:50:44.203 - Database   [INFO    ] Non set logging! Using default logging.
2023-11-27 20:50:45.211 - Database   [INFO    ] Non set logging! Using default logging.
2023-11-27 20:50:46.740 - Database   [INFO    ] Non set logging! Using default logging.
2023-11-27 20:50:48.033 - CustomFuction [INFO    ] [Empty] Empty Folder : ./Data/Source
2023-11-27 20:50:48.034 - CustomFuction [INFO    ] ========[ File End ]========
2023-11-27 20:50:48.035 - CustomFuction [INFO    ] ========[ Delete Empty Folder ]========
2023-11-27 20:50:48.284 - CustomFuction [INFO    ] ========== Finally ==========
2023-11-27 20:50:51.067 - __init__   [INFO    ] Set process status code: 1, Last data time: None.
2023-11-27 20:51:01.384 - __init__   [INFO    ] # ===== [ XdmLib Ver. ] ===== #
2023-11-27 20:51:01.384 - __init__   [INFO    ] XdmLib Ver. 2.A.13
2023-11-27 20:51:01.386 - __init__   [INFO    ] # ===== [ XdmLib Ver. ] ===== #
2023-11-27 20:51:01.388 - __init__   [INFO    ] Console Quick Edit Disabled
2023-11-27 20:51:01.424 - __init__   [INFO    ] Server/Host Name: DESKTOP-J6AUF2I
2023-11-27 20:51:01.426 - __init__   [INFO    ] Archive setting non-setting, Archive files will be kept.
2023-11-27 20:51:01.426 - __init__   [INFO    ] Error setting non-setting, Error files will be kept.
2023-11-27 20:51:03.439 - __init__   [INFO    ] Server: DESKTOP-J6AUF2I, Status: 1, data_time_flg: None.
2023-11-27 20:51:04.168 - __init__   [INFO    ] Watching control file: D:\Ina\ETL_XdmLib_2.A.13\ETL_XdmLib_2.A.13\EDAETL\ETL_TABLE\ETL_XYN_XLSX_TO_KLARF\ETL_SICA88_TO_KLARF.py.*
2023-11-27 20:51:04.176 - __init__   [INFO    ] SetProcessStatus 0, Start time: 2023-11-27 20:51:01.326680
2023-11-27 20:51:06.559 - __init__   [INFO    ] Set process status code: 0.
2023-11-27 20:51:06.784 - Database   [INFO    ] Non set logging! Using default logging.
2023-11-27 20:51:07.949 - Database   [INFO    ] Non set logging! Using default logging.
2023-11-27 20:51:09.072 - Database   [INFO    ] Non set logging! Using default logging.
2023-11-27 20:51:11.496 - ETL_SICA88_TO_KLARF [INFO    ] Read Source File:0:00:01.430530
2023-11-27 21:33:49.664 - base       [ERROR   ] Exception during reset or similar
Traceback (most recent call last):
  File "../..\XdmLib\CustomFuction.py", line 597, in file2db_init
    file, pre_params, db_src, db_tgt)
  File "D:/Ina/ETL_XdmLib_2.A.13/ETL_XdmLib_2.A.13/EDAETL/ETL_TABLE/ETL_XYN_XLSX_TO_KLARF/ETL_SICA88_TO_KLARF.py", line 46, in do_file
    int((row['X(mm)'] + 75) * 10000)/10.0,# 统一单位成um
  File "D:/Ina/ETL_XdmLib_2.A.13/ETL_XdmLib_2.A.13/EDAETL/ETL_TABLE/ETL_XYN_XLSX_TO_KLARF/ETL_SICA88_TO_KLARF.py", line 46, in do_file
    int((row['X(mm)'] + 75) * 10000)/10.0,# 统一单位成um
  File "_pydevd_bundle\pydevd_cython_win32_37_64.pyx", line 1179, in _pydevd_bundle.pydevd_cython_win32_37_64.SafeCallWrapper.__call__
  File "_pydevd_bundle\pydevd_cython_win32_37_64.pyx", line 620, in _pydevd_bundle.pydevd_cython_win32_37_64.PyDBFrame.trace_dispatch
  File "_pydevd_bundle\pydevd_cython_win32_37_64.pyx", line 929, in _pydevd_bundle.pydevd_cython_win32_37_64.PyDBFrame.trace_dispatch
  File "_pydevd_bundle\pydevd_cython_win32_37_64.pyx", line 920, in _pydevd_bundle.pydevd_cython_win32_37_64.PyDBFrame.trace_dispatch
  File "_pydevd_bundle\pydevd_cython_win32_37_64.pyx", line 317, in _pydevd_bundle.pydevd_cython_win32_37_64.PyDBFrame.do_wait_suspend
  File "D:\soft\PyCharm Community Edition 2022.1.3\plugins\python-ce\helpers\pydev\pydevd.py", line 1155, in do_wait_suspend
    self._do_wait_suspend(thread, frame, event, arg, suspend_type, from_this_thread)
  File "D:\soft\PyCharm Community Edition 2022.1.3\plugins\python-ce\helpers\pydev\pydevd.py", line 1169, in _do_wait_suspend
    self.process_internal_commands()
  File "D:\soft\PyCharm Community Edition 2022.1.3\plugins\python-ce\helpers\pydev\pydevd.py", line 792, in process_internal_commands
    all_threads = threadingEnumerate()
  File "D:\Python37\lib\threading.py", line 1244, in enumerate
    with _active_limbo_lock:
KeyboardInterrupt

During handling of the above exception, another exception occurred:

Traceback (most recent call last):
  File "D:\Python37\lib\site-packages\sqlalchemy\pool\base.py", line 697, in _finalize_fairy
    fairy._reset(pool)
  File "D:\Python37\lib\site-packages\sqlalchemy\pool\base.py", line 893, in _reset
    pool._dialect.do_rollback(self)
  File "D:\Python37\lib\site-packages\sqlalchemy\engine\default.py", line 559, in do_rollback
    dbapi_connection.rollback()
cx_Oracle.DatabaseError: DPI-1080: connection was closed by ORA-3135
2023-11-27 21:33:49.847 - base       [ERROR   ] Exception closing connection <cx_Oracle.Connection to vidatest@(DESCRIPTION=(ADDRESS=(PROTOCOL=TCP)(HOST=192.168.1.73)(PORT=1521))(CONNECT_DATA=(SID=demodb)))>
Traceback (most recent call last):
  File "../..\XdmLib\CustomFuction.py", line 597, in file2db_init
    file, pre_params, db_src, db_tgt)
  File "D:/Ina/ETL_XdmLib_2.A.13/ETL_XdmLib_2.A.13/EDAETL/ETL_TABLE/ETL_XYN_XLSX_TO_KLARF/ETL_SICA88_TO_KLARF.py", line 46, in do_file
    int((row['X(mm)'] + 75) * 10000)/10.0,# 统一单位成um
  File "D:/Ina/ETL_XdmLib_2.A.13/ETL_XdmLib_2.A.13/EDAETL/ETL_TABLE/ETL_XYN_XLSX_TO_KLARF/ETL_SICA88_TO_KLARF.py", line 46, in do_file
    int((row['X(mm)'] + 75) * 10000)/10.0,# 统一单位成um
  File "_pydevd_bundle\pydevd_cython_win32_37_64.pyx", line 1179, in _pydevd_bundle.pydevd_cython_win32_37_64.SafeCallWrapper.__call__
  File "_pydevd_bundle\pydevd_cython_win32_37_64.pyx", line 620, in _pydevd_bundle.pydevd_cython_win32_37_64.PyDBFrame.trace_dispatch
  File "_pydevd_bundle\pydevd_cython_win32_37_64.pyx", line 929, in _pydevd_bundle.pydevd_cython_win32_37_64.PyDBFrame.trace_dispatch
  File "_pydevd_bundle\pydevd_cython_win32_37_64.pyx", line 920, in _pydevd_bundle.pydevd_cython_win32_37_64.PyDBFrame.trace_dispatch
  File "_pydevd_bundle\pydevd_cython_win32_37_64.pyx", line 317, in _pydevd_bundle.pydevd_cython_win32_37_64.PyDBFrame.do_wait_suspend
  File "D:\soft\PyCharm Community Edition 2022.1.3\plugins\python-ce\helpers\pydev\pydevd.py", line 1155, in do_wait_suspend
    self._do_wait_suspend(thread, frame, event, arg, suspend_type, from_this_thread)
  File "D:\soft\PyCharm Community Edition 2022.1.3\plugins\python-ce\helpers\pydev\pydevd.py", line 1169, in _do_wait_suspend
    self.process_internal_commands()
  File "D:\soft\PyCharm Community Edition 2022.1.3\plugins\python-ce\helpers\pydev\pydevd.py", line 792, in process_internal_commands
    all_threads = threadingEnumerate()
  File "D:\Python37\lib\threading.py", line 1244, in enumerate
    with _active_limbo_lock:
KeyboardInterrupt

During handling of the above exception, another exception occurred:

Traceback (most recent call last):
  File "D:\Python37\lib\site-packages\sqlalchemy\pool\base.py", line 270, in _close_connection
    self._dialect.do_close(connection)
  File "D:\Python37\lib\site-packages\sqlalchemy\engine\default.py", line 565, in do_close
    dbapi_connection.close()
cx_Oracle.DatabaseError: DPI-1080: connection was closed by ORA-3135
2023-11-27 21:33:49.909 - base       [ERROR   ] Exception during reset or similar
Traceback (most recent call last):
  File "../..\XdmLib\CustomFuction.py", line 597, in file2db_init
    file, pre_params, db_src, db_tgt)
  File "D:/Ina/ETL_XdmLib_2.A.13/ETL_XdmLib_2.A.13/EDAETL/ETL_TABLE/ETL_XYN_XLSX_TO_KLARF/ETL_SICA88_TO_KLARF.py", line 46, in do_file
    int((row['X(mm)'] + 75) * 10000)/10.0,# 统一单位成um
  File "D:/Ina/ETL_XdmLib_2.A.13/ETL_XdmLib_2.A.13/EDAETL/ETL_TABLE/ETL_XYN_XLSX_TO_KLARF/ETL_SICA88_TO_KLARF.py", line 46, in do_file
    int((row['X(mm)'] + 75) * 10000)/10.0,# 统一单位成um
  File "_pydevd_bundle\pydevd_cython_win32_37_64.pyx", line 1179, in _pydevd_bundle.pydevd_cython_win32_37_64.SafeCallWrapper.__call__
  File "_pydevd_bundle\pydevd_cython_win32_37_64.pyx", line 620, in _pydevd_bundle.pydevd_cython_win32_37_64.PyDBFrame.trace_dispatch
  File "_pydevd_bundle\pydevd_cython_win32_37_64.pyx", line 929, in _pydevd_bundle.pydevd_cython_win32_37_64.PyDBFrame.trace_dispatch
  File "_pydevd_bundle\pydevd_cython_win32_37_64.pyx", line 920, in _pydevd_bundle.pydevd_cython_win32_37_64.PyDBFrame.trace_dispatch
  File "_pydevd_bundle\pydevd_cython_win32_37_64.pyx", line 317, in _pydevd_bundle.pydevd_cython_win32_37_64.PyDBFrame.do_wait_suspend
  File "D:\soft\PyCharm Community Edition 2022.1.3\plugins\python-ce\helpers\pydev\pydevd.py", line 1155, in do_wait_suspend
    self._do_wait_suspend(thread, frame, event, arg, suspend_type, from_this_thread)
  File "D:\soft\PyCharm Community Edition 2022.1.3\plugins\python-ce\helpers\pydev\pydevd.py", line 1169, in _do_wait_suspend
    self.process_internal_commands()
  File "D:\soft\PyCharm Community Edition 2022.1.3\plugins\python-ce\helpers\pydev\pydevd.py", line 792, in process_internal_commands
    all_threads = threadingEnumerate()
  File "D:\Python37\lib\threading.py", line 1244, in enumerate
    with _active_limbo_lock:
KeyboardInterrupt

During handling of the above exception, another exception occurred:

Traceback (most recent call last):
  File "D:\Python37\lib\site-packages\sqlalchemy\pool\base.py", line 697, in _finalize_fairy
    fairy._reset(pool)
  File "D:\Python37\lib\site-packages\sqlalchemy\pool\base.py", line 893, in _reset
    pool._dialect.do_rollback(self)
  File "D:\Python37\lib\site-packages\sqlalchemy\engine\default.py", line 559, in do_rollback
    dbapi_connection.rollback()
cx_Oracle.DatabaseError: DPI-1080: connection was closed by ORA-3135
2023-11-27 21:33:49.923 - base       [ERROR   ] Exception closing connection <cx_Oracle.Connection to vidatest@(DESCRIPTION=(ADDRESS=(PROTOCOL=TCP)(HOST=192.168.1.73)(PORT=1521))(CONNECT_DATA=(SID=demodb)))>
Traceback (most recent call last):
  File "../..\XdmLib\CustomFuction.py", line 597, in file2db_init
    file, pre_params, db_src, db_tgt)
  File "D:/Ina/ETL_XdmLib_2.A.13/ETL_XdmLib_2.A.13/EDAETL/ETL_TABLE/ETL_XYN_XLSX_TO_KLARF/ETL_SICA88_TO_KLARF.py", line 46, in do_file
    int((row['X(mm)'] + 75) * 10000)/10.0,# 统一单位成um
  File "D:/Ina/ETL_XdmLib_2.A.13/ETL_XdmLib_2.A.13/EDAETL/ETL_TABLE/ETL_XYN_XLSX_TO_KLARF/ETL_SICA88_TO_KLARF.py", line 46, in do_file
    int((row['X(mm)'] + 75) * 10000)/10.0,# 统一单位成um
  File "_pydevd_bundle\pydevd_cython_win32_37_64.pyx", line 1179, in _pydevd_bundle.pydevd_cython_win32_37_64.SafeCallWrapper.__call__
  File "_pydevd_bundle\pydevd_cython_win32_37_64.pyx", line 620, in _pydevd_bundle.pydevd_cython_win32_37_64.PyDBFrame.trace_dispatch
  File "_pydevd_bundle\pydevd_cython_win32_37_64.pyx", line 929, in _pydevd_bundle.pydevd_cython_win32_37_64.PyDBFrame.trace_dispatch
  File "_pydevd_bundle\pydevd_cython_win32_37_64.pyx", line 920, in _pydevd_bundle.pydevd_cython_win32_37_64.PyDBFrame.trace_dispatch
  File "_pydevd_bundle\pydevd_cython_win32_37_64.pyx", line 317, in _pydevd_bundle.pydevd_cython_win32_37_64.PyDBFrame.do_wait_suspend
  File "D:\soft\PyCharm Community Edition 2022.1.3\plugins\python-ce\helpers\pydev\pydevd.py", line 1155, in do_wait_suspend
    self._do_wait_suspend(thread, frame, event, arg, suspend_type, from_this_thread)
  File "D:\soft\PyCharm Community Edition 2022.1.3\plugins\python-ce\helpers\pydev\pydevd.py", line 1169, in _do_wait_suspend
    self.process_internal_commands()
  File "D:\soft\PyCharm Community Edition 2022.1.3\plugins\python-ce\helpers\pydev\pydevd.py", line 792, in process_internal_commands
    all_threads = threadingEnumerate()
  File "D:\Python37\lib\threading.py", line 1244, in enumerate
    with _active_limbo_lock:
KeyboardInterrupt

During handling of the above exception, another exception occurred:

Traceback (most recent call last):
  File "D:\Python37\lib\site-packages\sqlalchemy\pool\base.py", line 270, in _close_connection
    self._dialect.do_close(connection)
  File "D:\Python37\lib\site-packages\sqlalchemy\engine\default.py", line 565, in do_close
    dbapi_connection.close()
cx_Oracle.DatabaseError: DPI-1080: connection was closed by ORA-3135
2023-11-27 21:33:53.370 - __init__   [INFO    ] # ===== [ XdmLib Ver. ] ===== #
2023-11-27 21:33:53.370 - __init__   [INFO    ] XdmLib Ver. 2.A.13
2023-11-27 21:33:53.371 - __init__   [INFO    ] # ===== [ XdmLib Ver. ] ===== #
2023-11-27 21:33:53.376 - __init__   [INFO    ] Console Quick Edit Disabled
2023-11-27 21:33:53.434 - __init__   [INFO    ] Server/Host Name: DESKTOP-J6AUF2I
2023-11-27 21:33:53.436 - __init__   [INFO    ] Archive setting non-setting, Archive files will be kept.
2023-11-27 21:33:53.436 - __init__   [INFO    ] Error setting non-setting, Error files will be kept.
2023-11-27 21:34:35.662 - __init__   [INFO    ] # ===== [ XdmLib Ver. ] ===== #
2023-11-27 21:34:35.663 - __init__   [INFO    ] XdmLib Ver. 2.A.13
2023-11-27 21:34:35.663 - __init__   [INFO    ] # ===== [ XdmLib Ver. ] ===== #
2023-11-27 21:34:35.667 - __init__   [INFO    ] Console Quick Edit Disabled
2023-11-27 21:34:35.717 - __init__   [INFO    ] Server/Host Name: DESKTOP-J6AUF2I
2023-11-27 21:34:35.717 - __init__   [INFO    ] Archive setting non-setting, Archive files will be kept.
2023-11-27 21:34:35.717 - __init__   [INFO    ] Error setting non-setting, Error files will be kept.
2023-11-27 21:34:46.335 - __init__   [INFO    ] Server: DESKTOP-J6AUF2I, Status: 0, data_time_flg: None.
2023-11-27 21:34:46.336 - __init__   [WARNING ] The loader duplicate execute(Set attribute: 'ALLOW_DUPLICATE_EXECUTE = False' disable it).
2023-11-27 21:34:51.955 - __init__   [INFO    ] Watching control file: D:\Ina\ETL_XdmLib_2.A.13\ETL_XdmLib_2.A.13\EDAETL\ETL_TABLE\ETL_XYN_XLSX_TO_KLARF\ETL_SICA88_TO_KLARF.py.*
2023-11-27 21:34:51.971 - __init__   [INFO    ] SetProcessStatus 0, Start time: 2023-11-27 21:34:35.630296
2023-11-27 21:34:56.206 - __init__   [INFO    ] Set process status code: 0.
2023-11-27 21:34:56.424 - Database   [INFO    ] Non set logging! Using default logging.
2023-11-27 21:34:57.327 - Database   [INFO    ] Non set logging! Using default logging.
2023-11-27 21:34:58.714 - Database   [INFO    ] Non set logging! Using default logging.
2023-11-27 21:35:02.641 - ETL_SICA88_TO_KLARF [INFO    ] Read Source File:0:00:01.272276
2023-11-27 21:35:02.648 - CustomFuction [ERROR   ] 'N0.'
Traceback (most recent call last):
  File "D:\Python37\lib\site-packages\pandas\core\indexes\base.py", line 2898, in get_loc
    return self._engine.get_loc(casted_key)
  File "pandas\_libs\index.pyx", line 70, in pandas._libs.index.IndexEngine.get_loc
  File "pandas\_libs\index.pyx", line 101, in pandas._libs.index.IndexEngine.get_loc
  File "pandas\_libs\hashtable_class_helper.pxi", line 1675, in pandas._libs.hashtable.PyObjectHashTable.get_item
  File "pandas\_libs\hashtable_class_helper.pxi", line 1683, in pandas._libs.hashtable.PyObjectHashTable.get_item
KeyError: 'N0.'

The above exception was the direct cause of the following exception:

Traceback (most recent call last):
  File "../..\XdmLib\CustomFuction.py", line 597, in file2db_init
    file, pre_params, db_src, db_tgt)
  File "D:/Ina/ETL_XdmLib_2.A.13/ETL_XdmLib_2.A.13/EDAETL/ETL_TABLE/ETL_XYN_XLSX_TO_KLARF/ETL_SICA88_TO_KLARF.py", line 45, in do_file
    row['N0.'],
  File "D:\Python37\lib\site-packages\pandas\core\series.py", line 882, in __getitem__
    return self._get_value(key)
  File "D:\Python37\lib\site-packages\pandas\core\series.py", line 990, in _get_value
    loc = self.index.get_loc(label)
  File "D:\Python37\lib\site-packages\pandas\core\indexes\base.py", line 2900, in get_loc
    raise KeyError(key) from err
KeyError: 'N0.'
Stack (most recent call last):
  File "D:/Ina/ETL_XdmLib_2.A.13/ETL_XdmLib_2.A.13/EDAETL/ETL_TABLE/ETL_XYN_XLSX_TO_KLARF/ETL_SICA88_TO_KLARF.py", line 117, in <module>
    do_file, before_do_file, after_do_file, skip_file, None, log, config, config_sql)
  File "../..\XdmLib\CustomFuction.py", line 631, in file2db_init
    log.error(ex, exc_info=True, stack_info=True)
2023-11-27 21:35:02.698 - CustomFuction [INFO    ] [ERROR] 1-HB0185F0CIB0.xlsx
2023-11-27 21:35:02.700 - CustomFuction [INFO    ] Move file: 1-HB0185F0CIB0.xlsx to ERROR folder: Data\ERROR\1-HB0185F0CIB0.xlsx.
2023-11-27 21:35:06.548 - ETL_SICA88_TO_KLARF [INFO    ] Read Source File:0:00:00.126903
2023-11-27 21:35:06.551 - CustomFuction [ERROR   ] 'N0.'
Traceback (most recent call last):
  File "D:\Python37\lib\site-packages\pandas\core\indexes\base.py", line 2898, in get_loc
    return self._engine.get_loc(casted_key)
  File "pandas\_libs\index.pyx", line 70, in pandas._libs.index.IndexEngine.get_loc
  File "pandas\_libs\index.pyx", line 101, in pandas._libs.index.IndexEngine.get_loc
  File "pandas\_libs\hashtable_class_helper.pxi", line 1675, in pandas._libs.hashtable.PyObjectHashTable.get_item
  File "pandas\_libs\hashtable_class_helper.pxi", line 1683, in pandas._libs.hashtable.PyObjectHashTable.get_item
KeyError: 'N0.'

The above exception was the direct cause of the following exception:

Traceback (most recent call last):
  File "../..\XdmLib\CustomFuction.py", line 597, in file2db_init
    file, pre_params, db_src, db_tgt)
  File "D:/Ina/ETL_XdmLib_2.A.13/ETL_XdmLib_2.A.13/EDAETL/ETL_TABLE/ETL_XYN_XLSX_TO_KLARF/ETL_SICA88_TO_KLARF.py", line 45, in do_file
    row['N0.'],
  File "D:\Python37\lib\site-packages\pandas\core\series.py", line 882, in __getitem__
    return self._get_value(key)
  File "D:\Python37\lib\site-packages\pandas\core\series.py", line 990, in _get_value
    loc = self.index.get_loc(label)
  File "D:\Python37\lib\site-packages\pandas\core\indexes\base.py", line 2900, in get_loc
    raise KeyError(key) from err
KeyError: 'N0.'
Stack (most recent call last):
  File "D:/Ina/ETL_XdmLib_2.A.13/ETL_XdmLib_2.A.13/EDAETL/ETL_TABLE/ETL_XYN_XLSX_TO_KLARF/ETL_SICA88_TO_KLARF.py", line 117, in <module>
    do_file, before_do_file, after_do_file, skip_file, None, log, config, config_sql)
  File "../..\XdmLib\CustomFuction.py", line 631, in file2db_init
    log.error(ex, exc_info=True, stack_info=True)
2023-11-27 21:35:06.590 - CustomFuction [INFO    ] [ERROR] 1-HB0185F0CIB2.xls
2023-11-27 21:35:06.593 - CustomFuction [INFO    ] Move file: 1-HB0185F0CIB2.xls to ERROR folder: Data\ERROR\1-HB0185F0CIB2.xls.
2023-11-27 21:35:11.738 - ETL_SICA88_TO_KLARF [INFO    ] Read Source File:0:00:00.025393
2023-11-27 21:35:11.741 - CustomFuction [ERROR   ] 'N0.'
Traceback (most recent call last):
  File "D:\Python37\lib\site-packages\pandas\core\indexes\base.py", line 2898, in get_loc
    return self._engine.get_loc(casted_key)
  File "pandas\_libs\index.pyx", line 70, in pandas._libs.index.IndexEngine.get_loc
  File "pandas\_libs\index.pyx", line 101, in pandas._libs.index.IndexEngine.get_loc
  File "pandas\_libs\hashtable_class_helper.pxi", line 1675, in pandas._libs.hashtable.PyObjectHashTable.get_item
  File "pandas\_libs\hashtable_class_helper.pxi", line 1683, in pandas._libs.hashtable.PyObjectHashTable.get_item
KeyError: 'N0.'

The above exception was the direct cause of the following exception:

Traceback (most recent call last):
  File "../..\XdmLib\CustomFuction.py", line 597, in file2db_init
    file, pre_params, db_src, db_tgt)
  File "D:/Ina/ETL_XdmLib_2.A.13/ETL_XdmLib_2.A.13/EDAETL/ETL_TABLE/ETL_XYN_XLSX_TO_KLARF/ETL_SICA88_TO_KLARF.py", line 45, in do_file
    row['N0.'],
  File "D:\Python37\lib\site-packages\pandas\core\series.py", line 882, in __getitem__
    return self._get_value(key)
  File "D:\Python37\lib\site-packages\pandas\core\series.py", line 990, in _get_value
    loc = self.index.get_loc(label)
  File "D:\Python37\lib\site-packages\pandas\core\indexes\base.py", line 2900, in get_loc
    raise KeyError(key) from err
KeyError: 'N0.'
Stack (most recent call last):
  File "D:/Ina/ETL_XdmLib_2.A.13/ETL_XdmLib_2.A.13/EDAETL/ETL_TABLE/ETL_XYN_XLSX_TO_KLARF/ETL_SICA88_TO_KLARF.py", line 117, in <module>
    do_file, before_do_file, after_do_file, skip_file, None, log, config, config_sql)
  File "../..\XdmLib\CustomFuction.py", line 631, in file2db_init
    log.error(ex, exc_info=True, stack_info=True)
2023-11-27 21:35:11.813 - CustomFuction [INFO    ] [ERROR] 5_HB07FYQ6CIB5.csv
2023-11-27 21:35:11.816 - CustomFuction [INFO    ] Move file: 5_HB07FYQ6CIB5.csv to ERROR folder: Data\ERROR\5_HB07FYQ6CIB5.csv.
2023-11-27 21:35:14.456 - CustomFuction [INFO    ] ========[ File End ]========
2023-11-27 21:35:14.456 - CustomFuction [INFO    ] ========[ Delete Empty Folder ]========
2023-11-27 21:35:14.933 - CustomFuction [INFO    ] ========== Finally ==========
2023-11-27 21:35:17.501 - __init__   [INFO    ] Set process status code: 5.
2023-11-27 21:39:41.406 - __init__   [INFO    ] # ===== [ XdmLib Ver. ] ===== #
2023-11-27 21:39:41.407 - __init__   [INFO    ] XdmLib Ver. 2.A.13
2023-11-27 21:39:41.408 - __init__   [INFO    ] # ===== [ XdmLib Ver. ] ===== #
2023-11-27 21:39:41.412 - __init__   [INFO    ] Console Quick Edit Disabled
2023-11-27 21:39:41.441 - __init__   [INFO    ] Server/Host Name: DESKTOP-J6AUF2I
2023-11-27 21:39:41.441 - __init__   [INFO    ] Archive setting non-setting, Archive files will be kept.
2023-11-27 21:39:41.441 - __init__   [INFO    ] Error setting non-setting, Error files will be kept.
2023-11-27 21:39:42.633 - __init__   [INFO    ] Server: DESKTOP-J6AUF2I, Status: 5, data_time_flg: None.
2023-11-27 21:39:43.192 - __init__   [INFO    ] Watching control file: D:\Ina\ETL_XdmLib_2.A.13\ETL_XdmLib_2.A.13\EDAETL\ETL_TABLE\ETL_XYN_XLSX_TO_KLARF\ETL_SICA88_TO_KLARF.py.*
2023-11-27 21:39:43.195 - __init__   [INFO    ] SetProcessStatus 0, Start time: 2023-11-27 21:39:41.372459
2023-11-27 21:39:44.451 - __init__   [INFO    ] Set process status code: 0.
2023-11-27 21:39:44.559 - Database   [INFO    ] Non set logging! Using default logging.
2023-11-27 21:39:45.037 - Database   [INFO    ] Non set logging! Using default logging.
2023-11-27 21:39:45.522 - Database   [INFO    ] Non set logging! Using default logging.
2023-11-27 21:39:47.137 - ETL_SICA88_TO_KLARF [INFO    ] Read Source File:0:00:01.085953
2023-11-27 21:39:47.142 - CustomFuction [ERROR   ] 'NO.'
Traceback (most recent call last):
  File "D:\Python37\lib\site-packages\pandas\core\indexes\base.py", line 2898, in get_loc
    return self._engine.get_loc(casted_key)
  File "pandas\_libs\index.pyx", line 70, in pandas._libs.index.IndexEngine.get_loc
  File "pandas\_libs\index.pyx", line 101, in pandas._libs.index.IndexEngine.get_loc
  File "pandas\_libs\hashtable_class_helper.pxi", line 1675, in pandas._libs.hashtable.PyObjectHashTable.get_item
  File "pandas\_libs\hashtable_class_helper.pxi", line 1683, in pandas._libs.hashtable.PyObjectHashTable.get_item
KeyError: 'NO.'

The above exception was the direct cause of the following exception:

Traceback (most recent call last):
  File "../..\XdmLib\CustomFuction.py", line 597, in file2db_init
    file, pre_params, db_src, db_tgt)
  File "D:/Ina/ETL_XdmLib_2.A.13/ETL_XdmLib_2.A.13/EDAETL/ETL_TABLE/ETL_XYN_XLSX_TO_KLARF/ETL_SICA88_TO_KLARF.py", line 45, in do_file
    row['NO.'],
  File "D:\Python37\lib\site-packages\pandas\core\series.py", line 882, in __getitem__
    return self._get_value(key)
  File "D:\Python37\lib\site-packages\pandas\core\series.py", line 990, in _get_value
    loc = self.index.get_loc(label)
  File "D:\Python37\lib\site-packages\pandas\core\indexes\base.py", line 2900, in get_loc
    raise KeyError(key) from err
KeyError: 'NO.'
Stack (most recent call last):
  File "D:/Ina/ETL_XdmLib_2.A.13/ETL_XdmLib_2.A.13/EDAETL/ETL_TABLE/ETL_XYN_XLSX_TO_KLARF/ETL_SICA88_TO_KLARF.py", line 117, in <module>
    do_file, before_do_file, after_do_file, skip_file, None, log, config, config_sql)
  File "../..\XdmLib\CustomFuction.py", line 631, in file2db_init
    log.error(ex, exc_info=True, stack_info=True)
2023-11-27 21:39:47.175 - CustomFuction [INFO    ] [ERROR] 1-HB0185F0CIB0.xlsx
2023-11-27 21:39:47.177 - CustomFuction [INFO    ] Move file: 1-HB0185F0CIB0.xlsx to ERROR folder: Data\ERROR\1-HB0185F0CIB0.xlsx.
2023-11-27 21:39:48.483 - ETL_SICA88_TO_KLARF [INFO    ] Read Source File:0:00:00.085938
2023-11-27 21:39:48.486 - CustomFuction [ERROR   ] 'NO.'
Traceback (most recent call last):
  File "D:\Python37\lib\site-packages\pandas\core\indexes\base.py", line 2898, in get_loc
    return self._engine.get_loc(casted_key)
  File "pandas\_libs\index.pyx", line 70, in pandas._libs.index.IndexEngine.get_loc
  File "pandas\_libs\index.pyx", line 101, in pandas._libs.index.IndexEngine.get_loc
  File "pandas\_libs\hashtable_class_helper.pxi", line 1675, in pandas._libs.hashtable.PyObjectHashTable.get_item
  File "pandas\_libs\hashtable_class_helper.pxi", line 1683, in pandas._libs.hashtable.PyObjectHashTable.get_item
KeyError: 'NO.'

The above exception was the direct cause of the following exception:

Traceback (most recent call last):
  File "../..\XdmLib\CustomFuction.py", line 597, in file2db_init
    file, pre_params, db_src, db_tgt)
  File "D:/Ina/ETL_XdmLib_2.A.13/ETL_XdmLib_2.A.13/EDAETL/ETL_TABLE/ETL_XYN_XLSX_TO_KLARF/ETL_SICA88_TO_KLARF.py", line 45, in do_file
    row['NO.'],
  File "D:\Python37\lib\site-packages\pandas\core\series.py", line 882, in __getitem__
    return self._get_value(key)
  File "D:\Python37\lib\site-packages\pandas\core\series.py", line 990, in _get_value
    loc = self.index.get_loc(label)
  File "D:\Python37\lib\site-packages\pandas\core\indexes\base.py", line 2900, in get_loc
    raise KeyError(key) from err
KeyError: 'NO.'
Stack (most recent call last):
  File "D:/Ina/ETL_XdmLib_2.A.13/ETL_XdmLib_2.A.13/EDAETL/ETL_TABLE/ETL_XYN_XLSX_TO_KLARF/ETL_SICA88_TO_KLARF.py", line 117, in <module>
    do_file, before_do_file, after_do_file, skip_file, None, log, config, config_sql)
  File "../..\XdmLib\CustomFuction.py", line 631, in file2db_init
    log.error(ex, exc_info=True, stack_info=True)
2023-11-27 21:39:48.560 - CustomFuction [INFO    ] [ERROR] 1-HB0185F0CIB2.xls
2023-11-27 21:39:48.562 - CustomFuction [INFO    ] Move file: 1-HB0185F0CIB2.xls to ERROR folder: Data\ERROR\1-HB0185F0CIB2.xls.
2023-11-27 21:39:50.510 - ETL_SICA88_TO_KLARF [INFO    ] Read Source File:0:00:00.136407
2023-11-27 21:39:50.512 - CustomFuction [ERROR   ] 'NO.'
Traceback (most recent call last):
  File "D:\Python37\lib\site-packages\pandas\core\indexes\base.py", line 2898, in get_loc
    return self._engine.get_loc(casted_key)
  File "pandas\_libs\index.pyx", line 70, in pandas._libs.index.IndexEngine.get_loc
  File "pandas\_libs\index.pyx", line 101, in pandas._libs.index.IndexEngine.get_loc
  File "pandas\_libs\hashtable_class_helper.pxi", line 1675, in pandas._libs.hashtable.PyObjectHashTable.get_item
  File "pandas\_libs\hashtable_class_helper.pxi", line 1683, in pandas._libs.hashtable.PyObjectHashTable.get_item
KeyError: 'NO.'

The above exception was the direct cause of the following exception:

Traceback (most recent call last):
  File "../..\XdmLib\CustomFuction.py", line 597, in file2db_init
    file, pre_params, db_src, db_tgt)
  File "D:/Ina/ETL_XdmLib_2.A.13/ETL_XdmLib_2.A.13/EDAETL/ETL_TABLE/ETL_XYN_XLSX_TO_KLARF/ETL_SICA88_TO_KLARF.py", line 45, in do_file
    row['NO.'],
  File "D:\Python37\lib\site-packages\pandas\core\series.py", line 882, in __getitem__
    return self._get_value(key)
  File "D:\Python37\lib\site-packages\pandas\core\series.py", line 990, in _get_value
    loc = self.index.get_loc(label)
  File "D:\Python37\lib\site-packages\pandas\core\indexes\base.py", line 2900, in get_loc
    raise KeyError(key) from err
KeyError: 'NO.'
Stack (most recent call last):
  File "D:/Ina/ETL_XdmLib_2.A.13/ETL_XdmLib_2.A.13/EDAETL/ETL_TABLE/ETL_XYN_XLSX_TO_KLARF/ETL_SICA88_TO_KLARF.py", line 117, in <module>
    do_file, before_do_file, after_do_file, skip_file, None, log, config, config_sql)
  File "../..\XdmLib\CustomFuction.py", line 631, in file2db_init
    log.error(ex, exc_info=True, stack_info=True)
2023-11-27 21:39:50.546 - CustomFuction [INFO    ] [ERROR] 40-4N46-DF07016.xlsx
2023-11-27 21:39:50.548 - CustomFuction [INFO    ] Move file: 40-4N46-DF07016.xlsx to ERROR folder: Data\ERROR\40-4N46-DF07016.xlsx.
2023-11-27 21:39:51.787 - ETL_SICA88_TO_KLARF [INFO    ] Read Source File:0:00:00.010992
2023-11-27 21:39:51.791 - CustomFuction [ERROR   ] 'NO.'
Traceback (most recent call last):
  File "D:\Python37\lib\site-packages\pandas\core\indexes\base.py", line 2898, in get_loc
    return self._engine.get_loc(casted_key)
  File "pandas\_libs\index.pyx", line 70, in pandas._libs.index.IndexEngine.get_loc
  File "pandas\_libs\index.pyx", line 101, in pandas._libs.index.IndexEngine.get_loc
  File "pandas\_libs\hashtable_class_helper.pxi", line 1675, in pandas._libs.hashtable.PyObjectHashTable.get_item
  File "pandas\_libs\hashtable_class_helper.pxi", line 1683, in pandas._libs.hashtable.PyObjectHashTable.get_item
KeyError: 'NO.'

The above exception was the direct cause of the following exception:

Traceback (most recent call last):
  File "../..\XdmLib\CustomFuction.py", line 597, in file2db_init
    file, pre_params, db_src, db_tgt)
  File "D:/Ina/ETL_XdmLib_2.A.13/ETL_XdmLib_2.A.13/EDAETL/ETL_TABLE/ETL_XYN_XLSX_TO_KLARF/ETL_SICA88_TO_KLARF.py", line 45, in do_file
    row['NO.'],
  File "D:\Python37\lib\site-packages\pandas\core\series.py", line 882, in __getitem__
    return self._get_value(key)
  File "D:\Python37\lib\site-packages\pandas\core\series.py", line 990, in _get_value
    loc = self.index.get_loc(label)
  File "D:\Python37\lib\site-packages\pandas\core\indexes\base.py", line 2900, in get_loc
    raise KeyError(key) from err
KeyError: 'NO.'
Stack (most recent call last):
  File "D:/Ina/ETL_XdmLib_2.A.13/ETL_XdmLib_2.A.13/EDAETL/ETL_TABLE/ETL_XYN_XLSX_TO_KLARF/ETL_SICA88_TO_KLARF.py", line 117, in <module>
    do_file, before_do_file, after_do_file, skip_file, None, log, config, config_sql)
  File "../..\XdmLib\CustomFuction.py", line 631, in file2db_init
    log.error(ex, exc_info=True, stack_info=True)
2023-11-27 21:39:51.814 - CustomFuction [INFO    ] [ERROR] 5_HB07FYQ6CIB5.csv
2023-11-27 21:39:51.816 - CustomFuction [INFO    ] Move file: 5_HB07FYQ6CIB5.csv to ERROR folder: Data\ERROR\5_HB07FYQ6CIB5.csv.
2023-11-27 21:39:53.023 - CustomFuction [INFO    ] ========[ File End ]========
2023-11-27 21:39:53.024 - CustomFuction [INFO    ] ========[ Delete Empty Folder ]========
2023-11-27 21:39:53.247 - CustomFuction [INFO    ] ========== Finally ==========
2023-11-27 21:39:54.435 - __init__   [INFO    ] Set process status code: 5.
2023-11-27 21:41:29.552 - __init__   [INFO    ] # ===== [ XdmLib Ver. ] ===== #
2023-11-27 21:41:29.553 - __init__   [INFO    ] XdmLib Ver. 2.A.13
2023-11-27 21:41:29.553 - __init__   [INFO    ] # ===== [ XdmLib Ver. ] ===== #
2023-11-27 21:41:29.556 - __init__   [INFO    ] Console Quick Edit Disabled
2023-11-27 21:41:29.593 - __init__   [INFO    ] Server/Host Name: DESKTOP-J6AUF2I
2023-11-27 21:41:29.593 - __init__   [INFO    ] Archive setting non-setting, Archive files will be kept.
2023-11-27 21:41:29.594 - __init__   [INFO    ] Error setting non-setting, Error files will be kept.
2023-11-27 21:41:31.210 - __init__   [INFO    ] Server: DESKTOP-J6AUF2I, Status: 5, data_time_flg: None.
2023-11-27 21:41:31.697 - __init__   [INFO    ] Watching control file: D:\Ina\ETL_XdmLib_2.A.13\ETL_XdmLib_2.A.13\EDAETL\ETL_TABLE\ETL_XYN_XLSX_TO_KLARF\ETL_SICA88_TO_KLARF.py.*
2023-11-27 21:41:31.702 - __init__   [INFO    ] SetProcessStatus 0, Start time: 2023-11-27 21:41:29.527754
2023-11-27 21:41:32.967 - __init__   [INFO    ] Set process status code: 0.
2023-11-27 21:41:33.092 - Database   [INFO    ] Non set logging! Using default logging.
2023-11-27 21:41:33.630 - Database   [INFO    ] Non set logging! Using default logging.
2023-11-27 21:41:34.143 - Database   [INFO    ] Non set logging! Using default logging.
2023-11-27 21:41:35.936 - ETL_SICA88_TO_KLARF [INFO    ] Read Source File:0:00:01.304039
2023-11-27 21:41:35.997 - ETL_SICA88_TO_KLARF [INFO    ] Converter ./Data/Source\1-HB0185F0CIB0 to KLA-Tencor_None_HB0185F0CIB0_01_HB0185F0CIB0_2023-11-27-21-41-34.001 ;Total Used:0:00:01.365042
2023-11-27 21:41:36.018 - CustomFuction [INFO    ] [Archive] 1-HB0185F0CIB0.xlsx
2023-11-27 21:41:36.020 - CustomFuction [INFO    ] Move file: 1-HB0185F0CIB0.xlsx to Archive folder: Data\Archive\1-HB0185F0CIB0.xlsx.
2023-11-27 21:41:36.075 - ETL_SICA88_TO_KLARF [INFO    ] Read Source File:0:00:00.054613
2023-11-27 21:41:36.136 - ETL_SICA88_TO_KLARF [INFO    ] Converter ./Data/Source\1-HB0185F0CIB2 to KLA-Tencor_None_HB0185F0CIB2_01_HB0185F0CIB2_2023-11-27-21-41-36.001 ;Total Used:0:00:00.115662
2023-11-27 21:41:36.156 - CustomFuction [INFO    ] [Archive] 1-HB0185F0CIB2.xls
2023-11-27 21:41:36.157 - CustomFuction [INFO    ] Move file: 1-HB0185F0CIB2.xls to Archive folder: Data\Archive\1-HB0185F0CIB2.xls.
2023-11-27 21:41:36.239 - ETL_SICA88_TO_KLARF [INFO    ] Read Source File:0:00:00.080987
2023-11-27 21:41:36.245 - CustomFuction [ERROR   ] 'No.'
Traceback (most recent call last):
  File "D:\Python37\lib\site-packages\pandas\core\indexes\base.py", line 2898, in get_loc
    return self._engine.get_loc(casted_key)
  File "pandas\_libs\index.pyx", line 70, in pandas._libs.index.IndexEngine.get_loc
  File "pandas\_libs\index.pyx", line 101, in pandas._libs.index.IndexEngine.get_loc
  File "pandas\_libs\hashtable_class_helper.pxi", line 1675, in pandas._libs.hashtable.PyObjectHashTable.get_item
  File "pandas\_libs\hashtable_class_helper.pxi", line 1683, in pandas._libs.hashtable.PyObjectHashTable.get_item
KeyError: 'No.'

The above exception was the direct cause of the following exception:

Traceback (most recent call last):
  File "../..\XdmLib\CustomFuction.py", line 597, in file2db_init
    file, pre_params, db_src, db_tgt)
  File "D:/Ina/ETL_XdmLib_2.A.13/ETL_XdmLib_2.A.13/EDAETL/ETL_TABLE/ETL_XYN_XLSX_TO_KLARF/ETL_SICA88_TO_KLARF.py", line 45, in do_file
    row['No.'],
  File "D:\Python37\lib\site-packages\pandas\core\series.py", line 882, in __getitem__
    return self._get_value(key)
  File "D:\Python37\lib\site-packages\pandas\core\series.py", line 990, in _get_value
    loc = self.index.get_loc(label)
  File "D:\Python37\lib\site-packages\pandas\core\indexes\base.py", line 2900, in get_loc
    raise KeyError(key) from err
KeyError: 'No.'
Stack (most recent call last):
  File "D:/Ina/ETL_XdmLib_2.A.13/ETL_XdmLib_2.A.13/EDAETL/ETL_TABLE/ETL_XYN_XLSX_TO_KLARF/ETL_SICA88_TO_KLARF.py", line 117, in <module>
    do_file, before_do_file, after_do_file, skip_file, None, log, config, config_sql)
  File "../..\XdmLib\CustomFuction.py", line 631, in file2db_init
    log.error(ex, exc_info=True, stack_info=True)
2023-11-27 21:41:36.292 - CustomFuction [INFO    ] [ERROR] 40-4N46-DF07016.xlsx
2023-11-27 21:41:36.293 - CustomFuction [INFO    ] Move file: 40-4N46-DF07016.xlsx to ERROR folder: Data\ERROR\40-4N46-DF07016.xlsx.
2023-11-27 21:41:37.668 - ETL_SICA88_TO_KLARF [INFO    ] Read Source File:0:00:00.019005
2023-11-27 21:41:37.750 - ETL_SICA88_TO_KLARF [INFO    ] Converter ./Data/Source\5-HB07FYQ6CIB5 to KLA-Tencor_None_HB07FYQ6CIB5_01_HB07FYQ6CIB5_2023-11-27-21-41-37.001 ;Total Used:0:00:00.100680
2023-11-27 21:41:37.780 - CustomFuction [INFO    ] [Archive] 5_HB07FYQ6CIB5.csv
2023-11-27 21:41:37.784 - CustomFuction [INFO    ] Move file: 5_HB07FYQ6CIB5.csv to Archive folder: Data\Archive\5_HB07FYQ6CIB5.csv.
2023-11-27 21:41:37.785 - CustomFuction [INFO    ] ========[ File End ]========
2023-11-27 21:41:37.785 - CustomFuction [INFO    ] ========[ Delete Empty Folder ]========
2023-11-27 21:41:37.923 - CustomFuction [INFO    ] ========== Finally ==========
2023-11-27 21:41:39.100 - __init__   [INFO    ] Set process status code: 5.
2023-11-27 22:47:17.403 - __init__   [INFO    ] # ===== [ XdmLib Ver. ] ===== #
2023-11-27 22:47:17.404 - __init__   [INFO    ] XdmLib Ver. 2.A.13
2023-11-27 22:47:17.404 - __init__   [INFO    ] # ===== [ XdmLib Ver. ] ===== #
2023-11-27 22:47:17.405 - __init__   [INFO    ] Console Quick Edit Disabled
2023-11-27 22:47:17.419 - __init__   [INFO    ] Server/Host Name: DESKTOP-J6AUF2I
2023-11-27 22:47:17.419 - __init__   [INFO    ] Archive setting non-setting, Archive files will be kept.
2023-11-27 22:47:17.419 - __init__   [INFO    ] Error setting non-setting, Error files will be kept.
2023-11-27 22:47:38.848 - Database   [WARNING ] (cx_Oracle.DatabaseError) ORA-12170: TNS:Connect timeout occurred
(Background on this error at: http://sqlalche.me/e/13/4xp6)
2023-11-27 22:47:38.854 - __init__   [ERROR   ] Access XDM Loader control table fail.
2023-11-27 22:47:53.176 - __init__   [INFO    ] # ===== [ XdmLib Ver. ] ===== #
2023-11-27 22:47:53.177 - __init__   [INFO    ] XdmLib Ver. 2.A.13
2023-11-27 22:47:53.177 - __init__   [INFO    ] # ===== [ XdmLib Ver. ] ===== #
2023-11-27 22:47:53.178 - __init__   [INFO    ] Console Quick Edit Disabled
2023-11-27 22:47:53.191 - __init__   [INFO    ] Server/Host Name: DESKTOP-J6AUF2I
2023-11-27 22:47:53.191 - __init__   [INFO    ] Archive setting non-setting, Archive files will be kept.
2023-11-27 22:47:53.191 - __init__   [INFO    ] Error setting non-setting, Error files will be kept.
2023-11-27 22:47:54.465 - __init__   [INFO    ] Server: DESKTOP-J6AUF2I, Status: 5, data_time_flg: None.
2023-11-27 22:47:54.962 - __init__   [INFO    ] Watching control file: D:\Ina\ETL_XdmLib_2.A.13\ETL_XdmLib_2.A.13\EDAETL\ETL_TABLE\ETL_XYN_XLSX_TO_KLARF\ETL_SICA88_TO_KLARF.py.*
2023-11-27 22:47:54.964 - __init__   [INFO    ] SetProcessStatus 0, Start time: 2023-11-27 22:47:53.168759
2023-11-27 22:47:56.199 - __init__   [INFO    ] Set process status code: 0.
2023-11-27 22:47:56.310 - Database   [INFO    ] Non set logging! Using default logging.
2023-11-27 22:47:56.810 - Database   [INFO    ] Non set logging! Using default logging.
2023-11-27 22:47:57.276 - Database   [INFO    ] Non set logging! Using default logging.
2023-11-27 22:47:58.552 - ETL_SICA88_TO_KLARF [INFO    ] Read Source File:0:00:00.791993
2023-11-27 22:47:58.560 - CustomFuction [ERROR   ] 'Area(um2)'
Traceback (most recent call last):
  File "D:\Python37\lib\site-packages\pandas\core\indexes\base.py", line 2898, in get_loc
    return self._engine.get_loc(casted_key)
  File "pandas\_libs\index.pyx", line 70, in pandas._libs.index.IndexEngine.get_loc
  File "pandas\_libs\index.pyx", line 101, in pandas._libs.index.IndexEngine.get_loc
  File "pandas\_libs\hashtable_class_helper.pxi", line 1675, in pandas._libs.hashtable.PyObjectHashTable.get_item
  File "pandas\_libs\hashtable_class_helper.pxi", line 1683, in pandas._libs.hashtable.PyObjectHashTable.get_item
KeyError: 'Area(um2)'

The above exception was the direct cause of the following exception:

Traceback (most recent call last):
  File "../..\XdmLib\CustomFuction.py", line 597, in file2db_init
    file, pre_params, db_src, db_tgt)
  File "D:/Ina/ETL_XdmLib_2.A.13/ETL_XdmLib_2.A.13/EDAETL/ETL_TABLE/ETL_XYN_XLSX_TO_KLARF/ETL_SICA88_TO_KLARF.py", line 57, in do_file
    row['Area(um2)'],
  File "D:\Python37\lib\site-packages\pandas\core\series.py", line 882, in __getitem__
    return self._get_value(key)
  File "D:\Python37\lib\site-packages\pandas\core\series.py", line 990, in _get_value
    loc = self.index.get_loc(label)
  File "D:\Python37\lib\site-packages\pandas\core\indexes\base.py", line 2900, in get_loc
    raise KeyError(key) from err
KeyError: 'Area(um2)'
Stack (most recent call last):
  File "D:/Ina/ETL_XdmLib_2.A.13/ETL_XdmLib_2.A.13/EDAETL/ETL_TABLE/ETL_XYN_XLSX_TO_KLARF/ETL_SICA88_TO_KLARF.py", line 123, in <module>
    do_file, before_do_file, after_do_file, skip_file, None, log, config, config_sql)
  File "../..\XdmLib\CustomFuction.py", line 631, in file2db_init
    log.error(ex, exc_info=True, stack_info=True)
2023-11-27 22:47:58.614 - CustomFuction [INFO    ] [ERROR] 40-4N46-DF07016.xlsx
2023-11-27 22:47:58.614 - CustomFuction [INFO    ] Move file: 40-4N46-DF07016.xlsx to ERROR folder: Data\ERROR\40-4N46-DF07016.xlsx.
2023-11-27 22:47:59.741 - CustomFuction [INFO    ] ========[ File End ]========
2023-11-27 22:47:59.741 - CustomFuction [INFO    ] ========[ Delete Empty Folder ]========
2023-11-27 22:47:59.889 - CustomFuction [INFO    ] ========== Finally ==========
2023-11-27 22:48:00.950 - __init__   [INFO    ] Set process status code: 5.
2023-11-27 22:50:28.092 - __init__   [INFO    ] # ===== [ XdmLib Ver. ] ===== #
2023-11-27 22:50:28.093 - __init__   [INFO    ] XdmLib Ver. 2.A.13
2023-11-27 22:50:28.093 - __init__   [INFO    ] # ===== [ XdmLib Ver. ] ===== #
2023-11-27 22:50:28.095 - __init__   [INFO    ] Console Quick Edit Disabled
2023-11-27 22:50:28.109 - __init__   [INFO    ] Server/Host Name: DESKTOP-J6AUF2I
2023-11-27 22:50:28.109 - __init__   [INFO    ] Archive setting non-setting, Archive files will be kept.
2023-11-27 22:50:28.109 - __init__   [INFO    ] Error setting non-setting, Error files will be kept.
2023-11-27 22:50:29.204 - __init__   [INFO    ] Server: DESKTOP-J6AUF2I, Status: 5, data_time_flg: None.
2023-11-27 22:50:29.646 - __init__   [INFO    ] Watching control file: D:\Ina\ETL_XdmLib_2.A.13\ETL_XdmLib_2.A.13\EDAETL\ETL_TABLE\ETL_XYN_XLSX_TO_KLARF\ETL_SICA88_TO_KLARF.py.*
2023-11-27 22:50:29.652 - __init__   [INFO    ] SetProcessStatus 0, Start time: 2023-11-27 22:50:28.080119
2023-11-27 22:50:30.807 - __init__   [INFO    ] Set process status code: 0.
2023-11-27 22:50:30.909 - Database   [INFO    ] Non set logging! Using default logging.
2023-11-27 22:50:31.392 - Database   [INFO    ] Non set logging! Using default logging.
2023-11-27 22:50:31.885 - Database   [INFO    ] Non set logging! Using default logging.
2023-11-27 22:50:32.809 - ETL_SICA88_TO_KLARF [INFO    ] Read Source File:0:00:00.446211
2023-11-27 22:50:32.811 - CustomFuction [ERROR   ] 'Class'
Traceback (most recent call last):
  File "D:\Python37\lib\site-packages\pandas\core\indexes\base.py", line 2898, in get_loc
    return self._engine.get_loc(casted_key)
  File "pandas\_libs\index.pyx", line 70, in pandas._libs.index.IndexEngine.get_loc
  File "pandas\_libs\index.pyx", line 101, in pandas._libs.index.IndexEngine.get_loc
  File "pandas\_libs\hashtable_class_helper.pxi", line 1675, in pandas._libs.hashtable.PyObjectHashTable.get_item
  File "pandas\_libs\hashtable_class_helper.pxi", line 1683, in pandas._libs.hashtable.PyObjectHashTable.get_item
KeyError: 'Class'

The above exception was the direct cause of the following exception:

Traceback (most recent call last):
  File "../..\XdmLib\CustomFuction.py", line 597, in file2db_init
    file, pre_params, db_src, db_tgt)
  File "D:/Ina/ETL_XdmLib_2.A.13/ETL_XdmLib_2.A.13/EDAETL/ETL_TABLE/ETL_XYN_XLSX_TO_KLARF/ETL_SICA88_TO_KLARF.py", line 58, in do_file
    int(row['Class']),
  File "D:\Python37\lib\site-packages\pandas\core\series.py", line 882, in __getitem__
    return self._get_value(key)
  File "D:\Python37\lib\site-packages\pandas\core\series.py", line 990, in _get_value
    loc = self.index.get_loc(label)
  File "D:\Python37\lib\site-packages\pandas\core\indexes\base.py", line 2900, in get_loc
    raise KeyError(key) from err
KeyError: 'Class'
Stack (most recent call last):
  File "D:/Ina/ETL_XdmLib_2.A.13/ETL_XdmLib_2.A.13/EDAETL/ETL_TABLE/ETL_XYN_XLSX_TO_KLARF/ETL_SICA88_TO_KLARF.py", line 123, in <module>
    do_file, before_do_file, after_do_file, skip_file, None, log, config, config_sql)
  File "../..\XdmLib\CustomFuction.py", line 631, in file2db_init
    log.error(ex, exc_info=True, stack_info=True)
2023-11-27 22:50:32.832 - CustomFuction [INFO    ] [ERROR] 40-4N46-DF07016.xlsx
2023-11-27 22:50:32.833 - CustomFuction [INFO    ] Move file: 40-4N46-DF07016.xlsx to ERROR folder: Data\ERROR\40-4N46-DF07016.xlsx.
2023-11-27 22:50:33.935 - CustomFuction [INFO    ] ========[ File End ]========
2023-11-27 22:50:33.935 - CustomFuction [INFO    ] ========[ Delete Empty Folder ]========
2023-11-27 22:50:34.072 - CustomFuction [INFO    ] ========== Finally ==========
2023-11-27 22:50:35.117 - __init__   [INFO    ] Set process status code: 5.
2023-11-27 22:51:24.722 - __init__   [INFO    ] # ===== [ XdmLib Ver. ] ===== #
2023-11-27 22:51:24.723 - __init__   [INFO    ] XdmLib Ver. 2.A.13
2023-11-27 22:51:24.723 - __init__   [INFO    ] # ===== [ XdmLib Ver. ] ===== #
2023-11-27 22:51:24.724 - __init__   [INFO    ] Console Quick Edit Disabled
2023-11-27 22:51:24.737 - __init__   [INFO    ] Server/Host Name: DESKTOP-J6AUF2I
2023-11-27 22:51:24.737 - __init__   [INFO    ] Archive setting non-setting, Archive files will be kept.
2023-11-27 22:51:24.737 - __init__   [INFO    ] Error setting non-setting, Error files will be kept.
2023-11-27 22:51:25.850 - __init__   [INFO    ] Server: DESKTOP-J6AUF2I, Status: 5, data_time_flg: None.
2023-11-27 22:51:26.250 - __init__   [INFO    ] Watching control file: D:\Ina\ETL_XdmLib_2.A.13\ETL_XdmLib_2.A.13\EDAETL\ETL_TABLE\ETL_XYN_XLSX_TO_KLARF\ETL_SICA88_TO_KLARF.py.*
2023-11-27 22:51:26.252 - __init__   [INFO    ] SetProcessStatus 0, Start time: 2023-11-27 22:51:24.714464
2023-11-27 22:58:05.460 - __init__   [INFO    ] # ===== [ XdmLib Ver. ] ===== #
2023-11-27 22:58:05.461 - __init__   [INFO    ] XdmLib Ver. 2.A.13
2023-11-27 22:58:05.461 - __init__   [INFO    ] # ===== [ XdmLib Ver. ] ===== #
2023-11-27 22:58:05.462 - __init__   [INFO    ] Console Quick Edit Disabled
2023-11-27 22:58:05.476 - __init__   [INFO    ] Server/Host Name: DESKTOP-J6AUF2I
2023-11-27 22:58:05.477 - __init__   [INFO    ] Archive setting non-setting, Archive files will be kept.
2023-11-27 22:58:05.477 - __init__   [INFO    ] Error setting non-setting, Error files will be kept.
2023-11-27 22:58:06.745 - __init__   [INFO    ] Server: DESKTOP-J6AUF2I, Status: 0, data_time_flg: None.
2023-11-27 22:58:06.746 - __init__   [WARNING ] The loader duplicate execute(Set attribute: 'ALLOW_DUPLICATE_EXECUTE = False' disable it).
2023-11-27 22:58:07.164 - __init__   [INFO    ] Watching control file: D:\Ina\ETL_XdmLib_2.A.13\ETL_XdmLib_2.A.13\EDAETL\ETL_TABLE\ETL_XYN_XLSX_TO_KLARF\ETL_SICA88_TO_KLARF.py.*
2023-11-27 22:58:07.167 - __init__   [INFO    ] SetProcessStatus 0, Start time: 2023-11-27 22:58:05.449346
2023-11-27 22:58:08.381 - __init__   [INFO    ] Set process status code: 0.
2023-11-27 22:58:08.478 - Database   [INFO    ] Non set logging! Using default logging.
2023-11-27 22:58:08.921 - Database   [INFO    ] Non set logging! Using default logging.
2023-11-27 22:58:09.386 - Database   [INFO    ] Non set logging! Using default logging.
2023-11-27 22:58:10.400 - ETL_SICA88_TO_KLARF [INFO    ] Read Source File:0:00:00.551188
2023-11-27 22:58:10.407 - ETL_SICA88_TO_KLARF [INFO    ] Converter ./Data/Source\40-4N46-DF07016 to KLA-Tencor_None_None_01_None_2023-11-27-22-58-09.001 ;Total Used:0:00:00.558160
2023-11-27 22:58:10.426 - CustomFuction [INFO    ] [Archive] 40-4N46-DF07016.xlsx
2023-11-27 22:58:10.426 - CustomFuction [INFO    ] Move file: 40-4N46-DF07016.xlsx to Archive folder: Data\Archive\40-4N46-DF07016.xlsx.
2023-11-27 22:58:10.427 - CustomFuction [INFO    ] ========[ File End ]========
2023-11-27 22:58:10.427 - CustomFuction [INFO    ] ========[ Delete Empty Folder ]========
2023-11-27 22:58:10.539 - CustomFuction [INFO    ] ========== Finally ==========
2023-11-27 22:58:11.559 - __init__   [INFO    ] Set process status code: 1, Last data time: None.
2023-11-27 23:01:16.549 - __init__   [INFO    ] # ===== [ XdmLib Ver. ] ===== #
2023-11-27 23:01:16.549 - __init__   [INFO    ] XdmLib Ver. 2.A.13
2023-11-27 23:01:16.549 - __init__   [INFO    ] # ===== [ XdmLib Ver. ] ===== #
2023-11-27 23:01:16.551 - __init__   [INFO    ] Console Quick Edit Disabled
2023-11-27 23:01:16.563 - __init__   [INFO    ] Server/Host Name: DESKTOP-J6AUF2I
2023-11-27 23:01:16.564 - __init__   [INFO    ] Archive setting non-setting, Archive files will be kept.
2023-11-27 23:01:16.564 - __init__   [INFO    ] Error setting non-setting, Error files will be kept.
2023-11-27 23:01:17.679 - __init__   [INFO    ] Server: DESKTOP-J6AUF2I, Status: 1, data_time_flg: None.
2023-11-27 23:01:18.108 - __init__   [INFO    ] Watching control file: D:\Ina\ETL_XdmLib_2.A.13\ETL_XdmLib_2.A.13\EDAETL\ETL_TABLE\ETL_XYN_XLSX_TO_KLARF\ETL_SICA88_TO_KLARF.py.*
2023-11-27 23:01:18.113 - __init__   [INFO    ] SetProcessStatus 0, Start time: 2023-11-27 23:01:16.540966
2023-11-27 23:01:19.290 - __init__   [INFO    ] Set process status code: 0.
2023-11-27 23:01:19.414 - Database   [INFO    ] Non set logging! Using default logging.
2023-11-27 23:01:19.840 - Database   [INFO    ] Non set logging! Using default logging.
2023-11-27 23:01:20.297 - Database   [INFO    ] Non set logging! Using default logging.
2023-11-27 23:01:21.169 - ETL_SICA88_TO_KLARF [INFO    ] Read Source File:0:00:00.468002
2023-11-27 23:01:21.174 - ETL_SICA88_TO_KLARF [INFO    ] Converter ./Data/Source\40-4N46-DF07016 to KLA-Tencor_None_None_01_None_2023-11-27-23-01-20.001 ;Total Used:0:00:00.473001
2023-11-27 23:01:21.194 - CustomFuction [INFO    ] [Archive] 40-4N46-DF07016.xlsx
2023-11-27 23:01:21.195 - CustomFuction [INFO    ] Move file: 40-4N46-DF07016.xlsx to Archive folder: Data\Archive\40-4N46-DF07016.xlsx.
2023-11-27 23:01:21.195 - CustomFuction [INFO    ] ========[ File End ]========
2023-11-27 23:01:21.195 - CustomFuction [INFO    ] ========[ Delete Empty Folder ]========
2023-11-27 23:01:21.322 - CustomFuction [INFO    ] ========== Finally ==========
2023-11-27 23:01:22.281 - __init__   [INFO    ] Set process status code: 1, Last data time: None.
2023-11-27 23:04:26.904 - __init__   [INFO    ] # ===== [ XdmLib Ver. ] ===== #
2023-11-27 23:04:26.904 - __init__   [INFO    ] XdmLib Ver. 2.A.13
2023-11-27 23:04:26.904 - __init__   [INFO    ] # ===== [ XdmLib Ver. ] ===== #
2023-11-27 23:04:26.906 - __init__   [INFO    ] Console Quick Edit Disabled
2023-11-27 23:04:26.919 - __init__   [INFO    ] Server/Host Name: DESKTOP-J6AUF2I
2023-11-27 23:04:26.919 - __init__   [INFO    ] Archive setting non-setting, Archive files will be kept.
2023-11-27 23:04:26.919 - __init__   [INFO    ] Error setting non-setting, Error files will be kept.
2023-11-27 23:04:28.665 - __init__   [INFO    ] Server: DESKTOP-J6AUF2I, Status: 1, data_time_flg: None.
2023-11-27 23:04:29.514 - __init__   [INFO    ] Watching control file: D:\Ina\ETL_XdmLib_2.A.13\ETL_XdmLib_2.A.13\EDAETL\ETL_TABLE\ETL_XYN_XLSX_TO_KLARF\ETL_SICA88_TO_KLARF.py.*
2023-11-27 23:04:29.516 - __init__   [INFO    ] SetProcessStatus 0, Start time: 2023-11-27 23:04:26.896192
2023-11-27 23:04:31.117 - __init__   [INFO    ] Set process status code: 0.
2023-11-27 23:04:31.220 - Database   [INFO    ] Non set logging! Using default logging.
2023-11-27 23:04:31.654 - Database   [INFO    ] Non set logging! Using default logging.
2023-11-27 23:04:32.147 - Database   [INFO    ] Non set logging! Using default logging.
2023-11-27 23:04:33.291 - ETL_SICA88_TO_KLARF [INFO    ] Read Source File:0:00:00.734000
2023-11-27 23:04:33.296 - ETL_SICA88_TO_KLARF [INFO    ] Converter ./Data/Source\40-4N46-DF07016 to KLA-Tencor_None_4N46-DF07016_01_4N46-DF07016_2023-11-27-23-04-32.001 ;Total Used:0:00:00.738999
2023-11-27 23:04:33.318 - CustomFuction [INFO    ] [Archive] 40-4N46-DF07016.xlsx
2023-11-27 23:04:33.319 - CustomFuction [INFO    ] Move file: 40-4N46-DF07016.xlsx to Archive folder: Data\Archive\40-4N46-DF07016.xlsx.
2023-11-27 23:04:33.319 - CustomFuction [INFO    ] ========[ File End ]========
2023-11-27 23:04:33.320 - CustomFuction [INFO    ] ========[ Delete Empty Folder ]========
2023-11-27 23:04:33.468 - CustomFuction [INFO    ] ========== Finally ==========
2023-11-27 23:04:34.435 - __init__   [INFO    ] Set process status code: 1, Last data time: None.
2023-11-27 23:05:24.906 - __init__   [INFO    ] # ===== [ XdmLib Ver. ] ===== #
2023-11-27 23:05:24.906 - __init__   [INFO    ] XdmLib Ver. 2.A.13
2023-11-27 23:05:24.906 - __init__   [INFO    ] # ===== [ XdmLib Ver. ] ===== #
2023-11-27 23:05:24.907 - __init__   [INFO    ] Console Quick Edit Disabled
2023-11-27 23:05:24.918 - __init__   [INFO    ] Server/Host Name: DESKTOP-J6AUF2I
2023-11-27 23:05:24.919 - __init__   [INFO    ] Archive setting non-setting, Archive files will be kept.
2023-11-27 23:05:24.919 - __init__   [INFO    ] Error setting non-setting, Error files will be kept.
2023-11-27 23:05:26.056 - __init__   [INFO    ] Server: DESKTOP-J6AUF2I, Status: 1, data_time_flg: None.
2023-11-27 23:05:26.492 - __init__   [INFO    ] Watching control file: D:\Ina\ETL_XdmLib_2.A.13\ETL_XdmLib_2.A.13\EDAETL\ETL_TABLE\ETL_XYN_XLSX_TO_KLARF\ETL_SICA88_TO_KLARF.py.*
2023-11-27 23:05:26.495 - __init__   [INFO    ] SetProcessStatus 0, Start time: 2023-11-27 23:05:24.898597
2023-11-27 23:05:27.632 - __init__   [INFO    ] Set process status code: 0.
2023-11-27 23:05:27.742 - Database   [INFO    ] Non set logging! Using default logging.
2023-11-27 23:05:28.214 - Database   [INFO    ] Non set logging! Using default logging.
2023-11-27 23:05:28.644 - Database   [INFO    ] Non set logging! Using default logging.
2023-11-27 23:05:29.089 - CustomFuction [INFO    ] [Empty] Empty Folder : ./Data/Source
2023-11-27 23:05:29.090 - CustomFuction [INFO    ] ========[ File End ]========
2023-11-27 23:05:29.090 - CustomFuction [INFO    ] ========[ Delete Empty Folder ]========
2023-11-27 23:05:29.236 - CustomFuction [INFO    ] ========== Finally ==========
2023-11-27 23:05:30.322 - __init__   [INFO    ] Set process status code: 1, Last data time: None.
2023-11-27 23:05:48.693 - __init__   [INFO    ] # ===== [ XdmLib Ver. ] ===== #
2023-11-27 23:05:48.694 - __init__   [INFO    ] XdmLib Ver. 2.A.13
2023-11-27 23:05:48.694 - __init__   [INFO    ] # ===== [ XdmLib Ver. ] ===== #
2023-11-27 23:05:48.695 - __init__   [INFO    ] Console Quick Edit Disabled
2023-11-27 23:05:48.705 - __init__   [INFO    ] Server/Host Name: DESKTOP-J6AUF2I
2023-11-27 23:05:48.706 - __init__   [INFO    ] Archive setting non-setting, Archive files will be kept.
2023-11-27 23:05:48.706 - __init__   [INFO    ] Error setting non-setting, Error files will be kept.
2023-11-27 23:05:49.859 - __init__   [INFO    ] Server: DESKTOP-J6AUF2I, Status: 1, data_time_flg: None.
2023-11-27 23:05:50.316 - __init__   [INFO    ] Watching control file: D:\Ina\ETL_XdmLib_2.A.13\ETL_XdmLib_2.A.13\EDAETL\ETL_TABLE\ETL_XYN_XLSX_TO_KLARF\ETL_SICA88_TO_KLARF.py.*
2023-11-27 23:05:50.318 - __init__   [INFO    ] SetProcessStatus 0, Start time: 2023-11-27 23:05:48.676295
2023-11-27 23:05:51.517 - __init__   [INFO    ] Set process status code: 0.
2023-11-27 23:05:51.621 - Database   [INFO    ] Non set logging! Using default logging.
2023-11-27 23:05:52.068 - Database   [INFO    ] Non set logging! Using default logging.
2023-11-27 23:05:52.558 - Database   [INFO    ] Non set logging! Using default logging.
2023-11-27 23:05:53.501 - ETL_SICA88_TO_KLARF [INFO    ] Read Source File:0:00:00.443025
2023-11-27 23:05:53.506 - ETL_SICA88_TO_KLARF [INFO    ] Converter ./Data/Source\40-4N46-DF07016 to KLA-Tencor_None_4N46-DF07016_01_4N46-DF07016_2023-11-27-23-05-53.001 ;Total Used:0:00:00.448024
2023-11-27 23:05:53.524 - CustomFuction [INFO    ] [Archive] 40-4N46-DF07016.xlsx
2023-11-27 23:05:53.525 - CustomFuction [INFO    ] Move file: 40-4N46-DF07016.xlsx to Archive folder: Data\Archive\40-4N46-DF07016.xlsx.
2023-11-27 23:05:53.525 - CustomFuction [INFO    ] ========[ File End ]========
2023-11-27 23:05:53.525 - CustomFuction [INFO    ] ========[ Delete Empty Folder ]========
2023-11-27 23:05:53.655 - CustomFuction [INFO    ] ========== Finally ==========
2023-11-27 23:05:54.585 - __init__   [INFO    ] Set process status code: 1, Last data time: None.
2023-11-27 23:06:54.454 - __init__   [INFO    ] # ===== [ XdmLib Ver. ] ===== #
2023-11-27 23:06:54.454 - __init__   [INFO    ] XdmLib Ver. 2.A.13
2023-11-27 23:06:54.454 - __init__   [INFO    ] # ===== [ XdmLib Ver. ] ===== #
2023-11-27 23:06:54.455 - __init__   [INFO    ] Console Quick Edit Disabled
2023-11-27 23:06:54.466 - __init__   [INFO    ] Server/Host Name: DESKTOP-J6AUF2I
2023-11-27 23:06:54.466 - __init__   [INFO    ] Archive setting non-setting, Archive files will be kept.
2023-11-27 23:06:54.466 - __init__   [INFO    ] Error setting non-setting, Error files will be kept.
2023-11-27 23:06:55.604 - __init__   [INFO    ] Server: DESKTOP-J6AUF2I, Status: 1, data_time_flg: None.
2023-11-27 23:06:56.051 - __init__   [INFO    ] Watching control file: D:\Ina\ETL_XdmLib_2.A.13\ETL_XdmLib_2.A.13\EDAETL\ETL_TABLE\ETL_XYN_XLSX_TO_KLARF\ETL_SICA88_TO_KLARF.py.*
2023-11-27 23:06:56.054 - __init__   [INFO    ] SetProcessStatus 0, Start time: 2023-11-27 23:06:54.443538
2023-11-27 23:06:57.143 - __init__   [INFO    ] Set process status code: 0.
2023-11-27 23:06:57.259 - Database   [INFO    ] Non set logging! Using default logging.
2023-11-27 23:06:57.745 - Database   [INFO    ] Non set logging! Using default logging.
2023-11-27 23:06:58.215 - Database   [INFO    ] Non set logging! Using default logging.
2023-11-27 23:06:59.127 - ETL_SICA88_TO_KLARF [INFO    ] Read Source File:0:00:00.473326
2023-11-27 23:06:59.149 - ETL_SICA88_TO_KLARF [INFO    ] Converter ./Data/Source\1-HB0185F0CIB0 to KLA-Tencor_None_HB0185F0CIB0_01_HB0185F0CIB0_2023-11-27-23-06-58.001 ;Total Used:0:00:00.495314
2023-11-27 23:06:59.170 - CustomFuction [INFO    ] [Archive] 1-HB0185F0CIB0.xlsx
2023-11-27 23:06:59.170 - CustomFuction [INFO    ] Move file: 1-HB0185F0CIB0.xlsx to Archive folder: Data\Archive\1-HB0185F0CIB0.xlsx.
2023-11-27 23:06:59.240 - ETL_SICA88_TO_KLARF [INFO    ] Read Source File:0:00:00.069034
2023-11-27 23:06:59.261 - ETL_SICA88_TO_KLARF [INFO    ] Converter ./Data/Source\1-HB0185F0CIB2 to KLA-Tencor_None_HB0185F0CIB2_01_HB0185F0CIB2_2023-11-27-23-06-59.001 ;Total Used:0:00:00.090033
2023-11-27 23:06:59.279 - CustomFuction [INFO    ] [Archive] 1-HB0185F0CIB2.xls
2023-11-27 23:06:59.280 - CustomFuction [INFO    ] Move file: 1-HB0185F0CIB2.xls to Archive folder: Data\Archive\1-HB0185F0CIB2.xls.
2023-11-27 23:06:59.315 - ETL_SICA88_TO_KLARF [INFO    ] Read Source File:0:00:00.034984
2023-11-27 23:06:59.321 - ETL_SICA88_TO_KLARF [INFO    ] Converter ./Data/Source\40-4N46-DF07016 to KLA-Tencor_None_4N46-DF07016_01_4N46-DF07016_2023-11-27-23-06-59.001 ;Total Used:0:00:00.040984
2023-11-27 23:06:59.342 - CustomFuction [INFO    ] [Archive] 40-4N46-DF07016.xlsx
2023-11-27 23:06:59.343 - CustomFuction [INFO    ] Move file: 40-4N46-DF07016.xlsx to Archive folder: Data\Archive\40-4N46-DF07016.xlsx.
2023-11-27 23:06:59.353 - ETL_SICA88_TO_KLARF [INFO    ] Read Source File:0:00:00.010004
2023-11-27 23:06:59.365 - ETL_SICA88_TO_KLARF [INFO    ] Converter ./Data/Source\5-HB07FYQ6CIB5 to KLA-Tencor_None_HB07FYQ6CIB5_01_HB07FYQ6CIB5_2023-11-27-23-06-59.001 ;Total Used:0:00:00.022021
2023-11-27 23:06:59.385 - CustomFuction [INFO    ] [Archive] 5_HB07FYQ6CIB5.csv
2023-11-27 23:06:59.386 - CustomFuction [INFO    ] Move file: 5_HB07FYQ6CIB5.csv to Archive folder: Data\Archive\5_HB07FYQ6CIB5.csv.
2023-11-27 23:06:59.386 - CustomFuction [INFO    ] ========[ File End ]========
2023-11-27 23:06:59.387 - CustomFuction [INFO    ] ========[ Delete Empty Folder ]========
2023-11-27 23:06:59.515 - CustomFuction [INFO    ] ========== Finally ==========
2023-11-27 23:07:00.551 - __init__   [INFO    ] Set process status code: 1, Last data time: None.
2023-11-27 23:19:22.491 - __init__   [INFO    ] # ===== [ XdmLib Ver. ] ===== #
2023-11-27 23:19:22.492 - __init__   [INFO    ] XdmLib Ver. 2.A.13
2023-11-27 23:19:22.492 - __init__   [INFO    ] # ===== [ XdmLib Ver. ] ===== #
2023-11-27 23:19:22.493 - __init__   [INFO    ] Console Quick Edit Disabled
2023-11-27 23:19:22.506 - __init__   [INFO    ] Server/Host Name: DESKTOP-J6AUF2I
2023-11-27 23:19:22.506 - __init__   [INFO    ] Archive setting non-setting, Archive files will be kept.
2023-11-27 23:19:22.507 - __init__   [INFO    ] Error setting non-setting, Error files will be kept.
2023-11-27 23:19:23.578 - __init__   [INFO    ] Server: DESKTOP-J6AUF2I, Status: 1, data_time_flg: None.
2023-11-27 23:19:23.983 - __init__   [INFO    ] Watching control file: D:\Ina\ETL_XdmLib_2.A.13\ETL_XdmLib_2.A.13\EDAETL\ETL_TABLE\ETL_XYN_XLSX_TO_KLARF\ETL_SICA88_TO_KLARF.py.*
2023-11-27 23:19:23.986 - __init__   [INFO    ] SetProcessStatus 0, Start time: 2023-11-27 23:19:22.483402
2023-11-27 23:19:25.133 - __init__   [INFO    ] Set process status code: 0.
2023-11-27 23:19:25.233 - Database   [INFO    ] Non set logging! Using default logging.
2023-11-27 23:19:25.686 - Database   [INFO    ] Non set logging! Using default logging.
2023-11-27 23:19:26.138 - Database   [INFO    ] Non set logging! Using default logging.
2023-11-27 23:19:27.094 - ETL_SICA88_TO_KLARF [INFO    ] Read Source File:0:00:00.477965
2023-11-27 23:19:27.115 - ETL_SICA88_TO_KLARF [INFO    ] Converter ./Data/Source\1-HB0185F0CIB0 to KLA-Tencor_None_HB0185F0CIB0_01_HB0185F0CIB0_2023-11-27-23-19-26.001 ;Total Used:0:00:00.499006
2023-11-27 23:19:27.135 - CustomFuction [INFO    ] [Archive] 1-HB0185F0CIB0.xlsx
2023-11-27 23:19:27.136 - CustomFuction [INFO    ] Move file: 1-HB0185F0CIB0.xlsx to Archive folder: Data\Archive\1-HB0185F0CIB0.xlsx.
2023-11-27 23:19:27.156 - ETL_SICA88_TO_KLARF [INFO    ] Read Source File:0:00:00.019990
2023-11-27 23:19:27.178 - ETL_SICA88_TO_KLARF [INFO    ] Converter ./Data/Source\1-HB0185F0CIB2 to KLA-Tencor_None_HB0185F0CIB2_01_HB0185F0CIB2_2023-11-27-23-19-27.001 ;Total Used:0:00:00.041992
2023-11-27 23:19:27.196 - CustomFuction [INFO    ] [Archive] 1-HB0185F0CIB2.xls
2023-11-27 23:19:27.197 - CustomFuction [INFO    ] Move file: 1-HB0185F0CIB2.xls to Archive folder: Data\Archive\1-HB0185F0CIB2.xls.
2023-11-27 23:19:27.229 - ETL_SICA88_TO_KLARF [INFO    ] Read Source File:0:00:00.031990
2023-11-27 23:19:27.235 - ETL_SICA88_TO_KLARF [INFO    ] Converter ./Data/Source\40-4N46-DF07016 to KLA-Tencor_None_4N46-DF07016_01_4N46-DF07016_2023-11-27-23-19-27.001 ;Total Used:0:00:00.037965
2023-11-27 23:19:27.271 - CustomFuction [INFO    ] [Archive] 40-4N46-DF07016.xlsx
2023-11-27 23:19:27.272 - CustomFuction [INFO    ] Move file: 40-4N46-DF07016.xlsx to Archive folder: Data\Archive\40-4N46-DF07016.xlsx.
2023-11-27 23:19:27.275 - ETL_SICA88_TO_KLARF [INFO    ] Read Source File:0:00:00.003001
2023-11-27 23:19:27.287 - ETL_SICA88_TO_KLARF [INFO    ] Converter ./Data/Source\5-HB07FYQ6CIB5 to KLA-Tencor_None_HB07FYQ6CIB5_01_HB07FYQ6CIB5_2023-11-27-23-19-27.001 ;Total Used:0:00:00.014001
2023-11-27 23:19:27.305 - CustomFuction [INFO    ] [Archive] 5_HB07FYQ6CIB5.csv
2023-11-27 23:19:27.305 - CustomFuction [INFO    ] Move file: 5_HB07FYQ6CIB5.csv to Archive folder: Data\Archive\5_HB07FYQ6CIB5.csv.
2023-11-27 23:19:27.306 - CustomFuction [INFO    ] ========[ File End ]========
2023-11-27 23:19:27.306 - CustomFuction [INFO    ] ========[ Delete Empty Folder ]========
2023-11-27 23:19:27.419 - CustomFuction [INFO    ] ========== Finally ==========
2023-11-27 23:19:28.454 - __init__   [INFO    ] Set process status code: 1, Last data time: None.
2023-11-27 23:21:49.099 - __init__   [INFO    ] # ===== [ XdmLib Ver. ] ===== #
2023-11-27 23:21:49.099 - __init__   [INFO    ] XdmLib Ver. 2.A.13
2023-11-27 23:21:49.099 - __init__   [INFO    ] # ===== [ XdmLib Ver. ] ===== #
2023-11-27 23:21:49.100 - __init__   [INFO    ] Console Quick Edit Disabled
2023-11-27 23:21:49.116 - __init__   [INFO    ] Server/Host Name: DESKTOP-J6AUF2I
2023-11-27 23:21:49.116 - __init__   [INFO    ] Archive setting non-setting, Archive files will be kept.
2023-11-27 23:21:49.116 - __init__   [INFO    ] Error setting non-setting, Error files will be kept.
2023-11-27 23:21:50.225 - __init__   [INFO    ] Server: DESKTOP-J6AUF2I, Status: 1, data_time_flg: None.
2023-11-27 23:21:50.635 - __init__   [INFO    ] Watching control file: D:\Ina\ETL_XdmLib_2.A.13\ETL_XdmLib_2.A.13\EDAETL\ETL_TABLE\ETL_XYN_XLSX_TO_KLARF\ETL_SICA88_TO_KLARF.py.*
2023-11-27 23:21:50.636 - __init__   [INFO    ] SetProcessStatus 0, Start time: 2023-11-27 23:21:49.091992
2023-11-27 23:21:51.835 - __init__   [INFO    ] Set process status code: 0.
2023-11-27 23:21:51.941 - Database   [INFO    ] Non set logging! Using default logging.
2023-11-27 23:21:52.470 - Database   [INFO    ] Non set logging! Using default logging.
2023-11-27 23:21:52.886 - Database   [INFO    ] Non set logging! Using default logging.
2023-11-27 23:21:53.780 - ETL_SICA88_TO_KLARF [INFO    ] Read Source File:0:00:00.457957
2023-11-27 23:21:53.804 - ETL_SICA88_TO_KLARF [INFO    ] Converter ./Data/Source\1-HB0185F0CIB0 to KLA-Tencor_None_HB0185F0CIB0_01_HB0185F0CIB0_2023-11-27-23-21-53.001 ;Total Used:0:00:00.481954
2023-11-27 23:21:53.823 - CustomFuction [INFO    ] [Archive] 1-HB0185F0CIB0.xlsx
2023-11-27 23:21:53.823 - CustomFuction [INFO    ] Move file: 1-HB0185F0CIB0.xlsx to Archive folder: Data\Archive\1-HB0185F0CIB0.xlsx.
2023-11-27 23:21:53.842 - ETL_SICA88_TO_KLARF [INFO    ] Read Source File:0:00:00.017994
2023-11-27 23:21:53.864 - ETL_SICA88_TO_KLARF [INFO    ] Converter ./Data/Source\1-HB0185F0CIB2 to KLA-Tencor_None_HB0185F0CIB2_01_HB0185F0CIB2_2023-11-27-23-21-53.001 ;Total Used:0:00:00.040032
2023-11-27 23:21:53.883 - CustomFuction [INFO    ] [Archive] 1-HB0185F0CIB2.xls
2023-11-27 23:21:53.884 - CustomFuction [INFO    ] Move file: 1-HB0185F0CIB2.xls to Archive folder: Data\Archive\1-HB0185F0CIB2.xls.
2023-11-27 23:21:53.908 - ETL_SICA88_TO_KLARF [INFO    ] Read Source File:0:00:00.023991
2023-11-27 23:21:53.920 - ETL_SICA88_TO_KLARF [INFO    ] Converter ./Data/Source\4-HB0F3985CIC3 to KLA-Tencor_None_HB0F3985CIC3_01_HB0F3985CIC3_2023-11-27-23-21-53.001 ;Total Used:0:00:00.034988
2023-11-27 23:21:53.938 - CustomFuction [INFO    ] [Archive] 4-HB0F3985CIC3.xls
2023-11-27 23:21:53.938 - CustomFuction [INFO    ] Move file: 4-HB0F3985CIC3.xls to Archive folder: Data\Archive\4-HB0F3985CIC3.xls.
2023-11-27 23:21:53.974 - ETL_SICA88_TO_KLARF [INFO    ] Read Source File:0:00:00.034990
2023-11-27 23:21:53.979 - ETL_SICA88_TO_KLARF [INFO    ] Converter ./Data/Source\40-4N46-DF07016 to KLA-Tencor_None_4N46-DF07016_01_4N46-DF07016_2023-11-27-23-21-53.001 ;Total Used:0:00:00.039990
2023-11-27 23:21:53.998 - CustomFuction [INFO    ] [Archive] 40-4N46-DF07016.xlsx
2023-11-27 23:21:54.012 - CustomFuction [INFO    ] Move file: 40-4N46-DF07016.xlsx to Archive folder: Data\Archive\40-4N46-DF07016.xlsx.
2023-11-27 23:21:54.015 - ETL_SICA88_TO_KLARF [INFO    ] Read Source File:0:00:00.003012
2023-11-27 23:21:54.026 - ETL_SICA88_TO_KLARF [INFO    ] Converter ./Data/Source\5-HB07FYQ6CIB5 to KLA-Tencor_None_HB07FYQ6CIB5_01_HB07FYQ6CIB5_2023-11-27-23-21-54.001 ;Total Used:0:00:00.014012
2023-11-27 23:21:54.045 - CustomFuction [INFO    ] [Archive] 5_HB07FYQ6CIB5.csv
2023-11-27 23:21:54.046 - CustomFuction [INFO    ] Move file: 5_HB07FYQ6CIB5.csv to Archive folder: Data\Archive\5_HB07FYQ6CIB5.csv.
2023-11-27 23:21:54.046 - CustomFuction [INFO    ] ========[ File End ]========
2023-11-27 23:21:54.046 - CustomFuction [INFO    ] ========[ Delete Empty Folder ]========
2023-11-27 23:21:54.163 - CustomFuction [INFO    ] ========== Finally ==========
2023-11-27 23:21:55.224 - __init__   [INFO    ] Set process status code: 1, Last data time: None.
