2024-01-11 14:56:50.587 - __init__   [INFO    ] # ===== [ XdmLib Ver. ] ===== #
2024-01-11 14:56:50.588 - __init__   [INFO    ] XdmLib Ver. 2.A.13
2024-01-11 14:56:50.588 - __init__   [INFO    ] # ===== [ XdmLib Ver. ] ===== #
2024-01-11 14:56:50.589 - __init__   [INFO    ] Console Quick Edit Disabled
2024-01-11 14:56:50.602 - __init__   [INFO    ] Server/Host Name: DESKTOP-J6AUF2I
2024-01-11 14:56:50.602 - __init__   [INFO    ] Archive setting non-setting, Archive files will be kept.
2024-01-11 14:56:50.602 - __init__   [INFO    ] Error setting non-setting, Error files will be kept.
2024-01-11 14:56:50.908 - __init__   [INFO    ] Server: DESKTOP-J6AUF2I, Status: 1, data_time_flg: None.
2024-01-11 14:56:50.955 - __init__   [INFO    ] Watching control file: D:\Ina\ETL_XdmLib_2.A.13\ETL_XdmLib_2.A.13\EDAETL\ETL_TABLE\ETL_XYN_XLSX_TO_KLARF\ETL_SICA88_TO_KLARF.py.*
2024-01-11 14:56:50.966 - __init__   [INFO    ] SetProcessStatus 0, Start time: 2024-01-11 14:56:50.577760
2024-01-11 14:56:51.158 - __init__   [INFO    ] Set process status code: 0.
2024-01-11 14:56:51.169 - Database   [INFO    ] Non set logging! Using default logging.
2024-01-11 14:56:51.275 - Database   [INFO    ] Non set logging! Using default logging.
2024-01-11 14:56:51.356 - Database   [INFO    ] Non set logging! Using default logging.
2024-01-11 14:56:52.186 - ETL_SICA88_TO_KLARF [INFO    ] Read Source File:0:00:00.735510
2024-01-11 14:56:52.193 - ETL_SICA88_TO_KLARF [INFO    ] Converter ./Data/Source\1-T17601236105 to KLA-Tencor_None_T17601236105_01_T17601236105_2024-01-11-14-56-51.001 ;Total Used:0:00:00.741467
2024-01-11 14:56:52.194 - CustomFuction [INFO    ] [Archive] 1-T17601236105.xlsx
2024-01-11 14:56:52.195 - CustomFuction [INFO    ] Move file: 1-T17601236105.xlsx to Archive folder: Data\Archive\1-T17601236105.xlsx.
2024-01-11 14:56:52.255 - ETL_SICA88_TO_KLARF [INFO    ] Read Source File:0:00:00.059988
2024-01-11 14:56:52.260 - ETL_SICA88_TO_KLARF [INFO    ] Converter ./Data/Source\2-T06709236J25 to KLA-Tencor_None_T06709236J25_01_T06709236J25_2024-01-11-14-56-52.001 ;Total Used:0:00:00.065027
2024-01-11 14:56:52.261 - CustomFuction [INFO    ] [Archive] 2-T06709236J25.xls
2024-01-11 14:56:52.262 - CustomFuction [INFO    ] Move file: 2-T06709236J25.xls to Archive folder: Data\Archive\2-T06709236J25.xls.
2024-01-11 14:56:52.287 - ETL_SICA88_TO_KLARF [INFO    ] Read Source File:0:00:00.024997
2024-01-11 14:56:52.290 - CustomFuction [ERROR   ] 'NO.'
Traceback (most recent call last):
  File "D:\Python37\lib\site-packages\pandas\core\indexes\base.py", line 2898, in get_loc
    return self._engine.get_loc(casted_key)
  File "pandas\_libs\index.pyx", line 70, in pandas._libs.index.IndexEngine.get_loc
  File "pandas\_libs\index.pyx", line 101, in pandas._libs.index.IndexEngine.get_loc
  File "pandas\_libs\hashtable_class_helper.pxi", line 1675, in pandas._libs.hashtable.PyObjectHashTable.get_item
  File "pandas\_libs\hashtable_class_helper.pxi", line 1683, in pandas._libs.hashtable.PyObjectHashTable.get_item
KeyError: 'NO.'

The above exception was the direct cause of the following exception:

Traceback (most recent call last):
  File "../..\XdmLib\CustomFuction.py", line 597, in file2db_init
    file, pre_params, db_src, db_tgt)
  File "D:/Ina/ETL_XdmLib_2.A.13/ETL_XdmLib_2.A.13/EDAETL/ETL_TABLE/ETL_XYN_XLSX_TO_KLARF/ETL_SICA88_TO_KLARF.py", line 58, in do_file
    row['NO.'],
  File "D:\Python37\lib\site-packages\pandas\core\series.py", line 882, in __getitem__
    return self._get_value(key)
  File "D:\Python37\lib\site-packages\pandas\core\series.py", line 990, in _get_value
    loc = self.index.get_loc(label)
  File "D:\Python37\lib\site-packages\pandas\core\indexes\base.py", line 2900, in get_loc
    raise KeyError(key) from err
KeyError: 'NO.'
Stack (most recent call last):
  File "D:/Ina/ETL_XdmLib_2.A.13/ETL_XdmLib_2.A.13/EDAETL/ETL_TABLE/ETL_XYN_XLSX_TO_KLARF/ETL_SICA88_TO_KLARF.py", line 130, in <module>
    do_file, before_do_file, after_do_file, skip_file, None, log, config, config_sql)
  File "../..\XdmLib\CustomFuction.py", line 631, in file2db_init
    log.error(ex, exc_info=True, stack_info=True)
2024-01-11 14:56:52.311 - CustomFuction [INFO    ] [ERROR] 82-TKZ76DN316.xlsx
2024-01-11 14:56:52.312 - CustomFuction [INFO    ] Move file: 82-TKZ76DN316.xlsx to ERROR folder: Data\ERROR\82-TKZ76DN316.xlsx.
2024-01-11 14:56:52.575 - ETL_SICA88_TO_KLARF [INFO    ] Read Source File:0:00:00.032000
2024-01-11 14:56:52.576 - CustomFuction [ERROR   ] 'NO.'
Traceback (most recent call last):
  File "D:\Python37\lib\site-packages\pandas\core\indexes\base.py", line 2898, in get_loc
    return self._engine.get_loc(casted_key)
  File "pandas\_libs\index.pyx", line 70, in pandas._libs.index.IndexEngine.get_loc
  File "pandas\_libs\index.pyx", line 101, in pandas._libs.index.IndexEngine.get_loc
  File "pandas\_libs\hashtable_class_helper.pxi", line 1675, in pandas._libs.hashtable.PyObjectHashTable.get_item
  File "pandas\_libs\hashtable_class_helper.pxi", line 1683, in pandas._libs.hashtable.PyObjectHashTable.get_item
KeyError: 'NO.'

The above exception was the direct cause of the following exception:

Traceback (most recent call last):
  File "../..\XdmLib\CustomFuction.py", line 597, in file2db_init
    file, pre_params, db_src, db_tgt)
  File "D:/Ina/ETL_XdmLib_2.A.13/ETL_XdmLib_2.A.13/EDAETL/ETL_TABLE/ETL_XYN_XLSX_TO_KLARF/ETL_SICA88_TO_KLARF.py", line 58, in do_file
    row['NO.'],
  File "D:\Python37\lib\site-packages\pandas\core\series.py", line 882, in __getitem__
    return self._get_value(key)
  File "D:\Python37\lib\site-packages\pandas\core\series.py", line 990, in _get_value
    loc = self.index.get_loc(label)
  File "D:\Python37\lib\site-packages\pandas\core\indexes\base.py", line 2900, in get_loc
    raise KeyError(key) from err
KeyError: 'NO.'
Stack (most recent call last):
  File "D:/Ina/ETL_XdmLib_2.A.13/ETL_XdmLib_2.A.13/EDAETL/ETL_TABLE/ETL_XYN_XLSX_TO_KLARF/ETL_SICA88_TO_KLARF.py", line 130, in <module>
    do_file, before_do_file, after_do_file, skip_file, None, log, config, config_sql)
  File "../..\XdmLib\CustomFuction.py", line 631, in file2db_init
    log.error(ex, exc_info=True, stack_info=True)
2024-01-11 14:56:52.578 - CustomFuction [INFO    ] [ERROR] 83-TKZ76DN317.xlsx
2024-01-11 14:56:52.579 - CustomFuction [INFO    ] Move file: 83-TKZ76DN317.xlsx to ERROR folder: Data\ERROR\83-TKZ76DN317.xlsx.
2024-01-11 14:56:52.772 - CustomFuction [INFO    ] [Empty] Empty Folder : ./Data/Source\AT00057
2024-01-11 14:56:52.772 - CustomFuction [INFO    ] ========[ File End ]========
2024-01-11 14:56:52.772 - CustomFuction [INFO    ] ========[ Delete Empty Folder ]========
2024-01-11 14:56:52.773 - CustomFuction [INFO    ] [Delete] Delete Empty Folder : Data\Source\AT00057
2024-01-11 14:56:52.782 - CustomFuction [INFO    ] ========== Finally ==========
2024-01-11 14:56:52.925 - __init__   [INFO    ] Set process status code: 5.
2024-01-11 14:58:05.216 - __init__   [INFO    ] # ===== [ XdmLib Ver. ] ===== #
2024-01-11 14:58:05.216 - __init__   [INFO    ] XdmLib Ver. 2.A.13
2024-01-11 14:58:05.216 - __init__   [INFO    ] # ===== [ XdmLib Ver. ] ===== #
2024-01-11 14:58:05.218 - __init__   [INFO    ] Console Quick Edit Disabled
2024-01-11 14:58:05.228 - __init__   [INFO    ] Server/Host Name: DESKTOP-J6AUF2I
2024-01-11 14:58:05.228 - __init__   [INFO    ] Archive setting non-setting, Archive files will be kept.
2024-01-11 14:58:05.228 - __init__   [INFO    ] Error setting non-setting, Error files will be kept.
2024-01-11 14:58:05.533 - __init__   [INFO    ] Server: DESKTOP-J6AUF2I, Status: 5, data_time_flg: None.
2024-01-11 14:58:05.602 - __init__   [INFO    ] Watching control file: D:\Ina\ETL_XdmLib_2.A.13\ETL_XdmLib_2.A.13\EDAETL\ETL_TABLE\ETL_XYN_XLSX_TO_KLARF\ETL_SICA88_TO_KLARF.py.*
2024-01-11 14:58:05.605 - __init__   [INFO    ] SetProcessStatus 0, Start time: 2024-01-11 14:58:05.208531
2024-01-11 14:58:05.806 - __init__   [INFO    ] Set process status code: 0.
2024-01-11 14:58:05.817 - Database   [INFO    ] Non set logging! Using default logging.
2024-01-11 14:58:05.884 - Database   [INFO    ] Non set logging! Using default logging.
2024-01-11 14:58:05.970 - Database   [INFO    ] Non set logging! Using default logging.
2024-01-11 14:58:06.100 - ETL_SICA88_TO_KLARF [INFO    ] Read Source File:0:00:00.041135
2024-01-11 14:58:06.104 - CustomFuction [ERROR   ] 'N0.'
Traceback (most recent call last):
  File "D:\Python37\lib\site-packages\pandas\core\indexes\base.py", line 2898, in get_loc
    return self._engine.get_loc(casted_key)
  File "pandas\_libs\index.pyx", line 70, in pandas._libs.index.IndexEngine.get_loc
  File "pandas\_libs\index.pyx", line 101, in pandas._libs.index.IndexEngine.get_loc
  File "pandas\_libs\hashtable_class_helper.pxi", line 1675, in pandas._libs.hashtable.PyObjectHashTable.get_item
  File "pandas\_libs\hashtable_class_helper.pxi", line 1683, in pandas._libs.hashtable.PyObjectHashTable.get_item
KeyError: 'N0.'

The above exception was the direct cause of the following exception:

Traceback (most recent call last):
  File "../..\XdmLib\CustomFuction.py", line 597, in file2db_init
    file, pre_params, db_src, db_tgt)
  File "D:/Ina/ETL_XdmLib_2.A.13/ETL_XdmLib_2.A.13/EDAETL/ETL_TABLE/ETL_XYN_XLSX_TO_KLARF/ETL_SICA88_TO_KLARF.py", line 58, in do_file
    row['N0.'],
  File "D:\Python37\lib\site-packages\pandas\core\series.py", line 882, in __getitem__
    return self._get_value(key)
  File "D:\Python37\lib\site-packages\pandas\core\series.py", line 990, in _get_value
    loc = self.index.get_loc(label)
  File "D:\Python37\lib\site-packages\pandas\core\indexes\base.py", line 2900, in get_loc
    raise KeyError(key) from err
KeyError: 'N0.'
Stack (most recent call last):
  File "D:/Ina/ETL_XdmLib_2.A.13/ETL_XdmLib_2.A.13/EDAETL/ETL_TABLE/ETL_XYN_XLSX_TO_KLARF/ETL_SICA88_TO_KLARF.py", line 130, in <module>
    do_file, before_do_file, after_do_file, skip_file, None, log, config, config_sql)
  File "../..\XdmLib\CustomFuction.py", line 631, in file2db_init
    log.error(ex, exc_info=True, stack_info=True)
2024-01-11 14:58:06.111 - CustomFuction [INFO    ] [ERROR] 2-HB019RD5CID2.xls
2024-01-11 14:58:06.111 - CustomFuction [INFO    ] Move file: 2-HB019RD5CID2.xls to ERROR folder: Data\ERROR\2-HB019RD5CID2.xls.
2024-01-11 14:58:06.366 - ETL_SICA88_TO_KLARF [INFO    ] Read Source File:0:00:00.026170
2024-01-11 14:58:06.367 - CustomFuction [ERROR   ] 'N0.'
Traceback (most recent call last):
  File "D:\Python37\lib\site-packages\pandas\core\indexes\base.py", line 2898, in get_loc
    return self._engine.get_loc(casted_key)
  File "pandas\_libs\index.pyx", line 70, in pandas._libs.index.IndexEngine.get_loc
  File "pandas\_libs\index.pyx", line 101, in pandas._libs.index.IndexEngine.get_loc
  File "pandas\_libs\hashtable_class_helper.pxi", line 1675, in pandas._libs.hashtable.PyObjectHashTable.get_item
  File "pandas\_libs\hashtable_class_helper.pxi", line 1683, in pandas._libs.hashtable.PyObjectHashTable.get_item
KeyError: 'N0.'

The above exception was the direct cause of the following exception:

Traceback (most recent call last):
  File "../..\XdmLib\CustomFuction.py", line 597, in file2db_init
    file, pre_params, db_src, db_tgt)
  File "D:/Ina/ETL_XdmLib_2.A.13/ETL_XdmLib_2.A.13/EDAETL/ETL_TABLE/ETL_XYN_XLSX_TO_KLARF/ETL_SICA88_TO_KLARF.py", line 58, in do_file
    row['N0.'],
  File "D:\Python37\lib\site-packages\pandas\core\series.py", line 882, in __getitem__
    return self._get_value(key)
  File "D:\Python37\lib\site-packages\pandas\core\series.py", line 990, in _get_value
    loc = self.index.get_loc(label)
  File "D:\Python37\lib\site-packages\pandas\core\indexes\base.py", line 2900, in get_loc
    raise KeyError(key) from err
KeyError: 'N0.'
Stack (most recent call last):
  File "D:/Ina/ETL_XdmLib_2.A.13/ETL_XdmLib_2.A.13/EDAETL/ETL_TABLE/ETL_XYN_XLSX_TO_KLARF/ETL_SICA88_TO_KLARF.py", line 130, in <module>
    do_file, before_do_file, after_do_file, skip_file, None, log, config, config_sql)
  File "../..\XdmLib\CustomFuction.py", line 631, in file2db_init
    log.error(ex, exc_info=True, stack_info=True)
2024-01-11 14:58:06.371 - CustomFuction [INFO    ] [ERROR] 3-HB07F141CIC7.xls
2024-01-11 14:58:06.372 - CustomFuction [INFO    ] Move file: 3-HB07F141CIC7.xls to ERROR folder: Data\ERROR\3-HB07F141CIC7.xls.
2024-01-11 14:58:07.028 - ETL_SICA88_TO_KLARF [INFO    ] Read Source File:0:00:00.426374
2024-01-11 14:58:07.029 - CustomFuction [ERROR   ] 'AREA(UM2)'
Traceback (most recent call last):
  File "D:\Python37\lib\site-packages\pandas\core\indexes\base.py", line 2898, in get_loc
    return self._engine.get_loc(casted_key)
  File "pandas\_libs\index.pyx", line 70, in pandas._libs.index.IndexEngine.get_loc
  File "pandas\_libs\index.pyx", line 101, in pandas._libs.index.IndexEngine.get_loc
  File "pandas\_libs\hashtable_class_helper.pxi", line 1675, in pandas._libs.hashtable.PyObjectHashTable.get_item
  File "pandas\_libs\hashtable_class_helper.pxi", line 1683, in pandas._libs.hashtable.PyObjectHashTable.get_item
KeyError: 'AREA(UM2)'

The above exception was the direct cause of the following exception:

Traceback (most recent call last):
  File "../..\XdmLib\CustomFuction.py", line 597, in file2db_init
    file, pre_params, db_src, db_tgt)
  File "D:/Ina/ETL_XdmLib_2.A.13/ETL_XdmLib_2.A.13/EDAETL/ETL_TABLE/ETL_XYN_XLSX_TO_KLARF/ETL_SICA88_TO_KLARF.py", line 64, in do_file
    row['AREA(UM2)'],
  File "D:\Python37\lib\site-packages\pandas\core\series.py", line 882, in __getitem__
    return self._get_value(key)
  File "D:\Python37\lib\site-packages\pandas\core\series.py", line 990, in _get_value
    loc = self.index.get_loc(label)
  File "D:\Python37\lib\site-packages\pandas\core\indexes\base.py", line 2900, in get_loc
    raise KeyError(key) from err
KeyError: 'AREA(UM2)'
Stack (most recent call last):
  File "D:/Ina/ETL_XdmLib_2.A.13/ETL_XdmLib_2.A.13/EDAETL/ETL_TABLE/ETL_XYN_XLSX_TO_KLARF/ETL_SICA88_TO_KLARF.py", line 130, in <module>
    do_file, before_do_file, after_do_file, skip_file, None, log, config, config_sql)
  File "../..\XdmLib\CustomFuction.py", line 631, in file2db_init
    log.error(ex, exc_info=True, stack_info=True)
2024-01-11 14:58:07.031 - CustomFuction [INFO    ] [ERROR] 82-TKZ76DN316.xlsx
2024-01-11 14:58:07.032 - CustomFuction [INFO    ] Move file: 82-TKZ76DN316.xlsx to ERROR folder: Data\ERROR\82-TKZ76DN316.xlsx.
2024-01-11 14:58:07.279 - ETL_SICA88_TO_KLARF [INFO    ] Read Source File:0:00:00.037021
2024-01-11 14:58:07.280 - CustomFuction [ERROR   ] 'AREA(UM2)'
Traceback (most recent call last):
  File "D:\Python37\lib\site-packages\pandas\core\indexes\base.py", line 2898, in get_loc
    return self._engine.get_loc(casted_key)
  File "pandas\_libs\index.pyx", line 70, in pandas._libs.index.IndexEngine.get_loc
  File "pandas\_libs\index.pyx", line 101, in pandas._libs.index.IndexEngine.get_loc
  File "pandas\_libs\hashtable_class_helper.pxi", line 1675, in pandas._libs.hashtable.PyObjectHashTable.get_item
  File "pandas\_libs\hashtable_class_helper.pxi", line 1683, in pandas._libs.hashtable.PyObjectHashTable.get_item
KeyError: 'AREA(UM2)'

The above exception was the direct cause of the following exception:

Traceback (most recent call last):
  File "../..\XdmLib\CustomFuction.py", line 597, in file2db_init
    file, pre_params, db_src, db_tgt)
  File "D:/Ina/ETL_XdmLib_2.A.13/ETL_XdmLib_2.A.13/EDAETL/ETL_TABLE/ETL_XYN_XLSX_TO_KLARF/ETL_SICA88_TO_KLARF.py", line 64, in do_file
    row['AREA(UM2)'],
  File "D:\Python37\lib\site-packages\pandas\core\series.py", line 882, in __getitem__
    return self._get_value(key)
  File "D:\Python37\lib\site-packages\pandas\core\series.py", line 990, in _get_value
    loc = self.index.get_loc(label)
  File "D:\Python37\lib\site-packages\pandas\core\indexes\base.py", line 2900, in get_loc
    raise KeyError(key) from err
KeyError: 'AREA(UM2)'
Stack (most recent call last):
  File "D:/Ina/ETL_XdmLib_2.A.13/ETL_XdmLib_2.A.13/EDAETL/ETL_TABLE/ETL_XYN_XLSX_TO_KLARF/ETL_SICA88_TO_KLARF.py", line 130, in <module>
    do_file, before_do_file, after_do_file, skip_file, None, log, config, config_sql)
  File "../..\XdmLib\CustomFuction.py", line 631, in file2db_init
    log.error(ex, exc_info=True, stack_info=True)
2024-01-11 14:58:07.283 - CustomFuction [INFO    ] [ERROR] 83-TKZ76DN317.xlsx
2024-01-11 14:58:07.284 - CustomFuction [INFO    ] Move file: 83-TKZ76DN317.xlsx to ERROR folder: Data\ERROR\83-TKZ76DN317.xlsx.
2024-01-11 14:58:07.472 - CustomFuction [INFO    ] ========[ File End ]========
2024-01-11 14:58:07.472 - CustomFuction [INFO    ] ========[ Delete Empty Folder ]========
2024-01-11 14:58:07.483 - CustomFuction [INFO    ] ========== Finally ==========
2024-01-11 14:58:07.760 - __init__   [INFO    ] Set process status code: 5.
2024-01-11 15:00:27.434 - __init__   [INFO    ] # ===== [ XdmLib Ver. ] ===== #
2024-01-11 15:00:27.434 - __init__   [INFO    ] XdmLib Ver. 2.A.13
2024-01-11 15:00:27.434 - __init__   [INFO    ] # ===== [ XdmLib Ver. ] ===== #
2024-01-11 15:00:27.435 - __init__   [INFO    ] Console Quick Edit Disabled
2024-01-11 15:00:27.446 - __init__   [INFO    ] Server/Host Name: DESKTOP-J6AUF2I
2024-01-11 15:00:27.447 - __init__   [INFO    ] Archive setting non-setting, Archive files will be kept.
2024-01-11 15:00:27.447 - __init__   [INFO    ] Error setting non-setting, Error files will be kept.
2024-01-11 15:00:27.777 - __init__   [INFO    ] Server: DESKTOP-J6AUF2I, Status: 5, data_time_flg: None.
2024-01-11 15:00:27.828 - __init__   [INFO    ] Watching control file: D:\Ina\ETL_XdmLib_2.A.13\ETL_XdmLib_2.A.13\EDAETL\ETL_TABLE\ETL_XYN_XLSX_TO_KLARF\ETL_SICA88_TO_KLARF.py.*
2024-01-11 15:00:27.829 - __init__   [INFO    ] SetProcessStatus 0, Start time: 2024-01-11 15:00:27.427099
2024-01-11 15:00:28.016 - __init__   [INFO    ] Set process status code: 0.
2024-01-11 15:00:28.033 - Database   [INFO    ] Non set logging! Using default logging.
2024-01-11 15:00:28.147 - Database   [INFO    ] Non set logging! Using default logging.
2024-01-11 15:00:28.223 - Database   [INFO    ] Non set logging! Using default logging.
2024-01-11 15:00:28.348 - ETL_SICA88_TO_KLARF [INFO    ] Read Source File:0:00:00.039968
2024-01-11 15:00:28.351 - CustomFuction [ERROR   ] 'N0.'
Traceback (most recent call last):
  File "D:\Python37\lib\site-packages\pandas\core\indexes\base.py", line 2898, in get_loc
    return self._engine.get_loc(casted_key)
  File "pandas\_libs\index.pyx", line 70, in pandas._libs.index.IndexEngine.get_loc
  File "pandas\_libs\index.pyx", line 101, in pandas._libs.index.IndexEngine.get_loc
  File "pandas\_libs\hashtable_class_helper.pxi", line 1675, in pandas._libs.hashtable.PyObjectHashTable.get_item
  File "pandas\_libs\hashtable_class_helper.pxi", line 1683, in pandas._libs.hashtable.PyObjectHashTable.get_item
KeyError: 'N0.'

The above exception was the direct cause of the following exception:

Traceback (most recent call last):
  File "../..\XdmLib\CustomFuction.py", line 597, in file2db_init
    file, pre_params, db_src, db_tgt)
  File "D:/Ina/ETL_XdmLib_2.A.13/ETL_XdmLib_2.A.13/EDAETL/ETL_TABLE/ETL_XYN_XLSX_TO_KLARF/ETL_SICA88_TO_KLARF.py", line 58, in do_file
    row['N0.'],
  File "D:\Python37\lib\site-packages\pandas\core\series.py", line 882, in __getitem__
    return self._get_value(key)
  File "D:\Python37\lib\site-packages\pandas\core\series.py", line 990, in _get_value
    loc = self.index.get_loc(label)
  File "D:\Python37\lib\site-packages\pandas\core\indexes\base.py", line 2900, in get_loc
    raise KeyError(key) from err
KeyError: 'N0.'
Stack (most recent call last):
  File "D:/Ina/ETL_XdmLib_2.A.13/ETL_XdmLib_2.A.13/EDAETL/ETL_TABLE/ETL_XYN_XLSX_TO_KLARF/ETL_SICA88_TO_KLARF.py", line 130, in <module>
    do_file, before_do_file, after_do_file, skip_file, None, log, config, config_sql)
  File "../..\XdmLib\CustomFuction.py", line 631, in file2db_init
    log.error(ex, exc_info=True, stack_info=True)
2024-01-11 15:00:28.355 - CustomFuction [INFO    ] [ERROR] 2-HB019RD5CID2.xls
2024-01-11 15:00:28.356 - CustomFuction [INFO    ] Move file: 2-HB019RD5CID2.xls to ERROR folder: Data\ERROR\2-HB019RD5CID2.xls.
2024-01-11 15:00:28.602 - ETL_SICA88_TO_KLARF [INFO    ] Read Source File:0:00:00.011038
2024-01-11 15:00:28.603 - CustomFuction [ERROR   ] 'N0.'
Traceback (most recent call last):
  File "D:\Python37\lib\site-packages\pandas\core\indexes\base.py", line 2898, in get_loc
    return self._engine.get_loc(casted_key)
  File "pandas\_libs\index.pyx", line 70, in pandas._libs.index.IndexEngine.get_loc
  File "pandas\_libs\index.pyx", line 101, in pandas._libs.index.IndexEngine.get_loc
  File "pandas\_libs\hashtable_class_helper.pxi", line 1675, in pandas._libs.hashtable.PyObjectHashTable.get_item
  File "pandas\_libs\hashtable_class_helper.pxi", line 1683, in pandas._libs.hashtable.PyObjectHashTable.get_item
KeyError: 'N0.'

The above exception was the direct cause of the following exception:

Traceback (most recent call last):
  File "../..\XdmLib\CustomFuction.py", line 597, in file2db_init
    file, pre_params, db_src, db_tgt)
  File "D:/Ina/ETL_XdmLib_2.A.13/ETL_XdmLib_2.A.13/EDAETL/ETL_TABLE/ETL_XYN_XLSX_TO_KLARF/ETL_SICA88_TO_KLARF.py", line 58, in do_file
    row['N0.'],
  File "D:\Python37\lib\site-packages\pandas\core\series.py", line 882, in __getitem__
    return self._get_value(key)
  File "D:\Python37\lib\site-packages\pandas\core\series.py", line 990, in _get_value
    loc = self.index.get_loc(label)
  File "D:\Python37\lib\site-packages\pandas\core\indexes\base.py", line 2900, in get_loc
    raise KeyError(key) from err
KeyError: 'N0.'
Stack (most recent call last):
  File "D:/Ina/ETL_XdmLib_2.A.13/ETL_XdmLib_2.A.13/EDAETL/ETL_TABLE/ETL_XYN_XLSX_TO_KLARF/ETL_SICA88_TO_KLARF.py", line 130, in <module>
    do_file, before_do_file, after_do_file, skip_file, None, log, config, config_sql)
  File "../..\XdmLib\CustomFuction.py", line 631, in file2db_init
    log.error(ex, exc_info=True, stack_info=True)
2024-01-11 15:00:28.606 - CustomFuction [INFO    ] [ERROR] 3-HB07F141CIC7.xls
2024-01-11 15:00:28.606 - CustomFuction [INFO    ] Move file: 3-HB07F141CIC7.xls to ERROR folder: Data\ERROR\3-HB07F141CIC7.xls.
2024-01-11 15:00:29.197 - ETL_SICA88_TO_KLARF [INFO    ] Read Source File:0:00:00.395013
2024-01-11 15:00:29.198 - CustomFuction [ERROR   ] 'AREA(UM2)'
Traceback (most recent call last):
  File "D:\Python37\lib\site-packages\pandas\core\indexes\base.py", line 2898, in get_loc
    return self._engine.get_loc(casted_key)
  File "pandas\_libs\index.pyx", line 70, in pandas._libs.index.IndexEngine.get_loc
  File "pandas\_libs\index.pyx", line 101, in pandas._libs.index.IndexEngine.get_loc
  File "pandas\_libs\hashtable_class_helper.pxi", line 1675, in pandas._libs.hashtable.PyObjectHashTable.get_item
  File "pandas\_libs\hashtable_class_helper.pxi", line 1683, in pandas._libs.hashtable.PyObjectHashTable.get_item
KeyError: 'AREA(UM2)'

The above exception was the direct cause of the following exception:

Traceback (most recent call last):
  File "../..\XdmLib\CustomFuction.py", line 597, in file2db_init
    file, pre_params, db_src, db_tgt)
  File "D:/Ina/ETL_XdmLib_2.A.13/ETL_XdmLib_2.A.13/EDAETL/ETL_TABLE/ETL_XYN_XLSX_TO_KLARF/ETL_SICA88_TO_KLARF.py", line 64, in do_file
    row['AREA(UM2)'],
  File "D:\Python37\lib\site-packages\pandas\core\series.py", line 882, in __getitem__
    return self._get_value(key)
  File "D:\Python37\lib\site-packages\pandas\core\series.py", line 990, in _get_value
    loc = self.index.get_loc(label)
  File "D:\Python37\lib\site-packages\pandas\core\indexes\base.py", line 2900, in get_loc
    raise KeyError(key) from err
KeyError: 'AREA(UM2)'
Stack (most recent call last):
  File "D:/Ina/ETL_XdmLib_2.A.13/ETL_XdmLib_2.A.13/EDAETL/ETL_TABLE/ETL_XYN_XLSX_TO_KLARF/ETL_SICA88_TO_KLARF.py", line 130, in <module>
    do_file, before_do_file, after_do_file, skip_file, None, log, config, config_sql)
  File "../..\XdmLib\CustomFuction.py", line 631, in file2db_init
    log.error(ex, exc_info=True, stack_info=True)
2024-01-11 15:00:29.201 - CustomFuction [INFO    ] [ERROR] 82-TKZ76DN316.xlsx
2024-01-11 15:00:29.203 - CustomFuction [INFO    ] Move file: 82-TKZ76DN316.xlsx to ERROR folder: Data\ERROR\82-TKZ76DN316.xlsx.
2024-01-11 15:00:29.426 - ETL_SICA88_TO_KLARF [INFO    ] Read Source File:0:00:00.047979
2024-01-11 15:00:29.427 - CustomFuction [ERROR   ] 'AREA(UM2)'
Traceback (most recent call last):
  File "D:\Python37\lib\site-packages\pandas\core\indexes\base.py", line 2898, in get_loc
    return self._engine.get_loc(casted_key)
  File "pandas\_libs\index.pyx", line 70, in pandas._libs.index.IndexEngine.get_loc
  File "pandas\_libs\index.pyx", line 101, in pandas._libs.index.IndexEngine.get_loc
  File "pandas\_libs\hashtable_class_helper.pxi", line 1675, in pandas._libs.hashtable.PyObjectHashTable.get_item
  File "pandas\_libs\hashtable_class_helper.pxi", line 1683, in pandas._libs.hashtable.PyObjectHashTable.get_item
KeyError: 'AREA(UM2)'

The above exception was the direct cause of the following exception:

Traceback (most recent call last):
  File "../..\XdmLib\CustomFuction.py", line 597, in file2db_init
    file, pre_params, db_src, db_tgt)
  File "D:/Ina/ETL_XdmLib_2.A.13/ETL_XdmLib_2.A.13/EDAETL/ETL_TABLE/ETL_XYN_XLSX_TO_KLARF/ETL_SICA88_TO_KLARF.py", line 64, in do_file
    row['AREA(UM2)'],
  File "D:\Python37\lib\site-packages\pandas\core\series.py", line 882, in __getitem__
    return self._get_value(key)
  File "D:\Python37\lib\site-packages\pandas\core\series.py", line 990, in _get_value
    loc = self.index.get_loc(label)
  File "D:\Python37\lib\site-packages\pandas\core\indexes\base.py", line 2900, in get_loc
    raise KeyError(key) from err
KeyError: 'AREA(UM2)'
Stack (most recent call last):
  File "D:/Ina/ETL_XdmLib_2.A.13/ETL_XdmLib_2.A.13/EDAETL/ETL_TABLE/ETL_XYN_XLSX_TO_KLARF/ETL_SICA88_TO_KLARF.py", line 130, in <module>
    do_file, before_do_file, after_do_file, skip_file, None, log, config, config_sql)
  File "../..\XdmLib\CustomFuction.py", line 631, in file2db_init
    log.error(ex, exc_info=True, stack_info=True)
2024-01-11 15:00:29.430 - CustomFuction [INFO    ] [ERROR] 83-TKZ76DN317.xlsx
2024-01-11 15:00:29.431 - CustomFuction [INFO    ] Move file: 83-TKZ76DN317.xlsx to ERROR folder: Data\ERROR\83-TKZ76DN317.xlsx.
2024-01-11 15:00:29.584 - CustomFuction [INFO    ] ========[ File End ]========
2024-01-11 15:00:29.584 - CustomFuction [INFO    ] ========[ Delete Empty Folder ]========
2024-01-11 15:00:29.593 - CustomFuction [INFO    ] ========== Finally ==========
2024-01-11 15:00:29.814 - __init__   [INFO    ] Set process status code: 5.
2024-01-11 15:15:32.232 - __init__   [INFO    ] # ===== [ XdmLib Ver. ] ===== #
2024-01-11 15:15:32.233 - __init__   [INFO    ] XdmLib Ver. 2.A.13
2024-01-11 15:15:32.233 - __init__   [INFO    ] # ===== [ XdmLib Ver. ] ===== #
2024-01-11 15:15:32.234 - __init__   [INFO    ] Console Quick Edit Disabled
2024-01-11 15:15:32.246 - __init__   [INFO    ] Server/Host Name: DESKTOP-J6AUF2I
2024-01-11 15:15:32.246 - __init__   [INFO    ] Archive setting non-setting, Archive files will be kept.
2024-01-11 15:15:32.246 - __init__   [INFO    ] Error setting non-setting, Error files will be kept.
2024-01-11 15:15:32.514 - __init__   [INFO    ] Server: DESKTOP-J6AUF2I, Status: 5, data_time_flg: None.
2024-01-11 15:15:32.560 - __init__   [INFO    ] Watching control file: D:\Ina\ETL_XdmLib_2.A.13\ETL_XdmLib_2.A.13\EDAETL\ETL_TABLE\ETL_XYN_XLSX_TO_KLARF\ETL_SICA88_TO_KLARF.py.*
2024-01-11 15:15:32.562 - __init__   [INFO    ] SetProcessStatus 0, Start time: 2024-01-11 15:15:32.225536
2024-01-11 15:15:32.821 - __init__   [INFO    ] Set process status code: 0.
2024-01-11 15:15:32.836 - Database   [INFO    ] Non set logging! Using default logging.
2024-01-11 15:15:32.911 - Database   [INFO    ] Non set logging! Using default logging.
2024-01-11 15:15:33.001 - Database   [INFO    ] Non set logging! Using default logging.
2024-01-11 15:15:33.120 - ETL_SICA88_TO_KLARF [INFO    ] Read Source File:0:00:00.038993
2024-01-11 15:15:33.123 - CustomFuction [ERROR   ] 'N0.'
Traceback (most recent call last):
  File "D:\Python37\lib\site-packages\pandas\core\indexes\base.py", line 2898, in get_loc
    return self._engine.get_loc(casted_key)
  File "pandas\_libs\index.pyx", line 70, in pandas._libs.index.IndexEngine.get_loc
  File "pandas\_libs\index.pyx", line 101, in pandas._libs.index.IndexEngine.get_loc
  File "pandas\_libs\hashtable_class_helper.pxi", line 1675, in pandas._libs.hashtable.PyObjectHashTable.get_item
  File "pandas\_libs\hashtable_class_helper.pxi", line 1683, in pandas._libs.hashtable.PyObjectHashTable.get_item
KeyError: 'N0.'

The above exception was the direct cause of the following exception:

Traceback (most recent call last):
  File "../..\XdmLib\CustomFuction.py", line 597, in file2db_init
    file, pre_params, db_src, db_tgt)
  File "D:/Ina/ETL_XdmLib_2.A.13/ETL_XdmLib_2.A.13/EDAETL/ETL_TABLE/ETL_XYN_XLSX_TO_KLARF/ETL_SICA88_TO_KLARF.py", line 59, in do_file
    row['N0.'],
  File "D:\Python37\lib\site-packages\pandas\core\series.py", line 882, in __getitem__
    return self._get_value(key)
  File "D:\Python37\lib\site-packages\pandas\core\series.py", line 990, in _get_value
    loc = self.index.get_loc(label)
  File "D:\Python37\lib\site-packages\pandas\core\indexes\base.py", line 2900, in get_loc
    raise KeyError(key) from err
KeyError: 'N0.'
Stack (most recent call last):
  File "D:/Ina/ETL_XdmLib_2.A.13/ETL_XdmLib_2.A.13/EDAETL/ETL_TABLE/ETL_XYN_XLSX_TO_KLARF/ETL_SICA88_TO_KLARF.py", line 131, in <module>
    do_file, before_do_file, after_do_file, skip_file, None, log, config, config_sql)
  File "../..\XdmLib\CustomFuction.py", line 631, in file2db_init
    log.error(ex, exc_info=True, stack_info=True)
2024-01-11 15:15:33.131 - CustomFuction [INFO    ] [ERROR] 2-HB019RD5CID2.xls
2024-01-11 15:15:33.131 - CustomFuction [INFO    ] Move file: 2-HB019RD5CID2.xls to ERROR folder: Data\ERROR\2-HB019RD5CID2.xls.
2024-01-11 15:15:33.344 - ETL_SICA88_TO_KLARF [INFO    ] Read Source File:0:00:00.018983
2024-01-11 15:15:33.345 - CustomFuction [ERROR   ] 'N0.'
Traceback (most recent call last):
  File "D:\Python37\lib\site-packages\pandas\core\indexes\base.py", line 2898, in get_loc
    return self._engine.get_loc(casted_key)
  File "pandas\_libs\index.pyx", line 70, in pandas._libs.index.IndexEngine.get_loc
  File "pandas\_libs\index.pyx", line 101, in pandas._libs.index.IndexEngine.get_loc
  File "pandas\_libs\hashtable_class_helper.pxi", line 1675, in pandas._libs.hashtable.PyObjectHashTable.get_item
  File "pandas\_libs\hashtable_class_helper.pxi", line 1683, in pandas._libs.hashtable.PyObjectHashTable.get_item
KeyError: 'N0.'

The above exception was the direct cause of the following exception:

Traceback (most recent call last):
  File "../..\XdmLib\CustomFuction.py", line 597, in file2db_init
    file, pre_params, db_src, db_tgt)
  File "D:/Ina/ETL_XdmLib_2.A.13/ETL_XdmLib_2.A.13/EDAETL/ETL_TABLE/ETL_XYN_XLSX_TO_KLARF/ETL_SICA88_TO_KLARF.py", line 59, in do_file
    row['N0.'],
  File "D:\Python37\lib\site-packages\pandas\core\series.py", line 882, in __getitem__
    return self._get_value(key)
  File "D:\Python37\lib\site-packages\pandas\core\series.py", line 990, in _get_value
    loc = self.index.get_loc(label)
  File "D:\Python37\lib\site-packages\pandas\core\indexes\base.py", line 2900, in get_loc
    raise KeyError(key) from err
KeyError: 'N0.'
Stack (most recent call last):
  File "D:/Ina/ETL_XdmLib_2.A.13/ETL_XdmLib_2.A.13/EDAETL/ETL_TABLE/ETL_XYN_XLSX_TO_KLARF/ETL_SICA88_TO_KLARF.py", line 131, in <module>
    do_file, before_do_file, after_do_file, skip_file, None, log, config, config_sql)
  File "../..\XdmLib\CustomFuction.py", line 631, in file2db_init
    log.error(ex, exc_info=True, stack_info=True)
2024-01-11 15:15:33.348 - CustomFuction [INFO    ] [ERROR] 3-HB07F141CIC7.xls
2024-01-11 15:15:33.348 - CustomFuction [INFO    ] Move file: 3-HB07F141CIC7.xls to ERROR folder: Data\ERROR\3-HB07F141CIC7.xls.
2024-01-11 15:15:34.044 - ETL_SICA88_TO_KLARF [INFO    ] Read Source File:0:00:00.477278
2024-01-11 15:15:34.045 - CustomFuction [ERROR   ] 'AREA(UM2)'
Traceback (most recent call last):
  File "D:\Python37\lib\site-packages\pandas\core\indexes\base.py", line 2898, in get_loc
    return self._engine.get_loc(casted_key)
  File "pandas\_libs\index.pyx", line 70, in pandas._libs.index.IndexEngine.get_loc
  File "pandas\_libs\index.pyx", line 101, in pandas._libs.index.IndexEngine.get_loc
  File "pandas\_libs\hashtable_class_helper.pxi", line 1675, in pandas._libs.hashtable.PyObjectHashTable.get_item
  File "pandas\_libs\hashtable_class_helper.pxi", line 1683, in pandas._libs.hashtable.PyObjectHashTable.get_item
KeyError: 'AREA(UM2)'

The above exception was the direct cause of the following exception:

Traceback (most recent call last):
  File "../..\XdmLib\CustomFuction.py", line 597, in file2db_init
    file, pre_params, db_src, db_tgt)
  File "D:/Ina/ETL_XdmLib_2.A.13/ETL_XdmLib_2.A.13/EDAETL/ETL_TABLE/ETL_XYN_XLSX_TO_KLARF/ETL_SICA88_TO_KLARF.py", line 65, in do_file
    row['AREA(UM2)'],
  File "D:\Python37\lib\site-packages\pandas\core\series.py", line 882, in __getitem__
    return self._get_value(key)
  File "D:\Python37\lib\site-packages\pandas\core\series.py", line 990, in _get_value
    loc = self.index.get_loc(label)
  File "D:\Python37\lib\site-packages\pandas\core\indexes\base.py", line 2900, in get_loc
    raise KeyError(key) from err
KeyError: 'AREA(UM2)'
Stack (most recent call last):
  File "D:/Ina/ETL_XdmLib_2.A.13/ETL_XdmLib_2.A.13/EDAETL/ETL_TABLE/ETL_XYN_XLSX_TO_KLARF/ETL_SICA88_TO_KLARF.py", line 131, in <module>
    do_file, before_do_file, after_do_file, skip_file, None, log, config, config_sql)
  File "../..\XdmLib\CustomFuction.py", line 631, in file2db_init
    log.error(ex, exc_info=True, stack_info=True)
2024-01-11 15:15:34.047 - CustomFuction [INFO    ] [ERROR] 82-TKZ76DN316.xlsx
2024-01-11 15:15:34.048 - CustomFuction [INFO    ] Move file: 82-TKZ76DN316.xlsx to ERROR folder: Data\ERROR\82-TKZ76DN316.xlsx.
2024-01-11 15:15:34.256 - ETL_SICA88_TO_KLARF [INFO    ] Read Source File:0:00:00.029000
2024-01-11 15:15:34.257 - CustomFuction [ERROR   ] 'AREA(UM2)'
Traceback (most recent call last):
  File "D:\Python37\lib\site-packages\pandas\core\indexes\base.py", line 2898, in get_loc
    return self._engine.get_loc(casted_key)
  File "pandas\_libs\index.pyx", line 70, in pandas._libs.index.IndexEngine.get_loc
  File "pandas\_libs\index.pyx", line 101, in pandas._libs.index.IndexEngine.get_loc
  File "pandas\_libs\hashtable_class_helper.pxi", line 1675, in pandas._libs.hashtable.PyObjectHashTable.get_item
  File "pandas\_libs\hashtable_class_helper.pxi", line 1683, in pandas._libs.hashtable.PyObjectHashTable.get_item
KeyError: 'AREA(UM2)'

The above exception was the direct cause of the following exception:

Traceback (most recent call last):
  File "../..\XdmLib\CustomFuction.py", line 597, in file2db_init
    file, pre_params, db_src, db_tgt)
  File "D:/Ina/ETL_XdmLib_2.A.13/ETL_XdmLib_2.A.13/EDAETL/ETL_TABLE/ETL_XYN_XLSX_TO_KLARF/ETL_SICA88_TO_KLARF.py", line 65, in do_file
    row['AREA(UM2)'],
  File "D:\Python37\lib\site-packages\pandas\core\series.py", line 882, in __getitem__
    return self._get_value(key)
  File "D:\Python37\lib\site-packages\pandas\core\series.py", line 990, in _get_value
    loc = self.index.get_loc(label)
  File "D:\Python37\lib\site-packages\pandas\core\indexes\base.py", line 2900, in get_loc
    raise KeyError(key) from err
KeyError: 'AREA(UM2)'
Stack (most recent call last):
  File "D:/Ina/ETL_XdmLib_2.A.13/ETL_XdmLib_2.A.13/EDAETL/ETL_TABLE/ETL_XYN_XLSX_TO_KLARF/ETL_SICA88_TO_KLARF.py", line 131, in <module>
    do_file, before_do_file, after_do_file, skip_file, None, log, config, config_sql)
  File "../..\XdmLib\CustomFuction.py", line 631, in file2db_init
    log.error(ex, exc_info=True, stack_info=True)
2024-01-11 15:15:34.259 - CustomFuction [INFO    ] [ERROR] 83-TKZ76DN317.xlsx
2024-01-11 15:15:34.261 - CustomFuction [INFO    ] Move file: 83-TKZ76DN317.xlsx to ERROR folder: Data\ERROR\83-TKZ76DN317.xlsx.
2024-01-11 15:15:34.457 - CustomFuction [INFO    ] ========[ File End ]========
2024-01-11 15:15:34.458 - CustomFuction [INFO    ] ========[ Delete Empty Folder ]========
2024-01-11 15:15:34.475 - CustomFuction [INFO    ] ========== Finally ==========
2024-01-11 15:15:34.693 - __init__   [INFO    ] Set process status code: 5.
2024-01-11 15:19:12.622 - __init__   [INFO    ] # ===== [ XdmLib Ver. ] ===== #
2024-01-11 15:19:12.623 - __init__   [INFO    ] XdmLib Ver. 2.A.13
2024-01-11 15:19:12.623 - __init__   [INFO    ] # ===== [ XdmLib Ver. ] ===== #
2024-01-11 15:19:12.624 - __init__   [INFO    ] Console Quick Edit Disabled
2024-01-11 15:19:12.639 - __init__   [INFO    ] Server/Host Name: DESKTOP-J6AUF2I
2024-01-11 15:19:12.639 - __init__   [INFO    ] Archive setting non-setting, Archive files will be kept.
2024-01-11 15:19:12.639 - __init__   [INFO    ] Error setting non-setting, Error files will be kept.
2024-01-11 15:19:12.900 - __init__   [INFO    ] Server: DESKTOP-J6AUF2I, Status: 5, data_time_flg: None.
2024-01-11 15:19:12.949 - __init__   [INFO    ] Watching control file: D:\Ina\ETL_XdmLib_2.A.13\ETL_XdmLib_2.A.13\EDAETL\ETL_TABLE\ETL_XYN_XLSX_TO_KLARF\ETL_SICA88_TO_KLARF.py.*
2024-01-11 15:19:12.950 - __init__   [INFO    ] SetProcessStatus 0, Start time: 2024-01-11 15:19:12.614393
2024-01-11 15:19:13.152 - __init__   [INFO    ] Set process status code: 0.
2024-01-11 15:19:13.161 - Database   [INFO    ] Non set logging! Using default logging.
2024-01-11 15:19:13.259 - Database   [INFO    ] Non set logging! Using default logging.
2024-01-11 15:19:13.401 - Database   [INFO    ] Non set logging! Using default logging.
2024-01-11 15:19:13.512 - ETL_SICA88_TO_KLARF [INFO    ] Read Source File:0:00:00.028996
2024-01-11 15:19:13.515 - CustomFuction [ERROR   ] 'N0.'
Traceback (most recent call last):
  File "D:\Python37\lib\site-packages\pandas\core\indexes\base.py", line 2898, in get_loc
    return self._engine.get_loc(casted_key)
  File "pandas\_libs\index.pyx", line 70, in pandas._libs.index.IndexEngine.get_loc
  File "pandas\_libs\index.pyx", line 101, in pandas._libs.index.IndexEngine.get_loc
  File "pandas\_libs\hashtable_class_helper.pxi", line 1675, in pandas._libs.hashtable.PyObjectHashTable.get_item
  File "pandas\_libs\hashtable_class_helper.pxi", line 1683, in pandas._libs.hashtable.PyObjectHashTable.get_item
KeyError: 'N0.'

The above exception was the direct cause of the following exception:

Traceback (most recent call last):
  File "../..\XdmLib\CustomFuction.py", line 597, in file2db_init
    file, pre_params, db_src, db_tgt)
  File "D:/Ina/ETL_XdmLib_2.A.13/ETL_XdmLib_2.A.13/EDAETL/ETL_TABLE/ETL_XYN_XLSX_TO_KLARF/ETL_SICA88_TO_KLARF.py", line 59, in do_file
    row['N0.'],
  File "D:\Python37\lib\site-packages\pandas\core\series.py", line 882, in __getitem__
    return self._get_value(key)
  File "D:\Python37\lib\site-packages\pandas\core\series.py", line 990, in _get_value
    loc = self.index.get_loc(label)
  File "D:\Python37\lib\site-packages\pandas\core\indexes\base.py", line 2900, in get_loc
    raise KeyError(key) from err
KeyError: 'N0.'
Stack (most recent call last):
  File "D:/Ina/ETL_XdmLib_2.A.13/ETL_XdmLib_2.A.13/EDAETL/ETL_TABLE/ETL_XYN_XLSX_TO_KLARF/ETL_SICA88_TO_KLARF.py", line 131, in <module>
    do_file, before_do_file, after_do_file, skip_file, None, log, config, config_sql)
  File "../..\XdmLib\CustomFuction.py", line 631, in file2db_init
    log.error(ex, exc_info=True, stack_info=True)
2024-01-11 15:19:13.524 - CustomFuction [INFO    ] [ERROR] 2-HB019RD5CID2.xls
2024-01-11 15:19:13.525 - CustomFuction [INFO    ] Move file: 2-HB019RD5CID2.xls to ERROR folder: Data\Source\2-HB019RD5CID2.xls.
2024-01-11 15:19:13.720 - CustomFuction [INFO    ] ========[ File End ]========
2024-01-11 15:19:13.721 - CustomFuction [INFO    ] ========[ Delete Empty Folder ]========
2024-01-11 15:19:13.731 - CustomFuction [INFO    ] ========== Finally ==========
2024-01-11 15:19:13.932 - __init__   [INFO    ] Set process status code: 5.
2024-01-11 15:19:56.497 - __init__   [INFO    ] # ===== [ XdmLib Ver. ] ===== #
2024-01-11 15:19:56.497 - __init__   [INFO    ] XdmLib Ver. 2.A.13
2024-01-11 15:19:56.497 - __init__   [INFO    ] # ===== [ XdmLib Ver. ] ===== #
2024-01-11 15:19:56.498 - __init__   [INFO    ] Console Quick Edit Disabled
2024-01-11 15:19:56.510 - __init__   [INFO    ] Server/Host Name: DESKTOP-J6AUF2I
2024-01-11 15:19:56.510 - __init__   [INFO    ] Archive setting non-setting, Archive files will be kept.
2024-01-11 15:19:56.510 - __init__   [INFO    ] Error setting non-setting, Error files will be kept.
2024-01-11 15:19:56.803 - __init__   [INFO    ] Server: DESKTOP-J6AUF2I, Status: 5, data_time_flg: None.
2024-01-11 15:19:56.860 - __init__   [INFO    ] Watching control file: D:\Ina\ETL_XdmLib_2.A.13\ETL_XdmLib_2.A.13\EDAETL\ETL_TABLE\ETL_XYN_XLSX_TO_KLARF\ETL_SICA88_TO_KLARF.py.*
2024-01-11 15:19:56.861 - __init__   [INFO    ] SetProcessStatus 0, Start time: 2024-01-11 15:19:56.489899
2024-01-11 15:19:57.043 - __init__   [INFO    ] Set process status code: 0.
2024-01-11 15:19:57.050 - Database   [INFO    ] Non set logging! Using default logging.
2024-01-11 15:19:57.126 - Database   [INFO    ] Non set logging! Using default logging.
2024-01-11 15:19:57.194 - Database   [INFO    ] Non set logging! Using default logging.
2024-01-11 15:19:57.300 - ETL_SICA88_TO_KLARF [INFO    ] Read Source File:0:00:00.029954
2024-01-11 15:19:57.303 - CustomFuction [ERROR   ] 'N0.'
Traceback (most recent call last):
  File "D:\Python37\lib\site-packages\pandas\core\indexes\base.py", line 2898, in get_loc
    return self._engine.get_loc(casted_key)
  File "pandas\_libs\index.pyx", line 70, in pandas._libs.index.IndexEngine.get_loc
  File "pandas\_libs\index.pyx", line 101, in pandas._libs.index.IndexEngine.get_loc
  File "pandas\_libs\hashtable_class_helper.pxi", line 1675, in pandas._libs.hashtable.PyObjectHashTable.get_item
  File "pandas\_libs\hashtable_class_helper.pxi", line 1683, in pandas._libs.hashtable.PyObjectHashTable.get_item
KeyError: 'N0.'

The above exception was the direct cause of the following exception:

Traceback (most recent call last):
  File "../..\XdmLib\CustomFuction.py", line 597, in file2db_init
    file, pre_params, db_src, db_tgt)
  File "D:/Ina/ETL_XdmLib_2.A.13/ETL_XdmLib_2.A.13/EDAETL/ETL_TABLE/ETL_XYN_XLSX_TO_KLARF/ETL_SICA88_TO_KLARF.py", line 59, in do_file
    row['N0.'],
  File "D:\Python37\lib\site-packages\pandas\core\series.py", line 882, in __getitem__
    return self._get_value(key)
  File "D:\Python37\lib\site-packages\pandas\core\series.py", line 990, in _get_value
    loc = self.index.get_loc(label)
  File "D:\Python37\lib\site-packages\pandas\core\indexes\base.py", line 2900, in get_loc
    raise KeyError(key) from err
KeyError: 'N0.'
Stack (most recent call last):
  File "D:/Ina/ETL_XdmLib_2.A.13/ETL_XdmLib_2.A.13/EDAETL/ETL_TABLE/ETL_XYN_XLSX_TO_KLARF/ETL_SICA88_TO_KLARF.py", line 132, in <module>
    do_file, before_do_file, after_do_file, skip_file, None, log, config, config_sql)
  File "../..\XdmLib\CustomFuction.py", line 631, in file2db_init
    log.error(ex, exc_info=True, stack_info=True)
2024-01-11 15:19:57.310 - CustomFuction [INFO    ] [ERROR] 2-HB019RD5CID2.xls
2024-01-11 15:19:57.311 - CustomFuction [INFO    ] Move file: 2-HB019RD5CID2.xls to ERROR folder: Data\Source\2-HB019RD5CID2.xls.
2024-01-11 15:19:57.544 - ETL_SICA88_TO_KLARF [INFO    ] Read Source File:0:00:00.010002
2024-01-11 15:19:57.545 - CustomFuction [ERROR   ] 'N0.'
Traceback (most recent call last):
  File "D:\Python37\lib\site-packages\pandas\core\indexes\base.py", line 2898, in get_loc
    return self._engine.get_loc(casted_key)
  File "pandas\_libs\index.pyx", line 70, in pandas._libs.index.IndexEngine.get_loc
  File "pandas\_libs\index.pyx", line 101, in pandas._libs.index.IndexEngine.get_loc
  File "pandas\_libs\hashtable_class_helper.pxi", line 1675, in pandas._libs.hashtable.PyObjectHashTable.get_item
  File "pandas\_libs\hashtable_class_helper.pxi", line 1683, in pandas._libs.hashtable.PyObjectHashTable.get_item
KeyError: 'N0.'

The above exception was the direct cause of the following exception:

Traceback (most recent call last):
  File "../..\XdmLib\CustomFuction.py", line 597, in file2db_init
    file, pre_params, db_src, db_tgt)
  File "D:/Ina/ETL_XdmLib_2.A.13/ETL_XdmLib_2.A.13/EDAETL/ETL_TABLE/ETL_XYN_XLSX_TO_KLARF/ETL_SICA88_TO_KLARF.py", line 59, in do_file
    row['N0.'],
  File "D:\Python37\lib\site-packages\pandas\core\series.py", line 882, in __getitem__
    return self._get_value(key)
  File "D:\Python37\lib\site-packages\pandas\core\series.py", line 990, in _get_value
    loc = self.index.get_loc(label)
  File "D:\Python37\lib\site-packages\pandas\core\indexes\base.py", line 2900, in get_loc
    raise KeyError(key) from err
KeyError: 'N0.'
Stack (most recent call last):
  File "D:/Ina/ETL_XdmLib_2.A.13/ETL_XdmLib_2.A.13/EDAETL/ETL_TABLE/ETL_XYN_XLSX_TO_KLARF/ETL_SICA88_TO_KLARF.py", line 132, in <module>
    do_file, before_do_file, after_do_file, skip_file, None, log, config, config_sql)
  File "../..\XdmLib\CustomFuction.py", line 631, in file2db_init
    log.error(ex, exc_info=True, stack_info=True)
2024-01-11 15:19:57.548 - CustomFuction [INFO    ] [ERROR] 3-HB07F141CIC7.xls
2024-01-11 15:19:57.548 - CustomFuction [INFO    ] Move file: 3-HB07F141CIC7.xls to ERROR folder: Data\Source\3-HB07F141CIC7.xls.
2024-01-11 15:19:58.171 - ETL_SICA88_TO_KLARF [INFO    ] Read Source File:0:00:00.417049
2024-01-11 15:19:58.172 - CustomFuction [ERROR   ] 'AREA(UM2)'
Traceback (most recent call last):
  File "D:\Python37\lib\site-packages\pandas\core\indexes\base.py", line 2898, in get_loc
    return self._engine.get_loc(casted_key)
  File "pandas\_libs\index.pyx", line 70, in pandas._libs.index.IndexEngine.get_loc
  File "pandas\_libs\index.pyx", line 101, in pandas._libs.index.IndexEngine.get_loc
  File "pandas\_libs\hashtable_class_helper.pxi", line 1675, in pandas._libs.hashtable.PyObjectHashTable.get_item
  File "pandas\_libs\hashtable_class_helper.pxi", line 1683, in pandas._libs.hashtable.PyObjectHashTable.get_item
KeyError: 'AREA(UM2)'

The above exception was the direct cause of the following exception:

Traceback (most recent call last):
  File "../..\XdmLib\CustomFuction.py", line 597, in file2db_init
    file, pre_params, db_src, db_tgt)
  File "D:/Ina/ETL_XdmLib_2.A.13/ETL_XdmLib_2.A.13/EDAETL/ETL_TABLE/ETL_XYN_XLSX_TO_KLARF/ETL_SICA88_TO_KLARF.py", line 66, in do_file
    row['AREA(UM2)'],
  File "D:\Python37\lib\site-packages\pandas\core\series.py", line 882, in __getitem__
    return self._get_value(key)
  File "D:\Python37\lib\site-packages\pandas\core\series.py", line 990, in _get_value
    loc = self.index.get_loc(label)
  File "D:\Python37\lib\site-packages\pandas\core\indexes\base.py", line 2900, in get_loc
    raise KeyError(key) from err
KeyError: 'AREA(UM2)'
Stack (most recent call last):
  File "D:/Ina/ETL_XdmLib_2.A.13/ETL_XdmLib_2.A.13/EDAETL/ETL_TABLE/ETL_XYN_XLSX_TO_KLARF/ETL_SICA88_TO_KLARF.py", line 132, in <module>
    do_file, before_do_file, after_do_file, skip_file, None, log, config, config_sql)
  File "../..\XdmLib\CustomFuction.py", line 631, in file2db_init
    log.error(ex, exc_info=True, stack_info=True)
2024-01-11 15:19:58.177 - CustomFuction [INFO    ] [ERROR] 82-TKZ76DN316.xlsx
2024-01-11 15:19:58.178 - CustomFuction [INFO    ] Move file: 82-TKZ76DN316.xlsx to ERROR folder: Data\Source\82-TKZ76DN316.xlsx.
2024-01-11 15:19:58.412 - ETL_SICA88_TO_KLARF [INFO    ] Read Source File:0:00:00.031003
2024-01-11 15:19:58.413 - CustomFuction [ERROR   ] 'AREA(UM2)'
Traceback (most recent call last):
  File "D:\Python37\lib\site-packages\pandas\core\indexes\base.py", line 2898, in get_loc
    return self._engine.get_loc(casted_key)
  File "pandas\_libs\index.pyx", line 70, in pandas._libs.index.IndexEngine.get_loc
  File "pandas\_libs\index.pyx", line 101, in pandas._libs.index.IndexEngine.get_loc
  File "pandas\_libs\hashtable_class_helper.pxi", line 1675, in pandas._libs.hashtable.PyObjectHashTable.get_item
  File "pandas\_libs\hashtable_class_helper.pxi", line 1683, in pandas._libs.hashtable.PyObjectHashTable.get_item
KeyError: 'AREA(UM2)'

The above exception was the direct cause of the following exception:

Traceback (most recent call last):
  File "../..\XdmLib\CustomFuction.py", line 597, in file2db_init
    file, pre_params, db_src, db_tgt)
  File "D:/Ina/ETL_XdmLib_2.A.13/ETL_XdmLib_2.A.13/EDAETL/ETL_TABLE/ETL_XYN_XLSX_TO_KLARF/ETL_SICA88_TO_KLARF.py", line 66, in do_file
    row['AREA(UM2)'],
  File "D:\Python37\lib\site-packages\pandas\core\series.py", line 882, in __getitem__
    return self._get_value(key)
  File "D:\Python37\lib\site-packages\pandas\core\series.py", line 990, in _get_value
    loc = self.index.get_loc(label)
  File "D:\Python37\lib\site-packages\pandas\core\indexes\base.py", line 2900, in get_loc
    raise KeyError(key) from err
KeyError: 'AREA(UM2)'
Stack (most recent call last):
  File "D:/Ina/ETL_XdmLib_2.A.13/ETL_XdmLib_2.A.13/EDAETL/ETL_TABLE/ETL_XYN_XLSX_TO_KLARF/ETL_SICA88_TO_KLARF.py", line 132, in <module>
    do_file, before_do_file, after_do_file, skip_file, None, log, config, config_sql)
  File "../..\XdmLib\CustomFuction.py", line 631, in file2db_init
    log.error(ex, exc_info=True, stack_info=True)
2024-01-11 15:19:58.416 - CustomFuction [INFO    ] [ERROR] 83-TKZ76DN317.xlsx
2024-01-11 15:19:58.417 - CustomFuction [INFO    ] Move file: 83-TKZ76DN317.xlsx to ERROR folder: Data\Source\83-TKZ76DN317.xlsx.
2024-01-11 15:19:58.626 - CustomFuction [INFO    ] ========[ File End ]========
2024-01-11 15:19:58.626 - CustomFuction [INFO    ] ========[ Delete Empty Folder ]========
2024-01-11 15:19:58.638 - CustomFuction [INFO    ] ========== Finally ==========
2024-01-11 15:19:58.822 - __init__   [INFO    ] Set process status code: 5.
2024-01-11 15:21:10.240 - __init__   [INFO    ] # ===== [ XdmLib Ver. ] ===== #
2024-01-11 15:21:10.241 - __init__   [INFO    ] XdmLib Ver. 2.A.13
2024-01-11 15:21:10.241 - __init__   [INFO    ] # ===== [ XdmLib Ver. ] ===== #
2024-01-11 15:21:10.242 - __init__   [INFO    ] Console Quick Edit Disabled
2024-01-11 15:21:10.253 - __init__   [INFO    ] Server/Host Name: DESKTOP-J6AUF2I
2024-01-11 15:21:10.253 - __init__   [INFO    ] Archive setting non-setting, Archive files will be kept.
2024-01-11 15:21:10.253 - __init__   [INFO    ] Error setting non-setting, Error files will be kept.
2024-01-11 15:21:10.577 - __init__   [INFO    ] Server: DESKTOP-J6AUF2I, Status: 5, data_time_flg: None.
2024-01-11 15:21:10.722 - __init__   [INFO    ] Watching control file: D:\Ina\ETL_XdmLib_2.A.13\ETL_XdmLib_2.A.13\EDAETL\ETL_TABLE\ETL_XYN_XLSX_TO_KLARF\ETL_SICA88_TO_KLARF.py.*
2024-01-11 15:21:10.724 - __init__   [INFO    ] SetProcessStatus 0, Start time: 2024-01-11 15:21:10.233358
2024-01-11 15:21:10.948 - __init__   [INFO    ] Set process status code: 0.
2024-01-11 15:21:10.959 - Database   [INFO    ] Non set logging! Using default logging.
2024-01-11 15:21:11.034 - Database   [INFO    ] Non set logging! Using default logging.
2024-01-11 15:21:11.142 - Database   [INFO    ] Non set logging! Using default logging.
2024-01-11 15:21:11.251 - ETL_SICA88_TO_KLARF [INFO    ] Read Source File:0:00:00.026962
2024-01-11 15:21:11.254 - CustomFuction [ERROR   ] 'N0.'
Traceback (most recent call last):
  File "D:\Python37\lib\site-packages\pandas\core\indexes\base.py", line 2898, in get_loc
    return self._engine.get_loc(casted_key)
  File "pandas\_libs\index.pyx", line 70, in pandas._libs.index.IndexEngine.get_loc
  File "pandas\_libs\index.pyx", line 101, in pandas._libs.index.IndexEngine.get_loc
  File "pandas\_libs\hashtable_class_helper.pxi", line 1675, in pandas._libs.hashtable.PyObjectHashTable.get_item
  File "pandas\_libs\hashtable_class_helper.pxi", line 1683, in pandas._libs.hashtable.PyObjectHashTable.get_item
KeyError: 'N0.'

The above exception was the direct cause of the following exception:

Traceback (most recent call last):
  File "../..\XdmLib\CustomFuction.py", line 597, in file2db_init
    file, pre_params, db_src, db_tgt)
  File "D:/Ina/ETL_XdmLib_2.A.13/ETL_XdmLib_2.A.13/EDAETL/ETL_TABLE/ETL_XYN_XLSX_TO_KLARF/ETL_SICA88_TO_KLARF.py", line 59, in do_file
    row['N0.'],
  File "D:\Python37\lib\site-packages\pandas\core\series.py", line 882, in __getitem__
    return self._get_value(key)
  File "D:\Python37\lib\site-packages\pandas\core\series.py", line 990, in _get_value
    loc = self.index.get_loc(label)
  File "D:\Python37\lib\site-packages\pandas\core\indexes\base.py", line 2900, in get_loc
    raise KeyError(key) from err
KeyError: 'N0.'
Stack (most recent call last):
  File "D:/Ina/ETL_XdmLib_2.A.13/ETL_XdmLib_2.A.13/EDAETL/ETL_TABLE/ETL_XYN_XLSX_TO_KLARF/ETL_SICA88_TO_KLARF.py", line 132, in <module>
    do_file, before_do_file, after_do_file, skip_file, None, log, config, config_sql)
  File "../..\XdmLib\CustomFuction.py", line 631, in file2db_init
    log.error(ex, exc_info=True, stack_info=True)
2024-01-11 15:21:11.259 - CustomFuction [INFO    ] [ERROR] 2-HB019RD5CID2.xls
2024-01-11 15:21:11.259 - CustomFuction [INFO    ] Move file: 2-HB019RD5CID2.xls to ERROR folder: Data\Source\2-HB019RD5CID2.xls.
2024-01-11 15:21:11.498 - ETL_SICA88_TO_KLARF [INFO    ] Read Source File:0:00:00.021035
2024-01-11 15:21:11.499 - CustomFuction [ERROR   ] 'N0.'
Traceback (most recent call last):
  File "D:\Python37\lib\site-packages\pandas\core\indexes\base.py", line 2898, in get_loc
    return self._engine.get_loc(casted_key)
  File "pandas\_libs\index.pyx", line 70, in pandas._libs.index.IndexEngine.get_loc
  File "pandas\_libs\index.pyx", line 101, in pandas._libs.index.IndexEngine.get_loc
  File "pandas\_libs\hashtable_class_helper.pxi", line 1675, in pandas._libs.hashtable.PyObjectHashTable.get_item
  File "pandas\_libs\hashtable_class_helper.pxi", line 1683, in pandas._libs.hashtable.PyObjectHashTable.get_item
KeyError: 'N0.'

The above exception was the direct cause of the following exception:

Traceback (most recent call last):
  File "../..\XdmLib\CustomFuction.py", line 597, in file2db_init
    file, pre_params, db_src, db_tgt)
  File "D:/Ina/ETL_XdmLib_2.A.13/ETL_XdmLib_2.A.13/EDAETL/ETL_TABLE/ETL_XYN_XLSX_TO_KLARF/ETL_SICA88_TO_KLARF.py", line 59, in do_file
    row['N0.'],
  File "D:\Python37\lib\site-packages\pandas\core\series.py", line 882, in __getitem__
    return self._get_value(key)
  File "D:\Python37\lib\site-packages\pandas\core\series.py", line 990, in _get_value
    loc = self.index.get_loc(label)
  File "D:\Python37\lib\site-packages\pandas\core\indexes\base.py", line 2900, in get_loc
    raise KeyError(key) from err
KeyError: 'N0.'
Stack (most recent call last):
  File "D:/Ina/ETL_XdmLib_2.A.13/ETL_XdmLib_2.A.13/EDAETL/ETL_TABLE/ETL_XYN_XLSX_TO_KLARF/ETL_SICA88_TO_KLARF.py", line 132, in <module>
    do_file, before_do_file, after_do_file, skip_file, None, log, config, config_sql)
  File "../..\XdmLib\CustomFuction.py", line 631, in file2db_init
    log.error(ex, exc_info=True, stack_info=True)
2024-01-11 15:21:11.503 - CustomFuction [INFO    ] [ERROR] 3-HB07F141CIC7.xls
2024-01-11 15:21:11.503 - CustomFuction [INFO    ] Move file: 3-HB07F141CIC7.xls to ERROR folder: Data\Source\3-HB07F141CIC7.xls.
2024-01-11 15:21:12.133 - ETL_SICA88_TO_KLARF [INFO    ] Read Source File:0:00:00.425979
2024-01-11 15:21:12.133 - CustomFuction [ERROR   ] 'AREA（UM2)'
Traceback (most recent call last):
  File "D:\Python37\lib\site-packages\pandas\core\indexes\base.py", line 2898, in get_loc
    return self._engine.get_loc(casted_key)
  File "pandas\_libs\index.pyx", line 70, in pandas._libs.index.IndexEngine.get_loc
  File "pandas\_libs\index.pyx", line 101, in pandas._libs.index.IndexEngine.get_loc
  File "pandas\_libs\hashtable_class_helper.pxi", line 1675, in pandas._libs.hashtable.PyObjectHashTable.get_item
  File "pandas\_libs\hashtable_class_helper.pxi", line 1683, in pandas._libs.hashtable.PyObjectHashTable.get_item
KeyError: 'AREA（UM2)'

The above exception was the direct cause of the following exception:

Traceback (most recent call last):
  File "../..\XdmLib\CustomFuction.py", line 597, in file2db_init
    file, pre_params, db_src, db_tgt)
  File "D:/Ina/ETL_XdmLib_2.A.13/ETL_XdmLib_2.A.13/EDAETL/ETL_TABLE/ETL_XYN_XLSX_TO_KLARF/ETL_SICA88_TO_KLARF.py", line 66, in do_file
    row['AREA（UM2)'],
  File "D:\Python37\lib\site-packages\pandas\core\series.py", line 882, in __getitem__
    return self._get_value(key)
  File "D:\Python37\lib\site-packages\pandas\core\series.py", line 990, in _get_value
    loc = self.index.get_loc(label)
  File "D:\Python37\lib\site-packages\pandas\core\indexes\base.py", line 2900, in get_loc
    raise KeyError(key) from err
KeyError: 'AREA（UM2)'
Stack (most recent call last):
  File "D:/Ina/ETL_XdmLib_2.A.13/ETL_XdmLib_2.A.13/EDAETL/ETL_TABLE/ETL_XYN_XLSX_TO_KLARF/ETL_SICA88_TO_KLARF.py", line 132, in <module>
    do_file, before_do_file, after_do_file, skip_file, None, log, config, config_sql)
  File "../..\XdmLib\CustomFuction.py", line 631, in file2db_init
    log.error(ex, exc_info=True, stack_info=True)
2024-01-11 15:21:12.137 - CustomFuction [INFO    ] [ERROR] 82-TKZ76DN316.xlsx
2024-01-11 15:21:12.137 - CustomFuction [INFO    ] Move file: 82-TKZ76DN316.xlsx to ERROR folder: Data\Source\82-TKZ76DN316.xlsx.
2024-01-11 15:21:12.327 - ETL_SICA88_TO_KLARF [INFO    ] Read Source File:0:00:00.040004
2024-01-11 15:21:12.328 - CustomFuction [ERROR   ] 'AREA（UM2)'
Traceback (most recent call last):
  File "D:\Python37\lib\site-packages\pandas\core\indexes\base.py", line 2898, in get_loc
    return self._engine.get_loc(casted_key)
  File "pandas\_libs\index.pyx", line 70, in pandas._libs.index.IndexEngine.get_loc
  File "pandas\_libs\index.pyx", line 101, in pandas._libs.index.IndexEngine.get_loc
  File "pandas\_libs\hashtable_class_helper.pxi", line 1675, in pandas._libs.hashtable.PyObjectHashTable.get_item
  File "pandas\_libs\hashtable_class_helper.pxi", line 1683, in pandas._libs.hashtable.PyObjectHashTable.get_item
KeyError: 'AREA（UM2)'

The above exception was the direct cause of the following exception:

Traceback (most recent call last):
  File "../..\XdmLib\CustomFuction.py", line 597, in file2db_init
    file, pre_params, db_src, db_tgt)
  File "D:/Ina/ETL_XdmLib_2.A.13/ETL_XdmLib_2.A.13/EDAETL/ETL_TABLE/ETL_XYN_XLSX_TO_KLARF/ETL_SICA88_TO_KLARF.py", line 66, in do_file
    row['AREA（UM2)'],
  File "D:\Python37\lib\site-packages\pandas\core\series.py", line 882, in __getitem__
    return self._get_value(key)
  File "D:\Python37\lib\site-packages\pandas\core\series.py", line 990, in _get_value
    loc = self.index.get_loc(label)
  File "D:\Python37\lib\site-packages\pandas\core\indexes\base.py", line 2900, in get_loc
    raise KeyError(key) from err
KeyError: 'AREA（UM2)'
Stack (most recent call last):
  File "D:/Ina/ETL_XdmLib_2.A.13/ETL_XdmLib_2.A.13/EDAETL/ETL_TABLE/ETL_XYN_XLSX_TO_KLARF/ETL_SICA88_TO_KLARF.py", line 132, in <module>
    do_file, before_do_file, after_do_file, skip_file, None, log, config, config_sql)
  File "../..\XdmLib\CustomFuction.py", line 631, in file2db_init
    log.error(ex, exc_info=True, stack_info=True)
2024-01-11 15:21:12.330 - CustomFuction [INFO    ] [ERROR] 83-TKZ76DN317.xlsx
2024-01-11 15:21:12.331 - CustomFuction [INFO    ] Move file: 83-TKZ76DN317.xlsx to ERROR folder: Data\Source\83-TKZ76DN317.xlsx.
2024-01-11 15:21:12.509 - CustomFuction [INFO    ] ========[ File End ]========
2024-01-11 15:21:12.509 - CustomFuction [INFO    ] ========[ Delete Empty Folder ]========
2024-01-11 15:21:12.519 - CustomFuction [INFO    ] ========== Finally ==========
2024-01-11 15:21:12.708 - __init__   [INFO    ] Set process status code: 5.
2024-01-11 15:21:42.378 - __init__   [INFO    ] # ===== [ XdmLib Ver. ] ===== #
2024-01-11 15:21:42.378 - __init__   [INFO    ] XdmLib Ver. 2.A.13
2024-01-11 15:21:42.378 - __init__   [INFO    ] # ===== [ XdmLib Ver. ] ===== #
2024-01-11 15:21:42.379 - __init__   [INFO    ] Console Quick Edit Disabled
2024-01-11 15:21:42.389 - __init__   [INFO    ] Server/Host Name: DESKTOP-J6AUF2I
2024-01-11 15:21:42.389 - __init__   [INFO    ] Archive setting non-setting, Archive files will be kept.
2024-01-11 15:21:42.390 - __init__   [INFO    ] Error setting non-setting, Error files will be kept.
2024-01-11 15:21:42.739 - __init__   [INFO    ] Server: DESKTOP-J6AUF2I, Status: 5, data_time_flg: None.
2024-01-11 15:21:42.803 - __init__   [INFO    ] Watching control file: D:\Ina\ETL_XdmLib_2.A.13\ETL_XdmLib_2.A.13\EDAETL\ETL_TABLE\ETL_XYN_XLSX_TO_KLARF\ETL_SICA88_TO_KLARF.py.*
2024-01-11 15:21:42.805 - __init__   [INFO    ] SetProcessStatus 0, Start time: 2024-01-11 15:21:42.370571
2024-01-11 15:21:42.992 - __init__   [INFO    ] Set process status code: 0.
2024-01-11 15:21:43.001 - Database   [INFO    ] Non set logging! Using default logging.
2024-01-11 15:21:43.069 - Database   [INFO    ] Non set logging! Using default logging.
2024-01-11 15:21:43.144 - Database   [INFO    ] Non set logging! Using default logging.
2024-01-11 15:21:43.257 - ETL_SICA88_TO_KLARF [INFO    ] Read Source File:0:00:00.033002
2024-01-11 15:21:43.260 - CustomFuction [ERROR   ] 'N0.'
Traceback (most recent call last):
  File "D:\Python37\lib\site-packages\pandas\core\indexes\base.py", line 2898, in get_loc
    return self._engine.get_loc(casted_key)
  File "pandas\_libs\index.pyx", line 70, in pandas._libs.index.IndexEngine.get_loc
  File "pandas\_libs\index.pyx", line 101, in pandas._libs.index.IndexEngine.get_loc
  File "pandas\_libs\hashtable_class_helper.pxi", line 1675, in pandas._libs.hashtable.PyObjectHashTable.get_item
  File "pandas\_libs\hashtable_class_helper.pxi", line 1683, in pandas._libs.hashtable.PyObjectHashTable.get_item
KeyError: 'N0.'

The above exception was the direct cause of the following exception:

Traceback (most recent call last):
  File "../..\XdmLib\CustomFuction.py", line 597, in file2db_init
    file, pre_params, db_src, db_tgt)
  File "D:/Ina/ETL_XdmLib_2.A.13/ETL_XdmLib_2.A.13/EDAETL/ETL_TABLE/ETL_XYN_XLSX_TO_KLARF/ETL_SICA88_TO_KLARF.py", line 59, in do_file
    row['N0.'],
  File "D:\Python37\lib\site-packages\pandas\core\series.py", line 882, in __getitem__
    return self._get_value(key)
  File "D:\Python37\lib\site-packages\pandas\core\series.py", line 990, in _get_value
    loc = self.index.get_loc(label)
  File "D:\Python37\lib\site-packages\pandas\core\indexes\base.py", line 2900, in get_loc
    raise KeyError(key) from err
KeyError: 'N0.'
Stack (most recent call last):
  File "D:/Ina/ETL_XdmLib_2.A.13/ETL_XdmLib_2.A.13/EDAETL/ETL_TABLE/ETL_XYN_XLSX_TO_KLARF/ETL_SICA88_TO_KLARF.py", line 132, in <module>
    do_file, before_do_file, after_do_file, skip_file, None, log, config, config_sql)
  File "../..\XdmLib\CustomFuction.py", line 631, in file2db_init
    log.error(ex, exc_info=True, stack_info=True)
2024-01-11 15:21:43.265 - CustomFuction [INFO    ] [ERROR] 2-HB019RD5CID2.xls
2024-01-11 15:21:43.266 - CustomFuction [INFO    ] Move file: 2-HB019RD5CID2.xls to ERROR folder: Data\Source\2-HB019RD5CID2.xls.
2024-01-11 15:21:43.528 - ETL_SICA88_TO_KLARF [INFO    ] Read Source File:0:00:00.011289
2024-01-11 15:21:43.529 - CustomFuction [ERROR   ] 'N0.'
Traceback (most recent call last):
  File "D:\Python37\lib\site-packages\pandas\core\indexes\base.py", line 2898, in get_loc
    return self._engine.get_loc(casted_key)
  File "pandas\_libs\index.pyx", line 70, in pandas._libs.index.IndexEngine.get_loc
  File "pandas\_libs\index.pyx", line 101, in pandas._libs.index.IndexEngine.get_loc
  File "pandas\_libs\hashtable_class_helper.pxi", line 1675, in pandas._libs.hashtable.PyObjectHashTable.get_item
  File "pandas\_libs\hashtable_class_helper.pxi", line 1683, in pandas._libs.hashtable.PyObjectHashTable.get_item
KeyError: 'N0.'

The above exception was the direct cause of the following exception:

Traceback (most recent call last):
  File "../..\XdmLib\CustomFuction.py", line 597, in file2db_init
    file, pre_params, db_src, db_tgt)
  File "D:/Ina/ETL_XdmLib_2.A.13/ETL_XdmLib_2.A.13/EDAETL/ETL_TABLE/ETL_XYN_XLSX_TO_KLARF/ETL_SICA88_TO_KLARF.py", line 59, in do_file
    row['N0.'],
  File "D:\Python37\lib\site-packages\pandas\core\series.py", line 882, in __getitem__
    return self._get_value(key)
  File "D:\Python37\lib\site-packages\pandas\core\series.py", line 990, in _get_value
    loc = self.index.get_loc(label)
  File "D:\Python37\lib\site-packages\pandas\core\indexes\base.py", line 2900, in get_loc
    raise KeyError(key) from err
KeyError: 'N0.'
Stack (most recent call last):
  File "D:/Ina/ETL_XdmLib_2.A.13/ETL_XdmLib_2.A.13/EDAETL/ETL_TABLE/ETL_XYN_XLSX_TO_KLARF/ETL_SICA88_TO_KLARF.py", line 132, in <module>
    do_file, before_do_file, after_do_file, skip_file, None, log, config, config_sql)
  File "../..\XdmLib\CustomFuction.py", line 631, in file2db_init
    log.error(ex, exc_info=True, stack_info=True)
2024-01-11 15:21:43.531 - CustomFuction [INFO    ] [ERROR] 3-HB07F141CIC7.xls
2024-01-11 15:21:43.532 - CustomFuction [INFO    ] Move file: 3-HB07F141CIC7.xls to ERROR folder: Data\Source\3-HB07F141CIC7.xls.
2024-01-11 15:21:44.181 - ETL_SICA88_TO_KLARF [INFO    ] Read Source File:0:00:00.444213
2024-01-11 15:21:44.184 - ETL_SICA88_TO_KLARF [INFO    ] Converter ./Data/Source\82-TKZ76DN316 to KLA-Tencor_None_TKZ76DN316_01_TKZ76DN316_2024-01-11-15-21-43.001 ;Total Used:0:00:00.446529
2024-01-11 15:21:44.187 - CustomFuction [INFO    ] [Archive] 82-TKZ76DN316.xlsx
2024-01-11 15:21:44.187 - CustomFuction [INFO    ] Move file: 82-TKZ76DN316.xlsx to Archive folder: Data\Archive\82-TKZ76DN316.xlsx.
2024-01-11 15:21:44.215 - ETL_SICA88_TO_KLARF [INFO    ] Read Source File:0:00:00.028000
2024-01-11 15:21:44.218 - ETL_SICA88_TO_KLARF [INFO    ] Converter ./Data/Source\83-TKZ76DN317 to KLA-Tencor_None_TKZ76DN317_01_TKZ76DN317_2024-01-11-15-21-44.001 ;Total Used:0:00:00.031001
2024-01-11 15:21:44.220 - CustomFuction [INFO    ] [Archive] 83-TKZ76DN317.xlsx
2024-01-11 15:21:44.221 - CustomFuction [INFO    ] Move file: 83-TKZ76DN317.xlsx to Archive folder: Data\Archive\83-TKZ76DN317.xlsx.
2024-01-11 15:21:44.221 - CustomFuction [INFO    ] ========[ File End ]========
2024-01-11 15:21:44.222 - CustomFuction [INFO    ] ========[ Delete Empty Folder ]========
2024-01-11 15:21:44.232 - CustomFuction [INFO    ] ========== Finally ==========
2024-01-11 15:21:44.468 - __init__   [INFO    ] Set process status code: 5.
2024-01-11 15:58:44.695 - __init__   [INFO    ] # ===== [ XdmLib Ver. ] ===== #
2024-01-11 15:58:44.695 - __init__   [INFO    ] XdmLib Ver. 2.A.13
2024-01-11 15:58:44.695 - __init__   [INFO    ] # ===== [ XdmLib Ver. ] ===== #
2024-01-11 15:58:44.696 - __init__   [INFO    ] Console Quick Edit Disabled
2024-01-11 15:58:44.707 - __init__   [INFO    ] Server/Host Name: DESKTOP-J6AUF2I
2024-01-11 15:58:44.708 - __init__   [INFO    ] Archive setting non-setting, Archive files will be kept.
2024-01-11 15:58:44.708 - __init__   [INFO    ] Error setting non-setting, Error files will be kept.
2024-01-11 15:58:44.986 - __init__   [INFO    ] Server: DESKTOP-J6AUF2I, Status: 5, data_time_flg: None.
2024-01-11 15:58:47.462 - __init__   [INFO    ] Watching control file: D:\Ina\ETL_XdmLib_2.A.13\ETL_XdmLib_2.A.13\EDAETL\ETL_TABLE\ETL_XYN_XLSX_TO_KLARF\ETL_SICA88_TO_KLARF.py.*
2024-01-11 15:58:47.464 - __init__   [INFO    ] SetProcessStatus 0, Start time: 2024-01-11 15:58:44.687954
2024-01-11 15:58:47.714 - __init__   [INFO    ] Set process status code: 0.
2024-01-11 15:58:47.723 - Database   [INFO    ] Non set logging! Using default logging.
2024-01-11 15:58:47.820 - Database   [INFO    ] Non set logging! Using default logging.
2024-01-11 15:58:47.902 - Database   [INFO    ] Non set logging! Using default logging.
2024-01-11 15:58:48.514 - ETL_SICA88_TO_KLARF [INFO    ] Read Source File:0:00:00.531247
2024-01-11 15:58:48.536 - ETL_SICA88_TO_KLARF [INFO    ] Converter ./Data/Source\1-HB0185F0CIB0 to KLA-Tencor_None_HB0185F0CIB0_01_HB0185F0CIB0_2024-01-11-15-58-47.001 ;Total Used:0:00:00.553282
2024-01-11 15:58:48.538 - CustomFuction [INFO    ] [Archive] 1-HB0185F0CIB0.xlsx
2024-01-11 15:58:48.539 - CustomFuction [INFO    ] Move file: 1-HB0185F0CIB0.xlsx to Archive folder: Data\Archive\1-HB0185F0CIB0.xlsx.
2024-01-11 15:58:48.566 - ETL_SICA88_TO_KLARF [INFO    ] Read Source File:0:00:00.027023
2024-01-11 15:58:48.589 - ETL_SICA88_TO_KLARF [INFO    ] Converter ./Data/Source\1-HB0185F0CIB2 to KLA-Tencor_None_HB0185F0CIB2_01_HB0185F0CIB2_2024-01-11-15-58-48.001 ;Total Used:0:00:00.050022
2024-01-11 15:58:48.590 - CustomFuction [INFO    ] [Archive] 1-HB0185F0CIB2.xls
2024-01-11 15:58:48.591 - CustomFuction [INFO    ] Move file: 1-HB0185F0CIB2.xls to Archive folder: Data\Archive\1-HB0185F0CIB2.xls.
2024-01-11 15:58:48.621 - ETL_SICA88_TO_KLARF [INFO    ] Read Source File:0:00:00.029993
2024-01-11 15:58:48.626 - ETL_SICA88_TO_KLARF [INFO    ] Converter ./Data/Source\1-T17601236105 to KLA-Tencor_None_T17601236105_01_T17601236105_2024-01-11-15-58-48.001 ;Total Used:0:00:00.034990
2024-01-11 15:58:48.628 - CustomFuction [INFO    ] [Archive] 1-T17601236105.xlsx
2024-01-11 15:58:48.628 - CustomFuction [INFO    ] Move file: 1-T17601236105.xlsx to Archive folder: Data\Archive\1-T17601236105.xlsx.
2024-01-11 15:58:48.641 - ETL_SICA88_TO_KLARF [INFO    ] Read Source File:0:00:00.013019
2024-01-11 15:58:48.659 - ETL_SICA88_TO_KLARF [INFO    ] Converter ./Data/Source\2-HB019RD5CID2 to KLA-Tencor_None_HB019RD5CID2_01_HB019RD5CID2_2024-01-11-15-58-48.001 ;Total Used:0:00:00.030986
2024-01-11 15:58:48.661 - CustomFuction [INFO    ] [Archive] 2-HB019RD5CID2.xls
2024-01-11 15:58:48.663 - CustomFuction [INFO    ] Move file: 2-HB019RD5CID2.xls to Archive folder: Data\Archive\2-HB019RD5CID2.xls.
2024-01-11 15:58:48.671 - ETL_SICA88_TO_KLARF [INFO    ] Read Source File:0:00:00.008030
2024-01-11 15:58:48.675 - ETL_SICA88_TO_KLARF [INFO    ] Converter ./Data/Source\2-T06709236J25 to KLA-Tencor_None_T06709236J25_01_T06709236J25_2024-01-11-15-58-48.001 ;Total Used:0:00:00.012023
2024-01-11 15:58:48.677 - CustomFuction [INFO    ] [Archive] 2-T06709236J25.xls
2024-01-11 15:58:48.677 - CustomFuction [INFO    ] Move file: 2-T06709236J25.xls to Archive folder: Data\Archive\2-T06709236J25.xls.
2024-01-11 15:58:48.686 - ETL_SICA88_TO_KLARF [INFO    ] Read Source File:0:00:00.009002
2024-01-11 15:58:48.695 - ETL_SICA88_TO_KLARF [INFO    ] Converter ./Data/Source\3-HB07F141CIC7 to KLA-Tencor_None_HB07F141CIC7_01_HB07F141CIC7_2024-01-11-15-58-48.001 ;Total Used:0:00:00.018026
2024-01-11 15:58:48.697 - CustomFuction [INFO    ] [Archive] 3-HB07F141CIC7.xls
2024-01-11 15:58:48.698 - CustomFuction [INFO    ] Move file: 3-HB07F141CIC7.xls to Archive folder: Data\Archive\3-HB07F141CIC7.xls.
2024-01-11 15:58:48.710 - ETL_SICA88_TO_KLARF [INFO    ] Read Source File:0:00:00.012023
2024-01-11 15:58:48.719 - ETL_SICA88_TO_KLARF [INFO    ] Converter ./Data/Source\4-HB0F3985CIC3 to KLA-Tencor_None_HB0F3985CIC3_01_HB0F3985CIC3_2024-01-11-15-58-48.001 ;Total Used:0:00:00.020999
2024-01-11 15:58:48.721 - CustomFuction [INFO    ] [Archive] 4-HB0F3985CIC3.xls
2024-01-11 15:58:48.722 - CustomFuction [INFO    ] Move file: 4-HB0F3985CIC3.xls to Archive folder: Data\Archive\4-HB0F3985CIC3.xls.
2024-01-11 15:58:48.750 - ETL_SICA88_TO_KLARF [INFO    ] Read Source File:0:00:00.027993
2024-01-11 15:58:48.756 - ETL_SICA88_TO_KLARF [INFO    ] Converter ./Data/Source\40-4N46-DF07016 to KLA-Tencor_None_4N46-DF07016_01_4N46-DF07016_2024-01-11-15-58-48.001 ;Total Used:0:00:00.033993
2024-01-11 15:58:48.758 - CustomFuction [INFO    ] [Archive] 40-4N46-DF07016.xlsx
2024-01-11 15:58:48.758 - CustomFuction [INFO    ] Move file: 40-4N46-DF07016.xlsx to Archive folder: Data\Archive\40-4N46-DF07016.xlsx.
2024-01-11 15:58:48.764 - ETL_SICA88_TO_KLARF [INFO    ] Read Source File:0:00:00.006011
2024-01-11 15:58:48.774 - ETL_SICA88_TO_KLARF [INFO    ] Converter ./Data/Source\5-HB07FYQ6CIB5 to KLA-Tencor_None_HB07FYQ6CIB5_01_HB07FYQ6CIB5_2024-01-11-15-58-48.001 ;Total Used:0:00:00.016004
2024-01-11 15:58:48.775 - CustomFuction [INFO    ] [Archive] 5_HB07FYQ6CIB5.csv
2024-01-11 15:58:48.776 - CustomFuction [INFO    ] Move file: 5_HB07FYQ6CIB5.csv to Archive folder: Data\Archive\5_HB07FYQ6CIB5.csv.
2024-01-11 15:58:48.804 - ETL_SICA88_TO_KLARF [INFO    ] Read Source File:0:00:00.028026
2024-01-11 15:58:48.806 - ETL_SICA88_TO_KLARF [INFO    ] Converter ./Data/Source\82-TKZ76DN316 to KLA-Tencor_None_TKZ76DN316_01_TKZ76DN316_2024-01-11-15-58-48.001 ;Total Used:0:00:00.030001
2024-01-11 15:58:48.808 - CustomFuction [INFO    ] [Archive] 82-TKZ76DN316.xlsx
2024-01-11 15:58:48.809 - CustomFuction [INFO    ] Move file: 82-TKZ76DN316.xlsx to Archive folder: Data\Archive\82-TKZ76DN316.xlsx.
2024-01-11 15:58:48.864 - ETL_SICA88_TO_KLARF [INFO    ] Read Source File:0:00:00.054999
2024-01-11 15:58:48.867 - ETL_SICA88_TO_KLARF [INFO    ] Converter ./Data/Source\83-TKZ76DN317 to KLA-Tencor_None_TKZ76DN317_01_TKZ76DN317_2024-01-11-15-58-48.001 ;Total Used:0:00:00.058003
2024-01-11 15:58:48.869 - CustomFuction [INFO    ] [Archive] 83-TKZ76DN317.xlsx
2024-01-11 15:58:48.887 - CustomFuction [INFO    ] Move file: 83-TKZ76DN317.xlsx to Archive folder: Data\Archive\83-TKZ76DN317.xlsx.
2024-01-11 15:58:48.887 - CustomFuction [INFO    ] ========[ File End ]========
2024-01-11 15:58:48.887 - CustomFuction [INFO    ] ========[ Delete Empty Folder ]========
2024-01-11 15:58:48.896 - CustomFuction [INFO    ] ========== Finally ==========
2024-01-11 15:58:49.076 - __init__   [INFO    ] Set process status code: 1, Last data time: None.
