2023-08-18 11:49:14.698 - CustomFuction [ERROR   ] Move File Error
2023-08-18 11:49:14.700 - CustomFuction [ERROR   ] '.\\\\Data\\\\Source\\Slot02__4N46-DM06422_6inch_BarePl_6S000_20230428_101134.csv' and 'Data\\Source\\Slot02__4N46-DM06422_6inch_BarePl_6S000_20230428_101134.csv' are the same file
Traceback (most recent call last):
  File "D:\soft\anaconda3\lib\shutil.py", line 823, in move
    os.rename(src, real_dst)
PermissionError: [WinError 32] 另一个程序正在使用此文件，进程无法访问。: '.\\\\Data\\\\Source\\Slot02__4N46-DM06422_6inch_BarePl_6S000_20230428_101134.csv' -> 'Data\\Source\\Slot02__4N46-DM06422_6inch_BarePl_6S000_20230428_101134.csv'

During handling of the above exception, another exception occurred:

Traceback (most recent call last):
  File "D:\Ina\ETL_XdmLib_2.A.13\ETL_XdmLib_2.A.13\EDAETL\ETL_TABLE\ETL_POC_XLS_TO_KLARF_衬底\../..\XdmLib\CustomFuction.py", line 1035, in move_file
    msg = shutil.move(os.path.join(source_path, fileName),
  File "D:\soft\anaconda3\lib\shutil.py", line 843, in move
    copy_function(src, real_dst)
  File "D:\soft\anaconda3\lib\shutil.py", line 444, in copy2
    copyfile(src, dst, follow_symlinks=follow_symlinks)
  File "D:\soft\anaconda3\lib\shutil.py", line 244, in copyfile
    raise SameFileError("{!r} and {!r} are the same file".format(src, dst))
shutil.SameFileError: '.\\\\Data\\\\Source\\Slot02__4N46-DM06422_6inch_BarePl_6S000_20230428_101134.csv' and 'Data\\Source\\Slot02__4N46-DM06422_6inch_BarePl_6S000_20230428_101134.csv' are the same file
Stack (most recent call last):
  File "D:\Ina\ETL_XdmLib_2.A.13\ETL_XdmLib_2.A.13\EDAETL\ETL_TABLE\ETL_POC_XLS_TO_KLARF_衬底\ETL_XLS_TO_KLARF_TEST_衬底.py", line 129, in <module>
    XdmLib.CustomFuction.file2db_init(
  File "D:\Ina\ETL_XdmLib_2.A.13\ETL_XdmLib_2.A.13\EDAETL\ETL_TABLE\ETL_POC_XLS_TO_KLARF_衬底\../..\XdmLib\CustomFuction.py", line 629, in file2db_init
    move_file_self(move_file_info)
  File "D:\Ina\ETL_XdmLib_2.A.13\ETL_XdmLib_2.A.13\EDAETL\ETL_TABLE\ETL_POC_XLS_TO_KLARF_衬底\../..\XdmLib\CustomFuction.py", line 1044, in move_file
    log.error(ex, exc_info=True, stack_info=True)
2023-08-18 13:33:51.352 - CustomFuction [ERROR   ] Move File Error
2023-08-18 13:33:51.356 - CustomFuction [ERROR   ] '.\\\\Data\\\\Source\\Slot02__4N46-DM06422_6inch_BarePl_6S000_20230428_101134.csv' and 'Data\\Source\\Slot02__4N46-DM06422_6inch_BarePl_6S000_20230428_101134.csv' are the same file
Traceback (most recent call last):
  File "D:\soft\anaconda3\lib\shutil.py", line 823, in move
    os.rename(src, real_dst)
PermissionError: [WinError 32] 另一个程序正在使用此文件，进程无法访问。: '.\\\\Data\\\\Source\\Slot02__4N46-DM06422_6inch_BarePl_6S000_20230428_101134.csv' -> 'Data\\Source\\Slot02__4N46-DM06422_6inch_BarePl_6S000_20230428_101134.csv'

During handling of the above exception, another exception occurred:

Traceback (most recent call last):
  File "D:\Ina\ETL_XdmLib_2.A.13\ETL_XdmLib_2.A.13\EDAETL\ETL_TABLE\ETL_POC_XLS_TO_KLARF_衬底\../..\XdmLib\CustomFuction.py", line 1035, in move_file
    msg = shutil.move(os.path.join(source_path, fileName),
  File "D:\soft\anaconda3\lib\shutil.py", line 843, in move
    copy_function(src, real_dst)
  File "D:\soft\anaconda3\lib\shutil.py", line 444, in copy2
    copyfile(src, dst, follow_symlinks=follow_symlinks)
  File "D:\soft\anaconda3\lib\shutil.py", line 244, in copyfile
    raise SameFileError("{!r} and {!r} are the same file".format(src, dst))
shutil.SameFileError: '.\\\\Data\\\\Source\\Slot02__4N46-DM06422_6inch_BarePl_6S000_20230428_101134.csv' and 'Data\\Source\\Slot02__4N46-DM06422_6inch_BarePl_6S000_20230428_101134.csv' are the same file
Stack (most recent call last):
  File "D:\Ina\ETL_XdmLib_2.A.13\ETL_XdmLib_2.A.13\EDAETL\ETL_TABLE\ETL_POC_XLS_TO_KLARF_衬底\ETL_XLS_TO_KLARF_TEST_衬底.py", line 129, in <module>
    XdmLib.CustomFuction.file2db_init(
  File "D:\Ina\ETL_XdmLib_2.A.13\ETL_XdmLib_2.A.13\EDAETL\ETL_TABLE\ETL_POC_XLS_TO_KLARF_衬底\../..\XdmLib\CustomFuction.py", line 629, in file2db_init
    move_file_self(move_file_info)
  File "D:\Ina\ETL_XdmLib_2.A.13\ETL_XdmLib_2.A.13\EDAETL\ETL_TABLE\ETL_POC_XLS_TO_KLARF_衬底\../..\XdmLib\CustomFuction.py", line 1044, in move_file
    log.error(ex, exc_info=True, stack_info=True)
2023-08-18 13:55:38.830 - CustomFuction [ERROR   ] Move File Error
2023-08-18 13:55:38.833 - CustomFuction [ERROR   ] '.\\\\Data\\\\Source\\Slot02__4N46-DM06422_6inch_BarePl_6S000_20230428_101134.csv' and 'Data\\Source\\Slot02__4N46-DM06422_6inch_BarePl_6S000_20230428_101134.csv' are the same file
Traceback (most recent call last):
  File "D:\soft\anaconda3\lib\shutil.py", line 823, in move
    os.rename(src, real_dst)
PermissionError: [WinError 32] 另一个程序正在使用此文件，进程无法访问。: '.\\\\Data\\\\Source\\Slot02__4N46-DM06422_6inch_BarePl_6S000_20230428_101134.csv' -> 'Data\\Source\\Slot02__4N46-DM06422_6inch_BarePl_6S000_20230428_101134.csv'

During handling of the above exception, another exception occurred:

Traceback (most recent call last):
  File "D:\Ina\ETL_XdmLib_2.A.13\ETL_XdmLib_2.A.13\EDAETL\ETL_TABLE\ETL_POC_XLS_TO_KLARF_衬底\../..\XdmLib\CustomFuction.py", line 1035, in move_file
    msg = shutil.move(os.path.join(source_path, fileName),
  File "D:\soft\anaconda3\lib\shutil.py", line 843, in move
    copy_function(src, real_dst)
  File "D:\soft\anaconda3\lib\shutil.py", line 444, in copy2
    copyfile(src, dst, follow_symlinks=follow_symlinks)
  File "D:\soft\anaconda3\lib\shutil.py", line 244, in copyfile
    raise SameFileError("{!r} and {!r} are the same file".format(src, dst))
shutil.SameFileError: '.\\\\Data\\\\Source\\Slot02__4N46-DM06422_6inch_BarePl_6S000_20230428_101134.csv' and 'Data\\Source\\Slot02__4N46-DM06422_6inch_BarePl_6S000_20230428_101134.csv' are the same file
Stack (most recent call last):
  File "D:\Ina\ETL_XdmLib_2.A.13\ETL_XdmLib_2.A.13\EDAETL\ETL_TABLE\ETL_POC_XLS_TO_KLARF_衬底\ETL_XLS_TO_KLARF_TEST_衬底.py", line 137, in <module>
    XdmLib.CustomFuction.file2db_init(
  File "D:\Ina\ETL_XdmLib_2.A.13\ETL_XdmLib_2.A.13\EDAETL\ETL_TABLE\ETL_POC_XLS_TO_KLARF_衬底\../..\XdmLib\CustomFuction.py", line 629, in file2db_init
    move_file_self(move_file_info)
  File "D:\Ina\ETL_XdmLib_2.A.13\ETL_XdmLib_2.A.13\EDAETL\ETL_TABLE\ETL_POC_XLS_TO_KLARF_衬底\../..\XdmLib\CustomFuction.py", line 1044, in move_file
    log.error(ex, exc_info=True, stack_info=True)
2023-08-18 14:14:58.890 - CustomFuction [ERROR   ] 'Micropipe'
Traceback (most recent call last):
  File "D:\Ina\ETL_XdmLib_2.A.13\ETL_XdmLib_2.A.13\EDAETL\ETL_TABLE\ETL_POC_XLS_TO_KLARF_衬底\../..\XdmLib\CustomFuction.py", line 596, in file2db_init
    res = do_file(file_root_source_path,
  File "D:\Ina\ETL_XdmLib_2.A.13\ETL_XdmLib_2.A.13\EDAETL\ETL_TABLE\ETL_POC_XLS_TO_KLARF_衬底\ETL_XLS_TO_KLARF_TEST_衬底.py", line 52, in do_file
    DefectCodesDict[row['Class']],
KeyError: 'Micropipe'
Stack (most recent call last):
  File "D:\Ina\ETL_XdmLib_2.A.13\ETL_XdmLib_2.A.13\EDAETL\ETL_TABLE\ETL_POC_XLS_TO_KLARF_衬底\ETL_XLS_TO_KLARF_TEST_衬底.py", line 117, in <module>
    XdmLib.CustomFuction.file2db_init(
  File "D:\Ina\ETL_XdmLib_2.A.13\ETL_XdmLib_2.A.13\EDAETL\ETL_TABLE\ETL_POC_XLS_TO_KLARF_衬底\../..\XdmLib\CustomFuction.py", line 631, in file2db_init
    log.error(ex, exc_info=True, stack_info=True)
2023-08-18 14:15:02.443 - CustomFuction [ERROR   ] 'Micropipe'
Traceback (most recent call last):
  File "D:\Ina\ETL_XdmLib_2.A.13\ETL_XdmLib_2.A.13\EDAETL\ETL_TABLE\ETL_POC_XLS_TO_KLARF_衬底\../..\XdmLib\CustomFuction.py", line 596, in file2db_init
    res = do_file(file_root_source_path,
  File "D:\Ina\ETL_XdmLib_2.A.13\ETL_XdmLib_2.A.13\EDAETL\ETL_TABLE\ETL_POC_XLS_TO_KLARF_衬底\ETL_XLS_TO_KLARF_TEST_衬底.py", line 52, in do_file
    DefectCodesDict[row['Class']],
KeyError: 'Micropipe'
Stack (most recent call last):
  File "D:\Ina\ETL_XdmLib_2.A.13\ETL_XdmLib_2.A.13\EDAETL\ETL_TABLE\ETL_POC_XLS_TO_KLARF_衬底\ETL_XLS_TO_KLARF_TEST_衬底.py", line 117, in <module>
    XdmLib.CustomFuction.file2db_init(
  File "D:\Ina\ETL_XdmLib_2.A.13\ETL_XdmLib_2.A.13\EDAETL\ETL_TABLE\ETL_POC_XLS_TO_KLARF_衬底\../..\XdmLib\CustomFuction.py", line 631, in file2db_init
    log.error(ex, exc_info=True, stack_info=True)
2023-08-18 14:15:07.885 - CustomFuction [ERROR   ] 'Micropipe'
Traceback (most recent call last):
  File "D:\Ina\ETL_XdmLib_2.A.13\ETL_XdmLib_2.A.13\EDAETL\ETL_TABLE\ETL_POC_XLS_TO_KLARF_衬底\../..\XdmLib\CustomFuction.py", line 596, in file2db_init
    res = do_file(file_root_source_path,
  File "D:\Ina\ETL_XdmLib_2.A.13\ETL_XdmLib_2.A.13\EDAETL\ETL_TABLE\ETL_POC_XLS_TO_KLARF_衬底\ETL_XLS_TO_KLARF_TEST_衬底.py", line 52, in do_file
    DefectCodesDict[row['Class']],
KeyError: 'Micropipe'
Stack (most recent call last):
  File "D:\Ina\ETL_XdmLib_2.A.13\ETL_XdmLib_2.A.13\EDAETL\ETL_TABLE\ETL_POC_XLS_TO_KLARF_衬底\ETL_XLS_TO_KLARF_TEST_衬底.py", line 117, in <module>
    XdmLib.CustomFuction.file2db_init(
  File "D:\Ina\ETL_XdmLib_2.A.13\ETL_XdmLib_2.A.13\EDAETL\ETL_TABLE\ETL_POC_XLS_TO_KLARF_衬底\../..\XdmLib\CustomFuction.py", line 631, in file2db_init
    log.error(ex, exc_info=True, stack_info=True)
2023-08-18 14:53:07.951 - CustomFuction [ERROR   ] 'Micropipe'
Traceback (most recent call last):
  File "D:\Ina\ETL_XdmLib_2.A.13\ETL_XdmLib_2.A.13\EDAETL\ETL_TABLE\ETL_POC_XLS_TO_KLARF_衬底\../..\XdmLib\CustomFuction.py", line 596, in file2db_init
    res = do_file(file_root_source_path,
  File "D:\Ina\ETL_XdmLib_2.A.13\ETL_XdmLib_2.A.13\EDAETL\ETL_TABLE\ETL_POC_XLS_TO_KLARF_衬底\ETL_XLS_TO_KLARF_TEST_衬底.py", line 52, in do_file
    DefectCodesDict[row['Class']],
KeyError: 'Micropipe'
Stack (most recent call last):
  File "D:\Ina\ETL_XdmLib_2.A.13\ETL_XdmLib_2.A.13\EDAETL\ETL_TABLE\ETL_POC_XLS_TO_KLARF_衬底\ETL_XLS_TO_KLARF_TEST_衬底.py", line 117, in <module>
    XdmLib.CustomFuction.file2db_init(
  File "D:\Ina\ETL_XdmLib_2.A.13\ETL_XdmLib_2.A.13\EDAETL\ETL_TABLE\ETL_POC_XLS_TO_KLARF_衬底\../..\XdmLib\CustomFuction.py", line 631, in file2db_init
    log.error(ex, exc_info=True, stack_info=True)
2023-08-18 14:53:11.609 - CustomFuction [ERROR   ] 'Micropipe'
Traceback (most recent call last):
  File "D:\Ina\ETL_XdmLib_2.A.13\ETL_XdmLib_2.A.13\EDAETL\ETL_TABLE\ETL_POC_XLS_TO_KLARF_衬底\../..\XdmLib\CustomFuction.py", line 596, in file2db_init
    res = do_file(file_root_source_path,
  File "D:\Ina\ETL_XdmLib_2.A.13\ETL_XdmLib_2.A.13\EDAETL\ETL_TABLE\ETL_POC_XLS_TO_KLARF_衬底\ETL_XLS_TO_KLARF_TEST_衬底.py", line 52, in do_file
    DefectCodesDict[row['Class']],
KeyError: 'Micropipe'
Stack (most recent call last):
  File "D:\Ina\ETL_XdmLib_2.A.13\ETL_XdmLib_2.A.13\EDAETL\ETL_TABLE\ETL_POC_XLS_TO_KLARF_衬底\ETL_XLS_TO_KLARF_TEST_衬底.py", line 117, in <module>
    XdmLib.CustomFuction.file2db_init(
  File "D:\Ina\ETL_XdmLib_2.A.13\ETL_XdmLib_2.A.13\EDAETL\ETL_TABLE\ETL_POC_XLS_TO_KLARF_衬底\../..\XdmLib\CustomFuction.py", line 631, in file2db_init
    log.error(ex, exc_info=True, stack_info=True)
2023-08-18 14:53:17.007 - CustomFuction [ERROR   ] 'Micropipe'
Traceback (most recent call last):
  File "D:\Ina\ETL_XdmLib_2.A.13\ETL_XdmLib_2.A.13\EDAETL\ETL_TABLE\ETL_POC_XLS_TO_KLARF_衬底\../..\XdmLib\CustomFuction.py", line 596, in file2db_init
    res = do_file(file_root_source_path,
  File "D:\Ina\ETL_XdmLib_2.A.13\ETL_XdmLib_2.A.13\EDAETL\ETL_TABLE\ETL_POC_XLS_TO_KLARF_衬底\ETL_XLS_TO_KLARF_TEST_衬底.py", line 52, in do_file
    DefectCodesDict[row['Class']],
KeyError: 'Micropipe'
Stack (most recent call last):
  File "D:\Ina\ETL_XdmLib_2.A.13\ETL_XdmLib_2.A.13\EDAETL\ETL_TABLE\ETL_POC_XLS_TO_KLARF_衬底\ETL_XLS_TO_KLARF_TEST_衬底.py", line 117, in <module>
    XdmLib.CustomFuction.file2db_init(
  File "D:\Ina\ETL_XdmLib_2.A.13\ETL_XdmLib_2.A.13\EDAETL\ETL_TABLE\ETL_POC_XLS_TO_KLARF_衬底\../..\XdmLib\CustomFuction.py", line 631, in file2db_init
    log.error(ex, exc_info=True, stack_info=True)
2023-08-18 15:55:58.487 - CustomFuction [ERROR   ] Move File Error
2023-08-18 15:55:58.490 - CustomFuction [ERROR   ] '.\\\\Data\\\\Source\\SUB_6INCH_20230311-3-SX6-150_6K001_Sub_01_4N46-CB07527_13_DefectAttributes.csv' and 'Data\\Source\\SUB_6INCH_20230311-3-SX6-150_6K001_Sub_01_4N46-CB07527_13_DefectAttributes.csv' are the same file
Traceback (most recent call last):
  File "D:\soft\anaconda3\lib\shutil.py", line 823, in move
    os.rename(src, real_dst)
PermissionError: [WinError 32] 另一个程序正在使用此文件，进程无法访问。: '.\\\\Data\\\\Source\\SUB_6INCH_20230311-3-SX6-150_6K001_Sub_01_4N46-CB07527_13_DefectAttributes.csv' -> 'Data\\Source\\SUB_6INCH_20230311-3-SX6-150_6K001_Sub_01_4N46-CB07527_13_DefectAttributes.csv'

During handling of the above exception, another exception occurred:

Traceback (most recent call last):
  File "D:\Ina\ETL_XdmLib_2.A.13\ETL_XdmLib_2.A.13\EDAETL\ETL_TABLE\ETL_POC_XLS_TO_KLARF_衬底\../..\XdmLib\CustomFuction.py", line 1035, in move_file
    msg = shutil.move(os.path.join(source_path, fileName),
  File "D:\soft\anaconda3\lib\shutil.py", line 843, in move
    copy_function(src, real_dst)
  File "D:\soft\anaconda3\lib\shutil.py", line 444, in copy2
    copyfile(src, dst, follow_symlinks=follow_symlinks)
  File "D:\soft\anaconda3\lib\shutil.py", line 244, in copyfile
    raise SameFileError("{!r} and {!r} are the same file".format(src, dst))
shutil.SameFileError: '.\\\\Data\\\\Source\\SUB_6INCH_20230311-3-SX6-150_6K001_Sub_01_4N46-CB07527_13_DefectAttributes.csv' and 'Data\\Source\\SUB_6INCH_20230311-3-SX6-150_6K001_Sub_01_4N46-CB07527_13_DefectAttributes.csv' are the same file
Stack (most recent call last):
  File "D:\Ina\ETL_XdmLib_2.A.13\ETL_XdmLib_2.A.13\EDAETL\ETL_TABLE\ETL_POC_XLS_TO_KLARF_衬底\ETL_XLS_TO_KLARF_TEST_衬底.py", line 138, in <module>
    XdmLib.CustomFuction.file2db_init(
  File "D:\Ina\ETL_XdmLib_2.A.13\ETL_XdmLib_2.A.13\EDAETL\ETL_TABLE\ETL_POC_XLS_TO_KLARF_衬底\../..\XdmLib\CustomFuction.py", line 629, in file2db_init
    move_file_self(move_file_info)
  File "D:\Ina\ETL_XdmLib_2.A.13\ETL_XdmLib_2.A.13\EDAETL\ETL_TABLE\ETL_POC_XLS_TO_KLARF_衬底\../..\XdmLib\CustomFuction.py", line 1044, in move_file
    log.error(ex, exc_info=True, stack_info=True)
